File: mechanical/hysteresis/databak/g60_hysteresis - conductive_2.csv
Time,Extension,Load,Length,Width,Thickness,CS Area,Strain,Stress
(s),(mm),(N),(mm),(mm),(mm),(mm^2),(mm/mm),(MPa)
0,0,-0.00269,16.5,2.82,0.71,2.0022,0,-0.001343522126
0.5,0.0385,0.02239,,,,,0.002333333333,0.01118269903
1,0.08026,0.03335,,,,,0.004864242424,0.01665667765
1.5,0.12158,0.04366,,,,,0.007368484848,0.02180601339
2,0.16367,0.05099,,,,,0.009919393939,0.02546698632
2.5,0.20494,0.0562,,,,,0.01242060606,0.02806912396
3,0.24688,0.06384,,,,,0.01496242424,0.03188492658
3.5,0.28855,0.07279,,,,,0.01748787879,0.03635500949
4,0.32987,0.0784,,,,,0.01999212121,0.03915692738
4.5,0.37201,0.08234,,,,,0.02254606061,0.04112476276
5,0.41356,0.0903,,,,,0.02506424242,0.04510038957
5.5,0.45492,0.09659,,,,,0.02757090909,0.04824193387
6,0.49696,0.10253,,,,,0.03011878788,0.05120867046
6.5,0.53833,0.1069,,,,,0.03262606061,0.0533912696
7,0.58001,0.11154,,,,,0.03515212121,0.05570872041
7.5,0.62196,0.11769,,,,,0.03769454545,0.05878034162
8,0.66315,0.12393,,,,,0.04019090909,0.0618969134
8.5,0.70527,0.12864,,,,,0.04274363636,0.06424932574
9,0.74693,0.13331,,,,,0.04526848485,0.06658176006
9.5,0.78822,0.14095,,,,,0.04777090909,0.07039756268
10,0.83028,0.14492,,,,,0.05032,0.07238038158
10.5,0.87193,0.15062,,,,,0.05284424242,0.07522725002
11,0.91341,0.15681,,,,,0.05535818182,0.07831884927
11.5,0.95524,0.16211,,,,,0.05789333333,0.08096593747
12,0.99661,0.16794,,,,,0.06040060606,0.08387773449
12.5,1.03859,0.17305,,,,,0.06294484848,0.08642992708
13,1.08016,0.17775,,,,,0.06546424242,0.08877734492
13.5,1.12145,0.18195,,,,,0.06796666667,0.09087503746
14,1.16372,0.18886,,,,,0.07052848485,0.09432624113
14.5,1.20507,0.19445,,,,,0.07303454545,0.09711817001
15,1.24665,0.19925,,,,,0.07555454545,0.09951553291
15.5,1.28864,0.2042,,,,,0.07809939394,0.1019878134
16,1.32994,0.2094,,,,,0.08060242424,0.1045849565
16.5,1.37178,0.21673,,,,,0.08313818182,0.1082459295
17,1.41368,0.22032,,,,,0.08567757576,0.1100389571
17.5,1.45482,0.22424,,,,,0.08817090909,0.1119968035
18,1.49692,0.22963,,,,,0.09072242424,0.1146888423
18.5,1.53858,0.23443,,,,,0.09324727273,0.1170862052
19,1.57994,0.23838,,,,,0.09575393939,0.1190590351
19.5,1.62191,0.24448,,,,,0.09829757576,0.1221056837
19.844,1.65015,0.24612,,,,,0.1000090909,0.1229247827
20.245,1.62178,0.19944,,,,,0.09828969697,0.09961042853
20.745,1.58032,0.16708,,,,,0.0957769697,0.08344820697
21.245,1.53887,0.1434,,,,,0.09326484848,0.07162121666
21.745,1.49678,0.12469,,,,,0.09071393939,0.06227649585
22.245,1.45533,0.10843,,,,,0.08820181818,0.05415542903
22.745,1.41381,0.09542,,,,,0.08568545455,0.04765757667
23.245,1.37188,0.08236,,,,,0.08314424242,0.04113475177
23.745,1.33038,0.07087,,,,,0.08062909091,0.03539606433
24.245,1.28854,0.06116,,,,,0.07809333333,0.03054639896
24.745,1.24703,0.05129,,,,,0.07557757576,0.0256168215
25.245,1.20552,0.04392,,,,,0.07306181818,0.02193587054
25.745,1.16331,0.03511,,,,,0.07050363636,0.01753571072
26.245,1.1221,0.02705,,,,,0.06800606061,0.01351013885
26.745,1.08043,0.01864,,,,,0.06548060606,0.009309759265
27.245,1.03839,0.01139,,,,,0.06293272727,0.005688742383
27.745,0.99701,0.00522,,,,,0.06042484848,0.002607132155
28.245,0.95537,-0.00267,,,,,0.05790121212,-0.001333533114
28.745,0.91351,-0.00936,,,,,0.05536424242,-0.004674857657
29.245,0.87216,-0.01581,,,,,0.05285818182,-0.007896314055
29.745,0.83015,-0.02031,,,,,0.05031212121,-0.01014384177
30.245,0.78867,-0.02596,,,,,0.04779818182,-0.01296573769
30.745,0.74717,-0.03349,,,,,0.0452830303,-0.01672660074
31.245,0.70511,-0.03878,,,,,0.04273393939,-0.01936869444
31.745,0.66369,-0.04233,,,,,0.04022363636,-0.02114174408
32.245,0.62192,-0.04825,,,,,0.03769212121,-0.02409849166
32.745,0.58031,-0.05462,,,,,0.03517030303,-0.02727999201
33.245,0.53867,-0.05834,,,,,0.03264666667,-0.02913794826
33.745,0.49681,-0.06309,,,,,0.03010969697,-0.03151033863
34.245,0.4553,-0.06896,,,,,0.02759393939,-0.03444211367
34.745,0.41381,-0.07161,,,,,0.02507939394,-0.03576565778
35.245,0.37164,-0.0778,,,,,0.02252363636,-0.03885725702
35.745,0.33042,-0.08097,,,,,0.02002545455,-0.04044051543
36.245,0.28874,-0.08829,,,,,0.01749939394,-0.04409649386
36.745,0.24683,-0.09322,,,,,0.01495939394,-0.04655878534
37.245,0.20544,-0.09477,,,,,0.01245090909,-0.04733293377
37.745,0.16359,-0.09919,,,,,0.009914545455,-0.04954050544
38.245,0.12194,-0.10261,,,,,0.00739030303,-0.05124862651
38.745,0.0805,-0.10539,,,,,0.004878787879,-0.05263709919
39.245,0.03845,-0.10873,,,,,0.00233030303,-0.05430526421
39.711,-0.00006,-0.11234,,,,,-0.000003636363636,-0.05610828089
40.013,0.0197,-0.09727,,,,,0.001193939394,-0.04858156028
40.513,0.06178,-0.0811,,,,,0.003744242424,-0.04050544401
41.013,0.10348,-0.067,,,,,0.006271515152,-0.03346319049
41.513,0.14486,-0.05676,,,,,0.008779393939,-0.0283488163
42.013,0.18692,-0.04627,,,,,0.01132848485,-0.02310957946
42.513,0.22823,-0.0364,,,,,0.01383212121,-0.018180002
43.013,0.27012,-0.02751,,,,,0.01637090909,-0.01373988613
43.513,0.31181,-0.01934,,,,,0.01889757576,-0.009659374688
44.013,0.35298,-0.01237,,,,,0.02139272727,-0.006178203976
44.513,0.39521,-0.0024,,,,,0.02395212121,-0.00119868145
45.013,0.43681,0.00607,,,,,0.02647333333,0.003031665168
45.513,0.47807,0.01267,,,,,0.02897393939,0.006328039157
46.013,0.52009,0.01977,,,,,0.03152060606,0.009874138448
46.513,0.56172,0.02766,,,,,0.03404363636,0.01381480372
47.013,0.60328,0.03452,,,,,0.03656242424,0.01724103486
47.513,0.64523,0.0408,,,,,0.03910484848,0.02037758466
48.013,0.68647,0.04802,,,,,0.04160424242,0.02398361802
48.513,0.72853,0.05555,,,,,0.04415333333,0.02774448107
49.013,0.77014,0.0621,,,,,0.04667515152,0.03101588253
49.513,0.81145,0.06949,,,,,0.04917878788,0.0347068225
50.013,0.85358,0.07652,,,,,0.05173212121,0.03821796024
50.513,0.89502,0.08425,,,,,0.05424363636,0.04207871342
51.013,0.93663,0.0912,,,,,0.05676545455,0.04554989512
51.513,0.97856,0.0971,,,,,0.05930666667,0.04849665368
52.013,1.01982,0.1063,,,,,0.06180727273,0.05309159924
52.513,1.0617,0.11319,,,,,0.06434545455,0.0565328139
53.013,1.10353,0.12082,,,,,0.06688060606,0.06034362202
53.513,1.14472,0.12631,,,,,0.0693769697,0.06308560583
54.013,1.18688,0.13408,,,,,0.07193212121,0.06696633703
54.513,1.2285,0.14351,,,,,0.07445454545,0.07167615623
55.013,1.26987,0.14933,,,,,0.07696181818,0.07458295875
55.513,1.31192,0.15692,,,,,0.07951030303,0.07837378883
56.013,1.35339,0.1666,,,,,0.08202363636,0.08320847068
56.513,1.39508,0.17187,,,,,0.08455030303,0.08584057537
57.013,1.4368,0.17966,,,,,0.08707878788,0.08973129557
57.513,1.47813,0.18861,,,,,0.08958363636,0.09420137848
58.013,1.52023,0.19603,,,,,0.09213515152,0.09790730197
58.513,1.56171,0.20354,,,,,0.09464909091,0.101658176
59.013,1.60308,0.21058,,,,,0.09715636364,0.1051743083
59.513,1.64526,0.21844,,,,,0.09971272727,0.10909999
59.779,1.63908,0.19201,,,,,0.09933818182,0.09589951054
60.279,1.59718,0.15537,,,,,0.09679878788,0.0775996404
60.779,1.55523,0.13159,,,,,0.09425636364,0.06572270502
61.279,1.51375,0.11032,,,,,0.09174242424,0.05509939067
61.779,1.47197,0.09658,,,,,0.08921030303,0.04823693937
62.279,1.43034,0.08339,,,,,0.08668727273,0.0416491859
62.779,1.38881,0.07141,,,,,0.08417030303,0.03566576766
63.279,1.34677,0.05977,,,,,0.08162242424,0.02985216262
63.779,1.30547,0.04857,,,,,0.07911939394,0.02425831585
64.279,1.26375,0.04077,,,,,0.07659090909,0.02036260114
64.779,1.2218,0.03117,,,,,0.07404848485,0.01556787534
65.279,1.18045,0.02255,,,,,0.07154242424,0.01126261113
65.779,1.1387,0.01482,,,,,0.06901212121,0.007401857956
66.279,1.09692,0.00944,,,,,0.06648,0.004714813705
66.779,1.05556,0.00104,,,,,0.06397333333,0.0005194286285
67.279,1.01355,-0.00609,,,,,0.06142727273,-0.00304165418
67.779,0.97208,-0.01278,,,,,0.05891393939,-0.006382978723
68.279,0.93059,-0.01724,,,,,0.05639939394,-0.008610528419
68.779,0.88843,-0.02443,,,,,0.05384424242,-0.01220157826
69.279,0.84703,-0.0325,,,,,0.05133515152,-0.01623214464
69.779,0.80541,-0.03727,,,,,0.04881272727,-0.01861452402
70.279,0.76365,-0.04205,,,,,0.04628181818,-0.02100189791
70.779,0.72207,-0.04717,,,,,0.04376181818,-0.02355908501
71.279,0.68021,-0.05258,,,,,0.04122484848,-0.02626111278
71.779,0.63871,-0.05672,,,,,0.03870969697,-0.02832883828
72.279,0.59724,-0.06191,,,,,0.03619636364,-0.03092098691
72.779,0.55505,-0.06896,,,,,0.03363939394,-0.03444211367
73.279,0.51375,-0.07311,,,,,0.03113636364,-0.03651483368
73.779,0.47219,-0.07713,,,,,0.02861757576,-0.03852262511
74.279,0.43014,-0.08215,,,,,0.02606909091,-0.04102986715
74.779,0.38878,-0.0862,,,,,0.02356242424,-0.04305264209
75.279,0.34701,-0.08974,,,,,0.02103090909,-0.04482069723
75.779,0.30533,-0.09542,,,,,0.01850484848,-0.04765757667
76.279,0.26384,-0.09935,,,,,0.01599030303,-0.04962041754
76.779,0.22182,-0.10191,,,,,0.01344363636,-0.05089901109
77.279,0.18037,-0.10797,,,,,0.01093151515,-0.05392568175
77.779,0.1388,-0.11062,,,,,0.008412121212,-0.05524922585
78.279,0.09685,-0.11428,,,,,0.00586969697,-0.05707721506
78.779,0.05539,-0.11712,,,,,0.003356969697,-0.05849565478
79.279,0.01366,-0.12284,,,,,0.0008278787879,-0.06135251224
79.547,0.00238,-0.11981,,,,,0.0001442424242,-0.05983917691
80.047,0.04501,-0.09967,,,,,0.002727878788,-0.04978024173
80.547,0.08673,-0.08476,,,,,0.005256363636,-0.04233343322
81.047,0.12858,-0.07223,,,,,0.007792727273,-0.03607531715
81.547,0.16973,-0.06388,,,,,0.01028666667,-0.0319049046
82.047,0.21194,-0.05366,,,,,0.01284484848,-0.02680051943
82.547,0.2536,-0.04429,,,,,0.01536969697,-0.02212066727
83.047,0.29477,-0.03563,,,,,0.01786484848,-0.01779542503
83.547,0.33696,-0.02763,,,,,0.02042181818,-0.0137998202
84.047,0.37849,-0.01947,,,,,0.02293878788,-0.009724303266
84.547,0.41992,-0.01214,,,,,0.02544969697,-0.006063330337
85.047,0.46193,-0.00493,,,,,0.02799575758,-0.002462291479
85.547,0.50333,0.00252,,,,,0.03050484848,0.001258615523
86.047,0.54515,0.00862,,,,,0.03303939394,0.004305264209
86.547,0.58692,0.01846,,,,,0.03557090909,0.009219858156
87.047,0.62821,0.02466,,,,,0.03807333333,0.0123164519
87.547,0.67028,0.03179,,,,,0.0406230303,0.01587753471
88.047,0.71173,0.03737,,,,,0.04313515152,0.01866446908
88.547,0.75327,0.04476,,,,,0.04565272727,0.02235540905
89.047,0.79524,0.05197,,,,,0.04819636364,0.02595644791
89.547,0.83653,0.05875,,,,,0.05069878788,0.029342723
90.047,0.87848,0.06606,,,,,0.05324121212,0.03299370692
90.547,0.92023,0.07352,,,,,0.05577151515,0.03671960843
91.047,0.96139,0.0799,,,,,0.05826606061,0.03990610329
91.547,1.00358,0.08733,,,,,0.0608230303,0.04361702128
92.047,1.04524,0.09455,,,,,0.06334787879,0.04722305464
92.547,1.08647,0.10014,,,,,0.06584666667,0.05001498352
93.047,1.12868,0.10771,,,,,0.06840484848,0.05379582459
93.547,1.17008,0.11616,,,,,0.07091393939,0.0580161822
94.047,1.21174,0.1228,,,,,0.07343878788,0.06133253421
94.547,1.25352,0.12971,,,,,0.07597090909,0.06478373789
95.047,1.29488,0.13805,,,,,0.07847757576,0.06894915593
95.547,1.33692,0.14693,,,,,0.08102545455,0.07338427729
96.047,1.37851,0.15398,,,,,0.08354606061,0.07690540406
96.547,1.41979,0.16065,,,,,0.08604787879,0.08023673959
97.047,1.46195,0.16904,,,,,0.0886030303,0.08442713016
97.547,1.50344,0.17938,,,,,0.09111757576,0.08959144941
98.047,1.54489,0.1843,,,,,0.09362969697,0.09204874638
98.547,1.58702,0.19297,,,,,0.0961830303,0.09637898312
99.047,1.62825,0.20205,,,,,0.09868181818,0.1009139946
99.312,1.6502,0.20601,,,,,0.1000121212,0.102891819
99.812,1.61372,0.15692,,,,,0.09780121212,0.07837378883
100.312,1.57219,0.12933,,,,,0.09528424242,0.06459394666
100.812,1.53018,0.10914,,,,,0.09273818182,0.05451003896
101.312,1.4888,0.09296,,,,,0.09023030303,0.04642892818
101.812,1.44724,0.07958,,,,,0.08771151515,0.03974627909
102.312,1.40508,0.0656,,,,,0.08515636364,0.03276395964
102.812,1.36388,0.05509,,,,,0.08265939394,0.02751473379
103.312,1.3221,0.04571,,,,,0.08012727273,0.02282988712
103.812,1.28026,0.0355,,,,,0.07759151515,0.01773049645
104.312,1.23884,0.02659,,,,,0.07508121212,0.01328039157
104.812,1.19701,0.01959,,,,,0.07254606061,0.009784237339
105.312,1.15533,0.01311,,,,,0.07002,0.006547797423
105.812,1.11393,0.00368,,,,,0.06751090909,0.001837978224
106.312,1.07182,-0.00419,,,,,0.06495878788,-0.002092698032
106.812,1.03042,-0.00838,,,,,0.06244969697,-0.004185396064
107.312,0.98884,-0.01564,,,,,0.05992969697,-0.007811407452
107.812,0.94692,-0.02362,,,,,0.05738909091,-0.01179702327
108.312,0.90543,-0.02787,,,,,0.05487454545,-0.01391968834
108.812,0.86357,-0.03335,,,,,0.05233757576,-0.01665667765
109.312,0.82215,-0.03762,,,,,0.04982727273,-0.01878933174
109.812,0.78047,-0.04357,,,,,0.04730121212,-0.02176106283
110.312,0.7385,-0.05037,,,,,0.04475757576,-0.02515732694
110.812,0.69713,-0.05491,,,,,0.04225030303,-0.02742483268
111.312,0.65556,-0.06001,,,,,0.03973090909,-0.02997203077
111.812,0.61347,-0.06606,,,,,0.03718,-0.03299370692
112.312,0.5722,-0.07066,,,,,0.03467878788,-0.0352911797
112.812,0.5304,-0.0745,,,,,0.03214545455,-0.03720907002
113.312,0.48865,-0.07882,,,,,0.02961515152,-0.03936669663
113.812,0.44721,-0.0849,,,,,0.02710363636,-0.04240335631
114.312,0.4052,-0.08666,,,,,0.02455757576,-0.04328238937
114.812,0.36371,-0.09341,,,,,0.0220430303,-0.04665368095
115.312,0.32221,-0.09842,,,,,0.01952787879,-0.04915592848
115.812,0.28021,-0.10304,,,,,0.01698242424,-0.05146339027
116.312,0.23869,-0.1058,,,,,0.01446606061,-0.05284187394
116.812,0.19711,-0.11041,,,,,0.01194606061,-0.05514434122
117.312,0.15526,-0.11424,,,,,0.00940969697,-0.05705723704
117.812,0.11389,-0.1165,,,,,0.006902424242,-0.05818599541
118.312,0.07191,-0.12081,,,,,0.004358181818,-0.06033862751
118.812,0.03048,-0.12451,,,,,0.001847272727,-0.06218659475
119.18,-0.00012,-0.12746,,,,,-0.000007272727273,-0.06365997403
119.581,0.02853,-0.11069,,,,,0.001729090909,-0.05528418739
120.081,0.07013,-0.09779,,,,,0.00425030303,-0.0488412746
120.581,0.11137,-0.08384,,,,,0.00674969697,-0.04187393867
121.081,0.15357,-0.07197,,,,,0.009307272727,-0.03594545999
121.581,0.19512,-0.06529,,,,,0.01182545455,-0.03260912996
122.081,0.23647,-0.05373,,,,,0.01433151515,-0.02683548097
122.581,0.27849,-0.04714,,,,,0.01687818182,-0.02354410149
123.081,0.31995,-0.0395,,,,,0.01939090909,-0.01972829887
123.581,0.36174,-0.03068,,,,,0.02192363636,-0.01532314454
124.081,0.40352,-0.02419,,,,,0.02445575758,-0.01208171012
124.581,0.44471,-0.01427,,,,,0.02695212121,-0.007127160124
125.081,0.48684,-0.01047,,,,,0.02950545455,-0.005229247827
125.581,0.5285,-0.00063,,,,,0.03203030303,-0.0003146538807
126.081,0.56982,0.00482,,,,,0.03453454545,0.002407351913
126.581,0.61191,0.01051,,,,,0.03708545455,0.005249225852
127.081,0.65329,0.01969,,,,,0.03959333333,0.009834182399
127.581,0.69504,0.02735,,,,,0.04212363636,0.01365997403
128.081,0.7369,0.03335,,,,,0.04466060606,0.01665667765
128.581,0.77807,0.04258,,,,,0.04715575758,0.02126660673
129.081,0.82013,0.04828,,,,,0.04970484848,0.02411347518
129.581,0.86187,0.05448,,,,,0.05223454545,0.02721006892
130.081,0.90311,0.06367,,,,,0.05473393939,0.03180001998
130.581,0.94523,0.07352,,,,,0.05728666667,0.03671960843
131.081,0.98679,0.07484,,,,,0.05980545455,0.03737888323
131.581,1.02823,0.08165,,,,,0.0623169697,0.04078014184
132.081,1.07023,0.09103,,,,,0.06486242424,0.04546498851
132.581,1.11155,0.09651,,,,,0.06736666667,0.04820197782
133.081,1.15346,0.10395,,,,,0.06990666667,0.05191789032
133.581,1.19509,0.11163,,,,,0.07242969697,0.05575367096
134.081,1.23643,0.11874,,,,,0.07493515152,0.05930476476
134.581,1.27855,0.12519,,,,,0.07748787879,0.06252622116
135.081,1.31994,0.13324,,,,,0.07999636364,0.06654679852
135.581,1.36153,0.14055,,,,,0.0825169697,0.07019778244
136.081,1.40358,0.15091,,,,,0.08506545455,0.0753720907
136.581,1.44485,0.15793,,,,,0.08756666667,0.07887823394
137.081,1.48675,0.16404,,,,,0.09010606061,0.08192987714
137.581,1.52855,0.172,,,,,0.09263939394,0.08590550395
138.081,1.5697,0.17999,,,,,0.09513333333,0.08989611427
138.581,1.61187,0.18897,,,,,0.09768909091,0.0943811807
139.045,1.65006,0.19731,,,,,0.1000036364,0.09854659874
139.347,1.63069,0.1617,,,,,0.09882969697,0.08076116272
139.847,1.58853,0.13227,,,,,0.09627454545,0.06606233144
140.347,1.54723,0.11003,,,,,0.09377151515,0.05495455
140.847,1.50547,0.09281,,,,,0.09124060606,0.04635401059
141.347,1.46363,0.07824,,,,,0.08870484848,0.03907701528
141.847,1.42228,0.0662,,,,,0.08619878788,0.03306363001
142.347,1.3803,0.05508,,,,,0.08365454545,0.02750973929
142.847,1.33871,0.04431,,,,,0.08113393939,0.02213065628
143.347,1.2973,0.03292,,,,,0.07862424242,0.01644191389
143.847,1.25522,0.02729,,,,,0.07607393939,0.01363000699
144.347,1.2138,0.01868,,,,,0.07356363636,0.009329737289
144.847,1.17223,0.00755,,,,,0.07104424242,0.003770852063
145.347,1.13024,0.00088,,,,,0.06849939394,0.0004395165318
145.847,1.08879,-0.0044,,,,,0.06598727273,-0.002197582659
146.347,1.04708,-0.01115,,,,,0.06345939394,-0.005568874238
146.847,1.00544,-0.01869,,,,,0.06093575758,-0.009334731795
147.347,0.96392,-0.02403,,,,,0.05841939394,-0.01200179802
147.847,0.92185,-0.02881,,,,,0.05586969697,-0.01438917191
148.347,0.88053,-0.03622,,,,,0.05336545455,-0.01809010089
148.847,0.83895,-0.04247,,,,,0.05084545455,-0.02121166717
149.347,0.79681,-0.0465,,,,,0.04829151515,-0.0232244531
149.847,0.75547,-0.05082,,,,,0.04578606061,-0.02538207971
150.347,0.71386,-0.05703,,,,,0.04326424242,-0.02848366797
150.847,0.67194,-0.0623,,,,,0.04072363636,-0.03111577265
151.347,0.63053,-0.06669,,,,,0.03821393939,-0.0333083608
151.847,0.58862,-0.07243,,,,,0.03567393939,-0.03617520727
152.347,0.54707,-0.07479,,,,,0.03315575758,-0.0373539107
152.847,0.50559,-0.08326,,,,,0.03064181818,-0.04158425732
153.347,0.46351,-0.0849,,,,,0.02809151515,-0.04240335631
153.847,0.42215,-0.08865,,,,,0.02558484848,-0.04427629607
154.347,0.38049,-0.09526,,,,,0.02306,-0.04757766457
154.847,0.33873,-0.09913,,,,,0.02052909091,-0.04951053841
155.347,0.29712,-0.1015,,,,,0.01800727273,-0.05069423634
155.847,0.25534,-0.10544,,,,,0.01547515152,-0.05266207172
156.347,0.21376,-0.11203,,,,,0.01295515152,-0.0559534512
156.847,0.1723,-0.11383,,,,,0.01044242424,-0.05685246229
157.347,0.13009,-0.11678,,,,,0.007884242424,-0.05832584157
157.847,0.08887,-0.12177,,,,,0.005386060606,-0.06081810009
158.347,0.04723,-0.12528,,,,,0.002862424242,-0.06257117171
158.847,0.00519,-0.12846,,,,,0.0003145454545,-0.06415942463
159.116,0.01141,-0.12032,,,,,0.0006915151515,-0.06009389671
159.616,0.05311,-0.10518,,,,,0.003218787879,-0.05253221456
160.116,0.09527,-0.09403,,,,,0.005773939394,-0.04696334033
160.616,0.1367,-0.08111,,,,,0.008284848485,-0.04051043852
161.116,0.17836,-0.07133,,,,,0.01080969697,-0.03562581161
161.616,0.22015,-0.06083,,,,,0.01334242424,-0.03038158026
162.116,0.26154,-0.05559,,,,,0.01585090909,-0.02776445909
162.616,0.30347,-0.04749,,,,,0.01839212121,-0.0237189092
163.116,0.34525,-0.03779,,,,,0.02092424242,-0.01887423834
163.616,0.38649,-0.03103,,,,,0.02342363636,-0.01549795225
164.116,0.42862,-0.02426,,,,,0.0259769697,-0.01211667166
164.616,0.47002,-0.01866,,,,,0.02848606061,-0.009319748277
165.116,0.51171,-0.013,,,,,0.03101272727,-0.006492857856
165.616,0.55356,-0.00005,,,,,0.03354909091,-0.00002497253022
166.116,0.59486,0.00421,,,,,0.03605212121,0.002102687044
166.616,0.6369,0.00986,,,,,0.0386,0.004924582959
167.116,0.67856,0.01834,,,,,0.04112484848,0.009159924084
167.616,0.71976,0.02398,,,,,0.04362181818,0.01197682549
168.116,0.76181,0.03103,,,,,0.04617030303,0.01549795225
168.616,0.80346,0.0368,,,,,0.04869454545,0.01837978224
169.116,0.84483,0.04534,,,,,0.05120181818,0.0226450904
169.616,0.88697,0.04995,,,,,0.05375575758,0.02494755769
170.116,0.92824,0.05935,,,,,0.0562569697,0.02964239337
170.616,0.97017,0.06491,,,,,0.05879818182,0.03241933873
171.116,1.01183,0.07482,,,,,0.0613230303,0.03736889422
171.616,1.05315,0.07977,,,,,0.06382727273,0.03984117471
172.116,1.09527,0.08748,,,,,0.06638,0.04369193887
172.616,1.13686,0.09394,,,,,0.06890060606,0.04691838977
173.116,1.17821,0.09913,,,,,0.07140666667,0.04951053841
173.616,1.22027,0.10906,,,,,0.07395575758,0.05447008291
174.116,1.26169,0.11834,,,,,0.07646606061,0.05910498452
174.616,1.30334,0.12145,,,,,0.07899030303,0.0606582759
175.116,1.34529,0.13095,,,,,0.08153272727,0.06540305664
175.616,1.38644,0.14287,,,,,0.08402666667,0.07135650784
176.116,1.42858,0.14472,,,,,0.08658060606,0.07228049146
176.616,1.47019,0.1569,,,,,0.08910242424,0.07836379982
177.116,1.51151,0.1617,,,,,0.09160666667,0.08076116272
177.616,1.55356,0.17356,,,,,0.09415515152,0.08668464689
178.116,1.59517,0.18117,,,,,0.0966769697,0.09048546599
178.616,1.63664,0.18721,,,,,0.09919030303,0.09350214764
178.882,1.64791,0.18019,,,,,0.09987333333,0.0899960044
179.382,1.60577,0.1369,,,,,0.09731939394,0.06837478773
179.882,1.56381,0.11489,,,,,0.09477636364,0.05738187993
180.382,1.52218,0.09312,,,,,0.09225333333,0.04650884028
180.882,1.48074,0.08388,,,,,0.08974181818,0.04189391669
181.382,1.43875,0.06845,,,,,0.0871969697,0.03418739387
181.882,1.39719,0.05563,,,,,0.08467818182,0.02778443712
182.382,1.35578,0.04459,,,,,0.08216848485,0.02227050245
182.882,1.31371,0.03685,,,,,0.07961878788,0.01840475477
183.382,1.2723,0.02736,,,,,0.07710909091,0.01366496853
183.882,1.23063,0.01793,,,,,0.07458363636,0.008955149336
184.382,1.1889,0.01014,,,,,0.07205454545,0.005064429128
184.882,1.1474,0.0028,,,,,0.06953939394,0.001398461692
185.382,1.10539,-0.00412,,,,,0.06699333333,-0.00205773649
185.882,1.06407,-0.01012,,,,,0.06448909091,-0.005054440116
186.382,1.02232,-0.01653,,,,,0.06195878788,-0.00825591849
186.882,0.98033,-0.02397,,,,,0.05941393939,-0.01197183099
187.382,0.939,-0.02957,,,,,0.05690909091,-0.01476875437
187.882,0.89727,-0.03717,,,,,0.05438,-0.01856457896
188.382,0.85541,-0.04093,,,,,0.0518430303,-0.02044251324
188.882,0.81408,-0.04746,,,,,0.04933818182,-0.02370392568
189.382,0.77212,-0.05213,,,,,0.04679515152,-0.02603636
189.882,0.73059,-0.05934,,,,,0.04427818182,-0.02963739886
190.382,0.68915,-0.06312,,,,,0.04176666667,-0.03152532215
190.882,0.64702,-0.06667,,,,,0.03921333333,-0.03329837179
191.382,0.6056,-0.07352,,,,,0.0367030303,-0.03671960843
191.882,0.56406,-0.07758,,,,,0.03418545455,-0.03874737788
192.382,0.52215,-0.08162,,,,,0.03164545455,-0.04076515833
192.882,0.48061,-0.08543,,,,,0.02912787879,-0.04266806513
193.382,0.43884,-0.09257,,,,,0.02659636364,-0.04623414244
193.882,0.39724,-0.09523,,,,,0.02407515152,-0.04756268105
194.382,0.35579,-0.09908,,,,,0.0215630303,-0.04948556588
194.882,0.31363,-0.10303,,,,,0.01900787879,-0.05145839576
195.382,0.27231,-0.11143,,,,,0.01650363636,-0.05565378084
195.882,0.2308,-0.11136,,,,,0.01398787879,-0.0556188193
196.382,0.18867,-0.11365,,,,,0.01143454545,-0.05676256118
196.882,0.14732,-0.11842,,,,,0.008928484848,-0.05914494057
197.382,0.1056,-0.12323,,,,,0.0064,-0.06154729797
197.882,0.06386,-0.12428,,,,,0.00387030303,-0.06207172111
198.382,0.02235,-0.12945,,,,,0.001354545455,-0.06465388073
198.653,-0.0002,-0.12879,,,,,-0.00001212121212,-0.06432424333
199.153,0.03678,-0.11575,,,,,0.002229090909,-0.05781140745
199.653,0.07816,-0.09791,,,,,0.004736969697,-0.04890120867
200.153,0.12012,-0.08743,,,,,0.00728,-0.04366696634
200.653,0.16183,-0.07838,,,,,0.009807878788,-0.03914693837
201.153,0.20311,-0.0703,,,,,0.01230969697,-0.03511137748
201.653,0.24524,-0.05961,,,,,0.0148630303,-0.02977225052
202.153,0.28677,-0.05107,,,,,0.01738,-0.02550694236
202.653,0.32827,-0.0436,,,,,0.01989515152,-0.02177604635
203.153,0.37021,-0.0387,,,,,0.0224369697,-0.01932873839
203.653,0.41155,-0.03111,,,,,0.02494242424,-0.0155379083
204.153,0.45349,-0.02068,,,,,0.02748424242,-0.0103286385
204.653,0.4952,-0.01542,,,,,0.03001212121,-0.007701528319
205.153,0.53637,-0.01024,,,,,0.03250727273,-0.005114374188
205.653,0.57851,-0.00235,,,,,0.03506121212,-0.00117370892
206.153,0.62008,0.00427,,,,,0.03758060606,0.002132654081
206.653,0.66147,0.01136,,,,,0.04008909091,0.005673758865
207.153,0.70353,0.01726,,,,,0.04263818182,0.008620517431
207.653,0.74503,0.0243,,,,,0.04515333333,0.01213664969
208.153,0.7867,0.03018,,,,,0.04767878788,0.01507341924
208.653,0.82854,0.03678,,,,,0.05021454545,0.01836979323
209.153,0.86988,0.04434,,,,,0.05272,0.0221456398
209.653,0.91194,0.05156,,,,,0.05526909091,0.02575167316
210.153,0.95346,0.05872,,,,,0.05778545455,0.02932773949
210.653,0.99482,0.06453,,,,,0.06029212121,0.0322295475
211.153,1.03689,0.07223,,,,,0.06284181818,0.03607531715
211.653,1.07826,0.07616,,,,,0.06534909091,0.03803815803
212.153,1.12001,0.08543,,,,,0.06787939394,0.04266806513
212.653,1.16184,0.09138,,,,,0.07041454545,0.04563979622
213.153,1.20311,0.10063,,,,,0.07291575758,0.05025971431
213.653,1.24509,0.10687,,,,,0.07546,0.05337628609
214.153,1.28687,0.11275,,,,,0.07799212121,0.05631305564
214.653,1.32805,0.12342,,,,,0.08048787879,0.06164219359
215.153,1.37023,0.13102,,,,,0.08304424242,0.06543801818
215.653,1.4118,0.13725,,,,,0.08556363636,0.06854959545
216.153,1.4532,0.1449,,,,,0.08807272727,0.07237039257
216.653,1.49519,0.15463,,,,,0.09061757576,0.07723004695
217.153,1.53662,0.16144,,,,,0.09312848485,0.08063130556
217.653,1.57851,0.17024,,,,,0.09566727273,0.08502647088
218.153,1.62015,0.17887,,,,,0.09819090909,0.0893367296
218.518,1.65017,0.18663,,,,,0.100010303,0.09321246629
218.919,1.62187,0.14438,,,,,0.09829515152,0.07211067825
219.419,1.58049,0.11669,,,,,0.09578727273,0.05828089102
219.919,1.53901,0.09796,,,,,0.09327333333,0.0489261812
220.419,1.49693,0.08376,,,,,0.0907230303,0.04183398262
220.919,1.45549,0.06793,,,,,0.08821151515,0.03392767955
221.419,1.41392,0.0573,,,,,0.08569212121,0.02861851963
221.919,1.37203,0.04471,,,,,0.08315333333,0.02233043652
222.419,1.33054,0.03531,,,,,0.08063878788,0.01763560084
222.919,1.28865,0.02809,,,,,0.0781,0.01402956748
223.419,1.24716,0.01874,,,,,0.07558545455,0.009359704325
223.919,1.20561,0.01017,,,,,0.07306727273,0.005079412646
224.419,1.16344,0.00346,,,,,0.07051151515,0.001728099091
224.919,1.12222,-0.00416,,,,,0.06801333333,-0.002077714514
225.419,1.08053,-0.01311,,,,,0.06548666667,-0.006547797423
225.919,1.03854,-0.01822,,,,,0.06294181818,-0.009099990011
226.419,0.99715,-0.02311,,,,,0.06043333333,-0.01154230347
226.919,0.95546,-0.02886,,,,,0.05790666667,-0.01441414444
227.419,0.91369,-0.03632,,,,,0.05537515152,-0.01814004595
227.919,0.87231,-0.04124,,,,,0.05286727273,-0.02059734292
228.419,0.83027,-0.04663,,,,,0.05031939394,-0.02328938168
228.919,0.78882,-0.05207,,,,,0.04780727273,-0.02600639297
229.419,0.74733,-0.0571,,,,,0.04529272727,-0.02851862951
229.919,0.70525,-0.06147,,,,,0.04274242424,-0.03070122865
230.419,0.66382,-0.06711,,,,,0.04023151515,-0.03351813006
230.919,0.62204,-0.0745,,,,,0.03769939394,-0.03720907002
231.419,0.58048,-0.07596,,,,,0.03518060606,-0.03793826791
231.919,0.53879,-0.08,,,,,0.03265393939,-0.03995604835
232.419,0.49693,-0.08517,,,,,0.0301169697,-0.04253820797
232.919,0.45543,-0.0902,,,,,0.02760181818,-0.04505044451
233.419,0.41397,-0.09562,,,,,0.02508909091,-0.04775746679
233.919,0.37177,-0.09782,,,,,0.02253151515,-0.04885625812
234.419,0.33057,-0.10368,,,,,0.02003454545,-0.05178303866
234.919,0.28886,-0.10717,,,,,0.01750666667,-0.05352612127
235.419,0.24698,-0.11169,,,,,0.01496848485,-0.055783638
235.919,0.20561,-0.11573,,,,,0.01246121212,-0.05780141844
236.419,0.16369,-0.1181,,,,,0.009920606061,-0.05898511637
236.919,0.1221,-0.12289,,,,,0.0074,-0.06137748477
237.419,0.08065,-0.12671,,,,,0.004887878788,-0.06328538608
237.919,0.03858,-0.12911,,,,,0.002338181818,-0.06448406753
238.387,-0.00009,-0.13275,,,,,-0.000005454545455,-0.06630206773
238.689,0.01964,-0.12018,,,,,0.00119030303,-0.06002397363
239.189,0.06173,-0.10772,,,,,0.003741212121,-0.0538008191
239.689,0.10343,-0.09585,,,,,0.006268484848,-0.04787234043
240.189,0.14483,-0.08615,,,,,0.008777575758,-0.04302766956
240.689,0.18688,-0.07486,,,,,0.01132606061,-0.03738887224
241.189,0.22816,-0.06584,,,,,0.01382787879,-0.03288382779
241.689,0.27007,-0.05906,,,,,0.01636787879,-0.02949755269
242.189,0.31177,-0.05125,,,,,0.01889515152,-0.02559684347
242.689,0.35299,-0.0428,,,,,0.02139333333,-0.02137648587
243.189,0.39513,-0.03655,,,,,0.02394727273,-0.01825491959
243.689,0.43675,-0.0278,,,,,0.02646969697,-0.0138847268
244.189,0.47805,-0.02132,,,,,0.02897272727,-0.01064828688
244.689,0.52007,-0.01538,,,,,0.03151939394,-0.007681550295
245.189,0.56167,-0.00835,,,,,0.03404060606,-0.004170412546
245.689,0.60325,-0.00122,,,,,0.03656060606,-0.0006093297373
246.189,0.64518,0.00633,,,,,0.03910181818,0.003161522325
246.689,0.68637,0.01212,,,,,0.04159818182,0.006053341325
247.189,0.72854,0.01815,,,,,0.04415393939,0.009065028469
247.689,0.77009,0.02607,,,,,0.04667212121,0.01302067726
248.189,0.8114,0.03163,,,,,0.04917575758,0.01579762262
248.689,0.85353,0.03776,,,,,0.05172909091,0.01885925482
249.189,0.895,0.04652,,,,,0.05424242424,0.02323444211
249.689,0.93653,0.05116,,,,,0.05675939394,0.02555189292
250.189,0.97852,0.05857,,,,,0.05930424242,0.0292528219
250.689,1.01974,0.06525,,,,,0.06180242424,0.03258915193
251.189,1.06167,0.07093,,,,,0.06434363636,0.03542603137
251.689,1.10351,0.08096,,,,,0.06687939394,0.04043552093
252.189,1.14471,0.08469,,,,,0.06937636364,0.04229847168
252.689,1.18684,0.09437,,,,,0.07192969697,0.04713315353
253.189,1.22843,0.10006,,,,,0.07445030303,0.04997502747
253.689,1.26987,0.10853,,,,,0.07696181818,0.05420537409
254.189,1.31185,0.11433,,,,,0.07950606061,0.05710218759
254.689,1.35331,0.12173,,,,,0.08201878788,0.06079812207
255.189,1.39505,0.12866,,,,,0.08454848485,0.06425931475
255.689,1.43677,0.13739,,,,,0.0870769697,0.06861951853
256.189,1.47809,0.14651,,,,,0.08958121212,0.07317450804
256.689,1.52016,0.15543,,,,,0.09213090909,0.07762960743
257.189,1.56168,0.16304,,,,,0.09464727273,0.08143042653
257.689,1.60302,0.16947,,,,,0.09715272727,0.08464189392
258.189,1.6452,0.17759,,,,,0.09970909091,0.08869743282
258.455,1.63913,0.16184,,,,,0.09934121212,0.08083108581
258.955,1.5972,0.13357,,,,,0.0968,0.06671161722
259.455,1.55525,0.09942,,,,,0.09425757576,0.04965537908
259.955,1.51377,0.08465,,,,,0.09174363636,0.04227849366
260.455,1.47201,0.07152,,,,,0.08921272727,0.03572070722
260.955,1.43038,0.05854,,,,,0.08668969697,0.02923783838
261.455,1.38882,0.04853,,,,,0.08417090909,0.02423833783
261.955,1.34679,0.03905,,,,,0.08162363636,0.0195035461
262.455,1.30549,0.03085,,,,,0.07912060606,0.01540805114
262.955,1.26378,0.01954,,,,,0.07659272727,0.009759264809
263.455,1.22183,0.01151,,,,,0.07405030303,0.005748676456
263.955,1.18047,0.00347,,,,,0.07154363636,0.001733093597
264.455,1.13872,-0.0035,,,,,0.06901333333,-0.001748077115
264.955,1.09694,-0.01096,,,,,0.06648121212,-0.005473978624
265.455,1.05556,-0.01538,,,,,0.06397333333,-0.007681550295
265.955,1.01357,-0.01916,,,,,0.06142848485,-0.009569473579
266.455,0.9721,-0.02936,,,,,0.05891515152,-0.01466386974
266.955,0.93062,-0.0362,,,,,0.05640121212,-0.01808011188
267.455,0.88845,-0.04492,,,,,0.05384545455,-0.02243532115
267.955,0.84705,-0.04734,,,,,0.05133636364,-0.02364399161
268.455,0.80545,-0.05295,,,,,0.04881515152,-0.0264459095
268.955,0.76364,-0.0579,,,,,0.04628121212,-0.02891818999
269.455,0.72209,-0.06343,,,,,0.0437630303,-0.03168015183
269.955,0.68021,-0.0652,,,,,0.04122484848,-0.0325641794
270.455,0.63873,-0.07286,,,,,0.03871090909,-0.03638997103
270.955,0.59725,-0.07802,,,,,0.0361969697,-0.03896713615
271.455,0.55509,-0.0839,,,,,0.03364181818,-0.0419039057
271.955,0.51375,-0.08252,,,,,0.03113636364,-0.04121466387
272.455,0.47224,-0.09225,,,,,0.02862060606,-0.04607431825
272.955,0.43015,-0.09729,,,,,0.02606969697,-0.0485915493
273.455,0.3888,-0.09719,,,,,0.02356363636,-0.04854160424
273.955,0.34705,-0.1034,,,,,0.02103333333,-0.05164319249
274.455,0.30534,-0.10833,,,,,0.01850545455,-0.05410548397
274.955,0.26383,-0.11136,,,,,0.01598969697,-0.0556188193
275.455,0.22182,-0.11367,,,,,0.01344363636,-0.05677255019
275.955,0.1804,-0.11969,,,,,0.01093333333,-0.05977924283
276.455,0.13882,-0.12266,,,,,0.008413333333,-0.06126261113
276.955,0.09688,-0.12613,,,,,0.005871515152,-0.06299570472
277.455,0.05541,-0.13061,,,,,0.003358181818,-0.06523324343
277.955,0.01367,-0.13204,,,,,0.0008284848485,-0.0659474578
278.224,0.00232,-0.13199,,,,,0.0001406060606,-0.06592248527
278.724,0.04484,-0.11581,,,,,0.002717575758,-0.05784137449
279.224,0.08661,-0.10364,,,,,0.005249090909,-0.05176306063
279.724,0.12843,-0.09136,,,,,0.007783636364,-0.04562980721
280.224,0.16961,-0.08194,,,,,0.01027939394,-0.04092498252
280.724,0.21176,-0.07344,,,,,0.01283393939,-0.03667965238
281.224,0.25352,-0.06511,,,,,0.01536484848,-0.03251922885
281.724,0.29464,-0.05765,,,,,0.0178569697,-0.02879332734
282.224,0.33681,-0.04864,,,,,0.02041272727,-0.02429327739
282.724,0.37836,-0.04144,,,,,0.02293090909,-0.02069723304
283.224,0.41983,-0.03546,,,,,0.02544424242,-0.01771051843
283.724,0.46168,-0.02773,,,,,0.02798060606,-0.01384976526
284.224,0.50319,-0.02044,,,,,0.03049636364,-0.01020877035
284.724,0.54502,-0.01405,,,,,0.03303151515,-0.007017280991
285.224,0.58678,-0.00802,,,,,0.03556242424,-0.004005593847
285.724,0.62807,-0.00123,,,,,0.03806484848,-0.0006143242433
286.224,0.67015,0.0051,,,,,0.04061515152,0.002547198082
286.724,0.7116,0.01277,,,,,0.04312727273,0.006377984217
287.224,0.75312,0.01919,,,,,0.04564363636,0.009584457097
287.724,0.79513,0.02578,,,,,0.04818969697,0.01287583658
288.224,0.83636,0.03258,,,,,0.05068848485,0.01627210069
288.724,0.87838,0.03823,,,,,0.05323515152,0.0190939966
289.224,0.92009,0.04583,,,,,0.0557630303,0.0228898212
289.724,0.96131,0.05195,,,,,0.05826121212,0.0259464589
290.224,1.00333,0.05837,,,,,0.06080787879,0.02915293178
290.724,1.04511,0.06635,,,,,0.06334,0.0331385476
291.224,1.08633,0.07336,,,,,0.06583818182,0.03663969633
291.724,1.12853,0.08036,,,,,0.06839575758,0.04013585056
292.224,1.1699,0.08748,,,,,0.0709030303,0.04369193887
292.724,1.21161,0.09323,,,,,0.07343090909,0.04656377984
293.224,1.25338,0.10162,,,,,0.07596242424,0.05075417041
293.724,1.29472,0.10903,,,,,0.07846787879,0.05445509939
294.224,1.33684,0.11558,,,,,0.08102060606,0.05772650085
294.724,1.37834,0.12366,,,,,0.08353575758,0.06176206173
295.224,1.41968,0.132,,,,,0.08604121212,0.06592747977
295.724,1.46182,0.14041,,,,,0.08859515152,0.07012785935
296.224,1.50327,0.14726,,,,,0.09110727273,0.07354909599
296.724,1.54477,0.15609,,,,,0.09362242424,0.07795924483
297.224,1.58686,0.16596,,,,,0.09617333333,0.0828888223
297.724,1.62812,0.17433,,,,,0.09867393939,0.08706922385
297.991,1.65024,0.1765,,,,,0.1000145455,0.08815303167
298.491,1.61387,0.13352,,,,,0.09781030303,0.06668664469
298.991,1.57234,0.10875,,,,,0.09529333333,0.05431525322
299.491,1.53031,0.08934,,,,,0.09274606061,0.04462091699
299.991,1.48895,0.0765,,,,,0.09023939394,0.03820797123
300.491,1.44738,0.06268,,,,,0.08772,0.03130556388
300.991,1.40524,0.04971,,,,,0.08516606061,0.02482768954
301.491,1.36405,0.03937,,,,,0.08266969697,0.01966337029
301.991,1.32222,0.03172,,,,,0.08013454545,0.01584257317
302.491,1.28043,0.02371,,,,,0.07760181818,0.01184197383
302.991,1.239,0.01451,,,,,0.07509090909,0.007247028269
303.491,1.19712,0.00679,,,,,0.07255272727,0.003391269603
303.991,1.15548,-0.00048,,,,,0.07002909091,-0.0002397362901
304.491,1.11409,-0.00687,,,,,0.06752060606,-0.003431225652
304.991,1.07198,-0.01492,,,,,0.06496848485,-0.007451803017
305.491,1.03057,-0.02234,,,,,0.06245878788,-0.0111577265
305.991,0.98897,-0.02803,,,,,0.05993757576,-0.01399960044
306.491,0.94709,-0.03371,,,,,0.05739939394,-0.01683647987
306.991,0.90557,-0.03789,,,,,0.0548830303,-0.0189241834
307.491,0.86372,-0.04609,,,,,0.05234666667,-0.02301967835
307.991,0.8223,-0.05045,,,,,0.04983636364,-0.02519728299
308.491,0.78062,-0.05473,,,,,0.04731030303,-0.02733493158
308.991,0.73863,-0.05943,,,,,0.04476545455,-0.02968234942
309.491,0.69729,-0.06552,,,,,0.04226,-0.0327240036
309.991,0.65569,-0.07184,,,,,0.03973878788,-0.03588053142
310.491,0.61364,-0.07647,,,,,0.03719030303,-0.03819298771
310.991,0.57233,-0.0801,,,,,0.03468666667,-0.04000599341
311.491,0.53053,-0.0842,,,,,0.03215333333,-0.04205374089
311.991,0.48882,-0.08993,,,,,0.02962545455,-0.04491559285
312.491,0.44737,-0.09356,,,,,0.02711333333,-0.04672859854
312.991,0.40532,-0.09774,,,,,0.02456484848,-0.04881630207
313.491,0.36386,-0.10217,,,,,0.02205212121,-0.05102886824
313.991,0.32236,-0.10741,,,,,0.0195369697,-0.05364598941
314.491,0.28036,-0.11371,,,,,0.01699151515,-0.05679252822
314.991,0.23884,-0.11444,,,,,0.01447515152,-0.05715712716
315.491,0.19722,-0.11966,,,,,0.01195272727,-0.05976425931
315.991,0.15544,-0.12214,,,,,0.009420606061,-0.06100289681
316.491,0.11405,-0.12566,,,,,0.006912121212,-0.06276096294
316.991,0.07203,-0.13063,,,,,0.004365454545,-0.06524323244
317.491,0.03062,-0.13896,,,,,0.001855757576,-0.06940365598
317.861,-0.00015,-0.13372,,,,,-0.000009090909091,-0.06678653481
318.262,0.0285,-0.1212,,,,,0.001727272727,-0.06053341325
318.762,0.07008,-0.10891,,,,,0.004247272727,-0.05439516532
319.262,0.11133,-0.09862,,,,,0.006747272727,-0.0492558186
319.762,0.15355,-0.08808,,,,,0.009306060606,-0.04399160923
320.262,0.19508,-0.07709,,,,,0.0118230303,-0.03850264709
320.762,0.23647,-0.06807,,,,,0.01433151515,-0.03399760264
321.262,0.27835,-0.06452,,,,,0.01686969697,-0.03222455299
321.762,0.31999,-0.05657,,,,,0.01939333333,-0.02825392069
322.262,0.3617,-0.04728,,,,,0.02192121212,-0.02361402457
322.762,0.40348,-0.03854,,,,,0.02445333333,-0.01924882629
323.262,0.44469,-0.03047,,,,,0.02695090909,-0.01521825991
323.762,0.48684,-0.02697,,,,,0.02950545455,-0.0134701828
324.262,0.52842,-0.02143,,,,,0.03202545455,-0.01070322645
324.762,0.56985,-0.01296,,,,,0.03453636364,-0.006472879832
325.262,0.61187,-0.00602,,,,,0.0370830303,-0.003006692638
325.762,0.65325,0.0015,,,,,0.03959090909,0.0007491759065
326.262,0.695,0.00516,,,,,0.04212121212,0.002577165118
326.762,0.73685,0.01412,,,,,0.04465757576,0.007052242533
327.262,0.77802,0.0213,,,,,0.04715272727,0.01063829787
327.762,0.82006,0.02686,,,,,0.04970060606,0.01341524323
328.262,0.86187,0.03486,,,,,0.05223454545,0.01741084807
328.762,0.90308,0.04108,,,,,0.05473212121,0.02051743083
329.262,0.94515,0.04564,,,,,0.05728181818,0.02279492558
329.762,0.98671,0.05341,,,,,0.05980060606,0.02667565678
330.262,1.02824,0.06509,,,,,0.06231757576,0.03250923984
330.762,1.0701,0.0686,,,,,0.06485454545,0.03426231146
331.262,1.11153,0.07529,,,,,0.06736545455,0.037603636
331.762,1.15345,0.08108,,,,,0.06990606061,0.040495455
332.262,1.19505,0.08844,,,,,0.07242727273,0.04417141145
332.762,1.23637,0.0943,,,,,0.07493151515,0.04709819199
333.262,1.27854,0.10227,,,,,0.07748727273,0.05107881331
333.762,1.31996,0.10933,,,,,0.07999757576,0.05460493457
334.262,1.36145,0.11687,,,,,0.08251212121,0.05837079213
334.762,1.40353,0.12467,,,,,0.08506242424,0.06226650684
335.262,1.44481,0.13374,,,,,0.08756424242,0.06679652382
335.762,1.48668,0.14008,,,,,0.09010181818,0.06996304066
336.262,1.52853,0.14817,,,,,0.09263818182,0.07400359604
336.762,1.56971,0.15786,,,,,0.09513393939,0.0788432724
337.262,1.61186,0.16428,,,,,0.09768848485,0.08204974528
337.727,1.65003,0.17277,,,,,0.1000018182,0.08629008091
338.029,1.631,0.14162,,,,,0.09884848485,0.07073219459
338.529,1.58891,0.11349,,,,,0.09629757576,0.05668264909
339.029,1.5476,0.09526,,,,,0.09379393939,0.04757766457
339.529,1.50578,0.07828,,,,,0.09125939394,0.03909699331
340.029,1.46405,0.06252,,,,,0.08873030303,0.03122565178
340.529,1.42262,0.05158,,,,,0.08621939394,0.02576166217
341.029,1.3806,0.04205,,,,,0.08367272727,0.02100189791
341.529,1.33913,0.03275,,,,,0.08115939394,0.01635700729
342.029,1.29767,0.02382,,,,,0.07864666667,0.0118969134
342.529,1.25558,0.01348,,,,,0.07609575758,0.006732594146
343.029,1.21415,0.00622,,,,,0.07358484848,0.003106582759
343.529,1.17258,-0.00039,,,,,0.07106545455,-0.0001947857357
344.029,1.13064,-0.00775,,,,,0.06852363636,-0.003870742184
344.529,1.08919,-0.01422,,,,,0.06601151515,-0.007102187594
345.029,1.04736,-0.02097,,,,,0.06347636364,-0.01047347917
345.529,1.00585,-0.02617,,,,,0.06096060606,-0.01307062232
346.029,0.96429,-0.03241,,,,,0.05844181818,-0.01618719409
346.529,0.92218,-0.03829,,,,,0.05588969697,-0.01912396364
347.029,0.8809,-0.04416,,,,,0.05338787879,-0.02205573869
347.529,0.83929,-0.04878,,,,,0.05086606061,-0.02436320048
348.029,0.79719,-0.05271,,,,,0.04831454545,-0.02632604135
348.529,0.75582,-0.05833,,,,,0.04580727273,-0.02913295375
349.029,0.71416,-0.06421,,,,,0.04328242424,-0.0320697233
349.529,0.67233,-0.06993,,,,,0.04074727273,-0.03492658076
350.029,0.63092,-0.0726,,,,,0.03823757576,-0.03626011387
350.529,0.58893,-0.07745,,,,,0.03569272727,-0.03868244931
351.029,0.54744,-0.0823,,,,,0.03317818182,-0.04110478474
351.529,0.50595,-0.08906,,,,,0.03066363636,-0.04448107082
352.029,0.46391,-0.09251,,,,,0.02811575758,-0.04620417541
352.529,0.42249,-0.09499,,,,,0.02560545455,-0.04744281291
353.029,0.3808,-0.10097,,,,,0.02307878788,-0.05042952752
353.529,0.33912,-0.10607,,,,,0.02055272727,-0.0529767256
354.029,0.29749,-0.10714,,,,,0.01802969697,-0.05351113775
354.529,0.25566,-0.11072,,,,,0.01549454545,-0.05529917091
355.029,0.21415,-0.11641,,,,,0.01297878788,-0.05814104485
355.529,0.17268,-0.12072,,,,,0.01046545455,-0.06029367696
356.029,0.13043,-0.12488,,,,,0.007904848485,-0.06237139147
356.529,0.08923,-0.12706,,,,,0.005407878788,-0.06346019379
357.029,0.04757,-0.12966,,,,,0.002883030303,-0.06475876536
357.529,0.00561,-0.13461,,,,,0.00034,-0.06723104585
357.803,0.01123,-0.12925,,,,,0.0006806060606,-0.06455399061
358.303,0.05302,-0.11591,,,,,0.003213333333,-0.05789131955
358.803,0.09514,-0.10399,,,,,0.005766060606,-0.05193786834
359.303,0.13654,-0.09298,,,,,0.008275151515,-0.04643891719
359.803,0.17826,-0.08284,,,,,0.01080363636,-0.04137448806
360.303,0.22001,-0.07427,,,,,0.01333393939,-0.03709419638
360.803,0.26137,-0.06773,,,,,0.01584060606,-0.03382778943
361.303,0.30334,-0.05942,,,,,0.01838424242,-0.02967735491
361.803,0.34507,-0.05169,,,,,0.02091333333,-0.02581660174
362.303,0.38641,-0.04457,,,,,0.02341878788,-0.02226051344
362.803,0.42849,-0.03888,,,,,0.02596909091,-0.0194186395
363.303,0.46987,-0.03111,,,,,0.0284769697,-0.0155379083
363.803,0.51164,-0.02433,,,,,0.03100848485,-0.0121516332
364.303,0.55344,-0.01803,,,,,0.03354181818,-0.009005094396
364.803,0.59462,-0.01095,,,,,0.03603757576,-0.005468984117
365.303,0.63687,-0.00577,,,,,0.03859818182,-0.002881829987
365.803,0.67842,0.0012,,,,,0.04111636364,0.0005993407252
366.303,0.71963,0.00818,,,,,0.04361393939,0.004085505943
366.803,0.76164,0.01539,,,,,0.04616,0.007686544801
367.303,0.8034,0.02036,,,,,0.04869090909,0.0101688143
367.803,0.84473,0.02842,,,,,0.05119575758,0.01419438618
368.303,0.88682,0.03522,,,,,0.05374666667,0.01759065028
368.803,0.92811,0.04324,,,,,0.05624909091,0.02159624413
369.303,0.97005,0.04853,,,,,0.05879090909,0.02423833783
369.803,1.01168,0.05407,,,,,0.06131393939,0.02700529418
370.303,1.05305,0.06152,,,,,0.06382121212,0.03072620118
370.803,1.09517,0.06829,,,,,0.06637393939,0.03410748177
371.303,1.13665,0.07533,,,,,0.06888787879,0.03762361402
371.803,1.17814,0.08154,,,,,0.07140242424,0.04072520228
372.303,1.22017,0.09011,,,,,0.07394969697,0.04500549396
372.803,1.26153,0.09665,,,,,0.07645636364,0.04827190091
373.303,1.30321,0.10308,,,,,0.07898242424,0.05148336829
373.803,1.34516,0.11241,,,,,0.08152484848,0.05614324243
374.303,1.38634,0.11983,,,,,0.08402060606,0.05984916592
374.803,1.42836,0.12638,,,,,0.08656727273,0.06312056738
375.303,1.47009,0.13454,,,,,0.08909636364,0.06719608431
375.803,1.51138,0.14377,,,,,0.09159878788,0.07180601339
376.303,1.55342,0.15227,,,,,0.09414666667,0.07605134352
376.803,1.59504,0.15952,,,,,0.09666909091,0.0796723604
377.303,1.63657,0.16865,,,,,0.09918606061,0.08423234442
377.57,1.64794,0.1607,,,,,0.09987515152,0.08026171212
378.07,1.60569,0.12316,,,,,0.09731454545,0.06151233643
378.57,1.56374,0.09923,,,,,0.09477212121,0.04956048347
379.07,1.52211,0.0837,,,,,0.09224909091,0.04180401558
379.57,1.48067,0.07008,,,,,0.08973757576,0.03500149835
380.07,1.43866,0.05693,,,,,0.08719151515,0.0284337229
380.57,1.39712,0.04639,,,,,0.08467393939,0.02316951354
381.07,1.35572,0.03491,,,,,0.08216484848,0.0174358206
381.57,1.31364,0.026,,,,,0.07961454545,0.01298571571
382.07,1.27224,0.01893,,,,,0.07710545455,0.00945459994
382.57,1.23053,0.0105,,,,,0.07457757576,0.005244231346
383.07,1.18879,0.00221,,,,,0.07204787879,0.001103785836
383.57,1.14734,-0.00476,,,,,0.06953575758,-0.002377384877
384.07,1.10535,-0.01318,,,,,0.06699090909,-0.006582758965
384.57,1.06398,-0.01855,,,,,0.06448363636,-0.00926480871
385.07,1.02226,-0.02479,,,,,0.06195515152,-0.01238138048
385.57,0.98025,-0.03163,,,,,0.05940909091,-0.01579762262
386.07,0.93894,-0.03756,,,,,0.05690545455,-0.0187593647
386.57,0.89724,-0.04315,,,,,0.05437818182,-0.02155129358
387.07,0.85533,-0.04806,,,,,0.05183818182,-0.02400359604
387.57,0.81401,-0.05411,,,,,0.04933393939,-0.0270252722
388.07,0.77206,-0.05886,,,,,0.04679151515,-0.02939766257
388.57,0.73052,-0.06247,,,,,0.04427393939,-0.03120067925
389.07,0.68908,-0.06826,,,,,0.04176242424,-0.03409249825
389.57,0.64696,-0.07247,,,,,0.03920969697,-0.0361951853
390.07,0.60553,-0.07741,,,,,0.03669878788,-0.03866247128
390.57,0.56399,-0.08117,,,,,0.03418121212,-0.04054040555
391.07,0.52208,-0.08707,,,,,0.03164121212,-0.04348716412
391.57,0.48054,-0.09062,,,,,0.02912363636,-0.04526021376
392.07,0.43875,-0.09466,,,,,0.02659090909,-0.04727799421
392.57,0.39714,-0.10001,,,,,0.02406909091,-0.04995005494
393.07,0.3557,-0.10437,,,,,0.02155757576,-0.05212765957
393.57,0.31358,-0.10749,,,,,0.01900484848,-0.05368594546
394.07,0.27225,-0.11237,,,,,0.0165,-0.05612326441
394.57,0.23074,-0.11491,,,,,0.01398424242,-0.05739186894
395.07,0.1886,-0.12037,,,,,0.01143030303,-0.06011886924
395.57,0.14723,-0.12277,,,,,0.008923030303,-0.06131755069
396.07,0.10555,-0.12608,,,,,0.006396969697,-0.06297073219
396.57,0.06376,-0.1299,,,,,0.003864242424,-0.0648786335
397.07,0.02228,-0.13385,,,,,0.00135030303,-0.06685146339
397.338,-0.00001,-0.13519,,,,,-0.0000006060606061,-0.0675207272