File: mechanical/hysteresis/databak/g60_hysteresis - nonconductive_3.csv
Time,Extension,Load,Length,Width,Thickness,CS Area,Strain,Stress
(s),(mm),(N),(mm),(mm),(mm),(mm^2),(mm/mm),(MPa)
0,0,0.00005,16.5,2.71,0.36,0.9756,0,0.00005125051251
0.5,0.03923,0.00046,,,,,0.002377575758,0.000471504715
1,0.08048,0.00181,,,,,0.004877575758,0.001855268553
1.5,0.12258,0.00132,,,,,0.007429090909,0.00135301353
2,0.1642,0.00126,,,,,0.009951515152,0.001291512915
2.5,0.20548,0.00242,,,,,0.01245333333,0.002480524805
3,0.24756,0.00206,,,,,0.01500363636,0.002111521115
3.5,0.2889,0.0033,,,,,0.01750909091,0.003382533825
4,0.33076,0.00394,,,,,0.02004606061,0.004038540385
4.5,0.37245,0.00344,,,,,0.02257272727,0.00352603526
5,0.41383,0.00467,,,,,0.02508060606,0.004786797868
5.5,0.4559,0.00452,,,,,0.02763030303,0.00463304633
6,0.49753,0.00535,,,,,0.03015333333,0.005483804838
6.5,0.53871,0.0052,,,,,0.03264909091,0.005330053301
7,0.58101,0.00759,,,,,0.03521272727,0.007779827798
7.5,0.62246,0.00522,,,,,0.03772484848,0.005350553506
8,0.66392,0.00812,,,,,0.04023757576,0.008323083231
8.5,0.70594,0.00882,,,,,0.04278424242,0.009040590406
9,0.74725,0.00989,,,,,0.04528787879,0.01013735137
9.5,0.78912,0.01008,,,,,0.04782545455,0.01033210332
10,0.83082,0.01,,,,,0.05035272727,0.0102501025
10.5,0.87214,0.01269,,,,,0.0528569697,0.01300738007
11,0.91412,0.00962,,,,,0.05540121212,0.009860598606
11.5,0.95576,0.01059,,,,,0.05792484848,0.01085485855
12,0.99721,0.01201,,,,,0.0604369697,0.0123103731
12.5,1.03926,0.01252,,,,,0.06298545455,0.01283312833
13,1.08051,0.01227,,,,,0.06548545455,0.01257687577
13.5,1.12248,0.01361,,,,,0.06802909091,0.0139503895
14,1.16418,0.01377,,,,,0.07055636364,0.01411439114
14.5,1.2054,0.01468,,,,,0.07305454545,0.01504715047
15,1.24761,0.01267,,,,,0.07561272727,0.01298687987
15.5,1.28918,0.01349,,,,,0.07813212121,0.01382738827
16,1.33048,0.01504,,,,,0.08063515152,0.01541615416
16.5,1.37243,0.01622,,,,,0.08317757576,0.01662566626
17,1.41403,0.01619,,,,,0.08569878788,0.01659491595
17.5,1.45566,0.0181,,,,,0.08822181818,0.01855268553
18,1.49757,0.0174,,,,,0.09076181818,0.01783517835
18.5,1.53879,0.01801,,,,,0.09326,0.0184604346
19,1.58088,0.0134,,,,,0.09581090909,0.01373513735
19.5,1.62247,0.01703,,,,,0.09833151515,0.01745592456
19.831,1.65011,0.01713,,,,,0.1000066667,0.01755842558
20.232,1.62135,0.01858,,,,,0.09826363636,0.01904469045
20.732,1.57917,0.01654,,,,,0.09570727273,0.01695366954
21.232,1.53778,0.01426,,,,,0.09319878788,0.01461664617
21.732,1.49632,0.01375,,,,,0.09068606061,0.01409389094
22.232,1.4541,0.01417,,,,,0.08812727273,0.01452439524
22.732,1.41278,0.01225,,,,,0.0856230303,0.01255637556
23.232,1.3712,0.01163,,,,,0.0831030303,0.01192086921
23.732,1.32926,0.0112,,,,,0.08056121212,0.0114801148
24.232,1.28782,0.01051,,,,,0.07804969697,0.01077285773
24.732,1.24595,0.00926,,,,,0.07551212121,0.009491594916
25.232,1.20443,0.00777,,,,,0.07299575758,0.007964329643
25.732,1.16294,0.00648,,,,,0.07048121212,0.006642066421
26.232,1.12088,0.00693,,,,,0.06793212121,0.007103321033
26.732,1.0795,0.00715,,,,,0.06542424242,0.007328823288
27.232,1.03783,0.00725,,,,,0.06289878788,0.007431324313
27.732,0.99597,0.00682,,,,,0.06036181818,0.006990569906
28.232,0.95453,0.00491,,,,,0.05785030303,0.005032800328
28.732,0.91262,0.00213,,,,,0.05531030303,0.002183271833
29.232,0.87107,0.0036,,,,,0.05279212121,0.0036900369
29.732,0.8297,0.00107,,,,,0.05028484848,0.001096760968
30.232,0.78747,0.0009,,,,,0.04772545455,0.0009225092251
30.732,0.74613,0.00107,,,,,0.04522,0.001096760968
31.232,0.7046,-0.0008,,,,,0.0427030303,-0.0008200082001
31.732,0.66263,-0.00079,,,,,0.04015939394,-0.0008097580976
32.232,0.62112,-0.0015,,,,,0.03764363636,-0.001537515375
32.732,0.57945,-0.00047,,,,,0.03511818182,-0.0004817548175
33.232,0.53776,-0.00197,,,,,0.03259151515,-0.002019270193
33.732,0.49623,-0.00051,,,,,0.03007454545,-0.0005227552276
34.232,0.45422,-0.00199,,,,,0.02752848485,-0.002039770398
34.732,0.41288,-0.00391,,,,,0.0250230303,-0.004007790078
35.232,0.37129,-0.00674,,,,,0.02250242424,-0.006908569086
35.732,0.32911,-0.00477,,,,,0.01994606061,-0.004889298893
36.232,0.28787,-0.00635,,,,,0.01744666667,-0.006508815088
36.732,0.24609,-0.00852,,,,,0.01491454545,-0.008733087331
37.232,0.20426,-0.00939,,,,,0.01237939394,-0.009624846248
37.732,0.16285,-0.00846,,,,,0.00986969697,-0.008671586716
38.232,0.12101,-0.00711,,,,,0.007333939394,-0.007287822878
38.732,0.07934,-0.00851,,,,,0.004808484848,-0.008722837228
39.232,0.03797,-0.00859,,,,,0.002301212121,-0.008804838048
39.687,-0.00007,-0.01141,,,,,-0.000004242424242,-0.01169536695
39.989,0.01994,-0.01201,,,,,0.001208484848,-0.0123103731
40.489,0.06172,-0.01165,,,,,0.003740606061,-0.01194136941
40.989,0.10297,-0.00849,,,,,0.006240606061,-0.008702337023
41.489,0.14514,-0.00704,,,,,0.008796363636,-0.007216072161
41.989,0.18668,-0.00665,,,,,0.01131393939,-0.006816318163
42.489,0.22802,-0.00441,,,,,0.01381939394,-0.004520295203
42.989,0.27018,-0.00364,,,,,0.01637454545,-0.00373103731
43.489,0.31147,-0.00285,,,,,0.0188769697,-0.002921279213
43.989,0.35338,-0.00387,,,,,0.0214169697,-0.003966789668
44.489,0.39507,-0.00527,,,,,0.02394363636,-0.005401804018
44.989,0.4364,-0.00686,,,,,0.02644848485,-0.007031570316
45.489,0.47846,-0.00489,,,,,0.02899757576,-0.005012300123
45.989,0.52011,-0.00177,,,,,0.03152181818,-0.001814268143
46.489,0.56143,0.001,,,,,0.03402606061,0.00102501025
46.989,0.6034,0.00135,,,,,0.03656969697,0.001383763838
47.489,0.64492,0.00313,,,,,0.03908606061,0.003208282083
47.989,0.68656,-0.0017,,,,,0.04160969697,-0.001742517425
48.489,0.7284,0.00027,,,,,0.04414545455,0.0002767527675
48.989,0.7696,0.00052,,,,,0.04664242424,0.0005330053301
49.489,0.81184,0.00082,,,,,0.04920242424,0.0008405084051
49.989,0.85333,0.00261,,,,,0.0517169697,0.002675276753
50.489,0.8947,0.00305,,,,,0.05422424242,0.003126281263
50.989,0.93685,0.00413,,,,,0.05677878788,0.004233292333
51.489,0.97829,0.00779,,,,,0.05929030303,0.007984829848
51.989,1.01978,0.00789,,,,,0.06180484848,0.008087330873
52.489,1.0619,0.00617,,,,,0.06435757576,0.006324313243
52.989,1.10307,0.00442,,,,,0.06685272727,0.004530545305
53.489,1.14499,0.00405,,,,,0.06939333333,0.004151291513
53.989,1.18679,0.00607,,,,,0.07192666667,0.006221812218
54.489,1.22802,0.00738,,,,,0.07442545455,0.007564575646
54.989,1.27004,0.00769,,,,,0.07697212121,0.007882328823
55.489,1.31165,0.00979,,,,,0.07949393939,0.01003485035
55.989,1.35314,0.0106,,,,,0.08200848485,0.01086510865
56.489,1.39502,0.01191,,,,,0.08454666667,0.01220787208
56.989,1.43647,0.0122,,,,,0.08705878788,0.01250512505
57.489,1.47833,0.01091,,,,,0.08959575758,0.01118286183
57.989,1.52013,0.01312,,,,,0.09212909091,0.01344813448
58.489,1.56128,0.01189,,,,,0.0946230303,0.01218737187
58.989,1.60351,0.01165,,,,,0.09718242424,0.01194136941
59.489,1.64508,0.01119,,,,,0.09970181818,0.0114698647
59.75,1.63767,0.01177,,,,,0.09925272727,0.01206437064
60.25,1.59605,0.01263,,,,,0.09673030303,0.01294587946
60.75,1.5546,0.01319,,,,,0.09421818182,0.0135198852
61.25,1.51254,0.00997,,,,,0.09166909091,0.01021935219
61.75,1.47118,0.01,,,,,0.08916242424,0.0102501025
62.25,1.42931,0.00752,,,,,0.08662484848,0.007708077081
62.75,1.38781,0.00775,,,,,0.08410969697,0.007943829438
63.25,1.34618,0.00731,,,,,0.08158666667,0.007492824928
63.75,1.30414,0.00709,,,,,0.07903878788,0.007267322673
64.25,1.26283,0.00647,,,,,0.07653515152,0.006631816318
64.75,1.22118,0.006,,,,,0.07401090909,0.006150061501
65.25,1.17911,0.00355,,,,,0.07146121212,0.003638786388
65.75,1.13781,0.00416,,,,,0.06895818182,0.00426404264
66.25,1.096,0.00261,,,,,0.06642424242,0.002675276753
66.75,1.05428,0.00124,,,,,0.06389575758,0.00127101271
67.25,1.01296,0.00065,,,,,0.06139151515,0.0006662566626
67.75,0.97077,0.00004,,,,,0.05883454545,0.00004100041
68.25,0.92938,-0.00207,,,,,0.05632606061,-0.002121771218
68.75,0.88796,-0.00362,,,,,0.05381575758,-0.003710537105
69.25,0.84582,-0.00064,,,,,0.05126181818,-0.0006560065601
69.75,0.80436,-0.00232,,,,,0.04874909091,-0.00237802378
70.25,0.76279,-0.00203,,,,,0.04622969697,-0.002080770808
70.75,0.72095,-0.005,,,,,0.04369393939,-0.005125051251
71.25,0.67951,-0.00728,,,,,0.04118242424,-0.007462074621
71.75,0.63759,-0.00458,,,,,0.03864181818,-0.004694546945
72.25,0.59612,-0.00557,,,,,0.03612848485,-0.005709307093
72.75,0.55451,-0.00672,,,,,0.03360666667,-0.006888068881
73.25,0.51245,-0.00618,,,,,0.03105757576,-0.006334563346
73.75,0.47113,-0.00733,,,,,0.02855333333,-0.007513325133
74.25,0.4294,-0.00965,,,,,0.02602424242,-0.009891348913
74.75,0.38758,-0.01047,,,,,0.02348969697,-0.01073185732
75.25,0.34619,-0.00887,,,,,0.02098121212,-0.009091840918
75.75,0.30424,-0.01069,,,,,0.01843878788,-0.01095735957
76.25,0.26267,-0.00991,,,,,0.01591939394,-0.01015785158
76.75,0.22129,-0.01174,,,,,0.01341151515,-0.01203362034
77.25,0.17918,-0.01248,,,,,0.01085939394,-0.01279212792
77.75,0.13776,-0.01361,,,,,0.008349090909,-0.0139503895
78.25,0.09629,-0.01384,,,,,0.005835757576,-0.01418614186
78.75,0.05422,-0.01383,,,,,0.003286060606,-0.01417589176
79.25,0.01274,-0.01418,,,,,0.0007721212121,-0.01453464535
79.506,0.00221,-0.01527,,,,,0.0001339393939,-0.01565190652
80.006,0.04474,-0.01242,,,,,0.002711515152,-0.01273062731
80.506,0.08689,-0.01344,,,,,0.005266060606,-0.01377613776
81.006,0.12823,-0.0135,,,,,0.007771515152,-0.01383763838
81.506,0.17001,-0.01247,,,,,0.01030363636,-0.01278187782
82.006,0.21188,-0.01143,,,,,0.01284121212,-0.01171586716
82.506,0.25304,-0.01036,,,,,0.01533575758,-0.01061910619
83.006,0.29517,-0.00902,,,,,0.01788909091,-0.009245592456
83.506,0.33686,-0.00812,,,,,0.02041575758,-0.008323083231
84.006,0.37805,-0.00763,,,,,0.02291212121,-0.007820828208
84.506,0.42011,-0.00434,,,,,0.02546121212,-0.004448544485
85.006,0.46171,-0.00701,,,,,0.02798242424,-0.007185321853
85.506,0.50326,-0.00666,,,,,0.03050060606,-0.006826568266
86.006,0.54513,-0.00706,,,,,0.03303818182,-0.007236572366
86.506,0.58647,-0.00466,,,,,0.03554363636,-0.004776547765
87.006,0.6285,-0.00571,,,,,0.03809090909,-0.005852808528
87.506,0.67012,-0.00354,,,,,0.04061333333,-0.003628536285
88.006,0.71133,-0.00073,,,,,0.04311090909,-0.0007482574826
88.506,0.75357,-0.00171,,,,,0.04567090909,-0.001752767528
89.006,0.79507,-0.00427,,,,,0.04818606061,-0.004376793768
89.506,0.83653,-0.00226,,,,,0.05069878788,-0.002316523165
90.006,0.87851,-0.00289,,,,,0.0532430303,-0.002962279623
90.506,0.91992,0.00212,,,,,0.05575272727,0.00217302173
91.006,0.9617,0.00041,,,,,0.05828484848,0.0004202542025
91.506,1.00349,0.00324,,,,,0.06081757576,0.00332103321
92.006,1.04474,0.00337,,,,,0.06331757576,0.003454284543
92.506,1.08682,0.00365,,,,,0.06586787879,0.003741287413
93.006,1.12844,0.00167,,,,,0.06839030303,0.001711767118
93.506,1.16981,0.00198,,,,,0.07089757576,0.002029520295
94.006,1.21187,0.00429,,,,,0.07344666667,0.004397293973
94.506,1.2532,0.00668,,,,,0.07595151515,0.006847068471
95.006,1.29508,0.00526,,,,,0.07848969697,0.005391553916
95.506,1.33678,0.00583,,,,,0.0810169697,0.005975809758
96.006,1.37813,0.0057,,,,,0.0835230303,0.005842558426
96.506,1.42022,0.00596,,,,,0.08607393939,0.006109061091
97.006,1.46184,0.00519,,,,,0.08859636364,0.005319803198
97.506,1.503,0.00971,,,,,0.09109090909,0.009952849528
98.006,1.5453,0.01035,,,,,0.09365454545,0.01060885609
98.506,1.58673,0.01126,,,,,0.09616545455,0.01154161542
99.006,1.62819,0.01057,,,,,0.09867818182,0.01083435834
99.266,1.65015,0.00979,,,,,0.1000090909,0.01003485035
99.766,1.61277,0.00837,,,,,0.09774363636,0.008579335793
100.266,1.57099,0.00928,,,,,0.09521151515,0.009512095121
100.766,1.52953,0.00739,,,,,0.09269878788,0.007574825748
101.266,1.48748,0.00625,,,,,0.09015030303,0.006406314063
101.766,1.44607,0.00451,,,,,0.08764060606,0.004622796228
102.266,1.40455,0.00418,,,,,0.08512424242,0.004284542845
102.766,1.3625,0.00408,,,,,0.08257575758,0.00418204182
103.266,1.32112,0.00277,,,,,0.08006787879,0.002839278393
103.766,1.27937,0.00223,,,,,0.07753757576,0.002285772858
104.266,1.23763,0.0018,,,,,0.07500787879,0.00184501845
104.766,1.19616,0.00037,,,,,0.07249454545,0.0003792537925
105.266,1.15418,0.00183,,,,,0.06995030303,0.001875768758
105.766,1.11272,-0.00001,,,,,0.06743757576,-0.0000102501025
106.266,1.07136,-0.0005,,,,,0.06493090909,-0.0005125051251
106.766,1.02905,-0.00158,,,,,0.06236666667,-0.001619516195
107.266,0.98781,-0.00447,,,,,0.05986727273,-0.004581795818
107.766,0.94616,-0.00553,,,,,0.0573430303,-0.005668306683
108.266,0.90435,-0.00479,,,,,0.05480909091,-0.004909799098
108.766,0.86275,-0.00266,,,,,0.05228787879,-0.002726527265
109.266,0.82095,-0.00356,,,,,0.04975454545,-0.00364903649
109.766,0.77942,-0.00349,,,,,0.04723757576,-0.003577285773
110.266,0.73781,-0.00829,,,,,0.04471575758,-0.008497334973
110.766,0.69576,-0.00915,,,,,0.04216727273,-0.009378843788
111.266,0.65447,-0.01008,,,,,0.03966484848,-0.01033210332
111.766,0.61284,-0.00928,,,,,0.03714181818,-0.009512095121
112.266,0.5707,-0.00897,,,,,0.03458787879,-0.009194341943
112.766,0.52953,-0.00906,,,,,0.03209272727,-0.009286592866
113.266,0.48761,-0.00899,,,,,0.02955212121,-0.009214842148
113.766,0.44596,-0.01266,,,,,0.02702787879,-0.01297662977
114.266,0.40456,-0.01433,,,,,0.02451878788,-0.01468839688
114.766,0.36256,-0.01461,,,,,0.02197333333,-0.01497539975
115.266,0.32103,-0.01302,,,,,0.01945636364,-0.01334563346
115.766,0.27959,-0.01203,,,,,0.01694484848,-0.01233087331
116.266,0.23752,-0.01259,,,,,0.01439515152,-0.01290487905
116.766,0.19607,-0.01366,,,,,0.0118830303,-0.01400164002
117.266,0.15441,-0.01553,,,,,0.009358181818,-0.01591840918
117.766,0.11263,-0.01664,,,,,0.006826060606,-0.01705617056
118.266,0.07112,-0.01706,,,,,0.00431030303,-0.01748667487
118.766,0.02915,-0.01764,,,,,0.001766666667,-0.01808118081
119.121,-0.00011,-0.01882,,,,,-0.000006666666667,-0.01929069291
119.522,0.02853,-0.018,,,,,0.001729090909,-0.0184501845
120.022,0.06973,-0.01664,,,,,0.004226060606,-0.01705617056
120.522,0.11179,-0.01444,,,,,0.006775151515,-0.01480114801
121.022,0.15345,-0.0136,,,,,0.0093,-0.0139401394
121.522,0.19474,-0.01151,,,,,0.01180242424,-0.01179786798
122.022,0.23682,-0.01143,,,,,0.01435272727,-0.01171586716
122.522,0.27844,-0.01133,,,,,0.01687515152,-0.01161336613
123.022,0.31987,-0.00942,,,,,0.01938606061,-0.009655596556
123.522,0.36181,-0.00949,,,,,0.02192787879,-0.009727347273
124.022,0.40325,-0.01142,,,,,0.02443939394,-0.01170561706
124.522,0.44506,-0.01215,,,,,0.02697333333,-0.01245387454
125.022,0.48676,-0.0108,,,,,0.02950060606,-0.0110701107
125.522,0.52797,-0.00861,,,,,0.03199818182,-0.008825338253
126.022,0.57028,-0.0085,,,,,0.03456242424,-0.008712587126
126.522,0.61168,-0.00451,,,,,0.03707151515,-0.004622796228
127.022,0.65318,-0.00491,,,,,0.03958666667,-0.005032800328
127.522,0.69522,-0.00494,,,,,0.04213454545,-0.005063550636
128.022,0.73656,-0.00408,,,,,0.04464,-0.00418204182
128.522,0.77826,-0.00322,,,,,0.04716727273,-0.003300533005
129.022,0.82024,-0.0035,,,,,0.04971151515,-0.003587535875
129.522,0.86138,-0.00073,,,,,0.05220484848,-0.0007482574826
130.022,0.90341,-0.00324,,,,,0.05475212121,-0.00332103321
130.522,0.94516,-0.00227,,,,,0.05728242424,-0.002326773268
131.022,0.98644,-0.00219,,,,,0.05978424242,-0.002244772448
131.522,1.02844,-0.00129,,,,,0.06232969697,-0.001322263223
132.022,1.07001,0.00052,,,,,0.06484909091,0.0005330053301
132.522,1.11163,0.00022,,,,,0.06737151515,0.000225502255
133.022,1.15344,0.00146,,,,,0.06990545455,0.001496514965
133.522,1.19478,0.00241,,,,,0.07241090909,0.002470274703
134.022,1.2368,0.00259,,,,,0.07495757576,0.002654776548
134.522,1.27849,0.00439,,,,,0.07748424242,0.004499794998
135.022,1.31968,0.00417,,,,,0.07998060606,0.004274292743
135.522,1.36185,0.005,,,,,0.08253636364,0.005125051251
136.022,1.40339,0.00563,,,,,0.08505393939,0.005770807708
136.522,1.4448,0.00575,,,,,0.08756363636,0.005893808938
137.022,1.48681,0.00633,,,,,0.09010969697,0.006488314883
137.522,1.52821,0.00559,,,,,0.09261878788,0.005729807298
138.022,1.57008,0.00844,,,,,0.09515636364,0.008651086511
138.522,1.61175,0.00753,,,,,0.09768181818,0.007718327183
138.98,1.65,0.00801,,,,,0.1,0.008210332103
139.282,1.62959,0.00728,,,,,0.0987630303,0.007462074621
139.782,1.58783,0.00859,,,,,0.09623212121,0.008804838048
140.282,1.54578,0.00885,,,,,0.09368363636,0.009071340713
140.782,1.50443,0.00557,,,,,0.09117757576,0.005709307093
141.282,1.46272,0.00283,,,,,0.08864969697,0.002900779008
141.782,1.42087,0.00489,,,,,0.08611333333,0.005012300123
142.282,1.37952,0.0031,,,,,0.08360727273,0.003177531775
142.782,1.33755,0.00305,,,,,0.08106363636,0.003126281263
143.282,1.29601,0.00133,,,,,0.07854606061,0.001363263633
143.782,1.25464,0.0016,,,,,0.07603878788,0.0016400164
144.282,1.21238,-0.00141,,,,,0.07347757576,-0.001445264453
144.782,1.17105,-0.00003,,,,,0.07097272727,-0.0000307503075
145.282,1.12958,-0.00239,,,,,0.06845939394,-0.002449774498
145.782,1.08747,-0.00251,,,,,0.06590727273,-0.002572775728
146.282,1.04601,-0.00449,,,,,0.06339454545,-0.004602296023
146.782,1.00432,-0.00269,,,,,0.06086787879,-0.002757277573
147.282,0.96267,-0.00198,,,,,0.05834363636,-0.002029520295
147.782,0.9212,-0.00425,,,,,0.05583030303,-0.004356293563
148.282,0.87912,-0.00712,,,,,0.05328,-0.007298072981
148.782,0.83775,-0.00706,,,,,0.05077272727,-0.007236572366
149.282,0.79614,-0.01046,,,,,0.04825090909,-0.01072160722
149.782,0.75416,-0.009,,,,,0.04570666667,-0.009225092251
150.282,0.71282,-0.00766,,,,,0.04320121212,-0.007851578516
150.782,0.67103,-0.00921,,,,,0.04066848485,-0.009440344403
151.282,0.62931,-0.01034,,,,,0.03814,-0.01059860599
151.782,0.58794,-0.0098,,,,,0.03563272727,-0.01004510045
152.282,0.54582,-0.01182,,,,,0.03308,-0.01211562116
152.782,0.50439,-0.01224,,,,,0.03056909091,-0.01254612546
153.282,0.4629,-0.01389,,,,,0.02805454545,-0.01423739237
153.782,0.42081,-0.01119,,,,,0.02550363636,-0.0114698647
154.282,0.37939,-0.01626,,,,,0.02299333333,-0.01666666667
154.782,0.33779,-0.01403,,,,,0.02047212121,-0.01438089381
155.282,0.29594,-0.01609,,,,,0.01793575758,-0.01649241492
155.782,0.25441,-0.01525,,,,,0.01541878788,-0.01563140631
156.282,0.21257,-0.01746,,,,,0.0128830303,-0.01789667897
156.782,0.17109,-0.01821,,,,,0.01036909091,-0.01866543665
157.282,0.12955,-0.01608,,,,,0.007851515152,-0.01648216482
157.782,0.08738,-0.01834,,,,,0.005295757576,-0.01879868799
158.282,0.04616,-0.01741,,,,,0.002797575758,-0.01784542845
158.782,0.00451,-0.02018,,,,,0.0002733333333,-0.02068470685
159.038,0.01103,-0.01921,,,,,0.0006684848485,-0.0196904469
159.538,0.0535,-0.01864,,,,,0.003242424242,-0.01910619106
160.038,0.09512,-0.01818,,,,,0.005764848485,-0.01863468635
160.538,0.13643,-0.01638,,,,,0.008268484848,-0.0167896679
161.038,0.17845,-0.01786,,,,,0.01081515152,-0.01830668307
161.538,0.2199,-0.01514,,,,,0.01332727273,-0.01551865519
162.038,0.26168,-0.0146,,,,,0.01585939394,-0.01496514965
162.538,0.30342,-0.01484,,,,,0.01838909091,-0.01521115211
163.038,0.34472,-0.01199,,,,,0.02089212121,-0.0122898729
163.538,0.38683,-0.01259,,,,,0.02344424242,-0.01290487905
164.038,0.4284,-0.01216,,,,,0.02596363636,-0.01246412464
164.538,0.46966,-0.00938,,,,,0.02846424242,-0.009614596146
165.038,0.51187,-0.00932,,,,,0.03102242424,-0.009553095531
165.538,0.55325,-0.00843,,,,,0.03353030303,-0.008640836408
166.038,0.59492,-0.01158,,,,,0.03605575758,-0.0118696187
166.538,0.63677,-0.00835,,,,,0.03859212121,-0.008558835588
167.038,0.6781,-0.01001,,,,,0.0410969697,-0.0102603526
167.538,0.7201,-0.00932,,,,,0.04364242424,-0.009553095531
168.038,0.7618,-0.00709,,,,,0.04616969697,-0.007267322673
168.538,0.80305,-0.00747,,,,,0.04866969697,-0.007656826568
169.038,0.84516,-0.00313,,,,,0.05122181818,-0.003208282083
169.538,0.88673,-0.00393,,,,,0.05374121212,-0.004028290283
170.038,0.92821,-0.00192,,,,,0.05625515152,-0.00196801968
170.538,0.97012,-0.00142,,,,,0.05879515152,-0.001455514555
171.038,1.0114,0.00062,,,,,0.0612969697,0.0006355063551
171.538,1.05348,-0.00169,,,,,0.06384727273,-0.001732267323
172.038,1.09504,-0.00191,,,,,0.06636606061,-0.001957769578
172.538,1.13638,-0.00228,,,,,0.06887151515,-0.00233702337
173.038,1.17848,-0.00174,,,,,0.0714230303,-0.001783517835
173.538,1.22007,0.00006,,,,,0.07394363636,0.00006150061501
174.038,1.26137,0.00058,,,,,0.07644666667,0.0005945059451
174.538,1.3036,0.00162,,,,,0.07900606061,0.001660516605
175.038,1.34489,-0.00007,,,,,0.08150848485,-0.00007175071751
175.538,1.3866,0.00267,,,,,0.08403636364,0.002736777368
176.038,1.42854,0.00539,,,,,0.08657818182,0.005524805248
176.538,1.46977,0.00362,,,,,0.0890769697,0.003710537105
177.038,1.51176,0.006,,,,,0.09162181818,0.006150061501
177.538,1.55338,0.00815,,,,,0.09414424242,0.008353833538
178.038,1.59478,0.00624,,,,,0.09665333333,0.006396063961
178.538,1.63672,0.00715,,,,,0.09919515152,0.007328823288
178.799,1.64696,0.00578,,,,,0.09981575758,0.005924559246
179.299,1.60432,0.00823,,,,,0.09723151515,0.008435834358
179.799,1.5629,0.00303,,,,,0.09472121212,0.003105781058
180.299,1.52099,0.00333,,,,,0.09218121212,0.003413284133
180.799,1.47944,0.0019,,,,,0.0896630303,0.001947519475
181.299,1.43798,0.00083,,,,,0.08715030303,0.0008507585076
181.799,1.39585,0.00239,,,,,0.0845969697,0.002449774498
182.299,1.35447,0.00018,,,,,0.08208909091,0.000184501845
182.799,1.31303,-0.00057,,,,,0.07957757576,-0.0005842558426
183.299,1.27078,-0.00068,,,,,0.0770169697,-0.0006970069701
183.799,1.2295,-0.00193,,,,,0.07451515152,-0.001978269783
184.299,1.18772,-0.00187,,,,,0.0719830303,-0.001916769168
184.799,1.14612,-0.00372,,,,,0.06946181818,-0.00381303813
185.299,1.10449,-0.0051,,,,,0.06693878788,-0.005227552276
185.799,1.06256,-0.00537,,,,,0.06439757576,-0.005504305043
186.299,1.02116,-0.00367,,,,,0.06188848485,-0.003761787618
186.799,0.9796,-0.00765,,,,,0.05936969697,-0.007841328413
187.299,0.93747,-0.00614,,,,,0.05681636364,-0.006293562936
187.799,0.89623,-0.00786,,,,,0.0543169697,-0.008056580566
188.299,0.8545,-0.01077,,,,,0.05178787879,-0.01103936039
188.799,0.81258,-0.00956,,,,,0.04924727273,-0.009799097991
189.299,0.7713,-0.00968,,,,,0.04674545455,-0.009922099221
189.799,0.72923,-0.00959,,,,,0.04419575758,-0.009829848298
190.299,0.68772,-0.0091,,,,,0.04168,-0.009327593276
190.799,0.64631,-0.01332,,,,,0.03917030303,-0.01365313653
191.299,0.60418,-0.01178,,,,,0.0366169697,-0.01207462075
191.799,0.56273,-0.01381,,,,,0.03410484848,-0.01415539155
192.299,0.52125,-0.01425,,,,,0.03159090909,-0.01460639606
192.799,0.47928,-0.01539,,,,,0.02904727273,-0.01577490775
193.299,0.43782,-0.01345,,,,,0.02653454545,-0.01378638786
193.799,0.39601,-0.01412,,,,,0.02400060606,-0.01447314473
194.299,0.35443,-0.01643,,,,,0.02148060606,-0.01684091841
194.799,0.31292,-0.01907,,,,,0.01896484848,-0.01954694547
195.299,0.27086,-0.01736,,,,,0.01641575758,-0.01779417794
195.799,0.22956,-0.01792,,,,,0.01391272727,-0.01836818368
196.299,0.18785,-0.01721,,,,,0.01138484848,-0.0176404264
196.799,0.14587,-0.01782,,,,,0.008840606061,-0.01826568266
197.299,0.10452,-0.01929,,,,,0.006334545455,-0.01977244772
197.799,0.06273,-0.0216,,,,,0.003801818182,-0.0221402214
198.299,0.02096,-0.02216,,,,,0.00127030303,-0.02271422714
198.556,-0.00024,-0.02081,,,,,-0.00001454545455,-0.0213304633
199.056,0.03666,-0.01973,,,,,0.002221818182,-0.02022345223
199.556,0.07826,-0.01824,,,,,0.004743030303,-0.01869618696
200.056,0.12009,-0.0209,,,,,0.007278181818,-0.02142271423
200.556,0.1614,-0.01392,,,,,0.009781818182,-0.01426814268
201.056,0.2034,-0.01428,,,,,0.01232727273,-0.01463714637
201.556,0.245,-0.01353,,,,,0.01484848485,-0.01386838868
202.056,0.28626,-0.017,,,,,0.01734909091,-0.01742517425
202.556,0.32852,-0.01487,,,,,0.01991030303,-0.01524190242
203.056,0.36989,-0.01443,,,,,0.02241757576,-0.01479089791
203.556,0.41151,-0.0114,,,,,0.02494,-0.01168511685
204.056,0.45349,-0.011,,,,,0.02748424242,-0.01127511275
204.556,0.49474,-0.0114,,,,,0.02998424242,-0.01168511685
205.056,0.53671,-0.0113,,,,,0.03252787879,-0.01158261583
205.556,0.5785,-0.00865,,,,,0.03506060606,-0.008866338663
206.056,0.61967,-0.00836,,,,,0.03755575758,-0.008569085691
206.556,0.66173,-0.00703,,,,,0.04010484848,-0.007205822058
207.056,0.7034,-0.00828,,,,,0.04263030303,-0.008487084871
207.556,0.74483,-0.0076,,,,,0.04514121212,-0.007790077901
208.056,0.78675,-0.00625,,,,,0.04768181818,-0.006406314063
208.556,0.82819,-0.00493,,,,,0.05019333333,-0.005053300533
209.056,0.87002,-0.00648,,,,,0.05272848485,-0.006642066421
209.556,0.91167,-0.00439,,,,,0.05525272727,-0.004499794998
210.056,0.95292,-0.0046,,,,,0.05775272727,-0.00471504715
210.556,0.9951,-0.00528,,,,,0.06030909091,-0.005412054121
211.056,1.03672,-0.00348,,,,,0.06283151515,-0.00356703567
211.556,1.07803,-0.00198,,,,,0.06533515152,-0.002029520295
212.056,1.12012,-0.00274,,,,,0.06788606061,-0.002808528085
212.556,1.16163,-0.00231,,,,,0.07040181818,-0.002367773678
213.056,1.20324,-0.00196,,,,,0.07292363636,-0.00200902009
213.556,1.2451,-0.002,,,,,0.07546060606,-0.0020500205
214.056,1.28644,-0.00182,,,,,0.07796606061,-0.001865518655
214.556,1.32843,0.00043,,,,,0.08051090909,0.0004407544075
215.056,1.37006,-0.00079,,,,,0.08303393939,-0.0008097580976
215.556,1.41136,0.0025,,,,,0.0855369697,0.002562525625
216.056,1.45347,0.00323,,,,,0.08808909091,0.003310783108
216.556,1.49489,0.00233,,,,,0.09059939394,0.002388273883
217.056,1.53657,0.0049,,,,,0.09312545455,0.005022550226
217.556,1.57839,0.00472,,,,,0.09566,0.00483804838
218.056,1.61978,0.00692,,,,,0.09816848485,0.007093070931
218.416,1.6501,0.00389,,,,,0.1000060606,0.003987289873
218.817,1.62132,0.00286,,,,,0.09826181818,0.002931529315
219.317,1.57916,0.00376,,,,,0.09570666667,0.00385403854
219.817,1.53779,0.0026,,,,,0.09319939394,0.00266502665
220.317,1.49632,0.00167,,,,,0.09068606061,0.001711767118
220.817,1.45406,0.00044,,,,,0.08812484848,0.00045100451
221.317,1.41276,-0.00049,,,,,0.08562181818,-0.0005022550226
221.817,1.37119,-0.00355,,,,,0.08310242424,-0.003638786388
222.317,1.32923,-0.0023,,,,,0.08055939394,-0.002357523575
222.817,1.28778,-0.00311,,,,,0.07804727273,-0.003187781878
223.317,1.24593,-0.00185,,,,,0.07551090909,-0.001896268963
223.817,1.20444,-0.0033,,,,,0.07299636364,-0.003382533825
224.317,1.16294,-0.00348,,,,,0.07048121212,-0.00356703567
224.817,1.12086,-0.00485,,,,,0.06793090909,-0.004971299713
225.317,1.07951,-0.00603,,,,,0.06542484848,-0.006180811808
225.817,1.03784,-0.00808,,,,,0.06289939394,-0.008282082821
226.317,0.99596,-0.00718,,,,,0.06036121212,-0.007359573596
226.817,0.9545,-0.01004,,,,,0.05784848485,-0.01029110291
227.317,0.91261,-0.0084,,,,,0.05530969697,-0.008610086101
227.817,0.87106,-0.00908,,,,,0.05279151515,-0.009307093071
228.317,0.82967,-0.01047,,,,,0.0502830303,-0.01073185732
228.817,0.78744,-0.01009,,,,,0.04772363636,-0.01034235342
229.317,0.74612,-0.01,,,,,0.04521939394,-0.0102501025
229.817,0.70459,-0.01352,,,,,0.04270242424,-0.01385813858
230.317,0.66263,-0.01283,,,,,0.04015939394,-0.01315088151
230.817,0.62111,-0.01262,,,,,0.0376430303,-0.01293562936
231.317,0.57943,-0.01501,,,,,0.0351169697,-0.01538540385
231.817,0.53776,-0.01603,,,,,0.03259151515,-0.01643091431
232.317,0.49621,-0.01368,,,,,0.03007333333,-0.01402214022
232.817,0.45421,-0.01571,,,,,0.02752787879,-0.01610291103
233.317,0.41287,-0.01799,,,,,0.02502242424,-0.0184399344
233.817,0.37129,-0.01669,,,,,0.02250242424,-0.01710742107
234.317,0.32908,-0.01736,,,,,0.01994424242,-0.01779417794
234.817,0.28785,-0.01742,,,,,0.01744545455,-0.01785567856
235.317,0.24608,-0.02051,,,,,0.01491393939,-0.02102296023
235.817,0.20425,-0.0219,,,,,0.01237878788,-0.02244772448
236.317,0.16281,-0.02087,,,,,0.009867272727,-0.02139196392
236.817,0.121,-0.0213,,,,,0.007333333333,-0.02183271833
237.317,0.07933,-0.02184,,,,,0.004807878788,-0.02238622386
237.817,0.03796,-0.02189,,,,,0.002300606061,-0.02243747437
238.271,0,-0.02119,,,,,0,-0.0217199672
238.573,0.02003,-0.02293,,,,,0.001213939394,-0.02350348503
239.073,0.06181,-0.02011,,,,,0.003746060606,-0.02061295613
239.573,0.10304,-0.01858,,,,,0.006244848485,-0.01904469045
240.073,0.14522,-0.02041,,,,,0.008801212121,-0.0209204592
240.573,0.18678,-0.0199,,,,,0.01132,-0.02039770398
241.073,0.22811,-0.01794,,,,,0.01382484848,-0.01838868389
241.573,0.27027,-0.01621,,,,,0.01638,-0.01661541615
242.073,0.31157,-0.01672,,,,,0.0188830303,-0.01713817138
242.573,0.35346,-0.01526,,,,,0.02142181818,-0.01564165642
243.073,0.39516,-0.01393,,,,,0.02394909091,-0.01427839278
243.573,0.43649,-0.01362,,,,,0.02645393939,-0.01396063961
244.073,0.47856,-0.01265,,,,,0.02900363636,-0.01296637966
244.573,0.5202,-0.01357,,,,,0.03152727273,-0.01390938909
245.073,0.56152,-0.01253,,,,,0.03403151515,-0.01284337843
245.573,0.60353,-0.01252,,,,,0.03657757576,-0.01283312833
246.073,0.64503,-0.01101,,,,,0.03909272727,-0.01128536285
246.573,0.68665,-0.00948,,,,,0.04161515152,-0.009717097171
247.073,0.7285,-0.00854,,,,,0.04415151515,-0.008753587536
247.573,0.7697,-0.00827,,,,,0.04664848485,-0.008476834768
248.073,0.81194,-0.00812,,,,,0.04920848485,-0.008323083231
248.573,0.85342,-0.00852,,,,,0.05172242424,-0.008733087331
249.073,0.89479,-0.00726,,,,,0.05422969697,-0.007441574416
249.573,0.93692,-0.00739,,,,,0.0567830303,-0.007574825748
250.073,0.9784,-0.00344,,,,,0.0592969697,-0.00352603526
250.573,1.01986,-0.0053,,,,,0.06180969697,-0.005432554326
251.073,1.06201,-0.00402,,,,,0.06436424242,-0.004120541205
251.573,1.10319,-0.00134,,,,,0.06686,-0.001373513735
252.073,1.14507,-0.00491,,,,,0.06939818182,-0.005032800328
252.573,1.1869,-0.00317,,,,,0.07193333333,-0.003249282493
253.073,1.22809,-0.0003,,,,,0.07442969697,-0.000307503075
253.573,1.27013,-0.00138,,,,,0.07697757576,-0.001414514145
254.073,1.31176,0.00079,,,,,0.07950060606,0.0008097580976
254.573,1.35322,-0.00269,,,,,0.08201333333,-0.002757277573
255.073,1.39513,0.00003,,,,,0.08455333333,0.0000307503075
255.573,1.43659,0.00088,,,,,0.08706606061,0.0009020090201
256.073,1.47841,0.00182,,,,,0.08960060606,0.001865518655
256.573,1.52021,0.0034,,,,,0.09213393939,0.00348503485
257.073,1.56138,0.00395,,,,,0.09462909091,0.004048790488
257.573,1.60359,0.00413,,,,,0.09718727273,0.004233292333
258.073,1.64516,0.00309,,,,,0.09970666667,0.003167281673
258.333,1.6377,0.00415,,,,,0.09925454545,0.004253792538
258.833,1.59609,0.00366,,,,,0.09673272727,0.003751537515
259.333,1.55462,0.00123,,,,,0.09421939394,0.001260762608
259.833,1.51255,0.00161,,,,,0.09166969697,0.001650266503
260.333,1.47121,-0.00107,,,,,0.08916424242,-0.001096760968
260.833,1.42934,-0.00182,,,,,0.08662666667,-0.001865518655
261.333,1.38785,-0.00203,,,,,0.08411212121,-0.002080770808
261.833,1.34622,-0.00008,,,,,0.08158909091,-0.00008200082001
262.333,1.30419,-0.00252,,,,,0.07904181818,-0.00258302583
262.833,1.26284,-0.00342,,,,,0.07653575758,-0.003505535055
263.333,1.22121,-0.00425,,,,,0.07401272727,-0.004356293563
263.833,1.17916,-0.00602,,,,,0.07146424242,-0.006170561706
264.333,1.13786,-0.00668,,,,,0.06896121212,-0.006847068471
264.833,1.09602,-0.00711,,,,,0.06642545455,-0.007287822878
265.333,1.05432,-0.00654,,,,,0.06389818182,-0.006703567036
265.833,1.01302,-0.00731,,,,,0.06139515152,-0.007492824928
266.333,0.9708,-0.00831,,,,,0.05883636364,-0.008517835178
266.833,0.92941,-0.01007,,,,,0.05632787879,-0.01032185322
267.333,0.88797,-0.01023,,,,,0.05381636364,-0.01048585486
267.833,0.84586,-0.01023,,,,,0.05126424242,-0.01048585486
268.333,0.80441,-0.0122,,,,,0.04875212121,-0.01250512505
268.833,0.7628,-0.01191,,,,,0.04623030303,-0.01220787208
269.333,0.721,-0.0121,,,,,0.0436969697,-0.01240262403
269.833,0.67954,-0.01396,,,,,0.04118424242,-0.01430914309
270.333,0.63764,-0.01429,,,,,0.03864484848,-0.01464739647
270.833,0.59614,-0.01343,,,,,0.03612969697,-0.01376588766
271.333,0.55456,-0.01563,,,,,0.03360969697,-0.01602091021
271.833,0.5125,-0.01668,,,,,0.03106060606,-0.01709717097
272.333,0.47119,-0.01576,,,,,0.0285569697,-0.01615416154
272.833,0.42943,-0.01821,,,,,0.02602606061,-0.01866543665
273.333,0.3876,-0.01697,,,,,0.02349090909,-0.01739442394
273.833,0.3462,-0.01691,,,,,0.02098181818,-0.01733292333
274.333,0.30427,-0.02055,,,,,0.01844060606,-0.02106396064
274.833,0.2627,-0.01963,,,,,0.01592121212,-0.02012095121
275.333,0.22129,-0.01899,,,,,0.01341151515,-0.01946494465
275.833,0.17923,-0.01977,,,,,0.01086242424,-0.02026445264
276.333,0.13781,-0.01948,,,,,0.008352121212,-0.01996719967
276.833,0.09632,-0.02221,,,,,0.005837575758,-0.02276547765
277.333,0.05425,-0.02301,,,,,0.003287878788,-0.02358548585
277.833,0.0128,-0.02285,,,,,0.0007757575758,-0.02342148421
278.09,0.0021,-0.02112,,,,,0.0001272727273,-0.02164821648
278.59,0.04468,-0.02298,,,,,0.002707878788,-0.02355473555
279.09,0.08681,-0.01908,,,,,0.005261212121,-0.01955719557
279.59,0.12816,-0.02049,,,,,0.007767272727,-0.02100246002
280.09,0.16993,-0.02103,,,,,0.01029878788,-0.02155596556
280.59,0.2118,-0.01756,,,,,0.01283636364,-0.01799917999
281.09,0.25298,-0.01762,,,,,0.01533212121,-0.01806068061
281.59,0.29511,-0.01728,,,,,0.01788545455,-0.01771217712
282.09,0.33678,-0.01567,,,,,0.02041090909,-0.01606191062
282.59,0.37798,-0.01909,,,,,0.02290787879,-0.01956744567
283.09,0.42003,-0.01604,,,,,0.02545636364,-0.01644116441
283.59,0.46163,-0.01564,,,,,0.02797757576,-0.01603116031
284.09,0.50322,-0.01493,,,,,0.03049818182,-0.01530340303
284.59,0.54507,-0.01205,,,,,0.03303454545,-0.01235137351
285.09,0.58642,-0.01105,,,,,0.03554060606,-0.01132636326
285.59,0.62844,-0.01343,,,,,0.03808727273,-0.01376588766
286.09,0.67003,-0.01284,,,,,0.04060787879,-0.01316113161
286.59,0.71126,-0.01178,,,,,0.04310666667,-0.01207462075
287.09,0.75351,-0.01191,,,,,0.04566727273,-0.01220787208
287.59,0.79499,-0.00843,,,,,0.04818121212,-0.008640836408
288.09,0.83648,-0.00783,,,,,0.05069575758,-0.008025830258
288.59,0.87845,-0.0084,,,,,0.05323939394,-0.008610086101
289.09,0.91982,-0.00802,,,,,0.05574666667,-0.008220582206
289.59,0.96165,-0.00812,,,,,0.05828181818,-0.008323083231
290.09,1.00343,-0.00722,,,,,0.06081393939,-0.007400574006
290.59,1.04467,-0.0066,,,,,0.06331333333,-0.006765067651
291.09,1.08674,-0.0046,,,,,0.0658630303,-0.00471504715
291.59,1.12837,-0.00449,,,,,0.06838606061,-0.004602296023
292.09,1.16975,-0.00251,,,,,0.07089393939,-0.002572775728
292.59,1.21179,-0.00247,,,,,0.07344181818,-0.002531775318
293.09,1.25316,-0.00339,,,,,0.07594909091,-0.003474784748
293.59,1.29501,-0.00215,,,,,0.07848545455,-0.002203772038
294.09,1.33672,-0.00102,,,,,0.08101333333,-0.001045510455
294.59,1.37807,-0.00063,,,,,0.08351939394,-0.0006457564576
295.09,1.42017,0.00023,,,,,0.08607090909,0.0002357523575
295.59,1.46176,0.00017,,,,,0.08859151515,0.0001742517425
296.09,1.50292,0.00146,,,,,0.09108606061,0.001496514965
296.59,1.54523,0.00138,,,,,0.09365030303,0.001414514145
297.09,1.58665,0.0033,,,,,0.09616060606,0.003382533825
297.59,1.62812,0.00375,,,,,0.09867393939,0.003843788438
297.851,1.65017,0.00368,,,,,0.100010303,0.00377203772
298.351,1.6128,0.00302,,,,,0.09774545455,0.003095530955
298.851,1.57102,0.0005,,,,,0.09521333333,0.0005125051251
299.351,1.52956,0.00005,,,,,0.09270060606,0.00005125051251
299.851,1.48752,-0.00018,,,,,0.09015272727,-0.000184501845
300.351,1.44613,-0.00169,,,,,0.08764424242,-0.001732267323
300.851,1.4046,-0.00238,,,,,0.08512727273,-0.002439524395
301.351,1.36255,-0.00113,,,,,0.08257878788,-0.001158261583
301.851,1.32113,-0.00374,,,,,0.08006848485,-0.003833538335
302.351,1.27939,-0.00452,,,,,0.07753878788,-0.00463304633
302.851,1.23769,-0.00503,,,,,0.07501151515,-0.005155801558
303.351,1.19621,-0.00631,,,,,0.07249757576,-0.006467814678
303.851,1.15421,-0.0053,,,,,0.06995212121,-0.005432554326
304.351,1.11277,-0.00642,,,,,0.06744060606,-0.006580565806
304.851,1.07141,-0.00788,,,,,0.06493393939,-0.008077080771
305.351,1.02908,-0.00687,,,,,0.06236848485,-0.007041820418
305.851,0.98781,-0.0093,,,,,0.05986727273,-0.009532595326
306.351,0.94618,-0.0118,,,,,0.05734424242,-0.01209512095
306.851,0.90441,-0.01163,,,,,0.05481272727,-0.01192086921
307.351,0.86278,-0.01134,,,,,0.05228969697,-0.01162361624
307.851,0.82097,-0.01022,,,,,0.04975575758,-0.01047560476
308.351,0.77945,-0.01197,,,,,0.04723939394,-0.01226937269
308.851,0.73786,-0.01219,,,,,0.04471878788,-0.01249487495
309.351,0.69578,-0.01241,,,,,0.04216848485,-0.0127203772
309.851,0.65451,-0.01476,,,,,0.03966727273,-0.01512915129
310.351,0.6129,-0.01692,,,,,0.03714545455,-0.01734317343
310.851,0.57075,-0.01741,,,,,0.03459090909,-0.01784542845
311.351,0.52954,-0.01564,,,,,0.03209333333,-0.01603116031
311.851,0.48763,-0.01605,,,,,0.02955333333,-0.01645141451
312.351,0.44598,-0.01734,,,,,0.02702909091,-0.01777367774
312.851,0.40457,-0.01744,,,,,0.02451939394,-0.01787617876
313.351,0.36258,-0.01994,,,,,0.02197454545,-0.02043870439
313.851,0.32108,-0.02,,,,,0.01945939394,-0.020500205
314.351,0.27962,-0.02219,,,,,0.01694666667,-0.02274497745
314.851,0.23754,-0.01936,,,,,0.01439636364,-0.01984419844
315.351,0.19611,-0.0222,,,,,0.01188545455,-0.02275522755
315.851,0.15442,-0.02421,,,,,0.009358787879,-0.02481549815
316.351,0.11265,-0.02241,,,,,0.006827272727,-0.0229704797
316.851,0.07116,-0.02304,,,,,0.004312727273,-0.02361623616
317.351,0.02918,-0.02316,,,,,0.001768484848,-0.02373923739
317.706,-0.00009,-0.02369,,,,,-0.000005454545455,-0.02428249282
318.107,0.02857,-0.02448,,,,,0.001731515152,-0.02509225092
318.607,0.06977,-0.02248,,,,,0.004228484848,-0.02304223042
319.107,0.11183,-0.02123,,,,,0.006777575758,-0.02176096761
319.607,0.15348,-0.02301,,,,,0.009301818182,-0.02358548585
320.107,0.19476,-0.02032,,,,,0.01180363636,-0.02082820828
320.607,0.23684,-0.02069,,,,,0.01435393939,-0.02120746207
321.107,0.27845,-0.01865,,,,,0.01687575758,-0.01911644116
321.607,0.3199,-0.01808,,,,,0.01938787879,-0.01853218532
322.107,0.36184,-0.01611,,,,,0.02192969697,-0.01651291513
322.607,0.40327,-0.01702,,,,,0.02444060606,-0.01744567446
323.107,0.44508,-0.01659,,,,,0.02697454545,-0.01700492005
323.607,0.48678,-0.01516,,,,,0.02950181818,-0.01553915539
324.107,0.528,-0.01503,,,,,0.032,-0.01540590406
324.607,0.57028,-0.01349,,,,,0.03456242424,-0.01382738827
325.107,0.6117,-0.01284,,,,,0.03707272727,-0.01316113161
325.607,0.65318,-0.01065,,,,,0.03958666667,-0.01091635916
326.107,0.69525,-0.01182,,,,,0.04213636364,-0.01211562116
326.607,0.7366,-0.01155,,,,,0.04464242424,-0.01183886839
327.107,0.7783,-0.01359,,,,,0.04716969697,-0.0139298893
327.607,0.82026,-0.00935,,,,,0.04971272727,-0.009583845838
328.107,0.86141,-0.00979,,,,,0.05220666667,-0.01003485035
328.607,0.90344,-0.00779,,,,,0.05475393939,-0.007984829848
329.107,0.94518,-0.0074,,,,,0.05728363636,-0.007585075851
329.607,0.98646,-0.00616,,,,,0.05978545455,-0.006314063141
330.107,1.02847,-0.00608,,,,,0.06233151515,-0.006232062321
330.607,1.07004,-0.00841,,,,,0.06485090909,-0.008620336203
331.107,1.11165,-0.0063,,,,,0.06737272727,-0.006457564576
331.607,1.15347,-0.00549,,,,,0.06990727273,-0.005627306273
332.107,1.1948,-0.00367,,,,,0.07241212121,-0.003761787618
332.607,1.23681,-0.00414,,,,,0.07495818182,-0.004243542435
333.107,1.27852,-0.00391,,,,,0.07748606061,-0.004007790078
333.607,1.31971,-0.00291,,,,,0.07998242424,-0.002982779828
334.107,1.36188,-0.00251,,,,,0.08253818182,-0.002572775728
334.607,1.4034,-0.00424,,,,,0.08505454545,-0.00434604346
335.107,1.44481,-0.00013,,,,,0.08756424242,-0.0001332513325
335.607,1.48686,0.0012,,,,,0.09011272727,0.0012300123
336.107,1.52825,-0.00016,,,,,0.09262121212,-0.00016400164
336.607,1.57009,0.00116,,,,,0.0951569697,0.00118901189
337.107,1.61179,0.00099,,,,,0.09768424242,0.001014760148
337.565,1.65002,0.00276,,,,,0.1000012121,0.00282902829
337.867,1.62964,0.00073,,,,,0.09876606061,0.0007482574826
338.367,1.58789,0.00055,,,,,0.09623575758,0.0005637556376
338.867,1.54584,0.00281,,,,,0.09368727273,0.002880278803
339.367,1.50449,-0.00254,,,,,0.09118121212,-0.002603526035
339.867,1.46276,-0.00127,,,,,0.08865212121,-0.001301763018
340.367,1.42096,-0.00319,,,,,0.08611878788,-0.003269782698
340.867,1.37958,-0.00381,,,,,0.08361090909,-0.003905289053
341.367,1.3376,-0.00332,,,,,0.08106666667,-0.00340303403
341.867,1.29606,-0.00404,,,,,0.07854909091,-0.00414104141
342.367,1.2547,-0.00525,,,,,0.07604242424,-0.005381303813
342.867,1.21244,-0.00696,,,,,0.07348121212,-0.007134071341
343.367,1.1711,-0.00827,,,,,0.07097575758,-0.008476834768
343.867,1.1296,-0.00803,,,,,0.06846060606,-0.008230832308
344.367,1.08753,-0.00854,,,,,0.06591090909,-0.008753587536
344.867,1.04608,-0.00892,,,,,0.06339878788,-0.009143091431
345.367,1.00437,-0.00865,,,,,0.06087090909,-0.008866338663
345.867,0.96269,-0.01177,,,,,0.05834484848,-0.01206437064
346.367,0.92123,-0.01184,,,,,0.05583212121,-0.01213612136
346.867,0.87921,-0.01188,,,,,0.05328545455,-0.01217712177
347.367,0.83781,-0.01261,,,,,0.05077636364,-0.01292537925
347.867,0.7962,-0.01369,,,,,0.04825454545,-0.01403239032
348.367,0.75418,-0.01466,,,,,0.04570787879,-0.01502665027
348.867,0.71286,-0.01359,,,,,0.04320363636,-0.0139298893
349.367,0.67106,-0.01554,,,,,0.04067030303,-0.01592865929
349.867,0.62936,-0.01664,,,,,0.0381430303,-0.01705617056
350.367,0.58798,-0.01919,,,,,0.03563515152,-0.0196699467
350.867,0.54588,-0.01585,,,,,0.03308363636,-0.01624641246
351.367,0.50443,-0.01707,,,,,0.03057151515,-0.01749692497
351.867,0.46297,-0.01656,,,,,0.02805878788,-0.01697416974
352.367,0.42087,-0.01802,,,,,0.02550727273,-0.01847068471
352.867,0.37943,-0.02038,,,,,0.02299575758,-0.0208897089
353.367,0.33785,-0.0221,,,,,0.02047575758,-0.02265272653
353.867,0.29599,-0.02142,,,,,0.01793878788,-0.02195571956
354.367,0.25449,-0.02106,,,,,0.01542363636,-0.02158671587
354.867,0.21262,-0.02049,,,,,0.01288606061,-0.02100246002
355.367,0.17114,-0.02167,,,,,0.01037212121,-0.02221197212
355.867,0.12961,-0.02333,,,,,0.007855151515,-0.02391348913
356.367,0.08741,-0.02246,,,,,0.005297575758,-0.02302173022
356.867,0.04621,-0.02733,,,,,0.002800606061,-0.02801353014
357.367,0.00455,-0.02703,,,,,0.0002757575758,-0.02770602706
357.624,0.011,-0.02562,,,,,0.0006666666667,-0.02626076261
358.124,0.05348,-0.02538,,,,,0.003241212121,-0.02601476015
358.624,0.09507,-0.02225,,,,,0.005761818182,-0.02280647806
359.124,0.1364,-0.02243,,,,,0.008266666667,-0.02299097991
359.624,0.17842,-0.02023,,,,,0.01081333333,-0.02073595736
360.124,0.21985,-0.02079,,,,,0.01332424242,-0.0213099631
360.624,0.26168,-0.02033,,,,,0.01585939394,-0.02083845838
361.124,0.30342,-0.01705,,,,,0.01838909091,-0.01747642476
361.624,0.34471,-0.01815,,,,,0.02089151515,-0.01860393604
362.124,0.38681,-0.01748,,,,,0.0234430303,-0.01791717917
362.624,0.42839,-0.01718,,,,,0.0259630303,-0.0176096761
363.124,0.46963,-0.01627,,,,,0.02846242424,-0.01667691677
363.624,0.51184,-0.01607,,,,,0.03102060606,-0.01647191472
364.124,0.55321,-0.01381,,,,,0.03352787879,-0.01415539155
364.624,0.5949,-0.01218,,,,,0.03605454545,-0.01248462485
365.124,0.63674,-0.01407,,,,,0.03859030303,-0.01442189422
365.624,0.67807,-0.01099,,,,,0.04109515152,-0.01126486265
366.124,0.72007,-0.01353,,,,,0.04364060606,-0.01386838868
366.624,0.76178,-0.01221,,,,,0.04616848485,-0.01251537515
367.124,0.80305,-0.01073,,,,,0.04866969697,-0.01099835998
367.624,0.84513,-0.00963,,,,,0.05122,-0.009870848708
368.124,0.88671,-0.00906,,,,,0.05374,-0.009286592866
368.624,0.92817,-0.0084,,,,,0.05625272727,-0.008610086101
369.124,0.97009,-0.00737,,,,,0.05879333333,-0.007554325543
369.624,1.01139,-0.0086,,,,,0.06129636364,-0.008815088151
370.124,1.05345,-0.00649,,,,,0.06384545455,-0.006652316523
370.624,1.09501,-0.00844,,,,,0.06636424242,-0.008651086511
371.124,1.13638,-0.00555,,,,,0.06887151515,-0.005688806888
371.624,1.17846,-0.00549,,,,,0.07142181818,-0.005627306273
372.124,1.22005,-0.00442,,,,,0.07394242424,-0.004530545305
372.624,1.26134,-0.00187,,,,,0.07644484848,-0.001916769168
373.124,1.30358,-0.00417,,,,,0.07900484848,-0.004274292743
373.624,1.34488,-0.00123,,,,,0.08150787879,-0.001260762608
374.124,1.38658,-0.00252,,,,,0.08403515152,-0.00258302583
374.624,1.4285,0.00076,,,,,0.08657575758,0.0007790077901
375.124,1.46973,-0.00181,,,,,0.08907454545,-0.001855268553
375.624,1.51175,0.00111,,,,,0.09162121212,0.001137761378
376.124,1.55338,0.00037,,,,,0.09414424242,0.0003792537925
376.624,1.59476,0.00235,,,,,0.09665212121,0.002408774088
377.124,1.6367,0.00157,,,,,0.09919393939,0.001609266093
377.385,1.64692,0.00184,,,,,0.09981333333,0.00188601886
377.885,1.60434,0.00123,,,,,0.09723272727,0.001260762608
378.385,1.56291,-0.00044,,,,,0.09472181818,-0.00045100451
378.885,1.52098,-0.00025,,,,,0.09218060606,-0.0002562525625
379.385,1.47941,-0.00148,,,,,0.08966121212,-0.00151701517
379.885,1.43797,-0.00345,,,,,0.08714969697,-0.003536285363
380.385,1.39584,-0.00319,,,,,0.08459636364,-0.003269782698
380.885,1.35446,-0.00382,,,,,0.08208848485,-0.003915539155
381.385,1.31302,-0.00653,,,,,0.0795769697,-0.006693316933
381.885,1.27077,-0.00529,,,,,0.07701636364,-0.005422304223
382.385,1.22948,-0.00595,,,,,0.07451393939,-0.006098810988
382.885,1.18772,-0.00755,,,,,0.0719830303,-0.007738827388
383.385,1.1461,-0.00917,,,,,0.06946060606,-0.009399343993
383.885,1.10449,-0.00939,,,,,0.06693878788,-0.009624846248
384.385,1.06254,-0.01067,,,,,0.06439636364,-0.01093685937
384.885,1.02116,-0.00966,,,,,0.06188848485,-0.009901599016
385.385,0.97959,-0.01135,,,,,0.05936909091,-0.01163386634
385.885,0.93749,-0.01099,,,,,0.05681757576,-0.01126486265
386.385,0.8962,-0.01136,,,,,0.05431515152,-0.01164411644
386.885,0.85449,-0.01152,,,,,0.05178727273,-0.01180811808
387.385,0.81258,-0.01564,,,,,0.04924727273,-0.01603116031
387.885,0.77131,-0.01646,,,,,0.04674606061,-0.01687166872
388.385,0.72922,-0.01459,,,,,0.04419515152,-0.01495489955
388.885,0.68772,-0.01526,,,,,0.04168,-0.01564165642
389.385,0.64628,-0.01727,,,,,0.03916848485,-0.01770192702
389.885,0.60416,-0.0161,,,,,0.03661575758,-0.01650266503
390.385,0.56271,-0.01787,,,,,0.03410363636,-0.01831693317
390.885,0.52123,-0.01969,,,,,0.03158969697,-0.02018245182
391.385,0.47927,-0.01936,,,,,0.02904666667,-0.01984419844
391.885,0.43782,-0.02114,,,,,0.02653454545,-0.02166871669
392.385,0.39601,-0.01991,,,,,0.02400060606,-0.02040795408
392.885,0.35443,-0.02199,,,,,0.02148060606,-0.0225399754
393.385,0.31291,-0.02021,,,,,0.01896424242,-0.02071545715
393.885,0.27084,-0.02212,,,,,0.01641454545,-0.02267322673
394.385,0.22955,-0.02284,,,,,0.01391212121,-0.02341123411
394.885,0.18784,-0.02474,,,,,0.01138424242,-0.02535875359
395.385,0.14588,-0.02556,,,,,0.008841212121,-0.02619926199
395.885,0.1045,-0.02536,,,,,0.006333333333,-0.02599425994
396.385,0.06272,-0.02617,,,,,0.003801212121,-0.02682451825
396.885,0.02096,-0.02583,,,,,0.00127030303,-0.02647601476
397.14,-0.00007,-0.02472,,,,,-0.000004242424242,-0.02533825338