File: mechanical/hysteresis/databak/hmwg_hysteresis - conductive_1.csv
Time,Extension,Load,Length,Width,Thickness,CS Area,Strain,Stress
(s),(mm),(N),(mm),(mm),(mm),(mm^2),(mm/mm),(MPa)
0,0,-0.01386,16.5,2.82,0.31,0.8742,0,-0.01585449554
0.5,0.0386,0.09297,,,,,0.002339393939,0.1063486616
1,0.08049,0.15094,,,,,0.004878181818,0.1726607184
1.5,0.12187,0.19143,,,,,0.007386060606,0.2189773507
2,0.16384,0.22654,,,,,0.00992969697,0.2591397849
2.5,0.20542,0.2597,,,,,0.01244969697,0.2970716083
3,0.24671,0.28789,,,,,0.01495212121,0.3293182338
3.5,0.28896,0.31985,,,,,0.01751272727,0.3658773736
4,0.33039,0.34774,,,,,0.02002363636,0.3977808282
4.5,0.37192,0.37228,,,,,0.02254060606,0.4258522077
5,0.41395,0.40171,,,,,0.02508787879,0.4595172729
5.5,0.45525,0.42587,,,,,0.02759090909,0.4871539693
6,0.49705,0.4507,,,,,0.03012424242,0.5155570808
6.5,0.53896,0.47684,,,,,0.03266424242,0.5454587051
7,0.58009,0.49983,,,,,0.0351569697,0.571757035
7.5,0.62215,0.52252,,,,,0.03770606061,0.597712194
8,0.66383,0.54657,,,,,0.04023212121,0.6252230611
8.5,0.70519,0.56678,,,,,0.04273878788,0.6483413407
9,0.74719,0.59002,,,,,0.04528424242,0.6749256463
9.5,0.78867,0.61052,,,,,0.04779818182,0.6983756577
10,0.83039,0.62748,,,,,0.05032666667,0.7177762526
10.5,0.87215,0.64877,,,,,0.05285757576,0.7421299474
11,0.91347,0.66302,,,,,0.05536181818,0.7584305651
11.5,0.95554,0.68203,,,,,0.05791151515,0.7801761611
12,0.99717,0.69742,,,,,0.06043454545,0.7977808282
12.5,1.03844,0.70722,,,,,0.06293575758,0.8089910776
13,1.08061,0.72268,,,,,0.06549151515,0.8266758179
13.5,1.1221,0.73383,,,,,0.06800606061,0.8394303363
14,1.16361,0.74281,,,,,0.07052181818,0.8497025852
14.5,1.20552,0.75539,,,,,0.07306181818,0.8640928849
15,1.24686,0.76317,,,,,0.07556727273,0.8729924502
15.5,1.28881,0.77216,,,,,0.07810969697,0.8832761382
16,1.33049,0.78115,,,,,0.08063575758,0.8935598261
16.5,1.37176,0.7868,,,,,0.0831369697,0.9000228781
17,1.41389,0.79795,,,,,0.08569030303,0.9127773965
17.5,1.45544,0.80299,,,,,0.08820848485,0.9185426676
18,1.49693,0.80887,,,,,0.0907230303,0.9252688172
18.5,1.53886,0.81822,,,,,0.09326424242,0.9359643102
19,1.5803,0.82186,,,,,0.09577575758,0.9401281171
19.5,1.62212,0.82542,,,,,0.09831030303,0.9442004118
19.838,1.65012,0.82948,,,,,0.1000072727,0.948844658
20.239,1.62141,0.61859,,,,,0.09826727273,0.7076069549
20.739,1.58001,0.47437,,,,,0.09575818182,0.5426332647
21.239,1.5382,0.36952,,,,,0.09322424242,0.4226950355
21.739,1.49647,0.28384,,,,,0.09069515152,0.3246854267
22.239,1.45515,0.21977,,,,,0.08819090909,0.2513955617
22.739,1.41299,0.16082,,,,,0.08563575758,0.18396248
23.239,1.3716,0.1106,,,,,0.08312727273,0.1265156715
23.739,1.33013,0.06661,,,,,0.08061393939,0.07619537863
24.239,1.28801,0.02344,,,,,0.07806121212,0.02681308625
24.739,1.24655,-0.01205,,,,,0.07554848485,-0.01378403111
25.239,1.20497,-0.04459,,,,,0.07302848485,-0.05100663464
25.739,1.16317,-0.07687,,,,,0.07049515152,-0.08793182338
26.239,1.12168,-0.10344,,,,,0.06798060606,-0.118325326
26.739,1.07976,-0.12877,,,,,0.06544,-0.1473003889
27.239,1.03828,-0.15503,,,,,0.06292606061,-0.1773392816
27.739,0.99673,-0.17628,,,,,0.06040787879,-0.2016472203
28.239,0.95465,-0.2015,,,,,0.05785757576,-0.2304964539
28.739,0.91333,-0.22019,,,,,0.05535333333,-0.2518760009
29.239,0.87162,-0.23797,,,,,0.05282545455,-0.2722145962
29.739,0.82978,-0.25747,,,,,0.05028969697,-0.2945207046
30.239,0.78837,-0.27304,,,,,0.04778,-0.3123312743
30.739,0.74645,-0.29162,,,,,0.04523939394,-0.333584992
31.239,0.70491,-0.30823,,,,,0.04272181818,-0.3525852208
31.739,0.66345,-0.32301,,,,,0.04020909091,-0.3694921071
32.239,0.62137,-0.33763,,,,,0.03765878788,-0.3862159689
32.739,0.57995,-0.35107,,,,,0.03514848485,-0.4015900252
33.239,0.53844,-0.36342,,,,,0.03263272727,-0.4157172272
33.739,0.49642,-0.37864,,,,,0.03008606061,-0.4331274308
34.239,0.45493,-0.39112,,,,,0.02757151515,-0.4474033402
34.739,0.41323,-0.40334,,,,,0.02504424242,-0.4613818348
35.239,0.37158,-0.41553,,,,,0.02252,-0.4753260124
35.739,0.33006,-0.42579,,,,,0.02000363636,-0.4870624571
36.239,0.28798,-0.43506,,,,,0.01745333333,-0.4976664379
36.739,0.24667,-0.44345,,,,,0.01494969697,-0.507263784
37.239,0.2051,-0.44837,,,,,0.01243030303,-0.5128917868
37.739,0.16296,-0.44989,,,,,0.009876363636,-0.5146305193
38.239,0.12163,-0.45135,,,,,0.007371515152,-0.5163006177
38.739,0.08002,-0.45171,,,,,0.00484969697,-0.5167124228
39.239,0.03807,-0.45096,,,,,0.002307272727,-0.5158544955
39.698,-0.00001,-0.45121,,,,,-0.0000006060606061,-0.5161404713
40,0.02028,-0.44284,,,,,0.001229090909,-0.5065660032
40.5,0.06187,-0.4194,,,,,0.00374969697,-0.479752917
41,0.10392,-0.33469,,,,,0.006298181818,-0.3828528941
41.5,0.14526,-0.27203,,,,,0.008803636364,-0.3111759323
42,0.18704,-0.22605,,,,,0.01133575758,-0.2585792725
42.5,0.22893,-0.18316,,,,,0.01387454545,-0.2095172729
43,0.27008,-0.14977,,,,,0.01636848485,-0.1713223519
43.5,0.31223,-0.11467,,,,,0.0189230303,-0.1311713567
44,0.35383,-0.08394,,,,,0.02144424242,-0.09601921757
44.5,0.39517,-0.05598,,,,,0.02394969697,-0.06403568977
45,0.43721,-0.0269,,,,,0.02649757576,-0.03077099062
45.5,0.47872,0.00111,,,,,0.02901333333,0.001269732327
46,0.52038,0.02589,,,,,0.03153818182,0.02961564859
46.5,0.56216,0.05538,,,,,0.03407030303,0.06334934798
47,0.60347,0.0785,,,,,0.03657393939,0.08979638527
47.5,0.64557,0.1056,,,,,0.03912545455,0.1207961565
48,0.6871,0.13128,,,,,0.04164242424,0.1501715854
48.5,0.7284,0.15437,,,,,0.04414545455,0.1765843057
49,0.77066,0.1826,,,,,0.04670666667,0.2088766873
49.5,0.812,0.20665,,,,,0.04921212121,0.2363875543
50,0.85363,0.23113,,,,,0.05173515152,0.2643902997
50.5,0.8956,0.25793,,,,,0.05427878788,0.2950469
51,0.93682,0.28044,,,,,0.0567769697,0.3207961565
51.5,0.97877,0.30467,,,,,0.05931939394,0.3485129261
52,1.02059,0.33013,,,,,0.06185393939,0.3776366964
52.5,1.06175,0.35209,,,,,0.06434848485,0.4027568062
53,1.10384,0.37879,,,,,0.06689939394,0.4332990162
53.5,1.14545,0.40467,,,,,0.06942121212,0.4629032258
54,1.18693,0.42733,,,,,0.07193515152,0.4888240677
54.5,1.22889,0.45434,,,,,0.07447818182,0.5197208877
55,1.27023,0.47653,,,,,0.07698363636,0.5451040952
55.5,1.31213,0.49783,,,,,0.0795230303,0.569469229
56,1.35381,0.52338,,,,,0.08204909091,0.5986959506
56.5,1.39509,0.54597,,,,,0.08455090909,0.6245367193
57,1.43727,0.57089,,,,,0.08710727273,0.653042782
57.5,1.47882,0.59286,,,,,0.08962545455,0.6781743308
58,1.52014,0.61154,,,,,0.09212969697,0.6995424388
58.5,1.56222,0.63441,,,,,0.09468,0.7257035003
59,1.60368,0.65114,,,,,0.09719272727,0.7448409975
59.5,1.64536,0.66946,,,,,0.09971878788,0.7657973004
59.759,1.6387,0.56179,,,,,0.09931515152,0.6426332647
60.259,1.59639,0.39869,,,,,0.09675090909,0.4560626859
60.759,1.55495,0.29466,,,,,0.09423939394,0.3370624571
61.259,1.51354,0.21761,,,,,0.09172969697,0.2489247312
61.759,1.47122,0.15035,,,,,0.08916484848,0.1719858156
62.259,1.42999,0.09604,,,,,0.08666606061,0.1098604438
62.759,1.38833,0.04808,,,,,0.08414121212,0.0549988561
63.259,1.34654,0.00476,,,,,0.08160848485,0.005444978266
63.759,1.30498,-0.03312,,,,,0.07908969697,-0.03788606726
64.259,1.26316,-0.06627,,,,,0.07655515152,-0.07580645161
64.759,1.22158,-0.09813,,,,,0.07403515152,-0.1122512011
65.259,1.18006,-0.12518,,,,,0.07151878788,-0.1431937772
65.759,1.13798,-0.15231,,,,,0.06896848485,-0.1742278655
66.259,1.09668,-0.17684,,,,,0.06646545455,-0.202287806
66.759,1.05507,-0.19909,,,,,0.06394363636,-0.2277396477
67.259,1.013,-0.22348,,,,,0.06139393939,-0.2556394418
67.759,0.97177,-0.24256,,,,,0.05889515152,-0.277465111
68.259,0.92984,-0.26109,,,,,0.05635393939,-0.2986616335
68.759,0.88813,-0.28164,,,,,0.05382606061,-0.3221688401
69.259,0.84672,-0.29643,,,,,0.05131636364,-0.3390871654
69.759,0.80475,-0.31201,,,,,0.04877272727,-0.3569091741
70.259,0.76321,-0.32867,,,,,0.04625515152,-0.375966598
70.759,0.72178,-0.34342,,,,,0.04374424242,-0.3928391672
71.259,0.67969,-0.35997,,,,,0.04119333333,-0.4117707618
71.759,0.63824,-0.37401,,,,,0.03868121212,-0.4278311599
72.259,0.59664,-0.38735,,,,,0.03616,-0.4430908259
72.759,0.55485,-0.40061,,,,,0.03362727273,-0.4582589796
73.259,0.51333,-0.4112,,,,,0.03111090909,-0.4703729124
73.759,0.47139,-0.42264,,,,,0.02856909091,-0.4834591627
74.259,0.43002,-0.434,,,,,0.02606181818,-0.4964539007
74.759,0.38834,-0.4437,,,,,0.02353575758,-0.5075497598
75.259,0.34636,-0.45149,,,,,0.02099151515,-0.5164607641
75.759,0.30497,-0.45391,,,,,0.0184830303,-0.5192290094
76.259,0.26329,-0.45458,,,,,0.0159569697,-0.5199954244
76.759,0.22134,-0.45355,,,,,0.01341454545,-0.5188172043
77.259,0.18003,-0.45153,,,,,0.01091090909,-0.5165065202
77.759,0.13814,-0.45279,,,,,0.008372121212,-0.517947838
78.259,0.09655,-0.45263,,,,,0.005851515152,-0.5177648135
78.759,0.05515,-0.45035,,,,,0.003342424242,-0.5151567147
79.259,0.013,-0.44961,,,,,0.0007878787879,-0.5143102265
79.52,0.00268,-0.45082,,,,,0.0001624242424,-0.5156943491
80.02,0.0455,-0.44336,,,,,0.002757575758,-0.5071608328
80.52,0.08668,-0.4358,,,,,0.005253333333,-0.4985129261
81.02,0.12874,-0.40917,,,,,0.007802424242,-0.4680507893
81.52,0.1705,-0.34382,,,,,0.01033333333,-0.3932967284
82.02,0.21171,-0.28826,,,,,0.01283090909,-0.3297414779
82.52,0.25393,-0.24199,,,,,0.01538969697,-0.2768130863
83.02,0.29538,-0.20479,,,,,0.01790181818,-0.2342598948
83.52,0.337,-0.17102,,,,,0.02042424242,-0.1956302906
84.02,0.37882,-0.14069,,,,,0.02295878788,-0.1609357127
84.52,0.42017,-0.11213,,,,,0.02546484848,-0.1282658431
85.02,0.46219,-0.08508,,,,,0.02801151515,-0.09732326699
85.52,0.5038,-0.05888,,,,,0.03053333333,-0.06735300846
86.02,0.54505,-0.03425,,,,,0.03303333333,-0.03917867765
86.52,0.58727,-0.00646,,,,,0.03559212121,-0.007389613361
87.02,0.62875,0.01752,,,,,0.03810606061,0.02004118051
87.52,0.67012,0.03968,,,,,0.04061333333,0.04539007092
88.02,0.71225,0.06604,,,,,0.04316666667,0.07554335392
88.52,0.75349,0.08958,,,,,0.04566606061,0.1024708305
89.02,0.79548,0.11312,,,,,0.04821090909,0.129398307
89.52,0.83713,0.1378,,,,,0.05073515152,0.157629833
90.02,0.87846,0.16037,,,,,0.05324,0.1834477236
90.52,0.92055,0.18363,,,,,0.05579090909,0.2100549073
91.02,0.96219,0.20888,,,,,0.05831454545,0.238938458
91.52,1.00353,0.23028,,,,,0.06082,0.2634179822
92.02,1.04553,0.25704,,,,,0.06336545455,0.2940288264
92.52,1.08701,0.27991,,,,,0.06587939394,0.3201898879
93.02,1.12873,0.30244,,,,,0.06840787879,0.3459620224
93.52,1.17047,0.32977,,,,,0.07093757576,0.3772248913
94.02,1.21172,0.35042,,,,,0.07343757576,0.4008464882
94.52,1.25392,0.37599,,,,,0.07599515152,0.4300960879
95.02,1.29542,0.39998,,,,,0.07851030303,0.4575383208
95.52,1.33681,0.42195,,,,,0.08101878788,0.4826698696
96.02,1.37888,0.44839,,,,,0.08356848485,0.5129146648
96.52,1.42035,0.47337,,,,,0.08608181818,0.5414893617
97.02,1.46191,0.49543,,,,,0.08860060606,0.5667238618
97.52,1.50396,0.52106,,,,,0.09114909091,0.5960420956
98.02,1.54518,0.54225,,,,,0.09364727273,0.6202814001
98.52,1.58712,0.56535,,,,,0.09618909091,0.6467055594
99.02,1.62886,0.5896,,,,,0.09871878788,0.674445207
99.279,1.65021,0.60075,,,,,0.1000127273,0.6871997255
99.779,1.61331,0.39179,,,,,0.09777636364,0.4481697552
100.279,1.57181,0.28064,,,,,0.09526121212,0.3210249371
100.779,1.52976,0.19548,,,,,0.09271272727,0.2236101579
101.279,1.48827,0.13047,,,,,0.09019818182,0.149245024
101.779,1.44658,0.07605,,,,,0.08767151515,0.08699382292
102.279,1.40497,0.02713,,,,,0.08514969697,0.03103408831
102.779,1.36346,-0.01535,,,,,0.08263393939,-0.017558911
103.279,1.32142,-0.05293,,,,,0.08008606061,-0.06054678563
103.779,1.28006,-0.08636,,,,,0.07757939394,-0.09878746282
104.279,1.23844,-0.11573,,,,,0.0750569697,-0.1323838938
104.779,1.19642,-0.14552,,,,,0.07251030303,-0.1664607641
105.279,1.15505,-0.17097,,,,,0.0700030303,-0.1955730954
105.779,1.11326,-0.19479,,,,,0.06747030303,-0.2228208648
106.279,1.07154,-0.21867,,,,,0.06494181818,-0.2501372684
106.779,1.03017,-0.23854,,,,,0.06243454545,-0.2728666209
107.279,0.98804,-0.2589,,,,,0.05988121212,-0.2961564859
107.779,0.94664,-0.27767,,,,,0.05737212121,-0.3176275452
108.279,0.90515,-0.2939,,,,,0.05485757576,-0.3361930908
108.779,0.86309,-0.31249,,,,,0.05230848485,-0.3574582475
109.279,0.82165,-0.32781,,,,,0.0497969697,-0.3749828415
109.779,0.78005,-0.34349,,,,,0.04727575758,-0.3929192404
110.279,0.73822,-0.3586,,,,,0.04474060606,-0.4102036147
110.779,0.69673,-0.37165,,,,,0.04222606061,-0.4251315488
111.279,0.65482,-0.38369,,,,,0.03968606061,-0.4389041409
111.779,0.61337,-0.39798,,,,,0.03717393939,-0.4552505148
112.279,0.57183,-0.41024,,,,,0.03465636364,-0.4692747655
112.779,0.52962,-0.42403,,,,,0.03209818182,-0.4850491878
113.279,0.48841,-0.43413,,,,,0.02960060606,-0.4966026081
113.779,0.44673,-0.44353,,,,,0.02707454545,-0.5073552963
114.279,0.40473,-0.44975,,,,,0.02452909091,-0.5144703729
114.779,0.36334,-0.45043,,,,,0.02202060606,-0.515248227
115.279,0.32162,-0.45104,,,,,0.01949212121,-0.5159460078
115.779,0.27985,-0.45038,,,,,0.01696060606,-0.5151910318
116.279,0.23848,-0.45096,,,,,0.01445333333,-0.5158544955
116.779,0.19643,-0.45021,,,,,0.01190484848,-0.5149965683
117.279,0.15497,-0.45054,,,,,0.009392121212,-0.5153740563
117.779,0.11346,-0.44729,,,,,0.006876363636,-0.5116563715
118.279,0.07141,-0.44708,,,,,0.004327878788,-0.5114161519
118.779,0.03,-0.44725,,,,,0.001818181818,-0.5116106154
119.14,-0.00012,-0.44792,,,,,-0.000007272727273,-0.5123770304
119.541,0.02835,-0.44547,,,,,0.001718181818,-0.5095744681
120.041,0.07051,-0.44362,,,,,0.004273333333,-0.5074582475
120.541,0.1121,-0.43892,,,,,0.006793939394,-0.5020819035
121.041,0.15354,-0.42178,,,,,0.009305454545,-0.4824754061
121.541,0.19552,-0.3665,,,,,0.01184969697,-0.4192404484
122.041,0.23695,-0.30861,,,,,0.01436060606,-0.3530199039
122.541,0.27879,-0.26525,,,,,0.01689636364,-0.30342027
123.041,0.32042,-0.22864,,,,,0.01941939394,-0.2615419812
123.541,0.36177,-0.19778,,,,,0.02192545455,-0.2262411348
124.041,0.40387,-0.16804,,,,,0.0244769697,-0.1922214596
124.541,0.44528,-0.13887,,,,,0.02698666667,-0.1588538092
125.041,0.48676,-0.11345,,,,,0.02950060606,-0.129775795
125.541,0.52889,-0.08596,,,,,0.03205393939,-0.09832990162
126.041,0.57017,-0.06153,,,,,0.03455575758,-0.07038435141
126.541,0.612,-0.03813,,,,,0.03709090909,-0.04361702128
127.041,0.65384,-0.01401,,,,,0.03962666667,-0.01602608099
127.541,0.69503,0.00803,,,,,0.0421230303,0.009185541066
128.041,0.73715,0.03421,,,,,0.04467575758,0.03913292153
128.541,0.77886,0.05581,,,,,0.04720363636,0.06384122626
129.041,0.8201,0.07806,,,,,0.0497030303,0.08929306795
129.541,0.86216,0.10245,,,,,0.05225212121,0.117192862
130.041,0.90368,0.12659,,,,,0.05476848485,0.1448066804
130.541,0.94533,0.14571,,,,,0.05729272727,0.1666781057
131.041,0.98712,0.17174,,,,,0.05982545455,0.1964539007
131.541,1.02842,0.19351,,,,,0.06232848485,0.221356669
132.041,1.07044,0.21653,,,,,0.06487515152,0.2476893159
132.541,1.11207,0.23916,,,,,0.06739818182,0.2735758408
133.041,1.15331,0.26373,,,,,0.06989757576,0.3016815374
133.541,1.19555,0.28691,,,,,0.07245757576,0.3281972089
134.041,1.23706,0.31303,,,,,0.07497333333,0.3580759552
134.541,1.27854,0.33308,,,,,0.07748727273,0.3810112102
135.041,1.32047,0.35947,,,,,0.08002848485,0.4111988103
135.541,1.36186,0.38344,,,,,0.0825369697,0.4386181652
136.041,1.40377,0.4071,,,,,0.0850769697,0.4656829101
136.541,1.44547,0.43241,,,,,0.08760424242,0.4946350949
137.041,1.48676,0.45478,,,,,0.09010666667,0.520224205
137.541,1.52887,0.48041,,,,,0.09265878788,0.5495424388
138.041,1.57047,0.5051,,,,,0.09518,0.5777854038
138.541,1.61182,0.52608,,,,,0.09768606061,0.6017844887
138.999,1.65006,0.54715,,,,,0.1000036364,0.6258865248
139.301,1.63011,0.40913,,,,,0.09879454545,0.4680050332
139.801,1.58847,0.27992,,,,,0.09627090909,0.3202013269
140.301,1.54687,0.19446,,,,,0.09374969697,0.2224433768
140.801,1.50488,0.1252,,,,,0.09120484848,0.1432166552
141.301,1.4635,0.07078,,,,,0.0886969697,0.08096545413
141.801,1.42192,0.02174,,,,,0.0861769697,0.02486845116
142.301,1.37979,-0.02349,,,,,0.08362363636,-0.0268702814
142.801,1.33848,-0.05879,,,,,0.08112,-0.0672500572
143.301,1.29676,-0.09101,,,,,0.07859151515,-0.1041066118
143.801,1.25488,-0.12422,,,,,0.07605333333,-0.1420956303
144.301,1.21361,-0.15029,,,,,0.07355212121,-0.1719171814
144.801,1.17152,-0.17656,,,,,0.07100121212,-0.2019675132
145.301,1.13004,-0.20184,,,,,0.06848727273,-0.2308853809
145.801,1.08858,-0.22258,,,,,0.06597454545,-0.2546099291
146.301,1.0465,-0.24731,,,,,0.06342424242,-0.2828986502
146.801,1.00506,-0.26573,,,,,0.06091272727,-0.3039693434
147.301,0.96354,-0.28326,,,,,0.05839636364,-0.3240219629
147.801,0.9216,-0.30137,,,,,0.05585454545,-0.3447380462
148.301,0.88012,-0.31788,,,,,0.05334060606,-0.3636238847
148.801,0.83835,-0.33278,,,,,0.05080909091,-0.3806680394
149.301,0.79674,-0.34875,,,,,0.04828727273,-0.3989361702
149.801,0.75521,-0.36263,,,,,0.04577030303,-0.4148135438
150.301,0.71316,-0.37708,,,,,0.04322181818,-0.4313429421
150.801,0.6718,-0.39012,,,,,0.04071515152,-0.4462594372
151.301,0.63011,-0.40308,,,,,0.03818848485,-0.46108442
151.801,0.58819,-0.41645,,,,,0.03564787879,-0.4763784031
152.301,0.54682,-0.42762,,,,,0.03314060606,-0.4891557996
152.801,0.50499,-0.43799,,,,,0.03060545455,-0.5010180737
153.301,0.46331,-0.44528,,,,,0.02807939394,-0.5093571265
153.801,0.42194,-0.44841,,,,,0.02557212121,-0.5129375429
154.301,0.37989,-0.44807,,,,,0.02302363636,-0.5125486159
154.801,0.33843,-0.44772,,,,,0.02051090909,-0.5121482498
155.301,0.297,-0.44836,,,,,0.018,-0.5128803477
155.801,0.25487,-0.44881,,,,,0.01544666667,-0.5133951041
156.301,0.21342,-0.44899,,,,,0.01293454545,-0.5136010066
156.801,0.17178,-0.44832,,,,,0.01041090909,-0.5128345916
157.301,0.13,-0.44784,,,,,0.007878787879,-0.5122855182
157.801,0.08845,-0.44719,,,,,0.005360606061,-0.5115419812
158.301,0.04656,-0.4476,,,,,0.002821818182,-0.5120109815
158.801,0.00513,-0.44788,,,,,0.0003109090909,-0.5123312743
159.064,0.01194,-0.44796,,,,,0.0007236363636,-0.5124227865
159.564,0.05359,-0.44433,,,,,0.003247878788,-0.5082704187
160.064,0.09542,-0.44269,,,,,0.005783030303,-0.5063944178
160.564,0.13713,-0.43689,,,,,0.008310909091,-0.4997597804
161.064,0.17843,-0.42267,,,,,0.01081393939,-0.4834934798
161.564,0.22055,-0.36809,,,,,0.01336666667,-0.4210592542
162.064,0.26211,-0.31428,,,,,0.01588545455,-0.3595058339
162.564,0.3034,-0.27344,,,,,0.01838787879,-0.3127888355
163.064,0.34558,-0.23581,,,,,0.02094424242,-0.2697437657
163.564,0.387,-0.20481,,,,,0.02345454545,-0.2342827728
164.064,0.42856,-0.17659,,,,,0.02597333333,-0.2020018302
164.564,0.47059,-0.14788,,,,,0.02852060606,-0.1691603752
165.064,0.51175,-0.12427,,,,,0.03101515152,-0.1421528254
165.564,0.55387,-0.09917,,,,,0.03356787879,-0.1134408602
166.064,0.59549,-0.0746,,,,,0.03609030303,-0.08533516358
166.564,0.63679,-0.0532,,,,,0.03859333333,-0.06085563944
167.064,0.67883,-0.02832,,,,,0.04114121212,-0.03239533288
167.564,0.72048,-0.00497,,,,,0.04366545455,-0.005685197895
168.064,0.76193,0.01698,,,,,0.04617757576,0.01942347289
168.564,0.80382,0.04225,,,,,0.04871636364,0.04832990162
169.064,0.84518,0.06091,,,,,0.0512230303,0.06967513155
169.564,0.88716,0.08366,,,,,0.05376727273,0.09569892473
170.064,0.92879,0.1064,,,,,0.05629030303,0.1217112789
170.564,0.97002,0.12776,,,,,0.05878909091,0.1461450469
171.064,1.01228,0.1521,,,,,0.06135030303,0.1739876458
171.564,1.05371,0.17577,,,,,0.06386121212,0.2010638298
172.064,1.09522,0.19735,,,,,0.0663769697,0.2257492565
172.564,1.13723,0.22164,,,,,0.0689230303,0.2535346603
173.064,1.17857,0.24426,,,,,0.07142848485,0.2794097461
173.564,1.22036,0.26652,,,,,0.07396121212,0.3048730268
174.064,1.26226,0.29059,,,,,0.07650060606,0.3324067719
174.564,1.30343,0.3132,,,,,0.07899575758,0.3582704187
175.064,1.34549,0.33871,,,,,0.08154484848,0.3874513841
175.564,1.38713,0.36413,,,,,0.08406848485,0.4165293983
176.064,1.42849,0.38599,,,,,0.08657515152,0.4415351178
176.564,1.47047,0.41171,,,,,0.08911939394,0.4709563029
177.064,1.51197,0.43449,,,,,0.09163454545,0.4970144132
177.564,1.55365,0.45674,,,,,0.09416060606,0.5224662549
178.064,1.59545,0.48453,,,,,0.09669393939,0.5542553191
178.564,1.63672,0.50711,,,,,0.09919515152,0.5800846488
178.824,1.64781,0.47213,,,,,0.09986727273,0.540070922
179.324,1.60543,0.30065,,,,,0.09729878788,0.3439144361
179.824,1.56338,0.20109,,,,,0.09475030303,0.2300274537
180.324,1.52199,0.12818,,,,,0.09224181818,0.1466254862
180.824,1.48026,0.07151,,,,,0.08971272727,0.08180050332
181.324,1.43851,0.0207,,,,,0.08718242424,0.02367879204
181.824,1.39705,-0.02124,,,,,0.08466969697,-0.02429649966
182.324,1.35509,-0.05908,,,,,0.08212666667,-0.06758178906
182.824,1.31361,-0.09331,,,,,0.07961272727,-0.1067375887
183.324,1.27223,-0.12262,,,,,0.07710484848,-0.1402653855
183.824,1.22994,-0.15335,,,,,0.07454181818,-0.1754175246
184.324,1.18868,-0.17838,,,,,0.07204121212,-0.2040494166
184.824,1.14706,-0.20347,,,,,0.06951878788,-0.2327499428
185.324,1.10517,-0.22592,,,,,0.06698,-0.2584305651
185.824,1.06364,-0.24521,,,,,0.0644630303,-0.2804964539
186.324,1.02188,-0.26403,,,,,0.06193212121,-0.3020247083
186.824,0.98026,-0.28426,,,,,0.05940969697,-0.3251658659
187.324,0.93872,-0.30201,,,,,0.05689212121,-0.3454701441
187.824,0.89667,-0.31973,,,,,0.05434363636,-0.3657401052
188.324,0.85535,-0.33554,,,,,0.05183939394,-0.3838252116
188.824,0.81375,-0.34875,,,,,0.04931818182,-0.3989361702
189.324,0.77161,-0.36648,,,,,0.04676424242,-0.4192175704
189.824,0.73042,-0.37894,,,,,0.04426787879,-0.4334706017
190.324,0.68857,-0.392,,,,,0.04173151515,-0.4484099748
190.824,0.64682,-0.40669,,,,,0.03920121212,-0.4652139099
191.324,0.60544,-0.41719,,,,,0.03669333333,-0.4772248913
191.824,0.56348,-0.42941,,,,,0.03415030303,-0.491203386
192.324,0.52187,-0.43945,,,,,0.03162848485,-0.502688172
192.824,0.48049,-0.44605,,,,,0.02912060606,-0.5102379318
193.324,0.43838,-0.45008,,,,,0.02656848485,-0.5148478609
193.824,0.39694,-0.45033,,,,,0.0240569697,-0.5151338367
194.324,0.35534,-0.45048,,,,,0.02153575758,-0.5153054221
194.824,0.31348,-0.45018,,,,,0.01899878788,-0.5149622512
195.324,0.27201,-0.44838,,,,,0.01648545455,-0.5129032258
195.824,0.23009,-0.44771,,,,,0.01394484848,-0.5121368108
196.324,0.1887,-0.44727,,,,,0.01143636364,-0.5116334935
196.824,0.14699,-0.44783,,,,,0.008908484848,-0.5122740792
197.324,0.105,-0.44679,,,,,0.006363636364,-0.51108442
197.824,0.06365,-0.44792,,,,,0.003857575758,-0.5123770304
198.324,0.02201,-0.448,,,,,0.001333939394,-0.5124685427
198.59,-0.0002,-0.44902,,,,,-0.00001212121212,-0.5136353237
199.09,0.03709,-0.4469,,,,,0.002247878788,-0.5112102494
199.59,0.07865,-0.44433,,,,,0.004766666667,-0.5082704187
200.09,0.12002,-0.44166,,,,,0.007273939394,-0.5052161977
200.59,0.16213,-0.43541,,,,,0.009826060606,-0.4980668039
201.09,0.2035,-0.41572,,,,,0.01233333333,-0.4755433539
201.59,0.24517,-0.36144,,,,,0.01485878788,-0.4134522992
202.09,0.28711,-0.30827,,,,,0.01740060606,-0.3526309769
202.59,0.32832,-0.27065,,,,,0.01989818182,-0.3095973461
203.09,0.37032,-0.23684,,,,,0.02244363636,-0.2709219858
203.59,0.41212,-0.20601,,,,,0.0249769697,-0.2356554564
204.09,0.45326,-0.17943,,,,,0.02747030303,-0.2052505148
204.59,0.49548,-0.15225,,,,,0.03002909091,-0.1741592313
205.09,0.53702,-0.12749,,,,,0.03254666667,-0.1458361931
205.59,0.57844,-0.10521,,,,,0.0350569697,-0.1203500343
206.09,0.62038,-0.08055,,,,,0.03759878788,-0.09214138641
206.59,0.66179,-0.05776,,,,,0.04010848485,-0.06607183711
207.09,0.7037,-0.0363,,,,,0.04264848485,-0.04152367879
207.59,0.74537,-0.013,,,,,0.04517393939,-0.01487073896
208.09,0.78663,0.00662,,,,,0.04767454545,0.00757263784
208.59,0.82878,0.02877,,,,,0.05022909091,0.03291008922
209.09,0.87036,0.05303,,,,,0.05274909091,0.06066117593
209.59,0.91165,0.07322,,,,,0.05525151515,0.08375657744
210.09,0.95384,0.09772,,,,,0.05780848485,0.1117822009
210.59,0.99517,0.11764,,,,,0.06031333333,0.1345687486
211.09,1.03696,0.13812,,,,,0.06284606061,0.1579958819
211.59,1.07872,0.16193,,,,,0.0653769697,0.1852322123
212.09,1.12006,0.18284,,,,,0.06788242424,0.209151224
212.59,1.16209,0.20649,,,,,0.07042969697,0.2362045299
213.09,1.2037,0.2309,,,,,0.07295151515,0.264127202
213.59,1.24499,0.25244,,,,,0.07545393939,0.2887668726
214.09,1.28707,0.27661,,,,,0.07800424242,0.316415008
214.59,1.32865,0.29939,,,,,0.08052424242,0.3424731183
215.09,1.37018,0.32043,,,,,0.08304121212,0.3665408373
215.59,1.41207,0.34787,,,,,0.08558,0.3979295356
216.09,1.45328,0.37006,,,,,0.08807757576,0.4233127431
216.59,1.49545,0.39642,,,,,0.09063333333,0.4534660261
217.09,1.53699,0.42062,,,,,0.09315090909,0.4811484786
217.59,1.57839,0.44281,,,,,0.09566,0.5065316861
218.09,1.62047,0.46796,,,,,0.09821030303,0.5353008465
218.45,1.65018,0.48626,,,,,0.1000109091,0.5562342713
218.851,1.6217,0.32211,,,,,0.09828484848,0.3684625944
219.351,1.58031,0.21357,,,,,0.09577636364,0.2443033631
219.851,1.53844,0.1359,,,,,0.09323878788,0.1554564173
220.351,1.49678,0.07319,,,,,0.09071393939,0.08372226035
220.851,1.45545,0.02603,,,,,0.08820909091,0.02977579501
221.351,1.41324,-0.02057,,,,,0.08565090909,-0.02353008465
221.851,1.3719,-0.05867,,,,,0.08314545455,-0.06711278884
222.351,1.33031,-0.09503,,,,,0.08062484848,-0.1087051018
222.851,1.28827,-0.1267,,,,,0.0780769697,-0.1449325097
223.351,1.24681,-0.15324,,,,,0.07556424242,-0.1752916953
223.851,1.20519,-0.17759,,,,,0.07304181818,-0.2031457332
224.351,1.16347,-0.20316,,,,,0.07051333333,-0.2323953329
224.851,1.122,-0.22345,,,,,0.068,-0.2556051247
225.351,1.08001,-0.246,,,,,0.06545515152,-0.2814001373
225.851,1.03858,-0.26673,,,,,0.06294424242,-0.3051132464
226.351,0.99699,-0.28425,,,,,0.06042363636,-0.3251544269
226.851,0.95495,-0.30273,,,,,0.05787575758,-0.3462937543
227.351,0.91359,-0.31775,,,,,0.05536909091,-0.3634751773
227.851,0.87183,-0.33409,,,,,0.05283818182,-0.3821665523
228.351,0.83009,-0.3495,,,,,0.05030848485,-0.3997940975
228.851,0.78867,-0.36462,,,,,0.04779818182,-0.4170899108
229.351,0.74668,-0.37903,,,,,0.04525333333,-0.433573553
229.851,0.70519,-0.39369,,,,,0.04273878788,-0.4503431709
230.351,0.66373,-0.40331,,,,,0.04022606061,-0.4613475177
230.851,0.62165,-0.41618,,,,,0.03767575758,-0.4760695493
231.351,0.58021,-0.42683,,,,,0.03516424242,-0.4882521162
231.851,0.53867,-0.43741,,,,,0.03264666667,-0.5003546099
232.351,0.49671,-0.44655,,,,,0.03010363636,-0.5108098833
232.851,0.45521,-0.4488,,,,,0.02758848485,-0.5133836651
233.351,0.41344,-0.44972,,,,,0.0250569697,-0.5144360558
233.851,0.37187,-0.44938,,,,,0.02253757576,-0.5140471288
234.351,0.33033,-0.44845,,,,,0.02002,-0.512983299
234.851,0.28823,-0.44713,,,,,0.01746848485,-0.5114733471
235.351,0.24697,-0.4475,,,,,0.01496787879,-0.5118965912
235.851,0.20536,-0.4488,,,,,0.01244606061,-0.5133836651
236.351,0.16327,-0.44858,,,,,0.009895151515,-0.5131320064
236.851,0.12191,-0.4486,,,,,0.007388484848,-0.5131548845
237.351,0.08025,-0.44813,,,,,0.004863636364,-0.5126172501
237.851,0.03837,-0.44857,,,,,0.002325454545,-0.5131205674
238.314,-0.00007,-0.44755,,,,,-0.000004242424242,-0.5119537863
238.616,0.02019,-0.44684,,,,,0.001223636364,-0.5111416152
239.116,0.0618,-0.44531,,,,,0.003745454545,-0.5093914436
239.616,0.10382,-0.44292,,,,,0.006292121212,-0.5066575154
240.116,0.14513,-0.44169,,,,,0.008795757576,-0.5052505148
240.616,0.18697,-0.4341,,,,,0.01133151515,-0.496568291
241.116,0.22885,-0.40391,,,,,0.01386969697,-0.4620338595
241.616,0.27001,-0.34815,,,,,0.01636424242,-0.3982498284
242.116,0.31214,-0.30134,,,,,0.01891757576,-0.3447037291
242.616,0.35373,-0.26586,,,,,0.02143818182,-0.3041180508
243.116,0.39505,-0.23622,,,,,0.02394242424,-0.270212766
243.616,0.43711,-0.20741,,,,,0.02649151515,-0.2372569206
244.116,0.47863,-0.18008,,,,,0.02900787879,-0.2059940517
244.616,0.52032,-0.15555,,,,,0.03153454545,-0.1779341112
245.116,0.56207,-0.13058,,,,,0.03406484848,-0.1493708534
245.616,0.60338,-0.10883,,,,,0.03656848485,-0.1244909632
246.116,0.64547,-0.08586,,,,,0.03911939394,-0.09821551132
246.616,0.68697,-0.06309,,,,,0.04163454545,-0.07216884008
247.116,0.72833,-0.04297,,,,,0.04414121212,-0.04915351178
247.616,0.77057,-0.01886,,,,,0.04670121212,-0.02157401052
248.116,0.81184,0.00209,,,,,0.04920242424,0.002390757264
248.616,0.85355,0.02334,,,,,0.05173030303,0.02669869595
249.116,0.89551,0.04623,,,,,0.05427333333,0.05288263555
249.616,0.93671,0.06651,,,,,0.05677030303,0.07608098833
250.116,0.97869,0.08847,,,,,0.05931454545,0.1012010981
250.616,1.02044,0.11141,,,,,0.06184484848,0.1274422329
251.116,1.06166,0.13095,,,,,0.0643430303,0.1497940975
251.616,1.10382,0.15419,,,,,0.06689818182,0.1763784031
252.116,1.14536,0.17736,,,,,0.06941575758,0.2028826356
252.616,1.18687,0.19785,,,,,0.07193151515,0.226321208
253.116,1.22879,0.22152,,,,,0.07447212121,0.2533973919
253.616,1.27011,0.24354,,,,,0.07697636364,0.2785861359
254.116,1.31205,0.26635,,,,,0.07951818182,0.3046785633
254.616,1.35372,0.29052,,,,,0.08204363636,0.3323266987
255.116,1.395,0.31243,,,,,0.08454545455,0.3573896134
255.616,1.4372,0.33745,,,,,0.0871030303,0.3860100663
256.116,1.47872,0.36175,,,,,0.08961939394,0.4138069092
256.616,1.52008,0.3826,,,,,0.09212606061,0.4376572867
257.116,1.5621,0.41055,,,,,0.09467272727,0.4696293754
257.616,1.60352,0.43393,,,,,0.0971830303,0.4963738275
258.116,1.64531,0.45806,,,,,0.09971575758,0.5239762068
258.376,1.63909,0.37013,,,,,0.09933878788,0.4233928163
258.876,1.59668,0.23348,,,,,0.09676848485,0.2670784717
259.376,1.55533,0.1506,,,,,0.09426242424,0.1722717914
259.876,1.51389,0.08601,,,,,0.09175090909,0.09838709677
260.376,1.47162,0.02979,,,,,0.08918909091,0.03407687028
260.876,1.43038,-0.01397,,,,,0.08668969697,-0.01598032487
261.376,1.38859,-0.05315,,,,,0.0841569697,-0.06079844429
261.876,1.34695,-0.08766,,,,,0.08163333333,-0.1002745367
262.376,1.30536,-0.12021,,,,,0.07911272727,-0.1375085793
262.876,1.26347,-0.14993,,,,,0.07657393939,-0.1715053763
263.376,1.222,-0.17634,,,,,0.07406060606,-0.2017158545
263.876,1.18044,-0.20035,,,,,0.07154181818,-0.2291809655
264.376,1.13835,-0.22412,,,,,0.06899090909,-0.2563715397
264.876,1.09705,-0.24415,,,,,0.06648787879,-0.2792839167
265.376,1.0554,-0.26357,,,,,0.06396363636,-0.3014985129
265.876,1.01341,-0.28523,,,,,0.06141878788,-0.3262754518
266.376,0.97215,-0.30021,,,,,0.05891818182,-0.3434111187
266.876,0.93014,-0.31818,,,,,0.05637212121,-0.3639670556
267.376,0.88854,-0.33504,,,,,0.05385090909,-0.3832532601
267.876,0.84711,-0.34745,,,,,0.05134,-0.3974490963
268.376,0.80505,-0.36361,,,,,0.04879090909,-0.4159345687
268.876,0.76358,-0.37663,,,,,0.04627757576,-0.4308281858
269.376,0.72214,-0.39,,,,,0.04376606061,-0.4461221688
269.876,0.68009,-0.40484,,,,,0.04121757576,-0.4630976893
270.376,0.63864,-0.41558,,,,,0.03870545455,-0.4753832075
270.876,0.59693,-0.42872,,,,,0.03617757576,-0.4904140929
271.376,0.55526,-0.43871,,,,,0.03365212121,-0.5018416838
271.876,0.51376,-0.4447,,,,,0.0311369697,-0.5086936628
272.376,0.47173,-0.44695,,,,,0.02858969697,-0.5112674445
272.876,0.43039,-0.44782,,,,,0.02608424242,-0.5122626401
273.376,0.38872,-0.44932,,,,,0.02355878788,-0.5139784946
273.876,0.34671,-0.44874,,,,,0.02101272727,-0.5133150309
274.376,0.30535,-0.44969,,,,,0.01850606061,-0.5144017387
274.876,0.26359,-0.44834,,,,,0.01597515152,-0.5128574697
275.376,0.22178,-0.44877,,,,,0.01344121212,-0.513349348
275.876,0.18043,-0.44622,,,,,0.01093515152,-0.5104323953
276.376,0.13848,-0.44631,,,,,0.008392727273,-0.5105353466
276.876,0.09697,-0.44694,,,,,0.005876969697,-0.5112560055
277.376,0.05554,-0.44812,,,,,0.003366060606,-0.512605811
277.876,0.01334,-0.4469,,,,,0.0008084848485,-0.5112102494
278.142,0.00258,-0.44828,,,,,0.0001563636364,-0.5127888355
278.642,0.04542,-0.44595,,,,,0.002752727273,-0.5101235415
279.142,0.0866,-0.44329,,,,,0.005248484848,-0.5070807596
279.642,0.12867,-0.4422,,,,,0.007798181818,-0.5058339053
280.142,0.17043,-0.43745,,,,,0.01032909091,-0.500400366
280.642,0.21164,-0.42464,,,,,0.01282666667,-0.4857469687
281.142,0.25384,-0.38423,,,,,0.01538424242,-0.4395218485
281.642,0.29529,-0.33145,,,,,0.01789636364,-0.3791466484
282.142,0.33691,-0.29146,,,,,0.02041878788,-0.3334019675
282.642,0.37873,-0.25634,,,,,0.02295333333,-0.2932280943
283.142,0.42009,-0.22942,,,,,0.02546,-0.2624342256
283.642,0.46213,-0.20139,,,,,0.02800787879,-0.2303706246
284.142,0.50374,-0.17535,,,,,0.03052969697,-0.2005833905
284.642,0.545,-0.15491,,,,,0.03303030303,-0.1772020133
285.142,0.58715,-0.12954,,,,,0.03558484848,-0.1481811942
285.642,0.62868,-0.10778,,,,,0.03810181818,-0.123289865
286.142,0.67004,-0.08703,,,,,0.04060848485,-0.09955387783
286.642,0.71217,-0.06389,,,,,0.04316181818,-0.07308396248
287.142,0.75339,-0.04255,,,,,0.04566,-0.04867307252
287.642,0.79539,-0.0232,,,,,0.04820545455,-0.02653854953
288.142,0.83701,-0.00068,,,,,0.05072787879,-0.000777854038
288.642,0.87836,0.01847,,,,,0.05323393939,0.02112788836
289.142,0.92049,0.04098,,,,,0.05578727273,0.04687714482
289.642,0.96209,0.06247,,,,,0.05830848485,0.07145962022
290.142,1.00345,0.08112,,,,,0.06081515152,0.09279341112
290.642,1.04546,0.10476,,,,,0.06336121212,0.119835278
291.142,1.08686,0.1258,,,,,0.06587030303,0.143902997
291.642,1.12867,0.14649,,,,,0.06840424242,0.16757035
292.142,1.17043,0.17124,,,,,0.07093515152,0.1958819492
292.642,1.21162,0.19083,,,,,0.07343151515,0.2182910089
293.142,1.25388,0.21397,,,,,0.07599272727,0.2447609243
293.642,1.29532,0.23864,,,,,0.07850424242,0.2729810112
294.142,1.3367,0.25823,,,,,0.08101212121,0.2953900709
294.642,1.37883,0.28435,,,,,0.08356545455,0.3252688172
295.142,1.42032,0.30645,,,,,0.08608,0.3505490734
295.642,1.46186,0.32932,,,,,0.08859757576,0.376710135
296.142,1.5039,0.35664,,,,,0.09114545455,0.4079615649
296.642,1.54505,0.37921,,,,,0.09363939394,0.4337794555
297.142,1.58703,0.40271,,,,,0.09618363636,0.4606611759
297.642,1.62877,0.42865,,,,,0.09871333333,0.4903340197
297.903,1.65028,0.44059,,,,,0.1000169697,0.5039922215
298.403,1.61391,0.26204,,,,,0.09781272727,0.2997483413
298.903,1.57235,0.16669,,,,,0.09529393939,0.1906771906
299.403,1.53047,0.09511,,,,,0.09275575758,0.108796614
299.903,1.48906,0.04009,,,,,0.09024606061,0.04585907115
300.403,1.4471,-0.00654,,,,,0.0877030303,-0.007481125601
300.903,1.40563,-0.04739,,,,,0.08518969697,-0.05420956303
301.403,1.36411,-0.08361,,,,,0.08267333333,-0.09564172958
301.903,1.32202,-0.1169,,,,,0.08012242424,-0.1337222604
302.403,1.28068,-0.1467,,,,,0.0776169697,-0.1678105697
302.903,1.239,-0.17096,,,,,0.07509090909,-0.1955616564
303.403,1.19712,-0.19707,,,,,0.07255272727,-0.2254289636
303.903,1.15569,-0.21881,,,,,0.07004181818,-0.2502974148
304.403,1.11378,-0.24,,,,,0.06750181818,-0.2745367193
304.903,1.0722,-0.26038,,,,,0.06498181818,-0.2978494624
305.403,1.03085,-0.27825,,,,,0.06247575758,-0.3182910089
305.903,0.98861,-0.29609,,,,,0.05991575758,-0.3386982384
306.403,0.9473,-0.31245,,,,,0.05741212121,-0.3574124914
306.903,0.9057,-0.32872,,,,,0.05489090909,-0.3760237932
307.403,0.86379,-0.34585,,,,,0.05235090909,-0.3956188515
307.903,0.82228,-0.35971,,,,,0.04983515152,-0.4114733471
308.403,0.78059,-0.37372,,,,,0.04730848485,-0.427499428
308.903,0.73891,-0.38827,,,,,0.04478242424,-0.4441432167
309.403,0.6974,-0.40028,,,,,0.04226666667,-0.4578814916
309.903,0.65535,-0.41157,,,,,0.03971818182,-0.4707961565
310.403,0.61402,-0.42384,,,,,0.03721333333,-0.4848318463
310.903,0.57246,-0.4342,,,,,0.03469454545,-0.4966826813
311.403,0.53023,-0.44423,,,,,0.03213515152,-0.5081560284
311.903,0.48906,-0.44897,,,,,0.02964,-0.5135781286
312.403,0.44725,-0.44956,,,,,0.02710606061,-0.5142530313
312.903,0.40543,-0.44899,,,,,0.02457151515,-0.5136010066
313.403,0.36403,-0.44839,,,,,0.02206242424,-0.5129146648
313.903,0.32215,-0.44865,,,,,0.01952424242,-0.5132120796
314.403,0.2805,-0.44883,,,,,0.017,-0.5134179822
314.903,0.23914,-0.44836,,,,,0.01449333333,-0.5128803477
315.403,0.19703,-0.44916,,,,,0.01194121212,-0.5137954701
315.903,0.15562,-0.45018,,,,,0.009431515152,-0.5149622512
316.403,0.11403,-0.44871,,,,,0.006910909091,-0.5132807138
316.903,0.07212,-0.44693,,,,,0.004370909091,-0.5112445665
317.403,0.03065,-0.44677,,,,,0.001857575758,-0.511061542
317.771,-0.00009,-0.44745,,,,,-0.000005454545455,-0.511839396
318.172,0.02834,-0.44531,,,,,0.001717575758,-0.5093914436
318.672,0.07051,-0.44476,,,,,0.004273333333,-0.508762297
319.172,0.11211,-0.44472,,,,,0.006794545455,-0.5087165408
319.672,0.15357,-0.44217,,,,,0.009307272727,-0.5057995882
320.172,0.1955,-0.43676,,,,,0.01184848485,-0.499611073
320.672,0.23696,-0.41576,,,,,0.01436121212,-0.47558911
321.172,0.27881,-0.36408,,,,,0.01689757576,-0.4164722032
321.672,0.32041,-0.31654,,,,,0.01941878788,-0.3620910547
322.172,0.36174,-0.28145,,,,,0.02192363636,-0.3219514985
322.672,0.40387,-0.25091,,,,,0.0244769697,-0.287016701
323.172,0.44529,-0.22267,,,,,0.02698727273,-0.2547128803
323.672,0.48677,-0.19873,,,,,0.02950121212,-0.2273278426
324.172,0.52891,-0.17211,,,,,0.03205515152,-0.1968771448
324.672,0.57018,-0.14821,,,,,0.03455636364,-0.1695378632
325.172,0.61201,-0.12669,,,,,0.03709151515,-0.1449210707
325.672,0.65382,-0.10523,,,,,0.03962545455,-0.1203729124
326.172,0.69509,-0.08413,,,,,0.04212666667,-0.09623655914
326.672,0.73718,-0.06298,,,,,0.04467757576,-0.07204301075
327.172,0.77887,-0.04188,,,,,0.04720424242,-0.04790665752
327.672,0.8201,-0.02295,,,,,0.0497030303,-0.02625257378
328.172,0.86217,0.00183,,,,,0.05225272727,0.002093342485
328.672,0.90361,0.02103,,,,,0.05476424242,0.02405628003
329.172,0.94535,0.04017,,,,,0.05729393939,0.04595058339
329.672,0.98715,0.06309,,,,,0.05982727273,0.07216884008
330.172,1.02842,0.08254,,,,,0.06232848485,0.09441775337
330.672,1.07049,0.10333,,,,,0.06487818182,0.1181994967
331.172,1.11207,0.12476,,,,,0.06739818182,0.1427133379
331.672,1.15327,0.14466,,,,,0.06989515152,0.1654770075
332.172,1.19558,0.16849,,,,,0.07245939394,0.192736216
332.672,1.23709,0.18981,,,,,0.07497515152,0.2171242279
333.172,1.27854,0.21073,,,,,0.07748727273,0.2410546786
333.672,1.32047,0.23554,,,,,0.08002848485,0.2694349119
334.172,1.36187,0.25852,,,,,0.08253757576,0.2957218028
334.672,1.40373,0.27798,,,,,0.08507454545,0.3179821551
335.172,1.44548,0.30273,,,,,0.08760484848,0.3462937543
335.672,1.48681,0.32524,,,,,0.09010969697,0.3720430108
336.172,1.5289,0.35099,,,,,0.09266060606,0.4014985129
336.672,1.57047,0.3739,,,,,0.09518,0.4277053306
337.172,1.61184,0.397,,,,,0.09768727273,0.4541294898
337.63,1.65004,0.42143,,,,,0.1000024242,0.48207504
337.932,1.63034,0.30032,,,,,0.09880848485,0.3435369481
338.432,1.58873,0.18703,,,,,0.09628666667,0.2139441775
338.932,1.54716,0.11209,,,,,0.09376727273,0.1282200869
339.432,1.5051,0.04901,,,,,0.09121818182,0.05606268588
339.932,1.46373,0.00066,,,,,0.08871090909,0.000754975978
340.432,1.42214,-0.04236,,,,,0.08619030303,-0.04845573095
340.932,1.38006,-0.07969,,,,,0.08364,-0.09115762983
341.432,1.33874,-0.11194,,,,,0.08113575758,-0.1280485015
341.932,1.29702,-0.13982,,,,,0.07860727273,-0.159940517
342.432,1.25508,-0.17002,,,,,0.07606545455,-0.1944863876
342.932,1.21389,-0.1938,,,,,0.07356909091,-0.2216884008
343.432,1.17175,-0.21707,,,,,0.07101515152,-0.2483070236
343.932,1.13032,-0.23928,,,,,0.06850424242,-0.2737131091
344.432,1.08884,-0.25701,,,,,0.06599030303,-0.2939945093
344.932,1.04677,-0.27907,,,,,0.06344060606,-0.3192290094
345.432,1.00533,-0.29499,,,,,0.06092909091,-0.3374399451
345.932,0.96376,-0.30906,,,,,0.05840969697,-0.3535346603
346.432,0.92189,-0.32668,,,,,0.05587212121,-0.3736902311
346.932,0.88041,-0.3424,,,,,0.05335818182,-0.3916723862
347.432,0.83858,-0.35601,,,,,0.0508230303,-0.407240906
347.932,0.79704,-0.37187,,,,,0.04830545455,-0.4253832075
348.432,0.75547,-0.38392,,,,,0.04578606061,-0.4391672386
348.932,0.71343,-0.39752,,,,,0.04323818182,-0.4547243194
349.432,0.67207,-0.4083,,,,,0.04073151515,-0.4670555937
349.932,0.63036,-0.41958,,,,,0.03820363636,-0.4799588195
350.432,0.58848,-0.43413,,,,,0.03566545455,-0.4966026081
350.932,0.5471,-0.44214,,,,,0.03315757576,-0.5057652711
351.432,0.50522,-0.44591,,,,,0.03061939394,-0.5100777854
351.932,0.46357,-0.44696,,,,,0.02809515152,-0.5112788836
352.432,0.42221,-0.448,,,,,0.02558848485,-0.5124685427
352.932,0.38015,-0.44683,,,,,0.02303939394,-0.5111301762
353.432,0.33871,-0.44825,,,,,0.02052787879,-0.5127545184
353.932,0.29722,-0.4475,,,,,0.01801333333,-0.5118965912
354.432,0.25515,-0.44862,,,,,0.01546363636,-0.5131777625
354.932,0.2137,-0.44619,,,,,0.01295151515,-0.5103980782
355.432,0.172,-0.44659,,,,,0.01042424242,-0.5108556394
355.932,0.1303,-0.44971,,,,,0.007896969697,-0.5144246168
356.432,0.08877,-0.45003,,,,,0.00538,-0.5147906658
356.932,0.04676,-0.44593,,,,,0.002833939394,-0.5101006635
357.432,0.00543,-0.44912,,,,,0.0003290909091,-0.513749714
357.698,0.01189,-0.4479,,,,,0.0007206060606,-0.5123541524
358.198,0.05355,-0.44384,,,,,0.003245454545,-0.5077099062
358.698,0.09539,-0.44389,,,,,0.005781212121,-0.5077671013
359.198,0.13706,-0.44135,,,,,0.008306666667,-0.5048615877
359.698,0.17836,-0.43989,,,,,0.01080969697,-0.5031914894
360.198,0.22049,-0.42886,,,,,0.0133630303,-0.4905742393
360.698,0.26206,-0.39611,,,,,0.01588242424,-0.4531114162
361.198,0.30338,-0.34206,,,,,0.01838666667,-0.3912834592
361.698,0.34552,-0.30124,,,,,0.02094060606,-0.3445893388
362.198,0.38692,-0.26886,,,,,0.02344969697,-0.3075497598
362.698,0.42853,-0.24307,,,,,0.02597151515,-0.2780485015
363.198,0.47057,-0.21513,,,,,0.02851939394,-0.2460878518
363.698,0.51173,-0.19229,,,,,0.03101393939,-0.2199611073
364.198,0.55381,-0.16808,,,,,0.03356424242,-0.1922672157
364.698,0.59544,-0.1463,,,,,0.03608727273,-0.1673530085
365.198,0.63674,-0.12619,,,,,0.03859030303,-0.1443491192
365.698,0.67883,-0.10292,,,,,0.04114121212,-0.1177304965
366.198,0.72036,-0.08236,,,,,0.04365818182,-0.09421185084
366.698,0.76192,-0.06251,,,,,0.0461769697,-0.07150537634
367.198,0.80377,-0.04055,,,,,0.04871333333,-0.04638526653
367.698,0.84511,-0.02042,,,,,0.05121878788,-0.0233584992
368.198,0.88712,-0.00061,,,,,0.05376484848,-0.0006977808282
368.698,0.9287,0.01935,,,,,0.05628484848,0.02213452299
369.198,0.96997,0.03947,,,,,0.05878606061,0.04514985129
369.698,1.01233,0.06196,,,,,0.06135333333,0.0708762297
370.198,1.05368,0.08159,,,,,0.06385939394,0.09333104553
370.698,1.09519,0.10276,,,,,0.06637515152,0.117547472
371.198,1.13718,0.12407,,,,,0.06892,0.1419240448
371.698,1.1785,0.14431,,,,,0.07142424242,0.1650766415
372.198,1.22026,0.16519,,,,,0.07395515152,0.1889613361
372.698,1.26219,0.18865,,,,,0.07649636364,0.2157973004
373.198,1.30339,0.20957,,,,,0.07899333333,0.2397277511
373.698,1.34546,0.2325,,,,,0.0815430303,0.2659574468
374.198,1.3871,0.25599,,,,,0.08406666667,0.2928277282
374.698,1.42844,0.2772,,,,,0.08657212121,0.3170899108
375.198,1.47041,0.30272,,,,,0.08911575758,0.3462823153
375.698,1.51188,0.32603,,,,,0.09162909091,0.3729466941
376.198,1.55365,0.34778,,,,,0.09416060606,0.3978265843
376.698,1.59541,0.3739,,,,,0.09669151515,0.4277053306
377.198,1.6367,0.39571,,,,,0.09919393939,0.452653855
377.458,1.64784,0.36485,,,,,0.09986909091,0.4173530085
377.958,1.6055,0.21211,,,,,0.0973030303,0.2426332647
378.458,1.56342,0.12616,,,,,0.09475272727,0.1443148021
378.958,1.52203,0.06368,,,,,0.09224424242,0.07284374285
379.458,1.48032,0.01339,,,,,0.08971636364,0.01531686113
379.958,1.43857,-0.03209,,,,,0.08718606061,-0.03670784717
380.458,1.39712,-0.07046,,,,,0.08467393939,-0.08059940517
380.958,1.35522,-0.10261,,,,,0.08213454545,-0.1173758865
381.458,1.3136,-0.13474,,,,,0.07961212121,-0.1541294898
381.958,1.27228,-0.1603,,,,,0.07710787879,-0.1833676504
382.458,1.23,-0.18823,,,,,0.07454545455,-0.2153168611
382.958,1.18874,-0.21001,,,,,0.07204484848,-0.2402310684
383.458,1.14711,-0.23087,,,,,0.06952181818,-0.2640928849
383.958,1.10524,-0.25234,,,,,0.06698424242,-0.2886524823
384.458,1.06372,-0.27216,,,,,0.06446787879,-0.3113246397
384.958,1.02193,-0.28864,,,,,0.06193515152,-0.3301761611
385.458,0.98031,-0.30684,,,,,0.05941272727,-0.3509951956
385.958,0.93878,-0.32267,,,,,0.05689575758,-0.3691031801
386.458,0.89671,-0.33997,,,,,0.05434606061,-0.3888927019
386.958,0.85542,-0.35255,,,,,0.05184363636,-0.4032830016
387.458,0.81382,-0.36678,,,,,0.04932242424,-0.4195607412
387.958,0.77166,-0.38159,,,,,0.04676727273,-0.4365019446
388.458,0.73048,-0.39408,,,,,0.04427151515,-0.4507892931
388.958,0.68861,-0.40619,,,,,0.04173393939,-0.4646419584
389.458,0.64691,-0.41918,,,,,0.03920666667,-0.4795012583
389.958,0.60549,-0.42879,,,,,0.03669636364,-0.4904941661
390.458,0.56353,-0.43954,,,,,0.03415333333,-0.5027911233
390.958,0.52192,-0.44609,,,,,0.03163151515,-0.5102836879
391.458,0.48057,-0.44707,,,,,0.02912545455,-0.5114047129
391.958,0.43843,-0.44773,,,,,0.02657151515,-0.5121596889
392.458,0.397,-0.4478,,,,,0.02406060606,-0.5122397621
392.958,0.35539,-0.44956,,,,,0.02153878788,-0.5142530313
393.458,0.31357,-0.4485,,,,,0.01900424242,-0.5130404942
393.958,0.27209,-0.44818,,,,,0.01649030303,-0.5126744452
394.458,0.23014,-0.44711,,,,,0.01394787879,-0.511450469
394.958,0.18875,-0.44802,,,,,0.01143939394,-0.5124914207
395.458,0.14705,-0.44607,,,,,0.008912121212,-0.5102608099
395.958,0.10506,-0.44629,,,,,0.006367272727,-0.5105124685
396.458,0.06372,-0.44783,,,,,0.003861818182,-0.5122740792
396.958,0.02206,-0.44734,,,,,0.001336969697,-0.5117135667
397.222,-0.00001,-0.44799,,,,,-0.0000006060606061,-0.5124571036