File: mechanical/hysteresis/databak/hmwg_hysteresis - nonconductive_2.csv
Time,Extension,Load,Length,Width,Thickness,CS Area,Strain,Stress
(s),(mm),(N),(mm),(mm),(mm),(mm^2),(mm/mm),(MPa)
0,0,-0.00359,16.5,2.82,0.35,0.987,0,-0.003637284701
0.5,0.03866,-0.00003,,,,,0.002343030303,-0.00003039513678
1,0.08047,0.00262,,,,,0.004876969697,0.002654508612
1.5,0.12168,0.00119,,,,,0.007374545455,0.001205673759
2,0.16379,0.00294,,,,,0.009926666667,0.002978723404
2.5,0.20535,0.00543,,,,,0.01244545455,0.005501519757
3,0.24676,0.00524,,,,,0.01495515152,0.005309017224
3.5,0.28882,0.00593,,,,,0.01750424242,0.00600810537
4,0.33022,0.00715,,,,,0.02001333333,0.007244174265
4.5,0.37192,0.00824,,,,,0.02254060606,0.008348530902
5,0.41379,0.00815,,,,,0.02507818182,0.008257345491
5.5,0.45502,0.00991,,,,,0.0275769697,0.01004052685
6,0.49704,0.00799,,,,,0.03012363636,0.008095238095
6.5,0.53879,0.01146,,,,,0.03265393939,0.01161094225
7,0.58001,0.01442,,,,,0.03515212121,0.01460992908
7.5,0.62215,0.01205,,,,,0.03770606061,0.01220871327
8,0.66374,0.01282,,,,,0.04022666667,0.01298885512
8.5,0.70521,0.01326,,,,,0.04274,0.01343465046
9,0.74711,0.01455,,,,,0.04527939394,0.01474164134
9.5,0.78857,0.01582,,,,,0.04779212121,0.01602836879
10,0.83043,0.01585,,,,,0.05032909091,0.01605876393
10.5,0.87207,0.0154,,,,,0.05285272727,0.01560283688
11,0.91338,0.01879,,,,,0.05535636364,0.01903748734
11.5,0.9555,0.01843,,,,,0.05790909091,0.01867274569
12,0.99688,0.01954,,,,,0.0604169697,0.01979736575
12.5,1.03842,0.02148,,,,,0.06293454545,0.02176291793
13,1.08046,0.02108,,,,,0.06548242424,0.02135764944
13.5,1.12176,0.02306,,,,,0.06798545455,0.02336372847
14,1.16363,0.02439,,,,,0.0705230303,0.0247112462
14.5,1.20546,0.02545,,,,,0.07305818182,0.0257852077
15,1.24664,0.02568,,,,,0.07555393939,0.02601823708
15.5,1.28881,0.02665,,,,,0.07810969697,0.02700101317
16,1.33047,0.02699,,,,,0.08063454545,0.02734549139
16.5,1.37174,0.02964,,,,,0.08313575758,0.03003039514
17,1.41376,0.02973,,,,,0.08568242424,0.03012158055
17.5,1.45526,0.02977,,,,,0.08819757576,0.0301621074
18,1.49698,0.03037,,,,,0.09072606061,0.03077001013
18.5,1.53874,0.0333,,,,,0.0932569697,0.03373860182
19,1.58004,0.03239,,,,,0.09576,0.03281661601
19.5,1.62212,0.0333,,,,,0.09831030303,0.03373860182
19.839,1.65016,0.03355,,,,,0.100009697,0.03399189463
20.24,1.62131,0.03008,,,,,0.09826121212,0.03047619048
20.74,1.57994,0.02597,,,,,0.09575393939,0.02631205674
21.24,1.53828,0.02253,,,,,0.09322909091,0.02282674772
21.74,1.49634,0.01924,,,,,0.09068727273,0.01949341439
22.24,1.45502,0.01752,,,,,0.0881830303,0.01775075988
22.74,1.41312,0.01484,,,,,0.08564363636,0.01503546099
23.24,1.37154,0.01423,,,,,0.08312363636,0.01441742655
23.74,1.33014,0.0125,,,,,0.08061454545,0.01266464032
24.24,1.28798,0.01141,,,,,0.07805939394,0.01156028369
24.74,1.24659,0.00782,,,,,0.07555090909,0.007922998987
25.24,1.20501,0.0055,,,,,0.07303090909,0.005572441743
25.74,1.16308,0.00422,,,,,0.07048969697,0.004275582573
26.24,1.12158,0.00178,,,,,0.06797454545,0.001803444782
26.74,1.07985,0.00005,,,,,0.06544545455,0.0000506585613
27.24,1.03817,-0.00231,,,,,0.06291939394,-0.002340425532
27.74,0.99674,-0.00319,,,,,0.06040848485,-0.003232016211
28.24,0.9546,-0.00464,,,,,0.05785454545,-0.004701114488
28.74,0.91326,-0.00726,,,,,0.05534909091,-0.0073556231
29.24,0.87175,-0.00884,,,,,0.05283333333,-0.008956433637
29.74,0.82959,-0.00877,,,,,0.05027818182,-0.008885511651
30.24,0.78824,-0.01049,,,,,0.04777212121,-0.01062816616
30.74,0.7466,-0.0124,,,,,0.04524848485,-0.0125633232
31.24,0.70477,-0.01358,,,,,0.04271333333,-0.01375886525
31.74,0.66329,-0.01368,,,,,0.04019939394,-0.01386018237
32.24,0.62145,-0.01512,,,,,0.03766363636,-0.01531914894
32.74,0.57989,-0.01772,,,,,0.03514484848,-0.01795339412
33.24,0.53838,-0.01923,,,,,0.03262909091,-0.01948328267
33.74,0.49636,-0.01958,,,,,0.03008242424,-0.0198378926
34.24,0.45495,-0.0211,,,,,0.02757272727,-0.02137791287
34.74,0.41325,-0.02223,,,,,0.02504545455,-0.02252279635
35.24,0.37136,-0.02365,,,,,0.02250666667,-0.02396149949
35.74,0.32997,-0.0255,,,,,0.01999818182,-0.02583586626
36.24,0.28804,-0.0254,,,,,0.0174569697,-0.02573454914
36.74,0.24654,-0.02895,,,,,0.01494181818,-0.02933130699
37.24,0.20507,-0.02811,,,,,0.01242848485,-0.02848024316
37.74,0.16291,-0.02921,,,,,0.009873333333,-0.02959473151
38.24,0.12157,-0.03227,,,,,0.007367878788,-0.03269503546
38.74,0.08006,-0.03304,,,,,0.004852121212,-0.0334751773
39.24,0.03796,-0.03535,,,,,0.002300606061,-0.03581560284
39.701,-0.00005,-0.03712,,,,,-0.00000303030303,-0.03760891591
40.003,0.01979,-0.03342,,,,,0.001199393939,-0.03386018237
40.503,0.06175,-0.03091,,,,,0.003742424242,-0.03131712259
41.003,0.10353,-0.02576,,,,,0.006274545455,-0.02609929078
41.503,0.14472,-0.02545,,,,,0.008770909091,-0.0257852077
42.003,0.18694,-0.02382,,,,,0.01132969697,-0.0241337386
42.503,0.22848,-0.02131,,,,,0.01384727273,-0.02159067882
43.003,0.26977,-0.01888,,,,,0.01634969697,-0.01912867275
43.503,0.31196,-0.017,,,,,0.01890666667,-0.01722391084
44.003,0.35337,-0.01616,,,,,0.02141636364,-0.01637284701
44.503,0.39499,-0.0144,,,,,0.02393878788,-0.01458966565
45.003,0.43682,-0.01289,,,,,0.02647393939,-0.0130597771
45.503,0.4782,-0.01127,,,,,0.02898181818,-0.01141843972
46.003,0.52016,-0.00993,,,,,0.03152484848,-0.01006079027
46.503,0.56181,-0.00831,,,,,0.03404909091,-0.008419452888
47.003,0.60311,-0.0057,,,,,0.03655212121,-0.005775075988
47.503,0.64527,-0.00476,,,,,0.03910727273,-0.004822695035
48.003,0.68674,-0.00324,,,,,0.04162060606,-0.003282674772
48.503,0.72828,-0.00241,,,,,0.04413818182,-0.002441742655
49.003,0.77024,0.00043,,,,,0.04668121212,0.0004356636272
49.503,0.8115,0.00018,,,,,0.04918181818,0.0001823708207
50.003,0.85349,0.00226,,,,,0.05172666667,0.002289766971
50.503,0.89525,0.00129,,,,,0.05425757576,0.001306990881
51.003,0.93636,0.0035,,,,,0.05674909091,0.003546099291
51.503,0.97854,0.00523,,,,,0.05930545455,0.005298885512
52.003,1.02019,0.00718,,,,,0.06182969697,0.007274569402
52.503,1.0615,0.0071,,,,,0.06433333333,0.007193515704
53.003,1.10356,0.00758,,,,,0.06688242424,0.007679837893
53.503,1.14506,0.00975,,,,,0.06939757576,0.009878419453
54.003,1.18674,0.00898,,,,,0.07192363636,0.009098277609
54.503,1.22855,0.01295,,,,,0.07445757576,0.01312056738
55.003,1.26985,0.01338,,,,,0.07696060606,0.013556231
55.503,1.31195,0.01457,,,,,0.07951212121,0.01476190476
56.003,1.35342,0.01606,,,,,0.08202545455,0.01627152989
56.503,1.39481,0.01754,,,,,0.08453393939,0.0177710233
57.003,1.43693,0.01881,,,,,0.08708666667,0.01905775076
57.503,1.47827,0.01898,,,,,0.08959212121,0.01922998987
58.003,1.52,0.02105,,,,,0.09212121212,0.02132725431
58.503,1.56191,0.02281,,,,,0.09466121212,0.02311043566
59.003,1.60311,0.02543,,,,,0.09715818182,0.02576494428
59.503,1.64515,0.02498,,,,,0.09970606061,0.02530901722
59.766,1.63864,0.02041,,,,,0.09931151515,0.02067882472
60.266,1.5966,0.0181,,,,,0.09676363636,0.01833839919
60.766,1.55483,0.01683,,,,,0.09423212121,0.01705167173
61.266,1.51344,0.01232,,,,,0.09172363636,0.0124822695
61.766,1.47137,0.01142,,,,,0.08917393939,0.0115704154
62.266,1.42994,0.00959,,,,,0.0866630303,0.009716312057
62.766,1.38844,0.00699,,,,,0.08414787879,0.007082066869
63.266,1.34638,0.00522,,,,,0.08159878788,0.005288753799
63.766,1.30495,0.00356,,,,,0.07908787879,0.003606889564
64.266,1.26318,0.00098,,,,,0.07655636364,0.0009929078014
64.766,1.22157,-0.00141,,,,,0.07403454545,-0.001428571429
65.266,1.17993,-0.00171,,,,,0.07151090909,-0.001732522796
65.766,1.13803,-0.00318,,,,,0.06897151515,-0.003221884498
66.266,1.09658,-0.00551,,,,,0.06645939394,-0.005582573455
66.766,1.05508,-0.00693,,,,,0.06394424242,-0.007021276596
67.266,1.0129,-0.00913,,,,,0.06138787879,-0.009250253293
67.766,0.9717,-0.01159,,,,,0.05889090909,-0.01174265451
68.266,0.92995,-0.01194,,,,,0.05636060606,-0.01209726444
68.766,0.88812,-0.01512,,,,,0.05382545455,-0.01531914894
69.266,0.84676,-0.01603,,,,,0.05131878788,-0.01624113475
69.766,0.80483,-0.01638,,,,,0.04877757576,-0.01659574468
70.266,0.7632,-0.01746,,,,,0.04625454545,-0.0176899696
70.766,0.72175,-0.02156,,,,,0.04374242424,-0.02184397163
71.266,0.67971,-0.02119,,,,,0.04119454545,-0.02146909828
71.766,0.63821,-0.02288,,,,,0.03867939394,-0.02318135765
72.266,0.59673,-0.02545,,,,,0.03616545455,-0.0257852077
72.766,0.55469,-0.02677,,,,,0.03361757576,-0.02712259372
73.266,0.51336,-0.0268,,,,,0.03111272727,-0.02715298886
73.766,0.47147,-0.02735,,,,,0.02857393939,-0.02771023303
74.266,0.42989,-0.03032,,,,,0.02605393939,-0.03071935157
74.766,0.38843,-0.02926,,,,,0.02354121212,-0.02964539007
75.266,0.34631,-0.03138,,,,,0.02098848485,-0.03179331307
75.766,0.30494,-0.03265,,,,,0.01848121212,-0.03308004053
76.266,0.26345,-0.03445,,,,,0.01596666667,-0.03490374873
76.766,0.22131,-0.03575,,,,,0.01341272727,-0.03622087133
77.266,0.17991,-0.03828,,,,,0.01090363636,-0.03878419453
77.766,0.13836,-0.03986,,,,,0.008385454545,-0.04038500507
78.266,0.09642,-0.0415,,,,,0.005843636364,-0.04204660588
78.766,0.05502,-0.04017,,,,,0.003334545455,-0.04069908815
79.266,0.01306,-0.0425,,,,,0.0007915151515,-0.0430597771
79.529,0.00237,-0.04126,,,,,0.0001436363636,-0.04180344478
80.029,0.04521,-0.0375,,,,,0.00274,-0.03799392097
80.529,0.08638,-0.03549,,,,,0.005235151515,-0.03595744681
81.029,0.12868,-0.0324,,,,,0.007798787879,-0.03282674772
81.529,0.17014,-0.03038,,,,,0.01031151515,-0.03078014184
82.029,0.21157,-0.02853,,,,,0.01282242424,-0.02890577508
82.529,0.25361,-0.02632,,,,,0.01537030303,-0.02666666667
83.029,0.29494,-0.0246,,,,,0.01787515152,-0.02492401216
83.529,0.33677,-0.02263,,,,,0.02041030303,-0.02292806484
84.029,0.37846,-0.02006,,,,,0.0229369697,-0.02032421479
84.529,0.41984,-0.01934,,,,,0.02544484848,-0.01959473151
85.029,0.46178,-0.01723,,,,,0.02798666667,-0.01745694022
85.529,0.50346,-0.01652,,,,,0.03051272727,-0.01673758865
86.029,0.54486,-0.01297,,,,,0.03302181818,-0.0131408308
86.529,0.58692,-0.01278,,,,,0.03557090909,-0.01294832827
87.029,0.6282,-0.01011,,,,,0.03807272727,-0.01024316109
87.529,0.67015,-0.00959,,,,,0.04061515152,-0.009716312057
88.029,0.71187,-0.00765,,,,,0.04314363636,-0.007750759878
88.529,0.75305,-0.00622,,,,,0.04563939394,-0.006301925025
89.029,0.79526,-0.00597,,,,,0.04819757576,-0.006048632219
89.529,0.83686,-0.00345,,,,,0.05071878788,-0.003495440729
90.029,0.87813,-0.00142,,,,,0.05322,-0.001438703141
90.529,0.92013,-0.0019,,,,,0.05576545455,-0.001925025329
91.029,0.96172,0.00009,,,,,0.05828606061,0.00009118541033
91.529,1.00331,0.00095,,,,,0.06080666667,0.0009625126646
92.029,1.04523,0.00321,,,,,0.06334727273,0.003252279635
92.529,1.08645,0.00378,,,,,0.06584545455,0.003829787234
93.029,1.12855,0.00414,,,,,0.0683969697,0.004194528875
93.529,1.17014,0.00591,,,,,0.07091757576,0.005987841945
94.029,1.21145,0.00655,,,,,0.07342121212,0.00663627153
94.529,1.25362,0.00751,,,,,0.0759769697,0.007608915907
95.029,1.29509,0.00859,,,,,0.07849030303,0.008703140831
95.529,1.33661,0.00982,,,,,0.08100666667,0.009949341439
96.029,1.3786,0.0117,,,,,0.08355151515,0.01185410334
96.529,1.41987,0.01213,,,,,0.08605272727,0.01228976697
97.029,1.46175,0.01381,,,,,0.08859090909,0.01399189463
97.529,1.50356,0.01457,,,,,0.09112484848,0.01476190476
98.029,1.54476,0.01597,,,,,0.09362181818,0.01618034448
98.529,1.58693,0.01624,,,,,0.09617757576,0.01645390071
99.029,1.62852,0.01855,,,,,0.09869818182,0.01879432624
99.292,1.65026,0.02018,,,,,0.1000157576,0.02044579534
99.792,1.61331,0.01574,,,,,0.09777636364,0.0159473151
100.292,1.57182,0.01192,,,,,0.09526181818,0.01207700101
100.792,1.52968,0.01013,,,,,0.09270787879,0.01026342452
101.292,1.48825,0.00532,,,,,0.0901969697,0.005390070922
101.792,1.44666,0.00512,,,,,0.08767636364,0.005187436677
102.292,1.40482,0.00273,,,,,0.08514060606,0.002765957447
102.792,1.3633,0.00194,,,,,0.08262424242,0.001965552178
103.292,1.32139,0.00049,,,,,0.08008424242,0.0004964539007
103.792,1.27998,-0.00343,,,,,0.07757454545,-0.003475177305
104.292,1.23847,-0.00655,,,,,0.07505878788,-0.00663627153
104.792,1.19627,-0.00579,,,,,0.07250121212,-0.005866261398
105.292,1.15496,-0.00737,,,,,0.06999757576,-0.007467071935
105.792,1.11344,-0.01145,,,,,0.06748121212,-0.01160081054
106.292,1.07136,-0.0117,,,,,0.06493090909,-0.01185410334
106.792,1.02999,-0.01257,,,,,0.06242363636,-0.01273556231
107.292,0.98823,-0.01525,,,,,0.05989272727,-0.0154508612
107.792,0.9465,-0.01721,,,,,0.05736363636,-0.0174366768
108.292,0.90506,-0.01879,,,,,0.05485212121,-0.01903748734
108.792,0.86302,-0.01855,,,,,0.05230424242,-0.01879432624
109.292,0.82158,-0.01966,,,,,0.04979272727,-0.0199189463
109.792,0.77998,-0.02282,,,,,0.04727151515,-0.02312056738
110.292,0.7381,-0.02265,,,,,0.04473333333,-0.02294832827
110.792,0.69659,-0.0239,,,,,0.04221757576,-0.0242147923
111.292,0.65489,-0.02528,,,,,0.03969030303,-0.02561296859
111.792,0.61316,-0.02647,,,,,0.03716121212,-0.02681864235
112.292,0.57174,-0.02659,,,,,0.03465090909,-0.0269402229
112.792,0.5297,-0.02817,,,,,0.0321030303,-0.02854103343
113.292,0.48831,-0.02953,,,,,0.02959454545,-0.0299189463
113.792,0.44679,-0.03189,,,,,0.02707818182,-0.0323100304
114.292,0.40461,-0.03244,,,,,0.02452181818,-0.03286727457
114.792,0.36332,-0.03443,,,,,0.02201939394,-0.03488348531
115.292,0.32165,-0.03511,,,,,0.01949393939,-0.03557244174
115.792,0.27972,-0.03566,,,,,0.01695272727,-0.03612968592
116.292,0.23832,-0.038,,,,,0.01444363636,-0.03850050659
116.792,0.19655,-0.03957,,,,,0.01191212121,-0.04009118541
117.292,0.15485,-0.04142,,,,,0.009384848485,-0.04196555218
117.792,0.1134,-0.04269,,,,,0.006872727273,-0.04325227964
118.292,0.07129,-0.04387,,,,,0.004320606061,-0.04444782168
118.792,0.03,-0.04477,,,,,0.001818181818,-0.04535967579
119.154,-0.00013,-0.04443,,,,,-0.000007878787879,-0.04501519757
119.555,0.02817,-0.04081,,,,,0.001707272727,-0.04134751773
120.055,0.07017,-0.03639,,,,,0.004252727273,-0.03686930091
120.555,0.11156,-0.03721,,,,,0.006761212121,-0.03770010132
121.055,0.15342,-0.0352,,,,,0.009298181818,-0.03566362715
121.555,0.19512,-0.03225,,,,,0.01182545455,-0.03267477204
122.055,0.23638,-0.03008,,,,,0.01432606061,-0.03047619048
122.555,0.27849,-0.02933,,,,,0.01687818182,-0.02971631206
123.055,0.32008,-0.02964,,,,,0.01939878788,-0.03003039514
123.555,0.36148,-0.02478,,,,,0.02190787879,-0.02510638298
124.055,0.40351,-0.02447,,,,,0.02445515152,-0.0247922999
124.555,0.44496,-0.02258,,,,,0.02696727273,-0.02287740628
125.055,0.48669,-0.02092,,,,,0.02949636364,-0.02119554205
125.555,0.52851,-0.0177,,,,,0.03203090909,-0.0179331307
126.055,0.56969,-0.01609,,,,,0.03452666667,-0.01630192503
126.555,0.61188,-0.01518,,,,,0.03708363636,-0.01537993921
127.055,0.65354,-0.0132,,,,,0.03960848485,-0.01337386018
127.555,0.69468,-0.01181,,,,,0.04210181818,-0.01196555218
128.055,0.73689,-0.00994,,,,,0.04466,-0.01007092199
128.555,0.77839,-0.00952,,,,,0.04717515152,-0.009645390071
129.055,0.81989,-0.00823,,,,,0.04969030303,-0.008338399189
129.555,0.8618,-0.0054,,,,,0.05223030303,-0.00547112462
130.055,0.90321,-0.00615,,,,,0.05474,-0.00623100304
130.555,0.94505,-0.0044,,,,,0.05727575758,-0.004457953394
131.055,0.98681,-0.00333,,,,,0.05980666667,-0.003373860182
131.555,1.02812,-0.00211,,,,,0.06231030303,-0.002137791287
132.055,1.07024,-0.00009,,,,,0.0648630303,-0.00009118541033
132.555,1.11174,0.00036,,,,,0.06737818182,0.0003647416413
133.055,1.15324,0.00285,,,,,0.06989333333,0.002887537994
133.555,1.19523,0.00431,,,,,0.07243818182,0.004366767984
134.055,1.23644,0.00403,,,,,0.07493575758,0.004083080041
134.555,1.27844,0.00678,,,,,0.07748121212,0.006869300912
135.055,1.32021,0.0082,,,,,0.08001272727,0.008308004053
135.555,1.36134,0.01062,,,,,0.08250545455,0.01075987842
136.055,1.40343,0.00937,,,,,0.08505636364,0.009493414387
136.555,1.44514,0.0122,,,,,0.08758424242,0.01236068896
137.055,1.48639,0.0137,,,,,0.09008424242,0.0138804458
137.555,1.52854,0.01599,,,,,0.09263878788,0.0162006079
138.055,1.56993,0.01524,,,,,0.09514727273,0.01544072948
138.555,1.61167,0.01729,,,,,0.0976769697,0.0175177305
139.016,1.65001,0.01606,,,,,0.1000006061,0.01627152989
139.318,1.63008,0.01441,,,,,0.09879272727,0.01459979737
139.818,1.58808,0.01063,,,,,0.09624727273,0.01077001013
140.318,1.5466,0.00836,,,,,0.09373333333,0.008470111449
140.818,1.50476,0.00532,,,,,0.09119757576,0.005390070922
141.318,1.4633,0.00289,,,,,0.08868484848,0.002928064843
141.818,1.42161,0.00145,,,,,0.08615818182,0.001469098278
142.318,1.37966,-0.00071,,,,,0.08361575758,-0.0007193515704
142.818,1.33828,-0.00334,,,,,0.08110787879,-0.003383991895
143.318,1.29672,-0.00572,,,,,0.07858909091,-0.005795339412
143.818,1.25467,-0.00604,,,,,0.07604060606,-0.006119554205
144.318,1.21334,-0.009,,,,,0.07353575758,-0.009118541033
144.818,1.17154,-0.01208,,,,,0.07100242424,-0.01223910841
145.318,1.12979,-0.01236,,,,,0.06847212121,-0.01252279635
145.818,1.08842,-0.01467,,,,,0.06596484848,-0.01486322188
146.318,1.04639,-0.01471,,,,,0.06341757576,-0.01490374873
146.818,1.00487,-0.01571,,,,,0.06090121212,-0.01591691996
147.318,0.96338,-0.01908,,,,,0.05838666667,-0.01933130699
147.818,0.92135,-0.01972,,,,,0.05583939394,-0.01997973658
148.318,0.87987,-0.02013,,,,,0.05332545455,-0.02039513678
148.818,0.83829,-0.02197,,,,,0.05080545455,-0.02225937183
149.318,0.79644,-0.02325,,,,,0.04826909091,-0.023556231
149.818,0.75503,-0.02446,,,,,0.04575939394,-0.02478216819
150.318,0.71305,-0.02557,,,,,0.04321515152,-0.02590678825
150.818,0.67162,-0.02927,,,,,0.04070424242,-0.02965552178
151.318,0.63013,-0.02733,,,,,0.03818969697,-0.0276899696
151.818,0.58794,-0.02921,,,,,0.03563272727,-0.02959473151
152.318,0.54659,-0.02999,,,,,0.03312666667,-0.03038500507
152.818,0.50501,-0.03487,,,,,0.03060666667,-0.03532928065
153.318,0.46301,-0.03366,,,,,0.02806121212,-0.03410334347
153.818,0.42161,-0.03551,,,,,0.02555212121,-0.03597771023
154.318,0.3799,-0.03706,,,,,0.02302424242,-0.03754812563
154.818,0.33816,-0.03769,,,,,0.02049454545,-0.03818642351
155.318,0.29672,-0.03971,,,,,0.0179830303,-0.04023302938
155.818,0.25469,-0.03954,,,,,0.01543575758,-0.04006079027
156.318,0.21332,-0.04072,,,,,0.01292848485,-0.04125633232
156.818,0.17167,-0.04263,,,,,0.01040424242,-0.04319148936
157.318,0.12967,-0.04386,,,,,0.007858787879,-0.04443768997
157.818,0.08831,-0.04401,,,,,0.005352121212,-0.04458966565
158.318,0.04652,-0.04506,,,,,0.002819393939,-0.04565349544
158.818,0.00482,-0.04643,,,,,0.0002921212121,-0.04704154002
159.08,0.01152,-0.04725,,,,,0.0006981818182,-0.04787234043
159.58,0.05314,-0.04092,,,,,0.003220606061,-0.04145896657
160.08,0.09515,-0.03928,,,,,0.005766666667,-0.03979736575
160.58,0.13685,-0.03662,,,,,0.008293939394,-0.03710233029
161.08,0.17821,-0.03473,,,,,0.01080060606,-0.03518743668
161.58,0.22016,-0.0313,,,,,0.0133430303,-0.03171225937
162.08,0.26175,-0.03144,,,,,0.01586363636,-0.03185410334
162.58,0.30334,-0.02843,,,,,0.01838424242,-0.02880445795
163.08,0.34526,-0.0292,,,,,0.02092484848,-0.0295845998
163.58,0.38648,-0.02737,,,,,0.0234230303,-0.02773049645
164.08,0.4286,-0.02712,,,,,0.02597575758,-0.02747720365
164.58,0.47019,-0.02653,,,,,0.02849636364,-0.02687943262
165.08,0.51141,-0.02065,,,,,0.03099454545,-0.02092198582
165.58,0.55363,-0.02116,,,,,0.03355333333,-0.02143870314
166.08,0.59513,-0.0191,,,,,0.03606848485,-0.01935157042
166.58,0.63656,-0.02071,,,,,0.03857939394,-0.02098277609
167.08,0.67849,-0.01682,,,,,0.04112060606,-0.01704154002
167.58,0.71996,-0.01541,,,,,0.04363393939,-0.01561296859
168.08,0.76178,-0.0125,,,,,0.04616848485,-0.01266464032
168.58,0.80357,-0.01193,,,,,0.04870121212,-0.01208713273
169.08,0.8448,-0.01021,,,,,0.0512,-0.01034447822
169.58,0.88697,-0.00766,,,,,0.05375575758,-0.007760891591
170.08,0.92849,-0.00721,,,,,0.05627212121,-0.007304964539
170.58,0.9699,-0.00451,,,,,0.05878181818,-0.004569402229
171.08,1.01196,-0.00452,,,,,0.06133090909,-0.004579533941
171.58,1.05333,-0.00265,,,,,0.06383818182,-0.002684903749
172.08,1.09508,-0.0004,,,,,0.06636848485,-0.0004052684904
172.58,1.13695,0.00089,,,,,0.06890606061,0.0009017223911
173.08,1.17812,0.0013,,,,,0.07140121212,0.001317122594
173.58,1.22016,0.00364,,,,,0.07394909091,0.003687943262
174.08,1.26187,0.00309,,,,,0.0764769697,0.003130699088
174.58,1.3031,0.00642,,,,,0.07897575758,0.006504559271
175.08,1.34524,0.00862,,,,,0.08152969697,0.008733535968
175.58,1.38681,0.00646,,,,,0.08404909091,0.00654508612
176.08,1.42833,0.00808,,,,,0.08656545455,0.008186423506
176.58,1.47024,0.00938,,,,,0.08910545455,0.009503546099
177.08,1.51163,0.01034,,,,,0.09161393939,0.01047619048
177.58,1.55358,0.0124,,,,,0.09415636364,0.0125633232
178.08,1.59516,0.01216,,,,,0.09667636364,0.01232016211
178.58,1.6365,0.014,,,,,0.09918181818,0.01418439716
178.843,1.64755,0.01271,,,,,0.09985151515,0.01287740628
179.343,1.60515,0.01059,,,,,0.09728181818,0.01072948328
179.843,1.56307,0.00645,,,,,0.09473151515,0.006534954407
180.343,1.52179,0.00459,,,,,0.09222969697,0.004650455927
180.843,1.48019,0.00209,,,,,0.08970848485,0.002117527862
181.343,1.43802,-0.00068,,,,,0.08715272727,-0.0006889564336
181.843,1.39667,-0.00157,,,,,0.08464666667,-0.001590678825
182.343,1.35507,-0.00526,,,,,0.08212545455,-0.005329280648
182.843,1.31316,-0.00595,,,,,0.07958545455,-0.006028368794
183.343,1.27176,-0.00684,,,,,0.07707636364,-0.006930091185
183.843,1.22984,-0.00885,,,,,0.07453575758,-0.00896656535
184.343,1.18827,-0.01016,,,,,0.07201636364,-0.01029381966
184.843,1.14684,-0.01148,,,,,0.06950545455,-0.01163120567
185.343,1.10475,-0.01286,,,,,0.06695454545,-0.01302938197
185.843,1.06334,-0.01429,,,,,0.06444484848,-0.01447821682
186.343,1.02168,-0.01778,,,,,0.06192,-0.0180141844
186.843,0.97995,-0.0173,,,,,0.05939090909,-0.01752786221
187.343,0.93833,-0.0191,,,,,0.05686848485,-0.01935157042
187.843,0.89654,-0.02115,,,,,0.05433575758,-0.02142857143
188.343,0.85496,-0.02334,,,,,0.05181575758,-0.02364741641
188.843,0.81349,-0.02527,,,,,0.04930242424,-0.02560283688
189.343,0.7713,-0.02626,,,,,0.04674545455,-0.02660587639
189.843,0.73008,-0.02802,,,,,0.04424727273,-0.02838905775
190.343,0.68845,-0.02954,,,,,0.04172424242,-0.02992907801
190.843,0.64636,-0.03072,,,,,0.03917333333,-0.03112462006
191.343,0.60507,-0.0321,,,,,0.03667090909,-0.03252279635
191.843,0.5633,-0.0336,,,,,0.03413939394,-0.03404255319
192.343,0.52154,-0.03536,,,,,0.03160848485,-0.03582573455
192.843,0.48013,-0.03588,,,,,0.02909878788,-0.03635258359
193.343,0.43817,-0.03656,,,,,0.02655575758,-0.03704154002
193.843,0.39664,-0.03724,,,,,0.02403878788,-0.03773049645
194.343,0.35517,-0.03868,,,,,0.02152545455,-0.03918946302
194.843,0.31304,-0.03949,,,,,0.01897212121,-0.04001013171
195.343,0.27176,-0.04132,,,,,0.01647030303,-0.04186423506
195.843,0.22997,-0.04238,,,,,0.01393757576,-0.04293819656
196.343,0.18827,-0.04253,,,,,0.01141030303,-0.04309017224
196.843,0.14679,-0.04433,,,,,0.008896363636,-0.04491388045
197.343,0.10478,-0.04532,,,,,0.00635030303,-0.04591691996
197.843,0.06335,-0.04661,,,,,0.003839393939,-0.04722391084
198.343,0.02181,-0.04865,,,,,0.001321818182,-0.04929078014
198.607,-0.0002,-0.0489,,,,,-0.00001212121212,-0.04954407295
199.107,0.03688,-0.04558,,,,,0.002235151515,-0.04618034448
199.607,0.07833,-0.0414,,,,,0.004747272727,-0.04194528875
200.107,0.11992,-0.03893,,,,,0.007267878788,-0.03944275583
200.607,0.16179,-0.03744,,,,,0.009805454545,-0.0379331307
201.107,0.20322,-0.03566,,,,,0.01231636364,-0.03612968592
201.607,0.24512,-0.03158,,,,,0.01485575758,-0.03199594732
202.107,0.28685,-0.03326,,,,,0.01738484848,-0.03369807497
202.607,0.32799,-0.02914,,,,,0.01987818182,-0.02952380952
203.107,0.37026,-0.02802,,,,,0.02244,-0.02838905775
203.607,0.41182,-0.02829,,,,,0.02495878788,-0.02866261398
204.107,0.45308,-0.02669,,,,,0.02745939394,-0.02704154002
204.607,0.49522,-0.02354,,,,,0.03001333333,-0.02385005066
205.107,0.53661,-0.02179,,,,,0.03252181818,-0.02207700101
205.607,0.57833,-0.02299,,,,,0.03505030303,-0.02329280648
206.107,0.62012,-0.01794,,,,,0.0375830303,-0.01817629179
206.607,0.66149,-0.01709,,,,,0.04009030303,-0.01731509625
207.107,0.70344,-0.01707,,,,,0.04263272727,-0.01729483283
207.607,0.74515,-0.01499,,,,,0.04516060606,-0.01518743668
208.107,0.78648,-0.01357,,,,,0.04766545455,-0.01374873354
208.607,0.82854,-0.01062,,,,,0.05021454545,-0.01075987842
209.107,0.86994,-0.01088,,,,,0.05272363636,-0.01102330294
209.607,0.91169,-0.00878,,,,,0.05525393939,-0.008895643364
210.107,0.95347,-0.00755,,,,,0.05778606061,-0.007649442756
210.607,0.99465,-0.00586,,,,,0.06028181818,-0.005937183384
211.107,1.03686,-0.00584,,,,,0.06284,-0.005916919959
211.607,1.07848,-0.00343,,,,,0.06536242424,-0.003475177305
212.107,1.11969,-0.00218,,,,,0.06786,-0.002208713273
212.607,1.16177,-0.00253,,,,,0.07041030303,-0.002563323202
213.107,1.20343,-0.0012,,,,,0.07293515152,-0.001215805471
213.607,1.24483,0.00241,,,,,0.07544424242,0.002441742655
214.107,1.28691,0.00192,,,,,0.07799454545,0.001945288754
214.607,1.32821,0.00288,,,,,0.08049757576,0.002917933131
215.107,1.37013,0.005,,,,,0.08303818182,0.00506585613
215.607,1.41179,0.00454,,,,,0.0855630303,0.004599797366
216.107,1.45309,0.00811,,,,,0.08806606061,0.008216818642
216.607,1.49524,0.00995,,,,,0.09062060606,0.0100810537
217.107,1.53675,0.00989,,,,,0.09313636364,0.01002026342
217.607,1.57812,0.01121,,,,,0.09564363636,0.01135764944
218.107,1.62019,0.01127,,,,,0.09819333333,0.01141843972
218.47,1.65019,0.01304,,,,,0.1000115152,0.01321175279
218.871,1.6214,0.00721,,,,,0.09826666667,0.007304964539
219.371,1.58006,0.00611,,,,,0.09576121212,0.00619047619
219.871,1.53836,0.00192,,,,,0.09323393939,0.001945288754
220.371,1.49646,0.00172,,,,,0.09069454545,0.001742654509
220.871,1.45511,0.00019,,,,,0.08818848485,0.0001925025329
221.371,1.4132,-0.00221,,,,,0.08564848485,-0.002239108409
221.871,1.37165,-0.00594,,,,,0.08313030303,-0.006018237082
222.371,1.33023,-0.00716,,,,,0.08062,-0.007254305978
222.871,1.28808,-0.00785,,,,,0.07806545455,-0.007953394124
223.371,1.24669,-0.00993,,,,,0.0755569697,-0.01006079027
223.871,1.2051,-0.01097,,,,,0.07303636364,-0.01111448835
224.371,1.16321,-0.01331,,,,,0.07049757576,-0.01348530902
224.871,1.1217,-0.01359,,,,,0.06798181818,-0.01376899696
225.371,1.07995,-0.01541,,,,,0.06545151515,-0.01561296859
225.871,1.03831,-0.01734,,,,,0.06292787879,-0.01756838906
226.371,0.99683,-0.01736,,,,,0.06041393939,-0.01758865248
226.871,0.95469,-0.02033,,,,,0.05786,-0.02059777102
227.371,0.91336,-0.02226,,,,,0.05535515152,-0.02255319149
227.871,0.87186,-0.02377,,,,,0.05284,-0.02408308004
228.371,0.8297,-0.02465,,,,,0.05028484848,-0.02497467072
228.871,0.78835,-0.02716,,,,,0.04777878788,-0.0275177305
229.371,0.74671,-0.02711,,,,,0.04525515152,-0.02746707194
229.871,0.70489,-0.02949,,,,,0.04272060606,-0.02987841945
230.371,0.66341,-0.03109,,,,,0.04020666667,-0.03149949341
230.871,0.62153,-0.03127,,,,,0.03766848485,-0.03168186424
231.371,0.58,-0.03451,,,,,0.03515151515,-0.03496453901
231.871,0.53847,-0.0359,,,,,0.03263454545,-0.03637284701
232.371,0.49644,-0.03577,,,,,0.03008727273,-0.03624113475
232.871,0.45504,-0.03757,,,,,0.02757818182,-0.03806484296
233.371,0.41336,-0.03797,,,,,0.02505212121,-0.03847011145
233.871,0.37146,-0.04064,,,,,0.02251272727,-0.04117527862
234.371,0.33006,-0.03995,,,,,0.02000363636,-0.04047619048
234.871,0.28814,-0.04196,,,,,0.0174630303,-0.04251266464
235.371,0.24665,-0.04372,,,,,0.01494848485,-0.044295846
235.871,0.20518,-0.04435,,,,,0.01243515152,-0.04493414387
236.371,0.16299,-0.04555,,,,,0.009878181818,-0.04614994934
236.871,0.12169,-0.04716,,,,,0.007375151515,-0.04778115502
237.371,0.08015,-0.04808,,,,,0.004857575758,-0.04871327254
237.871,0.03811,-0.0504,,,,,0.00230969697,-0.05106382979
238.333,-0.00004,-0.05195,,,,,-0.000002424242424,-0.05263424519
238.635,0.01972,-0.04655,,,,,0.001195151515,-0.04716312057
239.135,0.0617,-0.04462,,,,,0.003739393939,-0.0452077001
239.635,0.10347,-0.04108,,,,,0.006270909091,-0.04162107396
240.135,0.14466,-0.03835,,,,,0.008767272727,-0.03885511651
240.635,0.18689,-0.03812,,,,,0.01132666667,-0.03862208713
241.135,0.22842,-0.03661,,,,,0.01384363636,-0.03709219858
241.635,0.26971,-0.03406,,,,,0.01634606061,-0.03450861196
242.135,0.31192,-0.03283,,,,,0.01890424242,-0.03326241135
242.635,0.35336,-0.03179,,,,,0.02141575758,-0.03220871327
243.135,0.39494,-0.0294,,,,,0.02393575758,-0.02978723404
243.635,0.43678,-0.02797,,,,,0.02647151515,-0.02833839919
244.135,0.47816,-0.0274,,,,,0.02897939394,-0.02776089159
244.635,0.52013,-0.02539,,,,,0.0315230303,-0.02572441743
245.135,0.56178,-0.02316,,,,,0.03404727273,-0.02346504559
245.635,0.60307,-0.02177,,,,,0.03654969697,-0.02205673759
246.135,0.6452,-0.02023,,,,,0.0391030303,-0.0204964539
246.635,0.6867,-0.01941,,,,,0.04161818182,-0.0196656535
247.135,0.72825,-0.01707,,,,,0.04413636364,-0.01729483283
247.635,0.7702,-0.01571,,,,,0.04667878788,-0.01591691996
248.135,0.81143,-0.01283,,,,,0.04917757576,-0.01299898683
248.635,0.85344,-0.01286,,,,,0.05172363636,-0.01302938197
249.135,0.8952,-0.01008,,,,,0.05425454545,-0.01021276596
249.635,0.93633,-0.00997,,,,,0.05674727273,-0.01010131712
250.135,0.9785,-0.00844,,,,,0.0593030303,-0.008551165147
250.635,1.02014,-0.00669,,,,,0.06182666667,-0.006778115502
251.135,1.06147,-0.00514,,,,,0.06433151515,-0.005207700101
251.635,1.10352,-0.00309,,,,,0.06688,-0.003130699088
252.135,1.14497,-0.00176,,,,,0.06939212121,-0.001783181358
252.635,1.18668,-0.00103,,,,,0.07192,-0.001043566363
253.135,1.22846,0.00105,,,,,0.07445212121,0.001063829787
253.635,1.26979,0.00113,,,,,0.0769569697,0.001144883485
254.135,1.31189,0.00012,,,,,0.07950848485,0.0001215805471
254.635,1.35337,0.00271,,,,,0.08202242424,0.002745694022
255.135,1.39477,0.00453,,,,,0.08453151515,0.004589665653
255.635,1.4369,0.00515,,,,,0.08708484848,0.005217831814
256.135,1.4782,0.00636,,,,,0.08958787879,0.006443768997
256.635,1.51998,0.00738,,,,,0.09212,0.007477203647
257.135,1.56186,0.00752,,,,,0.09465818182,0.007619047619
257.635,1.60303,0.01013,,,,,0.09715333333,0.01026342452
258.135,1.64509,0.01017,,,,,0.09970242424,0.01030395137
258.398,1.63877,0.01163,,,,,0.09931939394,0.01178318136
258.898,1.59665,0.00654,,,,,0.09676666667,0.006626139818
259.398,1.55496,0.00326,,,,,0.09424,0.003302938197
259.898,1.51355,0.00061,,,,,0.09173030303,0.0006180344478
260.398,1.47146,-0.00236,,,,,0.08917939394,-0.002391084093
260.898,1.43002,-0.00318,,,,,0.08666787879,-0.003221884498
261.398,1.38852,-0.00518,,,,,0.08415272727,-0.00524822695
261.898,1.34649,-0.0057,,,,,0.08160545455,-0.005775075988
262.398,1.30502,-0.00915,,,,,0.07909212121,-0.009270516717
262.898,1.26327,-0.0107,,,,,0.07656181818,-0.01084093212
263.398,1.22166,-0.01333,,,,,0.07404,-0.01350557244
263.898,1.18004,-0.01091,,,,,0.07151757576,-0.01105369807
264.398,1.13814,-0.01339,,,,,0.06897818182,-0.01356636272
264.898,1.0967,-0.01848,,,,,0.06646666667,-0.01872340426
265.398,1.05517,-0.01888,,,,,0.06394969697,-0.01912867275
265.898,1.01301,-0.01801,,,,,0.06139454545,-0.01824721378
266.398,0.97178,-0.02249,,,,,0.05889575758,-0.02278622087
266.898,0.93005,-0.02323,,,,,0.05636666667,-0.02353596758
267.398,0.8882,-0.0242,,,,,0.05383030303,-0.02451874367
267.898,0.84683,-0.02493,,,,,0.0513230303,-0.02525835866
268.398,0.80489,-0.02783,,,,,0.04878121212,-0.02819655522
268.898,0.76331,-0.02954,,,,,0.04626121212,-0.02992907801
269.398,0.72185,-0.02972,,,,,0.04374848485,-0.03011144883
269.898,0.67978,-0.03094,,,,,0.04119878788,-0.03134751773
270.398,0.63828,-0.03175,,,,,0.03868363636,-0.03216818642
270.898,0.59679,-0.036,,,,,0.03616909091,-0.03647416413
271.398,0.5548,-0.03552,,,,,0.03362424242,-0.03598784195
271.898,0.51346,-0.03736,,,,,0.03111878788,-0.037852077
272.398,0.47154,-0.03627,,,,,0.02857818182,-0.03674772036
272.898,0.42997,-0.03956,,,,,0.02605878788,-0.0400810537
273.398,0.38855,-0.0393,,,,,0.02354848485,-0.03981762918
273.898,0.3464,-0.0404,,,,,0.02099393939,-0.04093211753
274.398,0.30503,-0.04197,,,,,0.01848666667,-0.04252279635
274.898,0.26354,-0.04532,,,,,0.01597212121,-0.04591691996
275.398,0.22141,-0.04396,,,,,0.01341878788,-0.04453900709
275.898,0.18004,-0.0439,,,,,0.01091151515,-0.04447821682
276.398,0.13841,-0.04685,,,,,0.008388484848,-0.04746707194
276.898,0.09655,-0.04866,,,,,0.005851515152,-0.04930091185
277.398,0.05515,-0.04929,,,,,0.003342424242,-0.04993920973
277.898,0.01313,-0.0491,,,,,0.0007957575758,-0.04974670719
278.162,0.0024,-0.04975,,,,,0.0001454545455,-0.05040526849
278.662,0.04516,-0.04601,,,,,0.002736969697,-0.04661600811
279.162,0.08631,-0.04033,,,,,0.005230909091,-0.04086119554
279.662,0.12867,-0.03935,,,,,0.007798181818,-0.03986828774
280.162,0.17008,-0.04182,,,,,0.01030787879,-0.04237082067
280.662,0.21151,-0.03949,,,,,0.01281878788,-0.04001013171
281.162,0.25354,-0.03419,,,,,0.01536606061,-0.03464032421
281.662,0.29486,-0.03346,,,,,0.01787030303,-0.03390070922
282.162,0.33675,-0.03062,,,,,0.02040909091,-0.03102330294
282.662,0.37841,-0.03021,,,,,0.02293393939,-0.03060790274
283.162,0.41978,-0.02997,,,,,0.02544121212,-0.03036474164
283.662,0.46173,-0.0272,,,,,0.02798363636,-0.02755825735
284.162,0.50341,-0.0235,,,,,0.03050969697,-0.02380952381
284.662,0.54481,-0.02734,,,,,0.03301878788,-0.02770010132
285.162,0.58686,-0.02584,,,,,0.03556727273,-0.02618034448
285.662,0.62815,-0.01944,,,,,0.03806969697,-0.01969604863
286.162,0.67011,-0.02028,,,,,0.04061272727,-0.02054711246
286.662,0.71179,-0.0181,,,,,0.04313878788,-0.01833839919
287.162,0.75301,-0.01812,,,,,0.0456369697,-0.01835866261
287.662,0.79523,-0.01715,,,,,0.04819575758,-0.01737588652
288.162,0.83682,-0.01525,,,,,0.05071636364,-0.0154508612
288.662,0.87808,-0.01113,,,,,0.0532169697,-0.01127659574
289.162,0.92009,-0.01055,,,,,0.0557630303,-0.01068895643
289.662,0.96169,-0.01145,,,,,0.05828424242,-0.01160081054
290.162,1.0033,-0.00977,,,,,0.06080606061,-0.009898682877
290.662,1.0452,-0.00664,,,,,0.06334545455,-0.00672745694
291.162,1.0864,-0.00806,,,,,0.06584242424,-0.008166160081
291.662,1.12852,-0.00424,,,,,0.06839515152,-0.004295845998
292.162,1.17011,-0.00501,,,,,0.07091575758,-0.005075987842
292.662,1.21141,-0.00015,,,,,0.07341878788,-0.0001519756839
293.162,1.25354,-0.00252,,,,,0.07597212121,-0.002553191489
293.662,1.29503,-0.00071,,,,,0.07848666667,-0.0007193515704
294.162,1.33657,-0.0006,,,,,0.08100424242,-0.0006079027356
294.662,1.37854,0.00515,,,,,0.08354787879,0.005217831814
295.162,1.4198,0.00445,,,,,0.08604848485,0.004508611955
295.662,1.46171,0.0044,,,,,0.08858848485,0.004457953394
296.162,1.50352,0.00597,,,,,0.09112242424,0.006048632219
296.662,1.54472,0.00781,,,,,0.09361939394,0.007912867275
297.162,1.58686,0.00917,,,,,0.09617333333,0.009290780142
297.662,1.62848,0.01044,,,,,0.09869575758,0.0105775076
297.925,1.65022,0.00821,,,,,0.1000133333,0.008318135765
298.425,1.61339,0.00638,,,,,0.09778121212,0.006464032421
298.925,1.57191,0.00103,,,,,0.09526727273,0.001043566363
299.425,1.52978,-0.0034,,,,,0.09271393939,-0.003444782168
299.925,1.48835,-0.00269,,,,,0.0902030303,-0.002725430598
300.425,1.44672,-0.00608,,,,,0.08768,-0.006160081054
300.925,1.40493,-0.00471,,,,,0.08514727273,-0.004772036474
301.425,1.36343,-0.00834,,,,,0.08263212121,-0.008449848024
301.925,1.32149,-0.00893,,,,,0.08009030303,-0.009047619048
302.425,1.28008,-0.00879,,,,,0.07758060606,-0.008905775076
302.925,1.23856,-0.01238,,,,,0.07506424242,-0.01254305978
303.425,1.19637,-0.0121,,,,,0.07250727273,-0.01225937183
303.925,1.15506,-0.014,,,,,0.07000363636,-0.01418439716
304.425,1.11355,-0.01438,,,,,0.06748787879,-0.01456940223
304.925,1.07146,-0.01718,,,,,0.0649369697,-0.01740628166
305.425,1.03011,-0.01955,,,,,0.06243090909,-0.01980749747
305.925,0.98831,-0.02151,,,,,0.05989757576,-0.02179331307
306.425,0.94661,-0.02241,,,,,0.05737030303,-0.02270516717
306.925,0.90516,-0.02332,,,,,0.05485818182,-0.02362715299
307.425,0.86312,-0.02674,,,,,0.05231030303,-0.02709219858
307.925,0.8217,-0.02815,,,,,0.0498,-0.02852077001
308.425,0.78008,-0.03005,,,,,0.04727757576,-0.03044579534
308.925,0.73819,-0.02835,,,,,0.04473878788,-0.02872340426
309.425,0.69668,-0.03161,,,,,0.0422230303,-0.03202634245
309.925,0.65497,-0.03206,,,,,0.03969515152,-0.0324822695
310.425,0.61325,-0.0347,,,,,0.03716666667,-0.03515704154
310.925,0.57184,-0.03364,,,,,0.0346569697,-0.03408308004
311.425,0.52976,-0.0368,,,,,0.03210666667,-0.03728470111
311.925,0.4884,-0.03914,,,,,0.0296,-0.03965552178
312.425,0.44686,-0.04059,,,,,0.02708242424,-0.04112462006
312.925,0.40472,-0.0432,,,,,0.02452848485,-0.04376899696
313.425,0.36343,-0.04284,,,,,0.02202606061,-0.04340425532
313.925,0.32175,-0.04298,,,,,0.0195,-0.04354609929
314.425,0.27985,-0.04427,,,,,0.01696060606,-0.04485309017
314.925,0.2384,-0.04452,,,,,0.01444848485,-0.04510638298
315.425,0.19662,-0.04739,,,,,0.01191636364,-0.0480141844
315.925,0.15497,-0.04615,,,,,0.009392121212,-0.04675785208
316.425,0.11351,-0.04809,,,,,0.006879393939,-0.04872340426
316.925,0.07138,-0.04987,,,,,0.004326060606,-0.05052684904
317.425,0.03007,-0.05116,,,,,0.001822424242,-0.05183383992
317.788,-0.00013,-0.05357,,,,,-0.000007878787879,-0.05427558257
318.189,0.02817,-0.04862,,,,,0.001707272727,-0.04926038501
318.689,0.07015,-0.04539,,,,,0.004251515152,-0.04598784195
319.189,0.11156,-0.04447,,,,,0.006761212121,-0.04505572442
319.689,0.15341,-0.04062,,,,,0.009297575758,-0.0411550152
320.189,0.19512,-0.04138,,,,,0.01182545455,-0.04192502533
320.689,0.23638,-0.03691,,,,,0.01432606061,-0.03739614995
321.189,0.27848,-0.03286,,,,,0.01687757576,-0.03329280648
321.689,0.32009,-0.03294,,,,,0.01939939394,-0.03337386018
322.189,0.36147,-0.03229,,,,,0.02190727273,-0.03271529889
322.689,0.40351,-0.02915,,,,,0.02445515152,-0.02953394124
323.189,0.44499,-0.02904,,,,,0.02696909091,-0.0294224924
323.689,0.48671,-0.02843,,,,,0.02949757576,-0.02880445795
324.189,0.52851,-0.02526,,,,,0.03203090909,-0.02559270517
324.689,0.56969,-0.02336,,,,,0.03452666667,-0.02366767984
325.189,0.61191,-0.02153,,,,,0.03708545455,-0.02181357649
325.689,0.65354,-0.02195,,,,,0.03960848485,-0.02223910841
326.189,0.69468,-0.02034,,,,,0.04210181818,-0.02060790274
326.689,0.73688,-0.01953,,,,,0.04465939394,-0.01978723404
327.189,0.77839,-0.01807,,,,,0.04717515152,-0.01830800405
327.689,0.81989,-0.01687,,,,,0.04969030303,-0.01709219858
328.189,0.86178,-0.01584,,,,,0.05222909091,-0.01604863222
328.689,0.9032,-0.01382,,,,,0.05473939394,-0.01400202634
329.189,0.94506,-0.0144,,,,,0.05727636364,-0.01458966565
329.689,0.98682,-0.01033,,,,,0.05980727273,-0.01046605876
330.189,1.02814,-0.00955,,,,,0.06231151515,-0.009675785208
330.689,1.07023,-0.0103,,,,,0.06486242424,-0.01043566363
331.189,1.1117,-0.00626,,,,,0.06737575758,-0.006342451874
331.689,1.15324,-0.00683,,,,,0.06989333333,-0.006919959473
332.189,1.1952,-0.00359,,,,,0.07243636364,-0.003637284701
332.689,1.23642,-0.00412,,,,,0.07493454545,-0.004174265451
333.189,1.27845,-0.00179,,,,,0.07748181818,-0.001813576494
333.689,1.32018,-0.00077,,,,,0.08001090909,-0.000780141844
334.189,1.36133,-0.00154,,,,,0.08250484848,-0.001560283688
334.689,1.40343,0.00316,,,,,0.08505636364,0.003201621074
335.189,1.44517,0.00367,,,,,0.08758606061,0.003718338399
335.689,1.48639,0.00575,,,,,0.09008424242,0.005825734549
336.189,1.52853,0.00649,,,,,0.09263818182,0.006575481256
336.689,1.56993,0.00665,,,,,0.09514727273,0.006737588652
337.189,1.61167,0.0095,,,,,0.0976769697,0.009625126646
337.65,1.65003,0.01033,,,,,0.1000018182,0.01046605876
337.952,1.63016,0.0067,,,,,0.09879757576,0.006788247214
338.452,1.58816,0.00506,,,,,0.09625212121,0.005126646403
338.952,1.5467,0.00366,,,,,0.09373939394,0.003708206687
339.452,1.50483,-0.00075,,,,,0.09120181818,-0.0007598784195
339.952,1.4634,-0.00309,,,,,0.08869090909,-0.003130699088
340.452,1.42173,-0.00569,,,,,0.08616545455,-0.005764944276
340.952,1.37975,-0.0064,,,,,0.08362121212,-0.006484295846
341.452,1.33838,-0.00896,,,,,0.08111393939,-0.009078014184
341.952,1.29682,-0.01034,,,,,0.07859515152,-0.01047619048
342.452,1.25474,-0.01056,,,,,0.07604484848,-0.01069908815
342.952,1.21342,-0.01611,,,,,0.07354060606,-0.01632218845
343.452,1.17161,-0.01713,,,,,0.07100666667,-0.0173556231
343.952,1.12991,-0.01633,,,,,0.06847939394,-0.01654508612
344.452,1.08853,-0.02108,,,,,0.06597151515,-0.02135764944
344.952,1.04647,-0.01913,,,,,0.06342242424,-0.01938196555
345.452,1.00498,-0.02295,,,,,0.06090787879,-0.02325227964
345.952,0.96349,-0.02396,,,,,0.05839333333,-0.02427558257
346.452,0.92145,-0.02558,,,,,0.05584545455,-0.02591691996
346.952,0.87995,-0.02507,,,,,0.05333030303,-0.02540020263
347.452,0.83836,-0.02899,,,,,0.05080969697,-0.02937183384
347.952,0.79653,-0.0311,,,,,0.04827454545,-0.03150962513
348.452,0.75514,-0.03101,,,,,0.04576606061,-0.03141843972
348.952,0.71313,-0.032,,,,,0.04322,-0.03242147923
349.452,0.67172,-0.03292,,,,,0.04071030303,-0.03335359676
349.952,0.63023,-0.03616,,,,,0.03819575758,-0.03663627153
350.452,0.58803,-0.03534,,,,,0.03563818182,-0.03580547112
350.952,0.54669,-0.03782,,,,,0.03313272727,-0.03831813576
351.452,0.5051,-0.03949,,,,,0.03061212121,-0.04001013171
351.952,0.46311,-0.04051,,,,,0.02806727273,-0.04104356636
352.452,0.42169,-0.03958,,,,,0.0255569697,-0.04010131712
352.952,0.37998,-0.04128,,,,,0.02302909091,-0.04182370821
353.452,0.33826,-0.0425,,,,,0.02050060606,-0.0430597771
353.952,0.29678,-0.04351,,,,,0.01798666667,-0.04408308004
354.452,0.25478,-0.0429,,,,,0.01544121212,-0.04346504559
354.952,0.21341,-0.04683,,,,,0.01293393939,-0.04744680851
355.452,0.17174,-0.04795,,,,,0.01040848485,-0.04858156028
355.952,0.12974,-0.04745,,,,,0.007863030303,-0.04807497467
356.452,0.08841,-0.04924,,,,,0.005358181818,-0.04988855117
356.952,0.04659,-0.05144,,,,,0.002823636364,-0.05211752786
357.452,0.00494,-0.05233,,,,,0.0002993939394,-0.05301925025
357.716,0.0114,-0.05221,,,,,0.0006909090909,-0.05289766971
358.216,0.05302,-0.04791,,,,,0.003213333333,-0.04854103343
358.716,0.09505,-0.04545,,,,,0.005760606061,-0.04604863222
359.216,0.13673,-0.04228,,,,,0.008286666667,-0.04283687943
359.716,0.17813,-0.0408,,,,,0.01079575758,-0.04133738602
360.216,0.22007,-0.03913,,,,,0.01333757576,-0.03964539007
360.716,0.26163,-0.03476,,,,,0.01585636364,-0.03521783181
361.216,0.30326,-0.0358,,,,,0.01837939394,-0.03627152989
361.716,0.34515,-0.03364,,,,,0.02091818182,-0.03408308004
362.216,0.38636,-0.03293,,,,,0.02341575758,-0.03336372847
362.716,0.4285,-0.03022,,,,,0.02596969697,-0.03061803445
363.216,0.47008,-0.02932,,,,,0.02848969697,-0.02970618034
363.716,0.51133,-0.02639,,,,,0.03098969697,-0.02673758865
364.216,0.55352,-0.02633,,,,,0.03354666667,-0.02667679838
364.716,0.59503,-0.02514,,,,,0.03606242424,-0.02547112462
365.216,0.63647,-0.02406,,,,,0.03857393939,-0.0243768997
365.716,0.67837,-0.02042,,,,,0.04111333333,-0.02068895643
366.216,0.71986,-0.02159,,,,,0.04362787879,-0.02187436677
366.716,0.76172,-0.01859,,,,,0.04616484848,-0.01883485309
367.216,0.80346,-0.01822,,,,,0.04869454545,-0.01845997974
367.716,0.84471,-0.01538,,,,,0.05119454545,-0.01558257345
368.216,0.88687,-0.01404,,,,,0.05374969697,-0.01422492401
368.716,0.92839,-0.01359,,,,,0.05626606061,-0.01376899696
369.216,0.96979,-0.01028,,,,,0.05877515152,-0.0104154002
369.716,1.01186,-0.01148,,,,,0.06132484848,-0.01163120567
370.216,1.05322,-0.01055,,,,,0.06383151515,-0.01068895643
370.716,1.095,-0.00852,,,,,0.06636363636,-0.008632218845
371.216,1.13685,-0.00787,,,,,0.0689,-0.007973657548
371.716,1.17801,-0.00412,,,,,0.07139454545,-0.004174265451
372.216,1.22007,-0.00283,,,,,0.07394363636,-0.002867274569
372.716,1.26174,-0.00168,,,,,0.07646909091,-0.00170212766
373.216,1.30302,0.0005,,,,,0.07897090909,0.000506585613
373.716,1.34513,0.00111,,,,,0.0815230303,0.001124620061
374.216,1.38669,0.00188,,,,,0.08404181818,0.001904761905
374.716,1.42824,0.00243,,,,,0.08656,0.002462006079
375.216,1.47013,0.00388,,,,,0.08909878788,0.003931104357
375.716,1.51149,0.00548,,,,,0.09160545455,0.005552178318
376.216,1.55347,0.00389,,,,,0.09414969697,0.003941236069
376.716,1.59505,0.0088,,,,,0.09666969697,0.008915906788
377.216,1.6364,0.00909,,,,,0.09917575758,0.009209726444
377.48,1.6477,0.01022,,,,,0.09986060606,0.01035460993
377.98,1.60531,0.00501,,,,,0.09729151515,0.005075987842
378.48,1.56322,0.00348,,,,,0.09474060606,0.003525835866
378.98,1.52196,-0.00214,,,,,0.09224,-0.002168186424
379.48,1.48034,-0.00507,,,,,0.08971757576,-0.005136778116
379.98,1.43817,-0.0049,,,,,0.08716181818,-0.004964539007
380.48,1.39683,-0.00489,,,,,0.08465636364,-0.004954407295
380.98,1.35522,-0.01075,,,,,0.08213454545,-0.01089159068
381.48,1.31334,-0.01437,,,,,0.07959636364,-0.01455927052
381.98,1.27196,-0.01253,,,,,0.07708848485,-0.01269503546
382.48,1.22997,-0.01395,,,,,0.07454363636,-0.0141337386
382.98,1.18846,-0.01594,,,,,0.07202787879,-0.01614994934
383.48,1.147,-0.01826,,,,,0.06951515152,-0.01850050659
383.98,1.1049,-0.02044,,,,,0.06696363636,-0.02070921986
384.48,1.0635,-0.01955,,,,,0.06445454545,-0.01980749747
384.98,1.02182,-0.02311,,,,,0.06192848485,-0.02341438703
385.48,0.98013,-0.0243,,,,,0.05940181818,-0.02462006079
385.98,0.93851,-0.02287,,,,,0.05687939394,-0.02317122594
386.48,0.89669,-0.02611,,,,,0.05434484848,-0.02645390071
386.98,0.85515,-0.02725,,,,,0.05182727273,-0.02760891591
387.48,0.81366,-0.02922,,,,,0.04931272727,-0.02960486322
387.98,0.77145,-0.02945,,,,,0.04675454545,-0.0298378926
388.48,0.73026,-0.03123,,,,,0.04425818182,-0.03164133739
388.98,0.6886,-0.03339,,,,,0.04173333333,-0.03382978723
389.48,0.64656,-0.03549,,,,,0.03918545455,-0.03595744681
389.98,0.60524,-0.03471,,,,,0.03668121212,-0.03516717325
390.48,0.56343,-0.03559,,,,,0.03414727273,-0.03605876393
390.98,0.52173,-0.03865,,,,,0.03162,-0.03915906788
391.48,0.48028,-0.04127,,,,,0.02910787879,-0.04181357649
391.98,0.43832,-0.03896,,,,,0.02656484848,-0.03947315096
392.48,0.39681,-0.04116,,,,,0.02404909091,-0.04170212766
392.98,0.35533,-0.04333,,,,,0.02153515152,-0.04390070922
393.48,0.31319,-0.0438,,,,,0.01898121212,-0.0443768997
393.98,0.27194,-0.04564,,,,,0.01648121212,-0.04624113475
394.48,0.23013,-0.04688,,,,,0.01394727273,-0.04749746707
394.98,0.18846,-0.0486,,,,,0.01142181818,-0.04924012158
395.48,0.14696,-0.04977,,,,,0.008906666667,-0.05042553191
395.98,0.1049,-0.04845,,,,,0.006357575758,-0.0490881459
396.48,0.06351,-0.05272,,,,,0.003849090909,-0.05341438703
396.98,0.02199,-0.05365,,,,,0.001332727273,-0.05435663627
397.244,-0.00006,-0.05223,,,,,-0.000003636363636,-0.05291793313