File: mechanical/hysteresis/databak/hmwg_hysteresis - conductive_6.csv
Time,Extension,Load,Length,Width,Thickness,CS Area,Strain,Stress
(s),(mm),(N),(mm),(mm),(mm),(mm^2),(mm/mm),(MPa)
0,0,-0.02779,16.5,2.82,0.35,0.987,0,-0.02815602837
0.5,0.03876,0.09206,,,,,0.002349090909,0.09327254306
1,0.08048,0.15242,,,,,0.004877575758,0.1544275583
1.5,0.12182,0.18802,,,,,0.007383030303,0.1904964539
2,0.16379,0.21674,,,,,0.009926666667,0.2195947315
2.5,0.20523,0.23581,,,,,0.01243818182,0.2389159068
3,0.24711,0.25155,,,,,0.01497636364,0.2548632219
3.5,0.28871,0.26573,,,,,0.01749757576,0.2692299899
4,0.33002,0.27604,,,,,0.02000121212,0.2796757852
4.5,0.37215,0.28477,,,,,0.02255454545,0.28852077
5,0.41374,0.30002,,,,,0.02507515152,0.3039716312
5.5,0.45498,0.30015,,,,,0.02757454545,0.3041033435
6,0.49717,0.30983,,,,,0.03013151515,0.3139108409
6.5,0.53864,0.31581,,,,,0.03264484848,0.3199696049
7,0.58024,0.32064,,,,,0.03516606061,0.3248632219
7.5,0.62218,0.32875,,,,,0.03770787879,0.3330800405
8,0.66352,0.33224,,,,,0.04021333333,0.3366160081
8.5,0.70543,0.3355,,,,,0.04275333333,0.3399189463
9,0.74711,0.34113,,,,,0.04527939394,0.3456231003
9.5,0.78837,0.34376,,,,,0.04778,0.3482877406
10,0.83049,0.34977,,,,,0.05033272727,0.3543768997
10.5,0.872,0.35243,,,,,0.05284848485,0.3570719352
11,0.91356,0.3531,,,,,0.05536727273,0.3577507599
11.5,0.95549,0.35745,,,,,0.05790848485,0.3621580547
12,0.99687,0.36081,,,,,0.06041636364,0.36556231
12.5,1.03877,0.36126,,,,,0.06295575758,0.3660182371
13,1.08051,0.36499,,,,,0.06548545455,0.3697973658
13.5,1.12164,0.3667,,,,,0.06797818182,0.3715298886
14,1.16387,0.37093,,,,,0.07053757576,0.3758156028
14.5,1.20549,0.37529,,,,,0.07306,0.3802330294
15,1.24674,0.37283,,,,,0.07556,0.3777406282
15.5,1.28887,0.37722,,,,,0.07811333333,0.3821884498
16,1.33026,0.37923,,,,,0.08062181818,0.384224924
16.5,1.37195,0.38071,,,,,0.08314848485,0.3857244174
17,1.41376,0.38454,,,,,0.08568242424,0.3896048632
17.5,1.45515,0.3828,,,,,0.08819090909,0.3878419453
18,1.49709,0.38654,,,,,0.09073272727,0.3916312057
18.5,1.53881,0.38876,,,,,0.09326121212,0.3938804458
19,1.58011,0.38884,,,,,0.09576424242,0.3939614995
19.5,1.62221,0.39336,,,,,0.09831575758,0.3985410334
19.841,1.65013,0.39093,,,,,0.1000078788,0.3960790274
20.242,1.62176,0.21575,,,,,0.09828848485,0.218591692
20.742,1.58035,0.09321,,,,,0.09577878788,0.09443768997
21.242,1.53882,0.00294,,,,,0.09326181818,0.002978723404
21.742,1.49669,-0.06913,,,,,0.09070848485,-0.07004052685
22.242,1.45534,-0.12664,,,,,0.08820242424,-0.1283080041
22.742,1.41378,-0.17656,,,,,0.08568363636,-0.1788855117
23.242,1.37178,-0.22317,,,,,0.08313818182,-0.2261094225
23.742,1.3304,-0.26158,,,,,0.08063030303,-0.2650253293
24.242,1.28846,-0.29701,,,,,0.07808848485,-0.3009219858
24.742,1.24706,-0.32684,,,,,0.07557939394,-0.3311448835
25.242,1.20545,-0.3577,,,,,0.07305757576,-0.3624113475
25.742,1.16338,-0.38527,,,,,0.07050787879,-0.3903444782
26.242,1.12205,-0.40995,,,,,0.0680030303,-0.4153495441
26.742,1.08039,-0.43255,,,,,0.06547818182,-0.4382472138
27.242,1.03844,-0.45734,,,,,0.06293575758,-0.4633637285
27.742,0.99705,-0.47511,,,,,0.06042727273,-0.4813677812
28.242,0.95519,-0.49801,,,,,0.05789030303,-0.5045694022
28.742,0.91357,-0.51453,,,,,0.05536787879,-0.5213069909
29.242,0.8722,-0.5293,,,,,0.05286060606,-0.5362715299
29.742,0.82999,-0.54727,,,,,0.05030242424,-0.5544782168
30.242,0.78862,-0.56212,,,,,0.04779515152,-0.5695238095
30.742,0.74714,-0.57602,,,,,0.04528121212,-0.5836068896
31.242,0.70506,-0.59145,,,,,0.04273090909,-0.5992401216
31.742,0.66362,-0.60453,,,,,0.04021939394,-0.6124924012
32.242,0.62202,-0.6155,,,,,0.03769818182,-0.6236068896
32.742,0.58025,-0.6281,,,,,0.03516666667,-0.636372847
33.242,0.53878,-0.63936,,,,,0.03265333333,-0.647781155
33.742,0.49681,-0.65073,,,,,0.03010969697,-0.6593009119
34.242,0.45536,-0.66087,,,,,0.02759757576,-0.6695744681
34.742,0.41376,-0.6721,,,,,0.02507636364,-0.680952381
35.242,0.37173,-0.68276,,,,,0.02252909091,-0.6917527862
35.742,0.33038,-0.69284,,,,,0.0200230303,-0.7019655522
36.242,0.2886,-0.70306,,,,,0.01749090909,-0.7123201621
36.742,0.24685,-0.7133,,,,,0.01496060606,-0.7226950355
37.242,0.20546,-0.72103,,,,,0.01245212121,-0.730526849
37.742,0.16345,-0.73056,,,,,0.009906060606,-0.7401823708
38.242,0.12197,-0.73875,,,,,0.007392121212,-0.7484802432
38.742,0.08053,-0.7473,,,,,0.004880606061,-0.7571428571
39.242,0.03844,-0.75508,,,,,0.00232969697,-0.7650253293
39.708,-0.00007,-0.7612,,,,,-0.000004242424242,-0.7712259372
40.01,0.01964,-0.68676,,,,,0.00119030303,-0.6958054711
40.51,0.06186,-0.62239,,,,,0.003749090909,-0.6305876393
41.01,0.10333,-0.57775,,,,,0.006262424242,-0.5853596758
41.51,0.14475,-0.54341,,,,,0.008772727273,-0.5505673759
42.01,0.1869,-0.50885,,,,,0.01132727273,-0.5155521783
42.51,0.22822,-0.48128,,,,,0.01383151515,-0.4876190476
43.01,0.26999,-0.45474,,,,,0.0163630303,-0.4607294833
43.51,0.31186,-0.42821,,,,,0.01890060606,-0.4338500507
44.01,0.35306,-0.40555,,,,,0.02139757576,-0.4108915907
44.51,0.39515,-0.38221,,,,,0.02394848485,-0.3872441743
45.01,0.43686,-0.35833,,,,,0.02647636364,-0.3630496454
45.51,0.47807,-0.33667,,,,,0.02897393939,-0.3411043566
46.01,0.52014,-0.31254,,,,,0.03152363636,-0.316656535
46.51,0.56174,-0.29159,,,,,0.03404484848,-0.2954305978
47.01,0.60331,-0.27426,,,,,0.03656424242,-0.2778723404
47.51,0.64513,-0.24943,,,,,0.03909878788,-0.2527152989
48.01,0.68646,-0.22871,,,,,0.04160363636,-0.2317223911
48.51,0.72845,-0.20755,,,,,0.04414848485,-0.2102836879
49.01,0.77008,-0.18714,,,,,0.04667151515,-0.1896048632
49.51,0.81131,-0.16662,,,,,0.04917030303,-0.1688145897
50.01,0.85357,-0.1445,,,,,0.05173151515,-0.1464032421
50.51,0.89507,-0.12321,,,,,0.05424666667,-0.1248328267
51.01,0.9365,-0.10488,,,,,0.05675757576,-0.1062613982
51.51,0.97853,-0.08135,,,,,0.05930484848,-0.08242147923
52.01,1.01993,-0.06338,,,,,0.06181393939,-0.0642147923
52.51,1.06176,-0.04309,,,,,0.06434909091,-0.04365754813
53.01,1.1035,-0.02107,,,,,0.06687878788,-0.02134751773
53.51,1.14481,-0.00192,,,,,0.06938242424,-0.001945288754
54.01,1.18686,0.01762,,,,,0.07193090909,0.017852077
54.51,1.22847,0.03896,,,,,0.07445272727,0.03947315096
55.01,1.26981,0.0556,,,,,0.07695818182,0.05633232016
55.51,1.31183,0.07761,,,,,0.07950484848,0.07863221884
56.01,1.35319,0.09725,,,,,0.08201151515,0.09853090172
56.51,1.39506,0.11563,,,,,0.08454909091,0.1171529889
57.01,1.43676,0.13508,,,,,0.08707636364,0.1368591692
57.51,1.47813,0.15134,,,,,0.08958363636,0.1533333333
58.01,1.52023,0.16747,,,,,0.09213515152,0.1696757852
58.51,1.56183,0.18718,,,,,0.09465636364,0.1896453901
59.01,1.603,0.19954,,,,,0.09715151515,0.2021681864
59.51,1.64526,0.21515,,,,,0.09971272727,0.2179837893
59.776,1.63918,0.12893,,,,,0.09934424242,0.1306281662
60.276,1.59714,-0.00398,,,,,0.09679636364,-0.004032421479
60.776,1.55517,-0.0926,,,,,0.09425272727,-0.09381965552
61.276,1.51376,-0.15877,,,,,0.0917430303,-0.1608611955
61.776,1.47202,-0.21331,,,,,0.08921333333,-0.2161195542
62.276,1.43033,-0.26205,,,,,0.08668666667,-0.2655015198
62.776,1.3889,-0.30267,,,,,0.08417575758,-0.306656535
63.276,1.34677,-0.33917,,,,,0.08162242424,-0.3436372847
63.776,1.30542,-0.37087,,,,,0.07911636364,-0.3757548126
64.276,1.26384,-0.39946,,,,,0.07659636364,-0.4047213779
64.776,1.22188,-0.42984,,,,,0.07405333333,-0.4355015198
65.276,1.18043,-0.45393,,,,,0.07154121212,-0.4599088146
65.776,1.1386,-0.47479,,,,,0.06900606061,-0.4810435664
66.276,1.097,-0.49778,,,,,0.06648484848,-0.5043363728
66.776,1.05552,-0.51569,,,,,0.06397090909,-0.5224822695
67.276,1.01345,-0.53492,,,,,0.06142121212,-0.5419655522
67.776,0.97207,-0.55268,,,,,0.05891333333,-0.5599594732
68.276,0.93069,-0.56821,,,,,0.05640545455,-0.5756940223
68.776,0.88839,-0.58613,,,,,0.05384181818,-0.5938500507
69.276,0.84711,-0.59902,,,,,0.05134,-0.6069098278
69.776,0.80538,-0.61301,,,,,0.04881090909,-0.6210840932
70.276,0.76371,-0.6275,,,,,0.04628545455,-0.6357649443
70.776,0.72211,-0.64096,,,,,0.04376424242,-0.649402229
71.276,0.68021,-0.65174,,,,,0.04122484848,-0.6603242148
71.776,0.6387,-0.66528,,,,,0.03870909091,-0.6740425532
72.276,0.59717,-0.67616,,,,,0.03619212121,-0.6850658561
72.776,0.55507,-0.68864,,,,,0.03364060606,-0.697710233
73.276,0.51379,-0.69719,,,,,0.03113878788,-0.706372847
73.776,0.47212,-0.7071,,,,,0.02861333333,-0.7164133739
74.276,0.4301,-0.71821,,,,,0.02606666667,-0.7276697062
74.776,0.38887,-0.72511,,,,,0.02356787879,-0.7346605876
75.276,0.34689,-0.73482,,,,,0.02102363636,-0.7444984802
75.776,0.30534,-0.74523,,,,,0.01850545455,-0.7550455927
76.276,0.26389,-0.75336,,,,,0.01599333333,-0.7632826748
76.776,0.22184,-0.76306,,,,,0.01344484848,-0.7731104357
77.276,0.18032,-0.77096,,,,,0.01092848485,-0.7811144883
77.776,0.13889,-0.77914,,,,,0.008417575758,-0.789402229
78.276,0.09684,-0.78959,,,,,0.005869090909,-0.7999898683
78.776,0.05539,-0.79551,,,,,0.003356969697,-0.8059878419
79.276,0.01367,-0.80187,,,,,0.0008284848485,-0.8124316109
79.545,0.00237,-0.78513,,,,,0.0001436363636,-0.7954711246
80.045,0.04495,-0.70165,,,,,0.002724242424,-0.7108915907
80.545,0.08651,-0.65543,,,,,0.005243030303,-0.6640628166
81.045,0.12855,-0.61754,,,,,0.007790909091,-0.6256737589
81.545,0.16976,-0.58733,,,,,0.01028848485,-0.5950658561
82.045,0.21183,-0.56037,,,,,0.01283818182,-0.5677507599
82.545,0.25348,-0.53329,,,,,0.01536242424,-0.5403140831
83.045,0.29476,-0.51057,,,,,0.01786424242,-0.5172948328
83.545,0.33684,-0.48472,,,,,0.02041454545,-0.4911043566
84.045,0.37844,-0.46408,,,,,0.02293575758,-0.4701925025
84.545,0.4199,-0.44128,,,,,0.02544848485,-0.4470921986
85.045,0.46179,-0.41958,,,,,0.02798727273,-0.425106383
85.545,0.50317,-0.40024,,,,,0.03049515152,-0.4055116515
86.045,0.54506,-0.38012,,,,,0.03303393939,-0.3851266464
86.545,0.58675,-0.35978,,,,,0.03556060606,-0.3645187437
87.045,0.62799,-0.34286,,,,,0.03806,-0.3473758865
87.545,0.67026,-0.32208,,,,,0.04062181818,-0.3263221884
88.045,0.71171,-0.30145,,,,,0.04313393939,-0.3054204661
88.545,0.75317,-0.28382,,,,,0.04564666667,-0.2875582573
89.045,0.79521,-0.26257,,,,,0.04819454545,-0.2660283688
89.545,0.83657,-0.24505,,,,,0.05070121212,-0.2482776089
90.045,0.87829,-0.22566,,,,,0.05322969697,-0.2286322188
90.545,0.92022,-0.20538,,,,,0.05577090909,-0.2080851064
91.045,0.96142,-0.1861,,,,,0.05826787879,-0.1885511651
91.545,1.00342,-0.16583,,,,,0.06081333333,-0.1680141844
92.045,1.04515,-0.14455,,,,,0.06334242424,-0.1464539007
92.545,1.08644,-0.12673,,,,,0.06584484848,-0.1283991895
93.045,1.12842,-0.10479,,,,,0.06838909091,-0.1061702128
93.545,1.16995,-0.0839,,,,,0.07090606061,-0.08500506586
94.045,1.21161,-0.06743,,,,,0.07343090909,-0.06831813576
94.545,1.2534,-0.04726,,,,,0.07596363636,-0.04788247214
95.045,1.29477,-0.02717,,,,,0.07847090909,-0.02752786221
95.545,1.33684,-0.00529,,,,,0.08102060606,-0.005359675785
96.045,1.37846,0.01543,,,,,0.0835430303,0.01563323202
96.545,1.41972,0.03363,,,,,0.08604363636,0.03407294833
97.045,1.46185,0.05562,,,,,0.0885969697,0.05635258359
97.545,1.5034,0.07471,,,,,0.09111515152,0.07569402229
98.045,1.54486,0.09363,,,,,0.09362787879,0.09486322188
98.545,1.58684,0.1138,,,,,0.09617212121,0.1152988855
99.045,1.62826,0.13217,,,,,0.09868242424,0.1339108409
99.311,1.65021,0.13973,,,,,0.1000127273,0.1415704154
99.811,1.61362,-0.02571,,,,,0.09779515152,-0.02604863222
100.311,1.57214,-0.11632,,,,,0.09528121212,-0.117852077
100.811,1.53012,-0.18622,,,,,0.09273454545,-0.1886727457
101.311,1.48876,-0.24088,,,,,0.09022787879,-0.2440526849
101.811,1.44713,-0.28752,,,,,0.08770484848,-0.2913069909
102.311,1.40508,-0.32971,,,,,0.08515636364,-0.3340526849
102.811,1.36376,-0.36311,,,,,0.08265212121,-0.3678926039
103.311,1.32199,-0.395,,,,,0.08012060606,-0.4002026342
103.811,1.28023,-0.42577,,,,,0.07758969697,-0.4313779129
104.311,1.23885,-0.45036,,,,,0.07508181818,-0.4562917933
104.811,1.19679,-0.47608,,,,,0.07253272727,-0.4823505572
105.311,1.15535,-0.49995,,,,,0.07002121212,-0.5065349544
105.811,1.11392,-0.51982,,,,,0.06751030303,-0.5266666667
106.311,1.07169,-0.53916,,,,,0.06495090909,-0.5462613982
106.811,1.03036,-0.55724,,,,,0.06244606061,-0.5645795339
107.311,0.98882,-0.57391,,,,,0.05992848485,-0.5814690983
107.811,0.94683,-0.59198,,,,,0.05738363636,-0.5997771023
108.311,0.90538,-0.60665,,,,,0.05487151515,-0.6146403242
108.811,0.86357,-0.61877,,,,,0.05233757576,-0.6269199595
109.311,0.82201,-0.63206,,,,,0.04981878788,-0.6403850051
109.811,0.78054,-0.64438,,,,,0.04730545455,-0.6528672746
110.311,0.73846,-0.65779,,,,,0.04475515152,-0.6664539007
110.811,0.69708,-0.67067,,,,,0.04224727273,-0.6795035461
111.311,0.65542,-0.6834,,,,,0.03972242424,-0.6924012158
111.811,0.6135,-0.69477,,,,,0.03718181818,-0.7039209726
112.311,0.5721,-0.70348,,,,,0.03467272727,-0.712745694
112.811,0.53026,-0.71445,,,,,0.0321369697,-0.7238601824
113.311,0.48865,-0.72451,,,,,0.02961515152,-0.7340526849
113.811,0.4473,-0.73468,,,,,0.02710909091,-0.7443566363
114.311,0.40507,-0.74425,,,,,0.02454969697,-0.7540526849
114.811,0.36376,-0.75395,,,,,0.02204606061,-0.7638804458
115.311,0.32218,-0.76277,,,,,0.01952606061,-0.772816616
115.811,0.28017,-0.77138,,,,,0.01698,-0.7815400203
116.311,0.23869,-0.77907,,,,,0.01446606061,-0.789331307
116.811,0.19704,-0.78728,,,,,0.01194181818,-0.7976494428
117.311,0.15529,-0.79267,,,,,0.009411515152,-0.8031104357
117.811,0.11373,-0.80111,,,,,0.006892727273,-0.8116616008
118.311,0.07181,-0.80633,,,,,0.004352121212,-0.8169503546
118.811,0.03043,-0.81315,,,,,0.001844242424,-0.8238601824
119.178,-0.0001,-0.81723,,,,,-0.000006060606061,-0.827993921
119.579,0.02845,-0.75463,,,,,0.001724242424,-0.7645694022
120.079,0.07024,-0.69896,,,,,0.004256969697,-0.7081661601
120.579,0.1114,-0.66128,,,,,0.006751515152,-0.6699898683
121.079,0.15359,-0.6288,,,,,0.009308484848,-0.6370820669
121.579,0.19519,-0.60044,,,,,0.01182969697,-0.6083485309
122.079,0.23649,-0.57645,,,,,0.01433272727,-0.5840425532
122.579,0.27849,-0.55139,,,,,0.01687818182,-0.5586524823
123.079,0.31998,-0.52893,,,,,0.01939272727,-0.5358966565
123.579,0.36177,-0.50902,,,,,0.02192545455,-0.5157244174
124.079,0.40351,-0.48742,,,,,0.02445515152,-0.4938399189
124.579,0.4448,-0.46735,,,,,0.02695757576,-0.4735055724
125.079,0.4869,-0.44818,,,,,0.02950909091,-0.45408308
125.579,0.52847,-0.4286,,,,,0.03202848485,-0.4342451874
126.079,0.56976,-0.41068,,,,,0.03453090909,-0.4160891591
126.579,0.61197,-0.39118,,,,,0.03708909091,-0.3963323202
127.079,0.65335,-0.36972,,,,,0.0395969697,-0.3745896657
127.579,0.69503,-0.35357,,,,,0.0421230303,-0.3582269504
128.079,0.73688,-0.33328,,,,,0.04465939394,-0.3376697062
128.579,0.7782,-0.31438,,,,,0.04716363636,-0.31852077
129.079,0.82019,-0.29761,,,,,0.04970848485,-0.3015298886
129.579,0.86187,-0.27915,,,,,0.05223454545,-0.2828267477
130.079,0.90315,-0.26068,,,,,0.05473636364,-0.2641134752
130.579,0.94519,-0.24075,,,,,0.05728424242,-0.2439209726
131.079,0.98679,-0.22307,,,,,0.05980545455,-0.2260081054
131.579,1.02825,-0.20469,,,,,0.06231818182,-0.2073860182
132.079,1.07022,-0.18255,,,,,0.06486181818,-0.1849544073
132.579,1.1115,-0.16428,,,,,0.06736363636,-0.166443769
133.079,1.15356,-0.14456,,,,,0.06991272727,-0.1464640324
133.579,1.19513,-0.12294,,,,,0.07243212121,-0.1245592705
134.079,1.23649,-0.10362,,,,,0.07493878788,-0.1049848024
134.579,1.27862,-0.08245,,,,,0.07749212121,-0.08353596758
135.079,1.32019,-0.06371,,,,,0.08001151515,-0.0645491388
135.579,1.36143,-0.04573,,,,,0.08251090909,-0.04633232016
136.079,1.40367,-0.02288,,,,,0.08507090909,-0.02318135765
136.579,1.44501,-0.00247,,,,,0.08757636364,-0.002502532928
137.079,1.48666,0.01595,,,,,0.09010060606,0.01616008105
137.579,1.52854,0.03788,,,,,0.09263878788,0.03837892604
138.079,1.56979,0.05499,,,,,0.09513878788,0.05571428571
138.579,1.61182,0.07443,,,,,0.09768606061,0.07541033435
139.042,1.65002,0.09343,,,,,0.1000012121,0.09466058764
139.344,1.63067,-0.01134,,,,,0.09882848485,-0.0114893617
139.844,1.58846,-0.12281,,,,,0.09627030303,-0.1244275583
140.344,1.54716,-0.19386,,,,,0.09376727273,-0.1964133739
140.844,1.50546,-0.25075,,,,,0.09124,-0.2540526849
141.344,1.4637,-0.29993,,,,,0.08870909091,-0.3038804458
141.844,1.42221,-0.33963,,,,,0.08619454545,-0.3441033435
142.344,1.38026,-0.37514,,,,,0.08365212121,-0.3800810537
142.844,1.33879,-0.40679,,,,,0.08113878788,-0.412147923
143.344,1.29732,-0.43531,,,,,0.07862545455,-0.4410435664
143.844,1.25515,-0.46174,,,,,0.07606969697,-0.4678216819
144.344,1.21379,-0.48687,,,,,0.0735630303,-0.4932826748
144.844,1.1723,-0.5087,,,,,0.07104848485,-0.5154002026
145.344,1.13018,-0.53024,,,,,0.06849575758,-0.5372239108
145.844,1.08885,-0.54904,,,,,0.06599090909,-0.5562715299
146.344,1.04703,-0.56621,,,,,0.06345636364,-0.5736676798
146.844,1.00549,-0.5835,,,,,0.06093878788,-0.5911854103
147.344,0.96389,-0.599,,,,,0.05841757576,-0.6068895643
147.844,0.92185,-0.61498,,,,,0.05586969697,-0.6230800405
148.344,0.88049,-0.62961,,,,,0.0533630303,-0.6379027356
148.844,0.83889,-0.64217,,,,,0.05084181818,-0.6506281662
149.344,0.79685,-0.65659,,,,,0.04829393939,-0.6652380952
149.844,0.75554,-0.66782,,,,,0.04579030303,-0.6766160081
150.344,0.71375,-0.68045,,,,,0.04325757576,-0.6894123607
150.844,0.67198,-0.69351,,,,,0.04072606061,-0.7026443769
151.344,0.63066,-0.70165,,,,,0.03822181818,-0.7108915907
151.844,0.58851,-0.71302,,,,,0.03566727273,-0.7224113475
152.344,0.54705,-0.72367,,,,,0.03315454545,-0.7332016211
152.844,0.50559,-0.73299,,,,,0.03064181818,-0.7426443769
153.344,0.46351,-0.74453,,,,,0.02809151515,-0.7543363728
153.844,0.42203,-0.7543,,,,,0.02557757576,-0.7642350557
154.344,0.38051,-0.76221,,,,,0.02306121212,-0.7722492401
154.844,0.33862,-0.77049,,,,,0.02052242424,-0.7806382979
155.344,0.29719,-0.77804,,,,,0.01801151515,-0.7882877406
155.844,0.25531,-0.78603,,,,,0.01547333333,-0.7963829787
156.344,0.21381,-0.79516,,,,,0.01295818182,-0.805633232
156.844,0.17226,-0.80184,,,,,0.01044,-0.8124012158
157.344,0.13018,-0.80828,,,,,0.00788969697,-0.8189260385
157.844,0.08887,-0.81376,,,,,0.005386060606,-0.8244782168
158.344,0.04715,-0.81799,,,,,0.002857575758,-0.8287639311
158.844,0.00528,-0.82166,,,,,0.00032,-0.8324822695
159.114,0.01131,-0.79995,,,,,0.0006854545455,-0.8104863222
159.614,0.05307,-0.74251,,,,,0.003216363636,-0.752289767
160.114,0.09514,-0.69758,,,,,0.005766060606,-0.7067679838
160.614,0.13666,-0.66338,,,,,0.008282424242,-0.6721175279
161.114,0.17825,-0.63477,,,,,0.0108030303,-0.6431306991
161.614,0.22009,-0.60733,,,,,0.01333878788,-0.6153292806
162.114,0.26141,-0.58506,,,,,0.0158430303,-0.5927659574
162.614,0.3035,-0.56382,,,,,0.01839393939,-0.5712462006
163.114,0.34499,-0.54022,,,,,0.02090848485,-0.5473353597
163.614,0.38632,-0.52067,,,,,0.02341333333,-0.5275278622
164.114,0.42857,-0.49817,,,,,0.02597393939,-0.5047315096
164.614,0.46995,-0.47871,,,,,0.02848181818,-0.4850151976
165.114,0.51154,-0.46152,,,,,0.03100242424,-0.4675987842
165.614,0.55353,-0.44067,,,,,0.03354727273,-0.4464741641
166.114,0.59476,-0.42371,,,,,0.03604606061,-0.4292907801
166.614,0.63666,-0.40567,,,,,0.03858545455,-0.4110131712
167.114,0.67849,-0.38553,,,,,0.04112060606,-0.3906079027
167.614,0.71966,-0.36908,,,,,0.04361575758,-0.3739412361
168.114,0.76175,-0.35188,,,,,0.04616666667,-0.356514691
168.614,0.80341,-0.33351,,,,,0.04869151515,-0.3379027356
169.114,0.84486,-0.31493,,,,,0.05120363636,-0.3190780142
169.614,0.88679,-0.2951,,,,,0.05374484848,-0.2989868288
170.114,0.9282,-0.27634,,,,,0.05625454545,-0.2799797366
170.614,0.97007,-0.25961,,,,,0.05879212121,-0.263029382
171.114,1.01173,-0.24043,,,,,0.0613169697,-0.2435967579
171.614,1.05297,-0.22292,,,,,0.06381636364,-0.2258561297
172.114,1.09518,-0.20266,,,,,0.06637454545,-0.2053292806
172.614,1.13669,-0.1827,,,,,0.06889030303,-0.185106383
173.114,1.17806,-0.1644,,,,,0.07139757576,-0.1665653495
173.614,1.22016,-0.14325,,,,,0.07394909091,-0.1451367781
174.114,1.26161,-0.12504,,,,,0.07646121212,-0.1266869301
174.614,1.30323,-0.10745,,,,,0.07898363636,-0.1088652482
175.114,1.34511,-0.08501,,,,,0.08152181818,-0.08612968592
175.614,1.38641,-0.06579,,,,,0.08402484848,-0.06665653495
176.114,1.42849,-0.04563,,,,,0.08657515152,-0.04623100304
176.614,1.47008,-0.0246,,,,,0.08909575758,-0.02492401216
177.114,1.51142,-0.00503,,,,,0.09160121212,-0.005096251266
177.614,1.55347,0.01704,,,,,0.09414969697,0.01726443769
178.114,1.59496,0.03758,,,,,0.09666424242,0.03807497467
178.614,1.63656,0.0574,,,,,0.09918545455,0.05815602837
178.881,1.64804,0.02982,,,,,0.09988121212,0.03021276596
179.381,1.60584,-0.11001,,,,,0.09732363636,-0.1114589666
179.881,1.56386,-0.19177,,,,,0.09477939394,-0.194295846
180.381,1.52242,-0.25184,,,,,0.09226787879,-0.2551570415
180.881,1.48091,-0.3003,,,,,0.08975212121,-0.3042553191
181.381,1.43868,-0.34304,,,,,0.08719272727,-0.3475582573
181.881,1.39741,-0.37757,,,,,0.08469151515,-0.3825430598
182.381,1.35586,-0.40975,,,,,0.08217333333,-0.4151469098
182.881,1.31382,-0.43978,,,,,0.07962545455,-0.4455724417
183.381,1.27236,-0.46649,,,,,0.07711272727,-0.4726342452
183.881,1.23075,-0.48987,,,,,0.07459090909,-0.4963221884
184.381,1.18894,-0.51345,,,,,0.0720569697,-0.520212766
184.881,1.14749,-0.5337,,,,,0.06954484848,-0.5407294833
185.381,1.10544,-0.55416,,,,,0.06699636364,-0.5614589666
185.881,1.06409,-0.57335,,,,,0.06449030303,-0.5809017224
186.381,1.02253,-0.58868,,,,,0.06197151515,-0.5964336373
186.881,0.9805,-0.60621,,,,,0.05942424242,-0.6141945289
187.381,0.93909,-0.62037,,,,,0.05691454545,-0.6285410334
187.881,0.89733,-0.63473,,,,,0.05438363636,-0.6430901722
188.381,0.85565,-0.64921,,,,,0.05185757576,-0.6577608916
188.881,0.81418,-0.66137,,,,,0.04934424242,-0.6700810537
189.381,0.77214,-0.67321,,,,,0.04679636364,-0.682077001
189.881,0.73069,-0.68485,,,,,0.04428424242,-0.6938703141
190.381,0.68931,-0.69549,,,,,0.04177636364,-0.7046504559
190.881,0.64703,-0.70789,,,,,0.03921393939,-0.7172137791
191.381,0.60575,-0.71796,,,,,0.03671212121,-0.7274164134
191.881,0.56407,-0.72856,,,,,0.03418606061,-0.7381560284
192.381,0.5223,-0.73997,,,,,0.03165454545,-0.7497163121
192.881,0.48073,-0.74869,,,,,0.02913515152,-0.7585511651
193.381,0.43894,-0.75741,,,,,0.02660242424,-0.7673860182
193.881,0.39739,-0.76804,,,,,0.02408424242,-0.7781560284
194.381,0.35586,-0.77551,,,,,0.02156727273,-0.7857244174
194.881,0.31372,-0.78508,,,,,0.01901333333,-0.7954204661
195.381,0.27246,-0.79256,,,,,0.01651272727,-0.8029989868
195.881,0.23081,-0.79908,,,,,0.01398848485,-0.8096048632
196.381,0.18873,-0.80793,,,,,0.01143818182,-0.8185714286
196.881,0.14751,-0.81279,,,,,0.00894,-0.8234954407
197.381,0.10558,-0.81639,,,,,0.006398787879,-0.8271428571
197.881,0.06393,-0.81963,,,,,0.003874545455,-0.8304255319
198.381,0.02246,-0.82058,,,,,0.001361212121,-0.8313880446
198.654,-0.00024,-0.82188,,,,,-0.00001454545455,-0.8327051672
199.154,0.03681,-0.78203,,,,,0.002230909091,-0.7923302938
199.654,0.07814,-0.73207,,,,,0.004735757576,-0.7417122594
200.154,0.12012,-0.69114,,,,,0.00728,-0.7002431611
200.654,0.16177,-0.65959,,,,,0.009804242424,-0.6682776089
201.154,0.20302,-0.63395,,,,,0.01230424242,-0.6422998987
201.654,0.24519,-0.60845,,,,,0.01486,-0.6164640324
202.154,0.28671,-0.58602,,,,,0.01737636364,-0.5937386018
202.654,0.32808,-0.56542,,,,,0.01988363636,-0.5728672746
203.154,0.37019,-0.54393,,,,,0.02243575758,-0.5510942249
203.654,0.41148,-0.52468,,,,,0.02493818182,-0.5315906788
204.154,0.4534,-0.50577,,,,,0.02747878788,-0.5124316109
204.654,0.49511,-0.48662,,,,,0.03000666667,-0.493029382
205.154,0.53642,-0.46786,,,,,0.03251030303,-0.4740222898
205.654,0.57851,-0.44867,,,,,0.03506121212,-0.4545795339
206.154,0.62018,-0.43004,,,,,0.03758666667,-0.435704154
206.654,0.66142,-0.41548,,,,,0.04008606061,-0.420952381
207.154,0.70349,-0.39518,,,,,0.04263575758,-0.4003850051
207.654,0.745,-0.37746,,,,,0.04515151515,-0.3824316109
208.154,0.78665,-0.36058,,,,,0.04767575758,-0.3653292806
208.654,0.82837,-0.34227,,,,,0.05020424242,-0.3467781155
209.154,0.86969,-0.32584,,,,,0.05270848485,-0.3301317123
209.654,0.91186,-0.30749,,,,,0.05526424242,-0.3115400203
210.154,0.95344,-0.28925,,,,,0.05778424242,-0.2930597771
210.654,0.99474,-0.27176,,,,,0.06028727273,-0.2753394124
211.154,1.03688,-0.25166,,,,,0.06284121212,-0.2549746707
211.654,1.07832,-0.23413,,,,,0.06535272727,-0.2372137791
212.154,1.11986,-0.21704,,,,,0.06787030303,-0.2198986829
212.654,1.16188,-0.19477,,,,,0.0704169697,-0.1973353597
213.154,1.20316,-0.17665,,,,,0.07291878788,-0.1789766971
213.654,1.24505,-0.15638,,,,,0.07545757576,-0.1584397163
214.154,1.28683,-0.13587,,,,,0.07798969697,-0.1376595745
214.654,1.32807,-0.11938,,,,,0.08048909091,-0.120952381
215.154,1.37013,-0.09689,,,,,0.08303818182,-0.09816616008
215.654,1.41168,-0.0766,,,,,0.08555636364,-0.07760891591
216.154,1.45322,-0.05823,,,,,0.08807393939,-0.05899696049
216.654,1.49511,-0.03582,,,,,0.09061272727,-0.03629179331
217.154,1.53655,-0.01555,,,,,0.09312424242,-0.01575481256
217.654,1.57839,0.00388,,,,,0.09566,0.003931104357
218.154,1.62014,0.02456,,,,,0.09819030303,0.02488348531
218.519,1.65012,0.0382,,,,,0.1000072727,0.03870314083
218.92,1.62195,-0.09123,,,,,0.0983,-0.09243161094
219.42,1.58057,-0.18014,,,,,0.09579212121,-0.1825126646
219.92,1.53904,-0.24482,,,,,0.09327515152,-0.2480445795
220.42,1.49693,-0.29815,,,,,0.0907230303,-0.302077001
220.92,1.45554,-0.3395,,,,,0.08821454545,-0.3439716312
221.42,1.41395,-0.37874,,,,,0.08569393939,-0.3837284701
221.92,1.37205,-0.41342,,,,,0.08315454545,-0.4188652482
222.42,1.33065,-0.44157,,,,,0.08064545455,-0.4473860182
222.92,1.28873,-0.46812,,,,,0.07810484848,-0.4742857143
223.42,1.24726,-0.49208,,,,,0.07559151515,-0.4985612969
223.92,1.20567,-0.51421,,,,,0.07307090909,-0.5209827761
224.42,1.1636,-0.53727,,,,,0.07052121212,-0.5443465046
224.92,1.12226,-0.55635,,,,,0.06801575758,-0.5636778116
225.42,1.08058,-0.57329,,,,,0.06548969697,-0.5808409321
225.92,1.03869,-0.59317,,,,,0.06295090909,-0.6009827761
226.42,0.99731,-0.60771,,,,,0.0604430303,-0.6157142857
226.92,0.95535,-0.62291,,,,,0.0579,-0.6311144883
227.42,0.91381,-0.63898,,,,,0.05538242424,-0.6473961499
227.92,0.87246,-0.65158,,,,,0.05287636364,-0.6601621074
228.42,0.83021,-0.66437,,,,,0.05031575758,-0.6731205674
228.92,0.78884,-0.67788,,,,,0.04780848485,-0.6868085106
229.42,0.74734,-0.68923,,,,,0.04529333333,-0.6983080041
229.92,0.70531,-0.70014,,,,,0.04274606061,-0.7093617021
230.42,0.66386,-0.71205,,,,,0.04023393939,-0.7214285714
230.92,0.62218,-0.72073,,,,,0.03770787879,-0.7302228977
231.42,0.58048,-0.73222,,,,,0.03518060606,-0.7418642351
231.92,0.53901,-0.74074,,,,,0.03266727273,-0.7504964539
232.42,0.49702,-0.75088,,,,,0.03012242424,-0.7607700101
232.92,0.45559,-0.76134,,,,,0.02761151515,-0.7713677812
233.42,0.41397,-0.76843,,,,,0.02508909091,-0.7785511651
233.92,0.37195,-0.77927,,,,,0.02254242424,-0.7895339412
234.42,0.33058,-0.78712,,,,,0.02003515152,-0.7974873354
234.92,0.2888,-0.79496,,,,,0.0175030303,-0.8054305978
235.42,0.2471,-0.80407,,,,,0.01497575758,-0.8146605876
235.92,0.20574,-0.80851,,,,,0.01246909091,-0.8191590679
236.42,0.16363,-0.81684,,,,,0.009916969697,-0.8275987842
236.92,0.12222,-0.81805,,,,,0.007407272727,-0.8288247214
237.42,0.08072,-0.81966,,,,,0.004892121212,-0.8304559271
237.92,0.03866,-0.8216,,,,,0.002343030303,-0.8324214792
238.389,-0.00008,-0.82191,,,,,-0.000004848484848,-0.8327355623
238.691,0.01961,-0.80534,,,,,0.001188484848,-0.8159473151
239.191,0.06184,-0.76527,,,,,0.003747878788,-0.7753495441
239.691,0.10331,-0.72062,,,,,0.006261212121,-0.7301114488
240.191,0.14472,-0.68683,,,,,0.008770909091,-0.6958763931
240.691,0.18685,-0.65581,,,,,0.01132424242,-0.6644478217
241.191,0.22818,-0.62909,,,,,0.01382909091,-0.6373758865
241.691,0.26998,-0.60706,,,,,0.01636242424,-0.6150557244
242.191,0.3118,-0.58509,,,,,0.0188969697,-0.5927963526
242.691,0.35304,-0.5655,,,,,0.02139636364,-0.5729483283
243.191,0.39515,-0.54573,,,,,0.02394848485,-0.5529179331
243.691,0.43684,-0.52567,,,,,0.02647515152,-0.5325937183
244.191,0.47805,-0.50837,,,,,0.02897272727,-0.5150658561
244.691,0.52011,-0.49021,,,,,0.03152181818,-0.4966666667
245.191,0.56171,-0.47121,,,,,0.0340430303,-0.4774164134
245.691,0.60328,-0.45543,,,,,0.03656242424,-0.4614285714
246.191,0.64511,-0.43668,,,,,0.03909757576,-0.4424316109
246.691,0.68642,-0.41871,,,,,0.04160121212,-0.424224924
247.191,0.72851,-0.40238,,,,,0.04415212121,-0.4076798379
247.691,0.77006,-0.38311,,,,,0.04667030303,-0.3881560284
248.191,0.81132,-0.36584,,,,,0.04917090909,-0.3706585613
248.691,0.85354,-0.34773,,,,,0.05172969697,-0.3523100304
249.191,0.89505,-0.32946,,,,,0.05424545455,-0.3337993921
249.691,0.93646,-0.31139,,,,,0.05675515152,-0.315491388
250.191,0.97852,-0.29313,,,,,0.05930424242,-0.2969908815
250.691,1.0199,-0.2755,,,,,0.06181212121,-0.2791286727
251.191,1.06174,-0.25855,,,,,0.06434787879,-0.2619554205
251.691,1.10349,-0.24042,,,,,0.06687818182,-0.2435866261
252.191,1.14477,-0.22041,,,,,0.06938,-0.2233130699
252.691,1.18684,-0.20215,,,,,0.07192969697,-0.2048125633
253.191,1.22845,-0.18325,,,,,0.07445151515,-0.1856636272
253.691,1.26982,-0.16596,,,,,0.07695878788,-0.1681458967
254.191,1.31183,-0.14299,,,,,0.07950484848,-0.1448733536
254.691,1.35317,-0.12488,,,,,0.08201030303,-0.1265248227
255.191,1.39504,-0.10505,,,,,0.08454787879,-0.1064336373
255.691,1.43672,-0.08361,,,,,0.08707393939,-0.0847112462
256.191,1.47813,-0.06449,,,,,0.08958363636,-0.06533941236
256.691,1.52026,-0.04291,,,,,0.0921369697,-0.0434751773
257.191,1.56182,-0.02158,,,,,0.09465575758,-0.02186423506
257.691,1.603,-0.00368,,,,,0.09715151515,-0.003728470111
258.191,1.64524,0.01734,,,,,0.09971151515,0.01756838906
258.457,1.63933,-0.05161,,,,,0.09935333333,-0.05228976697
258.957,1.59724,-0.1638,,,,,0.09680242424,-0.1659574468
259.457,1.5553,-0.2363,,,,,0.09426060606,-0.2394123607
259.957,1.5139,-0.28973,,,,,0.09175151515,-0.2935460993
260.457,1.47211,-0.33534,,,,,0.08921878788,-0.3397568389
260.957,1.43044,-0.37587,,,,,0.08669333333,-0.3808206687
261.457,1.38898,-0.4094,,,,,0.08418060606,-0.4147922999
261.957,1.34687,-0.44154,,,,,0.08162848485,-0.4473556231
262.457,1.30555,-0.46616,,,,,0.07912424242,-0.4722998987
262.957,1.26391,-0.49204,,,,,0.07660060606,-0.49852077
263.457,1.22198,-0.51738,,,,,0.07405939394,-0.5241945289
263.957,1.18055,-0.53582,,,,,0.07154848485,-0.5428774063
264.457,1.13872,-0.55524,,,,,0.06901333333,-0.5625531915
264.957,1.09711,-0.57461,,,,,0.06649151515,-0.5821783181
265.457,1.05564,-0.59002,,,,,0.06397818182,-0.5977912867
265.957,1.01355,-0.60813,,,,,0.06142727273,-0.6161398176
266.457,0.97219,-0.62296,,,,,0.05892060606,-0.6311651469
266.957,0.93078,-0.63582,,,,,0.05641090909,-0.6441945289
267.457,0.88852,-0.65161,,,,,0.05384969697,-0.6601925025
267.957,0.84722,-0.66423,,,,,0.05134666667,-0.6729787234
268.457,0.80549,-0.67646,,,,,0.04881757576,-0.6853698075
268.957,0.76382,-0.68988,,,,,0.04629212121,-0.6989665653
269.457,0.72223,-0.70023,,,,,0.04377151515,-0.7094528875
269.957,0.6803,-0.71197,,,,,0.04123030303,-0.7213475177
270.457,0.63886,-0.72382,,,,,0.03871878788,-0.7333535968
270.957,0.59729,-0.73278,,,,,0.03619939394,-0.7424316109
271.457,0.55517,-0.74506,,,,,0.03364666667,-0.7548733536
271.957,0.51392,-0.75302,,,,,0.03114666667,-0.7629381966
272.457,0.47222,-0.76146,,,,,0.02861939394,-0.7714893617
272.957,0.43024,-0.7735,,,,,0.02607515152,-0.7836879433
273.457,0.38901,-0.77917,,,,,0.02357636364,-0.7894326241
273.957,0.34698,-0.78783,,,,,0.02102909091,-0.7982066869
274.457,0.30545,-0.79454,,,,,0.01851212121,-0.8050050659
274.957,0.26401,-0.80245,,,,,0.01600060606,-0.8130192503
275.457,0.22193,-0.80939,,,,,0.01345030303,-0.8200506586
275.957,0.18041,-0.81438,,,,,0.01093393939,-0.825106383
276.457,0.13897,-0.81722,,,,,0.008422424242,-0.8279837893
276.957,0.09696,-0.82098,,,,,0.005876363636,-0.8317933131
277.457,0.05551,-0.82193,,,,,0.003364242424,-0.8327558257
277.957,0.01377,-0.82244,,,,,0.0008345454545,-0.8332725431
278.227,0.0024,-0.8207,,,,,0.0001454545455,-0.8315096251
278.727,0.04496,-0.79307,,,,,0.002724848485,-0.8035157042
279.227,0.08652,-0.75071,,,,,0.005243636364,-0.760597771
279.727,0.12858,-0.70976,,,,,0.007792727273,-0.7191084093
280.227,0.16976,-0.67801,,,,,0.01028848485,-0.6869402229
280.727,0.21183,-0.65138,,,,,0.01283818182,-0.6599594732
281.227,0.25348,-0.62655,,,,,0.01536242424,-0.6348024316
281.727,0.29479,-0.60448,,,,,0.01786606061,-0.6124417427
282.227,0.33683,-0.58166,,,,,0.02041393939,-0.5893211753
282.727,0.37847,-0.56299,,,,,0.02293757576,-0.5704052685
283.227,0.41988,-0.54571,,,,,0.02544727273,-0.5528976697
283.727,0.4618,-0.52417,,,,,0.02798787879,-0.5310739615
284.227,0.50325,-0.50763,,,,,0.0305,-0.5143161094
284.727,0.54508,-0.49008,,,,,0.03303515152,-0.4965349544
285.227,0.58673,-0.47293,,,,,0.03555939394,-0.4791590679
285.727,0.628,-0.45653,,,,,0.03806060606,-0.4625430598
286.227,0.67029,-0.43915,,,,,0.04062363636,-0.4449341439
286.727,0.71173,-0.41977,,,,,0.04313515152,-0.4252988855
287.227,0.75319,-0.40487,,,,,0.04564787879,-0.4102026342
287.727,0.79522,-0.38421,,,,,0.04819515152,-0.3892705167
288.227,0.8366,-0.36739,,,,,0.0507030303,-0.3722289767
288.727,0.8783,-0.35084,,,,,0.05323030303,-0.3554609929
289.227,0.92025,-0.33115,,,,,0.05577272727,-0.3355116515
289.727,0.96137,-0.3175,,,,,0.05826484848,-0.3216818642
290.227,1.00347,-0.29746,,,,,0.06081636364,-0.3013779129
290.727,1.04517,-0.27859,,,,,0.06334363636,-0.2822593718
291.227,1.08646,-0.26138,,,,,0.06584606061,-0.264822695
291.727,1.12845,-0.24259,,,,,0.06839090909,-0.2457852077
292.227,1.16996,-0.22414,,,,,0.07090666667,-0.2270921986
292.727,1.21162,-0.20727,,,,,0.07343151515,-0.21
293.227,1.2534,-0.18659,,,,,0.07596363636,-0.189047619
293.727,1.29481,-0.16785,,,,,0.07847333333,-0.1700607903
294.227,1.33684,-0.14971,,,,,0.08102060606,-0.1516818642
294.727,1.37848,-0.12955,,,,,0.08354424242,-0.1312563323
295.227,1.41972,-0.11107,,,,,0.08604363636,-0.1125329281
295.727,1.46185,-0.09105,,,,,0.0885969697,-0.09224924012
296.227,1.50338,-0.07039,,,,,0.09111393939,-0.07131712259
296.727,1.54491,-0.04995,,,,,0.09363090909,-0.05060790274
297.227,1.58688,-0.02691,,,,,0.09617454545,-0.02726443769
297.727,1.62826,-0.00579,,,,,0.09868242424,-0.005866261398
297.993,1.65024,0.00196,,,,,0.1000145455,0.001985815603
298.493,1.61376,-0.14172,,,,,0.09780363636,-0.1435866261
298.993,1.5723,-0.22275,,,,,0.09529090909,-0.2256838906
299.493,1.53026,-0.28181,,,,,0.0927430303,-0.2855217832
299.993,1.48891,-0.32771,,,,,0.0902369697,-0.3320263425
300.493,1.44728,-0.36972,,,,,0.08771393939,-0.3745896657
300.993,1.40525,-0.40531,,,,,0.08516666667,-0.4106484296
301.493,1.36393,-0.4347,,,,,0.08266242424,-0.4404255319
301.993,1.32207,-0.46389,,,,,0.08012545455,-0.47
302.493,1.2804,-0.49018,,,,,0.0776,-0.4966362715
302.993,1.239,-0.51258,,,,,0.07509090909,-0.519331307
303.493,1.19691,-0.53271,,,,,0.07254,-0.5397264438
303.993,1.15551,-0.55474,,,,,0.07003090909,-0.5620466059
304.493,1.11406,-0.57299,,,,,0.06751878788,-0.5805369807
304.993,1.07186,-0.59269,,,,,0.06496121212,-0.6004964539
305.493,1.03052,-0.60743,,,,,0.06245575758,-0.6154305978
305.993,0.98893,-0.62147,,,,,0.05993515152,-0.6296555218
306.493,0.94699,-0.63839,,,,,0.05739333333,-0.6467983789
306.993,0.90556,-0.6502,,,,,0.05488242424,-0.6587639311
307.493,0.86369,-0.66415,,,,,0.05234484848,-0.6728976697
307.993,0.82219,-0.67732,,,,,0.04982969697,-0.6862411348
308.493,0.78069,-0.688,,,,,0.04731454545,-0.6970618034
308.993,0.7386,-0.69997,,,,,0.04476363636,-0.709189463
309.493,0.69724,-0.71289,,,,,0.0422569697,-0.7222796353
309.993,0.65556,-0.72235,,,,,0.03973090909,-0.7318642351
310.493,0.61369,-0.73421,,,,,0.03719333333,-0.7438804458
310.993,0.57226,-0.74501,,,,,0.03468242424,-0.754822695
311.493,0.53038,-0.75397,,,,,0.03214424242,-0.7639007092
311.993,0.4888,-0.76351,,,,,0.02962424242,-0.7735663627
312.493,0.44745,-0.77354,,,,,0.02711818182,-0.7837284701
312.993,0.40521,-0.78176,,,,,0.02455818182,-0.7920567376
313.493,0.36391,-0.78972,,,,,0.02205515152,-0.8001215805
313.993,0.32233,-0.79511,,,,,0.01953515152,-0.8055825735
314.493,0.28034,-0.80435,,,,,0.01699030303,-0.8149442756
314.993,0.23885,-0.81023,,,,,0.01447575758,-0.8209017224
315.493,0.19716,-0.81293,,,,,0.01194909091,-0.8236372847
315.993,0.15545,-0.81646,,,,,0.009421212121,-0.8272137791
316.493,0.11389,-0.81895,,,,,0.006902424242,-0.8297365755
316.993,0.07193,-0.81918,,,,,0.004359393939,-0.8299696049
317.493,0.03059,-0.82121,,,,,0.001853939394,-0.8320263425
317.862,-0.00011,-0.82085,,,,,-0.000006666666667,-0.8316616008
318.263,0.02844,-0.80691,,,,,0.001723636364,-0.8175379939
318.763,0.07019,-0.77632,,,,,0.004253939394,-0.7865450861
319.263,0.11138,-0.73291,,,,,0.00675030303,-0.7425633232
319.763,0.15357,-0.69878,,,,,0.009307272727,-0.7079837893
320.263,0.19515,-0.66952,,,,,0.01182727273,-0.6783383992
320.763,0.23646,-0.64552,,,,,0.01433090909,-0.6540222898
321.263,0.27847,-0.62112,,,,,0.0168769697,-0.6293009119
321.763,0.31995,-0.60132,,,,,0.01939090909,-0.6092401216
322.263,0.36174,-0.58261,,,,,0.02192363636,-0.5902836879
322.763,0.40347,-0.56249,,,,,0.02445272727,-0.5698986829
323.263,0.44478,-0.54379,,,,,0.02695636364,-0.550952381
323.763,0.48688,-0.52443,,,,,0.02950787879,-0.531337386
324.263,0.52844,-0.5071,,,,,0.03202666667,-0.5137791287
324.763,0.56972,-0.48872,,,,,0.03452848485,-0.4951570415
325.263,0.61195,-0.46927,,,,,0.03708787879,-0.4754508612
325.763,0.65333,-0.45295,,,,,0.03959575758,-0.4589159068
326.263,0.69501,-0.43726,,,,,0.04212181818,-0.4430192503
326.763,0.73685,-0.41743,,,,,0.04465757576,-0.4229280648
327.263,0.77814,-0.40288,,,,,0.04716,-0.4081864235
327.763,0.82024,-0.38577,,,,,0.04971151515,-0.3908510638
328.263,0.86185,-0.36739,,,,,0.05223333333,-0.3722289767
328.763,0.90311,-0.35311,,,,,0.05473393939,-0.3577608916
329.263,0.94517,-0.33382,,,,,0.0572830303,-0.3382168186
329.763,0.98677,-0.31518,,,,,0.05980424242,-0.319331307
330.263,1.02821,-0.29839,,,,,0.06231575758,-0.3023201621
330.763,1.07026,-0.27916,,,,,0.06486424242,-0.2828368794
331.263,1.11148,-0.26112,,,,,0.06736242424,-0.2645592705
331.763,1.15353,-0.24245,,,,,0.06991090909,-0.2456433637
332.263,1.19512,-0.22481,,,,,0.07243151515,-0.2277710233
332.763,1.23644,-0.205,,,,,0.07493575758,-0.2077001013
333.263,1.27849,-0.1847,,,,,0.07748424242,-0.1871327254
333.763,1.3202,-0.16691,,,,,0.08001212121,-0.1691084093
334.263,1.36143,-0.14766,,,,,0.08251090909,-0.1496048632
334.763,1.40365,-0.12631,,,,,0.08506969697,-0.1279736575
335.263,1.44495,-0.10761,,,,,0.08757272727,-0.1090273556
335.763,1.48663,-0.08703,,,,,0.09009878788,-0.08817629179
336.263,1.52852,-0.06817,,,,,0.09263757576,-0.06906788247
336.763,1.56975,-0.04725,,,,,0.09513636364,-0.04787234043
337.263,1.61181,-0.02602,,,,,0.09768545455,-0.0263627153
337.727,1.65008,-0.00586,,,,,0.1000048485,-0.005937183384
338.029,1.63081,-0.10582,,,,,0.0988369697,-0.1072137791
338.529,1.58863,-0.20461,,,,,0.09628060606,-0.2073049645
339.029,1.54733,-0.26595,,,,,0.09377757576,-0.2694528875
339.529,1.50559,-0.31818,,,,,0.09124787879,-0.3223708207
340.029,1.46386,-0.36242,,,,,0.08871878788,-0.3671935157
340.529,1.42242,-0.39729,,,,,0.08620727273,-0.4025227964
341.029,1.3804,-0.43045,,,,,0.08366060606,-0.4361195542
341.529,1.33894,-0.45921,,,,,0.08114787879,-0.4652583587
342.029,1.29748,-0.48487,,,,,0.07863515152,-0.4912563323
342.529,1.25529,-0.50997,,,,,0.07607818182,-0.5166869301
343.029,1.21395,-0.53182,,,,,0.07357272727,-0.5388247214
343.529,1.17243,-0.55166,,,,,0.07105636364,-0.5589260385
344.029,1.13037,-0.57148,,,,,0.06850727273,-0.5790070922
344.529,1.08902,-0.59145,,,,,0.06600121212,-0.5992401216
345.029,1.04716,-0.6052,,,,,0.06346424242,-0.6131712259
345.529,1.00566,-0.6231,,,,,0.06094909091,-0.6313069909
346.029,0.96405,-0.63673,,,,,0.05842727273,-0.6451165147
346.529,0.92199,-0.65162,,,,,0.05587818182,-0.6602026342
347.029,0.88064,-0.66656,,,,,0.05337212121,-0.6753394124
347.529,0.839,-0.67825,,,,,0.05084848485,-0.687183384
348.029,0.79702,-0.6921,,,,,0.04830424242,-0.7012158055
348.529,0.75569,-0.70317,,,,,0.04579939394,-0.7124316109
349.029,0.71386,-0.7132,,,,,0.04326424242,-0.7225937183
349.529,0.67217,-0.72413,,,,,0.04073757576,-0.7336676798
350.029,0.63083,-0.73501,,,,,0.03823212121,-0.7446909828
350.529,0.58867,-0.74367,,,,,0.0356769697,-0.7534650456
351.029,0.54722,-0.75318,,,,,0.03316484848,-0.763100304
351.529,0.50576,-0.76311,,,,,0.03065212121,-0.7731610942
352.029,0.46365,-0.77374,,,,,0.0281,-0.7839311044
352.529,0.42219,-0.78405,,,,,0.02558727273,-0.7943768997
353.029,0.38066,-0.78653,,,,,0.02307030303,-0.7968895643
353.529,0.33882,-0.79781,,,,,0.02053454545,-0.8083181358
354.029,0.29735,-0.80448,,,,,0.01802121212,-0.8150759878
354.529,0.25544,-0.81027,,,,,0.01548121212,-0.8209422492
355.029,0.21399,-0.81461,,,,,0.01296909091,-0.8253394124
355.529,0.17241,-0.81988,,,,,0.01044909091,-0.8306788247
356.029,0.13034,-0.82054,,,,,0.007899393939,-0.8313475177
356.529,0.08903,-0.82196,,,,,0.005395757576,-0.8327862209
357.029,0.04728,-0.82203,,,,,0.002865454545,-0.8328571429
357.529,0.00547,-0.82152,,,,,0.0003315151515,-0.8323404255
357.8,0.01136,-0.81793,,,,,0.0006884848485,-0.8287031408
358.3,0.05313,-0.79952,,,,,0.00322,-0.8100506586
358.8,0.09518,-0.76154,,,,,0.005768484848,-0.7715704154
359.3,0.13673,-0.7219,,,,,0.008286666667,-0.731408308
359.8,0.17832,-0.69004,,,,,0.01080727273,-0.6991286727
360.3,0.22014,-0.6631,,,,,0.01334181818,-0.6718338399
360.8,0.26147,-0.63914,,,,,0.01584666667,-0.6475582573
361.3,0.30353,-0.61734,,,,,0.01839575758,-0.6254711246
361.8,0.34506,-0.59639,,,,,0.02091272727,-0.6042451874
362.3,0.38637,-0.57893,,,,,0.02341636364,-0.5865552178
362.8,0.42864,-0.55802,,,,,0.02597818182,-0.5653698075
363.3,0.47,-0.54078,,,,,0.02848484848,-0.5479027356
363.8,0.51161,-0.52353,,,,,0.03100666667,-0.5304255319
364.3,0.55354,-0.50382,,,,,0.03354787879,-0.5104559271
364.8,0.59485,-0.48707,,,,,0.03605151515,-0.493485309
365.3,0.63672,-0.47093,,,,,0.03858909091,-0.4771327254
365.8,0.67854,-0.45008,,,,,0.04112363636,-0.4560081054
366.3,0.7197,-0.43692,,,,,0.04361818182,-0.442674772
366.8,0.76182,-0.41729,,,,,0.04617090909,-0.4227862209
367.3,0.80341,-0.39931,,,,,0.04869151515,-0.4045694022
367.8,0.84487,-0.38503,,,,,0.05120424242,-0.3901013171
368.3,0.88689,-0.36544,,,,,0.05375090909,-0.3702532928
368.8,0.92828,-0.34874,,,,,0.05625939394,-0.3533333333
369.3,0.97011,-0.33446,,,,,0.05879454545,-0.3388652482
369.8,1.01178,-0.31561,,,,,0.06132,-0.3197669706
370.3,1.05304,-0.29922,,,,,0.06382060606,-0.3031610942
370.8,1.09521,-0.27971,,,,,0.06637636364,-0.2833941236
371.3,1.13683,-0.26216,,,,,0.06889878788,-0.2656129686
371.8,1.17812,-0.24465,,,,,0.07140121212,-0.2478723404
372.3,1.22022,-0.22341,,,,,0.07395272727,-0.2263525836
372.8,1.26167,-0.20588,,,,,0.07646484848,-0.208591692
373.3,1.30329,-0.18698,,,,,0.07898727273,-0.1894427558
373.8,1.34515,-0.16718,,,,,0.08152424242,-0.1693819656
374.3,1.38654,-0.14719,,,,,0.08403272727,-0.1491286727
374.8,1.42851,-0.12671,,,,,0.08657636364,-0.128378926
375.3,1.47013,-0.10699,,,,,0.08909878788,-0.1083991895
375.8,1.51145,-0.08629,,,,,0.0916030303,-0.08742654509
376.3,1.55349,-0.06495,,,,,0.09415090909,-0.06580547112
376.8,1.595,-0.04483,,,,,0.09666666667,-0.04542046606
377.3,1.63671,-0.02414,,,,,0.09919454545,-0.02445795339
377.565,1.64797,-0.04791,,,,,0.0998769697,-0.04854103343
378.065,1.60571,-0.17732,,,,,0.09731575758,-0.1796555218
378.565,1.56379,-0.24903,,,,,0.09477515152,-0.2523100304
379.065,1.52229,-0.30587,,,,,0.09226,-0.3098986829
379.565,1.48082,-0.34923,,,,,0.08974666667,-0.3538297872
380.065,1.43861,-0.39127,,,,,0.08718848485,-0.3964235056
380.565,1.39729,-0.42564,,,,,0.08468424242,-0.4312462006
381.065,1.35575,-0.4546,,,,,0.08216666667,-0.4605876393
381.565,1.31369,-0.48333,,,,,0.07961757576,-0.4896960486
382.065,1.27227,-0.50631,,,,,0.07710727273,-0.5129787234
382.565,1.23061,-0.52853,,,,,0.07458242424,-0.535491388
383.065,1.18883,-0.54973,,,,,0.07205030303,-0.556970618
383.565,1.14737,-0.56887,,,,,0.06953757576,-0.5763627153
384.065,1.10538,-0.58748,,,,,0.06699272727,-0.5952178318
384.565,1.06399,-0.60374,,,,,0.06448424242,-0.6116919959
385.065,1.02242,-0.61785,,,,,0.06196484848,-0.6259878419
385.565,0.9804,-0.63515,,,,,0.05941818182,-0.6435157042
386.065,0.93901,-0.65,,,,,0.05690969697,-0.6585612969
386.565,0.89726,-0.66001,,,,,0.05437939394,-0.6687031408
387.065,0.85555,-0.6776,,,,,0.05185151515,-0.6865248227
387.565,0.81407,-0.68882,,,,,0.04933757576,-0.6978926039
388.065,0.77205,-0.69972,,,,,0.04679090909,-0.7089361702
388.565,0.73058,-0.71185,,,,,0.04427757576,-0.7212259372
389.065,0.68923,-0.72271,,,,,0.04177151515,-0.7322289767
389.565,0.64694,-0.73582,,,,,0.03920848485,-0.7455116515
390.065,0.60565,-0.74411,,,,,0.03670606061,-0.7539108409
390.565,0.564,-0.75251,,,,,0.03418181818,-0.7624214792
391.065,0.52221,-0.76485,,,,,0.03164909091,-0.7749240122
391.565,0.48064,-0.77117,,,,,0.02912969697,-0.7813272543
392.065,0.43885,-0.78054,,,,,0.0265969697,-0.7908206687
392.565,0.39729,-0.78747,,,,,0.02407818182,-0.7978419453
393.065,0.35574,-0.7954,,,,,0.02156,-0.8058763931
393.565,0.31361,-0.80419,,,,,0.01900666667,-0.8147821682
394.065,0.27236,-0.80982,,,,,0.01650666667,-0.8204863222
394.565,0.23073,-0.814,,,,,0.01398363636,-0.8247213779
395.065,0.18861,-0.81929,,,,,0.01143090909,-0.8300810537
395.565,0.14742,-0.82127,,,,,0.008934545455,-0.8320871327
396.065,0.10551,-0.82149,,,,,0.006394545455,-0.8323100304
396.565,0.06384,-0.82155,,,,,0.003869090909,-0.8323708207
397.065,0.02235,-0.82274,,,,,0.001354545455,-0.8335764944
397.335,-0.00009,-0.82241,,,,,-0.000005454545455,-0.8332421479