File: mechanical/hysteresis/databak/hmwg_hysteresis - nonconductive_1.csv
Time,Extension,Load,Length,Width,Thickness,CS Area,Strain,Stress
(s),(mm),(N),(mm),(mm),(mm),(mm^2),(mm/mm),(MPa)
0,0,-0.00143,16.5,2.82,0.33,0.9306,0,-0.001536643026
0.5,0.03938,0.0004,,,,,0.002386666667,0.0004298302171
1,0.08056,0.00253,,,,,0.004882424242,0.002718676123
1.5,0.12264,0.00307,,,,,0.007432727273,0.003298946916
2,0.1642,0.00182,,,,,0.009951515152,0.001955727488
2.5,0.20579,0.00384,,,,,0.01247212121,0.004126370084
3,0.24765,0.00672,,,,,0.01500909091,0.007221147647
3.5,0.289,0.00715,,,,,0.01751515152,0.00768321513
4,0.33098,0.00818,,,,,0.02005939394,0.008790027939
4.5,0.37258,0.00999,,,,,0.02258060606,0.01073500967
5,0.41382,0.01187,,,,,0.02508,0.01275521169
5.5,0.45606,0.01043,,,,,0.02764,0.01120782291
6,0.49759,0.01446,,,,,0.0301569697,0.01553836235
6.5,0.53901,0.0139,,,,,0.03266727273,0.01493660004
7,0.58102,0.01437,,,,,0.03521333333,0.01544165055
7.5,0.62244,0.01728,,,,,0.03772363636,0.01856866538
8,0.66421,0.01943,,,,,0.04025515152,0.02087900279
8.5,0.70599,0.01749,,,,,0.04278727273,0.01879432624
9,0.74729,0.01984,,,,,0.04529030303,0.02131957877
9.5,0.78935,0.01699,,,,,0.04783939394,0.01825703847
10,0.83096,0.02156,,,,,0.05036121212,0.0231678487
10.5,0.87229,0.02336,,,,,0.05286606061,0.02510208468
11,0.91436,0.02451,,,,,0.05541575758,0.02633784655
11.5,0.95575,0.02558,,,,,0.05792424242,0.02748764238
12,0.99754,0.02564,,,,,0.0604569697,0.02755211691
12.5,1.03925,0.02976,,,,,0.06298484848,0.03197936815
13,1.08063,0.02988,,,,,0.06549272727,0.03210831721
13.5,1.12269,0.02806,,,,,0.06804181818,0.03015258973
14,1.16434,0.02946,,,,,0.07056606061,0.03165699549
14.5,1.20551,0.03006,,,,,0.07306121212,0.03230174081
15,1.2478,0.03201,,,,,0.07562424242,0.03439716312
15.5,1.28926,0.03342,,,,,0.0781369697,0.03591231464
16,1.3307,0.03372,,,,,0.08064848485,0.0362346873
16.5,1.3727,0.03642,,,,,0.08319393939,0.03913604126
17,1.41403,0.03764,,,,,0.08569878788,0.04044702343
17.5,1.45593,0.03736,,,,,0.08823818182,0.04014614227
18,1.49761,0.03881,,,,,0.09076424242,0.04170427681
18.5,1.53896,0.03859,,,,,0.09327030303,0.04146787019
19,1.58093,0.04002,,,,,0.09581393939,0.04300451322
19.5,1.6226,0.04089,,,,,0.09833939394,0.04393939394
19.828,1.6501,0.04167,,,,,0.1000060606,0.04477756286
20.229,1.62137,0.03571,,,,,0.09826484848,0.03837309263
20.729,1.5794,0.03328,,,,,0.09572121212,0.03576187406
21.229,1.53785,0.02903,,,,,0.0932030303,0.031194928
21.729,1.49648,0.02698,,,,,0.09069575758,0.02899204814
22.229,1.45423,0.02476,,,,,0.08813515152,0.02660649044
22.729,1.41294,0.02212,,,,,0.08563272727,0.023769611
23.229,1.37134,0.02004,,,,,0.08311151515,0.02153449387
23.729,1.32939,0.01796,,,,,0.08056909091,0.01929937675
24.229,1.28789,0.01512,,,,,0.07805393939,0.01624758221
24.729,1.2462,0.01232,,,,,0.07552727273,0.01323877069
25.229,1.20451,0.01126,,,,,0.07300060606,0.01209972061
25.729,1.16303,0.00809,,,,,0.07048666667,0.00869331614
26.229,1.12095,0.00887,,,,,0.06793636364,0.009531485063
26.729,1.07964,0.0059,,,,,0.06543272727,0.006339995702
27.229,1.03806,0.00627,,,,,0.06291272727,0.006737588652
27.729,0.99586,0.00225,,,,,0.06035515152,0.002417794971
28.229,0.95465,0.00063,,,,,0.05785757576,0.0006769825919
28.729,0.91286,0.00246,,,,,0.05532484848,0.002643455835
29.229,0.87106,-0.00127,,,,,0.05279151515,-0.001364710939
29.729,0.82963,-0.0014,,,,,0.05028060606,-0.00150440576
30.229,0.78774,-0.00274,,,,,0.04774181818,-0.002944336987
30.729,0.74613,-0.00518,,,,,0.04522,-0.005566301311
31.229,0.70476,-0.00709,,,,,0.04271272727,-0.007618740597
31.729,0.66262,-0.00835,,,,,0.04015878788,-0.008972705781
32.229,0.62122,-0.01113,,,,,0.03764969697,-0.01196002579
32.729,0.57965,-0.01303,,,,,0.03513030303,-0.01400171932
33.229,0.53774,-0.01343,,,,,0.03259030303,-0.01443154954
33.729,0.49629,-0.01354,,,,,0.03007818182,-0.01454975285
34.229,0.45438,-0.01589,,,,,0.02753818182,-0.01707500537
34.729,0.41295,-0.01929,,,,,0.02502727273,-0.02072856222
35.229,0.37128,-0.0182,,,,,0.02250181818,-0.01955727488
35.729,0.32931,-0.0185,,,,,0.01995818182,-0.01987964754
36.229,0.2879,-0.0231,,,,,0.01744848485,-0.02482269504
36.729,0.24632,-0.02274,,,,,0.01492848485,-0.02443584784
37.229,0.20426,-0.02322,,,,,0.01237939394,-0.0249516441
37.729,0.16299,-0.02653,,,,,0.009878181818,-0.02850848915
38.229,0.12117,-0.0268,,,,,0.007343636364,-0.02879862454
38.729,0.07946,-0.02712,,,,,0.004815757576,-0.02914248872
39.229,0.03808,-0.02838,,,,,0.002307878788,-0.0304964539
39.685,-0.00006,-0.02907,,,,,-0.000003636363636,-0.03123791103
39.987,0.01994,-0.02888,,,,,0.001208484848,-0.03103374167
40.487,0.06156,-0.02428,,,,,0.003730909091,-0.02609069418
40.987,0.10301,-0.02003,,,,,0.006243030303,-0.02152374812
41.487,0.14504,-0.02065,,,,,0.00879030303,-0.02218998496
41.987,0.18639,-0.01722,,,,,0.01129636364,-0.01850419084
42.487,0.22822,-0.01662,,,,,0.01383151515,-0.01785944552
42.987,0.27005,-0.0144,,,,,0.01636666667,-0.01547388781
43.487,0.31125,-0.01372,,,,,0.01886363636,-0.01474317645
43.987,0.35332,-0.00992,,,,,0.02141333333,-0.01065978938
44.487,0.39505,-0.00853,,,,,0.02394242424,-0.009166129379
44.987,0.43623,-0.00752,,,,,0.02643818182,-0.008080808081
45.487,0.47843,-0.00335,,,,,0.02899575758,-0.003599828068
45.987,0.51994,-0.00163,,,,,0.03151151515,-0.001751558135
46.487,0.56149,-0.00212,,,,,0.03402969697,-0.00227810015
46.987,0.60332,0.00092,,,,,0.03656484848,0.0009886094992
47.487,0.64467,0.00103,,,,,0.03907090909,0.001106812809
47.987,0.68671,0.00374,,,,,0.04161878788,0.00401891253
48.487,0.72832,0.00489,,,,,0.04414060606,0.005254674404
48.987,0.76956,0.00588,,,,,0.04664,0.006318504191
49.487,0.81175,0.0067,,,,,0.0491969697,0.007199656136
49.987,0.85325,0.00741,,,,,0.05171212121,0.007962604771
50.487,0.89467,0.00919,,,,,0.05422242424,0.009875349237
50.987,0.93679,0.01119,,,,,0.05677515152,0.01202450032
51.487,0.97808,0.01138,,,,,0.05927757576,0.01222866968
51.987,1.01996,0.01455,,,,,0.06181575758,0.01563507415
52.487,1.06171,0.01504,,,,,0.06434606061,0.01616161616
52.987,1.10299,0.01583,,,,,0.06684787879,0.01701053084
53.487,1.14506,0.01781,,,,,0.06939757576,0.01913819041
53.987,1.18669,0.01809,,,,,0.07192060606,0.01943907157
54.487,1.22807,0.0208,,,,,0.07442848485,0.02235117129
54.987,1.27005,0.02325,,,,,0.07697272727,0.02498388137
55.487,1.31151,0.02132,,,,,0.07948545455,0.02290995057
55.987,1.35321,0.0253,,,,,0.08201272727,0.02718676123
56.487,1.39501,0.02562,,,,,0.08454606061,0.0275306254
56.987,1.43624,0.02663,,,,,0.08704484848,0.0286159467
57.487,1.47847,0.02863,,,,,0.08960424242,0.03076509779
57.987,1.51992,0.03178,,,,,0.09211636364,0.03415001075
58.487,1.56133,0.03117,,,,,0.09462606061,0.03349451966
58.987,1.60344,0.03164,,,,,0.09717818182,0.03399957017
59.487,1.64491,0.03268,,,,,0.09969151515,0.03511712873
59.748,1.63787,0.03293,,,,,0.09926484848,0.03538577262
60.248,1.59626,0.02583,,,,,0.0967430303,0.02775628627
60.748,1.5548,0.02234,,,,,0.09423030303,0.02400601762
61.248,1.5127,0.02035,,,,,0.09167878788,0.02186761229
61.748,1.47126,0.01724,,,,,0.08916727273,0.01852568236
62.248,1.42966,0.01717,,,,,0.08664606061,0.01845046207
62.748,1.38789,0.01293,,,,,0.08411454545,0.01389426177
63.248,1.34641,0.01282,,,,,0.08160060606,0.01377605846
63.748,1.30447,0.00867,,,,,0.07905878788,0.009316569955
64.248,1.26301,0.00706,,,,,0.07654606061,0.007586503331
64.748,1.22142,0.00488,,,,,0.07402545455,0.005243928648
65.248,1.17937,0.00267,,,,,0.0714769697,0.002869116699
65.748,1.13801,0.00284,,,,,0.06897030303,0.003051794541
66.248,1.09629,0.00124,,,,,0.06644181818,0.001332473673
66.748,1.05447,0.00293,,,,,0.06390727273,0.00314850634
67.248,1.01311,-0.00113,,,,,0.06140060606,-0.001214270363
67.748,0.97111,-0.00559,,,,,0.05885515152,-0.006006877283
68.248,0.92957,-0.00645,,,,,0.05633757576,-0.00693101225
68.748,0.88819,-0.00553,,,,,0.05382969697,-0.005942402751
69.248,0.84608,-0.00982,,,,,0.05127757576,-0.01055233183
69.748,0.80466,-0.0116,,,,,0.04876727273,-0.01246507629
70.248,0.76313,-0.00961,,,,,0.04625030303,-0.01032667096
70.748,0.72116,-0.01472,,,,,0.04370666667,-0.01581775199
71.248,0.67967,-0.01506,,,,,0.04119212121,-0.01618310767
71.748,0.63788,-0.0175,,,,,0.03865939394,-0.018805072
72.248,0.5963,-0.01698,,,,,0.03613939394,-0.01824629271
72.748,0.55477,-0.01979,,,,,0.03362242424,-0.02126584999
73.248,0.51265,-0.02062,,,,,0.03106969697,-0.02215774769
73.748,0.47137,-0.02205,,,,,0.02856787879,-0.02369439072
74.248,0.42979,-0.02286,,,,,0.02604787879,-0.02456479691
74.748,0.38765,-0.02332,,,,,0.02349393939,-0.02505910165
75.248,0.34631,-0.02362,,,,,0.02098848485,-0.02538147432
75.748,0.30466,-0.02899,,,,,0.01846424242,-0.03115194498
76.248,0.2628,-0.02894,,,,,0.01592727273,-0.0310982162
76.748,0.22145,-0.02947,,,,,0.01342121212,-0.03166774124
77.248,0.17946,-0.03022,,,,,0.01087636364,-0.0324736729
77.748,0.13796,-0.02976,,,,,0.008361212121,-0.03197936815
78.248,0.09649,-0.03211,,,,,0.005847878788,-0.03450462067
78.748,0.05438,-0.03456,,,,,0.003295757576,-0.03713733075
79.248,0.01298,-0.03623,,,,,0.0007866666667,-0.03893187191
79.507,0.00204,-0.03444,,,,,0.0001236363636,-0.03700838169
80.007,0.04485,-0.03352,,,,,0.002718181818,-0.03601977219
80.507,0.08677,-0.02928,,,,,0.005258787879,-0.03146357189
81.007,0.12802,-0.02651,,,,,0.007758787879,-0.02848699764
81.507,0.16997,-0.02053,,,,,0.01030121212,-0.02206103589
82.007,0.21175,-0.0209,,,,,0.01283333333,-0.02245862884
82.507,0.25295,-0.01666,,,,,0.01533030303,-0.01790242854
83.007,0.29506,-0.01741,,,,,0.01788242424,-0.0187083602
83.507,0.33667,-0.01392,,,,,0.02040424242,-0.01495809155
84.007,0.37807,-0.01115,,,,,0.02291333333,-0.0119815173
84.507,0.42005,-0.01221,,,,,0.02545757576,-0.01312056738
85.007,0.46149,-0.01213,,,,,0.02796909091,-0.01303460133
85.507,0.50333,-0.00771,,,,,0.03050484848,-0.008284977434
86.007,0.54496,-0.0081,,,,,0.03302787879,-0.008704061896
86.507,0.5863,-0.00559,,,,,0.03553333333,-0.006006877283
87.007,0.62844,-0.0029,,,,,0.03808727273,-0.003116269074
87.507,0.66991,-0.00427,,,,,0.04060060606,-0.004588437567
88.007,0.71136,-0.00126,,,,,0.04311272727,-0.001353965184
88.507,0.75347,0.00109,,,,,0.04566484848,0.001171287342
89.007,0.79477,0.00271,,,,,0.04816787879,0.002912099721
89.507,0.83658,0.00318,,,,,0.05070181818,0.003417150226
90.007,0.87845,0.00293,,,,,0.05323939394,0.00314850634
90.507,0.91962,0.00659,,,,,0.05573454545,0.007081452826
91.007,0.96175,0.00733,,,,,0.05828787879,0.007876638728
91.507,1.00339,0.00815,,,,,0.06081151515,0.008757790673
92.007,1.04461,0.01149,,,,,0.06330969697,0.01234687299
92.507,1.08667,0.01243,,,,,0.06585878788,0.013356974
93.007,1.12821,0.01356,,,,,0.06837636364,0.01457124436
93.507,1.16987,0.01399,,,,,0.07090121212,0.01503331184
94.007,1.21168,0.01558,,,,,0.07343515152,0.01674188695
94.507,1.25304,0.01666,,,,,0.07594181818,0.01790242854
95.007,1.29505,0.01771,,,,,0.07848787879,0.01903073286
95.507,1.33665,0.02156,,,,,0.08100909091,0.0231678487
96.007,1.37789,0.02416,,,,,0.08350848485,0.02596174511
96.507,1.42014,0.02267,,,,,0.08606909091,0.02436062755
97.007,1.4616,0.02344,,,,,0.08858181818,0.02518805072
97.507,1.50311,0.02714,,,,,0.09109757576,0.02916398023
98.007,1.54508,0.02654,,,,,0.09364121212,0.0285192349
98.507,1.58647,0.02645,,,,,0.09614969697,0.0284225231
99.007,1.62833,0.02899,,,,,0.09868666667,0.03115194498
99.268,1.65024,0.02997,,,,,0.1000145455,0.03220502901
99.768,1.61307,0.0259,,,,,0.09776181818,0.02783150655
100.268,1.57137,0.02042,,,,,0.09523454545,0.02194283258
100.768,1.52974,0.0199,,,,,0.09271151515,0.0213840533
101.268,1.48789,0.01697,,,,,0.09017515152,0.01823554696
101.768,1.44638,0.01398,,,,,0.08765939394,0.01502256609
102.268,1.40482,0.01153,,,,,0.08514060606,0.01238985601
102.768,1.3627,0.01118,,,,,0.08258787879,0.01201375457
103.268,1.32143,0.00832,,,,,0.08008666667,0.008940468515
103.768,1.2798,0.00561,,,,,0.07756363636,0.006028368794
104.268,1.23774,0.00421,,,,,0.07501454545,0.004523963035
104.768,1.19651,0.00222,,,,,0.07251575758,0.002385557705
105.268,1.15454,0.00007,,,,,0.06997212121,0.00007522028799
105.768,1.11297,-0.00056,,,,,0.06745272727,-0.0006017623039
106.268,1.07157,-0.00385,,,,,0.06494363636,-0.004137115839
106.768,1.02947,-0.00459,,,,,0.06239212121,-0.004932301741
107.268,0.98795,-0.00711,,,,,0.05987575758,-0.007640232108
107.768,0.94653,-0.01033,,,,,0.05736545455,-0.01110036536
108.268,0.90446,-0.01249,,,,,0.05481575758,-0.01342144853
108.768,0.86303,-0.01175,,,,,0.05230484848,-0.01262626263
109.268,0.82134,-0.01596,,,,,0.04977818182,-0.01715022566
109.768,0.77961,-0.01614,,,,,0.04724909091,-0.01734364926
110.268,0.73813,-0.01564,,,,,0.04473515152,-0.01680636149
110.768,0.69614,-0.01731,,,,,0.04219030303,-0.01860090264
111.268,0.65477,-0.01983,,,,,0.0396830303,-0.02130883301
111.768,0.61307,-0.02106,,,,,0.03715575758,-0.02263056093
112.268,0.5711,-0.02312,,,,,0.03461212121,-0.02484418655
112.768,0.52976,-0.02412,,,,,0.03210666667,-0.02591876209
113.268,0.48804,-0.02465,,,,,0.02957818182,-0.02648828713
113.768,0.44619,-0.02476,,,,,0.02704181818,-0.02660649044
114.268,0.40484,-0.02716,,,,,0.02453575758,-0.02918547174
114.768,0.36287,-0.0281,,,,,0.02199212121,-0.03019557275
115.268,0.32136,-0.03062,,,,,0.01947636364,-0.03290350312
115.768,0.27994,-0.03184,,,,,0.01696606061,-0.03421448528
116.268,0.23774,-0.03116,,,,,0.01440848485,-0.03348377391
116.768,0.19637,-0.03353,,,,,0.01190121212,-0.03603051795
117.268,0.15477,-0.03458,,,,,0.00938,-0.03715882227
117.768,0.1129,-0.03611,,,,,0.006842424242,-0.03880292285
118.268,0.07137,-0.03721,,,,,0.004325454545,-0.03998495594
118.768,0.02954,-0.03752,,,,,0.00179030303,-0.04031807436
119.126,-0.0001,-0.03935,,,,,-0.000006060606061,-0.0422845476
119.527,0.02839,-0.03384,,,,,0.001720606061,-0.03636363636
120.027,0.06961,-0.03173,,,,,0.004218787879,-0.03409628197
120.527,0.11169,-0.0291,,,,,0.006769090909,-0.03127014829
121.027,0.15343,-0.02677,,,,,0.009298787879,-0.02876638728
121.527,0.19467,-0.02604,,,,,0.01179818182,-0.02798194713
122.027,0.23687,-0.02159,,,,,0.01435575758,-0.02320008597
122.527,0.2782,-0.02028,,,,,0.01686060606,-0.02179239201
123.027,0.32,-0.01819,,,,,0.01939393939,-0.01954652912
123.527,0.36174,-0.01732,,,,,0.02192363636,-0.0186116484
124.027,0.40304,-0.01523,,,,,0.02442666667,-0.01636578551
124.527,0.44518,-0.01478,,,,,0.02698060606,-0.01588222652
125.027,0.48673,-0.01337,,,,,0.02949878788,-0.01436707501
125.527,0.52803,-0.01005,,,,,0.03200181818,-0.0107994842
126.027,0.57017,-0.01189,,,,,0.03455575758,-0.0127767032
126.527,0.6116,-0.00937,,,,,0.03706666667,-0.01006877283
127.027,0.65314,-0.00818,,,,,0.03958424242,-0.008790027939
127.527,0.69521,-0.00493,,,,,0.04213393939,-0.005297657425
128.027,0.73639,-0.00409,,,,,0.04462969697,-0.004395013969
128.527,0.77843,-0.00306,,,,,0.04717757576,-0.003288201161
129.027,0.82008,-0.002,,,,,0.04970181818,-0.002149151085
129.527,0.86134,0.00019,,,,,0.05220242424,0.0002041693531
130.027,0.90343,0.00302,,,,,0.05475333333,0.003245218139
130.527,0.94504,0.00451,,,,,0.05727515152,0.004846335697
131.027,0.98648,0.00826,,,,,0.05978666667,0.008875993982
131.527,1.02842,0.00993,,,,,0.06232848485,0.01067053514
132.027,1.06982,0.00887,,,,,0.06483757576,0.009531485063
132.527,1.11173,0.012,,,,,0.06737757576,0.01289490651
133.027,1.15337,0.01151,,,,,0.06990121212,0.0123683645
133.527,1.19464,0.01421,,,,,0.07240242424,0.01526971846
134.027,1.23691,0.01649,,,,,0.07496424242,0.0177197507
134.527,1.27835,0.01325,,,,,0.07747575758,0.01423812594
135.027,1.31978,0.01608,,,,,0.07998666667,0.01727917473
135.527,1.36188,0.01821,,,,,0.08253818182,0.01956802063
136.027,1.40318,0.0201,,,,,0.08504121212,0.02159896841
136.527,1.4449,0.01988,,,,,0.08756969697,0.02136256179
137.027,1.48682,0.02253,,,,,0.09011030303,0.02421018698
137.527,1.52803,0.02272,,,,,0.09260787879,0.02441435633
138.027,1.57009,0.02332,,,,,0.0951569697,0.02505910165
138.527,1.61176,0.02433,,,,,0.09768242424,0.02614442295
138.985,1.65004,0.02875,,,,,0.1000024242,0.03089404685
139.287,1.62973,0.02428,,,,,0.09877151515,0.02609069418
139.787,1.58811,0.02063,,,,,0.09624909091,0.02216849345
140.287,1.54604,0.01888,,,,,0.09369939394,0.02028798625
140.787,1.50469,0.01418,,,,,0.09119333333,0.01523748119
141.287,1.46302,0.01158,,,,,0.08866787879,0.01244358478
141.787,1.4211,0.01033,,,,,0.08612727273,0.01110036536
142.287,1.3797,0.00737,,,,,0.08361818182,0.007919621749
142.787,1.33788,0.00673,,,,,0.08108363636,0.007231893402
143.287,1.29625,0.00701,,,,,0.07856060606,0.007532774554
143.787,1.2549,0.00164,,,,,0.07605454545,0.00176230389
144.287,1.21269,0.00165,,,,,0.07349636364,0.001773049645
144.787,1.17133,-0.0008,,,,,0.07098969697,-0.0008596604341
145.287,1.1298,-0.00469,,,,,0.06847272727,-0.005039759295
145.787,1.08775,-0.00451,,,,,0.06592424242,-0.004846335697
146.287,1.04628,-0.00626,,,,,0.06341090909,-0.006726842897
146.787,1.00469,-0.00809,,,,,0.06089030303,-0.00869331614
147.287,0.96285,-0.01113,,,,,0.05835454545,-0.01196002579
147.787,0.92134,-0.0104,,,,,0.05583878788,-0.01117558564
148.287,0.87945,-0.01257,,,,,0.0533,-0.01350741457
148.787,0.83802,-0.01525,,,,,0.05078909091,-0.01638727703
149.287,0.79648,-0.01427,,,,,0.04827151515,-0.01533419299
149.787,0.75429,-0.01789,,,,,0.04571454545,-0.01922415646
150.287,0.71308,-0.01882,,,,,0.0432169697,-0.02022351171
150.787,0.67138,-0.0205,,,,,0.04068969697,-0.02202879862
151.287,0.62938,-0.02075,,,,,0.03814424242,-0.02229744251
151.787,0.58802,-0.02226,,,,,0.03563757576,-0.02392005158
152.287,0.54625,-0.02611,,,,,0.03310606061,-0.02805716742
152.787,0.50451,-0.02816,,,,,0.03057636364,-0.03026004728
153.287,0.46315,-0.0302,,,,,0.02806969697,-0.03245218139
153.787,0.42105,-0.03005,,,,,0.02551818182,-0.03229099506
154.287,0.37961,-0.03308,,,,,0.02300666667,-0.03554695895
154.787,0.33808,-0.03323,,,,,0.02048969697,-0.03570814528
155.287,0.29605,-0.03438,,,,,0.01794242424,-0.03694390716
155.787,0.25461,-0.03565,,,,,0.01543090909,-0.0383086181
156.287,0.21286,-0.03455,,,,,0.01290060606,-0.037126585
156.787,0.1713,-0.03692,,,,,0.01038181818,-0.03967332904
157.287,0.12972,-0.0381,,,,,0.007861818182,-0.04094132818
157.787,0.08775,-0.03827,,,,,0.005318181818,-0.04112400602
158.287,0.04632,-0.04088,,,,,0.002807272727,-0.04392864818
158.787,0.0048,-0.04232,,,,,0.0002909090909,-0.04547603697
159.046,0.01099,-0.03941,,,,,0.0006660606061,-0.04234902214
159.546,0.05332,-0.03588,,,,,0.003231515152,-0.03855577047
160.046,0.09486,-0.03403,,,,,0.005749090909,-0.03656780572
160.546,0.13644,-0.03151,,,,,0.008269090909,-0.03385987535
161.046,0.17835,-0.02772,,,,,0.01080909091,-0.02978723404
161.546,0.21972,-0.02636,,,,,0.01331636364,-0.0283258113
162.046,0.26171,-0.02512,,,,,0.01586121212,-0.02699333763
162.546,0.30327,-0.0222,,,,,0.01838,-0.02385557705
163.046,0.34462,-0.01968,,,,,0.02088606061,-0.02114764668
163.546,0.38673,-0.01755,,,,,0.02343818182,-0.01885880077
164.046,0.42812,-0.01716,,,,,0.02594666667,-0.01843971631
164.546,0.46977,-0.01593,,,,,0.02847090909,-0.01711798839
165.046,0.51172,-0.01317,,,,,0.03101333333,-0.0141521599
165.546,0.55291,-0.00889,,,,,0.03350969697,-0.009552976574
166.046,0.5949,-0.0118,,,,,0.03605454545,-0.0126799914
166.546,0.63668,-0.0086,,,,,0.03858666667,-0.009241349667
167.046,0.67785,-0.00632,,,,,0.04108181818,-0.00679131743
167.546,0.72007,-0.00528,,,,,0.04364060606,-0.005673758865
168.046,0.76165,-0.00468,,,,,0.04616060606,-0.00502901354
168.546,0.803,-0.00258,,,,,0.04866666667,-0.0027724049
169.046,0.845,-0.00205,,,,,0.05121212121,-0.002202879862
169.546,0.88646,0.0002,,,,,0.05372484848,0.0002149151085
170.046,0.92826,0.001,,,,,0.05625818182,0.001074575543
170.546,0.96996,0.00247,,,,,0.05878545455,0.00265420159
171.046,1.01125,0.00591,,,,,0.06128787879,0.006350741457
171.546,1.05342,0.00559,,,,,0.06384363636,0.006006877283
172.046,1.09495,0.00838,,,,,0.06636060606,0.009004943047
172.546,1.13622,0.01038,,,,,0.06886181818,0.01115409413
173.046,1.17841,0.01097,,,,,0.07141878788,0.0117880937
173.546,1.21974,0.01232,,,,,0.07392363636,0.01323877069
174.046,1.2615,0.01388,,,,,0.07645454545,0.01491510853
174.546,1.30331,0.0151,,,,,0.07898848485,0.01622609069
175.046,1.34468,0.01561,,,,,0.08149575758,0.01677412422
175.546,1.38668,0.0179,,,,,0.08404121212,0.01923490221
176.046,1.42835,0.01813,,,,,0.08656666667,0.01948205459
176.546,1.46961,0.01924,,,,,0.08906727273,0.02067483344
177.046,1.51171,0.0198,,,,,0.09161878788,0.02127659574
177.546,1.55326,0.0225,,,,,0.0941369697,0.02417794971
178.046,1.59475,0.02389,,,,,0.09665151515,0.02567160971
178.546,1.63666,0.0264,,,,,0.09919151515,0.02836879433
178.807,1.6472,0.02574,,,,,0.09983030303,0.02765957447
179.307,1.60438,0.0185,,,,,0.09723515152,0.01987964754
179.807,1.56307,0.01796,,,,,0.09473151515,0.01929937675
180.307,1.52134,0.01248,,,,,0.09220242424,0.01341070277
180.807,1.47951,0.01168,,,,,0.08966727273,0.01255104234
181.307,1.43819,0.00906,,,,,0.0871630303,0.009735654417
181.807,1.3961,0.00659,,,,,0.08461212121,0.007081452826
182.307,1.35458,0.0033,,,,,0.08209575758,0.003546099291
182.807,1.31315,-0.0007,,,,,0.07958484848,-0.0007522028799
183.307,1.27103,-0.00036,,,,,0.07703212121,-0.0003868471954
183.807,1.22959,-0.00248,,,,,0.07452060606,-0.002664947346
184.307,1.18808,-0.00316,,,,,0.07200484848,-0.003395658715
184.807,1.14617,-0.00564,,,,,0.06946484848,-0.006060606061
185.307,1.10466,-0.00693,,,,,0.06694909091,-0.007446808511
185.807,1.06286,-0.00835,,,,,0.06441575758,-0.008972705781
186.307,1.02132,-0.00899,,,,,0.06189818182,-0.009660434129
186.807,0.97981,-0.01103,,,,,0.05938242424,-0.01185256824
187.307,0.9377,-0.01142,,,,,0.05683030303,-0.0122716527
187.807,0.89641,-0.0139,,,,,0.05432787879,-0.01493660004
188.307,0.85471,-0.01565,,,,,0.05180060606,-0.01681710724
188.807,0.8128,-0.01649,,,,,0.04926060606,-0.0177197507
189.307,0.77139,-0.01853,,,,,0.04675090909,-0.01991188481
189.807,0.72954,-0.02093,,,,,0.04421454545,-0.02249086611
190.307,0.68784,-0.02104,,,,,0.04168727273,-0.02260906942
190.807,0.64647,-0.02348,,,,,0.03918,-0.02523103374
191.307,0.60443,-0.02395,,,,,0.03663212121,-0.02573608425
191.807,0.56299,-0.02727,,,,,0.03412060606,-0.02930367505
192.307,0.5215,-0.02744,,,,,0.03160606061,-0.02948635289
192.807,0.47939,-0.02819,,,,,0.02905393939,-0.03029228455
193.307,0.43797,-0.03011,,,,,0.02654363636,-0.03235546959
193.807,0.39635,-0.03185,,,,,0.02402121212,-0.03422523103
194.307,0.35462,-0.03317,,,,,0.02149212121,-0.03564367075
194.807,0.31309,-0.03307,,,,,0.01897515152,-0.0355362132
195.307,0.2711,-0.03417,,,,,0.01643030303,-0.03671824629
195.807,0.2297,-0.03788,,,,,0.01392121212,-0.04070492156
196.307,0.18817,-0.03897,,,,,0.01140424242,-0.0418762089
196.807,0.14598,-0.03985,,,,,0.008847272727,-0.04282183538
197.307,0.10469,-0.0414,,,,,0.006344848485,-0.04448742747
197.807,0.06311,-0.0421,,,,,0.003824848485,-0.04523963035
198.307,0.0211,-0.04402,,,,,0.001278787879,-0.04730281539
198.566,-0.00023,-0.04404,,,,,-0.00001393939394,-0.0473243069
199.066,0.03637,-0.04044,,,,,0.002204242424,-0.04345583495
199.566,0.07836,-0.03511,,,,,0.004749090909,-0.0377283473
200.066,0.11994,-0.03236,,,,,0.007269090909,-0.03477326456
200.566,0.16132,-0.03152,,,,,0.009776969697,-0.0338706211
201.066,0.20344,-0.0303,,,,,0.01232969697,-0.03255963894
201.566,0.24496,-0.02682,,,,,0.01484606061,-0.02882011605
202.066,0.28636,-0.02572,,,,,0.01735515152,-0.02763808296
202.566,0.32841,-0.0219,,,,,0.01990363636,-0.02353320438
203.066,0.36974,-0.02075,,,,,0.02240848485,-0.02229744251
203.566,0.4115,-0.01773,,,,,0.02493939394,-0.01905222437
204.066,0.45342,-0.01534,,,,,0.02748,-0.01648398882
204.566,0.49459,-0.01623,,,,,0.02997515152,-0.01744036106
205.066,0.53675,-0.01325,,,,,0.03253030303,-0.01423812594
205.566,0.57836,-0.01237,,,,,0.03505212121,-0.01329249946
206.066,0.61968,-0.0099,,,,,0.03755636364,-0.01063829787
206.566,0.66173,-0.0071,,,,,0.04010484848,-0.007629486353
207.066,0.70328,-0.00916,,,,,0.0426230303,-0.009843111971
207.566,0.74491,-0.00748,,,,,0.04514606061,-0.008037825059
208.066,0.78666,-0.00484,,,,,0.04767636364,-0.005200945626
208.566,0.82799,-0.00615,,,,,0.05018121212,-0.006608639587
209.066,0.87004,-0.00452,,,,,0.05272969697,-0.004857081453
209.566,0.91157,-0.00028,,,,,0.05524666667,-0.0003008811519
210.066,0.9529,0.00109,,,,,0.05775151515,0.001171287342
210.566,0.99513,0.00236,,,,,0.06031090909,0.002535998281
211.066,1.03648,0.00572,,,,,0.0628169697,0.006146572104
211.566,1.07813,0.00475,,,,,0.06534121212,0.005104233828
212.066,1.12008,0.00818,,,,,0.06788363636,0.008790027939
212.566,1.16133,0.00827,,,,,0.07038363636,0.008886739738
213.066,1.20332,0.00827,,,,,0.07292848485,0.008886739738
213.566,1.24509,0.01271,,,,,0.07546,0.01365785515
214.066,1.28629,0.01314,,,,,0.0779569697,0.01411992263
214.566,1.32837,0.0156,,,,,0.08050727273,0.01676337847
215.066,1.36998,0.01776,,,,,0.08302909091,0.01908446164
215.566,1.41144,0.01717,,,,,0.08554181818,0.01845046207
216.066,1.45333,0.01876,,,,,0.08808060606,0.02015903718
216.566,1.49475,0.01977,,,,,0.09059090909,0.02124435848
217.066,1.53663,0.01947,,,,,0.09312909091,0.02092198582
217.566,1.57828,0.0217,,,,,0.09565333333,0.02331828928
218.066,1.61956,0.02264,,,,,0.09815515152,0.02432839029
218.426,1.65013,0.02472,,,,,0.1000078788,0.02656350741
218.827,1.62153,0.01948,,,,,0.09827454545,0.02093273157
219.327,1.57956,0.01606,,,,,0.09573090909,0.01725768322
219.827,1.53805,0.01384,,,,,0.09321515152,0.01487212551
220.327,1.49669,0.01096,,,,,0.09070848485,0.01177734795
220.827,1.4544,0.00957,,,,,0.08814545455,0.01028368794
221.327,1.41312,0.00696,,,,,0.08564363636,0.007479045777
221.827,1.37149,0.00302,,,,,0.08312060606,0.003245218139
222.327,1.32962,0.0033,,,,,0.0805830303,0.003546099291
222.827,1.28809,0.00187,,,,,0.07806606061,0.002009456265
223.327,1.24636,-0.00068,,,,,0.0755369697,-0.000730711369
223.827,1.20472,-0.00414,,,,,0.07301333333,-0.004448742747
224.327,1.16325,-0.0035,,,,,0.0705,-0.003761014399
224.827,1.12112,-0.00595,,,,,0.06794666667,-0.006393724479
225.327,1.07984,-0.00897,,,,,0.06544484848,-0.009638942618
225.827,1.03824,-0.01014,,,,,0.06292363636,-0.010896196
226.327,0.99605,-0.01051,,,,,0.06036666667,-0.01129378895
226.827,0.95486,-0.01177,,,,,0.05787030303,-0.01264775414
227.327,0.91301,-0.01495,,,,,0.05533393939,-0.01606490436
227.827,0.87126,-0.0183,,,,,0.05280363636,-0.01966473243
228.327,0.82983,-0.02024,,,,,0.05029272727,-0.02174940898
228.827,0.7879,-0.01888,,,,,0.04775151515,-0.02028798625
229.327,0.74633,-0.01925,,,,,0.04523212121,-0.0206855792
229.827,0.70492,-0.02263,,,,,0.04272242424,-0.02431764453
230.327,0.66279,-0.0238,,,,,0.04016909091,-0.02557489792
230.827,0.62142,-0.02485,,,,,0.03766181818,-0.02670320224
231.327,0.57979,-0.03028,,,,,0.03513878788,-0.03253814743
231.827,0.53794,-0.02996,,,,,0.03260242424,-0.03219428326
232.327,0.49647,-0.03208,,,,,0.03008909091,-0.03447238341
232.827,0.45456,-0.02834,,,,,0.02754909091,-0.03045347088
233.327,0.41315,-0.03348,,,,,0.02503939394,-0.03597678917
233.827,0.37146,-0.03178,,,,,0.02251272727,-0.03415001075
234.327,0.32946,-0.03386,,,,,0.01996727273,-0.03638512787
234.827,0.2881,-0.03551,,,,,0.01746060606,-0.03815817752
235.327,0.2465,-0.03656,,,,,0.01493939394,-0.03928648184
235.827,0.20446,-0.0381,,,,,0.01239151515,-0.04094132818
236.327,0.16315,-0.03388,,,,,0.009887878788,-0.03640661939
236.827,0.12133,-0.03903,,,,,0.007353333333,-0.04194068343
237.327,0.07966,-0.03965,,,,,0.004827878788,-0.04260692027
237.827,0.03828,-0.04048,,,,,0.00232,-0.04349881797
238.285,-0.00007,-0.04591,,,,,-0.000004242424242,-0.04933376316
238.587,0.01994,-0.04097,,,,,0.001208484848,-0.04402535998
239.087,0.06155,-0.03787,,,,,0.00373030303,-0.0406941758
239.587,0.10302,-0.03272,,,,,0.006243636364,-0.03516011176
240.087,0.14505,-0.03206,,,,,0.008790909091,-0.0344508919
240.587,0.18637,-0.03371,,,,,0.01129515152,-0.03622394154
241.087,0.22822,-0.02819,,,,,0.01383151515,-0.03029228455
241.587,0.27006,-0.02401,,,,,0.01636727273,-0.02580055878
242.087,0.31127,-0.02451,,,,,0.01886484848,-0.02633784655
242.587,0.35332,-0.02377,,,,,0.02141333333,-0.02554266065
243.087,0.39506,-0.02128,,,,,0.0239430303,-0.02286696755
243.587,0.43623,-0.0194,,,,,0.02643818182,-0.02084676553
244.087,0.47847,-0.01772,,,,,0.02899818182,-0.01904147862
244.587,0.51996,-0.01781,,,,,0.03151272727,-0.01913819041
245.087,0.56149,-0.01589,,,,,0.03402969697,-0.01707500537
245.587,0.60335,-0.01242,,,,,0.03656666667,-0.01334622824
246.087,0.64468,-0.01175,,,,,0.03907151515,-0.01262626263
246.587,0.68671,-0.01143,,,,,0.04161878788,-0.01228239845
247.087,0.72832,-0.00703,,,,,0.04414060606,-0.007554266065
247.587,0.76956,-0.00642,,,,,0.04664,-0.006898774984
248.087,0.81174,-0.00414,,,,,0.04919636364,-0.004448742747
248.587,0.8533,-0.00409,,,,,0.05171515152,-0.004395013969
249.087,0.89466,-0.00212,,,,,0.05422181818,-0.00227810015
249.587,0.9368,-0.00003,,,,,0.05677575758,-0.00003223726628
250.087,0.9781,0.00218,,,,,0.05927878788,0.002342574683
250.587,1.02,0.00049,,,,,0.06181818182,0.0005265420159
251.087,1.06168,0.00285,,,,,0.06434424242,0.003062540297
251.587,1.103,0.0045,,,,,0.06684848485,0.004835589942
252.087,1.14506,0.00521,,,,,0.06939757576,0.005598538577
252.587,1.1867,0.0082,,,,,0.07192121212,0.00881151945
253.087,1.22806,0.01043,,,,,0.07442787879,0.01120782291
253.587,1.27003,0.01149,,,,,0.07697151515,0.01234687299
254.087,1.31151,0.01545,,,,,0.07948545455,0.01660219213
254.587,1.35321,0.01395,,,,,0.08201272727,0.01499032882
255.087,1.39501,0.01461,,,,,0.08454606061,0.01569954868
255.587,1.43625,0.01649,,,,,0.08704545455,0.0177197507
256.087,1.47847,0.01919,,,,,0.08960424242,0.02062110466
256.587,1.51992,0.02012,,,,,0.09211636364,0.02162045992
257.087,1.56137,0.02174,,,,,0.09462848485,0.0233612723
257.587,1.60346,0.02421,,,,,0.09717939394,0.02601547389
258.087,1.64491,0.02331,,,,,0.09969151515,0.0250483559
258.348,1.63811,0.02343,,,,,0.09927939394,0.02517730496
258.848,1.59649,0.01925,,,,,0.0967569697,0.0206855792
259.348,1.55502,0.01509,,,,,0.09424363636,0.01621534494
259.848,1.51293,0.01263,,,,,0.09169272727,0.0135718891
260.348,1.47146,0.01104,,,,,0.08917939394,0.01186331399
260.848,1.42983,0.00651,,,,,0.08665636364,0.006995486783
261.348,1.38814,0.00542,,,,,0.08412969697,0.005824199441
261.848,1.34665,0.00404,,,,,0.08161515152,0.004341285192
262.348,1.30467,-0.00024,,,,,0.07907090909,-0.0002578981302
262.848,1.26319,-0.00084,,,,,0.0765569697,-0.0009026434558
263.348,1.22157,-0.00369,,,,,0.07403454545,-0.003965183752
263.848,1.17956,-0.00648,,,,,0.07148848485,-0.006963249516
264.348,1.13822,-0.00623,,,,,0.0689830303,-0.006694605631
264.848,1.09646,-0.00909,,,,,0.06645212121,-0.009767891683
265.348,1.05472,-0.00986,,,,,0.06392242424,-0.01059531485
265.848,1.01334,-0.00959,,,,,0.06141454545,-0.01030517945
266.348,0.97129,-0.01359,,,,,0.05886606061,-0.01460348162
266.848,0.92982,-0.01673,,,,,0.05635272727,-0.01797764883
267.348,0.88836,-0.0158,,,,,0.05384,-0.01697829357
267.848,0.8463,-0.01804,,,,,0.05129090909,-0.01938534279
268.348,0.80488,-0.01935,,,,,0.04878060606,-0.02079303675
268.848,0.76332,-0.02028,,,,,0.04626181818,-0.02179239201
269.348,0.7214,-0.02349,,,,,0.04372121212,-0.0252417795
269.848,0.67989,-0.02571,,,,,0.04120545455,-0.0276273372
270.348,0.63806,-0.0236,,,,,0.03867030303,-0.02535998281
270.848,0.59652,-0.02644,,,,,0.03615272727,-0.02841177735
271.348,0.555,-0.02931,,,,,0.03363636364,-0.03149580916
271.848,0.51285,-0.02969,,,,,0.03108181818,-0.03190414786
272.348,0.4716,-0.03146,,,,,0.02858181818,-0.03380614657
272.848,0.42996,-0.03264,,,,,0.02605818182,-0.03507414571
273.348,0.38786,-0.03252,,,,,0.02350666667,-0.03494519665
273.848,0.34652,-0.03627,,,,,0.02100121212,-0.03897485493
274.348,0.30487,-0.03873,,,,,0.0184769697,-0.04161831077
274.848,0.26305,-0.0384,,,,,0.01594242424,-0.04126370084
275.348,0.2217,-0.03743,,,,,0.01343636364,-0.04022136256
275.848,0.17965,-0.04068,,,,,0.01088787879,-0.04371373308
276.348,0.13817,-0.04079,,,,,0.008373939394,-0.04383193639
276.848,0.09668,-0.04398,,,,,0.005859393939,-0.04725983237
277.348,0.0546,-0.04374,,,,,0.003309090909,-0.04700193424
277.848,0.01317,-0.04326,,,,,0.0007981818182,-0.04648613798
278.109,0.0022,-0.04612,,,,,0.0001333333333,-0.04955942403
278.609,0.04488,-0.04144,,,,,0.00272,-0.04453041049
279.109,0.08679,-0.0375,,,,,0.00526,-0.04029658285
279.609,0.12804,-0.03367,,,,,0.00776,-0.03618095852
280.109,0.17,-0.03261,,,,,0.0103030303,-0.03504190845
280.609,0.21178,-0.02875,,,,,0.01283515152,-0.03089404685
281.109,0.25297,-0.0269,,,,,0.01533151515,-0.0289060821
281.609,0.2951,-0.02637,,,,,0.01788484848,-0.02833655706
282.109,0.33669,-0.02171,,,,,0.02040545455,-0.02332903503
282.609,0.37812,-0.02211,,,,,0.02291636364,-0.02375886525
283.109,0.4201,-0.02128,,,,,0.02546060606,-0.02286696755
283.609,0.46151,-0.02084,,,,,0.02797030303,-0.02239415431
284.109,0.50332,-0.01767,,,,,0.03050424242,-0.01898774984
284.609,0.545,-0.01679,,,,,0.03303030303,-0.01804212336
285.109,0.58633,-0.0155,,,,,0.03553515152,-0.01665592091
285.609,0.62844,-0.0145,,,,,0.03808727273,-0.01558134537
286.109,0.66994,-0.01397,,,,,0.04060242424,-0.01501182033
286.609,0.71139,-0.01074,,,,,0.04311454545,-0.01154094133
287.109,0.7535,-0.00826,,,,,0.04566666667,-0.008875993982
287.609,0.79478,-0.00598,,,,,0.04816848485,-0.006425961745
288.109,0.83657,-0.004,,,,,0.05070121212,-0.004298302171
288.609,0.87846,-0.00371,,,,,0.05324,-0.003986675263
289.109,0.91963,-0.00173,,,,,0.05573515152,-0.001859015689
289.609,0.96177,0.00059,,,,,0.05828909091,0.0006339995702
290.109,1.00346,0.003,,,,,0.06081575758,0.003223726628
290.609,1.04466,0.00206,,,,,0.06331272727,0.002213625618
291.109,1.08671,0.00436,,,,,0.06586121212,0.004685149366
291.609,1.12827,0.00696,,,,,0.06838,0.007479045777
292.109,1.16991,0.00655,,,,,0.07090363636,0.007038469804
292.609,1.21173,0.00844,,,,,0.07343818182,0.00906941758
293.109,1.25305,0.00896,,,,,0.07594242424,0.009628196862
293.609,1.29507,0.01035,,,,,0.07848909091,0.01112185687
294.109,1.33668,0.01103,,,,,0.08101090909,0.01185256824
294.609,1.37793,0.01422,,,,,0.08351090909,0.01528046422
295.109,1.42016,0.01542,,,,,0.08607030303,0.01656995487
295.609,1.46163,0.01591,,,,,0.08858363636,0.01709649688
296.109,1.50314,0.01861,,,,,0.09109939394,0.01999785085
296.609,1.54508,0.01996,,,,,0.09364121212,0.02144852783
297.109,1.58646,0.02003,,,,,0.09614909091,0.02152374812
297.609,1.62833,0.02069,,,,,0.09868666667,0.02223296798
297.869,1.6502,0.02044,,,,,0.1000121212,0.02196432409
298.369,1.61313,0.01689,,,,,0.09776545455,0.01814958092
298.869,1.57145,0.01331,,,,,0.09523939394,0.01430260047
299.369,1.52984,0.01133,,,,,0.09271757576,0.0121749409
299.869,1.48794,0.00852,,,,,0.09017818182,0.009155383623
300.369,1.44645,0.00729,,,,,0.08766363636,0.007833655706
300.869,1.40489,0.00375,,,,,0.08514484848,0.004029658285
301.369,1.3628,0.00105,,,,,0.08259393939,0.00112830432
301.869,1.32153,-0.00069,,,,,0.08009272727,-0.0007414571244
302.369,1.27986,-0.00077,,,,,0.07756727273,-0.0008274231678
302.869,1.23783,-0.00459,,,,,0.07502,-0.004932301741
303.369,1.19662,-0.0043,,,,,0.07252242424,-0.004620674833
303.869,1.15464,-0.00732,,,,,0.06997818182,-0.007865892972
304.369,1.11302,-0.00904,,,,,0.06745575758,-0.009714162906
304.869,1.07162,-0.01075,,,,,0.06494666667,-0.01155168708
305.369,1.02955,-0.01207,,,,,0.0623969697,-0.0129701268
305.869,0.98804,-0.01538,,,,,0.05988121212,-0.01652697185
306.369,0.94662,-0.01677,,,,,0.05737090909,-0.01802063185
306.869,0.90455,-0.01756,,,,,0.05482121212,-0.01886954653
307.369,0.8631,-0.01941,,,,,0.05230909091,-0.02085751128
307.869,0.82141,-0.01976,,,,,0.04978242424,-0.02123361272
308.369,0.77968,-0.0229,,,,,0.04725333333,-0.02460777993
308.869,0.73819,-0.02401,,,,,0.04473878788,-0.02580055878
309.369,0.69618,-0.02443,,,,,0.04219272727,-0.02625188051
309.869,0.65487,-0.02705,,,,,0.03968909091,-0.02906726843
310.369,0.61317,-0.02753,,,,,0.03716181818,-0.02958306469
310.869,0.57119,-0.02764,,,,,0.03461757576,-0.029701268
311.369,0.52982,-0.03066,,,,,0.03211030303,-0.03294648614
311.869,0.48811,-0.03193,,,,,0.02958242424,-0.03431119708
312.369,0.4463,-0.03021,,,,,0.02704848485,-0.03246292714
312.869,0.40493,-0.03512,,,,,0.02454121212,-0.03773909306
313.369,0.36297,-0.03354,,,,,0.02199818182,-0.0360412637
313.869,0.32145,-0.03587,,,,,0.01948181818,-0.03854502472
314.369,0.28003,-0.04045,,,,,0.01697151515,-0.0434665807
314.869,0.23781,-0.03897,,,,,0.01441272727,-0.0418762089
315.369,0.19646,-0.04101,,,,,0.01190666667,-0.044068343
315.869,0.15485,-0.04304,,,,,0.009384848485,-0.04624973136
316.369,0.11299,-0.04347,,,,,0.006847878788,-0.04671179884
316.869,0.07145,-0.04489,,,,,0.00433030303,-0.04823769611
317.369,0.02962,-0.04746,,,,,0.001795151515,-0.05099935525
317.728,-0.0001,-0.04764,,,,,-0.000006060606061,-0.05119277885
318.129,0.02836,-0.04235,,,,,0.001718787879,-0.04550827423
318.629,0.06957,-0.04042,,,,,0.004216363636,-0.04343434343
319.129,0.11166,-0.03856,,,,,0.006767272727,-0.04143563292
319.629,0.15342,-0.03534,,,,,0.009298181818,-0.03797549968
320.129,0.19466,-0.03465,,,,,0.01179757576,-0.03723404255
320.629,0.23682,-0.03126,,,,,0.01435272727,-0.03359123146
321.129,0.27821,-0.02701,,,,,0.01686121212,-0.02902428541
321.629,0.31997,-0.02778,,,,,0.01939212121,-0.02985170858
322.129,0.36171,-0.02564,,,,,0.02192181818,-0.02755211691
322.629,0.40302,-0.02197,,,,,0.02442545455,-0.02360842467
323.129,0.44517,-0.02226,,,,,0.02698,-0.02392005158
323.629,0.4867,-0.01803,,,,,0.0294969697,-0.01937459703
324.129,0.52801,-0.01838,,,,,0.03200060606,-0.01975069847
324.629,0.57018,-0.01541,,,,,0.03455636364,-0.01655920911
325.129,0.61158,-0.01544,,,,,0.03706545455,-0.01659144638
325.629,0.65313,-0.01223,,,,,0.03958363636,-0.01314205889
326.129,0.69518,-0.01108,,,,,0.04213212121,-0.01190629701
326.629,0.73641,-0.00999,,,,,0.04463090909,-0.01073500967
327.129,0.77841,-0.00715,,,,,0.04717636364,-0.00768321513
327.629,0.82005,-0.0077,,,,,0.0497,-0.008274231678
328.129,0.86132,-0.00461,,,,,0.05220121212,-0.004953793252
328.629,0.90343,-0.00491,,,,,0.05475333333,-0.005276165914
329.129,0.94505,-0.00349,,,,,0.05727575758,-0.003750268644
329.629,0.98648,-0.00083,,,,,0.05978666667,-0.0008918977004
330.129,1.02839,0.002,,,,,0.06232666667,0.002149151085
330.629,1.06977,0.00315,,,,,0.06483454545,0.003384912959
331.129,1.11173,0.00402,,,,,0.06737757576,0.004319793681
331.629,1.15334,0.00631,,,,,0.06989939394,0.006780571674
332.129,1.1946,0.0069,,,,,0.0724,0.007414571244
332.629,1.23687,0.00834,,,,,0.07496181818,0.008961960026
333.129,1.27831,0.01048,,,,,0.07747333333,0.01126155169
333.629,1.31977,0.01183,,,,,0.07998606061,0.01271222867
334.129,1.36182,0.01354,,,,,0.08253454545,0.01454975285
334.629,1.40313,0.01507,,,,,0.08503818182,0.01619385343
335.129,1.44486,0.01674,,,,,0.08756727273,0.01798839458
335.629,1.48682,0.01597,,,,,0.09011030303,0.01716097142
336.129,1.528,0.01963,,,,,0.09260606061,0.0210939179
336.629,1.57006,0.01749,,,,,0.09515515152,0.01879432624
337.129,1.61173,0.01907,,,,,0.09768060606,0.0204921556
337.587,1.65005,0.0209,,,,,0.1000030303,0.02245862884
337.889,1.62991,0.02009,,,,,0.09878242424,0.02158822265
338.389,1.58829,0.01673,,,,,0.09626,0.01797764883
338.889,1.54623,0.00972,,,,,0.09371090909,0.01044487427
339.389,1.50487,0.01013,,,,,0.09120424242,0.01088545025
339.889,1.46319,0.0061,,,,,0.08867818182,0.00655491081
340.389,1.42131,0.00252,,,,,0.08614,0.002707930368
340.889,1.37987,0.00314,,,,,0.08362848485,0.003374167204
341.389,1.33803,-0.00036,,,,,0.08109272727,-0.0003868471954
341.889,1.29643,-0.00128,,,,,0.07857151515,-0.001375456695
342.389,1.25507,-0.00506,,,,,0.07606484848,-0.005437352246
342.889,1.21285,-0.00461,,,,,0.07350606061,-0.004953793252
343.389,1.17153,-0.00744,,,,,0.07100181818,-0.007994842037
343.889,1.12996,-0.0084,,,,,0.06848242424,-0.009026434558
344.389,1.08795,-0.01131,,,,,0.06593636364,-0.01215344939
344.889,1.04645,-0.01316,,,,,0.06342121212,-0.01414141414
345.389,1.00482,-0.01263,,,,,0.06089818182,-0.0135718891
345.889,0.96308,-0.0147,,,,,0.05836848485,-0.01579626048
346.389,0.92154,-0.01722,,,,,0.05585090909,-0.01850419084
346.889,0.87959,-0.01769,,,,,0.05330848485,-0.01900924135
347.389,0.8382,-0.02109,,,,,0.0508,-0.02266279819
347.889,0.79669,-0.02197,,,,,0.04828424242,-0.02360842467
348.389,0.75445,-0.02242,,,,,0.04572424242,-0.02409198367
348.889,0.71324,-0.02579,,,,,0.04322666667,-0.02771330325
349.389,0.67151,-0.0273,,,,,0.04069757576,-0.02933591231
349.889,0.6296,-0.02836,,,,,0.03815757576,-0.03047496239
350.389,0.5882,-0.0289,,,,,0.03564848485,-0.03105523318
350.889,0.5464,-0.03077,,,,,0.03311515152,-0.03306468945
351.389,0.50469,-0.03082,,,,,0.03058727273,-0.03311841822
351.889,0.46333,-0.03436,,,,,0.02808060606,-0.03692241565
352.389,0.42122,-0.03243,,,,,0.02552848485,-0.03484848485
352.889,0.37978,-0.03486,,,,,0.0230169697,-0.03745970342
353.389,0.33823,-0.03761,,,,,0.02049878788,-0.04041478616
353.889,0.29627,-0.03735,,,,,0.01795575758,-0.04013539652
354.389,0.25481,-0.03973,,,,,0.0154430303,-0.04269288631
354.889,0.21302,-0.04126,,,,,0.01291030303,-0.04433698689
355.389,0.1715,-0.04416,,,,,0.01039393939,-0.04745325596
355.889,0.12992,-0.0448,,,,,0.007873939394,-0.04814098431
356.389,0.08789,-0.04535,,,,,0.005326666667,-0.04873200086
356.889,0.04651,-0.04637,,,,,0.002818787879,-0.04982806791
357.389,0.00499,-0.04898,,,,,0.0003024242424,-0.05263271008
357.65,0.011,-0.04504,,,,,0.0006666666667,-0.04839888244
358.15,0.05336,-0.04137,,,,,0.003233939394,-0.0444551902
358.65,0.0949,-0.03857,,,,,0.005751515152,-0.04144637868
359.15,0.13648,-0.03655,,,,,0.008271515152,-0.03927573608
359.65,0.17835,-0.03508,,,,,0.01080909091,-0.03769611004
360.15,0.21973,-0.03127,,,,,0.0133169697,-0.03360197722
360.65,0.26171,-0.03144,,,,,0.01586121212,-0.03378465506
361.15,0.30329,-0.03011,,,,,0.01838121212,-0.03235546959
361.65,0.34464,-0.02555,,,,,0.02088727273,-0.02745540511
362.15,0.38677,-0.02475,,,,,0.02344060606,-0.02659574468
362.65,0.42814,-0.02469,,,,,0.02594787879,-0.02653127015
363.15,0.46978,-0.02174,,,,,0.02847151515,-0.0233612723
363.65,0.51175,-0.02266,,,,,0.03101515152,-0.0243498818
364.15,0.55294,-0.01682,,,,,0.03351151515,-0.01807436063
364.65,0.59492,-0.01624,,,,,0.03605575758,-0.01745110681
365.15,0.6367,-0.01436,,,,,0.03858787879,-0.01543090479
365.65,0.67785,-0.01181,,,,,0.04108181818,-0.01269073716
366.15,0.7201,-0.01053,,,,,0.04364242424,-0.01131528046
366.65,0.7617,-0.00816,,,,,0.04616363636,-0.008768536428
367.15,0.80303,-0.00685,,,,,0.04866848485,-0.007360842467
367.65,0.84502,-0.00456,,,,,0.05121333333,-0.004900064475
368.15,0.88647,-0.00375,,,,,0.05372545455,-0.004029658285
368.65,0.92828,-0.00218,,,,,0.05625939394,-0.002342574683
369.15,0.97002,-0.00144,,,,,0.05878909091,-0.001547388781
369.65,1.01125,-0.00012,,,,,0.06128787879,-0.0001289490651
370.15,1.05341,0.00211,,,,,0.0638430303,0.002267354395
370.65,1.09496,0.00353,,,,,0.06636121212,0.003793251666
371.15,1.13624,0.00432,,,,,0.0688630303,0.004642166344
371.65,1.17844,0.00506,,,,,0.07142060606,0.005437352246
372.15,1.2198,0.00649,,,,,0.07392727273,0.006973995272
372.65,1.26149,0.00865,,,,,0.07645393939,0.009295078444
373.15,1.30334,0.01122,,,,,0.07899030303,0.01205673759
373.65,1.34468,0.01053,,,,,0.08149575758,0.01131528046
374.15,1.38671,0.01334,,,,,0.0840430303,0.01433483774
374.65,1.4284,0.01321,,,,,0.08656969697,0.01419514292
375.15,1.46965,0.01611,,,,,0.08906969697,0.01731141199
375.65,1.5117,0.01821,,,,,0.09161818182,0.01956802063
376.15,1.55327,0.01835,,,,,0.09413757576,0.01971846121
376.65,1.59477,0.02029,,,,,0.09665272727,0.02180313776
377.15,1.63671,0.02217,,,,,0.09919454545,0.02382333978
377.411,1.64739,0.02303,,,,,0.09984181818,0.02474747475
377.911,1.60457,0.01665,,,,,0.09724666667,0.01789168279
378.411,1.56326,0.01243,,,,,0.0947430303,0.013356974
378.911,1.52148,0.00925,,,,,0.09221090909,0.00993982377
379.411,1.4797,0.0069,,,,,0.08967878788,0.007414571244
379.911,1.43841,0.00483,,,,,0.08717636364,0.005190199871
380.411,1.39625,0.00329,,,,,0.08462121212,0.003535353535
380.911,1.3548,0.00199,,,,,0.08210909091,0.00213840533
381.411,1.31336,-0.00292,,,,,0.07959757576,-0.003137760585
381.911,1.27122,-0.00361,,,,,0.07704363636,-0.003879217709
382.411,1.22977,-0.00615,,,,,0.07453151515,-0.006608639587
382.911,1.18824,-0.00934,,,,,0.07201454545,-0.01003653557
383.411,1.14634,-0.01006,,,,,0.06947515152,-0.01081022996
383.911,1.1049,-0.01181,,,,,0.06696363636,-0.01269073716
384.411,1.06304,-0.01159,,,,,0.06442666667,-0.01245433054
384.911,1.02153,-0.01414,,,,,0.06191090909,-0.01519449817
385.411,0.97999,-0.01601,,,,,0.05939333333,-0.01720395444
385.911,0.93792,-0.01685,,,,,0.05684363636,-0.01810659789
386.411,0.89659,-0.01859,,,,,0.05433878788,-0.01997635934
386.911,0.85488,-0.02,,,,,0.05181090909,-0.02149151085
387.411,0.813,-0.02157,,,,,0.04927272727,-0.02317859446
387.911,0.77156,-0.02244,,,,,0.04676121212,-0.02411347518
388.411,0.7297,-0.02397,,,,,0.04422424242,-0.02575757576
388.911,0.68807,-0.02642,,,,,0.04170121212,-0.02839028584
389.411,0.64665,-0.02726,,,,,0.03919090909,-0.02929292929
389.911,0.6046,-0.02846,,,,,0.03664242424,-0.03058241994
390.411,0.56318,-0.03162,,,,,0.03413212121,-0.03397807866
390.911,0.52167,-0.03192,,,,,0.03161636364,-0.03430045132
391.411,0.47961,-0.03449,,,,,0.02906727273,-0.03706211047
391.911,0.43816,-0.03524,,,,,0.02655515152,-0.03786804212
392.411,0.3965,-0.03837,,,,,0.02403030303,-0.04123146357
392.911,0.35482,-0.03895,,,,,0.02150424242,-0.04185471739
393.411,0.31327,-0.04031,,,,,0.01898606061,-0.04331614012
393.911,0.27124,-0.04022,,,,,0.01643878788,-0.04321942833
394.411,0.22989,-0.04254,,,,,0.01393272727,-0.04571244358
394.911,0.18836,-0.04214,,,,,0.01141575758,-0.04528261337
395.411,0.14616,-0.04478,,,,,0.008858181818,-0.0481194928
395.911,0.10488,-0.04703,,,,,0.006356363636,-0.05053728777
396.411,0.06326,-0.04981,,,,,0.003833939394,-0.05352460778
396.911,0.02126,-0.04897,,,,,0.001288484848,-0.05262196432
397.17,-0.00002,-0.04701,,,,,-0.000001212121212,-0.05051579626