File: mechanical/hysteresis/databak/hmwg_hysteresis - conductive_3.csv
Time,Extension,Load,Length,Width,Thickness,CS Area,Strain,Stress
(s),(mm),(N),(mm),(mm),(mm),(mm^2),(mm/mm),(MPa)
0,0,-0.05333,16.5,2.82,0.29,0.8178,0,-0.06521154316
0.5,0.03908,0.06904,,,,,0.002368484848,0.08442161898
1,0.08072,0.12431,,,,,0.004892121212,0.1520053803
1.5,0.12203,0.16039,,,,,0.007395757576,0.1961237466
2,0.16415,0.18782,,,,,0.009948484848,0.2296649548
2.5,0.20575,0.20994,,,,,0.01246969697,0.2567131328
3,0.2472,0.22288,,,,,0.01498181818,0.2725360724
3.5,0.28907,0.24095,,,,,0.01751939394,0.2946319393
4,0.3305,0.25307,,,,,0.02003030303,0.3094521888
4.5,0.3724,0.26279,,,,,0.02256969697,0.3213377354
5,0.41397,0.27432,,,,,0.02508909091,0.3354365371
5.5,0.45526,0.28232,,,,,0.02759151515,0.3452188799
6,0.49755,0.29372,,,,,0.03015454545,0.3591587185
6.5,0.53895,0.30195,,,,,0.03266363636,0.3692223037
7,0.58044,0.30977,,,,,0.03517818182,0.3787845439
7.5,0.62249,0.3209,,,,,0.03772666667,0.3923942284
8,0.66387,0.32482,,,,,0.04023454545,0.3971875764
8.5,0.7056,0.32691,,,,,0.04276363636,0.3997432135
9,0.74752,0.33505,,,,,0.04530424242,0.4096967474
9.5,0.78868,0.33914,,,,,0.04779878788,0.4146979702
10,0.83073,0.3455,,,,,0.05034727273,0.4224749327
10.5,0.87245,0.35246,,,,,0.05287575758,0.430985571
11,0.91374,0.35468,,,,,0.05537818182,0.4337001712
11.5,0.95575,0.36294,,,,,0.05792424242,0.4438004402
12,0.99725,0.36632,,,,,0.06043939394,0.4479334801
12.5,1.03892,0.36858,,,,,0.06296484848,0.4506969919
13,1.08068,0.37591,,,,,0.06549575758,0.4596600636
13.5,1.12199,0.37829,,,,,0.06799939394,0.4625703106
14,1.16407,0.38179,,,,,0.07054969697,0.4668500856
14.5,1.20574,0.38822,,,,,0.07307515152,0.4747126437
15,1.24696,0.38869,,,,,0.07557333333,0.4752873563
15.5,1.28916,0.39538,,,,,0.07813090909,0.4834678405
16,1.33065,0.39861,,,,,0.08064545455,0.4874174615
16.5,1.37213,0.39897,,,,,0.08315939394,0.4878576669
17,1.41412,0.40588,,,,,0.08570424242,0.4963071656
17.5,1.45555,0.41067,,,,,0.08821515152,0.5021643434
18,1.4974,0.41192,,,,,0.09075151515,0.5036928344
18.5,1.53906,0.41517,,,,,0.09327636364,0.5076669112
19,1.58035,0.4168,,,,,0.09577878788,0.5096600636
19.5,1.62244,0.42168,,,,,0.09832969697,0.5156272927
19.836,1.65015,0.42416,,,,,0.1000090909,0.518659819
20.237,1.6215,0.23471,,,,,0.09827272727,0.2870017119
20.737,1.58009,0.10551,,,,,0.0957630303,0.1290168745
21.237,1.53862,0.01597,,,,,0.09324969697,0.01952800196
21.737,1.4965,-0.05984,,,,,0.0906969697,-0.07317192468
22.237,1.45505,-0.11919,,,,,0.08818484848,-0.1457446809
22.737,1.41348,-0.16696,,,,,0.08566545455,-0.2041574957
23.237,1.37168,-0.21484,,,,,0.08313212121,-0.2627048178
23.737,1.33021,-0.25296,,,,,0.08061878788,-0.3093176816
24.237,1.28825,-0.28847,,,,,0.07807575758,-0.352739056
24.737,1.24681,-0.32042,,,,,0.07556424242,-0.3918072878
25.237,1.20524,-0.34947,,,,,0.07304484848,-0.4273294204
25.737,1.16318,-0.37966,,,,,0.07049575758,-0.4642455368
26.237,1.12185,-0.4024,,,,,0.06799090909,-0.4920518464
26.737,1.08008,-0.42547,,,,,0.06545939394,-0.5202616777
27.237,1.03825,-0.4502,,,,,0.06292424242,-0.5505013451
27.737,0.99689,-0.47002,,,,,0.06041757576,-0.5747370995
28.237,0.95494,-0.48951,,,,,0.05787515152,-0.5985693324
28.737,0.91338,-0.50863,,,,,0.05535636364,-0.6219491318
29.237,0.87196,-0.52315,,,,,0.05284606061,-0.6397040841
29.737,0.82987,-0.5433,,,,,0.05029515152,-0.6643433602
30.237,0.78845,-0.5572,,,,,0.04778484848,-0.681340181
30.737,0.7469,-0.57415,,,,,0.04526666667,-0.7020665199
31.237,0.7049,-0.58649,,,,,0.04272121212,-0.7171557838
31.737,0.66347,-0.59997,,,,,0.04021030303,-0.7336390315
32.237,0.62169,-0.61452,,,,,0.03767818182,-0.7514306676
32.737,0.58011,-0.62794,,,,,0.03515818182,-0.7678405478
33.237,0.5386,-0.63977,,,,,0.03264242424,-0.7823061873
33.737,0.49648,-0.65256,,,,,0.03008969697,-0.797945708
34.237,0.45517,-0.66429,,,,,0.02758606061,-0.8122890682
34.737,0.41358,-0.67364,,,,,0.02506545455,-0.8237221815
35.237,0.37144,-0.68661,,,,,0.02251151515,-0.8395818048
35.737,0.33013,-0.6952,,,,,0.02000787879,-0.8500855955
36.237,0.2885,-0.7048,,,,,0.01748484848,-0.8618244069
36.737,0.24659,-0.71309,,,,,0.01494484848,-0.8719613597
37.237,0.20523,-0.71549,,,,,0.01243818182,-0.8748960626
37.737,0.16332,-0.71653,,,,,0.009898181818,-0.8761677672
38.237,0.12174,-0.71567,,,,,0.007378181818,-0.8751161653
38.737,0.08026,-0.71563,,,,,0.004864242424,-0.8750672536
39.237,0.03818,-0.7162,,,,,0.002313939394,-0.8757642455
39.701,-0.00006,-0.71408,,,,,-0.000003636363636,-0.8731719247
40.003,0.01956,-0.70981,,,,,0.001185454545,-0.8679505992
40.503,0.06181,-0.69427,,,,,0.003746060606,-0.8489483981
41.003,0.10337,-0.61014,,,,,0.006264848485,-0.7460748349
41.503,0.14471,-0.54709,,,,,0.00877030303,-0.6689777452
42.003,0.18681,-0.49992,,,,,0.01132181818,-0.611298606
42.503,0.22825,-0.46175,,,,,0.01383333333,-0.5646246026
43.003,0.26985,-0.42975,,,,,0.01635454545,-0.5254952311
43.503,0.3118,-0.39476,,,,,0.0188969697,-0.482709709
44.003,0.35306,-0.36798,,,,,0.02139757576,-0.4499633162
44.503,0.395,-0.34101,,,,,0.02393939394,-0.4169845928
45.003,0.43681,-0.31377,,,,,0.02647333333,-0.3836757153
45.503,0.47798,-0.29053,,,,,0.02896848485,-0.3552580093
46.003,0.52016,-0.26534,,,,,0.03152484848,-0.3244558572
46.503,0.56175,-0.24147,,,,,0.03404545455,-0.2952677916
47.003,0.60316,-0.21855,,,,,0.03655515152,-0.2672413793
47.503,0.64512,-0.19561,,,,,0.03909818182,-0.2391905111
48.003,0.68657,-0.17134,,,,,0.04161030303,-0.2095133284
48.503,0.7284,-0.149,,,,,0.04414545455,-0.182196136
49.003,0.77004,-0.1263,,,,,0.04666909091,-0.1544387381
49.503,0.81134,-0.10629,,,,,0.04917212121,-0.129970653
50.003,0.85349,-0.0832,,,,,0.05172666667,-0.1017363659
50.503,0.89496,-0.06112,,,,,0.05424,-0.07473709954
51.003,0.93638,-0.04103,,,,,0.05675030303,-0.050171191
51.503,0.97852,-0.01771,,,,,0.05930424242,-0.02165566153
52.003,1.01981,0.00238,,,,,0.06180666667,0.002910247004
52.503,1.06162,0.02234,,,,,0.06434060606,0.02731719247
53.003,1.10345,0.04413,,,,,0.06687575758,0.05396184886
53.503,1.14468,0.06326,,,,,0.06937454545,0.07735387625
54.003,1.18677,0.08529,,,,,0.07192545455,0.1042920029
54.503,1.22846,0.10674,,,,,0.07445212121,0.1305209098
55.003,1.2697,0.12368,,,,,0.07695151515,0.1512350208
55.503,1.31176,0.1459,,,,,0.07950060606,0.1784054781
56.003,1.35331,0.16414,,,,,0.08201878788,0.2007092199
56.503,1.39492,0.18217,,,,,0.08454060606,0.2227561751
57.003,1.43672,0.20251,,,,,0.08707393939,0.2476277819
57.503,1.47803,0.21783,,,,,0.08957757576,0.2663609685
58.003,1.52007,0.23513,,,,,0.09212545455,0.2875152849
58.503,1.56171,0.25189,,,,,0.09464909091,0.3080092932
59.003,1.60292,0.26511,,,,,0.09714666667,0.3241746148
59.503,1.64518,0.28096,,,,,0.09970787879,0.3435558816
59.768,1.63882,0.18229,,,,,0.09932242424,0.2229029102
60.268,1.59679,0.03714,,,,,0.09677515152,0.04541452678
60.768,1.55504,-0.05726,,,,,0.09424484848,-0.0700171191
61.268,1.51349,-0.12622,,,,,0.09172666667,-0.1543409146
61.768,1.47166,-0.18362,,,,,0.08919151515,-0.2245292247
62.268,1.4301,-0.23287,,,,,0.08667272727,-0.284751773
62.768,1.38856,-0.27312,,,,,0.08415515152,-0.3339691856
63.268,1.34644,-0.31418,,,,,0.08160242424,-0.3841770604
63.768,1.30516,-0.34588,,,,,0.07910060606,-0.422939594
64.268,1.26354,-0.37676,,,,,0.07657818182,-0.4606994375
64.768,1.22146,-0.40784,,,,,0.07402787879,-0.4987038396
65.268,1.18022,-0.43231,,,,,0.07152848485,-0.5286255808
65.768,1.13828,-0.45683,,,,,0.06898666667,-0.5586084617
66.268,1.09666,-0.47982,,,,,0.06646424242,-0.5867204696
66.768,1.0552,-0.50042,,,,,0.06395151515,-0.6119100024
67.268,1.0132,-0.51947,,,,,0.06140606061,-0.6352042064
67.768,0.9717,-0.53765,,,,,0.05889090909,-0.6574345806
68.268,0.93028,-0.55501,,,,,0.05638060606,-0.6786622646
68.768,0.88817,-0.57394,,,,,0.05382848485,-0.7018097334
69.268,0.84676,-0.58704,,,,,0.05131878788,-0.7178283199
69.768,0.80512,-0.60165,,,,,0.04879515152,-0.7356933236
70.268,0.76333,-0.61675,,,,,0.04626242424,-0.7541574957
70.768,0.72183,-0.63053,,,,,0.04374727273,-0.7710075813
71.268,0.67984,-0.64522,,,,,0.04120242424,-0.7889704084
71.768,0.63848,-0.65876,,,,,0.03869575758,-0.8055270237
72.268,0.59681,-0.66997,,,,,0.03617030303,-0.8192345317
72.768,0.55481,-0.68376,,,,,0.03362484848,-0.8360968452
73.268,0.51346,-0.69414,,,,,0.03111878788,-0.8487894351
73.768,0.47178,-0.70377,,,,,0.02859272727,-0.8605649303
74.268,0.42986,-0.71446,,,,,0.02605212121,-0.873636586
74.768,0.38856,-0.71792,,,,,0.02354909091,-0.8778674493
75.268,0.34664,-0.71711,,,,,0.02100848485,-0.876876987
75.768,0.30507,-0.71653,,,,,0.01848909091,-0.8761677672
76.268,0.26367,-0.71644,,,,,0.01598,-0.8760577158
76.768,0.22152,-0.71512,,,,,0.01342545455,-0.8744436292
77.268,0.1801,-0.71594,,,,,0.01091515152,-0.8754463194
77.768,0.13852,-0.71635,,,,,0.008395151515,-0.8759476645
78.268,0.09658,-0.71617,,,,,0.005853333333,-0.8757275618
78.768,0.05507,-0.71522,,,,,0.003337575758,-0.8745659085
79.268,0.01334,-0.71457,,,,,0.0008084848485,-0.8737710932
79.534,0.00224,-0.71495,,,,,0.0001357575758,-0.8742357545
80.034,0.04488,-0.71287,,,,,0.00272,-0.8716923453
80.534,0.0865,-0.70978,,,,,0.005242424242,-0.8679139154
81.034,0.12842,-0.70204,,,,,0.007783030303,-0.8584494987
81.534,0.16972,-0.66369,,,,,0.01028606061,-0.8115553925
82.034,0.21173,-0.58861,,,,,0.01283212121,-0.7197481047
82.534,0.25342,-0.53894,,,,,0.01535878788,-0.6590119834
83.034,0.29461,-0.50199,,,,,0.01785515152,-0.6138297872
83.534,0.33669,-0.4677,,,,,0.02040545455,-0.5719002201
84.034,0.37838,-0.43728,,,,,0.02293212121,-0.5347028613
84.534,0.41969,-0.41118,,,,,0.02543575758,-0.5027879677
85.034,0.46184,-0.38257,,,,,0.02799030303,-0.467803864
85.534,0.50318,-0.35934,,,,,0.03049575758,-0.4393983859
86.034,0.54496,-0.33678,,,,,0.03302787879,-0.411812179
86.534,0.58671,-0.31179,,,,,0.03555818182,-0.3812545855
87.034,0.62803,-0.28937,,,,,0.03806242424,-0.3538395696
87.534,0.67018,-0.26503,,,,,0.0406169697,-0.3240767914
88.034,0.7117,-0.24374,,,,,0.04313333333,-0.2980435314
88.534,0.75302,-0.22262,,,,,0.04563757576,-0.2722181462
89.034,0.79515,-0.19931,,,,,0.04819090909,-0.2437148447
89.534,0.83662,-0.17776,,,,,0.05070424242,-0.2173636586
90.034,0.87814,-0.15948,,,,,0.05322060606,-0.1950110051
90.534,0.92016,-0.13591,,,,,0.05576727273,-0.1661897775
91.034,0.96137,-0.11691,,,,,0.05826484848,-0.1429567131
91.534,1.00345,-0.09607,,,,,0.06081515152,-0.11747371
92.034,1.04508,-0.07459,,,,,0.06333818182,-0.09120811934
92.534,1.08638,-0.05425,,,,,0.06584121212,-0.06633651259
93.034,1.12846,-0.03182,,,,,0.06839151515,-0.03890926877
93.534,1.17004,-0.01107,,,,,0.07091151515,-0.01353631695
94.034,1.2115,0.00739,,,,,0.07342424242,0.009036439227
94.534,1.25337,0.03138,,,,,0.07596181818,0.03837123991
95.034,1.29479,0.05131,,,,,0.07847212121,0.06274150159
95.534,1.33672,0.07122,,,,,0.08101333333,0.08708730741
96.034,1.37835,0.09291,,,,,0.08353636364,0.1136096845
96.534,1.4196,0.11021,,,,,0.08603636364,0.134764001
97.034,1.4619,0.13286,,,,,0.0886,0.1624602592
97.534,1.50332,0.15338,,,,,0.09111030303,0.1875519687
98.034,1.54476,0.17034,,,,,0.09362181818,0.2082905356
98.534,1.5868,0.19242,,,,,0.09616969697,0.2352898019
99.034,1.62821,0.21011,,,,,0.09867939394,0.2569210076
99.299,1.65022,0.2187,,,,,0.1000133333,0.2674247982
99.799,1.61343,0.03124,,,,,0.09778363636,0.03820004891
100.299,1.5719,-0.07096,,,,,0.09526666667,-0.08676938127
100.799,1.52983,-0.14539,,,,,0.0927169697,-0.1777818538
101.299,1.48846,-0.20205,,,,,0.09020969697,-0.2470652971
101.799,1.44684,-0.25127,,,,,0.08768727273,-0.3072511617
102.299,1.40489,-0.29522,,,,,0.08514484848,-0.3609929078
102.799,1.3635,-0.33026,,,,,0.08263636364,-0.4038395696
103.299,1.3217,-0.36537,,,,,0.0801030303,-0.4467718269
103.799,1.28003,-0.39702,,,,,0.07757757576,-0.4854732208
104.299,1.23866,-0.42229,,,,,0.07507030303,-0.5163731964
104.799,1.19651,-0.44812,,,,,0.07251575758,-0.5479579359
105.299,1.15511,-0.47343,,,,,0.07000666667,-0.5789068232
105.799,1.11363,-0.49343,,,,,0.06749272727,-0.6033626804
106.299,1.07158,-0.51526,,,,,0.06494424242,-0.6300562485
106.799,1.03012,-0.53319,,,,,0.06243151515,-0.6519809244
107.299,0.98848,-0.55136,,,,,0.05990787879,-0.6741990707
107.799,0.94663,-0.57024,,,,,0.05737151515,-0.6972853999
108.299,0.90512,-0.5863,,,,,0.05485575758,-0.7169234532
108.799,0.86325,-0.60288,,,,,0.05231818182,-0.7371973588
109.299,0.8218,-0.61788,,,,,0.04980606061,-0.7555392517
109.799,0.78025,-0.6329,,,,,0.04728787879,-0.7739056004
110.299,0.73807,-0.64899,,,,,0.04473151515,-0.7935803375
110.799,0.69687,-0.66062,,,,,0.04223454545,-0.8078014184
111.299,0.65518,-0.67248,,,,,0.03970787879,-0.8223037417
111.799,0.61318,-0.68583,,,,,0.03716242424,-0.8386280264
112.299,0.57182,-0.69529,,,,,0.03465575758,-0.8501956469
112.799,0.53011,-0.70617,,,,,0.03212787879,-0.8634996332
113.299,0.48828,-0.71512,,,,,0.02959272727,-0.8744436292
113.799,0.44699,-0.71668,,,,,0.02709030303,-0.8763511861
114.299,0.4049,-0.71603,,,,,0.02453939394,-0.8755563708
114.799,0.3634,-0.71603,,,,,0.02202424242,-0.8755563708
115.299,0.3219,-0.71649,,,,,0.01950909091,-0.8761188555
115.799,0.27986,-0.7164,,,,,0.01696121212,-0.8760088041
116.299,0.23844,-0.71599,,,,,0.01445090909,-0.875507459
116.799,0.19667,-0.71581,,,,,0.01191939394,-0.8752873563
117.299,0.15511,-0.71639,,,,,0.009400606061,-0.8759965762
117.799,0.11343,-0.71612,,,,,0.006874545455,-0.8756664221
118.299,0.07153,-0.71524,,,,,0.004335151515,-0.8745903644
118.799,0.0301,-0.71596,,,,,0.001824242424,-0.8754707753
119.164,-0.00015,-0.71467,,,,,-0.000009090909091,-0.8738933725
119.565,0.02832,-0.7149,,,,,0.001716363636,-0.8741746148
120.065,0.07015,-0.71092,,,,,0.004251515152,-0.8693078992
120.565,0.11129,-0.70946,,,,,0.006744848485,-0.8675226217
121.065,0.15342,-0.70518,,,,,0.009298181818,-0.8622890682
121.565,0.1951,-0.68946,,,,,0.01182424242,-0.8430667645
122.065,0.23633,-0.62865,,,,,0.0143230303,-0.7687087307
122.565,0.27843,-0.57074,,,,,0.01687454545,-0.6978967963
123.065,0.31998,-0.53018,,,,,0.01939272727,-0.6483003179
123.565,0.36155,-0.49653,,,,,0.02191212121,-0.6071533382
124.065,0.40342,-0.46539,,,,,0.02444969697,-0.5690755686
124.565,0.4448,-0.43834,,,,,0.02695757576,-0.5359990218
125.065,0.48678,-0.41277,,,,,0.02950181818,-0.5047322084
125.565,0.52835,-0.38723,,,,,0.03202121212,-0.4735020787
126.065,0.5697,-0.36406,,,,,0.03452727273,-0.4451699682
126.565,0.61184,-0.34055,,,,,0.03708121212,-0.4164221081
127.065,0.65319,-0.3167,,,,,0.03958727273,-0.3872584984
127.565,0.69483,-0.29867,,,,,0.04211090909,-0.3652115432
128.065,0.73683,-0.27236,,,,,0.04465636364,-0.333039863
128.565,0.77804,-0.25398,,,,,0.04715393939,-0.3105649303
129.065,0.82001,-0.23221,,,,,0.04969757576,-0.2839447298
129.565,0.8618,-0.20883,,,,,0.05223030303,-0.2553558327
130.065,0.90292,-0.18958,,,,,0.05472242424,-0.2318170702
130.565,0.9451,-0.16792,,,,,0.05727878788,-0.2053313769
131.065,0.98671,-0.14686,,,,,0.05980060606,-0.1795793593
131.565,1.02809,-0.12613,,,,,0.06230848485,-0.1542308633
132.065,1.07007,-0.10437,,,,,0.06485272727,-0.1276228907
132.565,1.11153,-0.08233,,,,,0.06736545455,-0.1006725361
133.065,1.15339,-0.06428,,,,,0.06990242424,-0.07860112497
133.565,1.19508,-0.04026,,,,,0.07242909091,-0.0492296405
134.065,1.23634,-0.02279,,,,,0.07492969697,-0.02786744925
134.565,1.27847,-0.00006,,,,,0.0774830303,-0.00007336757153
135.065,1.32003,0.02167,,,,,0.08000181818,0.02649792125
135.565,1.36131,0.04203,,,,,0.08250363636,0.05139398386
136.065,1.40353,0.06411,,,,,0.08506242424,0.07839325018
136.565,1.44489,0.08578,,,,,0.08756909091,0.1048911714
137.065,1.48657,0.10537,,,,,0.09009515152,0.1288456835
137.565,1.52837,0.12713,,,,,0.09262848485,0.1554536562
138.065,1.56974,0.14581,,,,,0.09513575758,0.1782954268
138.565,1.61174,0.16831,,,,,0.09768121212,0.2058082661
139.028,1.65003,0.18674,,,,,0.1000018182,0.2283443385
139.33,1.63031,0.05739,,,,,0.09880666667,0.07017608217
139.83,1.58813,-0.06238,,,,,0.09625030303,-0.07627781854
140.33,1.54685,-0.14058,,,,,0.09374848485,-0.1719002201
140.83,1.50512,-0.20235,,,,,0.09121939394,-0.247432135
141.33,1.46325,-0.25453,,,,,0.08868181818,-0.3112374664
141.83,1.42196,-0.29663,,,,,0.08617939394,-0.3627170457
142.33,1.37988,-0.33606,,,,,0.08362909091,-0.4109317682
142.83,1.3384,-0.37022,,,,,0.08111515152,-0.4527023722
143.33,1.29696,-0.40142,,,,,0.07860363636,-0.4908535094
143.83,1.25483,-0.43011,,,,,0.07605030303,-0.5259354365
144.33,1.21339,-0.45632,,,,,0.07353878788,-0.5579848374
144.83,1.17187,-0.48043,,,,,0.07102242424,-0.5874663732
145.33,1.12991,-0.50522,,,,,0.06847939394,-0.6177794082
145.83,1.08851,-0.52389,,,,,0.06597030303,-0.6406089508
146.33,1.04667,-0.5446,,,,,0.06343454545,-0.665932991
146.83,1.00509,-0.56327,,,,,0.06091454545,-0.6887625336
147.33,0.96354,-0.57828,,,,,0.05839636364,-0.7071166544
147.83,0.92151,-0.59603,,,,,0.05584909091,-0.7288212277
148.33,0.88019,-0.61071,,,,,0.05334484848,-0.7467718269
148.83,0.83849,-0.62572,,,,,0.05081757576,-0.7651259477
149.33,0.79653,-0.64071,,,,,0.04827454545,-0.7834556126
149.83,0.75516,-0.65415,,,,,0.04576727273,-0.7998899486
150.33,0.71338,-0.66789,,,,,0.04323515152,-0.8166911225
150.83,0.67169,-0.682,,,,,0.04070848485,-0.8339447298
151.33,0.63027,-0.69284,,,,,0.03819818182,-0.8471998044
151.83,0.58825,-0.70526,,,,,0.03565151515,-0.8623868917
152.33,0.54677,-0.71409,,,,,0.03313757576,-0.8731841526
152.83,0.50529,-0.7188,,,,,0.03062363636,-0.878943507
153.33,0.46317,-0.71919,,,,,0.02807090909,-0.8794203962
153.83,0.42176,-0.71711,,,,,0.02556121212,-0.876876987
154.33,0.38011,-0.71652,,,,,0.0230369697,-0.8761555393
154.83,0.33837,-0.71423,,,,,0.02050727273,-0.8733553436
155.33,0.29682,-0.71547,,,,,0.01798909091,-0.8748716067
155.83,0.2549,-0.71445,,,,,0.01544848485,-0.873624358
156.33,0.21347,-0.71641,,,,,0.01293757576,-0.876021032
156.83,0.17197,-0.71627,,,,,0.01042242424,-0.875849841
157.33,0.12976,-0.71641,,,,,0.007864242424,-0.876021032
157.83,0.08848,-0.71476,,,,,0.005362424242,-0.8740034238
158.33,0.04693,-0.71449,,,,,0.002844242424,-0.8736732697
158.83,0.00488,-0.71506,,,,,0.0002957575758,-0.8743702617
159.096,0.01126,-0.71522,,,,,0.0006824242424,-0.8745659085
159.596,0.05292,-0.71247,,,,,0.003207272727,-0.8712032282
160.096,0.09501,-0.70973,,,,,0.005758181818,-0.8678527757
160.596,0.13664,-0.70883,,,,,0.008281212121,-0.8667522622
161.096,0.17812,-0.70543,,,,,0.01079515152,-0.8625947664
161.596,0.22015,-0.69513,,,,,0.01334242424,-0.85
162.096,0.2614,-0.64663,,,,,0.01584242424,-0.7906945463
162.596,0.30342,-0.58747,,,,,0.01838909091,-0.7183541208
163.096,0.34506,-0.54437,,,,,0.02091272727,-0.6656517486
163.596,0.38634,-0.51068,,,,,0.02341454545,-0.6244558572
164.096,0.42852,-0.47942,,,,,0.02597090909,-0.5862313524
164.596,0.47001,-0.45253,,,,,0.02848545455,-0.5533504524
165.096,0.51142,-0.42581,,,,,0.03099515152,-0.5206774272
165.596,0.55349,-0.40212,,,,,0.03354484848,-0.4917094644
166.096,0.59482,-0.37818,,,,,0.03604969697,-0.4624358034
166.596,0.63655,-0.35761,,,,,0.03857878788,-0.4372829543
167.096,0.67843,-0.33345,,,,,0.0411169697,-0.4077402788
167.596,0.71961,-0.31379,,,,,0.04361272727,-0.3837001712
168.096,0.76181,-0.29091,,,,,0.04617030303,-0.3557226706
168.596,0.80339,-0.26857,,,,,0.04869030303,-0.3284054781
169.096,0.84472,-0.24897,,,,,0.05119515152,-0.3044387381
169.596,0.88681,-0.22583,,,,,0.05374606061,-0.2761433113
170.096,0.92833,-0.20431,,,,,0.05626242424,-0.249828809
170.596,0.96995,-0.18591,,,,,0.05878484848,-0.2273294204
171.096,1.01173,-0.16368,,,,,0.0613169697,-0.2001467351
171.596,1.0531,-0.1449,,,,,0.06382424242,-0.1771826853
172.096,1.09512,-0.12498,,,,,0.06637090909,-0.1528246515
172.596,1.13665,-0.10239,,,,,0.06888787879,-0.1252017608
173.096,1.17797,-0.08332,,,,,0.07139212121,-0.101883101
173.596,1.22021,-0.0603,,,,,0.07395212121,-0.07373440939
174.096,1.26157,-0.03897,,,,,0.07645878788,-0.04765223771
174.596,1.30316,-0.01941,,,,,0.07897939394,-0.02373440939
175.096,1.34514,0.00439,,,,,0.08152363636,0.005368060651
175.596,1.38639,0.02429,,,,,0.08402363636,0.02970163854
176.096,1.42835,0.04586,,,,,0.08656666667,0.05607728051
176.596,1.47015,0.06836,,,,,0.0891,0.08359011983
177.096,1.51133,0.08732,,,,,0.09159575758,0.1067742724
177.596,1.5534,0.10867,,,,,0.09414545455,0.1328809
178.096,1.59502,0.1311,,,,,0.09666787879,0.1603081438
178.596,1.63647,0.14947,,,,,0.09918,0.1827708486
178.861,1.64751,0.11206,,,,,0.09984909091,0.1370261678
179.361,1.60527,-0.04354,,,,,0.09728909091,-0.05324040108
179.861,1.5633,-0.13259,,,,,0.09474545455,-0.1621301052
180.361,1.52179,-0.19908,,,,,0.09222969697,-0.2434336023
180.861,1.48036,-0.25197,,,,,0.08971878788,-0.3081071167
181.361,1.43809,-0.29976,,,,,0.0871569697,-0.3665443874
181.861,1.39682,-0.3386,,,,,0.08465575758,-0.414037662
182.361,1.35524,-0.37185,,,,,0.08213575758,-0.4546955246
182.861,1.31332,-0.40648,,,,,0.07959515152,-0.4970408413
183.361,1.27181,-0.43214,,,,,0.07707939394,-0.528417706
183.861,1.23008,-0.45835,,,,,0.07455030303,-0.5604671069
184.361,1.18838,-0.4825,,,,,0.0720230303,-0.5899975544
184.861,1.1469,-0.50509,,,,,0.06950909091,-0.6176204451
185.361,1.10488,-0.52577,,,,,0.06696242424,-0.6429078014
185.861,1.06353,-0.5445,,,,,0.06445636364,-0.6658107117
186.361,1.02194,-0.56379,,,,,0.06193575758,-0.6893983859
186.861,0.97978,-0.58219,,,,,0.05938060606,-0.7118977745
187.361,0.9386,-0.59831,,,,,0.05688484848,-0.7316091954
187.861,0.89679,-0.6156,,,,,0.05435090909,-0.7527512839
188.361,0.85494,-0.63015,,,,,0.05181454545,-0.77054292
188.861,0.81352,-0.64473,,,,,0.04930424242,-0.7883712399
189.361,0.77164,-0.65736,,,,,0.04676606061,-0.8038151137
189.861,0.73004,-0.67093,,,,,0.04424484848,-0.8204084128
190.361,0.68866,-0.68358,,,,,0.0417369697,-0.8358767425
190.861,0.64652,-0.69546,,,,,0.0391830303,-0.8504035216
191.361,0.6051,-0.70785,,,,,0.03667272727,-0.8655539252
191.861,0.56356,-0.71413,,,,,0.03415515152,-0.8732330643
192.361,0.52165,-0.71864,,,,,0.03161515152,-0.8787478601
192.861,0.48017,-0.71701,,,,,0.02910121212,-0.8767547078
193.361,0.43831,-0.71604,,,,,0.02656424242,-0.8755685987
193.861,0.39688,-0.71644,,,,,0.02405333333,-0.8760577158
194.361,0.35519,-0.71657,,,,,0.02152666667,-0.8762166789
194.861,0.3132,-0.71503,,,,,0.01898181818,-0.8743335779
195.361,0.27183,-0.7156,,,,,0.01647454545,-0.8750305698
195.861,0.23022,-0.71623,,,,,0.01395272727,-0.8758009293
196.361,0.18811,-0.71503,,,,,0.01140060606,-0.8743335779
196.861,0.14689,-0.71491,,,,,0.008902424242,-0.8741868427
197.361,0.10507,-0.71469,,,,,0.006367878788,-0.8739178283
197.861,0.06337,-0.71374,,,,,0.003840606061,-0.8727561751
198.361,0.02196,-0.71458,,,,,0.001330909091,-0.8737833211
198.627,-0.00021,-0.71474,,,,,-0.00001272727273,-0.873978968
199.127,0.03676,-0.71329,,,,,0.002227878788,-0.8722059183
199.627,0.07824,-0.71007,,,,,0.004741818182,-0.8682685253
200.127,0.11997,-0.70974,,,,,0.007270909091,-0.8678650037
200.627,0.16177,-0.70816,,,,,0.009804242424,-0.865932991
201.127,0.2031,-0.70438,,,,,0.01230909091,-0.8613108339
201.627,0.24517,-0.69596,,,,,0.01485878788,-0.8510149181
202.127,0.28666,-0.6499,,,,,0.01737333333,-0.794693079
202.627,0.32811,-0.59256,,,,,0.01988545455,-0.7245781365
203.127,0.37012,-0.54926,,,,,0.02243151515,-0.6716312057
203.627,0.4114,-0.51726,,,,,0.02493333333,-0.6325018342
204.127,0.45328,-0.48749,,,,,0.02747151515,-0.5960992908
204.627,0.49513,-0.45674,,,,,0.03000787879,-0.5584984104
205.127,0.5363,-0.43445,,,,,0.0325030303,-0.5312423575
205.627,0.57837,-0.40923,,,,,0.03505272727,-0.5004035216
206.127,0.62011,-0.38557,,,,,0.03758242424,-0.4714722426
206.627,0.66132,-0.36538,,,,,0.04008,-0.4467840548
207.127,0.7035,-0.34211,,,,,0.04263636364,-0.418329665
207.627,0.745,-0.32081,,,,,0.04515151515,-0.3922841771
208.127,0.78655,-0.29981,,,,,0.04766969697,-0.366605527
208.627,0.8284,-0.2784,,,,,0.05020606061,-0.3404255319
209.127,0.86982,-0.25879,,,,,0.05271636364,-0.316446564
209.627,0.91179,-0.23842,,,,,0.05526,-0.2915382734
210.127,0.95339,-0.21743,,,,,0.05778121212,-0.2658718513
210.627,0.99466,-0.19959,,,,,0.06028242424,-0.2440572267
211.127,1.0368,-0.17673,,,,,0.06283636364,-0.216104182
211.627,1.07833,-0.15593,,,,,0.06535333333,-0.1906700905
212.127,1.11968,-0.13584,,,,,0.06785939394,-0.166104182
212.627,1.16185,-0.11256,,,,,0.07041515152,-0.1376375642
213.127,1.20315,-0.09366,,,,,0.07291818182,-0.1145267792
213.627,1.24501,-0.07285,,,,,0.07545515152,-0.08908045977
214.127,1.28676,-0.05148,,,,,0.07798545455,-0.06294937638
214.627,1.32803,-0.03261,,,,,0.08048666667,-0.03987527513
215.127,1.37013,-0.01192,,,,,0.08303818182,-0.01457569088
215.627,1.41177,0.01103,,,,,0.08556181818,0.01348740523
216.127,1.45314,0.02928,,,,,0.08806909091,0.03580337491
216.627,1.4951,0.05344,,,,,0.09061212121,0.06534605038
217.127,1.5366,0.07454,,,,,0.09312727273,0.0911469797
217.627,1.57829,0.09421,,,,,0.09565393939,0.1151993152
218.127,1.62003,0.11629,,,,,0.09818363636,0.1421985816
218.491,1.65015,0.13075,,,,,0.1000090909,0.1598801663
218.892,1.62149,-0.01997,,,,,0.09827212121,-0.02441917339
219.392,1.58011,-0.12047,,,,,0.09576424242,-0.1473098557
219.892,1.53862,-0.19197,,,,,0.09324969697,-0.2347395451
220.392,1.4965,-0.24892,,,,,0.0906969697,-0.3043775984
220.892,1.45505,-0.29402,,,,,0.08818484848,-0.3595255564
221.392,1.41349,-0.33425,,,,,0.08566606061,-0.4087185131
221.892,1.37169,-0.37122,,,,,0.08313272727,-0.4539251651
222.392,1.33023,-0.4011,,,,,0.08062,-0.4904622157
222.892,1.28826,-0.43168,,,,,0.07807636364,-0.5278552213
223.392,1.24683,-0.45896,,,,,0.07556545455,-0.5612130105
223.892,1.20526,-0.48147,,,,,0.07304606061,-0.5887380778
224.392,1.16319,-0.50594,,,,,0.07049636364,-0.618659819
224.892,1.12186,-0.52644,,,,,0.06799151515,-0.6437270726
225.392,1.0801,-0.54596,,,,,0.06546060606,-0.6675959892
225.892,1.03827,-0.56566,,,,,0.06292545455,-0.6916850086
226.392,0.9969,-0.58364,,,,,0.06041818182,-0.7136708242
226.892,0.95495,-0.59878,,,,,0.05787575758,-0.732183908
227.392,0.91341,-0.61668,,,,,0.05535818182,-0.7540719002
227.892,0.87197,-0.63126,,,,,0.05284666667,-0.7719002201
228.392,0.82987,-0.64715,,,,,0.05029515152,-0.7913303986
228.892,0.78845,-0.65927,,,,,0.04778484848,-0.8061506481
229.392,0.74693,-0.67286,,,,,0.04526848485,-0.822768403
229.892,0.70492,-0.68699,,,,,0.04272242424,-0.8400464661
230.392,0.66347,-0.6967,,,,,0.04021030303,-0.8519197848
230.892,0.62168,-0.70855,,,,,0.03767757576,-0.8664098802
231.392,0.58014,-0.71672,,,,,0.03516,-0.8764000978
231.892,0.5386,-0.71915,,,,,0.03264242424,-0.8793714845
232.392,0.49649,-0.71753,,,,,0.03009030303,-0.87739056
232.892,0.45518,-0.71637,,,,,0.02758666667,-0.8759721203
233.392,0.4136,-0.71624,,,,,0.02506666667,-0.8758131573
233.892,0.37145,-0.71366,,,,,0.02251212121,-0.8726583517
234.392,0.33012,-0.71428,,,,,0.02000727273,-0.8734164832
234.892,0.28851,-0.71511,,,,,0.01748545455,-0.8744314013
235.392,0.24661,-0.71551,,,,,0.01494606061,-0.8749205185
235.892,0.20525,-0.71507,,,,,0.01243939394,-0.8743824896
236.392,0.16329,-0.71353,,,,,0.009896363636,-0.8724993886
236.892,0.12176,-0.71347,,,,,0.007379393939,-0.872426021
237.392,0.0803,-0.71393,,,,,0.004866666667,-0.8729885057
237.892,0.03823,-0.7134,,,,,0.002316969697,-0.8723404255
238.356,-0.00006,-0.71334,,,,,-0.000003636363636,-0.872267058
238.658,0.01953,-0.71231,,,,,0.001183636364,-0.8710075813
239.158,0.06181,-0.71321,,,,,0.003746060606,-0.8721080949
239.658,0.10337,-0.71226,,,,,0.006264848485,-0.8709464417
240.158,0.1447,-0.71049,,,,,0.00876969697,-0.8687820983
240.658,0.18686,-0.70937,,,,,0.01132484848,-0.8674125703
241.158,0.22826,-0.7062,,,,,0.01383393939,-0.8635363169
241.658,0.26985,-0.69327,,,,,0.01635454545,-0.8477256053
242.158,0.31182,-0.64269,,,,,0.01889818182,-0.7858767425
242.658,0.35303,-0.58719,,,,,0.02139575758,-0.7180117388
243.158,0.395,-0.54824,,,,,0.02393939394,-0.670383957
243.658,0.43679,-0.51481,,,,,0.02647212121,-0.6295059917
244.158,0.47796,-0.4871,,,,,0.02896727273,-0.5956224016
244.658,0.52017,-0.45984,,,,,0.03152545455,-0.5622890682
245.158,0.56173,-0.43465,,,,,0.03404424242,-0.5314869161
245.658,0.60314,-0.41408,,,,,0.03655393939,-0.506334067
246.158,0.6451,-0.39264,,,,,0.0390969697,-0.4801173881
246.658,0.68655,-0.36789,,,,,0.04160909091,-0.4498532649
247.158,0.7284,-0.34797,,,,,0.04414545455,-0.4254952311
247.658,0.77003,-0.32655,,,,,0.04666848485,-0.3993030081
248.158,0.81135,-0.30698,,,,,0.04917272727,-0.3753729518
248.658,0.85348,-0.28299,,,,,0.05172606061,-0.3460381511
249.158,0.89493,-0.26437,,,,,0.05423818182,-0.3232697481
249.658,0.93638,-0.24454,,,,,0.05675030303,-0.2990217657
250.158,0.97853,-0.22121,,,,,0.05930484848,-0.2704940083
250.658,1.01982,-0.20211,,,,,0.06180727273,-0.2471386647
251.158,1.06161,-0.18456,,,,,0.06434,-0.22567865
251.658,1.10345,-0.16096,,,,,0.06687575758,-0.1968207386
252.158,1.14468,-0.14285,,,,,0.06937454545,-0.1746759599
252.658,1.18676,-0.12062,,,,,0.07192484848,-0.1474932746
253.158,1.22844,-0.0997,,,,,0.07445090909,-0.121912448
253.658,1.2697,-0.08236,,,,,0.07695151515,-0.1007092199
254.158,1.31175,-0.05843,,,,,0.0795,-0.07144778674
254.658,1.35331,-0.03795,,,,,0.08201878788,-0.04640498899
255.158,1.3949,-0.02078,,,,,0.08453939394,-0.02540963561
255.658,1.43671,0.00328,,,,,0.08707333333,0.004010760577
256.158,1.47802,0.02631,,,,,0.0895769697,0.03217168012
256.658,1.52008,0.04601,,,,,0.09212606061,0.05626069944
257.158,1.56171,0.06997,,,,,0.09464909091,0.08555881634
257.658,1.60292,0.089,,,,,0.09714666667,0.1088285644
258.158,1.64519,0.11014,,,,,0.09970848485,0.1346784055
258.423,1.63889,0.02715,,,,,0.09932666667,0.03319882612
258.923,1.59687,-0.0994,,,,,0.09678,-0.1215456102
259.423,1.55513,-0.1798,,,,,0.09425030303,-0.219858156
259.923,1.51354,-0.23844,,,,,0.09172969697,-0.2915627293
260.423,1.4717,-0.28816,,,,,0.08919393939,-0.3523599902
260.923,1.43015,-0.3298,,,,,0.08667575758,-0.4032770849
261.423,1.38864,-0.36885,,,,,0.08416,-0.451027146
261.923,1.34649,-0.39967,,,,,0.08160545455,-0.4887136219
262.423,1.30521,-0.42818,,,,,0.07910363636,-0.5235754463
262.923,1.26358,-0.45561,,,,,0.07658060606,-0.5571166544
263.423,1.22153,-0.48245,,,,,0.07403212121,-0.5899364148
263.923,1.18029,-0.50019,,,,,0.07153272727,-0.6116287601
264.423,1.13835,-0.52535,,,,,0.06899090909,-0.6423942284
264.923,1.09672,-0.54186,,,,,0.06646787879,-0.6625825385
265.423,1.05528,-0.5618,,,,,0.06395636364,-0.6869650281
265.923,1.01327,-0.58052,,,,,0.06141030303,-0.7098557104
266.423,0.97177,-0.59774,,,,,0.05889515152,-0.7309122035
266.923,0.93033,-0.61343,,,,,0.05638363636,-0.7500978234
267.423,0.88824,-0.63154,,,,,0.05383272727,-0.7722426021
267.923,0.84683,-0.64574,,,,,0.0513230303,-0.7896062607
268.423,0.80516,-0.65878,,,,,0.04879757576,-0.8055514796
268.923,0.76341,-0.6751,,,,,0.04626727273,-0.825507459
269.423,0.72189,-0.68559,,,,,0.04375090909,-0.8383345561
269.923,0.67992,-0.6957,,,,,0.04120727273,-0.8506969919
270.423,0.63855,-0.70662,,,,,0.0387,-0.8640498899
270.923,0.59686,-0.71096,,,,,0.03617333333,-0.869356811
271.423,0.55487,-0.71752,,,,,0.03362848485,-0.8773783321
271.923,0.51352,-0.71702,,,,,0.03112242424,-0.8767669357
272.423,0.47183,-0.71493,,,,,0.02859575758,-0.8742112986
272.923,0.42993,-0.7156,,,,,0.02605636364,-0.8750305698
273.423,0.38865,-0.71478,,,,,0.02355454545,-0.8740278797
273.923,0.34669,-0.71496,,,,,0.02101151515,-0.8742479824
274.423,0.30513,-0.71377,,,,,0.01849272727,-0.8727928589
274.923,0.26373,-0.71397,,,,,0.01598363636,-0.8730374175
275.423,0.22158,-0.71574,,,,,0.01342909091,-0.8752017608
275.923,0.18014,-0.7147,,,,,0.01091757576,-0.8739300562
276.423,0.13855,-0.71594,,,,,0.008396969697,-0.8754463194
276.923,0.09666,-0.71586,,,,,0.005858181818,-0.875348496
277.423,0.05513,-0.71415,,,,,0.003341212121,-0.8732575202
277.923,0.01336,-0.71323,,,,,0.0008096969697,-0.8721325507
278.189,0.00219,-0.71452,,,,,0.0001327272727,-0.8737099535
278.689,0.04484,-0.71367,,,,,0.002717575758,-0.8726705796
279.189,0.08646,-0.71155,,,,,0.00524,-0.8700782587
279.689,0.12837,-0.70928,,,,,0.00778,-0.867302519
280.189,0.16964,-0.70952,,,,,0.01028121212,-0.8675959892
280.689,0.21169,-0.70761,,,,,0.01282969697,-0.8652604549
281.189,0.25336,-0.70152,,,,,0.01535515152,-0.8578136464
281.689,0.29454,-0.68027,,,,,0.01785090909,-0.8318292981
282.189,0.33665,-0.62025,,,,,0.0204030303,-0.7584372707
282.689,0.37835,-0.57507,,,,,0.02293030303,-0.7031914894
283.189,0.41965,-0.54194,,,,,0.02543333333,-0.6626803619
283.689,0.46178,-0.50993,,,,,0.02798666667,-0.6235387625
284.189,0.50312,-0.48363,,,,,0.03049212121,-0.5913793103
284.689,0.54492,-0.4608,,,,,0.03302545455,-0.5634629494
285.189,0.58665,-0.43528,,,,,0.03555454545,-0.5322572756
285.689,0.62796,-0.41249,,,,,0.03805818182,-0.5043898264
286.189,0.67011,-0.38968,,,,,0.04061272727,-0.4764979213
286.689,0.71165,-0.36645,,,,,0.04313030303,-0.4480924431
287.189,0.75298,-0.34804,,,,,0.04563515152,-0.4255808266
287.689,0.7951,-0.3258,,,,,0.04818787879,-0.3983859134
288.189,0.83654,-0.3053,,,,,0.05069939394,-0.3733186598
288.689,0.87811,-0.28542,,,,,0.05321878788,-0.3490095378
289.189,0.92011,-0.26434,,,,,0.05576424242,-0.3232330643
289.689,0.96129,-0.24765,,,,,0.05826,-0.3028246515
290.189,1.00338,-0.22507,,,,,0.06081090909,-0.2752139888
290.689,1.04501,-0.20699,,,,,0.06333393939,-0.2531058939
291.189,1.08631,-0.18638,,,,,0.0658369697,-0.227904133
291.689,1.12839,-0.1639,,,,,0.06838727273,-0.2004157496
292.189,1.16997,-0.14571,,,,,0.07090727273,-0.1781731475
292.689,1.21144,-0.12972,,,,,0.07342060606,-0.1586206897
293.189,1.25333,-0.10359,,,,,0.07595939394,-0.1266691123
293.689,1.29477,-0.08472,,,,,0.07847090909,-0.103595011
294.189,1.33668,-0.06501,,,,,0.08101090909,-0.07949376376
294.689,1.37827,-0.04167,,,,,0.08353151515,-0.05095377843
295.189,1.41954,-0.02348,,,,,0.08603272727,-0.02871117633
295.689,1.46185,0.00098,,,,,0.0885969697,0.001198337002
296.189,1.50324,0.02254,,,,,0.09110545455,0.02756175104
296.689,1.54475,0.04378,,,,,0.09362121212,0.05353387136
297.189,1.58676,0.06607,,,,,0.09616727273,0.08078992419
297.689,1.62815,0.0863,,,,,0.09867575758,0.1055270237
297.955,1.65025,0.09701,,,,,0.1000151515,0.1186231352
298.455,1.61347,-0.06987,,,,,0.09778606061,-0.08543653705
298.955,1.57197,-0.15991,,,,,0.09527090909,-0.1955368061
299.455,1.52992,-0.22597,,,,,0.09272242424,-0.2763145023
299.955,1.48854,-0.27697,,,,,0.09021454545,-0.3386769381
300.455,1.44688,-0.32208,,,,,0.08768969697,-0.393837124
300.955,1.40495,-0.36137,,,,,0.08514848485,-0.4418806554
301.455,1.36357,-0.39253,,,,,0.08264060606,-0.4799828809
301.955,1.32176,-0.42158,,,,,0.08010666667,-0.5155050135
302.455,1.28008,-0.45172,,,,,0.07758060606,-0.5523599902
302.955,1.23874,-0.47546,,,,,0.07507515152,-0.5813890927
303.455,1.19658,-0.50075,,,,,0.07252,-0.6123135241
303.955,1.15519,-0.52305,,,,,0.07001151515,-0.6395818048
304.455,1.11369,-0.54049,,,,,0.06749636364,-0.6609073123
304.955,1.07161,-0.56029,,,,,0.06494606061,-0.6851186109
305.455,1.03018,-0.57759,,,,,0.06243515152,-0.7062729274
305.955,0.98855,-0.59426,,,,,0.05991212121,-0.7266568843
306.455,0.9467,-0.61053,,,,,0.05737575758,-0.7465517241
306.955,0.9052,-0.62599,,,,,0.05486060606,-0.7654561017
307.455,0.86332,-0.64076,,,,,0.05232242424,-0.7835167523
307.955,0.82186,-0.65589,,,,,0.04980969697,-0.8020176082
308.455,0.78033,-0.66901,,,,,0.04729272727,-0.8180606505
308.955,0.73811,-0.68321,,,,,0.04473393939,-0.8354243091
309.455,0.69694,-0.69513,,,,,0.04223878788,-0.85
309.955,0.65522,-0.70502,,,,,0.03971030303,-0.8620934214
310.455,0.61326,-0.71568,,,,,0.03716727273,-0.8751283933
310.955,0.57189,-0.71681,,,,,0.03466,-0.8765101492
311.455,0.53016,-0.71806,,,,,0.03213090909,-0.8780386403
311.955,0.48836,-0.71709,,,,,0.02959757576,-0.8768525312
312.455,0.44702,-0.7157,,,,,0.02709212121,-0.8751528491
312.955,0.40496,-0.71422,,,,,0.0245430303,-0.8733431157
313.455,0.36347,-0.7136,,,,,0.02202848485,-0.8725849841
313.955,0.32197,-0.71304,,,,,0.01951333333,-0.8719002201
314.455,0.27994,-0.71297,,,,,0.01696606061,-0.8718146246
314.955,0.23851,-0.71344,,,,,0.01445515152,-0.8723893372
315.455,0.19673,-0.71359,,,,,0.0119230303,-0.8725727562
315.955,0.15517,-0.71522,,,,,0.009404242424,-0.8745659085
316.455,0.1135,-0.71476,,,,,0.006878787879,-0.8740034238
316.955,0.0716,-0.71421,,,,,0.004339393939,-0.8733308877
317.455,0.03019,-0.71371,,,,,0.00182969697,-0.8727194913
317.82,-0.00009,-0.7133,,,,,-0.000005454545455,-0.8722181462
318.221,0.02827,-0.71316,,,,,0.001713333333,-0.8720469552
318.721,0.07008,-0.71194,,,,,0.004247272727,-0.870555148
319.221,0.11121,-0.71285,,,,,0.00674,-0.8716678895
319.721,0.15334,-0.70983,,,,,0.009293333333,-0.867975055
320.221,0.19503,-0.71011,,,,,0.01182,-0.868317437
320.721,0.23627,-0.70642,,,,,0.01431939394,-0.8638053314
321.221,0.27837,-0.69832,,,,,0.01687090909,-0.8539007092
321.721,0.31989,-0.66359,,,,,0.01938727273,-0.8114331132
322.221,0.3615,-0.60565,,,,,0.02190909091,-0.740584495
322.721,0.40337,-0.56358,,,,,0.02444666667,-0.6891415994
323.221,0.44471,-0.53337,,,,,0.02695212121,-0.6522010271
323.721,0.4867,-0.5037,,,,,0.0294969697,-0.615920763
324.221,0.52829,-0.47762,,,,,0.03201757576,-0.5840303253
324.721,0.56964,-0.45535,,,,,0.03452363636,-0.5567987283
325.221,0.61177,-0.431,,,,,0.0370769697,-0.5270237222
325.721,0.65311,-0.40801,,,,,0.03958242424,-0.4989117144
326.221,0.69475,-0.38886,,,,,0.04210606061,-0.4754952311
326.721,0.73677,-0.36565,,,,,0.04465272727,-0.4471142089
327.221,0.77795,-0.34589,,,,,0.04714848485,-0.422951822
327.721,0.81994,-0.32786,,,,,0.04969333333,-0.4009048667
328.221,0.86173,-0.30583,,,,,0.05222606061,-0.37396674
328.721,0.90288,-0.28854,,,,,0.05472,-0.3528246515
329.221,0.94504,-0.2662,,,,,0.05727515152,-0.325507459
329.721,0.98664,-0.24598,,,,,0.05979636364,-0.3007825874
330.221,1.02803,-0.22774,,,,,0.06230484848,-0.2784788457
330.721,1.07,-0.20705,,,,,0.06484848485,-0.2531792614
331.221,1.11143,-0.18564,,,,,0.06735939394,-0.2269992663
331.721,1.15331,-0.16864,,,,,0.06989757576,-0.2062117877
332.221,1.19503,-0.1466,,,,,0.07242606061,-0.1792614331
332.721,1.23627,-0.12686,,,,,0.07492545455,-0.1551235021
333.221,1.27844,-0.10774,,,,,0.07748121212,-0.1317437026
333.721,1.31998,-0.08414,,,,,0.07999878788,-0.1028857911
334.221,1.36125,-0.06656,,,,,0.0825,-0.08138909269
334.721,1.40347,-0.04645,,,,,0.08505878788,-0.0567987283
335.221,1.44483,-0.02376,,,,,0.08756545455,-0.02905355833
335.721,1.48651,-0.00194,,,,,0.09009151515,-0.002372218146
336.221,1.52835,0.01899,,,,,0.09262727273,0.02322083639
336.721,1.56967,0.03973,,,,,0.09513151515,0.04858156028
337.221,1.61166,0.06189,,,,,0.09767636364,0.07567865004
337.685,1.65006,0.08228,,,,,0.1000036364,0.1006113964
337.987,1.63039,-0.03375,,,,,0.09881151515,-0.04126925899
338.487,1.58818,-0.14138,,,,,0.09625333333,-0.1728784544
338.987,1.54692,-0.20962,,,,,0.09375272727,-0.2563218391
339.487,1.50518,-0.26671,,,,,0.0912230303,-0.3261310834
339.987,1.46333,-0.31351,,,,,0.08868666667,-0.3833577892
340.487,1.42203,-0.3524,,,,,0.08618363636,-0.4309122035
340.987,1.37994,-0.38535,,,,,0.08363272727,-0.4712032282
341.487,1.33848,-0.41828,,,,,0.08112,-0.511469797
341.987,1.29702,-0.44356,,,,,0.07860727273,-0.5423820005
342.487,1.2549,-0.47201,,,,,0.07605454545,-0.5771704573
342.987,1.21343,-0.49539,,,,,0.07354121212,-0.6057593544
343.487,1.17195,-0.51713,,,,,0.07102727273,-0.6323428711
343.987,1.12999,-0.54045,,,,,0.06848424242,-0.6608584006
344.487,1.08855,-0.55859,,,,,0.06597272727,-0.683039863
344.987,1.04671,-0.57587,,,,,0.0634369697,-0.7041697236
345.487,1.00517,-0.59248,,,,,0.06091939394,-0.724480313
345.987,0.96363,-0.60762,,,,,0.05840181818,-0.7429933969
346.487,0.92157,-0.62503,,,,,0.05585272727,-0.7642822206
346.987,0.88026,-0.63735,,,,,0.05334909091,-0.7793470286
347.487,0.83854,-0.65264,,,,,0.05082060606,-0.7980435314
347.987,0.7966,-0.6667,,,,,0.04827878788,-0.815235999
348.487,0.75525,-0.67832,,,,,0.04577272727,-0.829444852
348.987,0.71346,-0.69009,,,,,0.04324,-0.843837124
349.487,0.67176,-0.70239,,,,,0.04071272727,-0.8588774762
349.987,0.63035,-0.71094,,,,,0.0382030303,-0.8693323551
350.487,0.58831,-0.71341,,,,,0.03565515152,-0.8723526535
350.987,0.54685,-0.7171,,,,,0.03314242424,-0.8768647591
351.487,0.50538,-0.71785,,,,,0.03062909091,-0.8777818538
351.987,0.46324,-0.71531,,,,,0.02807515152,-0.8746759599
352.487,0.42183,-0.71492,,,,,0.02556545455,-0.8741990707
352.987,0.38017,-0.71786,,,,,0.02304060606,-0.8777940817
353.487,0.33844,-0.71323,,,,,0.02051151515,-0.8721325507
353.987,0.29689,-0.7142,,,,,0.01799333333,-0.8733186598
354.487,0.25495,-0.71322,,,,,0.01545151515,-0.8721203228
354.987,0.21351,-0.71358,,,,,0.01294,-0.8725605282
355.487,0.17205,-0.71425,,,,,0.01042727273,-0.8733797995
355.987,0.12983,-0.71392,,,,,0.007868484848,-0.8729762778
356.487,0.08853,-0.71386,,,,,0.005365454545,-0.8729029102
356.987,0.047,-0.71392,,,,,0.002848484848,-0.8729762778
357.487,0.00496,-0.71383,,,,,0.0003006060606,-0.8728662265
357.753,0.01118,-0.71489,,,,,0.0006775757576,-0.8741623869
358.253,0.05288,-0.7108,,,,,0.003204848485,-0.8691611641
358.753,0.09494,-0.70883,,,,,0.005753939394,-0.8667522622
359.253,0.13657,-0.70979,,,,,0.008276969697,-0.8679261433
359.753,0.17808,-0.70874,,,,,0.01079272727,-0.8666422108
360.253,0.22007,-0.70696,,,,,0.01333757576,-0.8644656395
360.753,0.26134,-0.7038,,,,,0.01583878788,-0.8606016141
361.253,0.30338,-0.69147,,,,,0.01838666667,-0.8455245781
361.753,0.345,-0.6374,,,,,0.02090909091,-0.7794081683
362.253,0.38628,-0.59071,,,,,0.02341090909,-0.7223159697
362.753,0.42843,-0.55328,,,,,0.02596545455,-0.676546833
363.253,0.46995,-0.5233,,,,,0.02848181818,-0.6398875031
363.753,0.51138,-0.49705,,,,,0.03099272727,-0.6077891905
364.253,0.55344,-0.47004,,,,,0.03354181818,-0.5747615554
364.753,0.59475,-0.44829,,,,,0.03604545455,-0.5481658107
365.253,0.63651,-0.42606,,,,,0.03857636364,-0.5209831255
365.753,0.67837,-0.4051,,,,,0.04111333333,-0.4953533871
366.253,0.71954,-0.38489,,,,,0.04360848485,-0.4706407435
366.753,0.76174,-0.36238,,,,,0.04616606061,-0.4431156762
367.253,0.80334,-0.34447,,,,,0.04868727273,-0.4212154561
367.753,0.84468,-0.32612,,,,,0.05119272727,-0.3987772071
368.253,0.88671,-0.30413,,,,,0.05374,-0.3718879922
368.753,0.92827,-0.28649,,,,,0.05625878788,-0.3503179261
369.253,0.96991,-0.26584,,,,,0.05878242424,-0.3250672536
369.753,1.01165,-0.24554,,,,,0.06131212121,-0.3002445586
370.253,1.05301,-0.22895,,,,,0.06381878788,-0.279958425
370.753,1.09506,-0.20994,,,,,0.06636727273,-0.2567131328
371.253,1.13659,-0.18795,,,,,0.06888424242,-0.2298239178
371.753,1.17793,-0.16987,,,,,0.07138969697,-0.2077158229
372.253,1.22013,-0.14598,,,,,0.07394727273,-0.1785033015
372.753,1.26149,-0.12679,,,,,0.07645393939,-0.1550379066
373.253,1.30313,-0.10752,,,,,0.07897757576,-0.1314746882
373.753,1.34508,-0.08628,,,,,0.08152,-0.1055025679
374.253,1.38634,-0.06652,,,,,0.08402060606,-0.08134018097
374.753,1.42828,-0.04763,,,,,0.08656242424,-0.05824162387
375.253,1.4701,-0.02535,,,,,0.0890969697,-0.03099779897
375.753,1.51127,-0.00655,,,,,0.09159212121,-0.008009293226
376.253,1.55334,0.01642,,,,,0.09414181818,0.02007825874
376.753,1.59497,0.03618,,,,,0.09666484848,0.04424064563
377.253,1.6364,0.05607,,,,,0.09917575758,0.0685619956
377.519,1.6476,0.02593,,,,,0.09985454545,0.03170701883
378.019,1.60537,-0.11671,,,,,0.09729515152,-0.1427121546
378.519,1.5634,-0.19672,,,,,0.09475151515,-0.2405478112
379.019,1.52186,-0.2564,,,,,0.09223393939,-0.313524089
379.519,1.48049,-0.30335,,,,,0.08972666667,-0.3709342137
380.019,1.43819,-0.34578,,,,,0.0871630303,-0.4228173147
380.519,1.39691,-0.37918,,,,,0.08466121212,-0.4636585962
381.019,1.35533,-0.41278,,,,,0.08214121212,-0.5047444363
381.519,1.31344,-0.44186,,,,,0.07960242424,-0.5403032526
382.019,1.2719,-0.4668,,,,,0.07708484848,-0.5707997065
382.519,1.23017,-0.49,,,,,0.07455575758,-0.5991685009
383.019,1.18849,-0.51239,,,,,0.07202969697,-0.626546833
383.519,1.14699,-0.53331,,,,,0.06951454545,-0.6521276596
384.019,1.10498,-0.55291,,,,,0.06696848485,-0.6760943996
384.519,1.06365,-0.57049,,,,,0.06446363636,-0.6975910981
385.019,1.02206,-0.58745,,,,,0.0619430303,-0.718329665
385.519,0.97991,-0.60654,,,,,0.05938848485,-0.7416727806
386.019,0.93869,-0.62025,,,,,0.05689030303,-0.7584372707
386.519,0.89686,-0.6354,,,,,0.05435515152,-0.7769625825
387.019,0.85501,-0.65118,,,,,0.05181878788,-0.7962582539
387.519,0.81364,-0.66366,,,,,0.04931151515,-0.8115187087
388.019,0.77174,-0.67753,,,,,0.04677212121,-0.8284788457
388.519,0.73014,-0.68935,,,,,0.04425090909,-0.8429322573
389.019,0.68876,-0.70036,,,,,0.0417430303,-0.8563952067
389.519,0.64664,-0.71047,,,,,0.03919030303,-0.8687576425
390.019,0.6052,-0.71624,,,,,0.03667878788,-0.8758131573
390.519,0.56362,-0.71718,,,,,0.03415878788,-0.8769625825
391.019,0.52177,-0.71548,,,,,0.03162242424,-0.8748838347
391.519,0.48027,-0.71481,,,,,0.02910727273,-0.8740645635
392.019,0.4384,-0.71326,,,,,0.02656969697,-0.8721692345
392.519,0.39697,-0.71365,,,,,0.02405878788,-0.8726461237
393.019,0.3553,-0.71445,,,,,0.02153333333,-0.873624358
393.519,0.31331,-0.71306,,,,,0.01898848485,-0.871924676
394.019,0.27195,-0.71487,,,,,0.01648181818,-0.874137931
394.519,0.2303,-0.71611,,,,,0.01395757576,-0.8756541942
395.019,0.18823,-0.71527,,,,,0.01140787879,-0.8746270482
395.519,0.14699,-0.71649,,,,,0.008908484848,-0.8761188555
396.019,0.10515,-0.71564,,,,,0.006372727273,-0.8750794815
396.519,0.06347,-0.71498,,,,,0.003846666667,-0.8742724382
397.019,0.02205,-0.71386,,,,,0.001336363636,-0.8729029102
397.284,-0.00005,-0.71612,,,,,-0.00000303030303,-0.8756664221