File: mechanical/hysteresis/databak/hmwg_hysteresis - nonconductive_3.csv
Time,Extension,Load,Length,Width,Thickness,CS Area,Strain,Stress
(s),(mm),(N),(mm),(mm),(mm),(mm^2),(mm/mm),(MPa)
0,0,-0.0045,16.5,2.82,0.31,0.8742,0,-0.005147563487
0.5,0.03894,-0.0016,,,,,0.00236,-0.001830244795
1,0.08058,0.00112,,,,,0.004883636364,0.001281171357
1.5,0.12179,0.0023,,,,,0.007381212121,0.002630976893
2,0.16386,0.00271,,,,,0.009930909091,0.003099977122
2.5,0.20552,0.00206,,,,,0.01245575758,0.002356440174
3,0.24694,0.00188,,,,,0.01496606061,0.002150537634
3.5,0.28898,0.00763,,,,,0.01751393939,0.008727979867
4,0.33026,0.00631,,,,,0.02001575758,0.007218027911
4.5,0.3722,0.00646,,,,,0.02255757576,0.007389613361
5,0.41384,0.00722,,,,,0.02508121212,0.008258979639
5.5,0.45515,0.00882,,,,,0.02758484848,0.01008922443
6,0.49732,0.01001,,,,,0.03014060606,0.011450469
6.5,0.53886,0.01085,,,,,0.03265818182,0.01241134752
7,0.58024,0.00906,,,,,0.03516606061,0.01036376115
7.5,0.62231,0.01244,,,,,0.03771575758,0.01423015328
8,0.66366,0.01091,,,,,0.04022181818,0.0124799817
8.5,0.70539,0.01402,,,,,0.04275090909,0.01603752002
9,0.7473,0.0143,,,,,0.04529090909,0.01635781286
9.5,0.78848,0.01487,,,,,0.04778666667,0.01700983757
10,0.83062,0.01594,,,,,0.05034060606,0.01823381377
10.5,0.87225,0.01499,,,,,0.05286363636,0.01714710593
11,0.91356,0.01678,,,,,0.05536727273,0.01919469229
11.5,0.95562,0.01876,,,,,0.05791636364,0.02145962022
12,0.99712,0.01734,,,,,0.06043151515,0.01983527797
12.5,1.03872,0.01934,,,,,0.06295272727,0.02212308396
13,1.08052,0.0203,,,,,0.06548606061,0.02322123084
13.5,1.12187,0.02025,,,,,0.06799212121,0.02316403569
14,1.16393,0.02216,,,,,0.07054121212,0.02534889041
14.5,1.2055,0.02455,,,,,0.07306060606,0.02808281858
15,1.2468,0.0242,,,,,0.07556363636,0.02768245253
15.5,1.28905,0.02468,,,,,0.07812424242,0.02823152597
16,1.33042,0.02413,,,,,0.08063151515,0.02760237932
16.5,1.37198,0.0259,,,,,0.08315030303,0.02962708762
17,1.41396,0.02833,,,,,0.08569454545,0.03240677191
17.5,1.45525,0.02825,,,,,0.0881969697,0.03231525967
18,1.49714,0.03069,,,,,0.09073575758,0.03510638298
18.5,1.53897,0.03072,,,,,0.09327090909,0.03514070007
19,1.58011,0.03124,,,,,0.09576424242,0.03573552963
19.5,1.6222,0.03154,,,,,0.09831515152,0.03607870053
19.839,1.65017,0.03233,,,,,0.100010303,0.03698238389
20.24,1.62168,0.02574,,,,,0.09828363636,0.02944406314
20.74,1.58021,0.0222,,,,,0.09577030303,0.02539464653
21.24,1.53873,0.01882,,,,,0.09325636364,0.0215282544
21.74,1.49665,0.01683,,,,,0.09070606061,0.01925188744
22.24,1.45523,0.01429,,,,,0.08819575758,0.01634637383
22.74,1.41351,0.01223,,,,,0.08566727273,0.01398993365
23.24,1.37185,0.01046,,,,,0.08314242424,0.01196522535
23.74,1.33032,0.00873,,,,,0.08062545455,0.009986273164
24.24,1.28827,0.0067,,,,,0.0780769697,0.00766415008
24.74,1.24693,0.00593,,,,,0.07557151515,0.006783344772
25.24,1.20536,0.00001,,,,,0.07305212121,0.00001143902997
25.74,1.1632,0.00311,,,,,0.0704969697,0.003557538321
26.24,1.12192,0.00008,,,,,0.06799515152,0.00009151223976
26.74,1.08029,-0.00162,,,,,0.06547212121,-0.001853122855
27.24,1.03835,-0.00308,,,,,0.06293030303,-0.003523221231
27.74,0.99696,-0.00482,,,,,0.06042181818,-0.005513612446
28.24,0.95509,-0.00481,,,,,0.05788424242,-0.005502173416
28.74,0.9135,-0.00646,,,,,0.05536363636,-0.007389613361
29.24,0.87203,-0.00759,,,,,0.05285030303,-0.008682223747
29.74,0.82994,-0.00955,,,,,0.05029939394,-0.01092427362
30.24,0.78854,-0.01061,,,,,0.04779030303,-0.0121368108
30.74,0.74688,-0.01539,,,,,0.04526545455,-0.01760466712
31.24,0.70509,-0.01549,,,,,0.04273272727,-0.01771905742
31.74,0.66352,-0.01408,,,,,0.04021333333,-0.0161061542
32.24,0.62176,-0.01722,,,,,0.03768242424,-0.01969800961
32.74,0.58016,-0.01807,,,,,0.03516121212,-0.02067032716
33.24,0.53873,-0.01876,,,,,0.03265030303,-0.02145962022
33.74,0.49656,-0.02216,,,,,0.03009454545,-0.02534889041
34.24,0.45525,-0.0228,,,,,0.02759090909,-0.02608098833
34.74,0.41366,-0.02476,,,,,0.02507030303,-0.02832303821
35.24,0.37157,-0.02614,,,,,0.02251939394,-0.02990162434
35.74,0.33027,-0.02715,,,,,0.02001636364,-0.03105696637
36.24,0.28849,-0.02967,,,,,0.01748424242,-0.03393960192
36.74,0.24676,-0.02987,,,,,0.01495515152,-0.03416838252
37.24,0.20535,-0.03199,,,,,0.01244545455,-0.03659345687
37.74,0.16339,-0.0325,,,,,0.009902424242,-0.0371768474
38.24,0.1218,-0.03469,,,,,0.007381818182,-0.03968199497
38.74,0.08038,-0.03543,,,,,0.004871515152,-0.04052848318
39.24,0.03824,-0.03725,,,,,0.002317575758,-0.04261038664
39.705,-0.00003,-0.03686,,,,,-0.000001818181818,-0.04216426447
40.007,0.01957,-0.03422,,,,,0.001186060606,-0.03914436056
40.507,0.0617,-0.0316,,,,,0.003739393939,-0.03614733471
41.007,0.10336,-0.02958,,,,,0.006264242424,-0.03383665065
41.507,0.14469,-0.0261,,,,,0.008769090909,-0.02985586822
42.007,0.18669,-0.02375,,,,,0.01131454545,-0.02716769618
42.507,0.22831,-0.02221,,,,,0.0138369697,-0.02540608556
43.007,0.26984,-0.02133,,,,,0.01635393939,-0.02439945093
43.507,0.31179,-0.01768,,,,,0.01889636364,-0.02022420499
44.007,0.35306,-0.01471,,,,,0.02139757576,-0.01682681309
44.507,0.39512,-0.01591,,,,,0.02394666667,-0.01819949668
45.007,0.43676,-0.01328,,,,,0.02647030303,-0.0151910318
45.507,0.47798,-0.0131,,,,,0.02896848485,-0.01498512926
46.007,0.52019,-0.01211,,,,,0.03152666667,-0.01385266529
46.507,0.56174,-0.0072,,,,,0.03404484848,-0.008236101579
47.007,0.60306,-0.00768,,,,,0.03654909091,-0.008785175017
47.507,0.64505,-0.00645,,,,,0.03909393939,-0.007378174331
48.007,0.68655,-0.00611,,,,,0.04160909091,-0.006989247312
48.507,0.72826,-0.00529,,,,,0.0441369697,-0.006051246854
49.007,0.77008,-0.00314,,,,,0.04667151515,-0.003591855411
49.507,0.81133,-0.00118,,,,,0.04917151515,-0.001349805536
50.007,0.85349,-0.00117,,,,,0.05172666667,-0.001338366507
50.507,0.89507,0.00043,,,,,0.05424666667,0.0004918782887
51.007,0.93642,0.0032,,,,,0.05675272727,0.00366048959
51.507,0.97855,0.00427,,,,,0.05930606061,0.004884465797
52.007,1.0199,0.0038,,,,,0.06181212121,0.004346831389
52.507,1.0616,0.00408,,,,,0.06433939394,0.004667124228
53.007,1.1035,0.00677,,,,,0.06687878788,0.00774422329
53.507,1.14469,0.00749,,,,,0.06937515152,0.008567833448
54.007,1.1867,0.00761,,,,,0.07192121212,0.008705101807
54.507,1.22844,0.00945,,,,,0.07445090909,0.01080988332
55.007,1.26967,0.01078,,,,,0.07694969697,0.01233127431
55.507,1.31178,0.01278,,,,,0.07950181818,0.0146190803
56.007,1.35335,0.0131,,,,,0.08202121212,0.01498512926
56.507,1.39483,0.01484,,,,,0.08453515152,0.01697552048
57.007,1.43679,0.01656,,,,,0.08707818182,0.01894303363
57.507,1.47819,0.0162,,,,,0.08958727273,0.01853122855
58.007,1.52007,0.01623,,,,,0.09212545455,0.01856554564
58.507,1.56171,0.01936,,,,,0.09464909091,0.02214596202
59.007,1.60303,0.02008,,,,,0.09715333333,0.02296957218
59.507,1.64514,0.02175,,,,,0.09970545455,0.02487989019
59.772,1.6388,0.01982,,,,,0.09932121212,0.0226721574
60.272,1.59681,0.01414,,,,,0.09677636364,0.01617478838
60.772,1.555,0.01082,,,,,0.09424242424,0.01237703043
61.272,1.51351,0.00896,,,,,0.09172787879,0.01024937085
61.772,1.47157,0.00758,,,,,0.08918606061,0.008670784717
62.272,1.43021,0.00458,,,,,0.08667939394,0.005239075726
62.772,1.3885,0.00361,,,,,0.08415151515,0.004129489819
63.272,1.34649,0.00247,,,,,0.08160545455,0.002825440403
63.772,1.30515,-0.00027,,,,,0.0791,-0.0003088538092
64.272,1.26348,-0.00182,,,,,0.07657454545,-0.002081903455
64.772,1.2215,-0.00373,,,,,0.07403030303,-0.004266758179
65.272,1.1802,-0.00555,,,,,0.07152727273,-0.006348661633
65.772,1.13834,-0.00574,,,,,0.06899030303,-0.006566003203
66.272,1.09669,-0.00828,,,,,0.06646606061,-0.009471516815
66.772,1.05531,-0.01015,,,,,0.06395818182,-0.01161061542
67.272,1.01318,-0.01054,,,,,0.06140484848,-0.01205673759
67.772,0.97175,-0.01168,,,,,0.05889393939,-0.01336078701
68.272,0.93023,-0.01532,,,,,0.05637757576,-0.01752459391
68.772,0.88826,-0.01529,,,,,0.05383393939,-0.01749027682
69.272,0.84674,-0.01687,,,,,0.05131757576,-0.01929764356
69.772,0.80507,-0.01831,,,,,0.04879212121,-0.02094486388
70.272,0.7634,-0.02006,,,,,0.04626666667,-0.02294669412
70.772,0.72196,-0.02076,,,,,0.04375515152,-0.02374742622
71.272,0.67983,-0.02329,,,,,0.04120181818,-0.0266415008
71.772,0.63847,-0.02493,,,,,0.03869515152,-0.02851750172
72.272,0.59696,-0.02508,,,,,0.03617939394,-0.02868908717
72.772,0.55478,-0.0273,,,,,0.0336230303,-0.03122855182
73.272,0.51346,-0.02852,,,,,0.03111878788,-0.03262411348
73.772,0.47183,-0.03086,,,,,0.02859575758,-0.03530084649
74.272,0.42992,-0.03177,,,,,0.02605575758,-0.03634179822
74.772,0.3885,-0.03304,,,,,0.02354545455,-0.03779455502
75.272,0.34668,-0.03296,,,,,0.02101090909,-0.03770304278
75.772,0.30509,-0.03505,,,,,0.01849030303,-0.04009380005
76.272,0.26358,-0.0358,,,,,0.01597454545,-0.04095172729
76.772,0.22154,-0.03759,,,,,0.01342666667,-0.04299931366
77.272,0.18014,-0.03874,,,,,0.01091757576,-0.0443148021
77.772,0.13849,-0.03992,,,,,0.008393333333,-0.04566460764
78.272,0.09656,-0.04085,,,,,0.005852121212,-0.04672843743
78.772,0.05516,-0.04178,,,,,0.003343030303,-0.04779226722
79.272,0.01327,-0.04101,,,,,0.0008042424242,-0.04691146191
79.538,0.00225,-0.04299,,,,,0.0001363636364,-0.04917638984
80.038,0.04495,-0.03774,,,,,0.002724242424,-0.04317089911
80.538,0.08649,-0.03651,,,,,0.005241818182,-0.04176389842
81.038,0.12842,-0.03179,,,,,0.007783030303,-0.03636467628
81.538,0.16985,-0.03072,,,,,0.01029393939,-0.03514070007
82.038,0.21171,-0.02986,,,,,0.01283090909,-0.03415694349
82.538,0.25345,-0.02776,,,,,0.01536060606,-0.0317547472
83.038,0.29459,-0.02642,,,,,0.01785393939,-0.03022191718
83.538,0.33686,-0.02328,,,,,0.02041575758,-0.02663006177
84.038,0.37845,-0.02228,,,,,0.02293636364,-0.02548615877
84.538,0.41966,-0.01997,,,,,0.02543393939,-0.02284374285
85.038,0.46178,-0.01794,,,,,0.02798666667,-0.02052161977
85.538,0.50321,-0.01612,,,,,0.03049757576,-0.01843971631
86.038,0.54488,-0.01671,,,,,0.0330230303,-0.01911461908
86.538,0.58672,-0.01311,,,,,0.03555878788,-0.01499656829
87.038,0.62809,-0.01234,,,,,0.03806606061,-0.01411576298
87.538,0.67002,-0.01196,,,,,0.04060727273,-0.01368107984
88.038,0.71175,-0.01134,,,,,0.04313636364,-0.01297185999
88.538,0.75305,-0.00792,,,,,0.04563939394,-0.009059711736
89.038,0.79516,-0.00706,,,,,0.04819151515,-0.008075955159
89.538,0.83655,-0.00594,,,,,0.0507,-0.006794783802
90.038,0.87825,-0.00468,,,,,0.05322727273,-0.005353466026
90.538,0.92012,-0.00502,,,,,0.05576484848,-0.005742393045
91.038,0.96133,-0.00356,,,,,0.05826242424,-0.004072294669
91.538,1.00342,-0.00305,,,,,0.06081333333,-0.003488904141
92.038,1.04505,-0.00177,,,,,0.06333636364,-0.002024708305
92.538,1.08627,0.00409,,,,,0.06583454545,0.004678563258
93.038,1.12833,0.00317,,,,,0.06838363636,0.003626172501
93.538,1.17007,0.00295,,,,,0.07091333333,0.003374513841
94.038,1.21134,0.00358,,,,,0.07341454545,0.004095172729
94.538,1.2535,0.00425,,,,,0.07596969697,0.004861587737
95.038,1.29482,0.00529,,,,,0.07847393939,0.006051246854
95.538,1.3367,0.00641,,,,,0.08101212121,0.007332418211
96.038,1.37835,0.0093,,,,,0.08353636364,0.01063829787
96.538,1.41968,0.0099,,,,,0.08604121212,0.01132463967
97.038,1.46183,0.01059,,,,,0.08859575758,0.01211393274
97.538,1.50337,0.0139,,,,,0.09111333333,0.01590025166
98.038,1.5447,0.01267,,,,,0.09361818182,0.01449325097
98.538,1.58685,0.01558,,,,,0.09617272727,0.01782200869
99.038,1.62819,0.01666,,,,,0.09867818182,0.01905742393
99.304,1.65028,0.01678,,,,,0.1000169697,0.01919469229
99.804,1.61362,0.01218,,,,,0.09779515152,0.0139327385
100.304,1.57206,0.00848,,,,,0.09527636364,0.009700297415
100.804,1.52987,0.00632,,,,,0.09271939394,0.007229466941
101.304,1.48863,0.00343,,,,,0.09022,0.00392358728
101.804,1.44698,0.0009,,,,,0.08769575758,0.001029512697
102.304,1.40492,-0.00041,,,,,0.08514666667,-0.0004690002288
102.804,1.36357,-0.00187,,,,,0.08264060606,-0.002139098604
103.304,1.32187,-0.00446,,,,,0.08011333333,-0.005101807367
103.804,1.28007,-0.00604,,,,,0.07758,-0.006909174102
104.304,1.23869,-0.00727,,,,,0.07507212121,-0.008316174788
104.804,1.19665,-0.00788,,,,,0.07252424242,-0.009013955617
105.304,1.15518,-0.01104,,,,,0.07001090909,-0.01262868909
105.804,1.11372,-0.0111,,,,,0.06749818182,-0.01269732327
106.304,1.07164,-0.01235,,,,,0.06494787879,-0.01412720201
106.804,1.03022,-0.01569,,,,,0.06243757576,-0.01794783802
107.304,0.98847,-0.01585,,,,,0.05990727273,-0.0181308625
107.804,0.94688,-0.01898,,,,,0.05738666667,-0.02171127888
108.304,0.90522,-0.01855,,,,,0.05486181818,-0.02121940059
108.804,0.86333,-0.02016,,,,,0.0523230303,-0.02306108442
109.304,0.82184,-0.02351,,,,,0.04980848485,-0.02689315946
109.804,0.78036,-0.02423,,,,,0.04729454545,-0.02771676962
110.304,0.73818,-0.02525,,,,,0.04473818182,-0.02888355067
110.804,0.69696,-0.02753,,,,,0.04224,-0.03149164951
111.304,0.65525,-0.02837,,,,,0.03971212121,-0.03245252803
111.804,0.61332,-0.03037,,,,,0.03717090909,-0.03474033402
112.304,0.57198,-0.0303,,,,,0.03466545455,-0.03466026081
112.804,0.53008,-0.03304,,,,,0.03212606061,-0.03779455502
113.304,0.48849,-0.03285,,,,,0.02960545455,-0.03757721345
113.804,0.44703,-0.03367,,,,,0.02709272727,-0.03851521391
114.304,0.40499,-0.03667,,,,,0.02454484848,-0.0419469229
114.804,0.36351,-0.03722,,,,,0.02203090909,-0.04257606955
115.304,0.32203,-0.03848,,,,,0.0195169697,-0.04401738733
115.804,0.27995,-0.04087,,,,,0.01696666667,-0.04675131549
116.304,0.2386,-0.04143,,,,,0.01446060606,-0.04739190117
116.804,0.19675,-0.04319,,,,,0.01192424242,-0.04940517044
117.304,0.15517,-0.04445,,,,,0.009404242424,-0.05084648822
117.804,0.1137,-0.04232,,,,,0.006890909091,-0.04840997483
118.304,0.07161,-0.04481,,,,,0.00434,-0.0512582933
118.804,0.03021,-0.04742,,,,,0.001830909091,-0.05424388012
119.17,-0.00011,-0.04867,,,,,-0.000006666666667,-0.05567375887
119.571,0.02825,-0.04365,,,,,0.001712121212,-0.04993136582
120.071,0.0701,-0.0412,,,,,0.004248484848,-0.04712880348
120.571,0.11131,-0.03865,,,,,0.006746060606,-0.04421185084
121.071,0.15348,-0.03637,,,,,0.009301818182,-0.041603752
121.571,0.19502,-0.03324,,,,,0.01181939394,-0.03802333562
122.071,0.23629,-0.03326,,,,,0.01432060606,-0.03804621368
122.571,0.27846,-0.02959,,,,,0.01687636364,-0.03384808968
123.071,0.31995,-0.02782,,,,,0.01939090909,-0.03182338138
123.571,0.36151,-0.02667,,,,,0.02190969697,-0.03050789293
124.071,0.40335,-0.02607,,,,,0.02444545455,-0.02982155113
124.571,0.44478,-0.02417,,,,,0.02695636364,-0.02764813544
125.071,0.4867,-0.02113,,,,,0.0294969697,-0.02417067033
125.571,0.5284,-0.02094,,,,,0.03202424242,-0.02395332876
126.071,0.56968,-0.01799,,,,,0.03452606061,-0.02057881492
126.571,0.61183,-0.01725,,,,,0.03708060606,-0.0197323267
127.071,0.65335,-0.01585,,,,,0.0395969697,-0.0181308625
127.571,0.69481,-0.0133,,,,,0.04210969697,-0.01521390986
128.071,0.73684,-0.01213,,,,,0.0446569697,-0.01387554335
128.571,0.77808,-0.01355,,,,,0.04715636364,-0.01549988561
129.071,0.82,-0.0113,,,,,0.0496969697,-0.01292610387
129.571,0.86179,-0.00858,,,,,0.05222969697,-0.009814687714
130.071,0.90293,-0.00847,,,,,0.0547230303,-0.009688858385
130.571,0.94508,-0.00709,,,,,0.05727757576,-0.008110272249
131.071,0.98675,-0.00547,,,,,0.0598030303,-0.006257149394
131.571,1.02804,-0.01278,,,,,0.06230545455,-0.0146190803
132.071,1.07011,-0.00144,,,,,0.06485515152,-0.001647220316
132.571,1.11161,-0.00174,,,,,0.06737030303,-0.001990391215
133.071,1.15328,-0.0002,,,,,0.06989575758,-0.0002287805994
133.571,1.1951,0.00049,,,,,0.07243030303,0.0005605124685
134.071,1.23642,0.00301,,,,,0.07493454545,0.003443148021
134.571,1.27847,0.00177,,,,,0.0774830303,0.002024708305
135.071,1.31999,0.00998,,,,,0.07999939394,0.01141615191
135.571,1.3614,0.00521,,,,,0.08250909091,0.005959734615
136.071,1.40346,0.00859,,,,,0.08505818182,0.009826126744
136.571,1.44481,0.00598,,,,,0.08756424242,0.006840539922
137.071,1.48653,0.0095,,,,,0.09009272727,0.01086707847
137.571,1.52846,0.0093,,,,,0.09263393939,0.01063829787
138.071,1.56967,0.00913,,,,,0.09513151515,0.01044383436
138.571,1.61169,0.00867,,,,,0.09767818182,0.009917638984
139.034,1.65001,0.01506,,,,,0.1000006061,0.01722717914
139.336,1.6303,0.01167,,,,,0.09880606061,0.01334934798
139.836,1.58824,0.00848,,,,,0.0962569697,0.009700297415
140.336,1.54687,0.005,,,,,0.09374969697,0.005719514985
140.836,1.50511,0.00157,,,,,0.09121878788,0.001795927705
141.336,1.46332,-0.00116,,,,,0.08868606061,-0.001326927477
141.836,1.42197,-0.00305,,,,,0.08618,-0.003488904141
142.336,1.37998,-0.00355,,,,,0.08363515152,-0.004060855639
142.836,1.33851,-0.00646,,,,,0.08112181818,-0.007389613361
143.336,1.29705,-0.00765,,,,,0.07860909091,-0.008750857927
143.836,1.25491,-0.00996,,,,,0.07605515152,-0.01139327385
144.336,1.21349,-0.01122,,,,,0.07354484848,-0.01283459163
144.836,1.17187,-0.01499,,,,,0.07102242424,-0.01714710593
145.336,1.13006,-0.01528,,,,,0.06848848485,-0.01747883779
145.836,1.0885,-0.01628,,,,,0.06596969697,-0.01862274079
146.336,1.04666,-0.01612,,,,,0.06343393939,-0.01843971631
146.836,1.00515,-0.01932,,,,,0.06091818182,-0.0221002059
147.336,0.96367,-0.01927,,,,,0.05840424242,-0.02204301075
147.836,0.92148,-0.02276,,,,,0.05584727273,-0.02603523221
148.336,0.88018,-0.02261,,,,,0.05334424242,-0.02586364676
148.836,0.83866,-0.0262,,,,,0.05082787879,-0.02997025852
149.336,0.79655,-0.02631,,,,,0.04827575758,-0.03009608785
149.836,0.7552,-0.02709,,,,,0.04576969697,-0.03098833219
150.336,0.71344,-0.0277,,,,,0.04323878788,-0.03168611302
150.836,0.67176,-0.03022,,,,,0.04071272727,-0.03456874857
151.336,0.6303,-0.03033,,,,,0.0382,-0.0346945779
151.836,0.58828,-0.03207,,,,,0.03565333333,-0.03668496911
152.336,0.54682,-0.0336,,,,,0.03314060606,-0.0384351407
152.836,0.50523,-0.03513,,,,,0.03062,-0.04018531229
153.336,0.4633,-0.03528,,,,,0.02807878788,-0.04035689774
153.836,0.42181,-0.03678,,,,,0.02556424242,-0.04207275223
154.336,0.38011,-0.0396,,,,,0.0230369697,-0.04529855868
154.836,0.33835,-0.03935,,,,,0.02050606061,-0.04501258293
155.336,0.29692,-0.04123,,,,,0.01799515152,-0.04716312057
155.836,0.25488,-0.04267,,,,,0.01544727273,-0.04881034088
156.336,0.21356,-0.04421,,,,,0.0129430303,-0.0505719515
156.836,0.17204,-0.04577,,,,,0.01042666667,-0.05235644017
157.336,0.12983,-0.04763,,,,,0.007868484848,-0.05448409975
157.836,0.08856,-0.04833,,,,,0.005367272727,-0.05528483185
158.336,0.04694,-0.04889,,,,,0.002844848485,-0.05592541752
158.836,0.00499,-0.05119,,,,,0.0003024242424,-0.05855639442
159.102,0.01131,-0.04925,,,,,0.0006854545455,-0.0563372226
159.602,0.05293,-0.04384,,,,,0.003207878788,-0.05014870739
160.102,0.09522,-0.04185,,,,,0.005770909091,-0.04787234043
160.602,0.13673,-0.04064,,,,,0.008286666667,-0.0464882178
161.102,0.17807,-0.03859,,,,,0.01079212121,-0.04414321666
161.602,0.22021,-0.03564,,,,,0.01334606061,-0.04076870281
162.102,0.26152,-0.03559,,,,,0.01584969697,-0.04071150766
162.602,0.30335,-0.03412,,,,,0.01838484848,-0.03902997026
163.102,0.34511,-0.03061,,,,,0.02091575758,-0.03501487074
163.602,0.38643,-0.02934,,,,,0.02342,-0.03356211393
164.102,0.42841,-0.02848,,,,,0.02596424242,-0.03257835736
164.602,0.47007,-0.02863,,,,,0.02848909091,-0.0327499428
165.102,0.51145,-0.02307,,,,,0.0309969697,-0.02638984214
165.602,0.5535,-0.0212,,,,,0.03354545455,-0.02425074354
166.102,0.59478,-0.02277,,,,,0.03604727273,-0.02604667124
166.602,0.6367,-0.01922,,,,,0.03858787879,-0.0219858156
167.102,0.67845,-0.01635,,,,,0.04111818182,-0.018702814
167.602,0.71963,-0.01698,,,,,0.04361393939,-0.01942347289
168.102,0.76185,-0.01581,,,,,0.04617272727,-0.01808510638
168.602,0.80346,-0.01371,,,,,0.04869454545,-0.01568291009
169.102,0.84468,-0.01112,,,,,0.05119272727,-0.01272020133
169.602,0.88672,-0.01283,,,,,0.05374060606,-0.01467627545
170.102,0.92838,-0.01054,,,,,0.05626545455,-0.01205673759
170.602,0.96985,-0.00773,,,,,0.05877878788,-0.008842370167
171.102,1.01185,-0.00692,,,,,0.06132424242,-0.007915808739
171.602,1.05306,-0.00635,,,,,0.06382181818,-0.007263784031
172.102,1.09513,-0.00517,,,,,0.06637151515,-0.005913978495
172.602,1.13673,-0.00339,,,,,0.06889272727,-0.00387783116
173.102,1.17804,-0.00266,,,,,0.07139636364,-0.003042781972
173.602,1.22019,-0.00365,,,,,0.07395090909,-0.004175245939
174.102,1.26167,-0.00125,,,,,0.07646484848,-0.001429878746
174.602,1.30315,0.00297,,,,,0.07897878788,0.003397391901
175.102,1.34516,0.00246,,,,,0.08152484848,0.002814001373
175.602,1.38648,0.00373,,,,,0.08402909091,0.004266758179
176.102,1.42832,0.00513,,,,,0.08656484848,0.005868222375
176.602,1.47015,0.00573,,,,,0.0891,0.006554564173
177.102,1.51135,0.00745,,,,,0.0915969697,0.008522077328
177.602,1.5535,0.00811,,,,,0.09415151515,0.009277053306
178.102,1.59513,0.01069,,,,,0.09667454545,0.01222832304
178.602,1.63645,0.01153,,,,,0.09917878788,0.01318920156
178.867,1.64752,0.00708,,,,,0.09984969697,0.008098833219
179.367,1.60529,0.00453,,,,,0.09729030303,0.005181880577
179.867,1.56341,0.00133,,,,,0.09475212121,0.001521390986
180.367,1.52177,0.00056,,,,,0.09222848485,0.0006405856783
180.867,1.48043,-0.00253,,,,,0.0897230303,-0.002894074582
181.367,1.43825,-0.00373,,,,,0.08716666667,-0.004266758179
181.867,1.39683,-0.00617,,,,,0.08465636364,-0.007057881492
182.367,1.35528,-0.00694,,,,,0.08213818182,-0.007938686799
182.867,1.31331,-0.00809,,,,,0.07959454545,-0.009254175246
183.367,1.27188,-0.01228,,,,,0.07708363636,-0.0140471288
183.867,1.23003,-0.01045,,,,,0.07454727273,-0.01195378632
184.367,1.18853,-0.01336,,,,,0.07203212121,-0.01528254404
184.867,1.14688,-0.01475,,,,,0.06950787879,-0.01687256921
185.367,1.10492,-0.01555,,,,,0.06696484848,-0.0177876916
185.867,1.06356,-0.01783,,,,,0.06445818182,-0.02039579044
186.367,1.02198,-0.02001,,,,,0.06193818182,-0.02288949897
186.867,0.97987,-0.02123,,,,,0.05938606061,-0.02428506063
187.367,0.93858,-0.02234,,,,,0.05688363636,-0.02555479295
187.867,0.89683,-0.02313,,,,,0.05435333333,-0.02645847632
188.367,0.85506,-0.02444,,,,,0.05182181818,-0.02795698925
188.867,0.81368,-0.02539,,,,,0.04931393939,-0.02904369709
189.367,0.77163,-0.0282,,,,,0.04676545455,-0.03225806452
189.867,0.73013,-0.02899,,,,,0.04425030303,-0.03316174788
190.367,0.68868,-0.03044,,,,,0.04173818182,-0.03482040723
190.867,0.64661,-0.03325,,,,,0.03918848485,-0.03803477465
191.367,0.60512,-0.03437,,,,,0.03667393939,-0.03931594601
191.867,0.56353,-0.03623,,,,,0.03415333333,-0.04144360558
192.367,0.52171,-0.03702,,,,,0.03161878788,-0.04234728895
192.867,0.4803,-0.03768,,,,,0.02910909091,-0.04310226493
193.367,0.43832,-0.03914,,,,,0.02656484848,-0.0447723633
193.867,0.39687,-0.04093,,,,,0.02405272727,-0.04681994967
194.367,0.35543,-0.04156,,,,,0.02154121212,-0.04754060856
194.867,0.31318,-0.0417,,,,,0.01898060606,-0.04770075498
195.367,0.27187,-0.04331,,,,,0.0164769697,-0.0495424388
195.867,0.23031,-0.04482,,,,,0.01395818182,-0.05126973233
196.367,0.18827,-0.04765,,,,,0.01141030303,-0.05450697781
196.867,0.14684,-0.04804,,,,,0.008899393939,-0.05495309998
197.367,0.10512,-0.04896,,,,,0.006370909091,-0.05600549073
197.867,0.06341,-0.05034,,,,,0.003843030303,-0.05758407687
198.367,0.02192,-0.04843,,,,,0.001328484848,-0.05539922215
198.634,-0.00021,-0.05144,,,,,-0.00001272727273,-0.05884237017
199.134,0.03678,-0.04665,,,,,0.002229090909,-0.05336307481
199.634,0.07818,-0.04253,,,,,0.004738181818,-0.04865019446
200.134,0.11995,-0.04122,,,,,0.00726969697,-0.04715168154
200.634,0.16168,-0.03931,,,,,0.009798787879,-0.04496682681
201.134,0.20299,-0.03751,,,,,0.01230242424,-0.04290780142
201.634,0.24508,-0.03482,,,,,0.01485333333,-0.03983070236
202.134,0.28667,-0.03385,,,,,0.01737393939,-0.03872111645
202.634,0.32803,-0.02943,,,,,0.01988060606,-0.0336650652
203.134,0.37007,-0.02978,,,,,0.02242848485,-0.03406543125
203.634,0.41156,-0.02934,,,,,0.0249430303,-0.03356211393
204.134,0.45323,-0.02428,,,,,0.02746848485,-0.02777396477
204.634,0.4951,-0.02483,,,,,0.03000606061,-0.02840311142
205.134,0.5363,-0.02351,,,,,0.0325030303,-0.02689315946
205.634,0.57846,-0.02463,,,,,0.03505818182,-0.02817433082
206.134,0.62011,-0.02218,,,,,0.03758242424,-0.02537176847
206.634,0.66121,-0.02133,,,,,0.04007333333,-0.02439945093
207.134,0.70347,-0.01829,,,,,0.04263454545,-0.02092198582
207.634,0.74498,-0.01724,,,,,0.04515030303,-0.01972088767
208.134,0.78645,-0.01624,,,,,0.04766363636,-0.01857698467
208.634,0.82837,-0.01492,,,,,0.05020424242,-0.01706703272
209.134,0.86982,-0.01333,,,,,0.05271636364,-0.01524822695
209.634,0.91163,-0.01362,,,,,0.05525030303,-0.01557995882
210.134,0.95339,-0.01358,,,,,0.05778121212,-0.0155342027
210.634,0.99465,-0.01011,,,,,0.06028181818,-0.0115648593
211.134,1.03676,-0.01033,,,,,0.06283393939,-0.01181651796
211.634,1.07825,-0.00854,,,,,0.06534848485,-0.009768931595
212.134,1.11976,-0.00567,,,,,0.06786424242,-0.006485929993
212.634,1.16178,-0.00343,,,,,0.07041090909,-0.00392358728
213.134,1.20301,-0.00132,,,,,0.07290969697,-0.001509951956
213.634,1.24497,-0.00251,,,,,0.07545272727,-0.002871196523
214.134,1.28678,0.00073,,,,,0.07798666667,0.0008350491878
214.634,1.32793,0.00114,,,,,0.08048060606,0.001304049417
215.134,1.37,0.00133,,,,,0.08303030303,0.001521390986
215.634,1.41173,0.00233,,,,,0.08555939394,0.002665293983
216.134,1.45293,0.00678,,,,,0.08805636364,0.00775566232
216.634,1.49517,0.00694,,,,,0.09061636364,0.007938686799
217.134,1.53654,0.00718,,,,,0.09312363636,0.008213223519
217.634,1.5782,0.00935,,,,,0.09564848485,0.01069549302
218.134,1.61998,0.00975,,,,,0.09818060606,0.01115305422
218.499,1.65017,0.01134,,,,,0.100010303,0.01297185999
218.9,1.62169,0.00531,,,,,0.09828424242,0.006074124914
219.4,1.58025,0.00284,,,,,0.09577272727,0.003248684512
219.9,1.53875,0.00058,,,,,0.09325757576,0.0006634637383
220.4,1.4967,-0.00209,,,,,0.09070909091,-0.002390757264
220.9,1.45526,-0.00536,,,,,0.08819757576,-0.006131320064
221.4,1.41354,-0.00693,,,,,0.08566909091,-0.007927247769
221.9,1.3719,-0.00804,,,,,0.08314545455,-0.009196980096
222.4,1.33036,-0.01071,,,,,0.08062787879,-0.0122512011
222.9,1.28831,-0.01316,,,,,0.07807939394,-0.01505376344
223.4,1.24698,-0.0119,,,,,0.07557454545,-0.01361244566
223.9,1.20541,-0.01552,,,,,0.07305515152,-0.01775337451
224.4,1.16324,-0.01843,,,,,0.07049939394,-0.02108213224
224.9,1.12194,-0.0188,,,,,0.06799636364,-0.02150537634
225.4,1.08031,-0.02116,,,,,0.06547333333,-0.02420498742
225.9,1.0384,-0.02148,,,,,0.06293333333,-0.02457103638
226.4,0.99698,-0.02443,,,,,0.0604230303,-0.02794555022
226.9,0.9551,-0.02456,,,,,0.05788484848,-0.02809425761
227.4,0.91356,-0.02517,,,,,0.05536727273,-0.02879203844
227.9,0.87206,-0.02602,,,,,0.05285212121,-0.02976435598
228.4,0.82997,-0.028,,,,,0.05030121212,-0.03202928392
228.9,0.78858,-0.02926,,,,,0.04779272727,-0.03347060169
229.4,0.7469,-0.03158,,,,,0.04526666667,-0.03612445665
229.9,0.70515,-0.0324,,,,,0.04273636364,-0.0370624571
230.4,0.66356,-0.03215,,,,,0.04021575758,-0.03677648135
230.9,0.62179,-0.03476,,,,,0.03768424242,-0.03976206818
231.4,0.58021,-0.03588,,,,,0.03516424242,-0.04104323953
231.9,0.53876,-0.03843,,,,,0.03265212121,-0.04396019218
232.4,0.49661,-0.03676,,,,,0.03009757576,-0.04204987417
232.9,0.45531,-0.03957,,,,,0.02759454545,-0.04526424159
233.4,0.4137,-0.0403,,,,,0.02507272727,-0.04609929078
233.9,0.37162,-0.04074,,,,,0.02252242424,-0.0466026081
234.4,0.3303,-0.04313,,,,,0.02001818182,-0.04933653626
234.9,0.28855,-0.04444,,,,,0.01748787879,-0.05083504919
235.4,0.24679,-0.0461,,,,,0.0149569697,-0.05273392816
235.9,0.20537,-0.04585,,,,,0.01244666667,-0.05244795241
236.4,0.1634,-0.04664,,,,,0.009903030303,-0.05335163578
236.9,0.12184,-0.04679,,,,,0.007384242424,-0.05352322123
237.4,0.08042,-0.05074,,,,,0.004873939394,-0.05804163807
237.9,0.03828,-0.05245,,,,,0.00232,-0.05999771219
238.366,-0.00007,-0.05348,,,,,-0.000004242424242,-0.06117593228
238.668,0.0195,-0.04908,,,,,0.001181818182,-0.05614275909
239.168,0.06166,-0.04693,,,,,0.003736969697,-0.05368336765
239.668,0.10331,-0.04599,,,,,0.006261212121,-0.05260809883
240.168,0.14466,-0.04216,,,,,0.008767272727,-0.04822695035
240.668,0.18664,-0.0404,,,,,0.01131151515,-0.04621368108
241.168,0.22827,-0.03819,,,,,0.01383454545,-0.04368565546
241.668,0.26981,-0.03729,,,,,0.01635212121,-0.04265614276
242.168,0.31175,-0.03535,,,,,0.01889393939,-0.04043697094
242.668,0.353,-0.03423,,,,,0.02139393939,-0.03915579959
243.168,0.39509,-0.03208,,,,,0.02394484848,-0.03669640814
243.668,0.43673,-0.03012,,,,,0.02646848485,-0.03445435827
244.168,0.47789,-0.02881,,,,,0.0289630303,-0.03295584534
244.668,0.52015,-0.02806,,,,,0.03152424242,-0.0320979181
245.168,0.5617,-0.02782,,,,,0.03404242424,-0.03182338138
245.668,0.60302,-0.02349,,,,,0.03654666667,-0.0268702814
246.168,0.645,-0.02278,,,,,0.03909090909,-0.02605811027
246.668,0.68646,-0.02011,,,,,0.04160363636,-0.02300388927
247.168,0.72822,-0.01784,,,,,0.04413454545,-0.02040722947
247.668,0.77002,-0.01815,,,,,0.04666787879,-0.0207618394
248.168,0.81129,-0.0162,,,,,0.04916909091,-0.01853122855
248.668,0.85345,-0.01514,,,,,0.05172424242,-0.01731869137
249.168,0.89502,-0.01273,,,,,0.05424363636,-0.01456188515
249.668,0.93637,-0.01153,,,,,0.05674969697,-0.01318920156
250.168,0.97852,-0.00977,,,,,0.05930424242,-0.01117593228
250.668,1.01982,-0.00979,,,,,0.06180727273,-0.01119881034
251.168,1.06156,-0.00841,,,,,0.0643369697,-0.009620224205
251.668,1.10347,-0.00636,,,,,0.0668769697,-0.007275223061
252.168,1.14465,-0.00751,,,,,0.06937272727,-0.008590711508
252.668,1.18667,-0.00576,,,,,0.07191939394,-0.006588881263
253.168,1.22834,-0.00425,,,,,0.07444484848,-0.004861587737
253.668,1.26962,-0.00161,,,,,0.07694666667,-0.001841683825
254.168,1.31175,-0.00151,,,,,0.0795,-0.001727293526
254.668,1.35331,-0.00121,,,,,0.08201878788,-0.001384122626
255.168,1.39477,-0.00034,,,,,0.08453151515,-0.000388927019
255.668,1.43676,0.00204,,,,,0.08707636364,0.002333562114
256.168,1.47812,0.00323,,,,,0.0895830303,0.00369480668
256.668,1.52002,0.00474,,,,,0.09212242424,0.005422100206
257.168,1.56168,0.00543,,,,,0.09464727273,0.006211393274
257.668,1.60299,0.00629,,,,,0.09715090909,0.007195149851
258.168,1.64511,0.00889,,,,,0.09970363636,0.01016929764
258.434,1.63913,0.00648,,,,,0.09934121212,0.007412491421
258.934,1.59708,0.00239,,,,,0.09679272727,0.002733928163
259.434,1.55532,-0.00131,,,,,0.09426181818,-0.001498512926
259.934,1.51383,-0.00426,,,,,0.09174727273,-0.004873026767
260.434,1.47184,-0.0048,,,,,0.08920242424,-0.005490734386
260.934,1.43051,-0.00726,,,,,0.08669757576,-0.008304735758
261.434,1.38882,-0.00849,,,,,0.08417090909,-0.009711736445
261.934,1.34682,-0.01025,,,,,0.08162545455,-0.01172500572
262.434,1.30546,-0.01245,,,,,0.07911878788,-0.01424159231
262.934,1.26373,-0.01237,,,,,0.07658969697,-0.01415008007
263.434,1.22185,-0.01407,,,,,0.07405151515,-0.01609471517
263.934,1.18053,-0.01564,,,,,0.07154727273,-0.01789064287
264.434,1.13853,-0.01886,,,,,0.06900181818,-0.02157401052
264.934,1.09703,-0.01822,,,,,0.06648666667,-0.02084191261
265.434,1.05561,-0.0215,,,,,0.06397636364,-0.02459391444
265.934,1.01346,-0.02162,,,,,0.06142181818,-0.0247311828
266.434,0.97206,-0.02564,,,,,0.05891272727,-0.02932967284
266.934,0.93051,-0.02572,,,,,0.05639454545,-0.02942118508
267.434,0.8886,-0.02699,,,,,0.05385454545,-0.03087394189
267.934,0.84707,-0.03107,,,,,0.05133757576,-0.03554106612
268.434,0.80532,-0.03115,,,,,0.04880727273,-0.03563257836
268.934,0.76375,-0.03144,,,,,0.04628787879,-0.03596431023
269.434,0.72226,-0.03074,,,,,0.04377333333,-0.03516357813
269.934,0.68008,-0.03484,,,,,0.0412169697,-0.03985358042
270.434,0.63874,-0.03685,,,,,0.03871151515,-0.04215282544
270.934,0.59725,-0.03663,,,,,0.0361969697,-0.04190116678
271.434,0.55508,-0.03898,,,,,0.03364121212,-0.04458933882
271.934,0.51378,-0.03945,,,,,0.03113818182,-0.04512697323
272.434,0.47208,-0.04076,,,,,0.02861090909,-0.04662548616
272.934,0.43024,-0.04224,,,,,0.02607515152,-0.04831846259
273.434,0.3888,-0.0432,,,,,0.02356363636,-0.04941660947
273.934,0.34692,-0.04299,,,,,0.02102545455,-0.04917638984
274.434,0.30542,-0.0453,,,,,0.01851030303,-0.05181880577
274.934,0.26386,-0.04505,,,,,0.01599151515,-0.05153283002
275.434,0.22188,-0.04687,,,,,0.01344727273,-0.05361473347
275.934,0.18042,-0.04966,,,,,0.01093454545,-0.05680622283
276.434,0.13876,-0.05131,,,,,0.00840969697,-0.05869366278
276.934,0.09691,-0.0506,,,,,0.005873333333,-0.05788149165
277.434,0.05549,-0.05229,,,,,0.003363030303,-0.05981468771
277.934,0.01352,-0.05447,,,,,0.0008193939394,-0.06230839625
278.204,0.00216,-0.05185,,,,,0.0001309090909,-0.0593113704
278.704,0.04486,-0.04946,,,,,0.002718787879,-0.05657744223
279.204,0.08644,-0.04626,,,,,0.005238787879,-0.05291695264
279.704,0.12835,-0.04369,,,,,0.007778787879,-0.04997712194
280.204,0.16979,-0.04299,,,,,0.01029030303,-0.04917638984
280.704,0.21164,-0.0407,,,,,0.01282666667,-0.04655685198
281.204,0.25336,-0.03849,,,,,0.01535515152,-0.04402882636
281.704,0.29453,-0.03444,,,,,0.01785030303,-0.03939601922
282.204,0.33682,-0.03657,,,,,0.02041333333,-0.0418325326
282.704,0.37833,-0.03485,,,,,0.02292909091,-0.03986501945
283.204,0.41961,-0.0313,,,,,0.02543090909,-0.03580416381
283.704,0.46173,-0.03066,,,,,0.02798363636,-0.03507206589
284.204,0.50316,-0.02979,,,,,0.03049454545,-0.03407687028
284.704,0.54484,-0.0285,,,,,0.03302060606,-0.03260123542
285.204,0.58664,-0.02779,,,,,0.03555393939,-0.03178906429
285.704,0.62803,-0.02459,,,,,0.03806242424,-0.0281285747
286.204,0.66998,-0.02345,,,,,0.04060484848,-0.02682452528
286.704,0.71169,-0.02104,,,,,0.04313272727,-0.02406771906
287.204,0.75299,-0.01992,,,,,0.04563575758,-0.0227865477
287.704,0.79507,-0.0177,,,,,0.04818606061,-0.02024708305
288.204,0.83653,-0.01704,,,,,0.05069878788,-0.01949210707
288.704,0.8782,-0.01555,,,,,0.05322424242,-0.0177876916
289.204,0.92011,-0.01287,,,,,0.05576424242,-0.01472203157
289.704,0.96124,-0.01267,,,,,0.0582569697,-0.01449325097
290.204,1.00338,-0.01202,,,,,0.06081090909,-0.01374971402
290.704,1.04497,-0.01105,,,,,0.06333151515,-0.01264012812
291.204,1.08623,-0.00749,,,,,0.06583212121,-0.008567833448
291.704,1.12818,-0.00645,,,,,0.06837454545,-0.007378174331
292.204,1.17,-0.00596,,,,,0.07090909091,-0.006817661862
292.704,1.21134,-0.0061,,,,,0.07341454545,-0.006977808282
293.204,1.25343,-0.00467,,,,,0.07596545455,-0.005342026996
293.704,1.29471,-0.00221,,,,,0.07846727273,-0.002528025623
294.204,1.33663,-0.00163,,,,,0.08100787879,-0.001864561885
294.704,1.37828,-0.00133,,,,,0.08353212121,-0.001521390986
295.204,1.41961,0.00042,,,,,0.0860369697,0.0004804392588
295.704,1.46177,0.00107,,,,,0.08859212121,0.001223976207
296.204,1.50331,0.00219,,,,,0.09110969697,0.002505147563
296.704,1.54464,0.00515,,,,,0.09361454545,0.005891100435
297.204,1.58675,0.00504,,,,,0.09616666667,0.005765271105
297.704,1.62814,0.00679,,,,,0.09867515152,0.00776710135
297.97,1.65023,0.00804,,,,,0.1000139394,0.009196980096
298.47,1.61362,0.0038,,,,,0.09779515152,0.004346831389
298.97,1.57208,-0.00141,,,,,0.09527757576,-0.001612903226
299.47,1.52989,-0.0022,,,,,0.09272060606,-0.002516586593
299.97,1.48865,-0.00442,,,,,0.09022121212,-0.005056051247
300.47,1.44697,-0.00673,,,,,0.08769515152,-0.00769846717
300.97,1.40495,-0.00856,,,,,0.08514848485,-0.009791809655
301.47,1.36359,-0.01003,,,,,0.08264181818,-0.01147334706
301.97,1.32188,-0.01021,,,,,0.08011393939,-0.0116792496
302.47,1.28009,-0.01298,,,,,0.07758121212,-0.0148478609
302.97,1.23874,-0.016,,,,,0.07507515152,-0.01830244795
303.47,1.19666,-0.01682,,,,,0.07252484848,-0.01924044841
303.97,1.1552,-0.0187,,,,,0.07001212121,-0.02139098604
304.47,1.11373,-0.02137,,,,,0.06749878788,-0.02444520705
304.97,1.07166,-0.02241,,,,,0.06494909091,-0.02563486616
305.47,1.03024,-0.02346,,,,,0.06243878788,-0.02683596431
305.97,0.9885,-0.02546,,,,,0.05990909091,-0.0291237703
306.47,0.94688,-0.02778,,,,,0.05738666667,-0.03177762526
306.97,0.90524,-0.02914,,,,,0.0548630303,-0.03333333333
307.47,0.86333,-0.03005,,,,,0.0523230303,-0.03437428506
307.97,0.82187,-0.03187,,,,,0.04981030303,-0.03645618852
308.47,0.78038,-0.03438,,,,,0.04729575758,-0.03932738504
308.97,0.7382,-0.03476,,,,,0.04473939394,-0.03976206818
309.47,0.69696,-0.03597,,,,,0.04224,-0.0411461908
309.97,0.65527,-0.03819,,,,,0.03971333333,-0.04368565546
310.47,0.61334,-0.03714,,,,,0.03717212121,-0.04248455731
310.97,0.572,-0.03838,,,,,0.03466666667,-0.04390299703
311.47,0.53012,-0.03917,,,,,0.03212848485,-0.04480668039
311.97,0.4885,-0.04208,,,,,0.02960606061,-0.04813543811
312.47,0.44707,-0.04315,,,,,0.02709515152,-0.04935941432
312.97,0.40501,-0.04248,,,,,0.02454606061,-0.04859299931
313.47,0.36352,-0.04291,,,,,0.02203151515,-0.0490848776
313.97,0.32201,-0.04506,,,,,0.01951575758,-0.05154426905
314.47,0.27998,-0.04646,,,,,0.01696848485,-0.05314573324
314.97,0.23863,-0.04645,,,,,0.01446242424,-0.05313429421
315.47,0.19677,-0.04785,,,,,0.01192545455,-0.05473575841
315.97,0.1552,-0.04974,,,,,0.009406060606,-0.05689773507
316.47,0.11373,-0.05204,,,,,0.006892727273,-0.05952871197
316.97,0.07161,-0.05223,,,,,0.00434,-0.05974605353
317.47,0.03021,-0.05313,,,,,0.001830909091,-0.06077556623
317.837,-0.00015,-0.05428,,,,,-0.000009090909091,-0.06209105468
318.238,0.02818,-0.05105,,,,,0.001707878788,-0.058396248
318.738,0.07001,-0.04899,,,,,0.004243030303,-0.05603980782
319.238,0.11123,-0.04562,,,,,0.006741212121,-0.05218485472
319.738,0.15337,-0.04287,,,,,0.009295151515,-0.04903912148
320.238,0.19492,-0.04186,,,,,0.01181333333,-0.04788377946
320.738,0.23618,-0.03851,,,,,0.01431393939,-0.04405170442
321.238,0.27837,-0.03773,,,,,0.01687090909,-0.04315946008
321.738,0.31986,-0.03727,,,,,0.01938545455,-0.0426332647
322.238,0.36143,-0.03548,,,,,0.02190484848,-0.04058567833
322.738,0.40322,-0.03416,,,,,0.02443757576,-0.03907572638
323.238,0.44474,-0.03311,,,,,0.02695393939,-0.03787462823
323.738,0.48658,-0.03171,,,,,0.02948969697,-0.03627316404
324.238,0.52832,-0.0278,,,,,0.03201939394,-0.03180050332
324.738,0.56957,-0.02621,,,,,0.03451939394,-0.02998169755
325.238,0.61171,-0.02608,,,,,0.03707333333,-0.02983299016
325.738,0.65318,-0.02619,,,,,0.03958666667,-0.02995881949
326.238,0.69475,-0.02278,,,,,0.04210606061,-0.02605811027
326.738,0.73673,-0.02085,,,,,0.04465030303,-0.02385037749
327.238,0.77797,-0.01954,,,,,0.04714969697,-0.02235186456
327.738,0.81993,-0.01873,,,,,0.04969272727,-0.02142530313
328.238,0.86165,-0.01822,,,,,0.05222121212,-0.02084191261
328.738,0.90282,-0.01514,,,,,0.05471636364,-0.01731869137
329.238,0.945,-0.01311,,,,,0.05727272727,-0.01499656829
329.738,0.98667,-0.01215,,,,,0.05979818182,-0.01389842141
330.238,1.02795,-0.01085,,,,,0.0623,-0.01241134752
330.738,1.07002,-0.01003,,,,,0.06484969697,-0.01147334706
331.238,1.11146,-0.0085,,,,,0.06736121212,-0.009723175475
331.738,1.15323,-0.00659,,,,,0.06989272727,-0.00753832075
332.238,1.19501,-0.00587,,,,,0.07242484848,-0.006714710593
332.738,1.23639,-0.00453,,,,,0.07493272727,-0.005181880577
333.238,1.27839,-0.00364,,,,,0.07747818182,-0.004163806909
333.738,1.31988,-0.00279,,,,,0.07999272727,-0.003191489362
334.238,1.36126,-0.00085,,,,,0.08250060606,-0.0009723175475
334.738,1.40344,0.00052,,,,,0.0850569697,0.0005948295585
335.238,1.44459,0.00062,,,,,0.08755090909,0.0007092198582
335.738,1.48645,0.00236,,,,,0.09008787879,0.002699611073
336.238,1.52839,0.00348,,,,,0.09262969697,0.00398078243
336.738,1.56955,0.00655,,,,,0.09512424242,0.007492564631
337.238,1.61157,0.00579,,,,,0.09767090909,0.006623198353
337.703,1.65009,0.00672,,,,,0.1000054545,0.00768702814
338.005,1.63072,0.00362,,,,,0.09883151515,0.004140928849
338.505,1.58875,0.00083,,,,,0.09628787879,0.0009494394875
339.005,1.54737,-0.00162,,,,,0.09378,-0.001853122855
339.505,1.50551,-0.00432,,,,,0.0912430303,-0.004941660947
340.005,1.46387,-0.00756,,,,,0.08871939394,-0.008647906658
340.505,1.42247,-0.0088,,,,,0.08621030303,-0.01006634637
341.005,1.38041,-0.01244,,,,,0.08366121212,-0.01423015328
341.505,1.33897,-0.01071,,,,,0.08114969697,-0.0122512011
342.005,1.29751,-0.01574,,,,,0.0786369697,-0.01800503317
342.505,1.25537,-0.01622,,,,,0.0760830303,-0.01855410661
343.005,1.21397,-0.01732,,,,,0.07357393939,-0.01981239991
343.505,1.17227,-0.01864,,,,,0.07104666667,-0.02132235186
344.005,1.13059,-0.02073,,,,,0.06852060606,-0.02371310913
344.505,1.08902,-0.02328,,,,,0.06600121212,-0.02663006177
345.005,1.04705,-0.02458,,,,,0.06345757576,-0.02811713567
345.505,1.00566,-0.02737,,,,,0.06094909091,-0.03130862503
346.005,0.96413,-0.02648,,,,,0.05843212121,-0.03029055136
346.505,0.9219,-0.02737,,,,,0.05587272727,-0.03130862503
347.005,0.88064,-0.03132,,,,,0.05337212121,-0.03582704187
347.505,0.83906,-0.03195,,,,,0.05085212121,-0.03654770075
348.005,0.79709,-0.03276,,,,,0.04830848485,-0.03747426218
348.505,0.75572,-0.03485,,,,,0.04580121212,-0.03986501945
349.005,0.71384,-0.03418,,,,,0.0432630303,-0.03909860444
349.505,0.67225,-0.0373,,,,,0.04074242424,-0.04266758179
350.005,0.63079,-0.0371,,,,,0.03822969697,-0.04243880119
350.505,0.58873,-0.03796,,,,,0.03568060606,-0.04342255777
351.005,0.54728,-0.04033,,,,,0.03316848485,-0.04613360787
351.505,0.50567,-0.04057,,,,,0.03064666667,-0.04640814459
352.005,0.46385,-0.04148,,,,,0.02811212121,-0.04744909632
352.505,0.42226,-0.04305,,,,,0.02559151515,-0.04924502402
353.005,0.38051,-0.04489,,,,,0.02306121212,-0.05134980554
353.505,0.33888,-0.04646,,,,,0.02053818182,-0.05314573324
354.005,0.29741,-0.04524,,,,,0.01802484848,-0.05175017159
354.505,0.25527,-0.04641,,,,,0.01547090909,-0.05308853809
355.005,0.21402,-0.04883,,,,,0.01297090909,-0.05585678334
355.505,0.17244,-0.04988,,,,,0.01045090909,-0.05705788149
356.005,0.13032,-0.05061,,,,,0.007898181818,-0.05789293068
356.505,0.08903,-0.05139,,,,,0.005395757576,-0.05878517502
357.005,0.04733,-0.05311,,,,,0.002868484848,-0.06075268817
357.505,0.0055,-0.05559,,,,,0.0003333333333,-0.0635895676
357.777,0.01123,-0.05527,,,,,0.0006806060606,-0.06322351865
358.277,0.05286,-0.04951,,,,,0.003203636364,-0.05663463738
358.777,0.09515,-0.04746,,,,,0.005766666667,-0.05428963624
359.277,0.13665,-0.04488,,,,,0.008281818182,-0.05133836651
359.777,0.17803,-0.04334,,,,,0.01078969697,-0.04957675589
360.277,0.22014,-0.04245,,,,,0.01334181818,-0.04855868222
360.777,0.26148,-0.03902,,,,,0.01584727273,-0.04463509494
361.277,0.30327,-0.0391,,,,,0.01838,-0.04472660718
361.777,0.34504,-0.03817,,,,,0.02091151515,-0.0436627774
362.277,0.38637,-0.03301,,,,,0.02341636364,-0.03776023793
362.777,0.42833,-0.03353,,,,,0.02595939394,-0.03835506749
363.277,0.46996,-0.03241,,,,,0.02848242424,-0.03707389613
363.777,0.5114,-0.03073,,,,,0.03099393939,-0.0351521391
364.277,0.55347,-0.02932,,,,,0.03354363636,-0.03353923587
364.777,0.59474,-0.02757,,,,,0.03604484848,-0.03153740563
365.277,0.63664,-0.02591,,,,,0.03858424242,-0.02963852665
365.777,0.67845,-0.02609,,,,,0.04111818182,-0.02984442919
366.277,0.71949,-0.02278,,,,,0.04360545455,-0.02605811027
366.777,0.76179,-0.02247,,,,,0.04616909091,-0.02570350034
367.277,0.80341,-0.01983,,,,,0.04869151515,-0.02268359643
367.777,0.84465,-0.01988,,,,,0.05119090909,-0.02274079158
368.277,0.88661,-0.01754,,,,,0.05373393939,-0.02006405857
368.777,0.92827,-0.01598,,,,,0.05625878788,-0.01827956989
369.277,0.9698,-0.01462,,,,,0.05877575758,-0.01672386182
369.777,1.01177,-0.01349,,,,,0.06131939394,-0.01543125143
370.277,1.053,-0.01284,,,,,0.06381818182,-0.01468771448
370.777,1.09507,-0.01148,,,,,0.06636787879,-0.01313200641
371.277,1.13663,-0.00823,,,,,0.06888666667,-0.009414321666
371.777,1.17797,-0.00789,,,,,0.07139212121,-0.009025394647
372.277,1.22018,-0.00739,,,,,0.07395030303,-0.008453443148
372.777,1.2616,-0.00557,,,,,0.07646060606,-0.006371539693
373.277,1.30311,-0.00322,,,,,0.07897636364,-0.00368336765
373.777,1.34513,-0.00124,,,,,0.0815230303,-0.001418439716
374.277,1.38635,-0.00176,,,,,0.08402121212,-0.002013269275
374.777,1.42823,0.00064,,,,,0.08655939394,0.0007320979181
375.277,1.47015,0.00089,,,,,0.0891,0.001018073667
375.777,1.51127,0.00346,,,,,0.09159212121,0.00395790437
376.277,1.55346,0.00397,,,,,0.09414909091,0.004541294898
376.777,1.59507,0.00553,,,,,0.09667090909,0.006325783574
377.277,1.63634,0.00607,,,,,0.09917212121,0.006943491192
377.544,1.648,0.00357,,,,,0.09987878788,0.004083733699
378.044,1.60584,0.00179,,,,,0.09732363636,0.002047586365
378.544,1.56386,-0.00055,,,,,0.09477939394,-0.0006291466484
379.044,1.52229,-0.00437,,,,,0.09226,-0.004998856097
379.544,1.48088,-0.00581,,,,,0.08975030303,-0.006646076413
380.044,1.43877,-0.00892,,,,,0.08719818182,-0.01020361473
380.544,1.39734,-0.01033,,,,,0.08468727273,-0.01181651796
381.044,1.35576,-0.01087,,,,,0.08216727273,-0.01243422558
381.544,1.31385,-0.01412,,,,,0.07962727273,-0.01615191032
382.044,1.2724,-0.01578,,,,,0.07711515152,-0.01805078929
382.544,1.23047,-0.01609,,,,,0.07457393939,-0.01840539922
383.044,1.18907,-0.01861,,,,,0.07206484848,-0.02128803477
383.544,1.14742,-0.019,,,,,0.06954060606,-0.02173415694
384.044,1.1054,-0.02191,,,,,0.06699393939,-0.02506291466
384.544,1.06407,-0.02329,,,,,0.06448909091,-0.0266415008
385.044,1.02243,-0.02519,,,,,0.06196545455,-0.0288149165
385.544,0.98045,-0.02648,,,,,0.05942121212,-0.03029055136
386.044,0.93914,-0.02856,,,,,0.05691757576,-0.0326698696
386.544,0.89725,-0.03114,,,,,0.05437878788,-0.03562113933
387.044,0.85564,-0.03074,,,,,0.0518569697,-0.03516357813
387.544,0.81426,-0.0316,,,,,0.04934909091,-0.03614733471
388.044,0.7721,-0.03238,,,,,0.04679393939,-0.03703957904
388.544,0.73063,-0.03485,,,,,0.04428060606,-0.03986501945
389.044,0.68914,-0.03761,,,,,0.04176606061,-0.04302219172
389.544,0.64717,-0.03742,,,,,0.03922242424,-0.04280485015
390.044,0.60565,-0.03928,,,,,0.03670606061,-0.04493250972
390.544,0.56398,-0.04107,,,,,0.03418060606,-0.04698009609
391.044,0.52229,-0.04238,,,,,0.03165393939,-0.04847860901
391.544,0.48084,-0.04343,,,,,0.02914181818,-0.04967970716
392.044,0.43873,-0.04393,,,,,0.02658969697,-0.05025165866
392.544,0.39741,-0.04684,,,,,0.02408545455,-0.05358041638
393.044,0.35594,-0.04729,,,,,0.02157212121,-0.05409517273
393.544,0.31371,-0.04777,,,,,0.01901272727,-0.05464424617
394.044,0.27238,-0.04864,,,,,0.01650787879,-0.05563944178
394.544,0.23076,-0.05094,,,,,0.01398545455,-0.05827041867
395.044,0.18886,-0.05292,,,,,0.01144606061,-0.0605353466
395.544,0.1474,-0.05214,,,,,0.008933333333,-0.05964310226
396.044,0.10556,-0.0528,,,,,0.006397575758,-0.06039807824
396.544,0.06399,-0.05418,,,,,0.003878181818,-0.06197666438
397.044,0.02243,-0.05617,,,,,0.001359393939,-0.06425303134
397.315,-0.00005,-0.05594,,,,,-0.00000303030303,-0.06398993365