File: mechanical/hysteresis/databak/hmwg_hysteresis - conductive_2.csv
Time,Extension,Load,Length,Width,Thickness,CS Area,Strain,Stress
(s),(mm),(N),(mm),(mm),(mm),(mm^2),(mm/mm),(MPa)
0,0,-0.03187,16.5,2.82,0.32,0.9024,0,-0.03531693262
0.5,0.03884,0.08317,,,,,0.002353939394,0.09216533688
1,0.08041,0.13963,,,,,0.004873333333,0.1547318262
1.5,0.12176,0.17806,,,,,0.007379393939,0.1973182624
2,0.16386,0.21156,,,,,0.009930909091,0.2344414894
2.5,0.20534,0.23626,,,,,0.01244484848,0.2618129433
3,0.24696,0.25474,,,,,0.01496727273,0.2822916667
3.5,0.28889,0.27528,,,,,0.01750848485,0.3050531915
4,0.3301,0.29103,,,,,0.02000606061,0.3225066489
4.5,0.37207,0.30532,,,,,0.02254969697,0.3383421986
5,0.41382,0.32007,,,,,0.02508,0.3546875
5.5,0.45503,0.33155,,,,,0.02757757576,0.3674091312
6,0.49718,0.34445,,,,,0.03013212121,0.381704344
6.5,0.53875,0.35433,,,,,0.03265151515,0.3926529255
7,0.58018,0.36301,,,,,0.03516242424,0.4022717199
7.5,0.62216,0.37318,,,,,0.03770666667,0.4135416667
8,0.66357,0.38013,,,,,0.04021636364,0.4212433511
8.5,0.7054,0.38734,,,,,0.04275151515,0.429233156
9,0.74708,0.39645,,,,,0.04527757576,0.4393284574
9.5,0.78841,0.40204,,,,,0.04778242424,0.4455230496
10,0.83052,0.40912,,,,,0.05033454545,0.4533687943
10.5,0.87201,0.41631,,,,,0.05284909091,0.4613364362
11,0.91348,0.41959,,,,,0.05536242424,0.4649711879
11.5,0.95555,0.42915,,,,,0.05791212121,0.4755651596
12,0.99685,0.43452,,,,,0.06041515152,0.4815159574
12.5,1.03869,0.43927,,,,,0.06295090909,0.4867796986
13,1.08053,0.44577,,,,,0.06548666667,0.4939827128
13.5,1.12167,0.44856,,,,,0.06798,0.4970744681
14,1.16385,0.45348,,,,,0.07053636364,0.5025265957
14.5,1.20551,0.4597,,,,,0.07306121212,0.5094193262
15,1.24674,0.46205,,,,,0.07556,0.5120234929
15.5,1.28879,0.46857,,,,,0.07810848485,0.5192486702
16,1.33034,0.4725,,,,,0.08062666667,0.5236037234
16.5,1.37197,0.47477,,,,,0.08314969697,0.5261192376
17,1.41378,0.48042,,,,,0.08568363636,0.5323803191
17.5,1.45512,0.48161,,,,,0.08818909091,0.5336990248
18,1.49716,0.48502,,,,,0.0907369697,0.5374778369
18.5,1.53875,0.48883,,,,,0.09325757576,0.5416999113
19,1.58001,0.48931,,,,,0.09575818182,0.5422318262
19.5,1.62224,0.49436,,,,,0.09831757576,0.5478280142
19.841,1.65012,0.4953,,,,,0.1000072727,0.5488696809
20.242,1.62163,0.30655,,,,,0.09828060606,0.3397052305
20.742,1.5803,0.1753,,,,,0.09577575758,0.1942597518
21.242,1.5386,0.07989,,,,,0.09324848485,0.08853058511
21.742,1.49663,0.0039,,,,,0.09070484848,0.004321808511
22.242,1.4553,-0.05837,,,,,0.0882,-0.06468306738
22.742,1.41352,-0.11301,,,,,0.08566787879,-0.1252327128
23.242,1.37176,-0.16293,,,,,0.0831369697,-0.1805518617
23.742,1.33039,-0.20346,,,,,0.08062969697,-0.2254654255
24.242,1.28837,-0.24239,,,,,0.0780830303,-0.2686059397
24.742,1.24687,-0.27537,,,,,0.07556787879,-0.3051529255
25.242,1.20543,-0.30914,,,,,0.07305636364,-0.3425753546
25.742,1.16326,-0.34033,,,,,0.07050060606,-0.3771387411
26.242,1.12185,-0.36628,,,,,0.06799090909,-0.4058953901
26.742,1.08026,-0.39164,,,,,0.06547030303,-0.433998227
27.242,1.03845,-0.41626,,,,,0.06293636364,-0.4612810284
27.742,0.99692,-0.43775,,,,,0.06041939394,-0.4850953014
28.242,0.95505,-0.45764,,,,,0.05788181818,-0.5071365248
28.742,0.91356,-0.47882,,,,,0.05536727273,-0.5306072695
29.242,0.87208,-0.49414,,,,,0.05285333333,-0.5475842199
29.742,0.82989,-0.5138,,,,,0.05029636364,-0.5693705674
30.242,0.78858,-0.53055,,,,,0.04779272727,-0.5879321809
30.742,0.74706,-0.54489,,,,,0.04527636364,-0.6038231383
31.242,0.70496,-0.56244,,,,,0.04272484848,-0.6232712766
31.742,0.66359,-0.57685,,,,,0.04021757576,-0.639239805
32.242,0.62184,-0.59047,,,,,0.03768727273,-0.6543328901
32.742,0.58009,-0.60536,,,,,0.0351569697,-0.6708333333
33.242,0.53863,-0.6174,,,,,0.03264424242,-0.6841755319
33.742,0.49668,-0.63061,,,,,0.03010181818,-0.698814273
34.242,0.45522,-0.64288,,,,,0.02758909091,-0.7124113475
34.742,0.41363,-0.65533,,,,,0.02506848485,-0.7262078901
35.242,0.37168,-0.66923,,,,,0.02252606061,-0.7416112589
35.742,0.33025,-0.67944,,,,,0.02001515152,-0.7529255319
36.242,0.28852,-0.69137,,,,,0.01748606061,-0.7661458333
36.742,0.24676,-0.70103,,,,,0.01495515152,-0.7768506206
37.242,0.20533,-0.71197,,,,,0.01244424242,-0.7889738475
37.742,0.16329,-0.72103,,,,,0.009896363636,-0.7990137411
38.242,0.12193,-0.73205,,,,,0.00738969697,-0.8112256206
38.742,0.08042,-0.74026,,,,,0.004873939394,-0.8203235816
39.242,0.0382,-0.75075,,,,,0.002315151515,-0.8319481383
39.708,-0.00006,-0.75619,,,,,-0.000003636363636,-0.8379765071
40.01,0.01948,-0.67708,,,,,0.001180606061,-0.7503102837
40.51,0.06178,-0.60355,,,,,0.003744242424,-0.6688275709
41.01,0.10334,-0.55286,,,,,0.006263030303,-0.6126551418
41.51,0.14462,-0.51311,,,,,0.008764848485,-0.5686059397
42.01,0.18676,-0.47705,,,,,0.01131878788,-0.5286458333
42.51,0.22825,-0.44532,,,,,0.01383333333,-0.4934840426
43.01,0.26984,-0.41563,,,,,0.01635393939,-0.4605828901
43.51,0.31166,-0.38701,,,,,0.01888848485,-0.4288674645
44.01,0.35304,-0.36101,,,,,0.02139636364,-0.4000554078
44.51,0.395,-0.3341,,,,,0.02393939394,-0.3702349291
45.01,0.4367,-0.30748,,,,,0.02646666667,-0.3407358156
45.51,0.47796,-0.28559,,,,,0.02896727273,-0.3164782801
46.01,0.52013,-0.25864,,,,,0.0315230303,-0.2866134752
46.51,0.56164,-0.23554,,,,,0.03403878788,-0.2610150709
47.01,0.60314,-0.21312,,,,,0.03655393939,-0.2361702128
47.51,0.64511,-0.18769,,,,,0.03909757576,-0.207989805
48.01,0.68638,-0.16519,,,,,0.04159878788,-0.1830562943
48.51,0.72835,-0.14201,,,,,0.04414242424,-0.1573692376
49.01,0.77011,-0.11684,,,,,0.04667333333,-0.1294769504
49.51,0.81121,-0.09535,,,,,0.04916424242,-0.1056626773
50.01,0.85339,-0.07271,,,,,0.05172060606,-0.08057402482
50.51,0.89506,-0.04734,,,,,0.05424606061,-0.05246010638
51.01,0.93634,-0.0286,,,,,0.05674787879,-0.03169326241
51.51,0.97838,-0.00274,,,,,0.05929575758,-0.003036347518
52.01,1.01987,0.01972,,,,,0.06181030303,0.02185283688
52.51,1.06155,0.04142,,,,,0.06433636364,0.0458998227
53.01,1.10338,0.06537,,,,,0.06687151515,0.07244015957
53.51,1.14471,0.086,,,,,0.06937636364,0.09530141844
54.01,1.18676,0.10907,,,,,0.07192484848,0.120866578
54.51,1.2283,0.13088,,,,,0.07444242424,0.145035461
55.01,1.26971,0.15194,,,,,0.07695212121,0.168373227
55.51,1.3118,0.17577,,,,,0.0795030303,0.1947805851
56.01,1.35313,0.19644,,,,,0.08200787879,0.2176861702
56.51,1.39488,0.21678,,,,,0.08453818182,0.2402260638
57.01,1.43679,0.23912,,,,,0.08707818182,0.2649822695
57.51,1.47793,0.25657,,,,,0.08957151515,0.2843195922
58.01,1.51999,0.27675,,,,,0.09212060606,0.3066821809
58.51,1.56175,0.29375,,,,,0.09465151515,0.3255208333
59.01,1.60289,0.30959,,,,,0.09714484848,0.3430740248
59.51,1.64506,0.3289,,,,,0.09970060606,0.3644725177
59.777,1.63906,0.23433,,,,,0.0993369697,0.2596742021
60.277,1.59689,0.08772,,,,,0.09678121212,0.09720744681
60.777,1.55502,-0.00828,,,,,0.09424363636,-0.009175531915
61.277,1.51359,-0.08033,,,,,0.09173272727,-0.08901817376
61.777,1.47178,-0.14036,,,,,0.08919878788,-0.1555407801
62.277,1.43011,-0.19284,,,,,0.08667333333,-0.2136968085
62.777,1.38871,-0.23701,,,,,0.08416424242,-0.2626440603
63.277,1.34661,-0.27802,,,,,0.08161272727,-0.308089539
63.777,1.30516,-0.31352,,,,,0.07910060606,-0.347429078
64.277,1.26363,-0.34468,,,,,0.07658363636,-0.3819592199
64.777,1.2217,-0.37536,,,,,0.07404242424,-0.4159574468
65.277,1.18026,-0.40305,,,,,0.07153090909,-0.4466422872
65.777,1.13842,-0.4264,,,,,0.06899515152,-0.4725177305
66.277,1.09692,-0.45105,,,,,0.06648,-0.4998337766
66.777,1.05527,-0.47118,,,,,0.06395575758,-0.5221409574
67.277,1.01328,-0.4925,,,,,0.06141090909,-0.545766844
67.777,0.97186,-0.51242,,,,,0.05890060606,-0.5678413121
68.277,0.9303,-0.53049,,,,,0.05638181818,-0.5878656915
68.777,0.88816,-0.54997,,,,,0.05382787879,-0.6094525709
69.277,0.84696,-0.56434,,,,,0.05133090909,-0.625376773
69.777,0.80521,-0.58066,,,,,0.04880060606,-0.6434618794
70.277,0.76341,-0.59743,,,,,0.04626727273,-0.662045656
70.777,0.72202,-0.61012,,,,,0.04375878788,-0.676108156
71.277,0.68001,-0.62466,,,,,0.04121272727,-0.6922207447
71.777,0.63847,-0.63867,,,,,0.03869515152,-0.7077460106
72.277,0.59703,-0.64988,,,,,0.03618363636,-0.7201684397
72.777,0.55498,-0.6649,,,,,0.03363515152,-0.7368129433
73.277,0.5135,-0.67654,,,,,0.03112121212,-0.7497118794
73.777,0.47191,-0.68695,,,,,0.02860060606,-0.7612477837
74.277,0.43003,-0.70068,,,,,0.02606242424,-0.776462766
74.777,0.38867,-0.70915,,,,,0.02355575758,-0.7858488475
75.277,0.34667,-0.72005,,,,,0.02101030303,-0.7979277482
75.777,0.30523,-0.73119,,,,,0.01849878788,-0.8102726064
76.277,0.26375,-0.74013,,,,,0.01598484848,-0.8201795213
76.777,0.22158,-0.75136,,,,,0.01342909091,-0.8326241135
77.277,0.18022,-0.76011,,,,,0.01092242424,-0.8423204787
77.777,0.13865,-0.76638,,,,,0.008403030303,-0.849268617
78.277,0.09662,-0.77664,,,,,0.005855757576,-0.8606382979
78.777,0.05517,-0.78153,,,,,0.003343636364,-0.8660571809
79.277,0.01352,-0.78557,,,,,0.0008193939394,-0.8705341312
79.545,0.00235,-0.77724,,,,,0.0001424242424,-0.8613031915
80.045,0.04491,-0.68933,,,,,0.002721818182,-0.763885195
80.545,0.08632,-0.63401,,,,,0.005231515152,-0.7025820035
81.045,0.12835,-0.58863,,,,,0.007778787879,-0.652293883
81.545,0.16967,-0.55455,,,,,0.0102830303,-0.6145279255
82.045,0.21158,-0.52226,,,,,0.0128230303,-0.5787455674
82.545,0.25328,-0.4928,,,,,0.01535030303,-0.5460992908
83.045,0.29467,-0.46634,,,,,0.01785878788,-0.5167774823
83.545,0.33665,-0.44031,,,,,0.0204030303,-0.4879321809
84.045,0.3783,-0.41462,,,,,0.02292727273,-0.4594636525
84.545,0.41973,-0.3932,,,,,0.02543818182,-0.4357269504
85.045,0.46172,-0.36938,,,,,0.0279830303,-0.4093306738
85.545,0.50302,-0.34722,,,,,0.03048606061,-0.3847739362
86.045,0.54497,-0.32606,,,,,0.03302848485,-0.3613253546
86.545,0.58667,-0.30118,,,,,0.03555575758,-0.3337544326
87.045,0.6279,-0.27978,,,,,0.03805454545,-0.3100398936
87.545,0.67007,-0.25688,,,,,0.04061030303,-0.2846631206
88.045,0.71164,-0.23425,,,,,0.04312969697,-0.2595855496
88.545,0.75291,-0.21615,,,,,0.04563090909,-0.2395279255
89.045,0.79492,-0.19388,,,,,0.0481769697,-0.2148492908
89.545,0.83654,-0.17064,,,,,0.05069939394,-0.1890957447
90.045,0.87813,-0.1518,,,,,0.05322,-0.1682180851
90.545,0.92007,-0.1268,,,,,0.05576181818,-0.1405141844
91.045,0.96128,-0.10592,,,,,0.05825939394,-0.1173758865
91.545,1.00341,-0.08271,,,,,0.06081272727,-0.09165558511
92.045,1.04498,-0.061,,,,,0.06333212121,-0.06759751773
92.545,1.0863,-0.04123,,,,,0.06583636364,-0.04568927305
93.045,1.12845,-0.01613,,,,,0.06839090909,-0.01787455674
93.545,1.1699,0.00704,,,,,0.0709030303,0.00780141844
94.045,1.21145,0.02779,,,,,0.07342121212,0.03079565603
94.545,1.25342,0.05222,,,,,0.07596484848,0.0578679078
95.045,1.29467,0.07441,,,,,0.07846484848,0.08245789007
95.545,1.33655,0.09539,,,,,0.0810030303,0.1057070035
96.045,1.37835,0.1191,,,,,0.08353636364,0.131981383
96.545,1.41952,0.13935,,,,,0.08603151515,0.1544215426
97.045,1.46172,0.16453,,,,,0.08858909091,0.1823249113
97.545,1.50332,0.18603,,,,,0.09111030303,0.206150266
98.045,1.54473,0.20593,,,,,0.09362,0.2282025709
98.545,1.58669,0.22732,,,,,0.0961630303,0.2519060284
99.045,1.6282,0.24696,,,,,0.09867878788,0.2736702128
99.313,1.65028,0.25839,,,,,0.1000169697,0.2863364362
99.813,1.61355,0.07418,,,,,0.09779090909,0.08220301418
100.313,1.57212,-0.02678,,,,,0.09528,-0.02967641844
100.813,1.53003,-0.10307,,,,,0.09272909091,-0.1142176418
101.313,1.48862,-0.16491,,,,,0.09021939394,-0.1827460106
101.813,1.4471,-0.21534,,,,,0.0877030303,-0.2386303191
102.313,1.40502,-0.26314,,,,,0.08515272727,-0.2916001773
102.813,1.3636,-0.30046,,,,,0.08264242424,-0.3329565603
103.313,1.32186,-0.33566,,,,,0.08011272727,-0.3719636525
103.813,1.28023,-0.3693,,,,,0.07758969697,-0.4092420213
104.313,1.2387,-0.39812,,,,,0.07507272727,-0.441179078
104.813,1.19663,-0.42491,,,,,0.0725230303,-0.470866578
105.313,1.15531,-0.4486,,,,,0.07001878788,-0.4971187943
105.813,1.11373,-0.47192,,,,,0.06749878788,-0.5229609929
106.313,1.07155,-0.49436,,,,,0.06494242424,-0.5478280142
106.813,1.03027,-0.5143,,,,,0.06244060606,-0.5699246454
107.313,0.98867,-0.53283,,,,,0.05991939394,-0.5904587766
107.813,0.94673,-0.55264,,,,,0.05737757576,-0.6124113475
108.313,0.90533,-0.56886,,,,,0.05486848485,-0.6303856383
108.813,0.86345,-0.58435,,,,,0.05233030303,-0.6475509752
109.313,0.82188,-0.59822,,,,,0.04981090909,-0.6629210993
109.813,0.78042,-0.61305,,,,,0.04729818182,-0.6793550532
110.313,0.73834,-0.62831,,,,,0.04474787879,-0.6962655142
110.813,0.69696,-0.64201,,,,,0.04224,-0.7114472518
111.313,0.65529,-0.65396,,,,,0.03971454545,-0.7246897163
111.813,0.61349,-0.66901,,,,,0.03718121212,-0.7413674645
112.313,0.57193,-0.67879,,,,,0.03466242424,-0.7522052305
112.813,0.53011,-0.69128,,,,,0.03212787879,-0.7660460993
113.313,0.4885,-0.70401,,,,,0.02960606061,-0.7801529255
113.813,0.44708,-0.71306,,,,,0.02709575758,-0.7901817376
114.313,0.4049,-0.72459,,,,,0.02453939394,-0.8029587766
114.813,0.36364,-0.73548,,,,,0.02203878788,-0.8150265957
115.313,0.32206,-0.74459,,,,,0.01951878788,-0.8251218972
115.813,0.27994,-0.75622,,,,,0.01696606061,-0.8380097518
116.313,0.23864,-0.76486,,,,,0.0144630303,-0.8475842199
116.813,0.19692,-0.77384,,,,,0.01193454545,-0.857535461
117.313,0.15515,-0.78327,,,,,0.009403030303,-0.8679853723
117.813,0.11368,-0.78647,,,,,0.00688969697,-0.8715314716
118.313,0.07177,-0.7907,,,,,0.00434969697,-0.8762189716
118.813,0.03023,-0.79392,,,,,0.001832121212,-0.879787234
119.18,-0.00011,-0.79453,,,,,-0.000006666666667,-0.8804632092
119.581,0.0283,-0.76366,,,,,0.001715151515,-0.8462544326
120.081,0.07002,-0.69036,,,,,0.004243636364,-0.7650265957
120.581,0.11132,-0.64129,,,,,0.006746666667,-0.7106493794
121.081,0.15345,-0.60139,,,,,0.0093,-0.6664339539
121.581,0.19503,-0.56911,,,,,0.01182,-0.6306626773
122.081,0.23639,-0.54124,,,,,0.01432666667,-0.5997783688
122.581,0.27844,-0.51228,,,,,0.01687515152,-0.5676861702
123.081,0.31993,-0.48708,,,,,0.01938969697,-0.5397606383
123.581,0.36161,-0.46455,,,,,0.02191575758,-0.514793883
124.081,0.40344,-0.43905,,,,,0.02445090909,-0.4865359043
124.581,0.44467,-0.41765,,,,,0.02694969697,-0.4628213652
125.081,0.48679,-0.39581,,,,,0.02950242424,-0.4386192376
125.581,0.52844,-0.3731,,,,,0.03202666667,-0.4134530142
126.081,0.56961,-0.35413,,,,,0.03452181818,-0.3924312943
126.581,0.61179,-0.33082,,,,,0.03707818182,-0.3666001773
127.081,0.65334,-0.30799,,,,,0.03959636364,-0.3413009752
127.581,0.6948,-0.28887,,,,,0.04210909091,-0.3201130319
128.081,0.73673,-0.26607,,,,,0.04465030303,-0.2948470745
128.581,0.77815,-0.24587,,,,,0.04716060606,-0.2724623227
129.081,0.81996,-0.22536,,,,,0.04969454545,-0.2497340426
129.581,0.86175,-0.20371,,,,,0.05222727273,-0.2257424645
130.081,0.90305,-0.18506,,,,,0.05473030303,-0.2050753546
130.581,0.94516,-0.16168,,,,,0.05728242424,-0.1791666667
131.081,0.98661,-0.13689,,,,,0.05979454545,-0.1516954787
131.581,1.02815,-0.11908,,,,,0.06231212121,-0.1319592199
132.081,1.07007,-0.09626,,,,,0.06485272727,-0.1066710993
132.581,1.11135,-0.07619,,,,,0.06735454545,-0.0844304078
133.081,1.15332,-0.05438,,,,,0.06989818182,-0.06026152482
133.581,1.19506,-0.0326,,,,,0.07242787879,-0.03612588652
134.081,1.23625,-0.0104,,,,,0.07492424242,-0.0115248227
134.581,1.27833,0.01159,,,,,0.07747454545,0.01284352837
135.081,1.32008,0.03653,,,,,0.08000484848,0.04048093972
135.581,1.36131,0.05751,,,,,0.08250363636,0.06373005319
136.081,1.40346,0.0819,,,,,0.08505818182,0.09075797872
136.581,1.44495,0.10443,,,,,0.08757272727,0.115724734
137.081,1.48661,0.12437,,,,,0.09009757576,0.1378213652
137.581,1.52836,0.14936,,,,,0.09262787879,0.1655141844
138.081,1.56974,0.17127,,,,,0.09513575758,0.189793883
138.581,1.61179,0.19485,,,,,0.09768424242,0.2159242021
139.046,1.65005,0.21365,,,,,0.1000030303,0.2367575355
139.348,1.63054,0.09208,,,,,0.09882060606,0.1020390071
139.848,1.58832,-0.02745,,,,,0.09626181818,-0.03041888298
140.348,1.54692,-0.10752,,,,,0.09375272727,-0.1191489362
140.848,1.50526,-0.1714,,,,,0.09122787879,-0.1899379433
141.348,1.46345,-0.2255,,,,,0.08869393939,-0.2498891844
141.848,1.42196,-0.26973,,,,,0.08617939394,-0.2989029255
142.348,1.38,-0.30793,,,,,0.08363636364,-0.3412344858
142.848,1.3386,-0.34474,,,,,0.08112727273,-0.3820257092
143.348,1.29694,-0.37542,,,,,0.07860242424,-0.4160239362
143.848,1.25493,-0.40799,,,,,0.07605636364,-0.452116578
144.348,1.21359,-0.43179,,,,,0.07355090909,-0.4784906915
144.848,1.17195,-0.45756,,,,,0.07102727273,-0.5070478723
145.348,1.12995,-0.48294,,,,,0.06848181818,-0.5351728723
145.848,1.08871,-0.50312,,,,,0.06598242424,-0.557535461
146.348,1.04679,-0.52247,,,,,0.06344181818,-0.5789782801
146.848,1.00519,-0.5418,,,,,0.06092060606,-0.6003989362
147.348,0.96378,-0.55849,,,,,0.05841090909,-0.6188940603
147.848,0.92164,-0.57612,,,,,0.0558569697,-0.6384308511
148.348,0.88021,-0.59358,,,,,0.05334606061,-0.6577792553
148.848,0.83868,-0.60804,,,,,0.05082909091,-0.6738031915
149.348,0.79668,-0.6225,,,,,0.04828363636,-0.6898271277
149.848,0.75518,-0.63713,,,,,0.04576848485,-0.7060394504
150.348,0.7135,-0.64941,,,,,0.04324242424,-0.7196476064
150.848,0.6718,-0.66685,,,,,0.04071515152,-0.7389738475
151.348,0.63038,-0.67659,,,,,0.03820484848,-0.7497672872
151.848,0.58828,-0.68797,,,,,0.03565333333,-0.7623781028
152.348,0.54692,-0.69867,,,,,0.03314666667,-0.7742353723
152.848,0.50544,-0.70982,,,,,0.03063272727,-0.7865913121
153.348,0.46323,-0.72267,,,,,0.02807454545,-0.800831117
153.848,0.42192,-0.73351,,,,,0.02557090909,-0.8128435284
154.348,0.38028,-0.74167,,,,,0.02304727273,-0.8218860816
154.848,0.33838,-0.7537,,,,,0.02050787879,-0.8352171986
155.348,0.29695,-0.76329,,,,,0.0179969697,-0.8458444149
155.848,0.25512,-0.77073,,,,,0.01546181818,-0.8540890957
156.348,0.21354,-0.78006,,,,,0.01294181818,-0.8644281915
156.848,0.17201,-0.78646,,,,,0.01042484848,-0.8715203901
157.348,0.12997,-0.79054,,,,,0.007876969697,-0.8760416667
157.848,0.0886,-0.79382,,,,,0.00536969697,-0.8796764184
158.348,0.04693,-0.79572,,,,,0.002844242424,-0.8817819149
158.848,0.00503,-0.79587,,,,,0.0003048484848,-0.8819481383
159.116,0.01118,-0.79078,,,,,0.0006775757576,-0.8763076241
159.616,0.05297,-0.75267,,,,,0.00321030303,-0.8340757979
160.116,0.09497,-0.68784,,,,,0.005755757576,-0.7622340426
160.616,0.13656,-0.64022,,,,,0.008276363636,-0.7094636525
161.116,0.17814,-0.60618,,,,,0.01079636364,-0.6717420213
161.616,0.22005,-0.57513,,,,,0.01333636364,-0.6373337766
162.116,0.26126,-0.54828,,,,,0.01583393939,-0.6075797872
162.616,0.30337,-0.52176,,,,,0.01838606061,-0.5781914894
163.116,0.34499,-0.4968,,,,,0.02090848485,-0.5505319149
163.616,0.38622,-0.47585,,,,,0.02340727273,-0.5273160461
164.116,0.42844,-0.4523,,,,,0.02596606061,-0.5012189716
164.616,0.46999,-0.42957,,,,,0.02848424242,-0.4760305851
165.116,0.51138,-0.41022,,,,,0.03099272727,-0.454587766
165.616,0.55334,-0.38691,,,,,0.03353575758,-0.4287566489
166.116,0.59479,-0.36587,,,,,0.03604787879,-0.4054410461
166.616,0.6366,-0.34645,,,,,0.03858181818,-0.383920656
167.116,0.67838,-0.32285,,,,,0.04111393939,-0.3577681738
167.616,0.7196,-0.30518,,,,,0.04361212121,-0.3381870567
168.116,0.76179,-0.28383,,,,,0.04616909091,-0.3145279255
168.616,0.80332,-0.26285,,,,,0.04868606061,-0.2912788121
169.116,0.8447,-0.24362,,,,,0.05119393939,-0.2699689716
169.616,0.88673,-0.22008,,,,,0.05374121212,-0.2438829787
170.116,0.92812,-0.20068,,,,,0.05624969697,-0.2223847518
170.616,0.96987,-0.18105,,,,,0.05878,-0.2006316489
171.116,1.01173,-0.15794,,,,,0.0613169697,-0.1750221631
171.616,1.0529,-0.13906,,,,,0.06381212121,-0.1541001773
172.116,1.09498,-0.11721,,,,,0.06636242424,-0.1298869681
172.616,1.13673,-0.09542,,,,,0.06889272727,-0.1057402482
173.116,1.17791,-0.0753,,,,,0.07138848485,-0.08344414894
173.616,1.22009,-0.05031,,,,,0.07394484848,-0.05575132979
174.116,1.26163,-0.02886,,,,,0.07646242424,-0.03198138298
174.616,1.30315,-0.00864,,,,,0.07897878788,-0.009574468085
175.116,1.34504,0.01656,,,,,0.08151757576,0.01835106383
175.616,1.38643,0.03781,,,,,0.08402606061,0.04189937943
176.116,1.42837,0.0612,,,,,0.08656787879,0.06781914894
176.616,1.46991,0.08584,,,,,0.08908545455,0.09512411348
177.116,1.51127,0.10669,,,,,0.09159212121,0.1182291667
177.616,1.55342,0.13163,,,,,0.09414666667,0.145866578
178.116,1.59484,0.15407,,,,,0.0966569697,0.1707335993
178.616,1.63638,0.17526,,,,,0.09917454545,0.1942154255
178.884,1.64767,0.14253,,,,,0.09985878788,0.1579454787
179.384,1.60544,-0.0106,,,,,0.09729939394,-0.0117464539
179.884,1.56352,-0.10099,,,,,0.09475878788,-0.1119126773
180.384,1.52205,-0.16906,,,,,0.09224545455,-0.1873448582
180.884,1.48054,-0.22392,,,,,0.08972969697,-0.2481382979
181.384,1.43832,-0.27189,,,,,0.08717090909,-0.3012965426
181.884,1.39715,-0.31029,,,,,0.08467575758,-0.343849734
182.384,1.35546,-0.34648,,,,,0.08214909091,-0.3839539007
182.884,1.31346,-0.38074,,,,,0.07960363636,-0.4219193262
183.384,1.27206,-0.40938,,,,,0.07709454545,-0.4536569149
183.884,1.23038,-0.43613,,,,,0.07456848485,-0.4833000887
184.384,1.18857,-0.46266,,,,,0.07203454545,-0.5126994681
184.884,1.14722,-0.48344,,,,,0.06952848485,-0.5357269504
185.384,1.10515,-0.50596,,,,,0.06697878788,-0.5606826241
185.884,1.06366,-0.52648,,,,,0.06446424242,-0.5834219858
186.384,1.02217,-0.54539,,,,,0.06194969697,-0.6043772163
186.884,0.98011,-0.5639,,,,,0.05940060606,-0.6248891844
187.384,0.93871,-0.58167,,,,,0.05689151515,-0.644581117
187.884,0.89694,-0.59816,,,,,0.05436,-0.6628546099
188.384,0.85535,-0.61214,,,,,0.05183939394,-0.6783466312
188.884,0.8137,-0.62739,,,,,0.04931515152,-0.6952460106
189.384,0.77181,-0.64259,,,,,0.04677636364,-0.7120899823
189.884,0.73037,-0.65484,,,,,0.04426484848,-0.7256648936
190.384,0.68886,-0.66764,,,,,0.04174909091,-0.7398492908
190.884,0.64664,-0.67981,,,,,0.03919030303,-0.7533355496
191.384,0.60545,-0.6918,,,,,0.03669393939,-0.7666223404
191.884,0.56373,-0.70362,,,,,0.03416545455,-0.7797207447
192.384,0.52183,-0.71604,,,,,0.03162606061,-0.7934840426
192.884,0.48051,-0.72551,,,,,0.02912181818,-0.8039782801
193.384,0.43853,-0.73617,,,,,0.02657757576,-0.8157912234
193.884,0.39696,-0.74772,,,,,0.02405818182,-0.8285904255
194.384,0.35548,-0.75805,,,,,0.02154424242,-0.8400376773
194.884,0.31349,-0.76806,,,,,0.01899939394,-0.8511303191
195.384,0.27199,-0.77603,,,,,0.01648424242,-0.8599623227
195.884,0.23044,-0.78291,,,,,0.01396606061,-0.8675864362
196.384,0.18844,-0.79019,,,,,0.01142060606,-0.8756538121
196.884,0.14709,-0.79395,,,,,0.008914545455,-0.8798204787
197.384,0.10523,-0.79549,,,,,0.006377575758,-0.881527039
197.884,0.0637,-0.79759,,,,,0.003860606061,-0.8838541667
198.384,0.02221,-0.79769,,,,,0.001346060606,-0.8839649823
198.654,-0.00024,-0.79763,,,,,-0.00001454545455,-0.8838984929
199.154,0.03668,-0.78222,,,,,0.002223030303,-0.8668218085
199.654,0.07807,-0.7361,,,,,0.004731515152,-0.8157136525
200.154,0.11998,-0.68129,,,,,0.007271515152,-0.7549756206
200.654,0.1617,-0.63885,,,,,0.0098,-0.7079454787
201.154,0.20287,-0.60489,,,,,0.01229515152,-0.6703125
201.654,0.24516,-0.57618,,,,,0.01485818182,-0.6384973404
202.154,0.2867,-0.54889,,,,,0.01737575758,-0.6082557624
202.654,0.32797,-0.52504,,,,,0.0198769697,-0.5818262411
203.154,0.37008,-0.49942,,,,,0.02242909091,-0.5534352837
203.654,0.41152,-0.47923,,,,,0.02494060606,-0.5310616135
204.154,0.4532,-0.45756,,,,,0.02746666667,-0.5070478723
204.654,0.49496,-0.43474,,,,,0.02999757576,-0.4817597518
205.154,0.53637,-0.41426,,,,,0.03250727273,-0.4590647163
205.654,0.57827,-0.39413,,,,,0.03504666667,-0.4367575355
206.154,0.62,-0.37452,,,,,0.03757575758,-0.4150265957
206.654,0.66131,-0.35256,,,,,0.04007939394,-0.3906914894
207.154,0.7034,-0.33045,,,,,0.04263030303,-0.3661901596
207.654,0.74479,-0.31347,,,,,0.04513878788,-0.3473736702
208.154,0.78653,-0.29356,,,,,0.04766848485,-0.3253102837
208.654,0.82838,-0.2722,,,,,0.05020484848,-0.3016400709
209.154,0.86961,-0.25344,,,,,0.05270363636,-0.2808510638
209.654,0.91173,-0.23191,,,,,0.05525636364,-0.2569924645
210.154,0.95336,-0.21168,,,,,0.05777939394,-0.2345744681
210.654,0.99455,-0.19295,,,,,0.06027575758,-0.2138187057
211.154,1.03664,-0.17008,,,,,0.06282666667,-0.1884751773
211.654,1.07831,-0.14889,,,,,0.06535212121,-0.1649933511
212.154,1.1197,-0.12901,,,,,0.06786060606,-0.1429632092
212.654,1.16177,-0.10628,,,,,0.07041030303,-0.1177748227
213.154,1.20304,-0.08584,,,,,0.07291151515,-0.09512411348
213.654,1.245,-0.06396,,,,,0.07545454545,-0.07087765957
214.154,1.28665,-0.04189,,,,,0.07797878788,-0.04642065603
214.654,1.32796,-0.0192,,,,,0.08048242424,-0.02127659574
215.154,1.37009,0.0054,,,,,0.08303575758,0.005984042553
215.654,1.41163,0.02674,,,,,0.08555333333,0.0296320922
216.154,1.45303,0.04953,,,,,0.08806242424,0.05488696809
216.654,1.49506,0.07316,,,,,0.09060969697,0.08107269504
217.154,1.53644,0.09694,,,,,0.09311757576,0.1074246454
217.654,1.57813,0.11861,,,,,0.09564424242,0.1314383865
218.154,1.62009,0.14442,,,,,0.09818727273,0.1600398936
218.521,1.65018,0.1568,,,,,0.1000109091,0.1737588652
218.922,1.62177,0.01397,,,,,0.09828909091,0.01548093972
219.422,1.58047,-0.08753,,,,,0.09578606061,-0.09699689716
219.922,1.53875,-0.1594,,,,,0.09325757576,-0.1766400709
220.422,1.49679,-0.21942,,,,,0.09071454545,-0.2431515957
220.922,1.45548,-0.26853,,,,,0.08821090909,-0.2975731383
221.422,1.41367,-0.30937,,,,,0.0856769697,-0.3428302305
221.922,1.37195,-0.34765,,,,,0.08314848485,-0.3852504433
222.422,1.33057,-0.37978,,,,,0.08064060606,-0.4208554965
222.922,1.28852,-0.41056,,,,,0.07809212121,-0.454964539
223.422,1.24703,-0.43917,,,,,0.07557757576,-0.486668883
223.922,1.20559,-0.46295,,,,,0.07306606061,-0.5130208333
224.422,1.16343,-0.488,,,,,0.07051090909,-0.5407801418
224.922,1.12202,-0.50856,,,,,0.06800121212,-0.5635638298
225.422,1.0804,-0.52732,,,,,0.06547878788,-0.5843528369
225.922,1.03862,-0.5481,,,,,0.06294666667,-0.6073803191
226.422,0.99711,-0.56447,,,,,0.06043090909,-0.6255208333
226.922,0.95519,-0.58123,,,,,0.05789030303,-0.6440935284
227.422,0.91373,-0.59966,,,,,0.05537757576,-0.664516844
227.922,0.87224,-0.61331,,,,,0.0528630303,-0.6796431738
228.422,0.83005,-0.62917,,,,,0.05030606061,-0.6972185284
228.922,0.78874,-0.6441,,,,,0.04780242424,-0.7137632979
229.422,0.74721,-0.65644,,,,,0.04528545455,-0.7274379433
229.922,0.70513,-0.66962,,,,,0.04273515152,-0.7420434397
230.422,0.66377,-0.68023,,,,,0.04022848485,-0.7538009752
230.922,0.622,-0.69352,,,,,0.0376969697,-0.7685283688
231.422,0.58029,-0.70704,,,,,0.03516909091,-0.7835106383
231.922,0.53884,-0.71761,,,,,0.0326569697,-0.7952238475
232.422,0.49679,-0.72825,,,,,0.03010848485,-0.8070146277
232.922,0.45537,-0.73903,,,,,0.02759818182,-0.8189605496
233.422,0.41376,-0.74926,,,,,0.02507636364,-0.8302969858
233.922,0.37188,-0.76198,,,,,0.02253818182,-0.8443927305
234.422,0.33042,-0.76959,,,,,0.02002545455,-0.8528257979
234.922,0.28866,-0.77925,,,,,0.01749454545,-0.8635305851
235.422,0.24694,-0.78673,,,,,0.01496606061,-0.8718195922
235.922,0.20551,-0.7915,,,,,0.01245515152,-0.8771054965
236.422,0.16344,-0.79631,,,,,0.009905454545,-0.882435727
236.922,0.12209,-0.79737,,,,,0.007399393939,-0.8836103723
237.422,0.08059,-0.79778,,,,,0.004884242424,-0.8840647163
237.922,0.03838,-0.79781,,,,,0.002326060606,-0.884097961
238.39,-0.00006,-0.79689,,,,,-0.000003636363636,-0.8830784574
238.692,0.01941,-0.78979,,,,,0.001176363636,-0.8752105496
239.192,0.06172,-0.77002,,,,,0.003740606061,-0.853302305
239.692,0.10327,-0.71925,,,,,0.006258787879,-0.7970412234
240.192,0.14459,-0.67006,,,,,0.008763030303,-0.7425310284
240.692,0.1867,-0.63063,,,,,0.01131515152,-0.6988364362
241.192,0.22817,-0.59969,,,,,0.01382848485,-0.6645500887
241.692,0.26979,-0.57404,,,,,0.01635090909,-0.6361258865
242.192,0.31156,-0.54812,,,,,0.01888242424,-0.6074024823
242.692,0.35299,-0.52388,,,,,0.02139333333,-0.5805407801
243.192,0.39494,-0.50281,,,,,0.02393575758,-0.5571919326
243.692,0.43665,-0.4777,,,,,0.02646363636,-0.5293661348
244.192,0.4779,-0.45981,,,,,0.02896363636,-0.5095412234
244.692,0.52003,-0.43776,,,,,0.0315169697,-0.485106383
245.192,0.56156,-0.4177,,,,,0.03403393939,-0.462876773
245.692,0.60308,-0.39756,,,,,0.03655030303,-0.4405585106
246.192,0.64503,-0.37607,,,,,0.03909272727,-0.4167442376
246.692,0.68631,-0.35757,,,,,0.04159454545,-0.3962433511
247.192,0.72829,-0.33847,,,,,0.04413878788,-0.3750775709
247.692,0.77004,-0.31808,,,,,0.04666909091,-0.3524822695
248.192,0.81116,-0.29871,,,,,0.04916121212,-0.3310172872
248.692,0.85334,-0.27807,,,,,0.05171757576,-0.3081449468
249.192,0.89499,-0.25733,,,,,0.05424181818,-0.2851617908
249.692,0.93628,-0.23901,,,,,0.05674424242,-0.2648603723
250.192,0.97834,-0.21694,,,,,0.05929333333,-0.2404033688
250.692,1.01978,-0.19642,,,,,0.06180484848,-0.2176640071
251.192,1.06149,-0.17622,,,,,0.06433272727,-0.1952792553
251.692,1.10334,-0.15383,,,,,0.06686909091,-0.1704676418
252.192,1.14463,-0.13377,,,,,0.06937151515,-0.1482380319
252.692,1.18667,-0.11155,,,,,0.07191939394,-0.123614805
253.192,1.22825,-0.0904,,,,,0.07443939394,-0.100177305
253.692,1.26967,-0.06977,,,,,0.07694969697,-0.0773160461
254.192,1.31173,-0.04528,,,,,0.07949878788,-0.05017730496
254.692,1.35304,-0.0242,,,,,0.08200242424,-0.02681737589
255.192,1.39484,-0.00282,,,,,0.08453575758,-0.003125
255.692,1.4367,0.02284,,,,,0.08707272727,0.02531028369
256.192,1.47788,0.04235,,,,,0.08956848485,0.0469304078
256.692,1.51992,0.06648,,,,,0.09211636364,0.07367021277
257.192,1.56169,0.09157,,,,,0.09464787879,0.1014738475
257.692,1.60284,0.11158,,,,,0.09714181818,0.1236480496
258.192,1.645,0.13676,,,,,0.0996969697,0.1515514184
258.46,1.63926,0.05886,,,,,0.09934909091,0.06522606383
258.96,1.59704,-0.06804,,,,,0.09679030303,-0.07539893617
259.46,1.55519,-0.15002,,,,,0.09425393939,-0.1662455674
259.96,1.51381,-0.2102,,,,,0.09174606061,-0.2329343972
260.46,1.47194,-0.26052,,,,,0.08920848485,-0.2886968085
260.96,1.43029,-0.30467,,,,,0.08668424242,-0.3376218972
261.46,1.38892,-0.34184,,,,,0.0841769697,-0.3788120567
261.96,1.3468,-0.37789,,,,,0.08162424242,-0.4187610816
262.46,1.30536,-0.40647,,,,,0.07911272727,-0.4504321809
262.96,1.2638,-0.43551,,,,,0.07659393939,-0.4826130319
263.46,1.22189,-0.46092,,,,,0.07405393939,-0.5107712766
263.96,1.18045,-0.48454,,,,,0.07154242424,-0.536945922
264.46,1.13857,-0.50607,,,,,0.06900424242,-0.5608045213
264.96,1.09713,-0.52559,,,,,0.06649272727,-0.582435727
265.46,1.05546,-0.54635,,,,,0.06396727273,-0.6054410461
265.96,1.01345,-0.56403,,,,,0.06142121212,-0.6250332447
266.46,0.97208,-0.5819,,,,,0.05891393939,-0.6448359929
266.96,0.93047,-0.59756,,,,,0.05639212121,-0.6621897163
267.46,0.88836,-0.61689,,,,,0.05384,-0.6836103723
267.96,0.84713,-0.62965,,,,,0.05134121212,-0.6977504433
268.46,0.80535,-0.64332,,,,,0.04880909091,-0.7128989362
268.96,0.76362,-0.65994,,,,,0.04628,-0.7313164894
269.46,0.72223,-0.6691,,,,,0.04377151515,-0.7414671986
269.96,0.68016,-0.68253,,,,,0.04122181818,-0.756349734
270.46,0.63865,-0.69569,,,,,0.03870606061,-0.7709330674
270.96,0.59722,-0.70753,,,,,0.03619515152,-0.7840536348
271.46,0.55517,-0.71853,,,,,0.03364666667,-0.7962433511
271.96,0.51368,-0.72868,,,,,0.03113212121,-0.8074911348
272.46,0.47206,-0.74021,,,,,0.02860969697,-0.8202681738
272.96,0.43024,-0.75104,,,,,0.02607515152,-0.8322695035
273.46,0.38889,-0.76107,,,,,0.02356909091,-0.8433843085
273.96,0.34683,-0.76925,,,,,0.02102,-0.8524490248
274.46,0.30541,-0.77847,,,,,0.01850969697,-0.8626662234
274.96,0.26394,-0.78563,,,,,0.01599636364,-0.8706006206
275.46,0.22175,-0.79208,,,,,0.01343939394,-0.877748227
275.96,0.18042,-0.79637,,,,,0.01093454545,-0.8825022163
276.46,0.13882,-0.79672,,,,,0.008413333333,-0.8828900709
276.96,0.09682,-0.79809,,,,,0.005867878788,-0.8844082447
277.46,0.05539,-0.79659,,,,,0.003356969697,-0.8827460106
277.96,0.01367,-0.7983,,,,,0.0008284848485,-0.8846409574
278.23,0.00237,-0.79512,,,,,0.0001436363636,-0.8811170213
278.73,0.04495,-0.78683,,,,,0.002724242424,-0.8719304078
279.23,0.08635,-0.75955,,,,,0.005233333333,-0.8416999113
279.73,0.12838,-0.70176,,,,,0.007780606061,-0.7776595745
280.23,0.16972,-0.65465,,,,,0.01028606061,-0.725454344
280.73,0.21161,-0.62425,,,,,0.01282484848,-0.6917664007
281.23,0.2533,-0.5943,,,,,0.01535151515,-0.6585771277
281.73,0.29466,-0.56877,,,,,0.01785818182,-0.6302859043
282.23,0.33665,-0.54422,,,,,0.0204030303,-0.6030806738
282.73,0.37831,-0.51983,,,,,0.02292787879,-0.5760527482
283.23,0.41976,-0.50008,,,,,0.02544,-0.5541666667
283.73,0.46176,-0.47675,,,,,0.02798545455,-0.5283133865
284.23,0.50305,-0.45767,,,,,0.03048787879,-0.5071697695
284.73,0.545,-0.43593,,,,,0.03303030303,-0.4830784574
285.23,0.58669,-0.41563,,,,,0.0355569697,-0.4605828901
285.73,0.62791,-0.39804,,,,,0.03805515152,-0.4410904255
286.23,0.67012,-0.37748,,,,,0.04061333333,-0.4183067376
286.73,0.71167,-0.35819,,,,,0.04313151515,-0.3969304078
287.23,0.75292,-0.34235,,,,,0.04563151515,-0.3793772163
287.73,0.79493,-0.32014,,,,,0.04817757576,-0.3547650709
288.23,0.83657,-0.2998,,,,,0.05070121212,-0.3322251773
288.73,0.87815,-0.28176,,,,,0.05322121212,-0.3122340426
289.23,0.92009,-0.26135,,,,,0.0557630303,-0.289616578
289.73,0.96132,-0.24182,,,,,0.05826181818,-0.2679742908
290.23,1.00342,-0.22051,,,,,0.06081333333,-0.2443594858
290.73,1.04501,-0.19736,,,,,0.06333393939,-0.2187056738
291.23,1.08631,-0.17984,,,,,0.0658369697,-0.1992907801
291.73,1.12849,-0.15783,,,,,0.06839333333,-0.174900266
292.23,1.1699,-0.13758,,,,,0.0709030303,-0.1524601064
292.73,1.21144,-0.11721,,,,,0.07342060606,-0.1298869681
293.23,1.25345,-0.09219,,,,,0.07596666667,-0.1021609043
293.73,1.2947,-0.07083,,,,,0.07846666667,-0.07849069149
294.23,1.33657,-0.05043,,,,,0.08100424242,-0.05588430851
294.73,1.37838,-0.0257,,,,,0.08353818182,-0.02847960993
295.23,1.41956,-0.00614,,,,,0.08603393939,-0.006804078014
295.73,1.46174,0.01771,,,,,0.08859030303,0.01962544326
296.23,1.50336,0.04212,,,,,0.09111272727,0.04667553191
296.73,1.54474,0.06355,,,,,0.09362060606,0.0704233156
297.23,1.58673,0.08976,,,,,0.09616545455,0.09946808511
297.73,1.62824,0.11184,,,,,0.09868121212,0.1239361702
297.998,1.65028,0.1247,,,,,0.1000169697,0.1381870567
298.498,1.61376,-0.04163,,,,,0.09780363636,-0.04613253546
298.998,1.57231,-0.13026,,,,,0.09529151515,-0.1443484043
299.498,1.53021,-0.19844,,,,,0.09274,-0.2199024823
299.998,1.48881,-0.25242,,,,,0.09023090909,-0.2797207447
300.498,1.44726,-0.29836,,,,,0.08771272727,-0.3306294326
300.998,1.40524,-0.33818,,,,,0.08516606061,-0.3747562057
301.498,1.36382,-0.3729,,,,,0.08265575758,-0.413231383
301.998,1.32204,-0.40452,,,,,0.08012363636,-0.4482712766
302.498,1.28045,-0.43085,,,,,0.0776030303,-0.4774490248
302.998,1.23894,-0.4568,,,,,0.07508727273,-0.5062056738
303.498,1.19681,-0.48244,,,,,0.07253393939,-0.5346187943
303.998,1.15551,-0.50524,,,,,0.07003090909,-0.5598847518
304.498,1.11394,-0.52515,,,,,0.06751151515,-0.5819481383
304.998,1.07178,-0.54639,,,,,0.06495636364,-0.6054853723
305.498,1.03047,-0.56406,,,,,0.06245272727,-0.6250664894
305.998,0.98885,-0.58316,,,,,0.05993030303,-0.6462322695
306.498,0.94695,-0.5994,,,,,0.05739090909,-0.6642287234
306.998,0.90558,-0.61368,,,,,0.05488363636,-0.6800531915
307.498,0.86362,-0.62953,,,,,0.05234060606,-0.6976174645
307.998,0.82207,-0.6437,,,,,0.04982242424,-0.7133200355
308.498,0.78062,-0.65623,,,,,0.04731030303,-0.7272052305
308.998,0.73856,-0.67087,,,,,0.04476121212,-0.7434286348
309.498,0.69715,-0.68166,,,,,0.04225151515,-0.7553856383
309.998,0.65545,-0.6952,,,,,0.03972424242,-0.7703900709
310.498,0.61373,-0.70582,,,,,0.03719575758,-0.7821586879
310.998,0.57213,-0.71574,,,,,0.03467454545,-0.7931515957
311.498,0.5303,-0.72773,,,,,0.03213939394,-0.8064383865
311.998,0.48874,-0.74046,,,,,0.02962060606,-0.8205452128
312.498,0.44728,-0.74955,,,,,0.02710787879,-0.8306183511
312.998,0.4051,-0.76094,,,,,0.02455151515,-0.8432402482
313.498,0.36384,-0.77021,,,,,0.02205090909,-0.8535128546
313.998,0.32224,-0.77932,,,,,0.01952969697,-0.863608156
314.498,0.28017,-0.78774,,,,,0.01698,-0.8729388298
314.998,0.23885,-0.79221,,,,,0.01447575758,-0.8778922872
315.498,0.19708,-0.79488,,,,,0.01194424242,-0.8808510638
315.998,0.15537,-0.79675,,,,,0.009416363636,-0.8829233156
316.498,0.11392,-0.79849,,,,,0.006904242424,-0.8848515071
316.998,0.07196,-0.79714,,,,,0.004361212121,-0.8833554965
317.498,0.03044,-0.7983,,,,,0.001844848485,-0.8846409574
317.867,-0.00008,-0.79848,,,,,-0.000004848484848,-0.8848404255
318.268,0.02834,-0.79137,,,,,0.001717575758,-0.8769614362
318.768,0.07005,-0.77717,,,,,0.004245454545,-0.8612256206
319.268,0.11137,-0.73607,,,,,0.00674969697,-0.8156804078
319.768,0.15348,-0.68433,,,,,0.009301818182,-0.7583444149
320.268,0.19509,-0.64415,,,,,0.01182363636,-0.7138187057
320.768,0.23641,-0.61516,,,,,0.01432787879,-0.6816932624
321.268,0.2785,-0.58622,,,,,0.01687878788,-0.649623227
321.768,0.31998,-0.56102,,,,,0.01939272727,-0.621697695
322.268,0.36165,-0.54112,,,,,0.02191818182,-0.5996453901
322.768,0.40348,-0.51794,,,,,0.02445333333,-0.5739583333
323.268,0.44472,-0.49785,,,,,0.02695272727,-0.5516954787
323.768,0.48684,-0.47615,,,,,0.02950545455,-0.5276484929
324.268,0.5285,-0.45507,,,,,0.03203030303,-0.5042885638
324.768,0.56964,-0.43659,,,,,0.03452363636,-0.4838098404
325.268,0.61183,-0.41678,,,,,0.03708060606,-0.4618572695
325.768,0.6534,-0.39721,,,,,0.0396,-0.440170656
326.268,0.69484,-0.38042,,,,,0.04211151515,-0.4215647163
326.768,0.73679,-0.35826,,,,,0.04465393939,-0.3970079787
327.268,0.7782,-0.33794,,,,,0.04716363636,-0.3744902482
327.768,0.82002,-0.31843,,,,,0.04969818182,-0.3528701241
328.268,0.8618,-0.29793,,,,,0.05223030303,-0.3301529255
328.768,0.90311,-0.28029,,,,,0.05473393939,-0.3106050532
329.268,0.9452,-0.25973,,,,,0.05728484848,-0.2878213652
329.768,0.98668,-0.24062,,,,,0.05979878788,-0.2666445035
330.268,1.02821,-0.22124,,,,,0.06231575758,-0.2451684397
330.768,1.07015,-0.20044,,,,,0.06485757576,-0.2221187943
331.268,1.11143,-0.18013,,,,,0.06735939394,-0.1996121454
331.768,1.15339,-0.16007,,,,,0.06990242424,-0.1773825355
332.268,1.19512,-0.13817,,,,,0.07243151515,-0.1531139184
332.768,1.23632,-0.11895,,,,,0.07492848485,-0.1318151596
333.268,1.2784,-0.0965,,,,,0.07747878788,-0.1069370567
333.768,1.32014,-0.07273,,,,,0.08000848485,-0.08059618794
334.268,1.36137,-0.05218,,,,,0.08250727273,-0.05782358156
334.768,1.40352,-0.02611,,,,,0.08506181818,-0.0289339539
335.268,1.44495,-0.00357,,,,,0.08757272727,-0.003956117021
335.768,1.48665,0.01833,,,,,0.0901,0.0203125
336.268,1.52845,0.04235,,,,,0.09263333333,0.0469304078
336.768,1.56978,0.06299,,,,,0.09513818182,0.06980274823
337.268,1.61183,0.08899,,,,,0.09768666667,0.09861480496
337.732,1.65001,0.10763,,,,,0.1000006061,0.1192708333
338.034,1.63066,-0.0021,,,,,0.09882787879,-0.00232712766
338.534,1.58848,-0.11122,,,,,0.09627151515,-0.1232491135
339.034,1.54707,-0.18329,,,,,0.09376181818,-0.2031139184
339.534,1.5054,-0.23978,,,,,0.09123636364,-0.2657136525
340.034,1.46361,-0.28778,,,,,0.08870363636,-0.3189051418
340.534,1.42213,-0.33015,,,,,0.08618969697,-0.3658577128
341.034,1.38014,-0.36719,,,,,0.08364484848,-0.4069038121
341.534,1.33876,-0.39927,,,,,0.0811369697,-0.4424534574
342.034,1.29711,-0.42796,,,,,0.07861272727,-0.4742464539
342.534,1.2551,-0.45605,,,,,0.07606666667,-0.5053745567
343.034,1.21374,-0.48003,,,,,0.07356,-0.5319481383
343.534,1.17207,-0.50126,,,,,0.07103454545,-0.5554742908
344.034,1.13012,-0.52439,,,,,0.06849212121,-0.5811059397
344.534,1.08886,-0.54226,,,,,0.06599151515,-0.6009086879
345.034,1.04692,-0.55947,,,,,0.06344969697,-0.6199800532
345.534,1.00536,-0.57901,,,,,0.06093090909,-0.641633422
346.034,0.96395,-0.59353,,,,,0.05842121212,-0.6577238475
346.534,0.92181,-0.61067,,,,,0.05586727273,-0.6767176418
347.034,0.88036,-0.62658,,,,,0.05335515152,-0.6943484043
347.534,0.83881,-0.64072,,,,,0.0508369697,-0.7100177305
348.034,0.79687,-0.65475,,,,,0.04829515152,-0.7255651596
348.534,0.75533,-0.66697,,,,,0.04577757576,-0.7391068262
349.034,0.7136,-0.67979,,,,,0.04324848485,-0.7533133865
349.534,0.67198,-0.69261,,,,,0.04072606061,-0.7675199468
350.034,0.63055,-0.70477,,,,,0.03821515152,-0.7809951241
350.534,0.58842,-0.7171,,,,,0.03566181818,-0.7946586879
351.034,0.54706,-0.72818,,,,,0.03315515152,-0.8069370567
351.534,0.50558,-0.73876,,,,,0.03064121212,-0.8186613475
352.034,0.46342,-0.74946,,,,,0.02808606061,-0.830518617
352.534,0.42208,-0.75946,,,,,0.02558060606,-0.8416001773
353.034,0.38042,-0.76911,,,,,0.02305575758,-0.852293883
353.534,0.33858,-0.77872,,,,,0.02052,-0.8629432624
354.034,0.29715,-0.78602,,,,,0.01800909091,-0.8710328014
354.534,0.25523,-0.79112,,,,,0.01546848485,-0.8766843972
355.034,0.2137,-0.79496,,,,,0.01295151515,-0.8809397163
355.534,0.17216,-0.79638,,,,,0.01043393939,-0.8825132979
356.034,0.13011,-0.79826,,,,,0.007885454545,-0.8845966312
356.534,0.08875,-0.79913,,,,,0.005378787879,-0.885560727
357.034,0.04706,-0.8001,,,,,0.002852121212,-0.8866356383
357.534,0.00522,-0.79883,,,,,0.0003163636364,-0.8852282801
357.804,0.01113,-0.798,,,,,0.0006745454545,-0.8843085106
358.304,0.05293,-0.78525,,,,,0.003207878788,-0.8701795213
358.804,0.09492,-0.76391,,,,,0.005752727273,-0.8465314716
359.304,0.1365,-0.71252,,,,,0.008272727273,-0.7895833333
359.804,0.1781,-0.66901,,,,,0.01079393939,-0.7413674645
360.304,0.21999,-0.6344,,,,,0.01333272727,-0.7030141844
360.804,0.26119,-0.60603,,,,,0.01582969697,-0.6715757979
361.304,0.3033,-0.58007,,,,,0.01838181818,-0.6428080674
361.804,0.34491,-0.55763,,,,,0.02090363636,-0.6179410461
362.304,0.38616,-0.5337,,,,,0.02340363636,-0.5914228723
362.804,0.42838,-0.51397,,,,,0.02596242424,-0.5695589539
363.304,0.46989,-0.49212,,,,,0.02847818182,-0.5453457447
363.804,0.51134,-0.47327,,,,,0.03099030303,-0.5244570035
364.304,0.55327,-0.45394,,,,,0.03353151515,-0.5030363475
364.804,0.59474,-0.4354,,,,,0.03604484848,-0.4824911348
365.304,0.63652,-0.41654,,,,,0.0385769697,-0.4615913121
365.804,0.67833,-0.39546,,,,,0.04111090909,-0.438231383
366.304,0.71956,-0.37661,,,,,0.04360969697,-0.4173426418
366.804,0.76172,-0.35688,,,,,0.04616484848,-0.3954787234
367.304,0.80326,-0.33902,,,,,0.04868242424,-0.3756870567
367.804,0.84463,-0.32035,,,,,0.05118969697,-0.3549977837
368.304,0.88673,-0.29816,,,,,0.05374121212,-0.3304078014
368.804,0.92807,-0.27644,,,,,0.05624666667,-0.3063386525
369.304,0.96983,-0.25984,,,,,0.05877757576,-0.2879432624
369.804,1.0117,-0.23586,,,,,0.06131515152,-0.2613696809
370.304,1.05287,-0.21986,,,,,0.06381030303,-0.2436391844
370.804,1.09494,-0.20065,,,,,0.06636,-0.2223515071
371.304,1.13668,-0.17833,,,,,0.06888969697,-0.1976174645
371.804,1.17787,-0.16011,,,,,0.07138606061,-0.1774268617
372.304,1.22001,-0.13864,,,,,0.07394,-0.1536347518
372.804,1.26158,-0.11533,,,,,0.07645939394,-0.1278036348
373.304,1.30311,-0.09597,,,,,0.07897636364,-0.106349734
373.804,1.34498,-0.07179,,,,,0.08151393939,-0.07955452128
374.304,1.38637,-0.04945,,,,,0.08402242424,-0.0547983156
374.804,1.42834,-0.02722,,,,,0.08656606061,-0.03016400709
375.304,1.46987,-0.00313,,,,,0.0890830303,-0.003468528369
375.804,1.51125,0.01732,,,,,0.09159090909,0.01919326241
376.304,1.55335,0.04149,,,,,0.09414242424,0.04597739362
376.804,1.59477,0.06487,,,,,0.09665272727,0.07188608156
377.304,1.63632,0.08644,,,,,0.09917090909,0.09578900709
377.572,1.64777,0.05982,,,,,0.09986484848,0.06628989362
378.072,1.60548,-0.08384,,,,,0.09730181818,-0.09290780142
378.572,1.56358,-0.16602,,,,,0.09476242424,-0.1839760638
379.072,1.52211,-0.22814,,,,,0.09224909091,-0.2528147163
379.572,1.48061,-0.27788,,,,,0.08973393939,-0.3079343972
380.072,1.43837,-0.32192,,,,,0.08717393939,-0.3567375887
380.572,1.3972,-0.35706,,,,,0.08467878788,-0.3956781915
381.072,1.35552,-0.39173,,,,,0.08215272727,-0.434097961
381.572,1.31352,-0.42356,,,,,0.07960727273,-0.4693705674
382.072,1.27213,-0.45093,,,,,0.07709878788,-0.4997007979
382.572,1.23042,-0.4751,,,,,0.07457090909,-0.5264849291
383.072,1.1886,-0.49897,,,,,0.07203636364,-0.5529366135
383.572,1.14726,-0.51926,,,,,0.06953090909,-0.5754210993
384.072,1.1052,-0.53823,,,,,0.06698181818,-0.5964428191
384.572,1.06371,-0.55779,,,,,0.06446727273,-0.6181183511
385.072,1.02221,-0.5745,,,,,0.06195212121,-0.6366356383
385.572,0.98017,-0.59322,,,,,0.05940424242,-0.6573803191
386.072,0.93875,-0.60896,,,,,0.05689393939,-0.674822695
386.572,0.89698,-0.62597,,,,,0.05436242424,-0.6936724291
387.072,0.85542,-0.64017,,,,,0.05184363636,-0.7094082447
387.572,0.81375,-0.65424,,,,,0.04931818182,-0.725
388.072,0.77184,-0.66611,,,,,0.04677818182,-0.7381538121
388.572,0.73041,-0.68034,,,,,0.04426727273,-0.7539228723
389.072,0.68892,-0.69222,,,,,0.04175272727,-0.767087766
389.572,0.64671,-0.70448,,,,,0.03919454545,-0.7806737589
390.072,0.60552,-0.71367,,,,,0.03669818182,-0.7908577128
390.572,0.5638,-0.72451,,,,,0.03416969697,-0.8028701241
391.072,0.52189,-0.73724,,,,,0.03162969697,-0.8169769504
391.572,0.48056,-0.74767,,,,,0.02912484848,-0.8285350177
392.072,0.43859,-0.75794,,,,,0.02658121212,-0.8399157801
392.572,0.39702,-0.76933,,,,,0.02406181818,-0.8525376773
393.072,0.35553,-0.77793,,,,,0.02154727273,-0.8620678191
393.572,0.31354,-0.78622,,,,,0.01900242424,-0.8712544326
394.072,0.27205,-0.79123,,,,,0.01648787879,-0.8768062943
394.572,0.2305,-0.79532,,,,,0.01396969697,-0.8813386525
395.072,0.18849,-0.79659,,,,,0.01142363636,-0.8827460106
395.572,0.14715,-0.79879,,,,,0.008918181818,-0.8851839539
396.072,0.10529,-0.79774,,,,,0.006381212121,-0.8840203901
396.572,0.06372,-0.79872,,,,,0.003861818182,-0.885106383
397.072,0.02228,-0.79746,,,,,0.00135030303,-0.8837101064
397.34,-0.00004,-0.79945,,,,,-0.000002424242424,-0.8859153369