File: mechanical/hysteresis/databak/hmwg_hysteresis - conductive_4.csv
Time,Extension,Load,Length,Width,Thickness,CS Area,Strain,Stress
(s),(mm),(N),(mm),(mm),(mm),(mm^2),(mm/mm),(MPa)
0,0,-0.03247,16.5,2.82,0.31,0.8742,0,-0.03714253031
0.5,0.03825,0.04147,,,,,0.002318181818,0.04743765729
1,0.08046,0.08228,,,,,0.004876363636,0.0941203386
1.5,0.122,0.10989,,,,,0.007393939394,0.1257035003
2,0.16346,0.12719,,,,,0.009906666667,0.1454930222
2.5,0.20541,0.14133,,,,,0.01244909091,0.1616678106
3,0.24682,0.15272,,,,,0.01495878788,0.1746968657
3.5,0.28863,0.16065,,,,,0.01749272727,0.1837680165
4,0.33041,0.16906,,,,,0.02002484848,0.1933882407
4.5,0.37172,0.17398,,,,,0.02252848485,0.1990162434
5,0.41382,0.18013,,,,,0.02508,0.2060512469
5.5,0.4553,0.18462,,,,,0.02759393939,0.2111873713
6,0.49682,0.18747,,,,,0.03011030303,0.2144474949
6.5,0.53873,0.19303,,,,,0.03265030303,0.2208075955
7,0.58002,0.19571,,,,,0.03515272727,0.2238732555
7.5,0.62197,0.19789,,,,,0.03769515152,0.2263669641
8,0.66373,0.20169,,,,,0.04022606061,0.2307137955
8.5,0.70493,0.20382,,,,,0.0427230303,0.2331503089
9,0.74702,0.20623,,,,,0.04527393939,0.2359071151
9.5,0.78876,0.20844,,,,,0.04780363636,0.2384351407
10,0.82999,0.20875,,,,,0.05030242424,0.2387897506
10.5,0.87214,0.21295,,,,,0.0528569697,0.2435941432
11,0.91359,0.21488,,,,,0.05536909091,0.245801876
11.5,0.95526,0.21451,,,,,0.05789454545,0.2453786319
12,0.99704,0.21614,,,,,0.06042666667,0.2472431938
12.5,1.03839,0.21688,,,,,0.06293272727,0.248089682
13,1.08046,0.2185,,,,,0.06548242424,0.2499428049
13.5,1.12203,0.22018,,,,,0.06800181818,0.2518645619
14,1.1633,0.2193,,,,,0.0705030303,0.2508579272
14.5,1.20544,0.2214,,,,,0.0730569697,0.2532601235
15,1.24692,0.22204,,,,,0.07557090909,0.2539922215
15.5,1.28841,0.21995,,,,,0.07808545455,0.2516014642
16,1.33049,0.22323,,,,,0.08063575758,0.255353466
16.5,1.37174,0.22343,,,,,0.08313575758,0.2555822466
17,1.41372,0.22503,,,,,0.08568,0.2574124914
17.5,1.45539,0.22295,,,,,0.08820545455,0.2550331732
18,1.4967,0.22555,,,,,0.09070909091,0.258007321
18.5,1.53877,0.22684,,,,,0.09325878788,0.2594829558
19,1.5804,0.22817,,,,,0.09578181818,0.2610043468
19.5,1.62179,0.22596,,,,,0.09829030303,0.2584763212
19.838,1.65014,0.22959,,,,,0.1000084848,0.2626286891
20.239,1.62152,0.11372,,,,,0.09827393939,0.1300846488
20.739,1.58011,0.03043,,,,,0.09576424242,0.0348089682
21.239,1.53804,-0.03136,,,,,0.09321454545,-0.03587279799
21.739,1.49659,-0.08166,,,,,0.09070242424,-0.09341111874
22.239,1.45508,-0.12206,,,,,0.08818666667,-0.1396247998
22.739,1.41302,-0.16054,,,,,0.08563757576,-0.1836421871
23.239,1.37163,-0.19117,,,,,0.08312909091,-0.2186799359
23.739,1.32988,-0.22043,,,,,0.08059878788,-0.2521505376
24.239,1.28825,-0.24682,,,,,0.07807575758,-0.2823381377
24.739,1.2466,-0.26999,,,,,0.07555151515,-0.3088423702
25.239,1.20472,-0.29162,,,,,0.07301333333,-0.333584992
25.739,1.16324,-0.31327,,,,,0.07049939394,-0.3583504919
26.239,1.12176,-0.33153,,,,,0.06798545455,-0.3792381606
26.739,1.07956,-0.34993,,,,,0.06542787879,-0.4002859757
27.239,1.03834,-0.36566,,,,,0.06292969697,-0.4182795699
27.739,0.99664,-0.37989,,,,,0.06040242424,-0.4345573095
28.239,0.95472,-0.39664,,,,,0.05786181818,-0.4537176847
28.739,0.91335,-0.40985,,,,,0.05535454545,-0.4688286433
29.239,0.87146,-0.42296,,,,,0.05281575758,-0.4838252116
29.739,0.82989,-0.43582,,,,,0.05029636364,-0.4985358042
30.239,0.7884,-0.44735,,,,,0.04778181818,-0.5117250057
30.739,0.74639,-0.45763,,,,,0.04523575758,-0.5234843285
31.239,0.70489,-0.46962,,,,,0.04272060606,-0.5371997255
31.739,0.66338,-0.47887,,,,,0.04020484848,-0.5477808282
32.239,0.62134,-0.48843,,,,,0.0376569697,-0.5587165408
32.739,0.57999,-0.4974,,,,,0.03515090909,-0.5689773507
33.239,0.53815,-0.50667,,,,,0.03261515152,-0.5795813315
33.739,0.49655,-0.51474,,,,,0.03009393939,-0.5888126287
34.239,0.4551,-0.52267,,,,,0.02758181818,-0.5978837795
34.739,0.41298,-0.53267,,,,,0.02502909091,-0.6093228094
35.239,0.37162,-0.54085,,,,,0.02252242424,-0.6186799359
35.739,0.33006,-0.54784,,,,,0.02000363636,-0.6266758179
36.239,0.28797,-0.55545,,,,,0.01745272727,-0.6353809197
36.739,0.2466,-0.56267,,,,,0.01494545455,-0.6436398993
37.239,0.20504,-0.56952,,,,,0.01242666667,-0.6514756349
37.739,0.16315,-0.57622,,,,,0.009887878788,-0.6591397849
38.239,0.12171,-0.58307,,,,,0.007376363636,-0.6669755205
38.739,0.07976,-0.58772,,,,,0.004833939394,-0.6722946694
39.239,0.03834,-0.59423,,,,,0.002323636364,-0.6797414779
39.695,-0.00001,-0.59829,,,,,-0.0000006060606061,-0.6843857241
39.997,0.02058,-0.54967,,,,,0.001247272727,-0.6287691604
40.497,0.06199,-0.50839,,,,,0.003756969697,-0.5815488447
40.997,0.10407,-0.47425,,,,,0.006307272727,-0.5424959963
41.497,0.14566,-0.45063,,,,,0.008827878788,-0.5154770075
41.997,0.18705,-0.42868,,,,,0.01133636364,-0.4903683368
42.497,0.22909,-0.4077,,,,,0.01388424242,-0.4663692519
42.997,0.27051,-0.38653,,,,,0.01639454545,-0.4421528254
43.497,0.31226,-0.36907,,,,,0.01892484848,-0.4221802791
43.997,0.35406,-0.35013,,,,,0.02145818182,-0.4005147563
44.497,0.39526,-0.33306,,,,,0.02395515152,-0.3809883322
44.997,0.43743,-0.31636,,,,,0.02651090909,-0.3618851521
45.497,0.47909,-0.29884,,,,,0.02903575758,-0.3418439716
45.997,0.52024,-0.28365,,,,,0.03152969697,-0.3244680851
46.497,0.56247,-0.26652,,,,,0.03408909091,-0.3048730268
46.997,0.60397,-0.25124,,,,,0.03660424242,-0.287394189
47.497,0.64549,-0.23581,,,,,0.03912060606,-0.2697437657
47.997,0.68739,-0.21964,,,,,0.04166,-0.2512468543
48.497,0.72881,-0.20598,,,,,0.04417030303,-0.2356211393
48.997,0.77065,-0.19023,,,,,0.04670606061,-0.2176046671
49.497,0.81237,-0.17482,,,,,0.04923454545,-0.1999771219
49.997,0.85368,-0.1605,,,,,0.05173818182,-0.183596431
50.497,0.89581,-0.14438,,,,,0.05429151515,-0.1651567147
50.997,0.93722,-0.13078,,,,,0.05680121212,-0.149599634
51.497,0.97879,-0.11702,,,,,0.05932060606,-0.1338595287
51.997,1.02076,-0.1014,,,,,0.06186424242,-0.1159917639
52.497,1.06201,-0.08851,,,,,0.06436424242,-0.1012468543
52.997,1.104,-0.0732,,,,,0.06690909091,-0.08373369938
53.497,1.14575,-0.05931,,,,,0.06943939394,-0.06784488675
53.997,1.18692,-0.04651,,,,,0.07193454545,-0.05320292839
54.497,1.22903,-0.03259,,,,,0.07448666667,-0.03727979867
54.997,1.2707,-0.02022,,,,,0.07701212121,-0.0231297186
55.497,1.31196,-0.0063,,,,,0.07951272727,-0.007206588881
55.997,1.35416,0.00625,,,,,0.08207030303,0.007149393731
56.497,1.39549,0.01862,,,,,0.08457515152,0.0212994738
56.997,1.43726,0.02889,,,,,0.08710666667,0.03304735758
57.497,1.47899,0.04311,,,,,0.08963575758,0.0493136582
57.997,1.52036,0.05281,,,,,0.0921430303,0.06040951727
58.497,1.56244,0.06462,,,,,0.09469333333,0.07391901167
58.997,1.60401,0.07578,,,,,0.09721272727,0.08668496911
59.497,1.6453,0.08479,,,,,0.09971515152,0.09699153512
59.752,1.63862,0.02782,,,,,0.09931030303,0.03182338138
60.252,1.59633,-0.0619,,,,,0.09674727273,-0.07080759552
60.752,1.55491,-0.11808,,,,,0.0942369697,-0.1350720659
61.252,1.51328,-0.16473,,,,,0.09171393939,-0.1884351407
61.752,1.4715,-0.20365,,,,,0.08918181818,-0.2329558453
62.252,1.42994,-0.23784,,,,,0.0866630303,-0.2720658888
62.752,1.38809,-0.26584,,,,,0.08412666667,-0.3040951727
63.252,1.34656,-0.29292,,,,,0.08160969697,-0.3350720659
63.752,1.30509,-0.31592,,,,,0.07909636364,-0.3613818348
64.252,1.26292,-0.33955,,,,,0.07654060606,-0.3884122626
64.752,1.22159,-0.36005,,,,,0.07403575758,-0.4118622741
65.252,1.18004,-0.37745,,,,,0.07151757576,-0.4317661862
65.752,1.13799,-0.39596,,,,,0.06896909091,-0.4529398307
66.252,1.09664,-0.41198,,,,,0.0664630303,-0.4712651567
66.752,1.05487,-0.42579,,,,,0.06393151515,-0.4870624571
67.252,1.01318,-0.44178,,,,,0.06140484848,-0.505353466
67.752,0.97173,-0.45374,,,,,0.05889272727,-0.5190345459
68.252,0.92971,-0.4673,,,,,0.05634606061,-0.5345458705
68.752,0.88826,-0.47805,,,,,0.05383393939,-0.5468428277
69.252,0.84665,-0.48996,,,,,0.05131212121,-0.5604667124
69.752,0.8047,-0.50129,,,,,0.04876969697,-0.5734271334
70.252,0.76322,-0.51143,,,,,0.04625575758,-0.5850263098
70.752,0.72153,-0.51939,,,,,0.04372909091,-0.5941317776
71.252,0.67979,-0.53064,,,,,0.04119939394,-0.6070006863
71.752,0.63835,-0.53666,,,,,0.03868787879,-0.6138869824
72.252,0.59628,-0.54557,,,,,0.03613818182,-0.6240791581
72.752,0.55497,-0.55522,,,,,0.03363454545,-0.635117822
73.252,0.5134,-0.56049,,,,,0.03111515152,-0.6411461908
73.752,0.47125,-0.56893,,,,,0.02856060606,-0.6508007321
74.252,0.42997,-0.57578,,,,,0.02605878788,-0.6586364676
74.752,0.38832,-0.58572,,,,,0.02353454545,-0.6700068634
75.252,0.3464,-0.59185,,,,,0.02099393939,-0.6770189888
75.752,0.30495,-0.59812,,,,,0.01848181818,-0.6841912606
76.252,0.26317,-0.60577,,,,,0.01594969697,-0.6929421185
76.752,0.22149,-0.61262,,,,,0.01342363636,-0.700777854
77.252,0.18007,-0.61796,,,,,0.01091333333,-0.706886296
77.752,0.13795,-0.62529,,,,,0.008360606061,-0.715271105
78.252,0.09659,-0.63146,,,,,0.005853939394,-0.7223289865
78.752,0.05499,-0.63617,,,,,0.003332727273,-0.7277167696
79.252,0.01308,-0.64159,,,,,0.0007927272727,-0.7339167239
79.51,0.00256,-0.62629,,,,,0.0001551515152,-0.716415008
80.01,0.04559,-0.56875,,,,,0.002763030303,-0.6505948296
80.51,0.08718,-0.53731,,,,,0.005283636364,-0.6146305193
81.01,0.1288,-0.51288,,,,,0.007806060606,-0.5866849691
81.51,0.17073,-0.49095,,,,,0.01034727273,-0.5615991764
82.01,0.21195,-0.4701,,,,,0.01284545455,-0.5377487989
82.51,0.25407,-0.45247,,,,,0.01539818182,-0.5175817891
83.01,0.29568,-0.43744,,,,,0.01792,-0.500388927
83.51,0.33693,-0.41961,,,,,0.02042,-0.4799931366
84.01,0.3791,-0.40289,,,,,0.02297575758,-0.4608670785
84.51,0.42064,-0.38892,,,,,0.02549333333,-0.4448867536
85.01,0.46207,-0.37215,,,,,0.02800424242,-0.4257035003
85.51,0.50399,-0.35652,,,,,0.03054484848,-0.4078242965
86.01,0.54544,-0.34258,,,,,0.0330569697,-0.3918782887
86.51,0.58727,-0.32809,,,,,0.03559212121,-0.3753031343
87.01,0.62906,-0.31221,,,,,0.03812484848,-0.3571379547
87.51,0.67027,-0.29878,,,,,0.04062242424,-0.3417753375
88.01,0.71243,-0.28422,,,,,0.04317757576,-0.3251201098
88.51,0.75397,-0.26873,,,,,0.04569515152,-0.3074010524
89.01,0.79538,-0.25544,,,,,0.04820484848,-0.2921985816
89.51,0.83744,-0.2408,,,,,0.05075393939,-0.2754518417
90.01,0.8788,-0.2264,,,,,0.05326060606,-0.2589796385
90.51,0.92058,-0.21364,,,,,0.05579272727,-0.2443834363
91.01,0.96242,-0.19847,,,,,0.05832848485,-0.2270304278
91.51,1.00359,-0.18683,,,,,0.06082363636,-0.2137153969
92.01,1.04567,-0.17106,,,,,0.06337393939,-0.1956760467
92.51,1.08739,-0.15731,,,,,0.06590242424,-0.1799473805
93.01,1.12863,-0.14447,,,,,0.06840181818,-0.165259666
93.51,1.17075,-0.12916,,,,,0.07095454545,-0.1477465111
94.01,1.21227,-0.11569,,,,,0.07347090909,-0.1323381377
94.51,1.25383,-0.10264,,,,,0.07598969697,-0.1174102036
95.01,1.29571,-0.08712,,,,,0.07852787879,-0.0996568291
95.51,1.33706,-0.07412,,,,,0.08103393939,-0.08478609014
96.01,1.37904,-0.06011,,,,,0.08357818182,-0.06876000915
96.51,1.42062,-0.04568,,,,,0.08609818182,-0.0522534889
97.01,1.46197,-0.03307,,,,,0.08860424242,-0.03782887211
97.51,1.50411,-0.01882,,,,,0.09115818182,-0.0215282544
98.01,1.54551,-0.0053,,,,,0.09366727273,-0.006062685884
98.51,1.58709,0.00508,,,,,0.09618727273,0.005811027225
99.01,1.62913,0.01927,,,,,0.09873515152,0.02204301075
99.265,1.6502,0.02394,,,,,0.1000121212,0.02738503775
99.765,1.61332,-0.0844,,,,,0.0977769697,-0.09654541295
100.265,1.57143,-0.14775,,,,,0.09523818182,-0.1690116678
100.765,1.52998,-0.19589,,,,,0.09272606061,-0.2240791581
101.265,1.48829,-0.23259,,,,,0.09019939394,-0.2660603981
101.765,1.44634,-0.26551,,,,,0.0876569697,-0.3037176847
102.265,1.40498,-0.29476,,,,,0.08515030303,-0.3371768474
102.765,1.36337,-0.32003,,,,,0.08262848485,-0.3660832761
103.265,1.32129,-0.34392,,,,,0.08007818182,-0.3934111187
103.765,1.28002,-0.36554,,,,,0.0775769697,-0.4181423015
104.265,1.23825,-0.38197,,,,,0.07504545455,-0.4369366278
104.765,1.1965,-0.40309,,,,,0.07251515152,-0.4610958591
105.265,1.15511,-0.41824,,,,,0.07000666667,-0.4784259895
105.765,1.11303,-0.43293,,,,,0.06745636364,-0.4952299245
106.265,1.07153,-0.44936,,,,,0.06494121212,-0.5140242507
106.765,1.03006,-0.46302,,,,,0.06242787879,-0.5296499657
107.265,0.98803,-0.47562,,,,,0.05988060606,-0.5440631434
107.765,0.94654,-0.48592,,,,,0.05736606061,-0.5558453443
108.265,0.90492,-0.501,,,,,0.05484363636,-0.5730954015
108.765,0.86314,-0.511,,,,,0.05231151515,-0.5845344315
109.265,0.82171,-0.52475,,,,,0.04980060606,-0.6002630977
109.765,0.77973,-0.53348,,,,,0.04725636364,-0.6102493709
110.265,0.7383,-0.54157,,,,,0.04474545455,-0.6195035461
110.765,0.69684,-0.54867,,,,,0.04223272727,-0.6276252574
111.265,0.65461,-0.55919,,,,,0.03967333333,-0.6396591169
111.765,0.61328,-0.56867,,,,,0.03716848485,-0.6505033173
112.265,0.57169,-0.58114,,,,,0.03464787879,-0.6647677877
112.765,0.5297,-0.58537,,,,,0.0321030303,-0.6696064974
113.265,0.48826,-0.5904,,,,,0.02959151515,-0.6753603294
113.765,0.44656,-0.59637,,,,,0.02706424242,-0.6821894303
114.265,0.40484,-0.60699,,,,,0.02453575758,-0.6943376802
114.765,0.36336,-0.61244,,,,,0.02202181818,-0.7005719515
115.265,0.32134,-0.61849,,,,,0.01947515152,-0.7074925646
115.765,0.27998,-0.6258,,,,,0.01696848485,-0.7158544955
116.265,0.23833,-0.62972,,,,,0.01444424242,-0.7203385953
116.765,0.19632,-0.63702,,,,,0.01189818182,-0.7286890872
117.265,0.15495,-0.64298,,,,,0.009390909091,-0.735506749
117.765,0.11318,-0.64969,,,,,0.006859393939,-0.7431823381
118.265,0.07152,-0.65716,,,,,0.004334545455,-0.7517272935
118.765,0.03007,-0.66005,,,,,0.001822424242,-0.7550331732
119.122,-0.00008,-0.66466,,,,,-0.000004848484848,-0.760306566
119.523,0.02876,-0.61001,,,,,0.001743030303,-0.6977922672
120.023,0.07071,-0.57512,,,,,0.004285454545,-0.6578814916
120.523,0.11239,-0.5472,,,,,0.006811515152,-0.62594372
121.023,0.15352,-0.52662,,,,,0.009304242424,-0.6024021963
121.523,0.19582,-0.50642,,,,,0.01186787879,-0.5792953558
122.023,0.23738,-0.48871,,,,,0.01438666667,-0.5590368337
122.523,0.27862,-0.4734,,,,,0.01688606061,-0.5415236788
123.023,0.32081,-0.45597,,,,,0.0194430303,-0.5215854496
123.523,0.36218,-0.44105,,,,,0.02195030303,-0.5045184168
124.023,0.40387,-0.42626,,,,,0.0244769697,-0.4876000915
124.523,0.44565,-0.41084,,,,,0.02700909091,-0.4699611073
125.023,0.48702,-0.39644,,,,,0.02951636364,-0.4534889041
125.523,0.52897,-0.38355,,,,,0.03205878788,-0.4387439945
126.023,0.57069,-0.36952,,,,,0.03458727273,-0.4226950355
126.523,0.61202,-0.35517,,,,,0.03709212121,-0.4062800275
127.023,0.65413,-0.33913,,,,,0.03964424242,-0.3879318234
127.523,0.69549,-0.3261,,,,,0.04215090909,-0.3730267673
128.023,0.73726,-0.31264,,,,,0.04468242424,-0.357629833
128.523,0.77908,-0.29837,,,,,0.0472169697,-0.3413063372
129.023,0.82027,-0.28587,,,,,0.04971333333,-0.3270075498
129.523,0.86242,-0.2714,,,,,0.05226787879,-0.3104552734
130.023,0.90406,-0.25729,,,,,0.05479151515,-0.2943148021
130.523,0.94525,-0.24402,,,,,0.05728787879,-0.2791352093
131.023,0.9873,-0.22988,,,,,0.05983636364,-0.262960421
131.523,1.02897,-0.215,,,,,0.06236181818,-0.2459391444
132.023,1.07035,-0.20281,,,,,0.06486969697,-0.2319949668
132.523,1.11242,-0.1876,,,,,0.06741939394,-0.2145962022
133.023,1.15371,-0.17473,,,,,0.06992181818,-0.1998741707
133.523,1.1957,-0.16071,,,,,0.07246666667,-0.1838366507
134.023,1.23734,-0.14731,,,,,0.07499030303,-0.1685083505
134.523,1.27866,-0.13348,,,,,0.07749454545,-0.152688172
135.023,1.32083,-0.12001,,,,,0.08005030303,-0.1372797987
135.523,1.36232,-0.10614,,,,,0.08256484848,-0.1214138641
136.023,1.4037,-0.09268,,,,,0.08507272727,-0.1060169298
136.523,1.44578,-0.07664,,,,,0.0876230303,-0.08766872569
137.023,1.48713,-0.0637,,,,,0.09012909091,-0.07286662091
137.523,1.52887,-0.05148,,,,,0.09265878788,-0.05888812629
138.023,1.57076,-0.03744,,,,,0.09519757576,-0.04282772821
138.523,1.61194,-0.02522,,,,,0.09769333333,-0.02884923358
138.976,1.65002,-0.01244,,,,,0.1000012121,-0.01423015328
139.278,1.62971,-0.08452,,,,,0.09877030303,-0.09668268131
139.778,1.58832,-0.15567,,,,,0.09626181818,-0.1780713795
140.278,1.54675,-0.20427,,,,,0.09374242424,-0.2336650652
140.778,1.50459,-0.24511,,,,,0.09118727273,-0.2803820636
141.278,1.4633,-0.27807,,,,,0.08868484848,-0.3180851064
141.778,1.42164,-0.30695,,,,,0.08616,-0.3511210249
142.278,1.37973,-0.33304,,,,,0.08362,-0.3809654541
142.778,1.33834,-0.35557,,,,,0.08111151515,-0.4067375887
143.278,1.29645,-0.37749,,,,,0.07857272727,-0.4318119423
143.778,1.2549,-0.3972,,,,,0.07605454545,-0.4543582704
144.278,1.21341,-0.41485,,,,,0.07354,-0.4745481583
144.778,1.17134,-0.43117,,,,,0.07099030303,-0.4932166552
145.278,1.12995,-0.4456,,,,,0.06848181818,-0.5097231755
145.778,1.08823,-0.45996,,,,,0.06595333333,-0.5261496225
146.278,1.04647,-0.47462,,,,,0.06342242424,-0.5429192404
146.778,1.0049,-0.4861,,,,,0.0609030303,-0.5560512469
147.278,0.96314,-0.49831,,,,,0.05837212121,-0.5700183024
147.778,0.92154,-0.51031,,,,,0.05585090909,-0.5837451384
148.278,0.88008,-0.52068,,,,,0.05333818182,-0.5956074125
148.778,0.83794,-0.53205,,,,,0.05078424242,-0.6086135896
149.278,0.79666,-0.54153,,,,,0.04828242424,-0.61945779
149.778,0.75503,-0.54999,,,,,0.04575939394,-0.6291352093
150.278,0.71293,-0.5619,,,,,0.04320787879,-0.642759094
150.778,0.67163,-0.56843,,,,,0.04070484848,-0.6502287806
151.278,0.62987,-0.57912,,,,,0.03817393939,-0.6624571036
151.778,0.58812,-0.58721,,,,,0.03564363636,-0.6717112789
152.278,0.54669,-0.59393,,,,,0.03313272727,-0.679398307
152.778,0.50472,-0.60101,,,,,0.03058909091,-0.6874971402
153.278,0.46318,-0.60855,,,,,0.02807151515,-0.6961221688
153.778,0.42174,-0.6152,,,,,0.02556,-0.7037291238
154.278,0.37961,-0.62309,,,,,0.02300666667,-0.7127545184
154.778,0.3383,-0.62861,,,,,0.0205030303,-0.719068863
155.278,0.2966,-0.63499,,,,,0.01797575758,-0.7263669641
155.778,0.25487,-0.64194,,,,,0.01544666667,-0.7343170899
156.278,0.2134,-0.64565,,,,,0.01293333333,-0.73856097
156.778,0.1714,-0.65276,,,,,0.01038787879,-0.7466941203
157.278,0.12991,-0.65789,,,,,0.007873333333,-0.7525623427
157.778,0.0884,-0.66355,,,,,0.005357575758,-0.7590368337
158.278,0.04626,-0.66883,,,,,0.002803636364,-0.7650766415
158.778,0.00491,-0.67351,,,,,0.0002975757576,-0.7704301075
159.036,0.01218,-0.64336,,,,,0.0007381818182,-0.7359414322
159.536,0.05399,-0.60062,,,,,0.003272121212,-0.6870510181
160.036,0.09529,-0.57485,,,,,0.005775151515,-0.6575726378
160.536,0.13742,-0.55154,,,,,0.008328484848,-0.630908259
161.036,0.17886,-0.53195,,,,,0.01084,-0.6084991993
161.536,0.22048,-0.51482,,,,,0.01336242424,-0.5889041409
162.036,0.26231,-0.49718,,,,,0.01589757576,-0.5687256921
162.536,0.30367,-0.48108,,,,,0.01840424242,-0.5503088538
163.036,0.34568,-0.46598,,,,,0.02095030303,-0.5330359186
163.536,0.38735,-0.45029,,,,,0.02347575758,-0.5150880805
164.036,0.42865,-0.43718,,,,,0.02597878788,-0.5000915122
164.536,0.47077,-0.42225,,,,,0.02853151515,-0.4830130405
165.036,0.51225,-0.40974,,,,,0.03104545455,-0.468702814
165.536,0.55384,-0.39615,,,,,0.03356606061,-0.4531571723
166.036,0.59576,-0.38149,,,,,0.03610666667,-0.4363875543
166.536,0.63701,-0.36858,,,,,0.03860666667,-0.4216197666
167.036,0.67905,-0.35629,,,,,0.04115454545,-0.4075611988
167.536,0.72078,-0.34168,,,,,0.04368363636,-0.390848776
168.036,0.7619,-0.32896,,,,,0.04617575758,-0.3762983299
168.536,0.80404,-0.31673,,,,,0.04872969697,-0.3623083962
169.036,0.84565,-0.30204,,,,,0.05125151515,-0.3455044612
169.536,0.88701,-0.28935,,,,,0.05375818182,-0.3309883322
170.036,0.92903,-0.27506,,,,,0.05630484848,-0.3146419584
170.536,0.97052,-0.26159,,,,,0.05881939394,-0.299233585
171.036,1.01226,-0.2492,,,,,0.06134909091,-0.2850606269
171.536,1.05404,-0.23359,,,,,0.06388121212,-0.2672043011
172.036,1.09538,-0.22047,,,,,0.06638666667,-0.2521962938
172.536,1.13743,-0.20715,,,,,0.06893515152,-0.2369595058
173.036,1.17896,-0.19192,,,,,0.07145212121,-0.2195378632
173.536,1.22039,-0.18023,,,,,0.0739630303,-0.2061656372
174.036,1.26243,-0.1642,,,,,0.07651090909,-0.1878288721
174.536,1.30375,-0.15208,,,,,0.07901515152,-0.1739647678
175.036,1.34556,-0.13934,,,,,0.08154909091,-0.1593914436
175.536,1.38739,-0.12363,,,,,0.08408424242,-0.1414207275
176.036,1.42859,-0.11077,,,,,0.08658121212,-0.126710135
176.536,1.47062,-0.09674,,,,,0.08912848485,-0.1106611759
177.036,1.51239,-0.0833,,,,,0.09166,-0.09528711965
177.536,1.55356,-0.06956,,,,,0.09415515152,-0.07956989247
178.036,1.5958,-0.05614,,,,,0.09671515152,-0.06421871425
178.536,1.63728,-0.04339,,,,,0.09922909091,-0.04963395104
178.791,1.64741,-0.0598,,,,,0.0998430303,-0.06840539922
179.291,1.60498,-0.15211,,,,,0.09727151515,-0.1739990849
179.791,1.56301,-0.20582,,,,,0.09472787879,-0.2354381148
180.291,1.5217,-0.24705,,,,,0.09222424242,-0.2826012354
180.791,1.4798,-0.28207,,,,,0.08968484848,-0.3226607184
181.291,1.43819,-0.31256,,,,,0.0871630303,-0.3575383208
181.791,1.39678,-0.33828,,,,,0.08465333333,-0.3869595058
182.291,1.35463,-0.36316,,,,,0.08209878788,-0.4154198124
182.791,1.31321,-0.38443,,,,,0.07958848485,-0.4397506291
183.291,1.27169,-0.40362,,,,,0.07707212121,-0.4617021277
183.791,1.22973,-0.42208,,,,,0.07452909091,-0.482818577
184.291,1.18823,-0.43733,,,,,0.07201393939,-0.5002630977
184.791,1.14651,-0.45425,,,,,0.06948545455,-0.5196179364
185.291,1.1049,-0.46869,,,,,0.06696363636,-0.5361358957
185.791,1.06343,-0.48151,,,,,0.06445030303,-0.5508007321
186.291,1.02131,-0.49525,,,,,0.06189757576,-0.5665179593
186.791,0.97995,-0.50753,,,,,0.05939090909,-0.5805650881
187.291,0.93845,-0.51777,,,,,0.05687575758,-0.5922786548
187.791,0.89627,-0.52982,,,,,0.05431939394,-0.6060626859
188.291,0.85493,-0.54031,,,,,0.05181393939,-0.6180622283
188.791,0.81329,-0.55038,,,,,0.04929030303,-0.6295813315
189.291,0.77143,-0.5592,,,,,0.04675333333,-0.6396705559
189.791,0.72997,-0.56767,,,,,0.04424060606,-0.6493594143
190.291,0.68813,-0.5759,,,,,0.04170484848,-0.658773736
190.791,0.64658,-0.58532,,,,,0.03918666667,-0.6695493022
191.291,0.60505,-0.59315,,,,,0.03666969697,-0.6785060627
191.791,0.56303,-0.59985,,,,,0.0341230303,-0.6861702128
192.291,0.52161,-0.6087,,,,,0.03161272727,-0.6962937543
192.791,0.47997,-0.61577,,,,,0.02908909091,-0.7043811485
193.291,0.43805,-0.62232,,,,,0.02654848485,-0.7118737131
193.791,0.39664,-0.63002,,,,,0.02403878788,-0.7206817662
194.291,0.35472,-0.6343,,,,,0.02149818182,-0.725577671
194.791,0.3132,-0.64149,,,,,0.01898181818,-0.7338023336
195.291,0.27178,-0.64842,,,,,0.01647151515,-0.7417295813
195.791,0.22956,-0.65576,,,,,0.01391272727,-0.7501258293
196.291,0.18827,-0.66109,,,,,0.01141030303,-0.7562228323
196.791,0.14673,-0.66626,,,,,0.008892727273,-0.7621368108
197.291,0.10461,-0.67178,,,,,0.00634,-0.7684511553
197.791,0.06325,-0.67813,,,,,0.003833333333,-0.7757149394
198.291,0.02157,-0.68085,,,,,0.001307272727,-0.7788263555
198.549,-0.00018,-0.68556,,,,,-0.00001090909091,-0.7842141386
199.049,0.03706,-0.62561,,,,,0.002246060606,-0.715637154
199.549,0.07909,-0.59546,,,,,0.004793333333,-0.6811484786
200.049,0.12038,-0.57158,,,,,0.007295757576,-0.653832075
200.549,0.16228,-0.55211,,,,,0.009835151515,-0.6315602837
201.049,0.20398,-0.53346,,,,,0.01236242424,-0.6102264928
201.549,0.24534,-0.51754,,,,,0.01486909091,-0.5920155571
202.049,0.2873,-0.49991,,,,,0.01741212121,-0.5718485472
202.549,0.329,-0.48536,,,,,0.01993939394,-0.5552047586
203.049,0.37043,-0.47026,,,,,0.02245030303,-0.5379318234
203.549,0.41243,-0.45596,,,,,0.02499575758,-0.5215740105
204.049,0.45373,-0.4421,,,,,0.02749878788,-0.505719515
204.549,0.4957,-0.42871,,,,,0.03004242424,-0.4904026539
205.049,0.53731,-0.41367,,,,,0.03256424242,-0.4731983528
205.549,0.57851,-0.40212,,,,,0.03506121212,-0.4599862732
206.049,0.62075,-0.38821,,,,,0.03762121212,-0.4440745825
206.549,0.66233,-0.37597,,,,,0.04014121212,-0.4300732098
207.049,0.70361,-0.36279,,,,,0.0426430303,-0.4149965683
207.549,0.74564,-0.34833,,,,,0.04519030303,-0.398455731
208.049,0.78723,-0.33625,,,,,0.04771090909,-0.3846373827
208.549,0.82883,-0.32392,,,,,0.05023212121,-0.3705330588
209.049,0.87076,-0.30967,,,,,0.05277333333,-0.3542324411
209.549,0.91199,-0.29753,,,,,0.05527212121,-0.3403454587
210.049,0.95409,-0.28394,,,,,0.05782363636,-0.324799817
210.549,0.99567,-0.27093,,,,,0.06034363636,-0.309917639
211.049,1.03701,-0.25977,,,,,0.06284909091,-0.2971516815
211.549,1.07914,-0.24372,,,,,0.06540242424,-0.2787920384
212.049,1.12054,-0.23044,,,,,0.06791151515,-0.2636010066
212.549,1.16211,-0.21883,,,,,0.07043090909,-0.2503202928
213.049,1.20406,-0.20389,,,,,0.07297333333,-0.2332303821
213.549,1.24531,-0.19089,,,,,0.07547333333,-0.2183596431
214.049,1.28727,-0.17788,,,,,0.07801636364,-0.2034774651
214.549,1.32907,-0.16352,,,,,0.08054969697,-0.1870510181
215.049,1.37024,-0.1505,,,,,0.08304484848,-0.1721574011
215.549,1.41242,-0.13554,,,,,0.08560121212,-0.1550446122
216.049,1.45397,-0.12171,,,,,0.08811939394,-0.1392244338
216.549,1.49542,-0.10936,,,,,0.09063151515,-0.1250972318
217.049,1.53737,-0.09441,,,,,0.09317393939,-0.1079958819
217.549,1.57884,-0.07835,,,,,0.09568727273,-0.08962479982
218.049,1.62065,-0.06757,,,,,0.09822121212,-0.07729352551
218.403,1.65011,-0.05638,,,,,0.1000066667,-0.06449325097
218.804,1.62151,-0.14224,,,,,0.09827333333,-0.1627087623
219.304,1.5801,-0.20081,,,,,0.09576363636,-0.2297071608
219.804,1.53804,-0.24708,,,,,0.09321454545,-0.2826355525
220.304,1.49659,-0.28253,,,,,0.09070242424,-0.3231869137
220.804,1.45509,-0.31246,,,,,0.08818727273,-0.3574239305
221.304,1.41304,-0.3411,,,,,0.08563878788,-0.3901853123
221.804,1.37164,-0.36478,,,,,0.08312969697,-0.4172729353
222.304,1.32989,-0.38644,,,,,0.08059939394,-0.4420498742
222.804,1.28826,-0.40625,,,,,0.07807636364,-0.4647105925
223.304,1.2466,-0.42318,,,,,0.07555151515,-0.4840768703
223.804,1.20473,-0.4401,,,,,0.07301393939,-0.503431709
224.304,1.16325,-0.45876,,,,,0.0705,-0.5247769389
224.804,1.12176,-0.47122,,,,,0.06798545455,-0.5390299703
225.304,1.07956,-0.48508,,,,,0.06542787879,-0.5548844658
225.804,1.03834,-0.49857,,,,,0.06292969697,-0.5703157172
226.304,0.99665,-0.50896,,,,,0.0604030303,-0.5822008694
226.804,0.95471,-0.52348,,,,,0.05786121212,-0.5988103409
227.304,0.91335,-0.53115,,,,,0.05535454545,-0.6075840769
227.804,0.87145,-0.54297,,,,,0.05281515152,-0.6211050103
228.304,0.82988,-0.55447,,,,,0.05029575758,-0.6342598948
228.804,0.78841,-0.56306,,,,,0.04778242424,-0.6440860215
229.304,0.74638,-0.57124,,,,,0.04523515152,-0.653443148
229.804,0.70489,-0.57953,,,,,0.04272060606,-0.6629261039
230.304,0.66338,-0.5892,,,,,0.04020484848,-0.6739876458
230.804,0.62136,-0.59562,,,,,0.03765818182,-0.6813315031
231.304,0.57999,-0.60277,,,,,0.03515090909,-0.6895104095
231.804,0.53815,-0.60959,,,,,0.03261515152,-0.697311828
232.304,0.49657,-0.61888,,,,,0.03009515152,-0.7079386868
232.804,0.4551,-0.62494,,,,,0.02758181818,-0.714870739
233.304,0.41299,-0.63316,,,,,0.02502969697,-0.7242736216
233.804,0.37162,-0.63957,,,,,0.02252242424,-0.7316060398
234.304,0.33008,-0.64549,,,,,0.02000484848,-0.7383779456
234.804,0.28797,-0.65304,,,,,0.01745272727,-0.7470144132
235.304,0.24661,-0.6594,,,,,0.01494606061,-0.7542896362
235.804,0.20504,-0.66388,,,,,0.01242666667,-0.7594143217
236.304,0.16313,-0.67203,,,,,0.009886666667,-0.7687371311
236.804,0.12171,-0.67645,,,,,0.007376363636,-0.7737931823
237.304,0.07974,-0.68169,,,,,0.004832727273,-0.779787234
237.804,0.03834,-0.68855,,,,,0.002323636364,-0.7876344086
238.26,0,-0.69517,,,,,0,-0.7952070464
238.562,0.02054,-0.64751,,,,,0.001244848485,-0.7406886296
239.062,0.06195,-0.61365,,,,,0.003754545455,-0.7019560741
239.562,0.10404,-0.58701,,,,,0.006305454545,-0.6714824983
240.062,0.14561,-0.56731,,,,,0.008824848485,-0.6489476092
240.562,0.18703,-0.54931,,,,,0.01133515152,-0.6283573553
241.062,0.22906,-0.53166,,,,,0.01388242424,-0.6081674674
241.562,0.27049,-0.51479,,,,,0.01639333333,-0.5888698238
242.062,0.31224,-0.50369,,,,,0.01892363636,-0.5761725006
242.562,0.35402,-0.48598,,,,,0.02145575758,-0.5559139785
243.062,0.3952,-0.47344,,,,,0.02395151515,-0.5415694349
243.562,0.43738,-0.46089,,,,,0.02650787879,-0.5272134523
244.062,0.47905,-0.44554,,,,,0.02903333333,-0.5096545413
244.562,0.52021,-0.43468,,,,,0.03152787879,-0.4972317547
245.062,0.56244,-0.41819,,,,,0.03408727273,-0.4783687943
245.562,0.60393,-0.40618,,,,,0.03660181818,-0.4646305193
246.062,0.64544,-0.39408,,,,,0.03911757576,-0.4507892931
246.562,0.68735,-0.38052,,,,,0.04165757576,-0.4352779684
247.062,0.72877,-0.36803,,,,,0.04416787879,-0.42099062
247.562,0.77062,-0.35332,,,,,0.04670424242,-0.4041638069
248.062,0.81233,-0.3411,,,,,0.04923212121,-0.3901853123
248.562,0.85365,-0.3293,,,,,0.05173636364,-0.3766872569
249.062,0.89577,-0.3164,,,,,0.05428909091,-0.3619309083
249.562,0.93719,-0.30224,,,,,0.05679939394,-0.3457332418
250.062,0.97875,-0.29176,,,,,0.05931818182,-0.3337451384
250.562,1.0207,-0.2776,,,,,0.06186060606,-0.317547472
251.062,1.06197,-0.26426,,,,,0.06436181818,-0.302287806
251.562,1.10397,-0.25157,,,,,0.06690727273,-0.287771677
252.062,1.1457,-0.23952,,,,,0.06943636364,-0.2739876458
252.562,1.18686,-0.22628,,,,,0.07193090909,-0.2588423702
253.062,1.22897,-0.20965,,,,,0.0744830303,-0.2398192633
253.562,1.27066,-0.19652,,,,,0.07700969697,-0.224799817
254.062,1.31194,-0.18438,,,,,0.07951151515,-0.2109128346
254.562,1.3541,-0.17063,,,,,0.08206666667,-0.1951841684
255.062,1.39543,-0.15666,,,,,0.08457151515,-0.1792038435
255.562,1.43724,-0.14245,,,,,0.08710545455,-0.1629489819
256.062,1.47897,-0.12684,,,,,0.08963454545,-0.1450926561
256.562,1.52036,-0.11459,,,,,0.0921430303,-0.1310798444
257.062,1.56242,-0.09828,,,,,0.09469212121,-0.1124227865
257.562,1.60397,-0.08684,,,,,0.09721030303,-0.09933653626
258.062,1.64527,-0.0739,,,,,0.09971333333,-0.08453443148
258.317,1.63863,-0.11955,,,,,0.09931090909,-0.1367536033
258.817,1.59635,-0.19271,,,,,0.09674848485,-0.2204415466
259.317,1.55494,-0.24032,,,,,0.09423878788,-0.2749027682
259.817,1.5133,-0.27878,,,,,0.09171515152,-0.3188972775
260.317,1.47153,-0.3085,,,,,0.08918363636,-0.3528940746
260.817,1.42996,-0.33671,,,,,0.08666424242,-0.3851635781
261.317,1.38809,-0.36611,,,,,0.08412666667,-0.4187943262
261.817,1.34658,-0.38636,,,,,0.08161090909,-0.4419583619
262.317,1.30511,-0.40603,,,,,0.07909757576,-0.4644589339
262.817,1.26292,-0.42393,,,,,0.07654060606,-0.4849347975
263.317,1.2216,-0.44176,,,,,0.07403636364,-0.505330588
263.817,1.18008,-0.45884,,,,,0.07152,-0.5248684512
264.317,1.13802,-0.4717,,,,,0.06897090909,-0.5395790437
264.817,1.09664,-0.48568,,,,,0.0664630303,-0.5555708076
265.317,1.05488,-0.49903,,,,,0.06393212121,-0.5708419126
265.817,1.01319,-0.51439,,,,,0.06140545455,-0.5884122626
266.317,0.97172,-0.52337,,,,,0.05889212121,-0.5986845116
266.817,0.92972,-0.53385,,,,,0.05634666667,-0.610672615
267.317,0.88826,-0.54609,,,,,0.05383393939,-0.6246739876
267.817,0.84668,-0.55542,,,,,0.05131393939,-0.6353466026
268.317,0.80474,-0.56494,,,,,0.04877212121,-0.6462365591
268.817,0.76324,-0.57442,,,,,0.0462569697,-0.6570807596
269.317,0.72153,-0.58173,,,,,0.04372909091,-0.6654426905
269.817,0.67981,-0.59161,,,,,0.04120060606,-0.6767444521
270.317,0.63838,-0.59793,,,,,0.03868969697,-0.683973919
270.817,0.5963,-0.60628,,,,,0.03613939394,-0.693525509
271.317,0.55499,-0.61449,,,,,0.03363575758,-0.7029169526
271.817,0.51342,-0.62231,,,,,0.03111636364,-0.7118622741
272.317,0.47123,-0.63016,,,,,0.02855939394,-0.7208419126
272.817,0.42999,-0.63659,,,,,0.02606,-0.7281972089
273.317,0.38833,-0.64304,,,,,0.02353515152,-0.7355753832
273.817,0.34641,-0.65028,,,,,0.02099454545,-0.7438572409
274.317,0.30498,-0.65651,,,,,0.01848363636,-0.7509837566
274.817,0.26317,-0.66058,,,,,0.01594969697,-0.7556394418
275.317,0.22151,-0.66785,,,,,0.01342484848,-0.7639556166
275.817,0.18006,-0.67357,,,,,0.01091272727,-0.7704987417
276.317,0.13795,-0.67868,,,,,0.008360606061,-0.776344086
276.817,0.09664,-0.6837,,,,,0.005856969697,-0.7820864791
277.317,0.055,-0.6885,,,,,0.003333333333,-0.7875772135
277.817,0.0131,-0.69506,,,,,0.0007939393939,-0.7950812171
278.075,0.00251,-0.68295,,,,,0.0001521212121,-0.7812285518
278.575,0.04555,-0.63183,,,,,0.002760606061,-0.7227522306
279.075,0.08714,-0.60416,,,,,0.005281212121,-0.6911004347
279.575,0.12879,-0.58437,,,,,0.007805454545,-0.6684625944
280.075,0.17068,-0.56587,,,,,0.01034424242,-0.6473003889
280.575,0.21191,-0.54793,,,,,0.0128430303,-0.6267787692
281.075,0.25405,-0.53179,,,,,0.0153969697,-0.6083161748
281.575,0.29562,-0.51533,,,,,0.01791636364,-0.5894875315
282.075,0.33688,-0.50247,,,,,0.0204169697,-0.5747769389
282.575,0.37908,-0.48648,,,,,0.02297454545,-0.55648593
283.075,0.42063,-0.47157,,,,,0.02549272727,-0.5394303363
283.575,0.46204,-0.45839,,,,,0.02800242424,-0.5243536948
284.075,0.50395,-0.44544,,,,,0.03054242424,-0.509540151
284.575,0.5454,-0.43262,,,,,0.03305454545,-0.4948753146
285.075,0.58723,-0.4199,,,,,0.03558969697,-0.4803248685
285.575,0.629,-0.40689,,,,,0.03812121212,-0.4654426905
286.075,0.67025,-0.3962,,,,,0.04062121212,-0.4532143674
286.575,0.71237,-0.38263,,,,,0.04317393939,-0.4376916038
287.075,0.75391,-0.37138,,,,,0.04569151515,-0.424822695
287.575,0.79534,-0.35868,,,,,0.04820242424,-0.410295127
288.075,0.83739,-0.34546,,,,,0.05075090909,-0.3951727294
288.575,0.87875,-0.33248,,,,,0.05325757576,-0.3803248685
289.075,0.92056,-0.32075,,,,,0.05579151515,-0.3669068863
289.575,0.96236,-0.30666,,,,,0.05832484848,-0.3507892931
290.075,1.00353,-0.29424,,,,,0.06082,-0.3365820178
290.575,1.04564,-0.28069,,,,,0.06337212121,-0.3210821322
291.075,1.08736,-0.26777,,,,,0.06590060606,-0.3063029055
291.575,1.1286,-0.25341,,,,,0.0684,-0.2898764585
292.075,1.17071,-0.23957,,,,,0.07095212121,-0.274044841
292.575,1.21223,-0.22652,,,,,0.07346848485,-0.2591169069
293.075,1.25381,-0.21303,,,,,0.07598848485,-0.2436856555
293.575,1.29566,-0.20187,,,,,0.07852484848,-0.230919698
294.075,1.33701,-0.18625,,,,,0.08103090909,-0.2130519332
294.575,1.379,-0.17376,,,,,0.08357575758,-0.1987645848
295.075,1.42059,-0.15847,,,,,0.08609636364,-0.1812743079
295.575,1.46193,-0.14568,,,,,0.08860181818,-0.1666437886
296.075,1.50409,-0.13217,,,,,0.0911569697,-0.1511896591
296.575,1.54546,-0.11702,,,,,0.09366424242,-0.1338595287
297.075,1.58706,-0.10521,,,,,0.09618545455,-0.1203500343
297.575,1.62908,-0.08905,,,,,0.09873212121,-0.1018645619
297.831,1.65023,-0.0833,,,,,0.1000139394,-0.09528711965
298.331,1.61339,-0.17839,,,,,0.09778121212,-0.2040608556
298.831,1.57148,-0.23412,,,,,0.09524121212,-0.2678105697
299.331,1.53005,-0.2739,,,,,0.09273030303,-0.3133150309
299.831,1.48838,-0.30804,,,,,0.09020484848,-0.3523678792
300.331,1.44642,-0.3378,,,,,0.08766181818,-0.3864104324
300.831,1.40505,-0.36228,,,,,0.08515454545,-0.4144131778
301.331,1.36345,-0.38525,,,,,0.08263333333,-0.4406886296
301.831,1.32136,-0.40667,,,,,0.08008242424,-0.4651910318
302.331,1.28009,-0.42444,,,,,0.07758121212,-0.4855181881
302.831,1.2383,-0.44033,,,,,0.07504848485,-0.5036948067
303.331,1.19658,-0.4566,,,,,0.07252,-0.5223061084
303.831,1.15517,-0.47253,,,,,0.07001030303,-0.5405284832
304.331,1.11311,-0.48538,,,,,0.06746121212,-0.5552276367
304.831,1.07162,-0.50017,,,,,0.06494666667,-0.572145962
305.331,1.03013,-0.51312,,,,,0.06243212121,-0.5869595058
305.831,0.98809,-0.52416,,,,,0.05988424242,-0.5995881949
306.331,0.9466,-0.53626,,,,,0.05736969697,-0.6134294212
306.831,0.90498,-0.54526,,,,,0.05484727273,-0.6237245482
307.331,0.8632,-0.55759,,,,,0.05231515152,-0.6378288721
307.831,0.82178,-0.56654,,,,,0.04980484848,-0.6480668039
308.331,0.77979,-0.57703,,,,,0.04726,-0.6600663464
308.831,0.73837,-0.58566,,,,,0.04474969697,-0.6699382292
309.331,0.69691,-0.59384,,,,,0.0422369697,-0.6792953558
309.831,0.65467,-0.60242,,,,,0.0396769697,-0.6891100435
310.331,0.61335,-0.60919,,,,,0.03717272727,-0.6968542668
310.831,0.57177,-0.61825,,,,,0.03465272727,-0.7072180279
311.331,0.52977,-0.62581,,,,,0.03210727273,-0.7158659346
311.831,0.48833,-0.63009,,,,,0.02959575758,-0.7207618394
312.331,0.44661,-0.63714,,,,,0.02706727273,-0.7288263555
312.831,0.40492,-0.64452,,,,,0.02454060606,-0.7372683596
313.331,0.36343,-0.65117,,,,,0.02202606061,-0.7448753146
313.831,0.3214,-0.65793,,,,,0.01947878788,-0.7526080988
314.331,0.28005,-0.66312,,,,,0.01697272727,-0.7585449554
314.831,0.2384,-0.66949,,,,,0.01444848485,-0.7658316175
315.331,0.19638,-0.67671,,,,,0.01190181818,-0.7740905971
315.831,0.15504,-0.68141,,,,,0.009396363636,-0.7794669412
316.331,0.11325,-0.68705,,,,,0.006863636364,-0.7859185541
316.831,0.07159,-0.69403,,,,,0.004338787879,-0.793902997
317.331,0.03014,-0.69823,,,,,0.001826666667,-0.7987073896
317.689,-0.00012,-0.70371,,,,,-0.000007272727273,-0.804975978
318.09,0.02872,-0.65193,,,,,0.001740606061,-0.7457446809
318.59,0.07066,-0.62093,,,,,0.004282424242,-0.7102836879
319.09,0.11234,-0.59562,,,,,0.006808484848,-0.6813315031
319.59,0.15349,-0.57716,,,,,0.009302424242,-0.6602150538
320.09,0.19579,-0.55875,,,,,0.01186606061,-0.6391557996
320.59,0.23735,-0.54362,,,,,0.01438484848,-0.6218485472
321.09,0.27859,-0.52948,,,,,0.01688424242,-0.6056737589
321.59,0.32077,-0.51466,,,,,0.01944060606,-0.5887211164
322.09,0.36214,-0.50068,,,,,0.02194787879,-0.5727293526
322.59,0.40383,-0.48755,,,,,0.02447454545,-0.5577099062
323.09,0.44561,-0.47344,,,,,0.02700666667,-0.5415694349
323.59,0.48699,-0.45891,,,,,0.02951454545,-0.5249485244
324.09,0.52895,-0.44686,,,,,0.03205757576,-0.5111644933
324.59,0.57066,-0.43369,,,,,0.03458545455,-0.4960992908
325.09,0.61198,-0.41991,,,,,0.03708969697,-0.4803363075
325.59,0.65407,-0.40636,,,,,0.03964060606,-0.4648364219
326.09,0.69545,-0.39419,,,,,0.04214848485,-0.4509151224
326.59,0.73723,-0.38373,,,,,0.04468060606,-0.438949897
327.09,0.77903,-0.37034,,,,,0.04721393939,-0.4236330359
327.59,0.82023,-0.35818,,,,,0.04971090909,-0.4097231755
328.09,0.86238,-0.34618,,,,,0.05226545455,-0.3959963395
328.59,0.90403,-0.33419,,,,,0.05478969697,-0.3822809426
329.09,0.9452,-0.32158,,,,,0.05728484848,-0.3678563258
329.59,0.98728,-0.30846,,,,,0.05983515152,-0.3528483185
330.09,1.02893,-0.29459,,,,,0.06235939394,-0.3369823839
330.59,1.07036,-0.28171,,,,,0.06487030303,-0.3222489133
331.09,1.11238,-0.2696,,,,,0.0674169697,-0.308396248
331.59,1.15366,-0.25513,,,,,0.06991878788,-0.2918439716
332.09,1.19567,-0.24214,,,,,0.07246484848,-0.2769846717
332.59,1.23731,-0.23011,,,,,0.07498848485,-0.2632235186
333.09,1.27863,-0.21509,,,,,0.07749272727,-0.2460420956
333.59,1.32079,-0.20115,,,,,0.08004787879,-0.2300960879
334.09,1.36227,-0.18725,,,,,0.08256181818,-0.2141958362
334.59,1.40367,-0.17339,,,,,0.08507090909,-0.1983413407
335.09,1.44575,-0.15881,,,,,0.08762121212,-0.181663235
335.59,1.48708,-0.14474,,,,,0.09012606061,-0.1655685198
336.09,1.52884,-0.13174,,,,,0.0926569697,-0.1506977808
336.59,1.57074,-0.11701,,,,,0.09519636364,-0.1338480897
337.09,1.61191,-0.10288,,,,,0.09769151515,-0.1176847403
337.544,1.65007,-0.09324,,,,,0.1000042424,-0.1066575154
337.846,1.62983,-0.15889,,,,,0.09877757576,-0.1817547472
338.346,1.58844,-0.22055,,,,,0.09626909091,-0.252287806
338.846,1.54686,-0.26559,,,,,0.09374909091,-0.303809197
339.346,1.50471,-0.30131,,,,,0.09119454545,-0.344669412
339.846,1.46342,-0.33131,,,,,0.08869212121,-0.3789865019
340.346,1.42175,-0.35776,,,,,0.08616666667,-0.4092427362
340.846,1.37988,-0.38411,,,,,0.08362909091,-0.4393845802
341.346,1.33847,-0.40297,,,,,0.08111939394,-0.4609585907
341.846,1.29655,-0.42167,,,,,0.07857878788,-0.4823495768
342.346,1.25501,-0.44093,,,,,0.07606121212,-0.5043811485
342.846,1.21351,-0.45659,,,,,0.07354606061,-0.5222946694
343.346,1.17145,-0.47328,,,,,0.0709969697,-0.5413864104
343.846,1.13005,-0.4864,,,,,0.06848787879,-0.5563944178
344.346,1.08834,-0.50126,,,,,0.06596,-0.5733928163
344.846,1.04659,-0.51475,,,,,0.06342969697,-0.5888240677
345.346,1.00502,-0.52566,,,,,0.06091030303,-0.6013040494
345.846,0.96323,-0.5367,,,,,0.05837757576,-0.6139327385
346.346,0.92166,-0.5482,,,,,0.05585818182,-0.627087623
346.846,0.88022,-0.55811,,,,,0.05334666667,-0.6384237017
347.346,0.83805,-0.56838,,,,,0.05079090909,-0.6501715854
347.846,0.79678,-0.57738,,,,,0.04828969697,-0.6604667124
348.346,0.75515,-0.58672,,,,,0.04576666667,-0.6711507664
348.846,0.71306,-0.59501,,,,,0.04321575758,-0.6806337223
349.346,0.67176,-0.60303,,,,,0.04071272727,-0.6898078243
349.846,0.62996,-0.61032,,,,,0.03817939394,-0.6981468771
350.346,0.58824,-0.61906,,,,,0.03565090909,-0.7081445893
350.846,0.54681,-0.62714,,,,,0.03314,-0.7173873256
351.346,0.50484,-0.63373,,,,,0.03059636364,-0.7249256463
351.846,0.4633,-0.6412,,,,,0.02807878788,-0.7334706017
352.346,0.42185,-0.64828,,,,,0.02556666667,-0.7415694349
352.846,0.37974,-0.65517,,,,,0.02301454545,-0.7494509266
353.346,0.33842,-0.66108,,,,,0.02051030303,-0.7562113933
353.846,0.29668,-0.6676,,,,,0.01798060606,-0.7636696408
354.346,0.25499,-0.67298,,,,,0.01545393939,-0.7698238389
354.846,0.21351,-0.67833,,,,,0.01294,-0.77594372
355.346,0.1715,-0.68558,,,,,0.01039393939,-0.7842370167
355.846,0.13005,-0.69097,,,,,0.007881818182,-0.7904026539
356.346,0.0885,-0.69567,,,,,0.005363636364,-0.7957789979
356.846,0.04638,-0.70102,,,,,0.002810909091,-0.801898879
357.346,0.00502,-0.70534,,,,,0.0003042424242,-0.8068405399
357.606,0.01209,-0.67671,,,,,0.0007327272727,-0.7740905971
358.106,0.0539,-0.63684,,,,,0.003266666667,-0.7284831846
358.606,0.09521,-0.61118,,,,,0.00577030303,-0.6991306337
359.106,0.13733,-0.58972,,,,,0.008323030303,-0.6745824754
359.606,0.17877,-0.57205,,,,,0.01083454545,-0.6543697094
360.106,0.22041,-0.55666,,,,,0.01335818182,-0.6367650423
360.606,0.26222,-0.53891,,,,,0.01589212121,-0.6164607641
361.106,0.30356,-0.52505,,,,,0.01839757576,-0.6006062686
361.606,0.3456,-0.51147,,,,,0.02094545455,-0.5850720659
362.106,0.38727,-0.49729,,,,,0.02347090909,-0.5688515214
362.606,0.42856,-0.48467,,,,,0.02597333333,-0.5544154656
363.106,0.47068,-0.47157,,,,,0.02852606061,-0.5394303363
363.606,0.51217,-0.45811,,,,,0.03104060606,-0.524033402
364.106,0.55376,-0.4463,,,,,0.03356121212,-0.5105239076
364.606,0.59567,-0.43312,,,,,0.03610121212,-0.4954472661
365.106,0.6369,-0.42039,,,,,0.0386,-0.4808853809
365.606,0.67896,-0.4079,,,,,0.04114909091,-0.4665980325
366.106,0.7207,-0.39481,,,,,0.04367878788,-0.4516243423
366.606,0.7618,-0.38251,,,,,0.04616969697,-0.4375543354
367.106,0.80397,-0.37065,,,,,0.04872545455,-0.4239876458
367.606,0.84555,-0.35765,,,,,0.05124545455,-0.4091169069
368.106,0.88693,-0.34603,,,,,0.05375333333,-0.3958247541
368.606,0.92894,-0.33292,,,,,0.05629939394,-0.3808281858
369.106,0.9704,-0.31841,,,,,0.05881212121,-0.3642301533
369.606,1.01219,-0.3081,,,,,0.06134484848,-0.3524365134
370.106,1.05394,-0.29264,,,,,0.06387515152,-0.334751773
370.606,1.09529,-0.2794,,,,,0.06638121212,-0.3196064974
371.106,1.13735,-0.26398,,,,,0.06893030303,-0.3019675132
371.606,1.17886,-0.25114,,,,,0.07144606061,-0.2872797987
372.106,1.2203,-0.24276,,,,,0.07395757576,-0.2776938916
372.606,1.26232,-0.22623,,,,,0.07650424242,-0.258785175
373.106,1.30365,-0.21326,,,,,0.07900909091,-0.2439487531
373.606,1.34549,-0.20083,,,,,0.08154484848,-0.2297300389
374.106,1.38729,-0.18721,,,,,0.08407818182,-0.2141500801
374.606,1.42851,-0.17403,,,,,0.08657636364,-0.1990734386
375.106,1.47052,-0.16069,,,,,0.08912242424,-0.1838137726
375.606,1.5123,-0.14572,,,,,0.09165454545,-0.1666895447
376.106,1.55349,-0.13179,,,,,0.09415090909,-0.150754976
376.606,1.5957,-0.11662,,,,,0.09670909091,-0.1334019675
377.106,1.63715,-0.10125,,,,,0.09922121212,-0.1158201784
377.362,1.64752,-0.1194,,,,,0.09984969697,-0.1365820178
377.862,1.60504,-0.20491,,,,,0.09727515152,-0.2343971631
378.362,1.56313,-0.25707,,,,,0.09473515152,-0.2940631434
378.862,1.52181,-0.29384,,,,,0.09223090909,-0.3361244566
379.362,1.47988,-0.32572,,,,,0.08968969697,-0.3725920842
379.862,1.43829,-0.35418,,,,,0.08716909091,-0.4051475635
380.362,1.39688,-0.37768,,,,,0.08465939394,-0.4320292839
380.862,1.35473,-0.40041,,,,,0.08210484848,-0.458030199
381.362,1.31331,-0.41994,,,,,0.07959454545,-0.4803706246
381.862,1.27176,-0.43701,,,,,0.07707636364,-0.4998970487
382.362,1.22984,-0.45487,,,,,0.07453575758,-0.5203271563
382.862,1.18831,-0.47053,,,,,0.07201878788,-0.5382406772
383.362,1.1466,-0.48465,,,,,0.06949090909,-0.5543925875
383.862,1.10499,-0.49924,,,,,0.06696909091,-0.5710821322
384.362,1.06352,-0.51236,,,,,0.06445575758,-0.5860901396
384.862,1.0214,-0.52486,,,,,0.0619030303,-0.600388927
385.362,0.98004,-0.53609,,,,,0.05939636364,-0.6132349577
385.862,0.93853,-0.54797,,,,,0.05688060606,-0.6268245253
386.362,0.89637,-0.56076,,,,,0.05432545455,-0.6414550446
386.862,0.85502,-0.56995,,,,,0.05181939394,-0.6519675132
387.362,0.81336,-0.57837,,,,,0.04929454545,-0.6615991764
387.862,0.77152,-0.58925,,,,,0.04675878788,-0.674044841
388.362,0.73009,-0.59713,,,,,0.04424787879,-0.6830587966
388.862,0.6882,-0.60262,,,,,0.04170909091,-0.6893388241
389.362,0.64667,-0.61156,,,,,0.03919212121,-0.6995653169
389.862,0.60514,-0.61971,,,,,0.03667515152,-0.7088881263
390.362,0.56313,-0.62726,,,,,0.03412909091,-0.7175245939
390.862,0.52169,-0.63361,,,,,0.03161757576,-0.7247883779
391.362,0.48004,-0.64233,,,,,0.02909333333,-0.7347632121
391.862,0.43817,-0.64882,,,,,0.02655575758,-0.7421871425
392.362,0.39677,-0.65593,,,,,0.02404666667,-0.7503202928
392.862,0.35481,-0.65887,,,,,0.02150363636,-0.7536833677
393.362,0.31332,-0.66917,,,,,0.01898909091,-0.7654655685
393.862,0.27186,-0.6735,,,,,0.01647636364,-0.7704186685
394.362,0.22964,-0.68147,,,,,0.01391757576,-0.7795355754
394.862,0.18837,-0.68654,,,,,0.01141636364,-0.7853351636
395.362,0.1468,-0.69185,,,,,0.008896969697,-0.7914092885
395.862,0.10472,-0.69961,,,,,0.006346666667,-0.8002859757
396.362,0.06334,-0.70253,,,,,0.003838787879,-0.8036261725
396.862,0.02166,-0.70816,,,,,0.001312727273,-0.8100663464
397.119,-0.00001,-0.71141,,,,,-0.0000006060606061,-0.8137840311