File: mechanical/hysteresis/databak/pristine_hysteresis - conductive_1.csv
Time,Extension,Load,Length,Width,Thickness,CS Area,Strain,Stress
(s),(mm),(N),(mm),(mm),(mm),(mm^2),(mm/mm),(MPa)
0,0,-0.02731,16.5,2.82,0.34,0.9588,0,-0.02848352107
0.5,0.03903,0.01366,,,,,0.002365454545,0.01424697539
1,0.08046,0.03148,,,,,0.004876363636,0.03283270755
1.5,0.12252,0.04699,,,,,0.007425454545,0.04900917814
2,0.16385,0.0572,,,,,0.00993030303,0.05965790572
2.5,0.20566,0.06523,,,,,0.01246424242,0.06803295786
3,0.24752,0.07471,,,,,0.01500121212,0.07792031706
3.5,0.28874,0.07924,,,,,0.01749939394,0.08264497288
4,0.33076,0.0848,,,,,0.02004606061,0.08844388819
4.5,0.37252,0.09101,,,,,0.0225769697,0.09492073425
5,0.41372,0.09466,,,,,0.02507393939,0.09872757614
5.5,0.45593,0.09965,,,,,0.02763212121,0.1039319983
6,0.49741,0.10335,,,,,0.03014606061,0.1077909887
6.5,0.53892,0.10529,,,,,0.03266181818,0.1098143513
7,0.58081,0.11086,,,,,0.03520060606,0.1156236963
7.5,0.62218,0.11129,,,,,0.03770787879,0.1160721736
8,0.66414,0.11388,,,,,0.04025090909,0.1187734668
8.5,0.70579,0.117,,,,,0.04277515152,0.1220275344
9,0.74703,0.11883,,,,,0.04527454545,0.1239361702
9.5,0.78922,0.1211,,,,,0.04783151515,0.126303713
10,0.83077,0.1234,,,,,0.05034969697,0.1287025448
10.5,0.87208,0.12439,,,,,0.05285333333,0.1297350855
11,0.91426,0.12961,,,,,0.05540969697,0.1351793909
11.5,0.95557,0.1305,,,,,0.05791333333,0.1361076345
12,0.99743,0.13151,,,,,0.06045030303,0.1371610346
12.5,1.03915,0.1357,,,,,0.06297878788,0.1415310805
13,1.08044,0.13636,,,,,0.06548121212,0.142219441
13.5,1.12254,0.13881,,,,,0.06803272727,0.1447747184
14,1.16418,0.1415,,,,,0.07055636364,0.1475803087
14.5,1.2055,0.14401,,,,,0.07306060606,0.1501981644
15,1.24752,0.14536,,,,,0.07560727273,0.1516061744
15.5,1.28902,0.14642,,,,,0.07812242424,0.152711723
16,1.33062,0.14673,,,,,0.08064363636,0.1530350438
16.5,1.37244,0.14966,,,,,0.08317818182,0.156090947
17,1.41369,0.15086,,,,,0.08567818182,0.1573425115
17.5,1.45591,0.15228,,,,,0.0882369697,0.1588235294
18,1.49743,0.15503,,,,,0.09075333333,0.161691698
18.5,1.53877,0.15557,,,,,0.09325878788,0.162254902
19,1.58092,0.15922,,,,,0.09581333333,0.1660617438
19.5,1.62243,0.16084,,,,,0.09832909091,0.1677513559
19.831,1.65015,0.16118,,,,,0.1000090909,0.1681059658
20.232,1.62136,0.08486,,,,,0.09826424242,0.08850646642
20.732,1.57953,0.02985,,,,,0.09572909091,0.03113266583
21.232,1.53799,-0.01388,,,,,0.09321151515,-0.01447642887
21.732,1.49643,-0.04734,,,,,0.09069272727,-0.04937421777
22.232,1.4543,-0.07739,,,,,0.08813939394,-0.08071547768
22.732,1.41307,-0.10329,,,,,0.08564060606,-0.1077284105
23.232,1.37144,-0.12609,,,,,0.08311757576,-0.1315081352
23.732,1.32933,-0.14881,,,,,0.08056545455,-0.1552044222
24.232,1.28799,-0.16692,,,,,0.07806,-0.1740926158
24.732,1.24631,-0.18537,,,,,0.07553393939,-0.1933354193
25.232,1.20446,-0.20221,,,,,0.07299757576,-0.2108990405
25.732,1.16312,-0.21753,,,,,0.07049212121,-0.2268773467
26.232,1.12112,-0.23125,,,,,0.06794666667,-0.2411869003
26.732,1.0796,-0.24409,,,,,0.06543030303,-0.25457864
27.232,1.0381,-0.25725,,,,,0.06291515152,-0.2683041302
27.732,0.99602,-0.26949,,,,,0.06036484848,-0.2810700876
28.232,0.95464,-0.28111,,,,,0.0578569697,-0.2931894034
28.732,0.91293,-0.29095,,,,,0.05532909091,-0.303452232
29.232,0.87128,-0.30213,,,,,0.05280484848,-0.3151126408
29.732,0.82966,-0.30944,,,,,0.05028242424,-0.3227367543
30.232,0.7878,-0.31954,,,,,0.04774545455,-0.3332707551
30.732,0.7463,-0.32955,,,,,0.04523030303,-0.3437108886
31.232,0.70479,-0.33723,,,,,0.04271454545,-0.3517209011
31.732,0.6626,-0.34612,,,,,0.04015757576,-0.3609929078
32.232,0.62139,-0.35412,,,,,0.03766,-0.3693366708
32.732,0.57968,-0.36189,,,,,0.03513212121,-0.3774405507
33.232,0.53775,-0.37203,,,,,0.03259090909,-0.3880162703
33.732,0.49637,-0.37694,,,,,0.0300830303,-0.3931372549
34.232,0.45454,-0.38181,,,,,0.02754787879,-0.3982165207
34.732,0.41289,-0.39032,,,,,0.02502363636,-0.4070921986
35.232,0.37141,-0.3991,,,,,0.02250969697,-0.4162494785
35.732,0.32943,-0.4042,,,,,0.01996545455,-0.4215686275
36.232,0.2879,-0.41052,,,,,0.01744848485,-0.4281602003
36.732,0.24646,-0.41595,,,,,0.0149369697,-0.4338235294
37.232,0.20438,-0.42575,,,,,0.01238666667,-0.4440446391
37.732,0.16305,-0.42702,,,,,0.009881818182,-0.4453692115
38.232,0.12124,-0.43416,,,,,0.007347878788,-0.45281602
38.732,0.07962,-0.43819,,,,,0.004825454545,-0.4570191907
39.232,0.03811,-0.44436,,,,,0.00230969697,-0.4634543179
39.687,-0.00006,-0.4497,,,,,-0.000003636363636,-0.4690237797
39.989,0.02012,-0.40874,,,,,0.001219393939,-0.426303713
40.489,0.06179,-0.37621,,,,,0.003744848485,-0.3923758865
40.989,0.10307,-0.35003,,,,,0.006246666667,-0.365070922
41.489,0.1452,-0.33143,,,,,0.0088,-0.3456716729
41.989,0.18658,-0.31317,,,,,0.01130787879,-0.3266270338
42.489,0.22832,-0.30104,,,,,0.01383757576,-0.3139758031
42.989,0.27008,-0.28533,,,,,0.01636848485,-0.2975907384
43.489,0.3115,-0.27408,,,,,0.01887878788,-0.2858573217
43.989,0.35338,-0.25342,,,,,0.0214169697,-0.2643095536
44.489,0.39509,-0.24285,,,,,0.02394484848,-0.2532853567
44.989,0.43642,-0.23026,,,,,0.02644969697,-0.2401543596
45.489,0.47853,-0.21919,,,,,0.02900181818,-0.2286086775
45.989,0.5199,-0.20768,,,,,0.03150909091,-0.2166040884
46.489,0.56166,-0.19699,,,,,0.03404,-0.2054547351
46.989,0.60346,-0.18575,,,,,0.03657333333,-0.193731748
47.489,0.64468,-0.17549,,,,,0.03907151515,-0.1830308719
47.989,0.68682,-0.16575,,,,,0.04162545455,-0.1728723404
48.489,0.72847,-0.15404,,,,,0.04414969697,-0.1606591573
48.989,0.76964,-0.14333,,,,,0.04664484848,-0.1494889445
49.489,0.81175,-0.13265,,,,,0.0491969697,-0.1383500209
49.989,0.85343,-0.12375,,,,,0.0517230303,-0.1290675845
50.489,0.89481,-0.11292,,,,,0.05423090909,-0.1177722153
50.989,0.9369,-0.09974,,,,,0.05678181818,-0.1040258657
51.489,0.97813,-0.09255,,,,,0.05928060606,-0.09652690864
51.989,1.02007,-0.08091,,,,,0.06182242424,-0.08438673342
52.489,1.06174,-0.07114,,,,,0.06434787879,-0.07419691281
52.989,1.103,-0.06151,,,,,0.06684848485,-0.06415310805
53.489,1.14523,-0.05167,,,,,0.06940787879,-0.05389027952
53.989,1.18674,-0.04392,,,,,0.07192363636,-0.04580725907
54.489,1.22809,-0.03435,,,,,0.07442969697,-0.03582603254
54.989,1.27021,-0.02473,,,,,0.07698242424,-0.02579265749
55.489,1.31157,-0.01661,,,,,0.07948909091,-0.01732373801
55.989,1.35326,-0.01082,,,,,0.08201575758,-0.01128493951
56.489,1.39517,0.00162,,,,,0.08455575758,0.001689612015
56.989,1.43639,0.00748,,,,,0.08705393939,0.00780141844
57.489,1.47853,0.01584,,,,,0.08960787879,0.01652065081
57.989,1.52011,0.02379,,,,,0.09212787879,0.02481226533
58.489,1.56141,0.02998,,,,,0.09463090909,0.03126825198
58.989,1.60351,0.03928,,,,,0.09718242424,0.04096787651
59.489,1.64502,0.04706,,,,,0.09969818182,0.04908218607
59.749,1.638,0.00759,,,,,0.09927272727,0.007916145181
60.249,1.5964,-0.05489,,,,,0.09675151515,-0.05724864414
60.749,1.55469,-0.09675,,,,,0.09422363636,-0.1009073842
61.249,1.51269,-0.13011,,,,,0.09167818182,-0.1357008761
61.749,1.47134,-0.15695,,,,,0.08917212121,-0.1636942011
62.249,1.42961,-0.18289,,,,,0.0866430303,-0.1907488527
62.749,1.38779,-0.20323,,,,,0.08410848485,-0.2119628703
63.249,1.34643,-0.22164,,,,,0.08160181818,-0.2311639549
63.749,1.30445,-0.23974,,,,,0.07905757576,-0.2500417188
64.249,1.26293,-0.25696,,,,,0.07654121212,-0.2680016688
64.749,1.22152,-0.27127,,,,,0.07403151515,-0.2829265749
65.249,1.17938,-0.28698,,,,,0.07147757576,-0.2993116395
65.749,1.13796,-0.29988,,,,,0.06896727273,-0.3127659574
66.249,1.09638,-0.31222,,,,,0.06644727273,-0.3256362119
66.749,1.05452,-0.32507,,,,,0.06391030303,-0.3390383813
67.249,1.01299,-0.3359,,,,,0.06139333333,-0.3503337505
67.749,0.97115,-0.34676,,,,,0.05885757576,-0.3616604088
68.249,0.92961,-0.35723,,,,,0.05634,-0.3725803087
68.749,0.88814,-0.36514,,,,,0.05382666667,-0.3808302044
69.249,0.84597,-0.3767,,,,,0.05127090909,-0.392886942
69.749,0.80467,-0.38432,,,,,0.04876787879,-0.4008343763
70.249,0.76314,-0.39222,,,,,0.04625090909,-0.4090738423
70.749,0.721,-0.39942,,,,,0.0436969697,-0.416583229
71.249,0.67968,-0.40743,,,,,0.04119272727,-0.4249374218
71.749,0.63795,-0.41482,,,,,0.03866363636,-0.4326449729
72.249,0.59619,-0.42075,,,,,0.03613272727,-0.4388297872
72.749,0.55473,-0.42792,,,,,0.03362,-0.4463078849
73.249,0.51279,-0.4352,,,,,0.03107818182,-0.4539007092
73.749,0.47131,-0.44069,,,,,0.02856424242,-0.4596266166
74.249,0.42976,-0.44754,,,,,0.02604606061,-0.4667709637
74.749,0.38777,-0.45309,,,,,0.02350121212,-0.4725594493
75.249,0.34632,-0.45847,,,,,0.02098909091,-0.47817063
75.749,0.30459,-0.46482,,,,,0.01846,-0.4847934919
76.249,0.26279,-0.4714,,,,,0.01592666667,-0.491656237
76.749,0.22138,-0.47671,,,,,0.0134169697,-0.4971944097
77.249,0.17938,-0.48087,,,,,0.01087151515,-0.5015331665
77.749,0.138,-0.48537,,,,,0.008363636364,-0.5062265332
78.249,0.09648,-0.49211,,,,,0.005847272727,-0.5132561535
78.749,0.05428,-0.49774,,,,,0.00328969697,-0.5191280768
79.249,0.01302,-0.50133,,,,,0.0007890909091,-0.5228723404
79.506,0.00215,-0.48695,,,,,0.0001303030303,-0.5078744264
80.006,0.04491,-0.44161,,,,,0.002721818182,-0.4605861494
80.506,0.08673,-0.41533,,,,,0.005256363636,-0.4331768878
81.006,0.1281,-0.39592,,,,,0.007763636364,-0.4129328327
81.506,0.17011,-0.37679,,,,,0.01030969697,-0.3929808093
82.006,0.21179,-0.36157,,,,,0.01283575758,-0.3771068002
82.506,0.25306,-0.34897,,,,,0.0153369697,-0.3639653734
83.006,0.29519,-0.33464,,,,,0.01789030303,-0.3490196078
83.506,0.3367,-0.32015,,,,,0.02040606061,-0.333906967
84.006,0.37824,-0.30977,,,,,0.02292363636,-0.3230809345
84.506,0.42018,-0.29598,,,,,0.02546545455,-0.308698373
85.006,0.46144,-0.28455,,,,,0.02796606061,-0.2967772215
85.506,0.50343,-0.27454,,,,,0.03051090909,-0.286337088
86.006,0.5452,-0.26093,,,,,0.03304242424,-0.2721422612
86.506,0.58633,-0.2525,,,,,0.03553515152,-0.2633500209
87.006,0.62847,-0.24049,,,,,0.03808909091,-0.2508239466
87.506,0.67009,-0.22972,,,,,0.04061151515,-0.2395911556
88.006,0.71144,-0.21921,,,,,0.04311757576,-0.2286295369
88.506,0.75344,-0.2067,,,,,0.0456630303,-0.2155819775
89.006,0.79493,-0.19736,,,,,0.04817757576,-0.2058406341
89.506,0.83666,-0.18912,,,,,0.05070666667,-0.1972465582
90.006,0.87844,-0.1778,,,,,0.05323878788,-0.1854401335
90.506,0.91981,-0.16718,,,,,0.05574606061,-0.1743637881
91.006,0.96185,-0.15844,,,,,0.05829393939,-0.165248227
91.506,1.00339,-0.14662,,,,,0.06081151515,-0.1529203171
92.006,1.04479,-0.13671,,,,,0.06332060606,-0.1425844806
92.506,1.08685,-0.12682,,,,,0.06586969697,-0.1322695035
93.006,1.12817,-0.1161,,,,,0.06837393939,-0.1210888611
93.506,1.16993,-0.10578,,,,,0.07090484848,-0.1103254068
94.006,1.21184,-0.0973,,,,,0.07344484848,-0.1014810179
94.506,1.25304,-0.08771,,,,,0.07594181818,-0.091478932
95.006,1.29506,-0.07654,,,,,0.07848848485,-0.07982895286
95.506,1.33681,-0.06729,,,,,0.08101878788,-0.07018147685
96.006,1.378,-0.05927,,,,,0.08351515152,-0.0618168544
96.506,1.42019,-0.04577,,,,,0.08607212121,-0.04773675428
97.006,1.46171,-0.03775,,,,,0.08858848485,-0.03937213183
97.506,1.50321,-0.03009,,,,,0.09110363636,-0.03138297872
98.006,1.54511,-0.02043,,,,,0.0936430303,-0.02130788486
98.506,1.5865,-0.01213,,,,,0.09615151515,-0.01265123071
99.006,1.62846,-0.00469,,,,,0.09869454545,-0.004891531081
99.266,1.65021,0.00027,,,,,0.1000127273,0.0002816020025
99.766,1.61303,-0.07631,,,,,0.09775939394,-0.07958906967
100.266,1.57107,-0.12316,,,,,0.09521636364,-0.128452232
100.766,1.5297,-0.15831,,,,,0.09270909091,-0.1651126408
101.266,1.48791,-0.18749,,,,,0.09017636364,-0.1955465165
101.766,1.44622,-0.20964,,,,,0.08764969697,-0.2186483104
102.266,1.40485,-0.23338,,,,,0.08514242424,-0.2434084272
102.766,1.36273,-0.25404,,,,,0.08258969697,-0.2649561952
103.266,1.32133,-0.27218,,,,,0.08008060606,-0.2838756779
103.766,1.27975,-0.28894,,,,,0.07756060606,-0.3013558615
104.266,1.23776,-0.30334,,,,,0.07501575758,-0.316374635
104.766,1.19634,-0.3166,,,,,0.07250545455,-0.3302044222
105.266,1.15452,-0.32928,,,,,0.06997090909,-0.3434292866
105.766,1.11298,-0.34065,,,,,0.06745333333,-0.3552878598
106.266,1.07134,-0.35333,,,,,0.06492969697,-0.3685127242
106.766,1.0294,-0.36382,,,,,0.06238787879,-0.3794534835
107.266,0.98799,-0.37415,,,,,0.05987818182,-0.3902273675
107.766,0.94644,-0.38359,,,,,0.05736,-0.4000730079
108.266,0.90428,-0.39184,,,,,0.05480484848,-0.4086775136
108.766,0.86307,-0.40154,,,,,0.05230727273,-0.4187943262
109.266,0.82128,-0.4097,,,,,0.04977454545,-0.4273049645
109.766,0.77953,-0.41843,,,,,0.04724424242,-0.436410096
110.266,0.73817,-0.42565,,,,,0.04473757576,-0.4439403421
110.766,0.69613,-0.43438,,,,,0.04218969697,-0.4530454735
111.266,0.65461,-0.44165,,,,,0.03967333333,-0.4606278682
111.766,0.61313,-0.44784,,,,,0.03715939394,-0.4670838548
112.266,0.57108,-0.45581,,,,,0.03461090909,-0.4753963287
112.766,0.52959,-0.46134,,,,,0.03209636364,-0.4811639549
113.266,0.48804,-0.46851,,,,,0.02957818182,-0.4886420526
113.766,0.44612,-0.47523,,,,,0.02703757576,-0.4956508135
114.266,0.40472,-0.47973,,,,,0.02452848485,-0.5003441802
114.766,0.3628,-0.48452,,,,,0.02198787879,-0.5053400083
115.266,0.32131,-0.49203,,,,,0.01947333333,-0.5131727159
115.766,0.27983,-0.49613,,,,,0.01695939394,-0.5174488945
116.266,0.23766,-0.5008,,,,,0.01440363636,-0.5223195661
116.766,0.19634,-0.50585,,,,,0.01189939394,-0.5275865665
117.266,0.15478,-0.51079,,,,,0.009380606061,-0.5327388402
117.766,0.11273,-0.51787,,,,,0.006832121212,-0.5401230705
118.266,0.07132,-0.52111,,,,,0.004322424242,-0.5435022945
118.766,0.02964,-0.52264,,,,,0.001796363636,-0.5450980392
119.122,-0.00013,-0.53016,,,,,-0.000007878787879,-0.5529411765
119.523,0.0284,-0.48167,,,,,0.001721212121,-0.5023675428
120.023,0.06974,-0.45137,,,,,0.004226666667,-0.4707655403
120.523,0.11177,-0.43221,,,,,0.006773939394,-0.4507822278
121.023,0.15344,-0.41318,,,,,0.009299393939,-0.4309345015
121.523,0.19485,-0.39643,,,,,0.01180909091,-0.4134647476
122.023,0.23687,-0.38304,,,,,0.01435575758,-0.3994993742
122.523,0.27816,-0.37034,,,,,0.01685818182,-0.3862536504
123.023,0.3201,-0.35778,,,,,0.0194,-0.3731539424
123.523,0.36176,-0.34486,,,,,0.02192484848,-0.3596787651
124.023,0.40303,-0.33437,,,,,0.02442606061,-0.3487380058
124.523,0.44522,-0.32171,,,,,0.0269830303,-0.3355340008
125.023,0.48678,-0.30905,,,,,0.02950181818,-0.3223299958
125.523,0.52805,-0.29962,,,,,0.0320030303,-0.3124947851
126.023,0.57003,-0.28672,,,,,0.03454727273,-0.2990404673
126.523,0.61165,-0.27647,,,,,0.03706969697,-0.2883500209
127.023,0.65327,-0.26662,,,,,0.03959212121,-0.2780767626
127.523,0.69521,-0.25656,,,,,0.04213393939,-0.2675844806
128.023,0.73641,-0.24421,,,,,0.04463090909,-0.2547037964
128.523,0.77852,-0.23276,,,,,0.0471830303,-0.2427617856
129.023,0.82011,-0.22296,,,,,0.04970363636,-0.2325406758
129.523,0.86144,-0.21222,,,,,0.05220848485,-0.221339174
130.023,0.90358,-0.20226,,,,,0.05476242424,-0.210951189
130.523,0.94503,-0.1931,,,,,0.05727454545,-0.2013975803
131.023,0.98654,-0.18424,,,,,0.05979030303,-0.1921568627
131.523,1.02854,-0.171,,,,,0.06233575758,-0.1783479349
132.023,1.06979,-0.16264,,,,,0.06483575758,-0.1696287025
132.523,1.11168,-0.15409,,,,,0.06737454545,-0.1607113058
133.023,1.1535,-0.14149,,,,,0.06990909091,-0.147569879
133.523,1.19468,-0.13336,,,,,0.07240484848,-0.1390905298
134.023,1.23683,-0.12453,,,,,0.07495939394,-0.1298811014
134.523,1.27846,-0.11169,,,,,0.07748242424,-0.1164893617
135.023,1.31982,-0.10487,,,,,0.07998909091,-0.1093763037
135.523,1.36184,-0.09333,,,,,0.08253575758,-0.09734042553
136.023,1.4033,-0.08419,,,,,0.08504848485,-0.08780767626
136.523,1.44508,-0.07238,,,,,0.08758060606,-0.07549019608
137.023,1.48676,-0.06432,,,,,0.09010666667,-0.06708385482
137.523,1.52807,-0.05468,,,,,0.09261030303,-0.05702962036
138.023,1.57023,-0.04597,,,,,0.09516545455,-0.04794534835
138.523,1.61169,-0.036,,,,,0.09767818182,-0.03754693367
138.981,1.65004,-0.02723,,,,,0.1000024242,-0.02840008344
139.283,1.6297,-0.08105,,,,,0.09876969697,-0.08453274927
139.783,1.58815,-0.13217,,,,,0.09625151515,-0.1378493951
140.283,1.54611,-0.1679,,,,,0.09370363636,-0.1751147267
140.783,1.50465,-0.20007,,,,,0.09119090909,-0.2086670839
141.283,1.46316,-0.22377,,,,,0.08867636364,-0.2333854819
141.783,1.42104,-0.24736,,,,,0.08612363636,-0.2579891531
142.283,1.37962,-0.26794,,,,,0.08361333333,-0.2794534835
142.783,1.33795,-0.2868,,,,,0.08108787879,-0.2991239049
143.283,1.29624,-0.30195,,,,,0.07856,-0.3149249061
143.783,1.25468,-0.31561,,,,,0.07604121212,-0.3291718815
144.283,1.21268,-0.33,,,,,0.07349575758,-0.3441802253
144.783,1.17132,-0.34593,,,,,0.07098909091,-0.3607947434
145.283,1.12979,-0.35778,,,,,0.06847212121,-0.3731539424
145.783,1.08759,-0.36881,,,,,0.06591454545,-0.3846579057
146.283,1.04632,-0.37949,,,,,0.06341333333,-0.3957968294
146.783,1.00478,-0.38986,,,,,0.06089575758,-0.4066124322
147.283,0.96275,-0.40032,,,,,0.05834848485,-0.4175219024
147.783,0.92138,-0.4097,,,,,0.05584121212,-0.4273049645
148.283,0.87953,-0.41546,,,,,0.05330484848,-0.4333124739
148.783,0.8379,-0.42726,,,,,0.05078181818,-0.4456195244
149.283,0.79639,-0.43387,,,,,0.04826606061,-0.4525135586
149.783,0.75435,-0.44204,,,,,0.04571818182,-0.4610346266
150.283,0.71292,-0.44885,,,,,0.04320727273,-0.4681372549
150.783,0.67132,-0.45626,,,,,0.04068606061,-0.4758656654
151.283,0.62947,-0.46314,,,,,0.03814969697,-0.4830413016
151.783,0.58797,-0.46987,,,,,0.03563454545,-0.4900604923
152.283,0.54619,-0.47585,,,,,0.03310242424,-0.4962974552
152.783,0.50452,-0.48236,,,,,0.0305769697,-0.5030871923
153.283,0.46312,-0.48839,,,,,0.02806787879,-0.5093763037
153.783,0.42097,-0.49525,,,,,0.02551333333,-0.5165310805
154.283,0.37969,-0.5016,,,,,0.02301151515,-0.5231539424
154.783,0.33812,-0.50732,,,,,0.02049212121,-0.529119733
155.283,0.29601,-0.51377,,,,,0.01794,-0.5358468919
155.783,0.2547,-0.5185,,,,,0.01543636364,-0.5407801418
156.283,0.21296,-0.52393,,,,,0.01290666667,-0.546443471
156.783,0.17111,-0.52912,,,,,0.01037030303,-0.5518564873
157.283,0.12968,-0.53308,,,,,0.007859393939,-0.55598665
157.783,0.08783,-0.53721,,,,,0.005323030303,-0.5602941176
158.283,0.04623,-0.54088,,,,,0.002801818182,-0.5641218189
158.783,0.00481,-0.54552,,,,,0.0002915151515,-0.5689612015
159.04,0.01123,-0.51926,,,,,0.0006806060606,-0.5415727993
159.54,0.05349,-0.48152,,,,,0.003241818182,-0.5022110972
160.04,0.09497,-0.45737,,,,,0.005755757576,-0.4770233625
160.54,0.13669,-0.43986,,,,,0.008284242424,-0.4587609512
161.04,0.17851,-0.42328,,,,,0.01081878788,-0.4414685023
161.54,0.21965,-0.40905,,,,,0.01331212121,-0.4266270338
162.04,0.26183,-0.39494,,,,,0.01586848485,-0.4119107217
162.54,0.30349,-0.38112,,,,,0.01839333333,-0.3974968711
163.04,0.34462,-0.36855,,,,,0.02088606061,-0.3843867334
163.54,0.38685,-0.35698,,,,,0.02344545455,-0.3723195661
164.04,0.42834,-0.34496,,,,,0.02596,-0.3597830622
164.54,0.46988,-0.33498,,,,,0.02847757576,-0.3493742178
165.04,0.51177,-0.32228,,,,,0.03101636364,-0.336128494
165.54,0.5532,-0.31205,,,,,0.03352727273,-0.325458907
166.04,0.59506,-0.30096,,,,,0.03606424242,-0.3138923655
166.54,0.63679,-0.29081,,,,,0.03859333333,-0.3033062161
167.04,0.67811,-0.28173,,,,,0.04109757576,-0.2938360451
167.54,0.72022,-0.27086,,,,,0.04364969697,-0.282498957
168.04,0.76166,-0.26099,,,,,0.04616121212,-0.2722048394
168.54,0.80322,-0.25057,,,,,0.04868,-0.261337088
169.04,0.84516,-0.23902,,,,,0.05122181818,-0.2492907801
169.54,0.88638,-0.23091,,,,,0.05372,-0.2408322904
170.04,0.92836,-0.22044,,,,,0.05626424242,-0.2299123905
170.54,0.97014,-0.20876,,,,,0.05879636364,-0.2177304965
171.04,1.01132,-0.19761,,,,,0.06129212121,-0.2061013767
171.54,1.05339,-0.18803,,,,,0.06384181818,-0.1961097205
172.04,1.09513,-0.1783,,,,,0.06637151515,-0.1859616187
172.54,1.13642,-0.16886,,,,,0.06887393939,-0.1761159783
173.04,1.17852,-0.15844,,,,,0.07142545455,-0.165248227
173.54,1.21995,-0.14777,,,,,0.07393636364,-0.154119733
174.04,1.26166,-0.13818,,,,,0.07646424242,-0.1441176471
174.54,1.3034,-0.12741,,,,,0.07899393939,-0.1328848561
175.04,1.34475,-0.11908,,,,,0.0815,-0.1241969128
175.54,1.38687,-0.10868,,,,,0.08405272727,-0.1133500209
176.04,1.42844,-0.09897,,,,,0.08657212121,-0.1032227785
176.54,1.4697,-0.09059,,,,,0.08907272727,-0.09448268669
177.04,1.51183,-0.07969,,,,,0.09162606061,-0.08311430955
177.54,1.55332,-0.06894,,,,,0.09414060606,-0.07190237797
178.04,1.5948,-0.06191,,,,,0.09665454545,-0.0645702962
178.54,1.63686,-0.05051,,,,,0.09920363636,-0.05268043388
178.8,1.64716,-0.06422,,,,,0.09982787879,-0.06697955778
179.3,1.60441,-0.13287,,,,,0.0972369697,-0.1385794743
179.8,1.56294,-0.17529,,,,,0.09472363636,-0.1828222778
180.3,1.52129,-0.20693,,,,,0.09219939394,-0.2158218607
180.8,1.47947,-0.23418,,,,,0.08966484848,-0.2442428035
181.3,1.43801,-0.25652,,,,,0.08715212121,-0.2675427618
181.8,1.39611,-0.27705,,,,,0.08461272727,-0.2889549437
182.3,1.35469,-0.29442,,,,,0.08210242424,-0.3070713392
182.8,1.31307,-0.31117,,,,,0.07958,-0.324541093
183.3,1.27099,-0.3265,,,,,0.07702969697,-0.340529829
183.8,1.22966,-0.34198,,,,,0.07452484848,-0.3566750104
184.3,1.18805,-0.35329,,,,,0.0720030303,-0.3684710054
184.8,1.14604,-0.36597,,,,,0.0694569697,-0.3816958698
185.3,1.10474,-0.37692,,,,,0.06695393939,-0.3931163955
185.8,1.06287,-0.38812,,,,,0.06441636364,-0.4047976637
186.3,1.02121,-0.40043,,,,,0.06189151515,-0.4176366291
186.8,0.97982,-0.40982,,,,,0.0593830303,-0.427430121
187.3,0.9377,-0.41934,,,,,0.05683030303,-0.437359199
187.8,0.89627,-0.42745,,,,,0.05431939394,-0.4458176888
188.3,0.85474,-0.43479,,,,,0.05180242424,-0.4534730914
188.8,0.81275,-0.44515,,,,,0.04925757576,-0.4642782645
189.3,0.77126,-0.45231,,,,,0.0467430303,-0.4717459324
189.8,0.72961,-0.46171,,,,,0.04421878788,-0.481549854
190.3,0.68789,-0.46755,,,,,0.04169030303,-0.487640801
190.8,0.64644,-0.47395,,,,,0.03917818182,-0.4943158114
191.3,0.60439,-0.47966,,,,,0.03662969697,-0.5002711723
191.8,0.563,-0.48702,,,,,0.03412121212,-0.5079474343
192.3,0.52153,-0.49424,,,,,0.03160787879,-0.5154776804
192.8,0.47931,-0.50175,,,,,0.02904909091,-0.523310388
193.3,0.43797,-0.50561,,,,,0.02654363636,-0.5273362537
193.8,0.39634,-0.51139,,,,,0.02402060606,-0.5333646224
194.3,0.35446,-0.51697,,,,,0.02148242424,-0.5391843972
194.8,0.31299,-0.52129,,,,,0.01896909091,-0.5436900292
195.3,0.2712,-0.52748,,,,,0.01643636364,-0.5501460159
195.8,0.22958,-0.53239,,,,,0.01391393939,-0.5552670004
196.3,0.18806,-0.53646,,,,,0.01139757576,-0.5595118899
196.8,0.14603,-0.54309,,,,,0.00885030303,-0.5664267835
197.3,0.10467,-0.54809,,,,,0.006343636364,-0.5716416354
197.8,0.06302,-0.55191,,,,,0.003819393939,-0.5756257822
198.3,0.02106,-0.55775,,,,,0.001276363636,-0.5817167292
198.557,-0.00022,-0.55847,,,,,-0.00001333333333,-0.5824676679
199.057,0.03637,-0.50594,,,,,0.002204242424,-0.5276804339
199.557,0.07846,-0.48057,,,,,0.004755151515,-0.5012202753
200.057,0.12008,-0.46054,,,,,0.007277575758,-0.4803295786
200.557,0.16129,-0.44295,,,,,0.009775151515,-0.4619837297
201.057,0.20351,-0.42896,,,,,0.01233393939,-0.4473925741
201.557,0.24508,-0.4148,,,,,0.01485333333,-0.4326241135
202.057,0.28648,-0.40219,,,,,0.01736242424,-0.419472257
202.557,0.3284,-0.38856,,,,,0.0199030303,-0.4052565707
203.057,0.36987,-0.3779,,,,,0.02241636364,-0.3941385065
203.557,0.41169,-0.36585,,,,,0.02495090909,-0.3815707134
204.057,0.45348,-0.35228,,,,,0.02748363636,-0.3674176053
204.557,0.4947,-0.34396,,,,,0.02998181818,-0.3587400918
205.057,0.53686,-0.33297,,,,,0.0325369697,-0.3472778473
205.557,0.57839,-0.32079,,,,,0.03505393939,-0.3345744681
206.057,0.61979,-0.31066,,,,,0.0375630303,-0.3240091781
206.557,0.66184,-0.2995,,,,,0.04011151515,-0.3123696287
207.057,0.7032,-0.28841,,,,,0.04261818182,-0.3008030872
207.557,0.74499,-0.28055,,,,,0.04515090909,-0.29260534
208.057,0.78684,-0.26787,,,,,0.04768727273,-0.2793804756
208.557,0.82801,-0.25802,,,,,0.05018242424,-0.2691072174
209.057,0.87008,-0.24855,,,,,0.05273212121,-0.2592302879
209.557,0.9118,-0.23708,,,,,0.05526060606,-0.2472674176
210.057,0.95304,-0.22947,,,,,0.05776,-0.239330413
210.557,0.99512,-0.21926,,,,,0.06031030303,-0.2286816854
211.057,1.03671,-0.20898,,,,,0.06283090909,-0.2179599499
211.557,1.07823,-0.19913,,,,,0.06534727273,-0.2076866917
212.057,1.12014,-0.1884,,,,,0.06788727273,-0.1964956195
212.557,1.16152,-0.17897,,,,,0.07039515152,-0.1866604088
213.057,1.20347,-0.16958,,,,,0.07293757576,-0.176866917
213.557,1.24502,-0.15882,,,,,0.07545575758,-0.1656445557
214.057,1.28639,-0.14815,,,,,0.0779630303,-0.1545160617
214.557,1.32848,-0.1388,,,,,0.08051393939,-0.1447642887
215.057,1.36991,-0.12882,,,,,0.08302484848,-0.1343554443
215.557,1.41147,-0.11881,,,,,0.08554363636,-0.1239153108
216.057,1.45355,-0.10654,,,,,0.08809393939,-0.1111180642
216.557,1.49479,-0.0971,,,,,0.09059333333,-0.1012724239
217.057,1.53669,-0.0884,,,,,0.09313272727,-0.09219858156
217.557,1.57848,-0.0777,,,,,0.09566545455,-0.0810387985
218.057,1.61969,-0.06961,,,,,0.0981630303,-0.07260116813
218.416,1.65011,-0.06177,,,,,0.1000066667,-0.06442428035
218.817,1.62137,-0.12569,,,,,0.09826484848,-0.131090947
219.317,1.57952,-0.17301,,,,,0.09572848485,-0.1804443054
219.817,1.53799,-0.20702,,,,,0.09321151515,-0.215915728
220.317,1.49644,-0.23422,,,,,0.09069333333,-0.2442845223
220.817,1.4543,-0.25973,,,,,0.08813939394,-0.2708906967
221.317,1.41307,-0.27988,,,,,0.08564060606,-0.2919065499
221.817,1.37143,-0.2985,,,,,0.0831169697,-0.3113266583
222.317,1.32934,-0.3181,,,,,0.08056606061,-0.3317688778
222.817,1.28798,-0.33426,,,,,0.07805939394,-0.3486232791
223.317,1.24634,-0.34814,,,,,0.07553575758,-0.363099708
223.817,1.2045,-0.36229,,,,,0.073,-0.3778577388
224.317,1.16311,-0.37371,,,,,0.07049151515,-0.3897684606
224.817,1.12111,-0.38427,,,,,0.06794606061,-0.4007822278
225.317,1.07962,-0.39657,,,,,0.06543151515,-0.4136107635
225.817,1.03811,-0.40677,,,,,0.06291575758,-0.4242490613
226.317,0.99603,-0.41671,,,,,0.06036545455,-0.4346161869
226.817,0.95465,-0.42557,,,,,0.05785757576,-0.4438569045
227.317,0.91294,-0.43489,,,,,0.05532969697,-0.4535773884
227.817,0.87127,-0.44312,,,,,0.05280424242,-0.4621610346
228.317,0.82965,-0.4489,,,,,0.05028181818,-0.4681894034
228.817,0.78778,-0.45841,,,,,0.04774424242,-0.4781080517
229.317,0.74632,-0.4647,,,,,0.04523151515,-0.4846683354
229.817,0.7048,-0.47435,,,,,0.04271515152,-0.4947329996
230.317,0.6626,-0.48197,,,,,0.04015757576,-0.5026804339
230.817,0.62139,-0.48834,,,,,0.03766,-0.5093241552
231.317,0.5797,-0.49512,,,,,0.03513333333,-0.5163954944
231.817,0.53775,-0.50135,,,,,0.03259090909,-0.5228931998
232.317,0.49638,-0.50697,,,,,0.03008363636,-0.5287546934
232.817,0.45454,-0.51405,,,,,0.02754787879,-0.5361389237
233.317,0.41288,-0.51945,,,,,0.0250230303,-0.5417709637
233.817,0.37142,-0.52739,,,,,0.02251030303,-0.5500521485
234.317,0.32944,-0.52969,,,,,0.01996606061,-0.5524509804
234.817,0.2879,-0.53629,,,,,0.01744848485,-0.5593345849
235.317,0.24644,-0.5398,,,,,0.01493575758,-0.5629954109
235.817,0.20438,-0.5467,,,,,0.01238666667,-0.5701919065
236.317,0.16306,-0.549,,,,,0.009882424242,-0.5725907384
236.817,0.12124,-0.55461,,,,,0.007347878788,-0.5784418023
237.317,0.07961,-0.55914,,,,,0.004824848485,-0.5831664581
237.817,0.03812,-0.56342,,,,,0.00231030303,-0.5876303713
238.272,-0.00006,-0.56742,,,,,-0.000003636363636,-0.5918022528
238.574,0.02011,-0.53262,,,,,0.001218787879,-0.5555068836
239.074,0.06179,-0.49994,,,,,0.003744848485,-0.5214226116
239.574,0.10308,-0.47817,,,,,0.006247272727,-0.4987171464
240.074,0.14521,-0.4597,,,,,0.008800606061,-0.4794534835
240.574,0.18662,-0.44392,,,,,0.01131030303,-0.4629954109
241.074,0.22831,-0.43095,,,,,0.0138369697,-0.4494680851
241.574,0.2701,-0.41759,,,,,0.01636969697,-0.4355340008
242.074,0.3115,-0.40536,,,,,0.01887878788,-0.4227784731
242.574,0.3534,-0.39268,,,,,0.02141818182,-0.4095536087
243.074,0.39513,-0.38052,,,,,0.02394727273,-0.3968710889
243.574,0.43643,-0.36926,,,,,0.02645030303,-0.3851272424
244.074,0.47856,-0.35791,,,,,0.02900363636,-0.3732895286
244.574,0.51991,-0.34801,,,,,0.03150969697,-0.3629641218
245.074,0.56168,-0.33915,,,,,0.03404121212,-0.3537234043
245.574,0.60347,-0.32816,,,,,0.03657393939,-0.3422611598
246.074,0.6447,-0.31657,,,,,0.03907272727,-0.3301731331
246.574,0.68685,-0.30603,,,,,0.04162727273,-0.3191802253
247.074,0.72848,-0.2964,,,,,0.04415030303,-0.3091364205
247.574,0.76967,-0.2864,,,,,0.04664666667,-0.2987067167
248.074,0.81177,-0.27511,,,,,0.04919818182,-0.2869315811
248.574,0.85343,-0.26522,,,,,0.0517230303,-0.2766166041
249.074,0.89483,-0.25369,,,,,0.05423212121,-0.2645911556
249.574,0.9369,-0.24581,,,,,0.05678181818,-0.256372549
250.074,0.97817,-0.23532,,,,,0.0592830303,-0.2454317897
250.574,1.02008,-0.22648,,,,,0.0618230303,-0.2362119316
251.074,1.06176,-0.21501,,,,,0.06434909091,-0.2242490613
251.574,1.10307,-0.20468,,,,,0.06685272727,-0.2134751773
252.074,1.14525,-0.19449,,,,,0.06940909091,-0.2028473091
252.574,1.18677,-0.18665,,,,,0.07192545455,-0.1946704214
253.074,1.22813,-0.17623,,,,,0.07443212121,-0.18380267
253.574,1.27022,-0.16587,,,,,0.0769830303,-0.1729974969
254.074,1.31158,-0.15624,,,,,0.07948969697,-0.1629536921
254.574,1.35327,-0.14667,,,,,0.08201636364,-0.1529724656
255.074,1.39522,-0.13507,,,,,0.08455878788,-0.1408740092
255.574,1.4364,-0.12625,,,,,0.08705454545,-0.1316750104
256.074,1.47853,-0.11564,,,,,0.08960787879,-0.1206090947
256.574,1.52011,-0.10619,,,,,0.09212787879,-0.1107530246
257.074,1.56144,-0.096,,,,,0.09463272727,-0.1001251564
257.574,1.60352,-0.08509,,,,,0.0971830303,-0.0887463496
258.074,1.64505,-0.0751,,,,,0.0997,-0.07832707551
258.334,1.63803,-0.11248,,,,,0.09927454545,-0.1173133083
258.834,1.59644,-0.16829,,,,,0.09675393939,-0.1755214852
259.334,1.55473,-0.20481,,,,,0.09422606061,-0.2136107635
259.834,1.51275,-0.23572,,,,,0.09168181818,-0.2458489779
260.334,1.47139,-0.26058,,,,,0.08917515152,-0.2717772215
260.834,1.42964,-0.2831,,,,,0.08664484848,-0.2952649145
261.334,1.38784,-0.30317,,,,,0.08411151515,-0.31619733
261.834,1.34649,-0.31957,,,,,0.08160545455,-0.3333020442
262.334,1.3045,-0.33533,,,,,0.07906060606,-0.3497392574
262.834,1.26297,-0.35055,,,,,0.07654363636,-0.3656132666
263.334,1.22156,-0.36259,,,,,0.07403393939,-0.37817063
263.834,1.17942,-0.37566,,,,,0.07148,-0.3918022528
264.334,1.13802,-0.38801,,,,,0.06897090909,-0.404682937
264.834,1.09642,-0.39997,,,,,0.06644969697,-0.4171568627
265.334,1.05455,-0.41202,,,,,0.06391212121,-0.4297246558
265.834,1.01303,-0.42159,,,,,0.06139575758,-0.4397058824
266.334,0.97119,-0.42972,,,,,0.05886,-0.4481852315
266.834,0.92966,-0.43929,,,,,0.0563430303,-0.4581664581
267.334,0.88817,-0.44773,,,,,0.05382848485,-0.4669691281
267.834,0.84602,-0.45727,,,,,0.05127393939,-0.4769190655
268.334,0.80471,-0.46563,,,,,0.04877030303,-0.4856382979
268.834,0.7632,-0.47235,,,,,0.04625454545,-0.4926470588
269.334,0.72106,-0.48033,,,,,0.04370060606,-0.5009699625
269.834,0.67972,-0.48609,,,,,0.04119515152,-0.5069774718
270.334,0.63798,-0.49193,,,,,0.03866545455,-0.5130684189
270.834,0.59624,-0.49931,,,,,0.03613575758,-0.5207655403
271.334,0.55478,-0.50574,,,,,0.0336230303,-0.5274718398
271.834,0.51282,-0.51284,,,,,0.03108,-0.5348769295
272.334,0.47135,-0.51876,,,,,0.02856666667,-0.5410513141
272.834,0.42979,-0.52451,,,,,0.02604787879,-0.5470483938
273.334,0.38782,-0.53066,,,,,0.02350424242,-0.5534626617
273.834,0.34635,-0.53518,,,,,0.02099090909,-0.5581768878
274.334,0.30461,-0.54196,,,,,0.01846121212,-0.565248227
274.834,0.26284,-0.54731,,,,,0.01592969697,-0.5708281185
275.334,0.22144,-0.55218,,,,,0.01342060606,-0.5759073842
275.834,0.17941,-0.55733,,,,,0.01087333333,-0.5812786817
276.334,0.13805,-0.56253,,,,,0.008366666667,-0.5867021277
276.834,0.09651,-0.56513,,,,,0.005849090909,-0.5894138506
277.334,0.05433,-0.57069,,,,,0.003292727273,-0.595212766
277.834,0.01303,-0.57473,,,,,0.0007896969697,-0.5994263663
278.091,0.00224,-0.5599,,,,,0.0001357575758,-0.5839591156
278.591,0.04495,-0.52019,,,,,0.002724242424,-0.5425427618
279.091,0.08675,-0.49648,,,,,0.005257575758,-0.5178139341
279.591,0.12814,-0.47637,,,,,0.007766060606,-0.4968397997
280.091,0.17016,-0.46101,,,,,0.01031272727,-0.4808197747
280.591,0.21182,-0.44435,,,,,0.01283757576,-0.4634438882
281.091,0.25308,-0.43371,,,,,0.01533818182,-0.4523466834
281.591,0.29523,-0.4203,,,,,0.01789272727,-0.4383604506
282.091,0.33677,-0.40633,,,,,0.02041030303,-0.4237901544
282.591,0.37827,-0.39352,,,,,0.02292545455,-0.4104297038
283.091,0.42023,-0.38275,,,,,0.02546848485,-0.3991969128
283.591,0.46149,-0.37267,,,,,0.02796909091,-0.3886837714
284.091,0.50349,-0.36163,,,,,0.03051454545,-0.3771693784
284.591,0.54523,-0.35046,,,,,0.03304424242,-0.3655193992
285.091,0.58637,-0.34005,,,,,0.03553757576,-0.3546620776
285.591,0.62853,-0.33003,,,,,0.03809272727,-0.3442115144
286.091,0.67012,-0.31834,,,,,0.04061333333,-0.3320191907
286.591,0.71145,-0.30942,,,,,0.04311818182,-0.3227158949
287.091,0.75348,-0.29871,,,,,0.04566545455,-0.3115456821
287.591,0.79497,-0.29095,,,,,0.04818,-0.303452232
288.091,0.83669,-0.28072,,,,,0.05070848485,-0.292782645
288.591,0.87849,-0.27118,,,,,0.05324181818,-0.2828327076
289.091,0.91983,-0.26068,,,,,0.05574727273,-0.2718815186
289.591,0.9619,-0.24892,,,,,0.0582969697,-0.2596161869
290.091,1.00342,-0.24072,,,,,0.06081333333,-0.2510638298
290.591,1.04481,-0.22938,,,,,0.06332181818,-0.2392365457
291.091,1.08688,-0.21978,,,,,0.06587151515,-0.22922403
291.591,1.12823,-0.21072,,,,,0.06837757576,-0.2197747184
292.091,1.16996,-0.20105,,,,,0.07090666667,-0.2096891948
292.591,1.21188,-0.18862,,,,,0.07344727273,-0.196725073
293.091,1.25308,-0.17858,,,,,0.07594424242,-0.1862536504
293.591,1.2951,-0.16817,,,,,0.07849090909,-0.1753963287
294.091,1.33683,-0.15836,,,,,0.08102,-0.1651647893
294.591,1.37804,-0.1489,,,,,0.08351757576,-0.1552982895
295.091,1.42023,-0.13801,,,,,0.08607454545,-0.1439403421
295.591,1.46176,-0.12855,,,,,0.08859151515,-0.1340738423
296.091,1.50324,-0.11886,,,,,0.09110545455,-0.1239674593
296.591,1.54513,-0.109,,,,,0.09364424242,-0.1136837714
297.091,1.58654,-0.09923,,,,,0.09615393939,-0.1034939508
297.591,1.62849,-0.09083,,,,,0.09869636364,-0.09473299958
297.851,1.65023,-0.0835,,,,,0.1000139394,-0.0870880267
298.351,1.61309,-0.15678,,,,,0.0977630303,-0.1635168961
298.851,1.57114,-0.20089,,,,,0.09522060606,-0.2095223196
299.351,1.5298,-0.23257,,,,,0.09271515152,-0.2425636212
299.851,1.48798,-0.25968,,,,,0.09018060606,-0.2708385482
300.351,1.4463,-0.28382,,,,,0.08765454545,-0.2960158531
300.851,1.40494,-0.30313,,,,,0.08514787879,-0.3161556112
301.351,1.36281,-0.32171,,,,,0.08259454545,-0.3355340008
301.851,1.32142,-0.33836,,,,,0.08008606061,-0.3528994577
302.351,1.27982,-0.35257,,,,,0.07756484848,-0.3677200668
302.851,1.23787,-0.36779,,,,,0.07502242424,-0.3835940759
303.351,1.19641,-0.38029,,,,,0.07250969697,-0.3966312057
303.851,1.15457,-0.39111,,,,,0.06997393939,-0.4079161452
304.351,1.11307,-0.40279,,,,,0.06745878788,-0.4200980392
304.851,1.07145,-0.41287,,,,,0.06493636364,-0.4306111806
305.351,1.02946,-0.42224,,,,,0.06239151515,-0.4403838131
305.851,0.98807,-0.43166,,,,,0.0598830303,-0.4502085941
306.351,0.94651,-0.44203,,,,,0.05736424242,-0.4610241969
306.851,0.90438,-0.45142,,,,,0.05481090909,-0.4708176888
307.351,0.86315,-0.45955,,,,,0.05231212121,-0.479297038
307.851,0.82136,-0.46603,,,,,0.04977939394,-0.486055486
308.351,0.77962,-0.47419,,,,,0.04724969697,-0.4945661243
308.851,0.73825,-0.48376,,,,,0.04474242424,-0.5045473509
309.351,0.69619,-0.49142,,,,,0.04219333333,-0.512536504
309.851,0.65469,-0.49833,,,,,0.03967818182,-0.5197434293
310.351,0.61323,-0.50552,,,,,0.03716545455,-0.5272423863
310.851,0.57116,-0.51277,,,,,0.03461575758,-0.5348039216
311.351,0.52966,-0.51788,,,,,0.03210060606,-0.5401335002
311.851,0.48812,-0.52256,,,,,0.0295830303,-0.5450146016
312.351,0.44622,-0.52956,,,,,0.02704363636,-0.5523153942
312.851,0.40482,-0.5348,,,,,0.02453454545,-0.557780559
313.351,0.36285,-0.53949,,,,,0.02199090909,-0.5626720901
313.851,0.3214,-0.54531,,,,,0.01947878788,-0.5687421777
314.351,0.27994,-0.55099,,,,,0.01696606061,-0.5746662495
314.851,0.23775,-0.55582,,,,,0.01440909091,-0.5797037964
315.351,0.19642,-0.5597,,,,,0.01190424242,-0.5837505215
315.851,0.15484,-0.56296,,,,,0.009384242424,-0.5871506049
316.351,0.11281,-0.57045,,,,,0.006836969697,-0.5949624531
316.851,0.07142,-0.57418,,,,,0.004328484848,-0.5988527326
317.351,0.02971,-0.57798,,,,,0.001800606061,-0.60281602
317.708,-0.00013,-0.5849,,,,,-0.000007878787879,-0.6100333751
318.109,0.02841,-0.53722,,,,,0.001721818182,-0.5603045474
318.609,0.06973,-0.50978,,,,,0.004226060606,-0.5316854401
319.109,0.11175,-0.48791,,,,,0.006772727273,-0.5088756779
319.609,0.15341,-0.47297,,,,,0.009297575758,-0.4932937005
320.109,0.19484,-0.45825,,,,,0.01180848485,-0.4779411765
320.609,0.23685,-0.44496,,,,,0.01435454545,-0.4640801001
321.109,0.27815,-0.42969,,,,,0.01685757576,-0.4481539424
321.609,0.3201,-0.41729,,,,,0.0194,-0.4352211097
322.109,0.36177,-0.40642,,,,,0.02192545455,-0.4238840217
322.609,0.40299,-0.3946,,,,,0.02442363636,-0.4115561118
323.109,0.44521,-0.3857,,,,,0.02698242424,-0.4022736754
323.609,0.48677,-0.37576,,,,,0.02950121212,-0.3919065499
324.109,0.52803,-0.36428,,,,,0.03200181818,-0.3799332499
324.609,0.57005,-0.35325,,,,,0.03454848485,-0.3684292866
325.109,0.61164,-0.34207,,,,,0.03706909091,-0.3567688778
325.609,0.65326,-0.33183,,,,,0.03959151515,-0.3460888611
326.109,0.69516,-0.32265,,,,,0.04213090909,-0.336514393
326.609,0.7364,-0.31152,,,,,0.04463030303,-0.3249061327
327.109,0.7785,-0.30278,,,,,0.04718181818,-0.3157905715
327.609,0.82009,-0.29126,,,,,0.04970242424,-0.3037755528
328.109,0.8614,-0.28315,,,,,0.05220606061,-0.295317063
328.609,0.90358,-0.27338,,,,,0.05476242424,-0.2851272424
329.109,0.94503,-0.26166,,,,,0.05727454545,-0.2729036295
329.609,0.98655,-0.25263,,,,,0.05979090909,-0.263485607
330.109,1.02853,-0.24212,,,,,0.06233515152,-0.2525239883
330.609,1.06977,-0.23316,,,,,0.06483454545,-0.2431789737
331.109,1.11166,-0.22375,,,,,0.06737333333,-0.2333646224
331.609,1.1535,-0.21313,,,,,0.06990909091,-0.222288277
332.109,1.19466,-0.2042,,,,,0.07240363636,-0.2129745515
332.609,1.23685,-0.19321,,,,,0.07496060606,-0.2015123071
333.109,1.27845,-0.18272,,,,,0.07748181818,-0.1905715478
333.609,1.31982,-0.17303,,,,,0.07998909091,-0.1804651648
334.109,1.36183,-0.16243,,,,,0.08253515152,-0.1694096788
334.609,1.40329,-0.15245,,,,,0.08504787879,-0.1590008344
335.109,1.44508,-0.14239,,,,,0.08758060606,-0.1485085524
335.609,1.48677,-0.13108,,,,,0.09010727273,-0.1367125574
336.109,1.52807,-0.12115,,,,,0.09261030303,-0.1263558615
336.609,1.57019,-0.11053,,,,,0.0951630303,-0.1152795161
337.109,1.61168,-0.10203,,,,,0.09767757576,-0.1064142678
337.567,1.65005,-0.0931,,,,,0.1000030303,-0.09710054234
337.869,1.62979,-0.1441,,,,,0.09877515152,-0.1502920317
338.369,1.58825,-0.19145,,,,,0.09625757576,-0.1996766792
338.869,1.54619,-0.22487,,,,,0.09370848485,-0.2345327493
339.369,1.50476,-0.25609,,,,,0.09119757576,-0.2670942845
339.869,1.46325,-0.27852,,,,,0.08868181818,-0.2904881101
340.369,1.42115,-0.30209,,,,,0.08613030303,-0.315070922
340.869,1.37971,-0.31928,,,,,0.08361878788,-0.3329995828
341.369,1.33802,-0.3363,,,,,0.08109212121,-0.3507509387
341.869,1.29635,-0.35368,,,,,0.07856666667,-0.3688777639
342.369,1.25479,-0.36679,,,,,0.07604787879,-0.3825511055
342.869,1.21276,-0.38023,,,,,0.07350060606,-0.3965686275
343.369,1.17141,-0.39363,,,,,0.07099454545,-0.4105444305
343.869,1.12987,-0.40452,,,,,0.0684769697,-0.421902378
344.369,1.08769,-0.41473,,,,,0.06592060606,-0.4325511055
344.869,1.0464,-0.427,,,,,0.06341818182,-0.4453483521
345.369,1.00484,-0.43557,,,,,0.06089939394,-0.4542866083
345.869,0.96286,-0.44568,,,,,0.05835515152,-0.4648310388
346.369,0.92147,-0.4549,,,,,0.05584666667,-0.4744472257
346.869,0.87963,-0.4613,,,,,0.05331090909,-0.4811222361
347.369,0.83799,-0.47015,,,,,0.05078727273,-0.490352524
347.869,0.79649,-0.47898,,,,,0.04827212121,-0.4995619524
348.369,0.75445,-0.48263,,,,,0.04572424242,-0.5033687943
348.869,0.71303,-0.49158,,,,,0.04321393939,-0.5127033792
349.369,0.67139,-0.50023,,,,,0.04069030303,-0.521725073
349.869,0.62961,-0.50497,,,,,0.03815818182,-0.5266687526
350.369,0.58804,-0.51357,,,,,0.03563878788,-0.5356382979
350.869,0.54628,-0.52002,,,,,0.03310787879,-0.5423654568
351.369,0.50464,-0.52414,,,,,0.03058424242,-0.5466624948
351.869,0.4632,-0.53166,,,,,0.02807272727,-0.554505632
352.369,0.42105,-0.53968,,,,,0.02551818182,-0.5628702545
352.869,0.37978,-0.54418,,,,,0.0230169697,-0.5675636212
353.369,0.33821,-0.54866,,,,,0.02049757576,-0.5722361285
353.869,0.29611,-0.55587,,,,,0.01794606061,-0.5797559449
354.369,0.25478,-0.55884,,,,,0.01544121212,-0.582853567
354.869,0.21303,-0.56624,,,,,0.01291090909,-0.5905715478
355.369,0.17123,-0.56861,,,,,0.01037757576,-0.5930433876
355.869,0.12979,-0.57103,,,,,0.007866060606,-0.5955673759
356.369,0.08791,-0.57703,,,,,0.005327878788,-0.6018251982
356.869,0.04633,-0.57917,,,,,0.002807878788,-0.6040571548
357.369,0.00491,-0.5865,,,,,0.0002975757576,-0.6117021277
357.627,0.01123,-0.56383,,,,,0.0006806060606,-0.5880579892
358.127,0.0535,-0.52621,,,,,0.003242424242,-0.5488214435
358.627,0.09495,-0.50326,,,,,0.005754545455,-0.5248852733
359.127,0.13668,-0.48439,,,,,0.008283636364,-0.5052044222
359.627,0.1785,-0.46981,,,,,0.01081818182,-0.4899979141
360.127,0.21966,-0.45623,,,,,0.01331272727,-0.4758343763
360.627,0.26182,-0.44263,,,,,0.01586787879,-0.4616499791
361.127,0.30347,-0.42954,,,,,0.01839212121,-0.4479974969
361.627,0.34463,-0.41773,,,,,0.02088666667,-0.4356800167
362.127,0.38683,-0.40663,,,,,0.02344424242,-0.4241030455
362.627,0.42836,-0.39511,,,,,0.02596121212,-0.4120880267
363.127,0.46986,-0.38512,,,,,0.02847636364,-0.4016687526
363.627,0.51177,-0.37426,,,,,0.03101636364,-0.3903420943
364.127,0.55322,-0.36438,,,,,0.03352848485,-0.3800375469
364.627,0.59505,-0.35378,,,,,0.03606363636,-0.3689820609
365.127,0.6368,-0.34407,,,,,0.03859393939,-0.3588548185
365.627,0.67813,-0.33484,,,,,0.04109878788,-0.3492282019
366.127,0.72021,-0.32413,,,,,0.04364909091,-0.3380579892
366.627,0.76166,-0.31386,,,,,0.04616121212,-0.3273466834
367.127,0.80322,-0.30522,,,,,0.04868,-0.3183354193
367.627,0.84514,-0.29363,,,,,0.05122060606,-0.3062473926
368.127,0.88639,-0.28388,,,,,0.05372060606,-0.2960784314
368.627,0.92838,-0.27343,,,,,0.05626545455,-0.2851793909
369.127,0.97016,-0.26351,,,,,0.05879757576,-0.2748331247
369.627,1.01131,-0.25376,,,,,0.06129151515,-0.2646641635
370.127,1.05339,-0.24358,,,,,0.06384181818,-0.2540467251
370.627,1.09513,-0.23469,,,,,0.06637151515,-0.2447747184
371.127,1.1364,-0.2231,,,,,0.06887272727,-0.2326866917
371.627,1.17854,-0.21152,,,,,0.07142666667,-0.2206090947
372.127,1.21997,-0.20307,,,,,0.07393757576,-0.211795995
372.627,1.26167,-0.1953,,,,,0.07646484848,-0.2036921151
373.127,1.3034,-0.18134,,,,,0.07899393939,-0.1891322486
373.627,1.34474,-0.17384,,,,,0.08149939394,-0.1813099708
374.127,1.38687,-0.16457,,,,,0.08405272727,-0.1716416354
374.627,1.42843,-0.15284,,,,,0.08657151515,-0.1594075928
375.127,1.46968,-0.14412,,,,,0.08907151515,-0.1503128911
375.627,1.51183,-0.13392,,,,,0.09162606061,-0.1396745932
376.127,1.55331,-0.12237,,,,,0.09414,-0.1276282854
376.627,1.59479,-0.11337,,,,,0.09665393939,-0.1182415519
377.127,1.63685,-0.10132,,,,,0.0992030303,-0.1056737589
377.387,1.64721,-0.1174,,,,,0.09983090909,-0.1224447226
377.887,1.60446,-0.18061,,,,,0.09724,-0.1883708803
378.387,1.56302,-0.22178,,,,,0.09472848485,-0.2313099708
378.887,1.52138,-0.25286,,,,,0.09220484848,-0.2637254902
379.387,1.47957,-0.27725,,,,,0.08967090909,-0.2891635378
379.887,1.43809,-0.30017,,,,,0.0871569697,-0.3130684189
380.387,1.39617,-0.31914,,,,,0.08461636364,-0.332853567
380.887,1.35478,-0.33639,,,,,0.08210787879,-0.350844806
381.387,1.31313,-0.35256,,,,,0.07958363636,-0.367709637
381.887,1.27108,-0.36577,,,,,0.07703515152,-0.3814872758
382.387,1.22973,-0.38199,,,,,0.07452909091,-0.3984042553
382.887,1.1881,-0.39285,,,,,0.07200606061,-0.4097309136
383.387,1.1461,-0.40442,,,,,0.06946060606,-0.4217980809
383.887,1.1048,-0.41405,,,,,0.06695757576,-0.4318418857
384.387,1.06295,-0.42827,,,,,0.06442121212,-0.4466729245
384.887,1.0213,-0.43721,,,,,0.0618969697,-0.4559970797
385.387,0.97988,-0.44644,,,,,0.05938666667,-0.4656236963
385.887,0.93777,-0.45631,,,,,0.05683454545,-0.4759178139
386.387,0.89633,-0.4653,,,,,0.0543230303,-0.4852941176
386.887,0.85483,-0.47371,,,,,0.05180787879,-0.4940654985
387.387,0.81285,-0.48248,,,,,0.04926363636,-0.5032123488
387.887,0.77133,-0.48944,,,,,0.04674727273,-0.5104714226
388.387,0.72968,-0.49702,,,,,0.0442230303,-0.5183771381
388.887,0.68797,-0.50413,,,,,0.04169515152,-0.5257926575
389.387,0.64651,-0.51041,,,,,0.03918242424,-0.5323425115
389.887,0.60446,-0.5156,,,,,0.03663393939,-0.5377555277
390.387,0.56307,-0.52393,,,,,0.03412545455,-0.546443471
390.887,0.5216,-0.52804,,,,,0.03161212121,-0.5507300793
391.387,0.47938,-0.53399,,,,,0.02905333333,-0.556935753
391.887,0.43805,-0.53915,,,,,0.02654848485,-0.5623174802
392.387,0.39641,-0.54524,,,,,0.02402484848,-0.5686691698
392.887,0.35452,-0.55189,,,,,0.02148606061,-0.5756049228
393.387,0.31308,-0.5566,,,,,0.01897454545,-0.5805173133
393.887,0.27126,-0.55861,,,,,0.01644,-0.5826136838
394.387,0.22964,-0.56504,,,,,0.01391757576,-0.5893199833
394.887,0.18813,-0.57222,,,,,0.01140181818,-0.5968085106
395.387,0.14612,-0.57512,,,,,0.008855757576,-0.5998331247
395.887,0.10473,-0.58194,,,,,0.006347272727,-0.6069461827
396.387,0.06306,-0.58628,,,,,0.003821818182,-0.6114726742
396.887,0.02113,-0.58998,,,,,0.001280606061,-0.6153316646
397.143,-0.00005,-0.59065,,,,,-0.00000303030303,-0.6160304547