File: mechanical/hysteresis/databak/pristine_hysteresis - nonconductive_3.csv
Time,Extension,Load,Length,Width,Thickness,CS Area,Strain,Stress
(s),(mm),(N),(mm),(mm),(mm),(mm^2),(mm/mm),(MPa)
0,0,-0.00505,16.5,2.82,0.28,0.7896,0,-0.006395643364
0.5,0.03878,0.00547,,,,,0.00235030303,0.006927558257
1,0.08018,0.01226,,,,,0.004859393939,0.01552684904
1.5,0.12216,0.01966,,,,,0.007403636364,0.02489868288
2,0.16359,0.02288,,,,,0.009914545455,0.02897669706
2.5,0.20544,0.02894,,,,,0.01245090909,0.0366514691
3,0.24716,0.03337,,,,,0.01497939394,0.04226190476
3.5,0.28835,0.03752,,,,,0.01747575758,0.0475177305
4,0.33051,0.03951,,,,,0.02003090909,0.05003799392
4.5,0.37209,0.04383,,,,,0.02255090909,0.05550911854
5,0.41335,0.04733,,,,,0.02505151515,0.05994174265
5.5,0.45558,0.05102,,,,,0.02761090909,0.06461499493
6,0.49696,0.05371,,,,,0.03011878788,0.06802178318
6.5,0.53867,0.05668,,,,,0.03264666667,0.07178318136
7,0.58046,0.05876,,,,,0.03517939394,0.07441742655
7.5,0.62183,0.06399,,,,,0.03768666667,0.08104103343
8,0.66384,0.06607,,,,,0.04023272727,0.08367527862
8.5,0.70551,0.06924,,,,,0.04275818182,0.0876899696
9,0.74675,0.07241,,,,,0.04525757576,0.09170466059
9.5,0.78887,0.07493,,,,,0.04781030303,0.09489614995
10,0.83042,0.07819,,,,,0.05032848485,0.0990248227
10.5,0.87193,0.08158,,,,,0.05284424242,0.1033181358
11,0.9138,0.08435,,,,,0.05538181818,0.1068262411
11.5,0.95509,0.08698,,,,,0.05788424242,0.1101570415
12,0.99717,0.08997,,,,,0.06043454545,0.113943769
12.5,1.03871,0.09285,,,,,0.06295212121,0.1175911854
13,1.0801,0.09434,,,,,0.06546060606,0.1194782168
13.5,1.12223,0.0962,,,,,0.06801393939,0.1218338399
14,1.16379,0.09933,,,,,0.07053272727,0.1257978723
14.5,1.20511,0.10185,,,,,0.0730369697,0.1289893617
15,1.24734,0.10464,,,,,0.07559636364,0.1325227964
15.5,1.2886,0.10662,,,,,0.0780969697,0.1350303951
16,1.33035,0.10837,,,,,0.08062727273,0.1372467072
16.5,1.3722,0.11041,,,,,0.08316363636,0.1398302938
17,1.41347,0.11327,,,,,0.08566484848,0.143452381
17.5,1.45546,0.1156,,,,,0.08820969697,0.1464032421
18,1.49706,0.11709,,,,,0.09073090909,0.1482902736
18.5,1.53849,0.12062,,,,,0.09324181818,0.1527608916
19,1.58041,0.12227,,,,,0.09578242424,0.1548505572
19.5,1.62197,0.1242,,,,,0.09830121212,0.1572948328
19.834,1.65009,0.12672,,,,,0.1000054545,0.1604863222
20.235,1.62139,0.10541,,,,,0.09826606061,0.1334979737
20.735,1.57948,0.09015,,,,,0.09572606061,0.1141717325
21.235,1.53787,0.08002,,,,,0.09320424242,0.1013424519
21.735,1.49648,0.06938,,,,,0.09069575758,0.08786727457
22.235,1.45427,0.06156,,,,,0.08813757576,0.07796352584
22.735,1.41293,0.05378,,,,,0.08563212121,0.06811043566
23.235,1.37142,0.04499,,,,,0.08311636364,0.05697821682
23.735,1.32939,0.03767,,,,,0.08056909091,0.0477077001
24.235,1.28789,0.032,,,,,0.07805393939,0.04052684904
24.735,1.24626,0.02538,,,,,0.07553090909,0.03214285714
25.235,1.20455,0.01955,,,,,0.0730030303,0.02475937183
25.735,1.16303,0.01503,,,,,0.07048666667,0.01903495441
26.235,1.12104,0.0093,,,,,0.06794181818,0.0117781155
26.735,1.07966,0.00458,,,,,0.06543393939,0.005800405268
27.235,1.03808,-0.00282,,,,,0.06291393939,-0.003571428571
27.735,0.99588,-0.00484,,,,,0.06035636364,-0.006129685917
28.235,0.95467,-0.00842,,,,,0.05785878788,-0.01066362715
28.735,0.91295,-0.01422,,,,,0.05533030303,-0.01800911854
29.235,0.871,-0.01828,,,,,0.05278787879,-0.02315096251
29.735,0.82962,-0.02238,,,,,0.05028,-0.02834346505
30.235,0.78785,-0.02566,,,,,0.04774848485,-0.03249746707
30.735,0.74612,-0.02904,,,,,0.04521939394,-0.0367781155
31.235,0.70475,-0.03406,,,,,0.04271212121,-0.04313576494
31.735,0.66267,-0.03634,,,,,0.04016181818,-0.04602330294
32.235,0.62124,-0.04177,,,,,0.03765090909,-0.05290020263
32.735,0.57971,-0.04437,,,,,0.03513393939,-0.05619300912
33.235,0.53771,-0.04915,,,,,0.03258848485,-0.06224670719
33.735,0.49627,-0.05187,,,,,0.0300769697,-0.06569148936
34.235,0.45447,-0.05464,,,,,0.02754363636,-0.06919959473
34.735,0.41296,-0.05985,,,,,0.02502787879,-0.07579787234
35.235,0.37129,-0.06204,,,,,0.02250242424,-0.07857142857
35.735,0.32932,-0.06521,,,,,0.01995878788,-0.08258611955
36.235,0.28792,-0.06934,,,,,0.01744969697,-0.08781661601
36.735,0.24637,-0.07347,,,,,0.01493151515,-0.09304711246
37.235,0.20422,-0.07535,,,,,0.0123769697,-0.09542806484
37.735,0.16298,-0.07994,,,,,0.009877575758,-0.1012411348
38.235,0.12122,-0.08136,,,,,0.007346666667,-0.1030395137
38.735,0.07945,-0.0845,,,,,0.004815151515,-0.1070162107
39.235,0.03808,-0.08786,,,,,0.002307878788,-0.1112715299
39.69,0,-0.09073,,,,,0,-0.1149062817
39.992,0.02003,-0.07688,,,,,0.001213939394,-0.09736575481
40.492,0.06163,-0.06637,,,,,0.003735151515,-0.08405521783
40.992,0.10313,-0.05548,,,,,0.00625030303,-0.07026342452
41.492,0.14511,-0.04781,,,,,0.008794545455,-0.06054964539
41.992,0.18644,-0.04286,,,,,0.01129939394,-0.05428064843
42.492,0.22837,-0.03361,,,,,0.01384060606,-0.04256585613
42.992,0.27011,-0.0277,,,,,0.01637030303,-0.0350810537
43.492,0.31131,-0.02231,,,,,0.01886727273,-0.02825481256
43.992,0.35338,-0.01602,,,,,0.0214169697,-0.0202887538
44.492,0.3951,-0.01079,,,,,0.02394545455,-0.01366514691
44.992,0.43633,-0.00483,,,,,0.02644424242,-0.006117021277
45.492,0.47851,0.00141,,,,,0.02900060606,0.001785714286
45.992,0.51996,0.0044,,,,,0.03151272727,0.005572441743
46.492,0.56161,0.00945,,,,,0.0340369697,0.01196808511
46.992,0.60341,0.01497,,,,,0.03657030303,0.01895896657
47.492,0.64476,0.01936,,,,,0.03907636364,0.02451874367
47.992,0.68681,0.02477,,,,,0.04162484848,0.03137031408
48.492,0.7284,0.02877,,,,,0.04414545455,0.03643617021
48.992,0.76969,0.0321,,,,,0.04664787879,0.04065349544
49.492,0.81184,0.03742,,,,,0.04920242424,0.04739108409
49.992,0.85331,0.04026,,,,,0.05171575758,0.05098784195
50.492,0.89478,0.04281,,,,,0.05422909091,0.05421732523
50.992,0.93688,0.0483,,,,,0.05678060606,0.06117021277
51.492,0.97809,0.05056,,,,,0.05927818182,0.06403242148
51.992,1.0201,0.05446,,,,,0.06182424242,0.06897163121
52.492,1.06174,0.05949,,,,,0.06434787879,0.07534194529
52.992,1.10306,0.06093,,,,,0.06685212121,0.0771656535
53.492,1.14515,0.06674,,,,,0.0694030303,0.08452380952
53.992,1.18677,0.069,,,,,0.07192545455,0.08738601824
54.492,1.22818,0.07265,,,,,0.07443515152,0.09200861196
54.992,1.27009,0.07584,,,,,0.07697515152,0.09604863222
55.492,1.31153,0.07965,,,,,0.07948666667,0.1008738602
55.992,1.35332,0.08291,,,,,0.08201939394,0.1050025329
56.492,1.39504,0.08506,,,,,0.08454787879,0.1077254306
56.992,1.43627,0.09044,,,,,0.08704666667,0.1145390071
57.492,1.47856,0.09326,,,,,0.08960969697,0.1181104357
57.992,1.52001,0.09605,,,,,0.09212181818,0.1216438703
58.492,1.56144,0.09939,,,,,0.09463272727,0.1258738602
58.992,1.60352,0.10311,,,,,0.0971830303,0.1305851064
59.492,1.64493,0.1059,,,,,0.09969272727,0.134118541
59.752,1.63789,0.09433,,,,,0.09926606061,0.1194655522
60.252,1.59619,0.07524,,,,,0.09673878788,0.0952887538
60.752,1.55477,0.06369,,,,,0.09422848485,0.08066109422
61.252,1.51268,0.05354,,,,,0.09167757576,0.0678064843
61.752,1.4712,0.04507,,,,,0.08916363636,0.05707953394
62.252,1.42966,0.03856,,,,,0.08664606061,0.04883485309
62.752,1.38775,0.03037,,,,,0.08410606061,0.03846251266
63.252,1.34633,0.02546,,,,,0.08159575758,0.03224417427
63.752,1.30446,0.01888,,,,,0.07905818182,0.02391084093
64.252,1.26293,0.01285,,,,,0.07654121212,0.01627406282
64.752,1.22137,0.00658,,,,,0.07402242424,0.008333333333
65.252,1.17928,0.00119,,,,,0.07147151515,0.001507092199
65.752,1.13798,-0.0032,,,,,0.06896848485,-0.004052684904
66.252,1.09625,-0.00908,,,,,0.06643939394,-0.01149949341
66.752,1.0544,-0.01504,,,,,0.0639030303,-0.01904761905
67.252,1.01297,-0.01774,,,,,0.06139212121,-0.02246707194
67.752,0.97114,-0.0235,,,,,0.0588569697,-0.02976190476
68.252,0.92949,-0.02773,,,,,0.05633272727,-0.03511904762
68.752,0.88811,-0.03082,,,,,0.05382484848,-0.03903242148
69.252,0.84603,-0.03575,,,,,0.05127454545,-0.04527608916
69.752,0.80459,-0.03955,,,,,0.0487630303,-0.05008865248
70.252,0.76315,-0.04259,,,,,0.04625151515,-0.05393870314
70.752,0.72103,-0.04774,,,,,0.04369878788,-0.06046099291
71.252,0.67958,-0.04996,,,,,0.04118666667,-0.06327254306
71.752,0.63786,-0.05443,,,,,0.03865818182,-0.06893363728
72.252,0.59621,-0.05729,,,,,0.03613393939,-0.07255572442
72.752,0.55469,-0.06163,,,,,0.03361757576,-0.07805217832
73.252,0.51264,-0.06325,,,,,0.03106909091,-0.08010385005
73.752,0.47131,-0.06709,,,,,0.02856424242,-0.08496707194
74.252,0.42975,-0.07189,,,,,0.02604545455,-0.09104609929
74.752,0.38755,-0.07418,,,,,0.02348787879,-0.09394630193
75.252,0.34625,-0.07747,,,,,0.02098484848,-0.09811296859
75.752,0.30469,-0.08123,,,,,0.01846606061,-0.1028748734
76.252,0.26272,-0.08337,,,,,0.01592242424,-0.1055851064
76.752,0.22135,-0.0875,,,,,0.01341515152,-0.1108156028
77.252,0.17945,-0.0898,,,,,0.01087575758,-0.1137284701
77.752,0.13787,-0.09179,,,,,0.008355757576,-0.1162487335
78.252,0.09643,-0.09468,,,,,0.005844242424,-0.1199088146
78.752,0.05432,-0.09722,,,,,0.003292121212,-0.1231256332
79.252,0.0129,-0.1018,,,,,0.0007818181818,-0.1289260385
79.51,0.00208,-0.09594,,,,,0.0001260606061,-0.1215045593
80.01,0.04487,-0.08337,,,,,0.002719393939,-0.1055851064
80.51,0.08672,-0.07315,,,,,0.005255757576,-0.09264184397
81.01,0.12792,-0.06397,,,,,0.007752727273,-0.08101570415
81.51,0.16998,-0.05739,,,,,0.01030181818,-0.07268237082
82.01,0.21172,-0.05073,,,,,0.01283151515,-0.06424772036
82.51,0.25294,-0.04294,,,,,0.01532969697,-0.05438196555
83.01,0.29504,-0.03907,,,,,0.01788121212,-0.04948074975
83.51,0.33662,-0.03313,,,,,0.02040121212,-0.04195795339
84.01,0.37812,-0.02648,,,,,0.02291636364,-0.03353596758
84.51,0.42002,-0.02225,,,,,0.02545575758,-0.02817882472
85.01,0.46138,-0.01549,,,,,0.02796242424,-0.01961752786
85.51,0.50332,-0.0125,,,,,0.03050424242,-0.01583080041
86.01,0.54495,-0.00726,,,,,0.03302727273,-0.009194528875
86.51,0.58628,0.00009,,,,,0.03553212121,0.0001139817629
87.01,0.62839,0.00246,,,,,0.03808424242,0.00311550152
87.51,0.66983,0.00782,,,,,0.04059575758,0.009903748734
88.01,0.71135,0.01257,,,,,0.04311212121,0.01591945289
88.51,0.75339,0.01858,,,,,0.04566,0.02353090172
89.01,0.79464,0.02275,,,,,0.04816,0.02881205674
89.51,0.8366,0.02648,,,,,0.0507030303,0.03353596758
90.01,0.8784,0.03202,,,,,0.05323636364,0.04055217832
90.51,0.91955,0.03461,,,,,0.05573030303,0.04383232016
91.01,0.96175,0.03785,,,,,0.05828787879,0.04793566363
91.51,1.00335,0.04453,,,,,0.06080909091,0.05639564336
92.01,1.04463,0.04591,,,,,0.06331090909,0.05814336373
92.51,1.08664,0.05141,,,,,0.0658569697,0.06510891591
93.01,1.12812,0.05421,,,,,0.06837090909,0.0686550152
93.51,1.16988,0.05709,,,,,0.07090181818,0.07230243161
94.01,1.21166,0.06094,,,,,0.07343393939,0.07717831814
94.51,1.25296,0.06413,,,,,0.0759369697,0.0812183384
95.01,1.29507,0.06814,,,,,0.07848909091,0.08629685917
95.51,1.33664,0.07241,,,,,0.08100848485,0.09170466059
96.01,1.37787,0.07592,,,,,0.08350727273,0.09614994934
96.51,1.4201,0.0789,,,,,0.08606666667,0.09992401216
97.01,1.46153,0.08287,,,,,0.08857757576,0.1049518744
97.51,1.50314,0.08447,,,,,0.09109939394,0.1069782168
98.01,1.54497,0.08921,,,,,0.09363454545,0.1129812563
98.51,1.58636,0.09087,,,,,0.0961430303,0.1150835866
99.01,1.62832,0.09449,,,,,0.09868606061,0.1196681864
99.271,1.65019,0.09654,,,,,0.1000115152,0.1222644377
99.771,1.61304,0.07243,,,,,0.09776,0.09172998987
100.271,1.57121,0.05934,,,,,0.09522484848,0.07515197568
100.771,1.52963,0.05074,,,,,0.09270484848,0.06426038501
101.271,1.48784,0.04088,,,,,0.09017212121,0.05177304965
101.771,1.44627,0.034,,,,,0.08765272727,0.0430597771
102.271,1.40469,0.0273,,,,,0.08513272727,0.03457446809
102.771,1.36265,0.01954,,,,,0.08258484848,0.02474670719
103.271,1.32134,0.01346,,,,,0.08008121212,0.01704660588
103.771,1.27972,0.00888,,,,,0.07755878788,0.01124620061
104.271,1.23755,0.00166,,,,,0.0750030303,0.002102330294
104.771,1.19638,-0.00077,,,,,0.07250787879,-0.000975177305
105.271,1.15451,-0.00735,,,,,0.06997030303,-0.009308510638
105.771,1.11281,-0.01522,,,,,0.0674430303,-0.01927558257
106.271,1.07138,-0.01874,,,,,0.06493212121,-0.02373353597
106.771,1.02945,-0.02341,,,,,0.06239090909,-0.029647923
107.271,0.98789,-0.02766,,,,,0.05987212121,-0.03503039514
107.771,0.94645,-0.03226,,,,,0.05736060606,-0.04085612969
108.271,0.90434,-0.03458,,,,,0.05480848485,-0.04379432624
108.771,0.8629,-0.04148,,,,,0.0522969697,-0.05253292806
109.271,0.82131,-0.0454,,,,,0.04977636364,-0.05749746707
109.771,0.77947,-0.04932,,,,,0.04724060606,-0.06246200608
110.271,0.73795,-0.05265,,,,,0.04472424242,-0.06667933131
110.771,0.69606,-0.0569,,,,,0.04218545455,-0.07206180344
111.271,0.65465,-0.0605,,,,,0.03967575758,-0.07662107396
111.771,0.61296,-0.06309,,,,,0.03714909091,-0.07990121581
112.271,0.57099,-0.06703,,,,,0.03460545455,-0.08489108409
112.771,0.52963,-0.07106,,,,,0.03209878788,-0.08999493414
113.271,0.48802,-0.07317,,,,,0.0295769697,-0.09266717325
113.771,0.44598,-0.07552,,,,,0.02702909091,-0.09564336373
114.271,0.40471,-0.08054,,,,,0.02452787879,-0.1020010132
114.771,0.36283,-0.08152,,,,,0.02198969697,-0.1032421479
115.271,0.32124,-0.08636,,,,,0.01946909091,-0.1093718338
115.771,0.27982,-0.08757,,,,,0.01695878788,-0.1109042553
116.271,0.23767,-0.08842,,,,,0.01440424242,-0.1119807497
116.771,0.19623,-0.0934,,,,,0.01189272727,-0.1182877406
117.271,0.15471,-0.09703,,,,,0.009376363636,-0.1228850051
117.771,0.11273,-0.09754,,,,,0.006832121212,-0.1235309017
118.271,0.07122,-0.09995,,,,,0.004316363636,-0.12658308
118.771,0.02955,-0.10359,,,,,0.001790909091,-0.1311930091
119.128,-0.00015,-0.10495,,,,,-0.000009090909091,-0.1329154002
119.529,0.02835,-0.09224,,,,,0.001718181818,-0.1168186424
120.029,0.06956,-0.08224,,,,,0.004215757576,-0.104154002
120.529,0.11166,-0.07377,,,,,0.006767272727,-0.09342705167
121.029,0.15331,-0.06615,,,,,0.009291515152,-0.08377659574
121.529,0.19466,-0.05858,,,,,0.01179757576,-0.07418946302
122.029,0.23679,-0.05322,,,,,0.01435090909,-0.06740121581
122.529,0.27808,-0.04559,,,,,0.01685333333,-0.05773809524
123.029,0.32,-0.04043,,,,,0.01939393939,-0.05120314083
123.529,0.36166,-0.03597,,,,,0.02191878788,-0.04555471125
124.029,0.403,-0.02943,,,,,0.02442424242,-0.03727203647
124.529,0.44514,-0.02483,,,,,0.02697818182,-0.03144630193
125.029,0.48668,-0.02088,,,,,0.02949575758,-0.026443769
125.529,0.52803,-0.01455,,,,,0.03200181818,-0.01842705167
126.029,0.57012,-0.00854,,,,,0.03455272727,-0.01081560284
126.529,0.61149,-0.00337,,,,,0.03706,-0.004267983789
127.029,0.65317,-0.00028,,,,,0.03958606061,-0.0003546099291
127.529,0.69512,0.0046,,,,,0.04212848485,0.005825734549
128.029,0.73627,0.00922,,,,,0.04462242424,0.01167679838
128.529,0.7784,0.01292,,,,,0.04717575758,0.0163627153
129.029,0.82002,0.01631,,,,,0.04969818182,0.02065602837
129.529,0.86132,0.02159,,,,,0.05220121212,0.02734295846
130.029,0.90338,0.02766,,,,,0.05475030303,0.03503039514
130.529,0.94497,0.02931,,,,,0.05727090909,0.03712006079
131.029,0.9865,0.03484,,,,,0.05978787879,0.04412360689
131.529,1.02835,0.04019,,,,,0.06232424242,0.05089918946
132.029,1.06973,0.0413,,,,,0.06483212121,0.05230496454
132.529,1.11172,0.04503,,,,,0.0673769697,0.05702887538
133.029,1.15329,0.04893,,,,,0.06989636364,0.06196808511
133.529,1.19458,0.05246,,,,,0.07239878788,0.06643870314
134.029,1.23681,0.05571,,,,,0.07495818182,0.07055471125
134.529,1.27823,0.05879,,,,,0.07746848485,0.07445542047
135.029,1.3198,0.0626,,,,,0.07998787879,0.07928064843
135.529,1.36176,0.06582,,,,,0.08253090909,0.08335866261
136.029,1.40307,0.07014,,,,,0.08503454545,0.08882978723
136.529,1.44493,0.0729,,,,,0.08757151515,0.09232522796
137.029,1.4868,0.0772,,,,,0.09010909091,0.0977710233
137.529,1.52793,0.07956,,,,,0.09260181818,0.1007598784
138.029,1.57002,0.08295,,,,,0.09515272727,0.1050531915
138.529,1.61168,0.08769,,,,,0.09767757576,0.111056231
138.988,1.65008,0.09044,,,,,0.1000048485,0.1145390071
139.29,1.62964,0.07169,,,,,0.09876606061,0.09079280648
139.79,1.58803,0.05788,,,,,0.09624424242,0.0733029382
140.29,1.54603,0.04877,,,,,0.09369878788,0.06176545086
140.79,1.50462,0.03839,,,,,0.09118909091,0.0486195542
141.29,1.46302,0.02892,,,,,0.08866787879,0.03662613982
141.79,1.42101,0.02182,,,,,0.08612181818,0.02763424519
142.29,1.37967,0.01709,,,,,0.08361636364,0.02164387031
142.79,1.33789,0.01029,,,,,0.08108424242,0.01303191489
143.29,1.29614,0.00332,,,,,0.07855393939,0.004204660588
143.79,1.25478,-0.00062,,,,,0.07604727273,-0.0007852077001
144.29,1.21272,-0.00623,,,,,0.07349818182,-0.007890070922
144.79,1.17127,-0.01181,,,,,0.07098606061,-0.01495694022
145.29,1.12976,-0.01646,,,,,0.06847030303,-0.02084599797
145.79,1.08766,-0.02092,,,,,0.06591878788,-0.02649442756
146.29,1.04627,-0.02532,,,,,0.06341030303,-0.0320668693
146.79,1.00467,-0.03031,,,,,0.06088909091,-0.03838652482
147.29,0.96279,-0.03481,,,,,0.05835090909,-0.04408561297
147.79,0.92127,-0.03813,,,,,0.05583454545,-0.04829027356
148.29,0.87947,-0.04434,,,,,0.05330121212,-0.0561550152
148.79,0.83795,-0.04636,,,,,0.05078484848,-0.05871327254
149.29,0.79642,-0.05083,,,,,0.04826787879,-0.06437436677
149.79,0.75425,-0.05523,,,,,0.04571212121,-0.06994680851
150.29,0.71302,-0.05993,,,,,0.04321333333,-0.07589918946
150.79,0.67139,-0.06323,,,,,0.04069030303,-0.08007852077
151.29,0.6293,-0.06746,,,,,0.03813939394,-0.08543566363
151.79,0.58794,-0.06891,,,,,0.03563272727,-0.08727203647
152.29,0.5463,-0.07302,,,,,0.03310909091,-0.09247720365
152.79,0.50445,-0.07652,,,,,0.03057272727,-0.09690982776
153.29,0.46308,-0.08019,,,,,0.02806545455,-0.1015577508
153.79,0.42106,-0.08309,,,,,0.02551878788,-0.1052304965
154.29,0.37955,-0.08528,,,,,0.0230030303,-0.1080040527
154.79,0.33804,-0.08871,,,,,0.02048727273,-0.1123480243
155.29,0.29601,-0.09067,,,,,0.01794,-0.1148302938
155.79,0.25457,-0.09247,,,,,0.01542848485,-0.1171099291
156.29,0.21285,-0.09426,,,,,0.0129,-0.1193768997
156.79,0.17122,-0.09975,,,,,0.0103769697,-0.1263297872
157.29,0.12963,-0.10025,,,,,0.007856363636,-0.1269630193
157.79,0.08773,-0.10185,,,,,0.005316969697,-0.1289893617
158.29,0.04627,-0.10565,,,,,0.002804242424,-0.133801925
158.79,0.0048,-0.10685,,,,,0.0002909090909,-0.1353216819
159.048,0.01107,-0.10306,,,,,0.0006709090909,-0.1305217832
159.548,0.05336,-0.09179,,,,,0.003233939394,-0.1162487335
160.048,0.09485,-0.08272,,,,,0.005748484848,-0.1047619048
160.548,0.13656,-0.07312,,,,,0.008276363636,-0.09260385005
161.048,0.17838,-0.066,,,,,0.01081090909,-0.08358662614
161.548,0.21971,-0.06055,,,,,0.01331575758,-0.07668439716
162.048,0.26175,-0.05404,,,,,0.01586363636,-0.06843971631
162.548,0.3033,-0.04779,,,,,0.01838181818,-0.06052431611
163.048,0.34471,-0.04195,,,,,0.02089151515,-0.05312816616
163.548,0.38675,-0.03686,,,,,0.02343939394,-0.04668186424
164.048,0.42811,-0.03281,,,,,0.02594606061,-0.0415526849
164.548,0.46986,-0.02766,,,,,0.02847636364,-0.03503039514
165.048,0.51174,-0.02141,,,,,0.03101454545,-0.02711499493
165.548,0.55291,-0.01742,,,,,0.03350969697,-0.02206180344
166.048,0.59498,-0.01397,,,,,0.03605939394,-0.01769250253
166.548,0.63673,-0.00885,,,,,0.03858969697,-0.01120820669
167.048,0.67788,-0.00268,,,,,0.04108363636,-0.003394123607
167.548,0.7201,-0.0004,,,,,0.04364242424,-0.000506585613
168.048,0.76164,0.00588,,,,,0.04616,0.007446808511
168.548,0.80311,0.01043,,,,,0.04867333333,0.01320921986
169.048,0.84503,0.0149,,,,,0.05121393939,0.01887031408
169.548,0.88644,0.02007,,,,,0.05372363636,0.02541793313
170.048,0.9284,0.02221,,,,,0.05626666667,0.02812816616
170.548,0.97004,0.02747,,,,,0.05879030303,0.03478976697
171.048,1.0113,0.03227,,,,,0.06129090909,0.04086879433
171.548,1.05342,0.03569,,,,,0.06384363636,0.04520010132
172.048,1.09498,0.03845,,,,,0.06636242424,0.04869554205
172.548,1.13629,0.04309,,,,,0.06886606061,0.05457193516
173.048,1.17845,0.04828,,,,,0.07142121212,0.06114488349
173.548,1.21975,0.0504,,,,,0.07392424242,0.06382978723
174.048,1.26159,0.05464,,,,,0.07646,0.06919959473
174.548,1.30338,0.05728,,,,,0.07899272727,0.07254305978
175.048,1.34464,0.06172,,,,,0.08149333333,0.07816616008
175.548,1.38672,0.06525,,,,,0.08404363636,0.08263677812
176.048,1.4284,0.06943,,,,,0.08656969697,0.08793059777
176.548,1.46968,0.07127,,,,,0.08907151515,0.09026089159
177.048,1.51174,0.07589,,,,,0.09162060606,0.09611195542
177.548,1.55325,0.07909,,,,,0.09413636364,0.1001646403
178.048,1.59488,0.08215,,,,,0.09665939394,0.1040400203
178.548,1.63669,0.08511,,,,,0.09919333333,0.1077887538
178.809,1.64715,0.08037,,,,,0.09982727273,0.1017857143
179.309,1.60434,0.06028,,,,,0.09723272727,0.07634245187
179.809,1.56306,0.04959,,,,,0.09473090909,0.06280395137
180.309,1.52135,0.03867,,,,,0.0922030303,0.04897416413
180.809,1.47943,0.02961,,,,,0.08966242424,0.0375
181.309,1.43816,0.02321,,,,,0.08716121212,0.02939463019
181.809,1.39611,0.0166,,,,,0.08461272727,0.02102330294
182.309,1.35458,0.00974,,,,,0.08209575758,0.01233535968
182.809,1.31312,0.00344,,,,,0.0795830303,0.004356636272
183.309,1.27105,-0.00165,,,,,0.07703333333,-0.002089665653
183.809,1.22956,-0.0073,,,,,0.07451878788,-0.009245187437
184.309,1.18811,-0.01228,,,,,0.07200666667,-0.01555217832
184.809,1.14608,-0.01696,,,,,0.06945939394,-0.02147922999
185.309,1.10467,-0.02172,,,,,0.06694969697,-0.02750759878
185.809,1.06291,-0.02662,,,,,0.06441878788,-0.03371327254
186.309,1.02126,-0.03175,,,,,0.06189454545,-0.04021023303
186.809,0.97975,-0.03563,,,,,0.05937878788,-0.04512411348
187.309,0.9377,-0.04056,,,,,0.05683030303,-0.05136778116
187.809,0.89639,-0.0449,,,,,0.05432666667,-0.05686423506
188.309,0.8547,-0.04906,,,,,0.0518,-0.06213272543
188.809,0.81274,-0.05447,,,,,0.0492569697,-0.06898429585
189.309,0.77136,-0.05631,,,,,0.04674909091,-0.07131458967
189.809,0.72961,-0.0612,,,,,0.04421878788,-0.07750759878
190.309,0.6878,-0.06592,,,,,0.04168484848,-0.08348530902
190.809,0.64643,-0.06818,,,,,0.03917757576,-0.08634751773
191.309,0.60445,-0.07163,,,,,0.03663333333,-0.09071681864
191.809,0.56297,-0.07634,,,,,0.03411939394,-0.09668186424
192.309,0.52151,-0.08054,,,,,0.03160666667,-0.1020010132
192.809,0.47937,-0.08124,,,,,0.02905272727,-0.102887538
193.309,0.43794,-0.08635,,,,,0.02654181818,-0.1093591692
193.809,0.39637,-0.08738,,,,,0.02402242424,-0.1106636272
194.309,0.35454,-0.09556,,,,,0.02148727273,-0.1210233029
194.809,0.31299,-0.09396,,,,,0.01896909091,-0.1189969605
195.309,0.27115,-0.09738,,,,,0.01643333333,-0.1233282675
195.809,0.22965,-0.09883,,,,,0.01391818182,-0.1251646403
196.309,0.18818,-0.10015,,,,,0.01140484848,-0.1268363728
196.809,0.14598,-0.10184,,,,,0.008847272727,-0.1289766971
197.309,0.10464,-0.10417,,,,,0.006341818182,-0.1319275583
197.809,0.06314,-0.10643,,,,,0.003826666667,-0.134789767
198.309,0.02104,-0.10794,,,,,0.001275151515,-0.1367021277
198.567,-0.00021,-0.10888,,,,,-0.00001272727273,-0.1378926039
199.067,0.03634,-0.09937,,,,,0.002202424242,-0.1258485309
199.567,0.07843,-0.08866,,,,,0.004753333333,-0.1122847011
200.067,0.12006,-0.08199,,,,,0.007276363636,-0.103837386
200.567,0.16137,-0.07355,,,,,0.00978,-0.09314842958
201.067,0.2035,-0.06589,,,,,0.01233333333,-0.0834473151
201.567,0.24495,-0.06105,,,,,0.01484545455,-0.07731762918
202.067,0.28645,-0.05467,,,,,0.01736060606,-0.06923758865
202.567,0.32843,-0.04761,,,,,0.01990484848,-0.06029635258
203.067,0.3697,-0.04307,,,,,0.02240606061,-0.05454660588
203.567,0.41161,-0.03819,,,,,0.02494606061,-0.0483662614
204.067,0.45347,-0.03304,,,,,0.0274830303,-0.04184397163
204.567,0.49463,-0.02681,,,,,0.02997757576,-0.03395390071
205.067,0.53681,-0.02305,,,,,0.03253393939,-0.02919199595
205.567,0.5784,-0.01568,,,,,0.03505454545,-0.01985815603
206.067,0.61975,-0.01296,,,,,0.03756060606,-0.01641337386
206.567,0.66178,-0.0079,,,,,0.04010787879,-0.01000506586
207.067,0.70326,-0.00303,,,,,0.04262181818,-0.003837386018
207.567,0.745,0.00177,,,,,0.04515151515,0.002241641337
208.067,0.78671,0.00686,,,,,0.04767939394,0.008687943262
208.567,0.82804,0.01018,,,,,0.05018424242,0.01289260385
209.067,0.87012,0.01256,,,,,0.05273454545,0.01590678825
209.567,0.91159,0.01831,,,,,0.05524787879,0.02318895643
210.067,0.95299,0.02323,,,,,0.0577569697,0.02941995947
210.567,0.99518,0.02749,,,,,0.06031393939,0.03481509625
211.067,1.0365,0.03089,,,,,0.06281818182,0.03912107396
211.567,1.07822,0.03672,,,,,0.06534666667,0.04650455927
212.067,1.12014,0.03864,,,,,0.06788727273,0.04893617021
212.567,1.16136,0.04371,,,,,0.07038545455,0.05535714286
213.067,1.20341,0.04788,,,,,0.07293393939,0.06063829787
213.567,1.24516,0.04929,,,,,0.07546424242,0.06242401216
214.067,1.28632,0.05436,,,,,0.07795878788,0.0688449848
214.567,1.32839,0.05568,,,,,0.08050848485,0.07051671733
215.067,1.37,0.06074,,,,,0.08303030303,0.07692502533
215.567,1.41152,0.06387,,,,,0.08554666667,0.08088905775
216.067,1.45337,0.06811,,,,,0.0880830303,0.08625886525
216.567,1.49473,0.07082,,,,,0.09058969697,0.08969098278
217.067,1.5367,0.0724,,,,,0.09313333333,0.09169199595
217.567,1.57834,0.07576,,,,,0.0956569697,0.0959473151
218.067,1.61956,0.07897,,,,,0.09815515152,0.1000126646
218.426,1.65011,0.08357,,,,,0.1000066667,0.1058383992
218.827,1.62134,0.06434,,,,,0.0982630303,0.08148429585
219.327,1.57944,0.0502,,,,,0.09572363636,0.06357649443
219.827,1.53785,0.03918,,,,,0.0932030303,0.04962006079
220.327,1.49646,0.0306,,,,,0.09069454545,0.03875379939
220.827,1.45424,0.02308,,,,,0.08813575758,0.02922998987
221.327,1.4129,0.01514,,,,,0.08563030303,0.01917426545
221.827,1.3714,0.01053,,,,,0.08311515152,0.01333586626
222.327,1.32936,0.00291,,,,,0.08056727273,0.003685410334
222.827,1.28786,-0.00256,,,,,0.07805212121,-0.003242147923
223.327,1.24626,-0.00951,,,,,0.07553090909,-0.01204407295
223.827,1.20452,-0.01408,,,,,0.07300121212,-0.01783181358
224.327,1.16298,-0.02009,,,,,0.07048363636,-0.02544326241
224.827,1.12103,-0.02407,,,,,0.06794121212,-0.03048378926
225.327,1.07964,-0.02793,,,,,0.06543272727,-0.03537234043
225.827,1.03809,-0.03284,,,,,0.06291454545,-0.04159067882
226.327,0.99584,-0.03566,,,,,0.06035393939,-0.0451621074
226.827,0.95466,-0.0426,,,,,0.05785818182,-0.05395136778
227.327,0.91291,-0.04495,,,,,0.05532787879,-0.05692755826
227.827,0.871,-0.04993,,,,,0.05278787879,-0.06323454914
228.327,0.82958,-0.05255,,,,,0.05027757576,-0.0665526849
228.827,0.78782,-0.05771,,,,,0.04774666667,-0.07308763931
229.327,0.7461,-0.06272,,,,,0.04521818182,-0.07943262411
229.827,0.70476,-0.06574,,,,,0.04271272727,-0.08325734549
230.327,0.66266,-0.06717,,,,,0.04016121212,-0.08506838906
230.827,0.62122,-0.07273,,,,,0.03764969697,-0.09210992908
231.327,0.57968,-0.07757,,,,,0.03513212121,-0.09823961499
231.827,0.5377,-0.08065,,,,,0.03258787879,-0.1021403242
232.327,0.49626,-0.0836,,,,,0.03007636364,-0.1058763931
232.827,0.45444,-0.08547,,,,,0.02754181818,-0.1082446809
233.327,0.41296,-0.089,,,,,0.02502787879,-0.1127152989
233.827,0.37129,-0.09271,,,,,0.02250242424,-0.1174138804
234.327,0.32929,-0.09371,,,,,0.0199569697,-0.1186803445
234.827,0.2879,-0.09775,,,,,0.01744848485,-0.1237968592
235.327,0.24636,-0.09924,,,,,0.01493090909,-0.1256838906
235.827,0.20421,-0.10157,,,,,0.01237636364,-0.1286347518
236.327,0.16297,-0.10443,,,,,0.009876969697,-0.1322568389
236.827,0.12119,-0.1052,,,,,0.007344848485,-0.1332320162
237.327,0.07941,-0.10763,,,,,0.004812727273,-0.1363095238
237.827,0.03806,-0.11038,,,,,0.002306666667,-0.1397922999
238.282,-0.00003,-0.10987,,,,,-0.000001818181818,-0.1391464032
238.584,0.02,-0.10512,,,,,0.001212121212,-0.1331306991
239.084,0.06162,-0.09366,,,,,0.003734545455,-0.1186170213
239.584,0.10312,-0.08644,,,,,0.00624969697,-0.109473151
240.084,0.14509,-0.07949,,,,,0.008793333333,-0.1006712259
240.584,0.1864,-0.06866,,,,,0.0112969697,-0.08695542047
241.084,0.22837,-0.06508,,,,,0.01384060606,-0.08242147923
241.584,0.27011,-0.05653,,,,,0.01637030303,-0.07159321175
242.084,0.31128,-0.05294,,,,,0.01886545455,-0.06704660588
242.584,0.35337,-0.04602,,,,,0.02141636364,-0.05828267477
243.084,0.3951,-0.04117,,,,,0.02394545455,-0.05214032421
243.584,0.43633,-0.0374,,,,,0.02644424242,-0.04736575481
244.084,0.47853,-0.02978,,,,,0.02900181818,-0.03771529889
244.584,0.51995,-0.02646,,,,,0.03151212121,-0.0335106383
245.084,0.56161,-0.02174,,,,,0.0340369697,-0.02753292806
245.584,0.60341,-0.01617,,,,,0.03657030303,-0.0204787234
246.084,0.64475,-0.01252,,,,,0.03907575758,-0.01585612969
246.584,0.68681,-0.00998,,,,,0.04162484848,-0.01263931104
247.084,0.72839,-0.00445,,,,,0.04414484848,-0.005635764944
247.584,0.76965,-0.00093,,,,,0.04664545455,-0.00117781155
248.084,0.81183,0.00418,,,,,0.04920181818,0.005293819656
248.584,0.85331,0.00778,,,,,0.05171575758,0.009853090172
249.084,0.89477,0.01239,,,,,0.05422848485,0.01569148936
249.584,0.93685,0.01774,,,,,0.05677878788,0.02246707194
250.084,0.97809,0.02255,,,,,0.05927818182,0.02855876393
250.584,1.02007,0.02388,,,,,0.06182242424,0.03024316109
251.084,1.06175,0.02994,,,,,0.06434848485,0.03791793313
251.584,1.10307,0.03306,,,,,0.06685272727,0.04186930091
252.084,1.14514,0.03667,,,,,0.06940242424,0.04644123607
252.584,1.18676,0.04117,,,,,0.07192484848,0.05214032421
253.084,1.22814,0.0464,,,,,0.07443272727,0.0587639311
253.584,1.27009,0.04945,,,,,0.07697515152,0.0626266464
254.084,1.31152,0.05326,,,,,0.07948606061,0.06745187437
254.584,1.35333,0.05605,,,,,0.08202,0.07098530902
255.084,1.39503,0.06061,,,,,0.08454727273,0.07676038501
255.584,1.43627,0.06266,,,,,0.08704666667,0.07935663627
256.084,1.47856,0.06589,,,,,0.08960969697,0.0834473151
256.584,1.52001,0.07043,,,,,0.09212181818,0.0891970618
257.084,1.56144,0.07349,,,,,0.09463272727,0.09307244174
257.584,1.60351,0.07614,,,,,0.09718242424,0.09642857143
258.084,1.64491,0.0786,,,,,0.09969151515,0.09954407295
258.344,1.63791,0.07008,,,,,0.09926727273,0.08875379939
258.844,1.59623,0.05219,,,,,0.09674121212,0.06609675785
259.344,1.55478,0.04022,,,,,0.09422909091,0.05093718338
259.844,1.51268,0.03162,,,,,0.09167757576,0.04004559271
260.344,1.47121,0.02448,,,,,0.08916424242,0.03100303951
260.844,1.42967,0.01619,,,,,0.08664666667,0.02050405268
261.344,1.3878,0.00907,,,,,0.08410909091,0.01148682877
261.844,1.34636,0.00238,,,,,0.08159757576,0.003014184397
262.344,1.30447,-0.00421,,,,,0.07905878788,-0.005331813576
262.844,1.26293,-0.00803,,,,,0.07654121212,-0.01016970618
263.344,1.2214,-0.01397,,,,,0.07402424242,-0.01769250253
263.844,1.17932,-0.01732,,,,,0.07147393939,-0.02193515704
264.344,1.13801,-0.0229,,,,,0.06897030303,-0.02900202634
264.844,1.09626,-0.02746,,,,,0.06644,-0.03477710233
265.344,1.05441,-0.03392,,,,,0.06390363636,-0.04295845998
265.844,1.013,-0.03762,,,,,0.06139393939,-0.0476443769
266.344,0.97113,-0.04164,,,,,0.05885636364,-0.05273556231
266.844,0.9295,-0.04574,,,,,0.05633333333,-0.05792806484
267.344,0.88813,-0.04857,,,,,0.05382606061,-0.06151215805
267.844,0.84605,-0.05137,,,,,0.05127575758,-0.06505825735
268.344,0.80461,-0.05688,,,,,0.04876424242,-0.07203647416
268.844,0.76315,-0.06001,,,,,0.04625151515,-0.07600050659
269.344,0.72104,-0.06585,,,,,0.04369939394,-0.08339665653
269.844,0.6796,-0.06936,,,,,0.04118787879,-0.08784194529
270.344,0.6379,-0.07431,,,,,0.03866060606,-0.09411094225
270.844,0.59624,-0.07616,,,,,0.03613575758,-0.09645390071
271.344,0.5547,-0.07884,,,,,0.03361818182,-0.09984802432
271.844,0.51266,-0.08311,,,,,0.03107030303,-0.1052558257
272.344,0.47134,-0.08707,,,,,0.02856606061,-0.1102710233
272.844,0.42975,-0.09023,,,,,0.02604545455,-0.1142730496
273.344,0.38758,-0.09254,,,,,0.02348969697,-0.1171985816
273.844,0.34627,-0.09483,,,,,0.02098606061,-0.1200987842
274.344,0.3047,-0.09858,,,,,0.01846666667,-0.1248480243
274.844,0.26271,-0.10047,,,,,0.01592181818,-0.1272416413
275.344,0.22133,-0.10304,,,,,0.01341393939,-0.1304964539
275.844,0.17949,-0.10322,,,,,0.01087818182,-0.1307244174
276.344,0.1379,-0.10687,,,,,0.008357575758,-0.1353470111
276.844,0.09643,-0.10824,,,,,0.005844242424,-0.1370820669
277.344,0.05434,-0.10951,,,,,0.003293333333,-0.1386904762
277.844,0.01294,-0.11019,,,,,0.0007842424242,-0.1395516717
278.101,0.00219,-0.11136,,,,,0.0001327272727,-0.1410334347
278.601,0.04498,-0.10086,,,,,0.002726060606,-0.1277355623
279.101,0.08686,-0.09258,,,,,0.005264242424,-0.1172492401
279.601,0.12806,-0.08359,,,,,0.007761212121,-0.1058637285
280.101,0.17009,-0.07822,,,,,0.01030848485,-0.09906281662
280.601,0.21186,-0.07133,,,,,0.01284,-0.09033687943
281.101,0.25307,-0.06374,,,,,0.01533757576,-0.08072441743
281.601,0.29517,-0.05769,,,,,0.01788909091,-0.07306231003
282.101,0.33675,-0.05235,,,,,0.02040909091,-0.0662993921
282.601,0.37823,-0.04613,,,,,0.0229230303,-0.05842198582
283.101,0.42012,-0.03971,,,,,0.02546181818,-0.05029128673
283.601,0.46153,-0.03636,,,,,0.02797151515,-0.04604863222
284.101,0.50344,-0.03075,,,,,0.03051151515,-0.038943769
284.601,0.54507,-0.02697,,,,,0.03303454545,-0.03415653495
285.101,0.58639,-0.02166,,,,,0.03553878788,-0.02743161094
285.601,0.62852,-0.01754,,,,,0.03809212121,-0.02221377913
286.101,0.66997,-0.01333,,,,,0.04060424242,-0.01688196555
286.601,0.71147,-0.00841,,,,,0.04311939394,-0.01065096251
287.101,0.75354,-0.00419,,,,,0.04566909091,-0.005306484296
287.601,0.79479,0.00126,,,,,0.04816909091,0.001595744681
288.101,0.83669,0.00479,,,,,0.05070848485,0.006066362715
288.601,0.87852,0.00837,,,,,0.05324363636,0.01060030395
289.101,0.91968,0.01335,,,,,0.05573818182,0.01690729483
289.601,0.96185,0.01639,,,,,0.05829393939,0.02075734549
290.101,1.0035,0.02062,,,,,0.06081818182,0.02611448835
290.601,1.04473,0.02532,,,,,0.0633169697,0.0320668693
291.101,1.08676,0.03004,,,,,0.06586424242,0.03804457953
291.601,1.1283,0.03477,,,,,0.06838181818,0.04403495441
292.101,1.16999,0.03705,,,,,0.07090848485,0.0469224924
292.601,1.21178,0.04246,,,,,0.07344121212,0.05377406282
293.101,1.2531,0.04607,,,,,0.07594545455,0.05834599797
293.601,1.29519,0.04997,,,,,0.07849636364,0.0632852077
294.101,1.33677,0.05205,,,,,0.08101636364,0.06591945289
294.601,1.37797,0.05813,,,,,0.08351333333,0.0736195542
295.101,1.42023,0.0602,,,,,0.08607454545,0.07624113475
295.601,1.46168,0.06417,,,,,0.08858666667,0.08126899696
296.101,1.50324,0.06696,,,,,0.09110545455,0.08480243161
296.601,1.54513,0.0711,,,,,0.09364424242,0.09004559271
297.101,1.58649,0.07399,,,,,0.09615090909,0.09370567376
297.601,1.62843,0.07475,,,,,0.09869272727,0.09466818642
297.861,1.65025,0.07886,,,,,0.1000151515,0.0998733536
298.361,1.61313,0.05727,,,,,0.09776545455,0.07253039514
298.861,1.57133,0.04348,,,,,0.09523212121,0.05506585613
299.361,1.52974,0.03508,,,,,0.09271151515,0.04442755826
299.861,1.48794,0.0255,,,,,0.09017818182,0.03229483283
300.361,1.44638,0.01887,,,,,0.08765939394,0.02389817629
300.861,1.4048,0.01099,,,,,0.08513939394,0.01391843972
301.361,1.36273,0.00294,,,,,0.08258969697,0.003723404255
301.861,1.32144,-0.00304,,,,,0.08008727273,-0.003850050659
302.361,1.27982,-0.00916,,,,,0.07756484848,-0.01160081054
302.861,1.23767,-0.01512,,,,,0.07501030303,-0.01914893617
303.361,1.19649,-0.01803,,,,,0.07251454545,-0.0228343465
303.861,1.1546,-0.02387,,,,,0.06997575758,-0.03023049645
304.361,1.11292,-0.02988,,,,,0.06744969697,-0.03784194529
304.861,1.07146,-0.03405,,,,,0.0649369697,-0.0431231003
305.361,1.02955,-0.03745,,,,,0.0623969697,-0.04742907801
305.861,0.98799,-0.04294,,,,,0.05987818182,-0.05438196555
306.361,0.94654,-0.0463,,,,,0.05736606061,-0.0586372847
306.861,0.90446,-0.05105,,,,,0.05481575758,-0.06465298886
307.361,0.86302,-0.05373,,,,,0.05230424242,-0.06804711246
307.861,0.82138,-0.05875,,,,,0.04978060606,-0.0744047619
308.361,0.77958,-0.06288,,,,,0.04724727273,-0.07963525836
308.861,0.73807,-0.06507,,,,,0.04473151515,-0.08240881459
309.361,0.69615,-0.06957,,,,,0.04219090909,-0.08810790274
309.861,0.65476,-0.07258,,,,,0.03968242424,-0.09191995947
310.361,0.6131,-0.07594,,,,,0.03715757576,-0.09617527862
310.861,0.57109,-0.07833,,,,,0.03461151515,-0.09920212766
311.361,0.52972,-0.08154,,,,,0.03210424242,-0.1032674772
311.861,0.48809,-0.08567,,,,,0.02958121212,-0.1084979737
312.361,0.44613,-0.08926,,,,,0.02703818182,-0.1130445795
312.861,0.40483,-0.09237,,,,,0.02453515152,-0.1169832827
313.361,0.36293,-0.09503,,,,,0.02199575758,-0.120352077
313.861,0.32135,-0.09902,,,,,0.01947575758,-0.1254052685
314.361,0.27996,-0.10017,,,,,0.01696727273,-0.1268617021
314.861,0.23778,-0.10205,,,,,0.01441090909,-0.1292426545
315.361,0.19634,-0.10511,,,,,0.01189939394,-0.1331180344
315.861,0.15479,-0.10709,,,,,0.009381212121,-0.1356256332
316.361,0.11287,-0.10946,,,,,0.006840606061,-0.138627153
316.861,0.07135,-0.11071,,,,,0.004324242424,-0.140210233
317.361,0.02962,-0.11188,,,,,0.001795151515,-0.1416919959
317.719,-0.00014,-0.11187,,,,,-0.000008484848485,-0.1416793313
318.12,0.02838,-0.10551,,,,,0.00172,-0.1336246201
318.62,0.06957,-0.09719,,,,,0.004216363636,-0.1230876393
319.12,0.11167,-0.09099,,,,,0.006767878788,-0.1152355623
319.62,0.15332,-0.08264,,,,,0.009292121212,-0.1046605876
320.12,0.19468,-0.07407,,,,,0.01179878788,-0.09380699088
320.62,0.2368,-0.07117,,,,,0.01435151515,-0.09013424519
321.12,0.27808,-0.06392,,,,,0.01685333333,-0.08095238095
321.62,0.32001,-0.05917,,,,,0.01939454545,-0.0749366768
322.12,0.36169,-0.05317,,,,,0.02192060606,-0.0673378926
322.62,0.40299,-0.04667,,,,,0.02442363636,-0.05910587639
323.12,0.44516,-0.04157,,,,,0.02697939394,-0.05264690983
323.62,0.48669,-0.03613,,,,,0.02949636364,-0.04575734549
324.12,0.52803,-0.03208,,,,,0.03200181818,-0.04062816616
324.62,0.57013,-0.02607,,,,,0.03455333333,-0.03301671733
325.12,0.61151,-0.02156,,,,,0.03706121212,-0.02730496454
325.62,0.65319,-0.01755,,,,,0.03958727273,-0.02222644377
326.12,0.69514,-0.01075,,,,,0.04212969697,-0.01361448835
326.62,0.73628,-0.00512,,,,,0.0446230303,-0.006484295846
327.12,0.77843,-0.0028,,,,,0.04717757576,-0.003546099291
327.62,0.82004,0.00093,,,,,0.04969939394,0.00117781155
328.12,0.86133,0.00646,,,,,0.05220181818,0.008181357649
328.62,0.90339,0.01039,,,,,0.05475090909,0.0131585613
329.12,0.94498,0.01394,,,,,0.05727151515,0.01765450861
329.62,0.98652,0.01944,,,,,0.05978909091,0.02462006079
330.12,1.02836,0.02335,,,,,0.06232484848,0.02957193516
330.62,1.06973,0.02704,,,,,0.06483212121,0.03424518744
331.12,1.11174,0.03041,,,,,0.06737818182,0.03851317123
331.62,1.15329,0.03343,,,,,0.06989636364,0.0423378926
332.12,1.19459,0.03816,,,,,0.07239939394,0.04832826748
332.62,1.23683,0.04287,,,,,0.07495939394,0.05429331307
333.12,1.27825,0.04527,,,,,0.07746969697,0.05733282675
333.62,1.3198,0.04831,,,,,0.07998787879,0.06118287741
334.12,1.36178,0.05155,,,,,0.08253212121,0.06528622087
334.62,1.40308,0.05536,,,,,0.08503515152,0.07011144883
335.12,1.44493,0.05824,,,,,0.08757151515,0.07375886525
335.62,1.48681,0.06249,,,,,0.09010969697,0.07914133739
336.12,1.52796,0.06707,,,,,0.09260363636,0.08494174265
336.62,1.57001,0.06899,,,,,0.09515212121,0.0873733536
337.12,1.61169,0.0727,,,,,0.09767818182,0.09207193516
337.579,1.65008,0.07576,,,,,0.1000048485,0.0959473151
337.881,1.62984,0.05995,,,,,0.09877818182,0.07592451874
338.381,1.5882,0.04563,,,,,0.09625454545,0.0577887538
338.881,1.54619,0.03563,,,,,0.09370848485,0.04512411348
339.381,1.50479,0.02663,,,,,0.09119939394,0.03372593718
339.881,1.4632,0.01774,,,,,0.08867878788,0.02246707194
340.381,1.4212,0.0103,,,,,0.08613333333,0.01304457953
340.881,1.37986,0.00437,,,,,0.08362787879,0.005534447822
341.381,1.33806,-0.00178,,,,,0.08109454545,-0.002254305978
341.881,1.29636,-0.00659,,,,,0.07856727273,-0.008345997974
342.381,1.25497,-0.012,,,,,0.07605878788,-0.01519756839
342.881,1.21285,-0.01723,,,,,0.07350606061,-0.02182117528
343.381,1.17144,-0.02139,,,,,0.07099636364,-0.02708966565
343.881,1.12991,-0.02772,,,,,0.06847939394,-0.03510638298
344.381,1.08783,-0.03059,,,,,0.06592909091,-0.03874113475
344.881,1.04643,-0.03597,,,,,0.06342,-0.04555471125
345.381,1.00485,-0.04172,,,,,0.0609,-0.05283687943
345.881,0.96297,-0.04479,,,,,0.05836181818,-0.05672492401
346.381,0.92145,-0.04896,,,,,0.05584545455,-0.06200607903
346.881,0.87961,-0.05308,,,,,0.05330969697,-0.06722391084
347.381,0.83813,-0.05642,,,,,0.05079575758,-0.07145390071
347.881,0.79659,-0.06097,,,,,0.04827818182,-0.07721631206
348.381,0.75439,-0.06437,,,,,0.04572060606,-0.08152228977
348.881,0.7132,-0.0676,,,,,0.04322424242,-0.08561296859
349.381,0.67153,-0.07281,,,,,0.04069878788,-0.0922112462
349.881,0.62951,-0.07543,,,,,0.03815212121,-0.09552938197
350.381,0.58813,-0.07839,,,,,0.03564424242,-0.0992781155
350.881,0.54644,-0.08387,,,,,0.03311757576,-0.1062183384
351.381,0.50466,-0.08659,,,,,0.03058545455,-0.1096631206
351.881,0.46325,-0.08917,,,,,0.02807575758,-0.1129305978
352.381,0.4212,-0.09205,,,,,0.02552727273,-0.1165780142
352.881,0.37974,-0.09419,,,,,0.02301454545,-0.1192882472
353.381,0.33823,-0.098,,,,,0.02049878788,-0.1241134752
353.881,0.29619,-0.10176,,,,,0.01795090909,-0.1288753799
354.381,0.25477,-0.10279,,,,,0.01544060606,-0.1301798379
354.881,0.21302,-0.10569,,,,,0.01291030303,-0.1338525836
355.381,0.17143,-0.10707,,,,,0.01038969697,-0.135600304
355.881,0.12979,-0.10743,,,,,0.007866060606,-0.136056231
356.381,0.08789,-0.10908,,,,,0.005326666667,-0.1381458967
356.881,0.04645,-0.11171,,,,,0.002815151515,-0.1414766971
357.381,0.00497,-0.11368,,,,,0.0003012121212,-0.1439716312
357.641,0.01107,-0.11021,,,,,0.0006709090909,-0.139577001
358.141,0.05337,-0.10223,,,,,0.003234545455,-0.129470618
358.641,0.09484,-0.0946,,,,,0.005747878788,-0.1198074975
359.141,0.13657,-0.08601,,,,,0.008276969697,-0.1089285714
359.641,0.17838,-0.07949,,,,,0.01081090909,-0.1006712259
360.141,0.21974,-0.07203,,,,,0.01331757576,-0.09122340426
360.641,0.26177,-0.06626,,,,,0.01586484848,-0.08391590679
361.141,0.30331,-0.06007,,,,,0.01838242424,-0.07607649443
361.641,0.34471,-0.05473,,,,,0.02089151515,-0.06931357649
362.141,0.38676,-0.04943,,,,,0.02344,-0.06260131712
362.641,0.42812,-0.04408,,,,,0.02594666667,-0.05582573455
363.141,0.46987,-0.03741,,,,,0.0284769697,-0.04737841945
363.641,0.51176,-0.03262,,,,,0.03101575758,-0.04131205674
364.141,0.55292,-0.02764,,,,,0.03351030303,-0.03500506586
364.641,0.59497,-0.0235,,,,,0.03605878788,-0.02976190476
365.141,0.63672,-0.02091,,,,,0.03858909091,-0.02648176292
365.641,0.67789,-0.01547,,,,,0.04108424242,-0.01959219858
366.141,0.72012,-0.01005,,,,,0.04364363636,-0.01272796353
366.641,0.76167,-0.00559,,,,,0.04616181818,-0.007079533941
367.141,0.80313,-0.00027,,,,,0.04867454545,-0.0003419452888
367.641,0.84505,0.0041,,,,,0.05121515152,0.005192502533
368.141,0.88646,0.00779,,,,,0.05372484848,0.009865754813
368.641,0.9284,0.01092,,,,,0.05626666667,0.01382978723
369.141,0.97002,0.01421,,,,,0.05878909091,0.0179964539
369.641,1.01129,0.01842,,,,,0.06129030303,0.02332826748
370.141,1.05345,0.02246,,,,,0.06384545455,0.02844478217
370.641,1.09499,0.02755,,,,,0.0663630303,0.03489108409
371.141,1.13631,0.03042,,,,,0.06886727273,0.03852583587
371.641,1.17845,0.03251,,,,,0.07142121212,0.04117274569
372.141,1.21977,0.03888,,,,,0.07392545455,0.04924012158
372.641,1.2616,0.04062,,,,,0.07646060606,0.051443769
373.141,1.30338,0.0449,,,,,0.07899272727,0.05686423506
373.641,1.34464,0.04907,,,,,0.08149333333,0.06214539007
374.141,1.38673,0.05381,,,,,0.08404424242,0.06814842958
374.641,1.4284,0.05629,,,,,0.08656969697,0.07128926039
375.141,1.46969,0.06031,,,,,0.08907212121,0.0763804458
375.641,1.51175,0.06515,,,,,0.09162121212,0.08251013171
376.141,1.55326,0.06811,,,,,0.0941369697,0.08625886525
376.641,1.59489,0.07151,,,,,0.09666,0.09056484296
377.141,1.63669,0.07462,,,,,0.09919333333,0.0945035461
377.402,1.64721,0.06875,,,,,0.09983090909,0.08706940223
377.902,1.60447,0.05072,,,,,0.09724060606,0.06423505572
378.402,1.56319,0.03771,,,,,0.09473878788,0.04775835866
378.902,1.52147,0.02822,,,,,0.09221030303,0.03573961499
379.402,1.47954,0.02059,,,,,0.08966909091,0.02607649443
379.902,1.4383,0.0138,,,,,0.08716969697,0.01747720365
380.402,1.39622,0.00669,,,,,0.08461939394,0.008472644377
380.902,1.3547,-0.00004,,,,,0.0821030303,-0.0000506585613
381.402,1.31325,-0.00622,,,,,0.07959090909,-0.007877406282
381.902,1.27115,-0.00953,,,,,0.07703939394,-0.01206940223
382.402,1.22971,-0.01641,,,,,0.07452787879,-0.02078267477
382.902,1.18822,-0.02379,,,,,0.07201333333,-0.03012917933
383.402,1.14624,-0.02734,,,,,0.06946909091,-0.03462512665
383.902,1.1048,-0.03174,,,,,0.06695757576,-0.04019756839
384.402,1.06301,-0.03607,,,,,0.06442484848,-0.04568135765
384.902,1.0214,-0.04171,,,,,0.0619030303,-0.05282421479
385.402,0.97989,-0.0449,,,,,0.05938727273,-0.05686423506
385.902,0.93782,-0.04893,,,,,0.05683757576,-0.06196808511
386.402,0.89653,-0.05393,,,,,0.05433515152,-0.06830040527
386.902,0.85483,-0.05875,,,,,0.05180787879,-0.0744047619
387.402,0.81287,-0.06107,,,,,0.04926484848,-0.07734295846
387.902,0.7715,-0.0673,,,,,0.04675757576,-0.08523302938
388.402,0.72972,-0.06892,,,,,0.04422545455,-0.08728470111
388.902,0.68796,-0.0719,,,,,0.04169454545,-0.09105876393
389.402,0.64657,-0.07475,,,,,0.03918606061,-0.09466818642
389.902,0.60457,-0.07879,,,,,0.03664060606,-0.09978470111
390.402,0.56311,-0.08264,,,,,0.03412787879,-0.1046605876
390.902,0.52161,-0.08621,,,,,0.03161272727,-0.1091818642
391.402,0.47949,-0.08969,,,,,0.02906,-0.1135891591
391.902,0.43807,-0.09049,,,,,0.02654969697,-0.1146023303
392.402,0.39648,-0.09442,,,,,0.02402909091,-0.1195795339
392.902,0.35469,-0.09762,,,,,0.02149636364,-0.1236322188
393.402,0.31314,-0.09786,,,,,0.01897818182,-0.1239361702
393.902,0.27125,-0.10236,,,,,0.01643939394,-0.1296352584
394.402,0.22981,-0.10478,,,,,0.01392787879,-0.1327001013
394.902,0.18832,-0.10855,,,,,0.01141333333,-0.1374746707
395.402,0.1461,-0.10666,,,,,0.008854545455,-0.1350810537
395.902,0.10474,-0.11076,,,,,0.006347878788,-0.1402735562
396.402,0.06326,-0.1122,,,,,0.003833939394,-0.1420972644
396.902,0.02117,-0.11257,,,,,0.001283030303,-0.1425658561
397.16,-0.00007,-0.11045,,,,,-0.000004242424242,-0.1398809524