File: mechanical/tensile_failure/g60_conductive_3.csv
Time,Extension,Load,Length,Width,Thickness,CS Area,Strain,Stress
(s),(mm),(N),(mm),(mm),(mm),(mm^2),(mm/mm),(MPa)
0,0.35468,0.09041,16.5,3.24,0.45,1.458,0,0.06200960219
,0.53724,0.22331,,,,,0.01106424242,0.1531618656
,0.84005,0.25877,,,,,0.02941636364,0.1774828532
,1.14014,0.30776,,,,,0.04760363636,0.2110836763
,1.44026,0.35326,,,,,0.06579272727,0.2422908093
,1.74035,0.38221,,,,,0.08398,0.2621467764
,2.0403,0.44181,,,,,0.1021587879,0.3030246914
,2.34028,0.48632,,,,,0.1203393939,0.3335528121
,2.64027,0.50445,,,,,0.1385206061,0.3459876543
,2.94032,0.53595,,,,,0.1567054545,0.3675925926
,3.24025,0.5677,,,,,0.1748830303,0.3893689986
,3.54029,0.5828,,,,,0.1930672727,0.3997256516
,3.84028,0.6034,,,,,0.2112484848,0.4138545953
,4.14029,0.64627,,,,,0.2294309091,0.4432578875
,4.44028,0.64485,,,,,0.2476121212,0.4422839506
,4.74035,0.67175,,,,,0.2657981818,0.460733882
,5.04026,0.69864,,,,,0.2839745455,0.4791769547
,5.34031,0.74,,,,,0.3021593939,0.5075445816
,5.64028,0.74576,,,,,0.3203393939,0.5114951989
,5.9403,0.77365,,,,,0.3385224242,0.5306241427
,6.2403,0.77454,,,,,0.3567042424,0.5312345679
,6.54025,0.78329,,,,,0.3748830303,0.5372359396
,6.84028,0.80001,,,,,0.3930666667,0.5487037037
,7.14031,0.79844,,,,,0.411250303,0.5476268861
,7.44028,0.81783,,,,,0.429430303,0.5609259259
,7.74026,0.8359,,,,,0.4476109091,0.5733196159
,8.04031,0.84148,,,,,0.4657957576,0.5771467764
,8.34033,0.8624,,,,,0.4839787879,0.5914951989
,8.64024,0.8709,,,,,0.5021551515,0.5973251029
,8.94024,0.88584,,,,,0.5203369697,0.6075720165
,9.24034,0.89155,,,,,0.5385248485,0.6114883402
,9.54033,0.91228,,,,,0.5567060606,0.6257064472
,9.84029,0.91066,,,,,0.5748854545,0.6245953361
,10.14025,0.92745,,,,,0.5930648485,0.6361111111
,10.44025,0.941,,,,,0.6112466667,0.6454046639
,10.74031,0.95697,,,,,0.6294321212,0.6563580247
,11.04028,0.95864,,,,,0.6476121212,0.6575034294
,11.34031,0.96555,,,,,0.6657957576,0.6622427984
,11.64022,0.97123,,,,,0.6839721212,0.666138546
,11.94035,0.97542,,,,,0.7021618182,0.6690123457
,12.24028,0.98298,,,,,0.7203393939,0.6741975309
,12.54027,0.99613,,,,,0.7385206061,0.6832167353
,12.84034,1.01021,,,,,0.7567066667,0.6928737997
,13.14032,1.02543,,,,,0.7748872727,0.7033127572
,13.44022,1.02339,,,,,0.7930630303,0.7019135802
,13.74026,1.03456,,,,,0.8112472727,0.7095747599
,14.04026,1.02715,,,,,0.8294290909,0.7044924554
,14.34034,1.03524,,,,,0.8476157576,0.7100411523
,14.64034,1.05071,,,,,0.8657975758,0.7206515775
,14.94021,1.05828,,,,,0.8839715152,0.7258436214
,15.24026,1.0534,,,,,0.9021563636,0.7224965706
,15.54034,1.06779,,,,,0.9203430303,0.7323662551
,15.84028,1.05932,,,,,0.9385212121,0.7265569273
,16.14023,1.06846,,,,,0.9567,0.7328257888
,16.44027,1.1177,,,,,0.9748842424,0.7665980796
,16.7403,1.10647,,,,,0.9930678788,0.7588957476
,17.04029,1.114,,,,,1.011249091,0.7640603567
,17.34026,1.12546,,,,,1.029429091,0.771920439
,17.64031,1.13685,,,,,1.047613939,0.7797325103
,17.94035,1.16813,,,,,1.065798182,0.8011865569
,18.24031,1.18687,,,,,1.083977576,0.8140397805
,18.5402,1.16432,,,,,1.102152727,0.7985733882
,18.84027,1.18635,,,,,1.120338788,0.8136831276
,19.14034,1.1883,,,,,1.138524848,0.8150205761
,19.4403,1.1801,,,,,1.156704242,0.8093964335
,19.74026,1.21816,,,,,1.174883636,0.8355006859
,20.04026,1.23734,,,,,1.193065455,0.8486556927
,20.34028,1.2289,,,,,1.211248485,0.842866941
,20.6403,1.23269,,,,,1.229431515,0.8454663923
,20.94029,1.24003,,,,,1.247612727,0.8505006859
,21.24021,1.24144,,,,,1.265789697,0.8514677641
,21.54033,1.25912,,,,,1.283978788,0.8635939643
,21.84035,1.29062,,,,,1.302161818,0.8851989026
,22.14023,1.29605,,,,,1.320336364,0.8889231824
,22.4403,1.33159,,,,,1.338522424,0.9132990398
,22.74034,1.34255,,,,,1.356706667,0.9208161866
,23.04033,1.34864,,,,,1.374887879,0.9249931413
,23.34025,1.34608,,,,,1.393064848,0.9232373114
,23.64029,1.36407,,,,,1.411249091,0.9355761317
,23.94033,1.36076,,,,,1.429433333,0.9333058985
,24.2403,1.38549,,,,,1.447613333,0.9502674897
,24.54023,1.42556,,,,,1.465790909,0.9777503429
,24.84024,1.42414,,,,,1.483973333,0.976776406
,25.14033,1.44966,,,,,1.502160606,0.9942798354
,25.44034,1.46151,,,,,1.52034303,1.002407407
,25.74023,1.4488,,,,,1.538518182,0.9936899863
,26.04022,1.45848,,,,,1.556699394,1.000329218
,26.34032,1.46414,,,,,1.574887273,1.004211248
,26.64032,1.48532,,,,,1.593069091,1.018737997
,26.94027,1.51428,,,,,1.611247879,1.038600823
,27.2403,1.54342,,,,,1.629431515,1.058587106
,27.54032,1.54719,,,,,1.647614545,1.06117284
,27.84033,1.55873,,,,,1.66579697,1.069087791
,28.14027,1.56213,,,,,1.683975152,1.071419753
,28.44028,1.5603,,,,,1.702157576,1.070164609
,28.74026,1.57412,,,,,1.720338182,1.079643347
,29.04038,1.58577,,,,,1.738527273,1.087633745
,29.34023,1.61391,,,,,1.7567,1.106934156
,29.64023,1.65536,,,,,1.774881818,1.135363512
,29.94031,1.67773,,,,,1.793068485,1.150706447
,30.24032,1.68756,,,,,1.811250909,1.15744856
,30.54025,1.69954,,,,,1.829428485,1.165665295
,30.84025,1.69464,,,,,1.847610303,1.162304527
,31.14024,1.69545,,,,,1.865791515,1.162860082
,31.4403,1.71053,,,,,1.88397697,1.173203018
,31.74034,1.72552,,,,,1.902161212,1.183484225
,32.04026,1.74706,,,,,1.920338182,1.198257888
,32.34032,1.78225,,,,,1.938523636,1.22239369
,32.6403,1.79772,,,,,1.956704242,1.233004115
,32.94026,1.79862,,,,,1.974883636,1.233621399
,33.24028,1.8215,,,,,1.993066667,1.249314129
,33.54027,1.84623,,,,,2.011247879,1.26627572
,33.84033,1.83376,,,,,2.029433333,1.257722908
,34.14023,1.86258,,,,,2.047609091,1.277489712
,34.44024,1.87426,,,,,2.065791515,1.285500686
,34.7403,1.86542,,,,,2.08397697,1.279437586
,35.0403,1.88874,,,,,2.102158788,1.295432099
,35.34033,1.92616,,,,,2.120342424,1.321097394
,35.64025,1.93628,,,,,2.138519394,1.328038409
,35.94025,1.96799,,,,,2.156701212,1.34978738
,36.24029,1.98633,,,,,2.174885455,1.362366255
,36.54033,1.96025,,,,,2.193069697,1.344478738
,36.84034,1.97335,,,,,2.211252121,1.353463649
,37.14023,1.99016,,,,,2.229427273,1.364993141
,37.44031,2.00883,,,,,2.247613939,1.377798354
,37.74029,2.04661,,,,,2.265794545,1.403710562
,38.04028,2.06358,,,,,2.283975758,1.415349794
,38.34025,2.05801,,,,,2.302155758,1.411529492
,38.64037,2.07899,,,,,2.320344848,1.425919067
,38.94024,2.09837,,,,,2.338518788,1.439211248
,39.24026,2.09885,,,,,2.356701818,1.439540466
,39.54025,2.11705,,,,,2.37488303,1.45202332
,39.84029,2.13586,,,,,2.393067273,1.464924554
,40.14037,2.15964,,,,,2.411253939,1.481234568
,40.44026,2.18529,,,,,2.429429091,1.49882716
,40.74025,2.20664,,,,,2.447610303,1.513470508
,41.04027,2.22764,,,,,2.465793333,1.5278738
,41.34032,2.22791,,,,,2.483978182,1.528058985
,41.6403,2.23449,,,,,2.502158788,1.532572016
,41.94027,2.24199,,,,,2.520338788,1.537716049
,42.24029,2.24257,,,,,2.538521818,1.538113855
,42.54026,2.26761,,,,,2.556701818,1.555288066
,42.84026,2.29008,,,,,2.574883636,1.570699588
,43.14028,2.32598,,,,,2.593066667,1.595322359
,43.4403,2.3377,,,,,2.611249697,1.603360768
,43.74025,2.34572,,,,,2.629428485,1.608861454
,44.04029,2.37281,,,,,2.647612727,1.627441701
,44.34021,2.3879,,,,,2.665789697,1.637791495
,44.64028,2.40395,,,,,2.683975758,1.648799726
,44.94035,2.41543,,,,,2.702161818,1.656673525
,45.24032,2.42216,,,,,2.720341818,1.661289438
,45.54024,2.43263,,,,,2.738518788,1.668470508
,45.84022,2.44281,,,,,2.756699394,1.675452675
,46.14033,2.47976,,,,,2.774887879,1.70079561
,46.44033,2.49676,,,,,2.793069697,1.712455418
,46.74029,2.51944,,,,,2.811249091,1.728010974
,47.04028,2.52939,,,,,2.829430303,1.734835391
,47.34026,2.5506,,,,,2.847610909,1.749382716
,47.64032,2.54997,,,,,2.865796364,1.748950617
,47.94025,2.55024,,,,,2.883973939,1.749135802
,48.24029,2.56926,,,,,2.902158182,1.76218107
,48.5403,2.60849,,,,,2.920340606,1.789087791
,48.84029,2.64356,,,,,2.938521818,1.813141289
,49.14024,2.67179,,,,,2.956700606,1.832503429
,49.44029,2.67793,,,,,2.974885455,1.836714678
,49.74033,2.69067,,,,,2.993069697,1.845452675
,50.04033,2.68392,,,,,3.011251515,1.840823045
,50.34028,2.69526,,,,,3.029430303,1.848600823
,50.64021,2.71646,,,,,3.047607879,1.863141289
,50.94032,2.7323,,,,,3.065796364,1.874005487
,51.24035,2.76613,,,,,3.08398,1.897208505
,51.54029,2.7821,,,,,3.102158182,1.908161866
,51.84025,2.79951,,,,,3.120337576,1.920102881
,52.14031,2.81882,,,,,3.13852303,1.933347051
,52.4403,2.83684,,,,,3.156704242,1.945706447
,52.74025,2.84578,,,,,3.17488303,1.951838134
,53.04029,2.86647,,,,,3.193067273,1.966028807
,53.34027,2.87325,,,,,3.211247879,1.970679012
,53.64035,2.89821,,,,,3.229434545,1.987798354
,53.9403,2.93186,,,,,3.247613333,2.010877915
,54.24017,2.94409,,,,,3.265787273,2.019266118
,54.54035,2.9583,,,,,3.28398,2.029012346
,54.84038,2.96742,,,,,3.302163636,2.03526749
,55.14026,2.96451,,,,,3.320338182,2.033271605
,55.44022,2.9799,,,,,3.338517576,2.04382716
,55.74033,3.01579,,,,,3.356706061,2.068443073
,56.04025,3.04568,,,,,3.37488303,2.088943759
,56.34029,3.06233,,,,,3.393067273,2.100363512
,56.64022,3.09056,,,,,3.411244848,2.119725652
,56.94028,3.07494,,,,,3.429430303,2.109012346
,57.24032,3.09476,,,,,3.447614545,2.12260631
,57.5403,3.1304,,,,,3.465795152,2.147050754
,57.84025,3.12215,,,,,3.483973939,2.141392318
,58.14028,3.15193,,,,,3.502157576,2.161817558
,58.44033,3.17467,,,,,3.520342424,2.177414266
,58.74028,3.17669,,,,,3.538521212,2.178799726
,59.04025,3.20996,,,,,3.556701212,2.201618656
,59.34033,3.22032,,,,,3.574887879,2.20872428
,59.64032,3.24294,,,,,3.593069091,2.224238683
,59.94029,3.26179,,,,,3.611249091,2.237167353
,60.24025,3.27625,,,,,3.629428485,2.247085048
,60.54028,3.28302,,,,,3.647612121,2.251728395
,60.84029,3.30664,,,,,3.665794545,2.267928669
,61.14032,3.32209,,,,,3.683978182,2.278525377
,61.44021,3.33759,,,,,3.702153333,2.289156379
,61.74026,3.34368,,,,,3.720338182,2.293333333
,62.04036,3.37036,,,,,3.738526061,2.311632373
,62.34034,3.39326,,,,,3.756706667,2.32733882
,62.64022,3.42176,,,,,3.774881212,2.346886145
,62.94034,3.44538,,,,,3.793070303,2.36308642
,63.24031,3.44953,,,,,3.811250303,2.365932785
,63.54029,3.4423,,,,,3.829430909,2.360973937
,63.8403,3.47626,,,,,3.847613333,2.384266118
,64.1403,3.49605,,,,,3.865795152,2.397839506
,64.44027,3.51698,,,,,3.883975152,2.412194787
,64.74033,3.55065,,,,,3.902160606,2.435288066
,65.0402,3.56155,,,,,3.920334545,2.44276406
,65.34025,3.57249,,,,,3.938519394,2.45026749
,65.64033,3.57638,,,,,3.956706061,2.452935528
,65.94027,3.58158,,,,,3.974884242,2.456502058
,66.24021,3.61259,,,,,3.993062424,2.477770919
,66.54026,3.61257,,,,,4.011247273,2.477757202
,66.84031,3.6519,,,,,4.029432121,2.50473251
,67.14034,3.67753,,,,,4.047615758,2.522311385
,67.4403,3.69693,,,,,4.065795152,2.535617284
,67.74027,3.69731,,,,,4.083975152,2.535877915
,68.04028,3.72281,,,,,4.102157576,2.553367627
,68.3403,3.74697,,,,,4.120340606,2.569938272
,68.6403,3.74209,,,,,4.138522424,2.566591221
,68.94028,3.76705,,,,,4.15670303,2.583710562
,69.2403,3.78278,,,,,4.174886061,2.594499314
,69.54028,3.79853,,,,,4.193066667,2.605301783
,69.84026,3.84164,,,,,4.211247273,2.634869684
,70.14025,3.84704,,,,,4.229428485,2.638573388
,70.44029,3.84533,,,,,4.247612727,2.637400549
,70.74038,3.86922,,,,,4.2658,2.653786008
,71.04018,3.88595,,,,,4.283969697,2.665260631
,71.27727,2.66271,,,,,4.298338788,1.82627572
,71.28027,0.64589,,,,,4.298520606,0.4429972565
,71.28326,-0.77559,,,,,4.298701818,-0.5319547325
,71.28927,0.12202,,,,,4.299066061,0.08368998628
,71.29526,-0.18659,,,,,4.299429091,-0.1279766804
,71.30125,0.10868,,,,,4.299792121,0.07454046639
,71.30726,-0.07359,,,,,4.300156364,-0.05047325103
,71.31325,0.12247,,,,,4.300519394,0.08399862826
,71.31625,-0.01699,,,,,4.300701212,-0.01165294925
,71.31925,-0.19002,,,,,4.30088303,-0.1303292181
,71.32224,0.03002,,,,,4.301064242,0.02058984911
,71.32524,0.22294,,,,,4.301246061,0.1529080933
,71.32825,-0.03858,,,,,4.301428485,-0.02646090535
,71.33125,-0.20239,,,,,4.301610303,-0.1388134431
,71.33424,0.05013,,,,,4.301791515,0.03438271605
,71.33723,0.19669,,,,,4.301972727,0.1349039781
,71.34024,-0.0166,,,,,4.302155152,-0.01138545953
,71.34325,-0.15644,,,,,4.302337576,-0.107297668
,71.34624,0.00515,,,,,4.302518788,0.00353223594
,71.34924,0.13351,,,,,4.302700606,0.09157064472
,71.35524,-0.10824,,,,,4.303064242,-0.07423868313
,71.36124,0.09445,,,,,4.303427879,0.06478052126
,71.36726,-0.08963,,,,,4.303792727,-0.06147462277
,71.37326,0.08587,,,,,4.304156364,0.0588957476
,71.37927,-0.08497,,,,,4.304520606,-0.05827846365
,71.38527,0.06472,,,,,4.304884242,0.04438957476
,71.39127,-0.07351,,,,,4.305247879,-0.05041838134
,71.39729,0.07321,,,,,4.305612727,0.05021262003
,71.40329,-0.06398,,,,,4.305976364,-0.04388203018
,71.41229,0.06517,,,,,4.306521818,0.04469821674
,71.71234,0.00007,,,,,4.324706667,0.00004801097394
,72.01228,0.00108,,,,,4.342884848,0.0007407407407
,72.31227,0.01079,,,,,4.361066061,0.007400548697
,72.6123,-0.00155,,,,,4.379249697,-0.001063100137
,72.91225,-0.00232,,,,,4.397428485,-0.00159122085
,72.93624,-0.00427,,,,,4.398882424,-0.00292866941