File: mechanical/hysteresis/data/g60_conductive_3.csv
Time,Extension,Load,Length,Width,Thickness,CS Area,Strain,Stress
(s),(mm),(N),(mm),(mm),(mm),(mm^2),(mm/mm),(MPa)
0,0,-0.00344,16.5,2.82,0.54,1.5228,0,-0.002258996585
0.5,0.03872,0.00745,,,,,0.002346666667,0.004892303651
1,0.08035,0.00984,,,,,0.00486969697,0.00646178093
1.5,0.12235,0.01245,,,,,0.007415151515,0.00817572892
2,0.16352,0.01567,,,,,0.00991030303,0.01029025479
2.5,0.2056,0.01779,,,,,0.01246060606,0.01168242711
3,0.24723,0.02142,,,,,0.01498363636,0.01406619385
3.5,0.28857,0.02429,,,,,0.01748909091,0.01595087996
4,0.33056,0.02522,,,,,0.02003393939,0.01656159706
4.5,0.37206,0.02542,,,,,0.02254909091,0.01669293407
5,0.41369,0.0287,,,,,0.02507212121,0.01884686105
5.5,0.45555,0.03037,,,,,0.02760909091,0.01994352509
6,0.49692,0.03223,,,,,0.03011636364,0.02116495929
6.5,0.53893,0.03351,,,,,0.03266242424,0.02200551615
7,0.58061,0.03567,,,,,0.03518848485,0.02342395587
7.5,0.62179,0.03836,,,,,0.03768424242,0.02519043867
8,0.66398,0.04127,,,,,0.04024121212,0.02710139217
8.5,0.70554,0.03916,,,,,0.04276,0.02571578671
9,0.74698,0.04392,,,,,0.04527151515,0.02884160757
9.5,0.78899,0.04609,,,,,0.04781757576,0.03026661413
10,0.8304,0.04833,,,,,0.05032727273,0.03173758865
10.5,0.87221,0.05041,,,,,0.05286121212,0.03310349356
11,0.9138,0.0515,,,,,0.05538181818,0.03381928027
11.5,0.95516,0.05279,,,,,0.05788848485,0.03466640399
12,0.99729,0.05574,,,,,0.06044181818,0.0366036249
12.5,1.03887,0.05774,,,,,0.06296181818,0.03791699501
13,1.08026,0.0583,,,,,0.06547030303,0.03828473864
13.5,1.12228,0.05973,,,,,0.0680169697,0.03922379827
14,1.16374,0.06295,,,,,0.07052969697,0.04133832414
14.5,1.20547,0.06347,,,,,0.07305878788,0.04167980037
15,1.24735,0.06619,,,,,0.0755969697,0.04346598371
15.5,1.2885,0.06575,,,,,0.07809090909,0.04317704229
16,1.33066,0.06696,,,,,0.08064606061,0.04397163121
16.5,1.37231,0.06965,,,,,0.08317030303,0.045738114
17,1.41347,0.0726,,,,,0.08566484848,0.04767533491
17.5,1.45564,0.07329,,,,,0.08822060606,0.0481284476
18,1.49716,0.07506,,,,,0.0907369697,0.04929078014
18.5,1.53867,0.07679,,,,,0.09325272727,0.05042684529
19,1.58058,0.07898,,,,,0.09579272727,0.05186498555
19.5,1.62195,0.08114,,,,,0.0983,0.05328342527
19.834,1.65011,0.08245,,,,,0.1000066667,0.05414368269
20.235,1.62143,0.06855,,,,,0.09826848485,0.04501576044
20.735,1.57988,0.05798,,,,,0.09575030303,0.03807459942
21.235,1.53782,0.05169,,,,,0.09320121212,0.03394405043
21.735,1.49649,0.04559,,,,,0.09069636364,0.0299382716
22.235,1.45458,0.04084,,,,,0.08815636364,0.0268190176
22.735,1.41313,0.03552,,,,,0.08564424242,0.02332545311
23.235,1.3715,0.03007,,,,,0.08312121212,0.01974651957
23.735,1.32944,0.02483,,,,,0.08057212121,0.01630548989
24.235,1.28811,0.02011,,,,,0.07806727273,0.01320593643
24.735,1.24648,0.01672,,,,,0.07554424242,0.0109797741
25.235,1.20448,0.01283,,,,,0.07299878788,0.008425269241
25.735,1.16318,0.0113,,,,,0.07049575758,0.007420541108
26.235,1.12131,0.00685,,,,,0.06795818182,0.004498292619
26.735,1.07965,0.00188,,,,,0.06543333333,0.001234567901
27.235,1.03828,0.00009,,,,,0.06292606061,0.00005910165485
27.735,0.99611,-0.00398,,,,,0.06037030303,-0.002613606514
28.235,0.9547,-0.0076,,,,,0.05786060606,-0.004990806409
28.735,0.91323,-0.01012,,,,,0.05534727273,-0.006645652745
29.235,0.87112,-0.01355,,,,,0.05279515152,-0.00889808248
29.735,0.82965,-0.01509,,,,,0.05028181818,-0.009909377463
30.235,0.78809,-0.01664,,,,,0.0477630303,-0.0109272393
30.735,0.7463,-0.02153,,,,,0.04523030303,-0.01413842921
31.235,0.70481,-0.02157,,,,,0.04271575758,-0.01416469661
31.735,0.66291,-0.02454,,,,,0.04017636364,-0.01611505122
32.235,0.62143,-0.02772,,,,,0.03766242424,-0.01820330969
32.735,0.57989,-0.02955,,,,,0.03514484848,-0.01940504334
33.235,0.53779,-0.03203,,,,,0.03259333333,-0.02103362227
33.735,0.49647,-0.03371,,,,,0.03008909091,-0.02213685317
34.235,0.45473,-0.03615,,,,,0.02755939394,-0.0237391647
34.735,0.41294,-0.03794,,,,,0.02502666667,-0.02491463094
35.235,0.37151,-0.0383,,,,,0.02251575758,-0.02515103756
35.735,0.32955,-0.04047,,,,,0.01997272727,-0.02657604413
36.235,0.28802,-0.04427,,,,,0.01745575758,-0.02907144733
36.735,0.24658,-0.04569,,,,,0.01494424242,-0.03000394011
37.235,0.2045,-0.04688,,,,,0.01239393939,-0.03078539532
37.735,0.16309,-0.05077,,,,,0.009884242424,-0.03333990018
38.235,0.12155,-0.05144,,,,,0.007366666667,-0.03377987917
38.735,0.07951,-0.05294,,,,,0.004818787879,-0.03476490675
39.235,0.03808,-0.05584,,,,,0.002307878788,-0.03666929341
39.691,-0.00007,-0.05906,,,,,-0.000004242424242,-0.03878381928
39.993,0.02017,-0.04911,,,,,0.001222424242,-0.03224980299
40.493,0.06181,-0.04295,,,,,0.003746060606,-0.02820462306
40.993,0.10343,-0.03911,,,,,0.006268484848,-0.02568295246
41.493,0.14521,-0.03365,,,,,0.008800606061,-0.02209745206
41.993,0.18658,-0.03029,,,,,0.01130787879,-0.01989099028
42.493,0.22863,-0.02703,,,,,0.01385636364,-0.01775019701
42.993,0.27016,-0.02239,,,,,0.01637333333,-0.01470317836
43.493,0.3115,-0.01931,,,,,0.01887878788,-0.01268058839
43.993,0.35371,-0.01665,,,,,0.0214369697,-0.01093380615
44.493,0.3951,-0.01479,,,,,0.02394545455,-0.009712371946
44.993,0.43673,-0.01144,,,,,0.02646848485,-0.007512477016
45.493,0.47865,-0.00858,,,,,0.02900909091,-0.005634357762
45.993,0.51993,-0.0078,,,,,0.03151090909,-0.00512214342
46.493,0.56188,-0.00307,,,,,0.03405333333,-0.002016023115
46.993,0.60367,-0.00043,,,,,0.03658606061,-0.0002823745732
47.493,0.64483,0.00336,,,,,0.03908060606,0.002206461781
47.993,0.68691,0.00449,,,,,0.04163090909,0.002948515892
48.493,0.7285,0.0074,,,,,0.04415151515,0.004859469398
48.993,0.76998,0.01038,,,,,0.04666545455,0.006816390859
49.493,0.81197,0.01365,,,,,0.04921030303,0.008963750985
49.993,0.85336,0.0181,,,,,0.05171878788,0.01188599947
50.493,0.89522,0.01868,,,,,0.05425575758,0.01226687681
50.993,0.93691,0.02169,,,,,0.05678242424,0.01424349882
51.493,0.97817,0.02489,,,,,0.0592830303,0.01634489099
51.993,1.02033,0.02844,,,,,0.06183818182,0.01867612293
52.493,1.06192,0.03148,,,,,0.06435878788,0.0206724455
52.993,1.10327,0.03264,,,,,0.06686484848,0.02143420016
53.493,1.14529,0.03603,,,,,0.06941151515,0.02366036249
53.993,1.18682,0.03841,,,,,0.07192848485,0.02522327292
54.493,1.22846,0.04131,,,,,0.07445212121,0.02712765957
54.993,1.27027,0.04445,,,,,0.07698606061,0.02918965064
55.493,1.31158,0.04775,,,,,0.07948969697,0.03135671132
55.993,1.35361,0.04996,,,,,0.0820369697,0.03280798529
56.493,1.39525,0.05282,,,,,0.08456060606,0.03468610454
56.993,1.43654,0.05586,,,,,0.0870630303,0.03668242711
57.493,1.47867,0.0586,,,,,0.08961636364,0.03848174416
57.993,1.52013,0.05983,,,,,0.09212909091,0.03928946677
58.493,1.56175,0.06234,,,,,0.09465151515,0.04093774626
58.993,1.60361,0.06646,,,,,0.09718848485,0.04364328868
59.493,1.64503,0.06815,,,,,0.09969878788,0.04475308642
59.752,1.6382,0.06367,,,,,0.09928484848,0.04181113738
60.252,1.59629,0.05046,,,,,0.09674484848,0.03313632782
60.752,1.55483,0.04299,,,,,0.09423212121,0.02823089046
61.252,1.51277,0.0392,,,,,0.0916830303,0.02574205411
61.752,1.47144,0.03142,,,,,0.08917818182,0.02063304439
62.252,1.42986,0.02542,,,,,0.08665818182,0.01669293407
62.752,1.38786,0.01939,,,,,0.08411272727,0.01273312319
63.252,1.34646,0.01742,,,,,0.08160363636,0.01143945364
63.752,1.30466,0.01207,,,,,0.07907030303,0.0079261886
64.252,1.26298,0.0087,,,,,0.07654424242,0.005713159968
64.752,1.2215,0.00465,,,,,0.07403030303,0.0030535855
65.252,1.17948,0.00043,,,,,0.07148363636,0.0002823745732
65.752,1.13802,-0.00309,,,,,0.06897090909,-0.002029156816
66.252,1.09664,-0.00466,,,,,0.0664630303,-0.003060152351
66.752,1.05435,-0.00917,,,,,0.0639,-0.006021801944
67.252,1.01312,-0.01212,,,,,0.06140121212,-0.007959022853
67.752,0.97141,-0.01514,,,,,0.05887333333,-0.009942211715
68.252,0.92967,-0.01815,,,,,0.05634363636,-0.01191883373
68.752,0.8881,-0.01924,,,,,0.05382424242,-0.01263462044
69.252,0.84626,-0.02189,,,,,0.05128848485,-0.01437483583
69.752,0.80472,-0.02598,,,,,0.04877090909,-0.0170606777
70.252,0.76321,-0.02753,,,,,0.04625515152,-0.01807853953
70.752,0.7211,-0.02833,,,,,0.0437030303,-0.01860388758
71.252,0.6798,-0.03238,,,,,0.0412,-0.02126346204
71.752,0.63815,-0.03702,,,,,0.03867575758,-0.02431048069
72.252,0.59609,-0.03761,,,,,0.03612666667,-0.02469792488
72.752,0.55486,-0.03842,,,,,0.03362787879,-0.02522983977
73.252,0.51293,-0.04117,,,,,0.03108666667,-0.02703572367
73.752,0.47129,-0.04366,,,,,0.0285630303,-0.02867086945
74.252,0.42982,-0.04633,,,,,0.02604969697,-0.03042421854
74.752,0.38785,-0.04648,,,,,0.02350606061,-0.0305227213
75.252,0.3463,-0.04876,,,,,0.02098787879,-0.03201996323
75.752,0.30488,-0.05175,,,,,0.01847757576,-0.03398345154
76.252,0.2628,-0.05327,,,,,0.01592727273,-0.03498161282
76.752,0.22139,-0.0538,,,,,0.01341757576,-0.0353296559
77.252,0.17971,-0.05728,,,,,0.01089151515,-0.03761491988
77.752,0.13796,-0.05865,,,,,0.008361212121,-0.03851457841
78.252,0.09649,-0.06007,,,,,0.005847878788,-0.03944707118
78.752,0.05452,-0.06328,,,,,0.003304242424,-0.04155503021
79.252,0.01313,-0.06606,,,,,0.0007957575758,-0.04338061466
79.51,0.00223,-0.06349,,,,,0.0001351515152,-0.04169293407
80.01,0.0453,-0.05243,,,,,0.002745454545,-0.03442999737
80.51,0.08693,-0.0485,,,,,0.005268484848,-0.03184922511
81.01,0.12818,-0.04339,,,,,0.007768484848,-0.02849356449
81.51,0.17034,-0.04128,,,,,0.01032363636,-0.02710795902
82.01,0.21188,-0.03728,,,,,0.01284121212,-0.02448121881
82.51,0.25323,-0.03352,,,,,0.01534727273,-0.022012083
83.01,0.29533,-0.03061,,,,,0.01789878788,-0.0201011295
83.51,0.33664,-0.02772,,,,,0.02040242424,-0.01820330969
84.01,0.37856,-0.0262,,,,,0.0229430303,-0.01720514841
84.51,0.42025,-0.02157,,,,,0.02546969697,-0.01416469661
85.01,0.46154,-0.01867,,,,,0.02797212121,-0.01226030996
85.51,0.50364,-0.01596,,,,,0.03052363636,-0.01048069346
86.01,0.54528,-0.01525,,,,,0.03304727273,-0.01001444707
86.51,0.58661,-0.01038,,,,,0.03555212121,-0.006816390859
87.01,0.62865,-0.00799,,,,,0.0381,-0.00524691358
87.51,0.67007,-0.00468,,,,,0.04061030303,-0.003073286052
88.01,0.71184,-0.00033,,,,,0.04314181818,-0.0002167060678
88.51,0.75355,0.00204,,,,,0.04566969697,0.00133963751
89.01,0.79479,0.00501,,,,,0.04816909091,0.00328999212
89.51,0.83704,0.00729,,,,,0.05072969697,0.004787234043
90.01,0.87859,0.01125,,,,,0.05324787879,0.007387706856
90.51,0.91992,0.01347,,,,,0.05575272727,0.008845547675
91.01,0.96206,0.01616,,,,,0.05830666667,0.01061203047
91.51,1.0035,0.01764,,,,,0.06081818182,0.01158392435
92.01,1.04495,0.02129,,,,,0.06333030303,0.0139808248
92.51,1.08705,0.02633,,,,,0.06588181818,0.01729051747
93.01,1.12827,0.02729,,,,,0.06838,0.01792093512
93.51,1.1702,0.03101,,,,,0.07092121212,0.02036380352
94.01,1.21198,0.03194,,,,,0.07345333333,0.02097452062
94.51,1.25321,0.03635,,,,,0.07595212121,0.02387050171
95.01,1.29526,0.04017,,,,,0.07850060606,0.02637903861
95.51,1.33684,0.04139,,,,,0.08102060606,0.02718019438
96.01,1.37836,0.04363,,,,,0.0835369697,0.0286511689
96.51,1.4202,0.04676,,,,,0.08607272727,0.03070659312
97.01,1.46169,0.04923,,,,,0.08858727273,0.0323286052
97.51,1.50355,0.05355,,,,,0.09112424242,0.03516548463
98.01,1.54532,0.05423,,,,,0.09365575758,0.03561203047
98.51,1.58651,0.05892,,,,,0.09615212121,0.03869188337
99.01,1.62869,0.06204,,,,,0.09870848485,0.04074074074
99.269,1.65021,0.06294,,,,,0.1000127273,0.04133175729
99.769,1.61318,0.05039,,,,,0.09776848485,0.03309035986
100.269,1.57111,0.04031,,,,,0.09521878788,0.02647097452
100.769,1.5298,0.03268,,,,,0.09271515152,0.02146046756
101.269,1.48805,0.02665,,,,,0.09018484848,0.01750065669
101.769,1.4462,0.02093,,,,,0.08764848485,0.01374441818
102.269,1.40484,0.01557,,,,,0.08514181818,0.01022458629
102.769,1.36285,0.01155,,,,,0.0825969697,0.007584712372
103.269,1.32133,0.00839,,,,,0.08008060606,0.005509587602
103.769,1.27993,0.00266,,,,,0.07757151515,0.001746782243
104.269,1.23771,0.00063,,,,,0.07501272727,0.0004137115839
104.769,1.19635,-0.0047,,,,,0.07250606061,-0.003086419753
105.269,1.15486,-0.00744,,,,,0.06999151515,-0.004885736801
105.769,1.11284,-0.01124,,,,,0.06744484848,-0.007381140005
106.269,1.07135,-0.01235,,,,,0.06493030303,-0.008110060415
106.769,1.02966,-0.01504,,,,,0.06240363636,-0.00987654321
107.269,0.988,-0.01813,,,,,0.05987878788,-0.01190570003
107.769,0.94658,-0.02181,,,,,0.05736848485,-0.01432230102
108.269,0.90449,-0.02257,,,,,0.05481757576,-0.01482138167
108.769,0.86307,-0.02456,,,,,0.05230727273,-0.01612818492
109.269,0.82147,-0.02842,,,,,0.04978606061,-0.01866298923
109.769,0.77948,-0.03174,,,,,0.04724121212,-0.02084318361
110.269,0.73811,-0.03325,,,,,0.04473393939,-0.02183477804
110.769,0.69632,-0.03545,,,,,0.04220121212,-0.02327948516
111.269,0.65465,-0.03617,,,,,0.03967575758,-0.0237522984
111.769,0.61325,-0.03877,,,,,0.03716666667,-0.02545967954
112.269,0.57111,-0.04041,,,,,0.03461272727,-0.02653664303
112.769,0.52973,-0.04343,,,,,0.03210484848,-0.02851983189
113.269,0.48822,-0.04526,,,,,0.02958909091,-0.02972156554
113.769,0.44619,-0.0477,,,,,0.02704181818,-0.03132387707
114.269,0.40475,-0.0508,,,,,0.02453030303,-0.03335960074
114.769,0.36313,-0.05248,,,,,0.02200787879,-0.03446283163
115.269,0.32128,-0.05489,,,,,0.01947151515,-0.03604544261
115.769,0.27977,-0.05742,,,,,0.01695575758,-0.03770685579
116.269,0.23787,-0.05966,,,,,0.01441636364,-0.03917783031
116.769,0.19642,-0.05994,,,,,0.01190424242,-0.03936170213
117.269,0.15485,-0.06159,,,,,0.009384848485,-0.04044523247
117.769,0.11268,-0.06473,,,,,0.006829090909,-0.04250722354
118.269,0.07146,-0.06604,,,,,0.004330909091,-0.04336748096
118.769,0.02978,-0.06802,,,,,0.001804848485,-0.04466771736
119.126,-0.00018,-0.06865,,,,,-0.00001090909091,-0.04508142895
119.527,0.02846,-0.0588,,,,,0.001724848485,-0.03861308117
120.027,0.06988,-0.05576,,,,,0.004235151515,-0.0366167586
120.527,0.11202,-0.0505,,,,,0.006789090909,-0.03316259522
121.027,0.15335,-0.04396,,,,,0.009293939394,-0.02886787497
121.527,0.1951,-0.04395,,,,,0.01182424242,-0.02886130812
122.027,0.23701,-0.04028,,,,,0.01436424242,-0.02645127397
122.527,0.2782,-0.03406,,,,,0.01686060606,-0.02236669293
123.027,0.32027,-0.03305,,,,,0.01941030303,-0.02170344103
123.527,0.36192,-0.02815,,,,,0.02193454545,-0.01848568427
124.027,0.40324,-0.02778,,,,,0.02443878788,-0.0182427108
124.527,0.44527,-0.02301,,,,,0.02698606061,-0.01511032309
125.027,0.48679,-0.02108,,,,,0.02950242424,-0.01384292094
125.527,0.52843,-0.01784,,,,,0.03202606061,-0.01171526136
126.027,0.57027,-0.01726,,,,,0.03456181818,-0.01133438403
126.527,0.61155,-0.01224,,,,,0.03706363636,-0.008037825059
127.027,0.65364,-0.00844,,,,,0.03961454545,-0.005542421854
127.527,0.69527,-0.00771,,,,,0.04213757576,-0.005063041765
128.027,0.73645,-0.00421,,,,,0.04463333333,-0.002764644077
128.527,0.77871,0.00086,,,,,0.04719454545,0.0005647491463
129.027,0.82017,0.00344,,,,,0.04970727273,0.002258996585
129.527,0.86164,0.00422,,,,,0.05222060606,0.002771210927
130.027,0.90358,0.00728,,,,,0.05476242424,0.004780667192
130.527,0.94507,0.01077,,,,,0.0572769697,0.00707249803
131.027,0.98687,0.01279,,,,,0.05981030303,0.008399001839
131.527,1.02865,0.01626,,,,,0.06234242424,0.01067769898
132.027,1.06989,0.01876,,,,,0.06484181818,0.01231941161
132.527,1.11199,0.02125,,,,,0.06739333333,0.01395455739
133.027,1.15356,0.02356,,,,,0.06991272727,0.01547149987
133.527,1.19494,0.02655,,,,,0.07242060606,0.01743498818
134.027,1.237,0.02989,,,,,0.07496969697,0.01962831626
134.527,1.27834,0.03239,,,,,0.07747515152,0.02127002889
135.027,1.32019,0.03414,,,,,0.08001151515,0.02241922774
135.527,1.36191,0.03574,,,,,0.08254,0.02346992382
136.027,1.40322,0.04078,,,,,0.08504363636,0.0267796165
136.527,1.44525,0.04289,,,,,0.08759090909,0.02816522196
137.027,1.48693,0.04594,,,,,0.0901169697,0.03016811137
137.527,1.52811,0.05028,,,,,0.09261272727,0.03301812451
138.027,1.57039,0.05066,,,,,0.09517515152,0.03326766483
138.527,1.61183,0.05432,,,,,0.09768666667,0.03567113213
138.984,1.65004,0.05918,,,,,0.1000024242,0.03886262149
139.286,1.6298,0.048,,,,,0.09877575758,0.03152088258
139.786,1.58821,0.03946,,,,,0.09625515152,0.02591279222
140.286,1.54626,0.03214,,,,,0.09371272727,0.02110585763
140.786,1.50474,0.02549,,,,,0.09119636364,0.01673890202
141.286,1.46324,0.02017,,,,,0.08868121212,0.01324533754
141.786,1.42112,0.01475,,,,,0.08612848485,0.009686104544
142.286,1.37975,0.01184,,,,,0.08362121212,0.007775151038
142.786,1.33834,0.0063,,,,,0.08111151515,0.004137115839
143.286,1.29615,0.00346,,,,,0.07855454545,0.002272130286
143.786,1.25484,-0.00141,,,,,0.07605090909,-0.0009259259259
144.286,1.21306,-0.00572,,,,,0.07351878788,-0.003756238508
144.786,1.17152,-0.00872,,,,,0.07100121212,-0.00572629367
145.286,1.12985,-0.01213,,,,,0.06847575758,-0.007965589703
145.786,1.08787,-0.01406,,,,,0.06593151515,-0.009232991857
146.286,1.04646,-0.01725,,,,,0.06342181818,-0.01132781718
146.786,1.00488,-0.02029,,,,,0.06090181818,-0.01332413974
147.286,0.96278,-0.02147,,,,,0.05835030303,-0.01409902811
147.786,0.92149,-0.02504,,,,,0.05584787879,-0.01644339375
148.286,0.87976,-0.02712,,,,,0.05331878788,-0.01780929866
148.786,0.83789,-0.03133,,,,,0.05078121212,-0.02057394274
149.286,0.79661,-0.03267,,,,,0.04827939394,-0.02145390071
149.786,0.75454,-0.03287,,,,,0.04572969697,-0.02158523772
150.286,0.71305,-0.03625,,,,,0.04321515152,-0.0238048332
150.786,0.6716,-0.03903,,,,,0.0407030303,-0.02563041765
151.286,0.62952,-0.04134,,,,,0.03815272727,-0.02714736013
151.786,0.58804,-0.04319,,,,,0.03563878788,-0.02836222748
152.286,0.54657,-0.04612,,,,,0.03312545455,-0.03028631468
152.786,0.50461,-0.04868,,,,,0.03058242424,-0.03196742842
153.286,0.46313,-0.05005,,,,,0.02806848485,-0.03286708695
153.786,0.42132,-0.05246,,,,,0.02553454545,-0.03444969792
154.286,0.37974,-0.05437,,,,,0.02301454545,-0.03570396638
154.786,0.33821,-0.05613,,,,,0.02049757576,-0.03685973207
155.286,0.29615,-0.05742,,,,,0.01794848485,-0.03770685579
155.786,0.25482,-0.0605,,,,,0.01544363636,-0.03972944576
156.286,0.21314,-0.0624,,,,,0.01291757576,-0.04097714736
156.786,0.17121,-0.06404,,,,,0.01037636364,-0.04205411085
157.286,0.12989,-0.06575,,,,,0.007872121212,-0.04317704229
157.786,0.08803,-0.06649,,,,,0.005335151515,-0.04366298923
158.286,0.04632,-0.07058,,,,,0.002807272727,-0.0463488311
158.786,0.00497,-0.0732,,,,,0.0003012121212,-0.04806934594
159.044,0.01143,-0.06721,,,,,0.0006927272727,-0.04413580247
159.544,0.05373,-0.05843,,,,,0.003256363636,-0.0383701077
160.044,0.09493,-0.05266,,,,,0.005753333333,-0.03458103494
160.544,0.13697,-0.04959,,,,,0.008301212121,-0.03256501182
161.044,0.17863,-0.04748,,,,,0.01082606061,-0.03117940636
161.544,0.21992,-0.04138,,,,,0.01332848485,-0.02717362753
162.044,0.26201,-0.03846,,,,,0.01587939394,-0.02525610717
162.544,0.30365,-0.03719,,,,,0.0184030303,-0.02442211715
163.044,0.34506,-0.03321,,,,,0.02091272727,-0.02180851064
163.544,0.38697,-0.02994,,,,,0.02345272727,-0.01966115051
164.044,0.42832,-0.02662,,,,,0.02595878788,-0.01748095613
164.544,0.47032,-0.0246,,,,,0.02850424242,-0.01615445232
165.044,0.51189,-0.02311,,,,,0.03102363636,-0.01517599159
165.544,0.55312,-0.01801,,,,,0.03352242424,-0.01182689782
166.044,0.59542,-0.01764,,,,,0.03608606061,-0.01158392435
166.544,0.63685,-0.01514,,,,,0.0385969697,-0.009942211715
167.044,0.67832,-0.01237,,,,,0.04111030303,-0.008123194116
167.544,0.7204,-0.00756,,,,,0.04366060606,-0.004964539007
168.044,0.76177,-0.00745,,,,,0.04616787879,-0.004892303651
168.544,0.80345,-0.00379,,,,,0.04869393939,-0.002488836354
169.044,0.84542,0.00027,,,,,0.05123757576,0.0001773049645
169.544,0.88658,0.00219,,,,,0.05373212121,0.001438140268
170.044,0.92857,0.00327,,,,,0.0562769697,0.002147360126
170.544,0.97031,0.00588,,,,,0.05880666667,0.003861308117
171.044,1.01168,0.01182,,,,,0.06131393939,0.007762017336
171.544,1.05365,0.01367,,,,,0.06385757576,0.008976884686
172.044,1.09514,0.01453,,,,,0.06637212121,0.009541633832
172.544,1.13681,0.02008,,,,,0.06889757576,0.01318623588
173.044,1.17856,0.02203,,,,,0.07142787879,0.01446677174
173.544,1.21992,0.02454,,,,,0.07393454545,0.01611505122
174.044,1.26197,0.02901,,,,,0.0764830303,0.01905043341
174.544,1.30368,0.03193,,,,,0.07901090909,0.02096795377
175.044,1.34487,0.03422,,,,,0.08150727273,0.02247176254
175.544,1.38704,0.03699,,,,,0.0840630303,0.02429078014
176.044,1.42857,0.04103,,,,,0.08658,0.02694378776
176.544,1.47003,0.0443,,,,,0.08909272727,0.02909114789
177.044,1.51202,0.04746,,,,,0.09163757576,0.03116627266
177.544,1.55341,0.0497,,,,,0.09414606061,0.03263724718
178.044,1.59524,0.05211,,,,,0.09668121212,0.03421985816
178.544,1.63695,0.05573,,,,,0.09920909091,0.03659705805
178.802,1.64734,0.05325,,,,,0.09983878788,0.03496847912
179.302,1.60449,0.04201,,,,,0.09724181818,0.02758733911
179.802,1.5631,0.03195,,,,,0.09473333333,0.02098108747
180.302,1.52162,0.02733,,,,,0.09221939394,0.01794720252
180.802,1.47945,0.02185,,,,,0.08966363636,0.01434856843
181.302,1.43808,0.01539,,,,,0.08715636364,0.01010638298
181.802,1.39649,0.01005,,,,,0.08463575758,0.006599684791
182.302,1.3546,0.00643,,,,,0.0820969697,0.004222484896
182.802,1.31309,0.00253,,,,,0.07958121212,0.001661413186
183.302,1.27121,-0.0006,,,,,0.0770430303,-0.0003940110323
183.802,1.22973,-0.0044,,,,,0.07452909091,-0.002889414237
184.302,1.18824,-0.0091,,,,,0.07201454545,-0.00597583399
184.802,1.14615,-0.01106,,,,,0.06946363636,-0.007262936696
185.302,1.10479,-0.01524,,,,,0.0669569697,-0.01000788022
185.802,1.06309,-0.0184,,,,,0.06442969697,-0.01208300499
186.302,1.02126,-0.0216,,,,,0.06189454545,-0.01418439716
186.802,0.9798,-0.02417,,,,,0.05938181818,-0.01587207775
187.302,0.93793,-0.02723,,,,,0.05684424242,-0.01788153402
187.802,0.8964,-0.02987,,,,,0.05432727273,-0.01961518256
188.302,0.85502,-0.03211,,,,,0.05181939394,-0.02108615708
188.802,0.81276,-0.03559,,,,,0.04925818182,-0.02337142107
189.302,0.77144,-0.03765,,,,,0.04675393939,-0.02472419228
189.802,0.72981,-0.03889,,,,,0.04423090909,-0.02553848174
190.302,0.68793,-0.04193,,,,,0.04169272727,-0.02753480431
190.802,0.64641,-0.04353,,,,,0.03917636364,-0.02858550039
191.302,0.60473,-0.04612,,,,,0.03665030303,-0.03028631468
191.802,0.56301,-0.0488,,,,,0.03412181818,-0.03204623063
192.302,0.52149,-0.04958,,,,,0.03160545455,-0.03255844497
192.802,0.47947,-0.05149,,,,,0.02905878788,-0.03381271342
193.302,0.43812,-0.05487,,,,,0.02655272727,-0.0360323089
193.802,0.39654,-0.05573,,,,,0.02403272727,-0.03659705805
194.302,0.35439,-0.05675,,,,,0.02147818182,-0.03726687681
194.802,0.31318,-0.06095,,,,,0.01898060606,-0.04002495403
195.302,0.27139,-0.06213,,,,,0.01644787879,-0.0407998424
195.802,0.22959,-0.06393,,,,,0.01391454545,-0.04198187549
196.302,0.18815,-0.06566,,,,,0.0114030303,-0.04311794064
196.802,0.14627,-0.06676,,,,,0.008864848485,-0.04384029419
197.302,0.10465,-0.07043,,,,,0.006342424242,-0.04625032834
197.802,0.06328,-0.07252,,,,,0.003835151515,-0.04762280011
198.302,0.02111,-0.07182,,,,,0.001279393939,-0.04716312057
198.56,-0.00024,-0.07453,,,,,-0.00001454545455,-0.04894273706
199.06,0.03647,-0.06449,,,,,0.00221030303,-0.04234961912
199.56,0.07866,-0.05813,,,,,0.004767272727,-0.03817310218
200.06,0.12023,-0.05296,,,,,0.007286666667,-0.03477804045
200.56,0.16161,-0.04913,,,,,0.009794545455,-0.0322629367
201.06,0.20355,-0.04627,,,,,0.01233636364,-0.03038481744
201.56,0.24505,-0.04239,,,,,0.01485151515,-0.02783687943
202.06,0.28689,-0.03981,,,,,0.01738727273,-0.02614263199
202.56,0.32856,-0.036,,,,,0.01991272727,-0.02364066194
203.06,0.36981,-0.03568,,,,,0.02241272727,-0.02343052272
203.56,0.41198,-0.03074,,,,,0.02496848485,-0.02018649856
204.06,0.45355,-0.02665,,,,,0.02748787879,-0.01750065669
204.56,0.49478,-0.02855,,,,,0.02998666667,-0.01874835829
205.06,0.53707,-0.02466,,,,,0.03254969697,-0.01619385343
205.56,0.57844,-0.02037,,,,,0.0350569697,-0.01337667455
206.06,0.6201,-0.01862,,,,,0.03758181818,-0.0122274757
206.56,0.66194,-0.01444,,,,,0.04011757576,-0.009482532178
207.06,0.70328,-0.01411,,,,,0.0426230303,-0.00926582611
207.56,0.74527,-0.01026,,,,,0.04516787879,-0.006737588652
208.06,0.78697,-0.00708,,,,,0.04769515152,-0.004649330181
208.56,0.82824,-0.00633,,,,,0.05019636364,-0.004156816391
209.06,0.87031,-0.00424,,,,,0.05274606061,-0.002784344628
209.56,0.91181,0.00044,,,,,0.05526121212,0.0002889414237
210.06,0.95335,0.00567,,,,,0.05777878788,0.003723404255
210.56,0.99523,0.00594,,,,,0.0603169697,0.00390070922
211.06,1.03655,0.00816,,,,,0.06282121212,0.005358550039
211.56,1.07863,0.01197,,,,,0.06537151515,0.007860520095
212.06,1.1202,0.0154,,,,,0.06789090909,0.01011294983
212.56,1.16156,0.01904,,,,,0.07039757576,0.01250328343
213.06,1.2037,0.02109,,,,,0.07295151515,0.01384948779
213.56,1.24527,0.02609,,,,,0.07547090909,0.01713291305
214.06,1.28652,0.02779,,,,,0.07797090909,0.01824927765
214.56,1.32874,0.03234,,,,,0.08052969697,0.02123719464
215.06,1.37005,0.03425,,,,,0.08303333333,0.02249146309
215.56,1.41179,0.03609,,,,,0.0855630303,0.02369976359
216.06,1.45365,0.03767,,,,,0.0881,0.02473732598
216.56,1.49489,0.0421,,,,,0.09059939394,0.02764644077
217.06,1.53687,0.045,,,,,0.09314363636,0.02955082742
217.56,1.57849,0.04854,,,,,0.09566606061,0.03187549251
218.06,1.61992,0.0511,,,,,0.0981769697,0.03355660625
218.418,1.65012,0.05349,,,,,0.1000072727,0.03512608353
218.819,1.62146,0.04206,,,,,0.09827030303,0.02762017336
219.319,1.5799,0.03254,,,,,0.09575151515,0.02136853165
219.819,1.53787,0.02625,,,,,0.09320424242,0.01723798266
220.319,1.49654,0.01942,,,,,0.09069939394,0.01275282375
220.819,1.45462,0.0171,,,,,0.08815878788,0.01122931442
221.319,1.41319,0.0114,,,,,0.08564787879,0.007486209614
221.819,1.37157,0.00528,,,,,0.08312545455,0.003467297084
222.319,1.32948,0.00222,,,,,0.08057454545,0.00145784082
222.819,1.28818,-0.00329,,,,,0.07807151515,-0.002160493827
223.319,1.24651,-0.00777,,,,,0.07554606061,-0.005102442868
223.819,1.20451,-0.00817,,,,,0.07300060606,-0.00536511689
224.319,1.16323,-0.01238,,,,,0.07049878788,-0.008129760967
224.819,1.12132,-0.01613,,,,,0.06795878788,-0.01059232992
225.319,1.07968,-0.01958,,,,,0.06543515152,-0.01285789335
225.819,1.03835,-0.01984,,,,,0.06293030303,-0.01302863147
226.319,0.99616,-0.02608,,,,,0.06037333333,-0.0171263462
226.819,0.95474,-0.02558,,,,,0.0578630303,-0.01679800368
227.319,0.9133,-0.02913,,,,,0.05535151515,-0.01912923562
227.819,0.8712,-0.03368,,,,,0.0528,-0.02211715261
228.319,0.82972,-0.03468,,,,,0.05028606061,-0.02277383767
228.819,0.78814,-0.03784,,,,,0.04776606061,-0.02484896244
229.319,0.74636,-0.03974,,,,,0.04523393939,-0.02609666404
229.819,0.70486,-0.0426,,,,,0.04271878788,-0.02797478329
230.319,0.66294,-0.04258,,,,,0.04017818182,-0.02796164959
230.819,0.62148,-0.04582,,,,,0.03766545455,-0.03008930917
231.319,0.57991,-0.04914,,,,,0.03514606061,-0.03226950355
231.819,0.53785,-0.05066,,,,,0.0325969697,-0.03326766483
232.319,0.49654,-0.05107,,,,,0.03009333333,-0.0335369057
232.819,0.45477,-0.05494,,,,,0.02756181818,-0.03607827686
233.319,0.41301,-0.05651,,,,,0.02503090909,-0.03710927239
233.819,0.37159,-0.05766,,,,,0.02252060606,-0.0378644602
234.319,0.32961,-0.05925,,,,,0.01997636364,-0.03890858944
234.819,0.28808,-0.06384,,,,,0.01745939394,-0.04192277384
235.319,0.24663,-0.06393,,,,,0.01494727273,-0.04198187549
235.819,0.20456,-0.06601,,,,,0.01239757576,-0.0433477804
236.319,0.16313,-0.06766,,,,,0.009886666667,-0.04443131074
236.819,0.12158,-0.0704,,,,,0.007368484848,-0.04623062779
237.319,0.07957,-0.07325,,,,,0.004822424242,-0.04810218019
237.819,0.03811,-0.07384,,,,,0.00230969697,-0.04848962438
238.275,-0.00001,-0.07758,,,,,-0.0000006060606061,-0.05094562648
238.577,0.02019,-0.06884,,,,,0.001223636364,-0.04520619911
239.077,0.06186,-0.06161,,,,,0.003749090909,-0.04045836617
239.577,0.10346,-0.05764,,,,,0.00627030303,-0.0378513265
240.077,0.14525,-0.05299,,,,,0.008803030303,-0.034797741
240.577,0.18663,-0.04957,,,,,0.01131090909,-0.03255187812
241.077,0.22863,-0.04705,,,,,0.01385636364,-0.03089703178
241.577,0.27021,-0.04413,,,,,0.01637636364,-0.02897951143
242.077,0.3115,-0.03999,,,,,0.01887878788,-0.0262608353
242.577,0.35377,-0.03735,,,,,0.02144060606,-0.02452718676
243.077,0.39513,-0.03597,,,,,0.02394727273,-0.02362096139
243.577,0.43676,-0.03156,,,,,0.02647030303,-0.0207249803
244.077,0.47872,-0.02854,,,,,0.02901333333,-0.01874179144
244.577,0.51996,-0.02702,,,,,0.03151272727,-0.01774363015
245.077,0.56189,-0.02603,,,,,0.03405393939,-0.01709351195
245.577,0.6037,-0.02008,,,,,0.03658787879,-0.01318623588
246.077,0.64487,-0.01818,,,,,0.0390830303,-0.01193853428
246.577,0.68694,-0.01527,,,,,0.04163272727,-0.01002758077
247.077,0.72859,-0.01324,,,,,0.0441569697,-0.008694510113
247.577,0.77,-0.00943,,,,,0.04666666667,-0.006192540058
248.077,0.81191,-0.00787,,,,,0.04920666667,-0.005168111374
248.577,0.85337,-0.0046,,,,,0.05171939394,-0.003020751248
249.077,0.89524,-0.00223,,,,,0.0542569697,-0.00146440767
249.577,0.93694,0.00289,,,,,0.05678424242,0.001897819806
250.077,0.9782,0.00499,,,,,0.05928484848,0.003276858419
250.577,1.02036,0.00697,,,,,0.06184,0.004577094825
251.077,1.06192,0.01009,,,,,0.06435878788,0.006625952193
251.577,1.10329,0.01345,,,,,0.06686606061,0.008832413974
252.077,1.14534,0.01636,,,,,0.06941454545,0.01074336748
252.577,1.18683,0.01864,,,,,0.07192909091,0.0122406094
253.077,1.22847,0.02202,,,,,0.07445272727,0.01446020489
253.577,1.27032,0.02429,,,,,0.07698909091,0.01595087996
254.077,1.31162,0.02727,,,,,0.07949212121,0.01790780142
254.577,1.35361,0.03107,,,,,0.0820369697,0.02040320462
255.077,1.39528,0.0328,,,,,0.08456242424,0.02153926977
255.577,1.43657,0.03515,,,,,0.08706484848,0.02308247964
256.077,1.47867,0.03975,,,,,0.08961636364,0.02610323089
256.577,1.52018,0.04228,,,,,0.09213212121,0.02776464408
257.077,1.56176,0.044,,,,,0.09465212121,0.02889414237
257.577,1.60364,0.04875,,,,,0.09719030303,0.03201339638
258.077,1.64503,0.05087,,,,,0.09969878788,0.03340556869
258.336,1.63828,0.04702,,,,,0.09928969697,0.03087733123
258.836,1.59639,0.03374,,,,,0.09675090909,0.02215655372
259.336,1.55492,0.02757,,,,,0.09423757576,0.01810480693
259.836,1.51285,0.02181,,,,,0.09168787879,0.01432230102
260.336,1.47151,0.01589,,,,,0.08918242424,0.01043472551
260.836,1.42994,0.00971,,,,,0.0866630303,0.006376411873
261.336,1.38794,0.00704,,,,,0.08411757576,0.004623062779
261.836,1.34654,0.00181,,,,,0.08160848485,0.001188599947
262.336,1.30474,-0.00237,,,,,0.07907515152,-0.001556343578
262.836,1.26307,-0.00789,,,,,0.07654969697,-0.005181245075
263.336,1.2216,-0.00808,,,,,0.07403636364,-0.005306015235
263.836,1.17955,-0.01261,,,,,0.07148787879,-0.008280798529
264.336,1.1381,-0.01752,,,,,0.06897575758,-0.01150512214
264.836,1.09671,-0.01873,,,,,0.06646727273,-0.01229971106
265.336,1.05444,-0.0218,,,,,0.06390545455,-0.01431573417
265.836,1.0132,-0.02516,,,,,0.06140606061,-0.01652219595
266.336,0.97146,-0.02776,,,,,0.05887636364,-0.01822957709
266.836,0.92974,-0.02966,,,,,0.05634787879,-0.0194772787
267.336,0.88818,-0.0312,,,,,0.05382909091,-0.02048857368
267.836,0.84631,-0.03577,,,,,0.05129151515,-0.02348962438
268.336,0.80481,-0.03803,,,,,0.04877636364,-0.0249737326
268.836,0.76328,-0.03913,,,,,0.04625939394,-0.02569608616
269.336,0.72116,-0.04121,,,,,0.04370666667,-0.02706199107
269.836,0.6799,-0.04428,,,,,0.04120606061,-0.02907801418
270.336,0.63821,-0.04639,,,,,0.03867939394,-0.03046361965
270.836,0.59617,-0.04679,,,,,0.03613151515,-0.03072629367
271.336,0.55495,-0.05221,,,,,0.03363333333,-0.03428552666
271.836,0.513,-0.05299,,,,,0.03109090909,-0.034797741
272.336,0.47137,-0.0543,,,,,0.02856787879,-0.03565799842
272.836,0.42994,-0.0576,,,,,0.0260569697,-0.0378250591
273.336,0.38789,-0.05871,,,,,0.02350848485,-0.03855397951
273.836,0.34639,-0.06201,,,,,0.02099333333,-0.04072104019
274.336,0.30496,-0.06326,,,,,0.01848242424,-0.04154189651
274.836,0.26289,-0.06492,,,,,0.01593272727,-0.0426319937
275.336,0.22148,-0.06873,,,,,0.0134230303,-0.04513396375
275.836,0.17977,-0.07028,,,,,0.01089515152,-0.04615182558
276.336,0.13807,-0.07274,,,,,0.008367878788,-0.04776727082
276.836,0.09654,-0.07228,,,,,0.005850909091,-0.04746519569
277.336,0.05459,-0.07487,,,,,0.003308484848,-0.04916600998
277.836,0.01323,-0.07858,,,,,0.0008018181818,-0.05160231153
278.095,0.00226,-0.07431,,,,,0.000136969697,-0.04879826635
278.595,0.04524,-0.06624,,,,,0.002741818182,-0.04349881797
279.095,0.08687,-0.06164,,,,,0.005264848485,-0.04047806672
279.595,0.12813,-0.05827,,,,,0.007765454545,-0.03826503809
280.095,0.17027,-0.05365,,,,,0.01031939394,-0.03523115314
280.595,0.21179,-0.05052,,,,,0.01283575758,-0.03317572892
281.095,0.2532,-0.04708,,,,,0.01534545455,-0.03091673234
281.595,0.2953,-0.047,,,,,0.0178969697,-0.03086419753
282.095,0.33657,-0.04038,,,,,0.02039818182,-0.02651694247
282.595,0.37845,-0.03739,,,,,0.02293636364,-0.02455345416
283.095,0.42026,-0.03564,,,,,0.02547030303,-0.02340425532
283.595,0.46149,-0.03149,,,,,0.02796909091,-0.02067901235
284.095,0.50359,-0.02944,,,,,0.03052060606,-0.01933280799
284.595,0.54522,-0.02713,,,,,0.03304363636,-0.01781586551
285.095,0.58656,-0.02345,,,,,0.03554909091,-0.01539926451
285.595,0.62852,-0.01967,,,,,0.03809212121,-0.01291699501
286.095,0.67002,-0.01792,,,,,0.04060727273,-0.01176779616
286.595,0.71178,-0.01535,,,,,0.04313818182,-0.01008011558
287.095,0.75348,-0.01142,,,,,0.04566545455,-0.007499343315
287.595,0.79478,-0.00868,,,,,0.04816848485,-0.005700026267
288.095,0.83698,-0.00644,,,,,0.05072606061,-0.004229051747
288.595,0.87845,-0.00435,,,,,0.05323939394,-0.002856579984
289.095,0.91986,-0.00145,,,,,0.05574909091,-0.0009521933281
289.595,0.96198,0.00144,,,,,0.05830181818,0.0009456264775
290.095,1.00342,0.00313,,,,,0.06081333333,0.002055424219
290.595,1.04493,0.00562,,,,,0.06332909091,0.003690570003
291.095,1.08697,0.0076,,,,,0.0658769697,0.004990806409
291.595,1.12815,0.01281,,,,,0.06837272727,0.00841213554
292.095,1.17012,0.01478,,,,,0.07091636364,0.009705805096
292.595,1.2119,0.01713,,,,,0.07344848485,0.01124901497
293.095,1.25315,0.02006,,,,,0.07594848485,0.01317310218
293.595,1.29521,0.02277,,,,,0.07849757576,0.01495271868
294.095,1.33676,0.02568,,,,,0.08101575758,0.01686367218
294.595,1.37831,0.02773,,,,,0.08353393939,0.01820987654
295.095,1.42013,0.03183,,,,,0.08606848485,0.02090228526
295.595,1.4616,0.035,,,,,0.08858181818,0.02298397688
296.095,1.50346,0.03803,,,,,0.09111878788,0.0249737326
296.595,1.54526,0.04197,,,,,0.09365212121,0.02756107171
297.095,1.58643,0.04605,,,,,0.09614727273,0.03024034673
297.595,1.62865,0.04732,,,,,0.09870606061,0.03107433675
297.855,1.65023,0.05071,,,,,0.1000139394,0.03330049908
298.355,1.61327,0.03565,,,,,0.09777393939,0.02341082217
298.855,1.57122,0.02613,,,,,0.09522545455,0.01715918046
299.355,1.5299,0.01901,,,,,0.09272121212,0.01248358287
299.855,1.48816,0.01451,,,,,0.09019151515,0.009528500131
300.355,1.44632,0.00897,,,,,0.08765575758,0.005890464933
300.855,1.40496,0.00505,,,,,0.08514909091,0.003316259522
301.355,1.36296,0.0022,,,,,0.08260363636,0.001444707118
301.855,1.32143,-0.00296,,,,,0.08008666667,-0.001943787759
302.355,1.28002,-0.00553,,,,,0.0775769697,-0.003631468348
302.855,1.23782,-0.01002,,,,,0.07501939394,-0.00657998424
303.355,1.19647,-0.01399,,,,,0.07251333333,-0.009187023903
303.855,1.15495,-0.01814,,,,,0.0699969697,-0.01191226688
304.355,1.11297,-0.01944,,,,,0.06745272727,-0.01276595745
304.855,1.07146,-0.02132,,,,,0.0649369697,-0.01400052535
305.355,1.02975,-0.02435,,,,,0.06240909091,-0.01599028106
305.855,0.9881,-0.02853,,,,,0.05988484848,-0.01873522459
306.355,0.94666,-0.03015,,,,,0.05737333333,-0.01979905437
306.855,0.9046,-0.03113,,,,,0.05482424242,-0.02044260573
307.355,0.86317,-0.0347,,,,,0.05231333333,-0.02278697137
307.855,0.82156,-0.03755,,,,,0.04979151515,-0.02465852377
308.355,0.7796,-0.0403,,,,,0.04724848485,-0.02646440767
308.855,0.73822,-0.0427,,,,,0.04474060606,-0.0280404518
309.355,0.69641,-0.04524,,,,,0.04220666667,-0.02970843184
309.855,0.65476,-0.04728,,,,,0.03968242424,-0.03104806935
310.355,0.61336,-0.04928,,,,,0.03717333333,-0.03236143945
310.855,0.57121,-0.0509,,,,,0.03461878788,-0.03342526924
311.355,0.52983,-0.05357,,,,,0.03211090909,-0.03517861833
311.855,0.48831,-0.05635,,,,,0.02959454545,-0.03700420278
312.355,0.4463,-0.0579,,,,,0.02704848485,-0.03802206462
312.855,0.40484,-0.06037,,,,,0.02453575758,-0.0396440767
313.355,0.36322,-0.06303,,,,,0.02201333333,-0.04139085894
313.855,0.32141,-0.06435,,,,,0.01947939394,-0.04225768322
314.355,0.27988,-0.06595,,,,,0.01696242424,-0.0433083793
314.855,0.23796,-0.06751,,,,,0.01442181818,-0.04433280799
315.355,0.19654,-0.06853,,,,,0.01191151515,-0.04500262674
315.855,0.15497,-0.07241,,,,,0.009392121212,-0.04755056475
316.355,0.11279,-0.07318,,,,,0.006835757576,-0.04805621224
316.855,0.07157,-0.07378,,,,,0.004337575758,-0.04845022327
317.355,0.02988,-0.07751,,,,,0.001810909091,-0.05089965852
317.713,-0.00016,-0.07857,,,,,-0.000009696969697,-0.05159574468
318.114,0.02843,-0.07241,,,,,0.001723030303,-0.04755056475
318.614,0.06986,-0.06489,,,,,0.004233939394,-0.04261229314
319.114,0.11198,-0.05777,,,,,0.006786666667,-0.03793669556
319.614,0.15331,-0.05532,,,,,0.009291515152,-0.03632781718
320.114,0.19508,-0.05162,,,,,0.0118230303,-0.03389808248
320.614,0.23697,-0.04841,,,,,0.01436181818,-0.03179012346
321.114,0.2781,-0.04457,,,,,0.01685454545,-0.02926845285
321.614,0.32026,-0.04312,,,,,0.01940969697,-0.02831625952
322.114,0.36195,-0.04028,,,,,0.02193636364,-0.02645127397
322.614,0.40317,-0.03564,,,,,0.02443454545,-0.02340425532
323.114,0.44522,-0.03186,,,,,0.0269830303,-0.02092198582
323.614,0.48684,-0.03082,,,,,0.02950545455,-0.02023903336
324.114,0.52842,-0.02877,,,,,0.03202545455,-0.018892829
324.614,0.57021,-0.02657,,,,,0.03455818182,-0.01744812188
325.114,0.61154,-0.02318,,,,,0.0370630303,-0.01522195955
325.614,0.6536,-0.02108,,,,,0.03961212121,-0.01384292094
326.114,0.69522,-0.01753,,,,,0.04213454545,-0.01151168899
326.614,0.73646,-0.01625,,,,,0.04463393939,-0.01067113213
327.114,0.77868,-0.01419,,,,,0.04719272727,-0.009318360914
327.614,0.82013,-0.01221,,,,,0.04970484848,-0.008018124507
328.114,0.86164,-0.00839,,,,,0.05222060606,-0.005509587602
328.614,0.90354,-0.00541,,,,,0.05476,-0.003552666141
329.114,0.94497,-0.00263,,,,,0.05727090909,-0.001727081692
329.614,0.98684,-0.00091,,,,,0.05980848485,-0.000597583399
330.114,1.02864,0.00406,,,,,0.06234181818,0.002666141319
330.614,1.06988,0.00712,,,,,0.06484121212,0.004675597583
331.114,1.11201,0.0083,,,,,0.06739454545,0.005450485947
331.614,1.15353,0.01177,,,,,0.06991090909,0.007729183084
332.114,1.19491,0.0164,,,,,0.07241878788,0.01076963488
332.614,1.23697,0.01818,,,,,0.07496787879,0.01193853428
333.114,1.2783,0.0209,,,,,0.07747272727,0.01372471763
333.614,1.32017,0.0244,,,,,0.08001030303,0.01602311531
334.114,1.36186,0.02722,,,,,0.0825369697,0.01787496717
334.614,1.40319,0.03027,,,,,0.08504181818,0.01987785658
335.114,1.44527,0.03432,,,,,0.08759212121,0.02253743105
335.614,1.48688,0.03624,,,,,0.09011393939,0.02379826635
336.114,1.52812,0.04012,,,,,0.09261333333,0.02634620436
336.614,1.57034,0.04561,,,,,0.09517212121,0.02995140531
337.114,1.61178,0.04624,,,,,0.09768363636,0.03036511689
337.571,1.65006,0.04772,,,,,0.1000036364,0.03133701077
337.873,1.62987,0.04048,,,,,0.09878,0.02658261098
338.373,1.58828,0.03094,,,,,0.09625939394,0.02031783557
338.873,1.54631,0.02352,,,,,0.09371575758,0.01544523247
339.373,1.50483,0.01795,,,,,0.09120181818,0.01178749672
339.873,1.46332,0.01068,,,,,0.08868606061,0.007013396375
340.373,1.42119,0.00638,,,,,0.08613272727,0.004189650644
340.873,1.37983,0.00224,,,,,0.08362606061,0.001470974521
341.373,1.3384,-0.00042,,,,,0.08111515152,-0.0002758077226
341.873,1.29621,-0.0056,,,,,0.07855818182,-0.003677436302
342.373,1.25491,-0.01151,,,,,0.07605515152,-0.00755844497
342.873,1.21312,-0.01168,,,,,0.07352242424,-0.007670081429
343.373,1.17158,-0.0176,,,,,0.07100484848,-0.01155765695
343.873,1.12991,-0.01471,,,,,0.06847939394,-0.009659837142
344.373,1.08793,-0.02343,,,,,0.06593515152,-0.01538613081
344.873,1.04652,-0.02333,,,,,0.06342545455,-0.01532046231
345.373,1.00494,-0.02821,,,,,0.06090545455,-0.01852508537
345.873,0.96286,-0.03101,,,,,0.05835515152,-0.02036380352
346.373,0.92158,-0.03236,,,,,0.05585333333,-0.02125032834
346.873,0.87982,-0.03518,,,,,0.05332242424,-0.02310218019
347.373,0.83798,-0.03851,,,,,0.05078666667,-0.02528894142
347.873,0.7967,-0.03985,,,,,0.04828484848,-0.0261688994
348.373,0.75461,-0.04137,,,,,0.04573393939,-0.02716706068
348.873,0.7131,-0.04481,,,,,0.04321818182,-0.02942605726
349.373,0.67167,-0.0483,,,,,0.04070727273,-0.0317178881
349.873,0.62959,-0.04786,,,,,0.0381569697,-0.03142894668
350.373,0.58812,-0.05195,,,,,0.03564363636,-0.03411478855
350.873,0.54663,-0.05361,,,,,0.03312909091,-0.03520488574
351.373,0.50468,-0.05662,,,,,0.03058666667,-0.03718150775
351.873,0.46322,-0.05978,,,,,0.02807393939,-0.03925663252
352.373,0.42138,-0.05913,,,,,0.02553818182,-0.03882978723
352.873,0.3798,-0.06349,,,,,0.02301818182,-0.04169293407
353.373,0.33828,-0.06502,,,,,0.02050181818,-0.0426976622
353.873,0.29622,-0.06808,,,,,0.01795272727,-0.04470711847
354.373,0.2549,-0.0683,,,,,0.01544848485,-0.04485158918
354.873,0.2132,-0.07166,,,,,0.01292121212,-0.04705805096
355.373,0.17128,-0.07389,,,,,0.01038060606,-0.04852245863
355.873,0.12996,-0.07314,,,,,0.007876363636,-0.04802994484
356.373,0.08811,-0.07644,,,,,0.00534,-0.05019700552
356.873,0.0464,-0.0775,,,,,0.002812121212,-0.05089309167
357.373,0.00504,-0.07993,,,,,0.0003054545455,-0.05248883635
357.632,0.01138,-0.07674,,,,,0.0006896969697,-0.05039401103
358.132,0.05368,-0.06721,,,,,0.003253333333,-0.04413580247
358.632,0.09488,-0.06287,,,,,0.00575030303,-0.04128578934
359.132,0.13693,-0.0601,,,,,0.008298787879,-0.03946677174
359.632,0.17859,-0.05548,,,,,0.01082363636,-0.03643288679
360.132,0.21987,-0.05019,,,,,0.01332545455,-0.03295902285
360.632,0.26192,-0.0494,,,,,0.01587393939,-0.03244024166
361.132,0.30364,-0.04858,,,,,0.01840242424,-0.03190175992
361.632,0.345,-0.04036,,,,,0.02090909091,-0.02650380877
362.132,0.38693,-0.03862,,,,,0.02345030303,-0.02536117678
362.632,0.42833,-0.03643,,,,,0.02595939394,-0.02392303651
363.132,0.47021,-0.03532,,,,,0.02849757576,-0.0231941161
363.632,0.51182,-0.03046,,,,,0.03101939394,-0.02000262674
364.132,0.55314,-0.02879,,,,,0.03352363636,-0.0189059627
364.632,0.59537,-0.02518,,,,,0.0360830303,-0.01653532966
365.132,0.63679,-0.02569,,,,,0.03859333333,-0.01687023903
365.632,0.67829,-0.02243,,,,,0.04110848485,-0.01472944576
366.132,0.72032,-0.01763,,,,,0.04365575758,-0.0115773575
366.632,0.76171,-0.01545,,,,,0.04616424242,-0.01014578408
367.132,0.80343,-0.01341,,,,,0.04869272727,-0.008806146572
367.632,0.84538,-0.01112,,,,,0.05123515152,-0.007302337799
368.132,0.88648,-0.00739,,,,,0.05372606061,-0.004852902548
368.632,0.92855,-0.00438,,,,,0.05627575758,-0.002876280536
369.132,0.97029,-0.00206,,,,,0.05880545455,-0.001352771211
369.632,1.01154,0.00103,,,,,0.06130545455,0.0006763856055
370.132,1.05361,0.00422,,,,,0.06385515152,0.002771210927
370.632,1.0951,0.00633,,,,,0.06636969697,0.004156816391
371.132,1.13673,0.01033,,,,,0.06889272727,0.006783556606
371.632,1.17852,0.01281,,,,,0.07142545455,0.00841213554
372.132,1.21987,0.01663,,,,,0.07393151515,0.01092067245
372.632,1.2619,0.01917,,,,,0.07647878788,0.01258865248
373.132,1.30358,0.02548,,,,,0.07900484848,0.01673233517
373.632,1.34485,0.02795,,,,,0.08150606061,0.01835434726
374.132,1.38702,0.02986,,,,,0.08406181818,0.01960861571
374.632,1.42851,0.03048,,,,,0.08657636364,0.02001576044
375.132,1.47,0.03488,,,,,0.08909090909,0.02290517468
375.632,1.51196,0.03761,,,,,0.09163393939,0.02469792488
376.132,1.55332,0.04065,,,,,0.09414060606,0.02669424744
376.632,1.59521,0.04311,,,,,0.09667939394,0.02830969267
377.132,1.63691,0.04638,,,,,0.09920666667,0.0304570528
377.391,1.64751,0.04799,,,,,0.09984909091,0.03151431573
377.891,1.6047,0.03528,,,,,0.09725454545,0.0231678487
378.391,1.56336,0.02538,,,,,0.09474909091,0.01666666667
378.891,1.52184,0.01766,,,,,0.09223272727,0.01159705805
379.391,1.47966,0.01451,,,,,0.08967636364,0.009528500131
379.891,1.43834,0.00905,,,,,0.08717212121,0.005942999737
380.391,1.39671,0.00162,,,,,0.08464909091,0.001063829787
380.891,1.35486,-0.00203,,,,,0.08211272727,-0.001333070659
381.391,1.31337,-0.00411,,,,,0.07959818182,-0.002698975571
381.891,1.27141,-0.00876,,,,,0.07705515152,-0.005752561072
382.391,1.23001,-0.01245,,,,,0.07454606061,-0.00817572892
382.891,1.18848,-0.0172,,,,,0.07202909091,-0.01129498293
383.391,1.1464,-0.01852,,,,,0.06947878788,-0.0121618072
383.891,1.10499,-0.02303,,,,,0.06696909091,-0.01512345679
384.391,1.06328,-0.02681,,,,,0.06444121212,-0.01760572629
384.891,1.02153,-0.02721,,,,,0.06191090909,-0.01786840032
385.391,0.9801,-0.03207,,,,,0.0594,-0.02105988968
385.891,0.93813,-0.03351,,,,,0.05685636364,-0.02200551615
386.391,0.89667,-0.03483,,,,,0.05434363636,-0.02287234043
386.891,0.85528,-0.03719,,,,,0.05183515152,-0.02442211715
387.391,0.81298,-0.04136,,,,,0.04927151515,-0.02716049383
387.891,0.77169,-0.04201,,,,,0.04676909091,-0.02758733911
388.391,0.73003,-0.04532,,,,,0.04424424242,-0.02976096664
388.891,0.68819,-0.04829,,,,,0.04170848485,-0.03171132125
389.391,0.64663,-0.04892,,,,,0.03918969697,-0.03212503283
389.891,0.60492,-0.05021,,,,,0.03666181818,-0.03297215655
390.391,0.56328,-0.054,,,,,0.03413818182,-0.03546099291
390.891,0.52174,-0.05673,,,,,0.03162060606,-0.0372537431
391.391,0.47969,-0.05797,,,,,0.02907212121,-0.03806803257
391.891,0.43836,-0.05972,,,,,0.02656727273,-0.03921723142
392.391,0.39677,-0.06377,,,,,0.02404666667,-0.04187680588
392.891,0.35465,-0.06484,,,,,0.02149393939,-0.04257945889
393.391,0.31342,-0.06655,,,,,0.01899515152,-0.04370239033
393.891,0.27158,-0.06905,,,,,0.01645939394,-0.04534410297
394.391,0.22986,-0.07212,,,,,0.01393090909,-0.04736012608
394.891,0.18841,-0.07389,,,,,0.01141878788,-0.04852245863
395.391,0.14647,-0.07331,,,,,0.008876969697,-0.0481415813
395.891,0.1049,-0.07769,,,,,0.006357575758,-0.05101786183
396.391,0.06352,-0.07929,,,,,0.00384969697,-0.05206855792
396.891,0.02136,-0.07985,,,,,0.001294545455,-0.05243630155
397.15,-0.00008,-0.08139,,,,,-0.000004848484848,-0.05344759653