File: mechanical/hysteresis/data/g60_nonconductive_1.csv
Time,Extension,Load,Length,Width,Thickness,CS Area,Strain,Stress
(s),(mm),(N),(mm),(mm),(mm),(mm^2),(mm/mm),(MPa)
0,0,-0.00123,16.5,2.52,0.44,1.1088,0,-0.001109307359
0.5,0.03904,0.00175,,,,,0.002366060606,0.001578282828
1,0.08022,-0.0001,,,,,0.004861818182,-0.00009018759019
1.5,0.12243,0.00016,,,,,0.00742,0.0001443001443
2,0.16399,0.00312,,,,,0.009938787879,0.002813852814
2.5,0.20527,0.00373,,,,,0.01244060606,0.003363997114
3,0.24739,0.00208,,,,,0.01499333333,0.001875901876
3.5,0.28883,0.00509,,,,,0.01750484848,0.004590548341
4,0.33048,0.00324,,,,,0.02002909091,0.002922077922
4.5,0.3723,0.00363,,,,,0.02256363636,0.003273809524
5,0.41365,0.00533,,,,,0.02506969697,0.004806998557
5.5,0.45565,0.00651,,,,,0.02761515152,0.005871212121
6,0.49734,0.00778,,,,,0.03014181818,0.007016594517
6.5,0.53864,0.00874,,,,,0.03264484848,0.007882395382
7,0.58074,0.00903,,,,,0.03519636364,0.008143939394
7.5,0.62223,0.00895,,,,,0.03771090909,0.008071789322
8,0.6638,0.01087,,,,,0.04023030303,0.009803391053
8.5,0.70575,0.01279,,,,,0.04277272727,0.01153499278
9,0.74698,0.01263,,,,,0.04527151515,0.01139069264
9.5,0.78902,0.0109,,,,,0.04781939394,0.00983044733
10,0.83076,0.01129,,,,,0.05034909091,0.01018217893
10.5,0.87184,0.01074,,,,,0.05283878788,0.009686147186
11,0.91403,0.0169,,,,,0.05539575758,0.01524170274
11.5,0.95562,0.01363,,,,,0.05791636364,0.01229256854
12,0.99699,0.01544,,,,,0.06042363636,0.01392496392
12.5,1.03903,0.01506,,,,,0.06297151515,0.01358225108
13,1.08051,0.01751,,,,,0.06548545455,0.01579184704
13.5,1.12227,0.01409,,,,,0.06801636364,0.01270743146
14,1.16404,0.02015,,,,,0.07054787879,0.01817279942
14.5,1.20532,0.02223,,,,,0.07304969697,0.0200487013
15,1.24743,0.0194,,,,,0.07560181818,0.0174963925
15.5,1.28897,0.02043,,,,,0.07811939394,0.01842532468
16,1.33034,0.01804,,,,,0.08062666667,0.01626984127
16.5,1.3724,0.01927,,,,,0.08317575758,0.01737914863
17,1.41373,0.02681,,,,,0.08568060606,0.02417929293
17.5,1.45551,0.0243,,,,,0.08821272727,0.02191558442
18,1.49739,0.01995,,,,,0.09075090909,0.01799242424
18.5,1.53854,0.02053,,,,,0.09324484848,0.01851551227
19,1.58058,0.02613,,,,,0.09579272727,0.02356601732
19.5,1.62237,0.02729,,,,,0.09832545455,0.02461219336
19.834,1.65012,0.02463,,,,,0.1000072727,0.02221320346
20.235,1.6213,0.0256,,,,,0.09826060606,0.02308802309
20.735,1.57926,0.02421,,,,,0.09571272727,0.02183441558
21.235,1.53769,0.01931,,,,,0.09319333333,0.01741522367
21.735,1.49622,0.02066,,,,,0.09068,0.01863275613
22.235,1.45412,0.02062,,,,,0.08812848485,0.0185966811
22.735,1.41281,0.01777,,,,,0.08562484848,0.01602633478
23.235,1.37108,0.01619,,,,,0.08309575758,0.01460137085
23.735,1.32932,0.01467,,,,,0.08056484848,0.01323051948
24.235,1.2879,0.01417,,,,,0.07805454545,0.01277958153
24.735,1.24583,0.0143,,,,,0.07550484848,0.0128968254
25.235,1.20443,0.01362,,,,,0.07299575758,0.01228354978
25.735,1.16296,0.01115,,,,,0.07048242424,0.01005591631
26.235,1.12079,0.01076,,,,,0.06792666667,0.009704184704
26.735,1.07943,0.01066,,,,,0.06542,0.009613997114
27.235,1.03794,0.00851,,,,,0.06290545455,0.007674963925
27.735,0.99589,0.00871,,,,,0.0603569697,0.007855339105
28.235,0.95448,0.00784,,,,,0.05784727273,0.007070707071
28.735,0.91258,0.00719,,,,,0.05530787879,0.006484487734
29.235,0.87114,0.00236,,,,,0.05279636364,0.002128427128
29.735,0.82951,0.00523,,,,,0.05027333333,0.004716810967
30.235,0.78745,0.00502,,,,,0.04772424242,0.004527417027
30.735,0.74613,0.00577,,,,,0.04522,0.005203823954
31.235,0.70448,0.0004,,,,,0.04269575758,0.0003607503608
31.735,0.66249,0.00032,,,,,0.04015090909,0.0002886002886
32.235,0.62115,0.00092,,,,,0.03764545455,0.0008297258297
32.735,0.57934,0.00246,,,,,0.03511151515,0.002218614719
33.235,0.53764,0.00095,,,,,0.03258424242,0.0008567821068
33.735,0.49632,-0.00073,,,,,0.03008,-0.0006583694084
34.235,0.45411,-0.00347,,,,,0.02752181818,-0.00312950938
34.735,0.41276,-0.00177,,,,,0.02501575758,-0.001596320346
35.235,0.37128,-0.00428,,,,,0.02250181818,-0.00386002886
35.735,0.32913,-0.00343,,,,,0.01994727273,-0.003093434343
36.235,0.28768,-0.00441,,,,,0.01743515152,-0.003977272727
36.735,0.24609,-0.00585,,,,,0.01491454545,-0.005275974026
37.235,0.20432,-0.0069,,,,,0.0123830303,-0.006222943723
37.735,0.16285,-0.00753,,,,,0.00986969697,-0.006791125541
38.235,0.12088,-0.00546,,,,,0.007326060606,-0.004924242424
38.735,0.07945,-0.00914,,,,,0.004815151515,-0.008243145743
39.235,0.03787,-0.00923,,,,,0.002295151515,-0.008324314574
39.689,-0.00006,-0.01165,,,,,-0.000003636363636,-0.01050685426
39.991,0.01995,-0.01062,,,,,0.001209090909,-0.009577922078
40.491,0.06188,-0.00952,,,,,0.00375030303,-0.008585858586
40.991,0.10306,-0.00533,,,,,0.006246060606,-0.004806998557
41.491,0.14512,-0.00577,,,,,0.008795151515,-0.005203823954
41.991,0.18684,-0.0052,,,,,0.01132363636,-0.00468975469
42.491,0.22818,-0.00478,,,,,0.01382909091,-0.004310966811
42.991,0.27022,-0.00515,,,,,0.0163769697,-0.004644660895
43.491,0.31165,-0.00031,,,,,0.01888787879,-0.0002795815296
43.991,0.35342,-0.00252,,,,,0.02141939394,-0.002272727273
44.491,0.39511,0.00027,,,,,0.02394606061,0.0002435064935
44.991,0.43643,-0.0009,,,,,0.02645030303,-0.0008116883117
45.491,0.47853,-0.00041,,,,,0.02900181818,-0.0003697691198
45.991,0.52016,0.00066,,,,,0.03152484848,0.0005952380952
46.491,0.56145,0.00317,,,,,0.03402727273,0.002858946609
46.991,0.60357,0.00502,,,,,0.03658,0.004527417027
47.491,0.64506,0.00426,,,,,0.03909454545,0.003841991342
47.991,0.68658,0.0034,,,,,0.04161090909,0.003066378066
48.491,0.72853,0.00361,,,,,0.04415333333,0.003255772006
48.991,0.76987,0.00461,,,,,0.04665878788,0.004157647908
49.491,0.81182,0.00539,,,,,0.04920121212,0.004861111111
49.991,0.85347,0.00839,,,,,0.05172545455,0.007566738817
50.491,0.89475,0.00762,,,,,0.05422727273,0.006872294372
50.991,0.93689,0.00716,,,,,0.05678121212,0.006457431457
51.491,0.97839,0.00627,,,,,0.05929636364,0.005654761905
51.991,1.01994,0.00925,,,,,0.06181454545,0.008342352092
52.491,1.06187,0.01337,,,,,0.06435575758,0.01205808081
52.991,1.10326,0.01281,,,,,0.06686424242,0.0115530303
53.491,1.14515,0.01028,,,,,0.0694030303,0.009271284271
53.991,1.18689,0.01032,,,,,0.07193272727,0.009307359307
54.491,1.22799,0.0128,,,,,0.07442363636,0.01154401154
54.991,1.27025,0.01544,,,,,0.07698484848,0.01392496392
55.491,1.31185,0.01664,,,,,0.07950606061,0.01500721501
55.991,1.35308,0.01688,,,,,0.08200484848,0.01522366522
56.491,1.39525,0.0134,,,,,0.08456060606,0.01208513709
56.991,1.43667,0.01413,,,,,0.08707090909,0.01274350649
57.491,1.47833,0.01653,,,,,0.08959575758,0.01490800866
57.991,1.52015,0.02007,,,,,0.09213030303,0.01810064935
58.491,1.56153,0.01774,,,,,0.09463818182,0.0159992785
58.991,1.60347,0.01842,,,,,0.09718,0.01661255411
59.491,1.64519,0.01931,,,,,0.09970848485,0.01741522367
59.752,1.6378,0.02055,,,,,0.09926060606,0.01853354978
60.252,1.5961,0.01782,,,,,0.09673333333,0.01607142857
60.752,1.55442,0.01767,,,,,0.09420727273,0.01593614719
61.252,1.51257,0.01643,,,,,0.09167090909,0.01481782107
61.752,1.47119,0.01302,,,,,0.0891630303,0.01174242424
62.252,1.4292,0.01408,,,,,0.08661818182,0.0126984127
62.752,1.38776,0.01349,,,,,0.08410666667,0.01216630592
63.252,1.34629,0.01086,,,,,0.08159333333,0.009794372294
63.752,1.30407,0.00989,,,,,0.07903454545,0.00891955267
64.252,1.26278,0.0104,,,,,0.07653212121,0.00937950938
64.752,1.2212,0.00859,,,,,0.07401212121,0.007747113997
65.252,1.17916,0.00578,,,,,0.07146424242,0.005212842713
65.752,1.13777,0.00696,,,,,0.06895575758,0.006277056277
66.252,1.09607,0.00747,,,,,0.06642848485,0.006737012987
66.752,1.05431,0.00564,,,,,0.06389757576,0.005086580087
67.252,1.01286,0.00423,,,,,0.06138545455,0.003814935065
67.752,0.9708,0.00336,,,,,0.05883636364,0.00303030303
68.252,0.92944,0.00281,,,,,0.05632969697,0.002534271284
68.752,0.88789,0.00194,,,,,0.05381151515,0.00174963925
69.252,0.84587,0.00097,,,,,0.05126484848,0.0008748196248
69.752,0.80447,0.00151,,,,,0.04875575758,0.001361832612
70.252,0.76271,-0.0002,,,,,0.04622484848,-0.0001803751804
70.752,0.72103,-0.00077,,,,,0.04369878788,-0.0006944444444
71.252,0.67959,-0.00196,,,,,0.04118727273,-0.001767676768
71.752,0.63752,-0.00178,,,,,0.03863757576,-0.001605339105
72.252,0.59608,-0.00374,,,,,0.03612606061,-0.003373015873
72.752,0.55469,-0.005,,,,,0.03361757576,-0.004509379509
73.252,0.51237,-0.00247,,,,,0.03105272727,-0.002227633478
73.752,0.47111,-0.00404,,,,,0.02855212121,-0.003643578644
74.252,0.42944,-0.00668,,,,,0.02602666667,-0.006024531025
74.752,0.38767,-0.00825,,,,,0.02349515152,-0.00744047619
75.252,0.3461,-0.00756,,,,,0.02097575758,-0.006818181818
75.752,0.30427,-0.00801,,,,,0.01844060606,-0.007224025974
76.252,0.26276,-0.01021,,,,,0.01592484848,-0.009208152958
76.752,0.22125,-0.00968,,,,,0.01340909091,-0.00873015873
77.252,0.17912,-0.00955,,,,,0.01085575758,-0.008612914863
77.752,0.13785,-0.0098,,,,,0.008354545455,-0.008838383838
78.252,0.09619,-0.01139,,,,,0.00582969697,-0.01027236652
78.752,0.05414,-0.01249,,,,,0.003281212121,-0.01126443001
79.252,0.01289,-0.01505,,,,,0.0007812121212,-0.01357323232
79.508,0.00237,-0.01194,,,,,0.0001436363636,-0.01076839827
80.008,0.04485,-0.0122,,,,,0.002718181818,-0.011002886
80.508,0.08692,-0.01007,,,,,0.005267878788,-0.009081890332
81.008,0.12846,-0.00784,,,,,0.007785454545,-0.007070707071
81.508,0.16999,-0.00937,,,,,0.01030242424,-0.008450577201
82.008,0.21189,-0.00732,,,,,0.01284181818,-0.006601731602
82.508,0.25311,-0.00809,,,,,0.01534,-0.007296176046
83.008,0.2953,-0.00876,,,,,0.0178969697,-0.0079004329
83.508,0.33679,-0.00397,,,,,0.02041151515,-0.00358044733
84.008,0.37814,-0.00238,,,,,0.02291757576,-0.002146464646
84.508,0.42026,-0.00277,,,,,0.02547030303,-0.002498196248
85.008,0.46178,-0.00397,,,,,0.02798666667,-0.00358044733
85.508,0.50318,-0.00472,,,,,0.03049575758,-0.004256854257
86.008,0.54536,-0.00102,,,,,0.03305212121,-0.0009199134199
86.508,0.58661,0.00218,,,,,0.03555212121,0.001966089466
87.008,0.62844,0.00047,,,,,0.03808727273,0.0004238816739
87.508,0.67026,-0.00186,,,,,0.04062181818,-0.001677489177
88.008,0.71148,0.0004,,,,,0.04312,0.0003607503608
88.508,0.75353,0.00348,,,,,0.04566848485,0.003138528139
89.008,0.79517,0.00537,,,,,0.04819212121,0.004843073593
89.508,0.83658,0.00354,,,,,0.05070181818,0.003192640693
90.008,0.87852,0.00243,,,,,0.05324363636,0.002191558442
90.508,0.91999,0.00408,,,,,0.0557569697,0.00367965368
91.008,0.96174,0.00679,,,,,0.05828727273,0.006123737374
91.508,1.00354,0.01072,,,,,0.06082060606,0.009668109668
92.008,1.04473,0.0065,,,,,0.0633169697,0.005862193362
92.508,1.08692,0.00733,,,,,0.06587393939,0.006610750361
93.008,1.12853,0.00371,,,,,0.06839575758,0.003345959596
93.508,1.16976,0.00948,,,,,0.07089454545,0.00854978355
94.008,1.21195,0.01226,,,,,0.07345151515,0.01105699856
94.508,1.25346,0.01218,,,,,0.07596727273,0.01098484848
95.008,1.295,0.0103,,,,,0.07848484848,0.009289321789
95.508,1.33683,0.0094,,,,,0.08102,0.008477633478
96.008,1.37822,0.01573,,,,,0.08352848485,0.01418650794
96.508,1.42019,0.01606,,,,,0.08607212121,0.01448412698
97.008,1.46189,0.01725,,,,,0.08859939394,0.01555735931
97.508,1.50315,0.01301,,,,,0.0911,0.01173340548
98.008,1.54529,0.01295,,,,,0.09365393939,0.01167929293
98.508,1.58678,0.01621,,,,,0.09616848485,0.01461940837
99.008,1.62828,0.02094,,,,,0.09868363636,0.01888528139
99.269,1.65021,0.01804,,,,,0.1000127273,0.01626984127
99.769,1.61268,0.01531,,,,,0.09773818182,0.01380772006
100.269,1.57118,0.01266,,,,,0.0952230303,0.01141774892
100.769,1.52973,0.01562,,,,,0.09271090909,0.01408730159
101.269,1.48749,0.01487,,,,,0.09015090909,0.01341089466
101.769,1.44615,0.01246,,,,,0.08764545455,0.01123737374
102.269,1.40462,0.00708,,,,,0.08512848485,0.006385281385
102.769,1.36255,0.00692,,,,,0.08257878788,0.006240981241
103.269,1.32111,0.00912,,,,,0.08006727273,0.008225108225
103.769,1.2795,0.0083,,,,,0.07754545455,0.007485569986
104.269,1.23765,0.00487,,,,,0.07500909091,0.004392135642
104.769,1.19625,0.00432,,,,,0.0725,0.003896103896
105.269,1.15424,0.00403,,,,,0.06995393939,0.003634559885
105.769,1.11288,0.00314,,,,,0.06744727273,0.002831890332
106.269,1.07123,0.0055,,,,,0.0649230303,0.00496031746
106.769,1.02917,0.00511,,,,,0.06237393939,0.004608585859
107.269,0.98787,0.00079,,,,,0.05987090909,0.0007124819625
107.769,0.94614,0.00002,,,,,0.05734181818,0.00001803751804
108.269,0.90433,0.00044,,,,,0.05480787879,0.0003968253968
108.769,0.86293,0.00022,,,,,0.05229878788,0.0001984126984
109.269,0.8209,-0.00004,,,,,0.04975151515,-0.00003607503608
109.769,0.7794,-0.00095,,,,,0.04723636364,-0.0008567821068
110.269,0.738,-0.00324,,,,,0.04472727273,-0.002922077922
110.769,0.69578,-0.00439,,,,,0.04216848485,-0.003959235209
111.269,0.65445,-0.00572,,,,,0.03966363636,-0.005158730159
111.769,0.61295,-0.00622,,,,,0.03714848485,-0.00560966811
112.269,0.57091,-0.00596,,,,,0.03460060606,-0.005375180375
112.769,0.52943,-0.00629,,,,,0.03208666667,-0.005672799423
113.269,0.48771,-0.00701,,,,,0.02955818182,-0.006322150072
113.769,0.44613,-0.00811,,,,,0.02703818182,-0.007314213564
114.269,0.40463,-0.01028,,,,,0.0245230303,-0.009271284271
114.769,0.36252,-0.00963,,,,,0.02197090909,-0.008685064935
115.269,0.32119,-0.0101,,,,,0.01946606061,-0.009108946609
115.769,0.27956,-0.0105,,,,,0.0169430303,-0.00946969697
116.269,0.2376,-0.01179,,,,,0.0144,-0.01063311688
116.769,0.19621,-0.01396,,,,,0.01189151515,-0.01259018759
117.269,0.15436,-0.01417,,,,,0.009355151515,-0.01277958153
117.769,0.11272,-0.01407,,,,,0.006831515152,-0.01268939394
118.269,0.07133,-0.01378,,,,,0.004323030303,-0.01242784993
118.769,0.02917,-0.01859,,,,,0.001767878788,-0.01676587302
119.124,-0.00011,-0.01549,,,,,-0.000006666666667,-0.01397005772
119.525,0.02861,-0.01441,,,,,0.001733939394,-0.01299603175
120.025,0.06993,-0.01286,,,,,0.004238181818,-0.0115981241
120.525,0.11187,-0.01243,,,,,0.00678,-0.01121031746
121.025,0.15353,-0.01141,,,,,0.009304848485,-0.01029040404
121.525,0.19478,-0.0107,,,,,0.01180484848,-0.00965007215
122.025,0.23696,-0.00911,,,,,0.01436121212,-0.008216089466
122.525,0.27852,-0.01035,,,,,0.01688,-0.009334415584
123.025,0.3199,-0.00939,,,,,0.01938787879,-0.008468614719
123.525,0.36197,-0.00499,,,,,0.02193757576,-0.00450036075
124.025,0.40343,-0.00462,,,,,0.02445030303,-0.004166666667
124.525,0.44514,-0.00632,,,,,0.02697818182,-0.0056998557
125.025,0.48696,-0.00768,,,,,0.02951272727,-0.006926406926
125.525,0.52825,-0.00704,,,,,0.03201515152,-0.006349206349
126.025,0.5703,-0.00346,,,,,0.03456363636,-0.00312049062
126.525,0.61192,-0.00373,,,,,0.03708606061,-0.003363997114
127.025,0.65317,-0.00145,,,,,0.03958606061,-0.001307720058
127.525,0.69531,-0.00208,,,,,0.04214,-0.001875901876
128.025,0.73669,-0.00036,,,,,0.04464787879,-0.0003246753247
128.525,0.77846,0.00068,,,,,0.04717939394,0.0006132756133
129.025,0.82019,0.0005,,,,,0.04970848485,0.0004509379509
129.525,0.86157,-0.00103,,,,,0.05221636364,-0.0009289321789
130.025,0.90363,0.00017,,,,,0.05476545455,0.0001533189033
130.525,0.94529,0.00361,,,,,0.05729030303,0.003255772006
131.025,0.98642,0.0056,,,,,0.0597830303,0.005050505051
131.525,1.02872,0.00486,,,,,0.06234666667,0.004383116883
132.025,1.07025,0.00304,,,,,0.06486363636,0.002741702742
132.525,1.11159,0.00531,,,,,0.06736909091,0.004788961039
133.025,1.15371,0.00644,,,,,0.06992181818,0.005808080808
133.525,1.19497,0.00956,,,,,0.07242242424,0.008621933622
134.025,1.23684,0.00679,,,,,0.07496,0.006123737374
134.525,1.27856,0.01033,,,,,0.07748848485,0.009316378066
135.025,1.31991,0.00926,,,,,0.07999454545,0.008351370851
135.525,1.36189,0.00897,,,,,0.08253878788,0.00808982684
136.025,1.40355,0.01148,,,,,0.08506363636,0.01035353535
136.525,1.44493,0.01119,,,,,0.08757151515,0.01009199134
137.025,1.487,0.01303,,,,,0.09012121212,0.011751443
137.525,1.52832,0.01427,,,,,0.09262545455,0.01286976912
138.025,1.5702,0.0149,,,,,0.09516363636,0.01343795094
138.525,1.61195,0.01516,,,,,0.09769393939,0.01367243867
138.983,1.65004,0.01426,,,,,0.1000024242,0.01286075036
139.285,1.62961,0.01326,,,,,0.09876424242,0.01195887446
139.785,1.58794,0.01162,,,,,0.09623878788,0.01047979798
140.285,1.54581,0.01273,,,,,0.09368545455,0.01148088023
140.785,1.50448,0.01196,,,,,0.09118060606,0.01078643579
141.285,1.46281,0.01016,,,,,0.08865515152,0.009163059163
141.785,1.42094,0.00729,,,,,0.08611757576,0.006574675325
142.285,1.37952,0.00697,,,,,0.08360727273,0.006286075036
142.785,1.33768,0.0071,,,,,0.08107151515,0.006403318903
143.285,1.29606,0.00572,,,,,0.07854909091,0.005158730159
143.785,1.25463,0.0043,,,,,0.07603818182,0.003878066378
144.285,1.21251,0.00578,,,,,0.07348545455,0.005212842713
144.785,1.17117,0.00622,,,,,0.07098,0.00560966811
145.285,1.12951,0.00421,,,,,0.06845515152,0.003796897547
145.785,1.08764,0.00202,,,,,0.06591757576,0.001821789322
146.285,1.04618,-0.00138,,,,,0.06340484848,-0.001244588745
146.785,1.00428,-0.00088,,,,,0.06086545455,-0.0007936507937
147.285,0.96274,0.00009,,,,,0.05834787879,0.00008116883117
147.785,0.92128,-0.00091,,,,,0.05583515152,-0.0008207070707
148.285,0.87917,0.00113,,,,,0.0532830303,0.001019119769
148.785,0.83778,-0.00302,,,,,0.05077454545,-0.002723665224
149.285,0.79633,-0.00485,,,,,0.04826242424,-0.004374098124
149.785,0.75414,-0.00458,,,,,0.04570545455,-0.004130591631
150.285,0.71286,-0.00574,,,,,0.04320363636,-0.005176767677
150.785,0.67106,-0.00721,,,,,0.04067030303,-0.006502525253
151.285,0.62945,-0.00587,,,,,0.03814848485,-0.005294011544
151.785,0.58787,-0.0059,,,,,0.03562848485,-0.005321067821
152.285,0.5459,-0.00718,,,,,0.03308484848,-0.006475468975
152.785,0.50452,-0.0082,,,,,0.0305769697,-0.007395382395
153.285,0.46293,-0.01213,,,,,0.02805636364,-0.01093975469
153.785,0.4208,-0.01208,,,,,0.0255030303,-0.01089466089
154.285,0.37949,-0.01207,,,,,0.02299939394,-0.01088564214
154.785,0.33778,-0.01132,,,,,0.02047151515,-0.01020923521
155.285,0.2959,-0.01306,,,,,0.01793333333,-0.01177849928
155.785,0.25462,-0.01049,,,,,0.01543151515,-0.009460678211
156.285,0.21251,-0.01498,,,,,0.01287939394,-0.01351010101
156.785,0.17105,-0.01622,,,,,0.01036666667,-0.01462842713
157.285,0.12962,-0.01568,,,,,0.007855757576,-0.01414141414
157.785,0.08752,-0.01702,,,,,0.005304242424,-0.01534992785
158.285,0.04607,-0.01638,,,,,0.002792121212,-0.01477272727
158.785,0.00456,-0.0172,,,,,0.0002763636364,-0.01551226551
159.041,0.01118,-0.01702,,,,,0.0006775757576,-0.01534992785
159.541,0.05364,-0.01429,,,,,0.003250909091,-0.01288780664
160.041,0.09512,-0.01804,,,,,0.005764848485,-0.01626984127
160.541,0.13653,-0.01584,,,,,0.008274545455,-0.01428571429
161.041,0.17863,-0.01492,,,,,0.01082606061,-0.01345598846
161.541,0.22007,-0.01202,,,,,0.01333757576,-0.01084054834
162.041,0.26164,-0.011,,,,,0.0158569697,-0.009920634921
162.541,0.30366,-0.00909,,,,,0.01840363636,-0.008198051948
163.041,0.34485,-0.00576,,,,,0.0209,-0.005194805195
163.541,0.38685,-0.01196,,,,,0.02344545455,-0.01078643579
164.041,0.42859,-0.00919,,,,,0.02597515152,-0.008288239538
164.541,0.46983,-0.00672,,,,,0.02847454545,-0.006060606061
165.041,0.51187,-0.00591,,,,,0.03102242424,-0.00533008658
165.541,0.55344,-0.00384,,,,,0.03354181818,-0.003463203463
166.041,0.59498,-0.00682,,,,,0.03605939394,-0.006150793651
166.541,0.63685,-0.00219,,,,,0.0385969697,-0.001975108225
167.041,0.67823,-0.00264,,,,,0.04110484848,-0.002380952381
167.541,0.72016,-0.00221,,,,,0.04364606061,-0.001993145743
168.041,0.76189,-0.00499,,,,,0.04617515152,-0.00450036075
168.541,0.80313,0.00094,,,,,0.04867454545,0.0008477633478
169.041,0.84529,0.00051,,,,,0.05122969697,0.00045995671
169.541,0.88686,0.00139,,,,,0.05374909091,0.001253607504
170.041,0.92821,0.00378,,,,,0.05625515152,0.003409090909
170.541,0.97029,0.00018,,,,,0.05880545455,0.0001623376623
171.041,1.01168,0.00154,,,,,0.06131393939,0.001388888889
171.541,1.05346,0.00191,,,,,0.06384606061,0.001722582973
172.041,1.09515,0.00286,,,,,0.06637272727,0.002579365079
172.541,1.13648,0.00585,,,,,0.06887757576,0.005275974026
173.041,1.17856,0.00488,,,,,0.07142787879,0.004401154401
173.541,1.22016,0.00746,,,,,0.07394909091,0.006727994228
174.041,1.26153,0.01146,,,,,0.07645636364,0.01033549784
174.541,1.30357,0.00877,,,,,0.07900424242,0.007909451659
175.041,1.34507,0.0098,,,,,0.08151939394,0.008838383838
175.541,1.38675,0.00848,,,,,0.08404545455,0.007647907648
176.041,1.42862,0.0086,,,,,0.0865830303,0.007756132756
176.541,1.46979,0.00978,,,,,0.08907818182,0.00882034632
177.041,1.51195,0.01373,,,,,0.09163333333,0.01238275613
177.541,1.55363,0.01343,,,,,0.09415939394,0.01211219336
178.041,1.59476,0.01352,,,,,0.09665212121,0.01219336219
178.541,1.63695,0.01515,,,,,0.09920909091,0.01366341991
178.801,1.64694,0.01402,,,,,0.09981454545,0.01264430014
179.301,1.60425,0.01401,,,,,0.09722727273,0.01263528139
179.801,1.5628,0.01135,,,,,0.09471515152,0.01023629149
180.301,1.52104,0.00611,,,,,0.09218424242,0.00551046176
180.801,1.47939,0.01285,,,,,0.08966,0.01158910534
181.301,1.43793,0.00721,,,,,0.08714727273,0.006502525253
181.801,1.39586,0.00692,,,,,0.08459757576,0.006240981241
182.301,1.35451,0.00439,,,,,0.08209151515,0.003959235209
182.801,1.31284,0.00341,,,,,0.07956606061,0.003075396825
183.301,1.27086,0.00357,,,,,0.07702181818,0.00321969697
183.801,1.22948,0.0045,,,,,0.07451393939,0.004058441558
184.301,1.18767,0.00181,,,,,0.07198,0.001632395382
184.801,1.14604,0.00068,,,,,0.0694569697,0.0006132756133
185.301,1.1046,-0.00189,,,,,0.06694545455,-0.001704545455
185.801,1.06245,-0.00134,,,,,0.06439090909,-0.001208513709
186.301,1.02111,0.00062,,,,,0.06188545455,0.0005591630592
186.801,0.97965,-0.00505,,,,,0.05937272727,-0.004554473304
187.301,0.93746,-0.0026,,,,,0.05681575758,-0.002344877345
187.801,0.89611,-0.00431,,,,,0.05430969697,-0.003887085137
188.301,0.85453,-0.0054,,,,,0.05178969697,-0.00487012987
188.801,0.81263,-0.00777,,,,,0.04925030303,-0.007007575758
189.301,0.77117,-0.00694,,,,,0.04673757576,-0.006259018759
189.801,0.72925,-0.00665,,,,,0.0441969697,-0.005997474747
190.301,0.68775,-0.00846,,,,,0.04168181818,-0.00762987013
190.801,0.64626,-0.01623,,,,,0.03916727273,-0.01463744589
191.301,0.60416,-0.01177,,,,,0.03661575758,-0.01061507937
191.801,0.56279,-0.01322,,,,,0.03410848485,-0.01192279942
192.301,0.5211,-0.01096,,,,,0.03158181818,-0.009884559885
192.801,0.47927,-0.01285,,,,,0.02904666667,-0.01158910534
193.301,0.43786,-0.01229,,,,,0.0265369697,-0.01108405483
193.801,0.39594,-0.01378,,,,,0.02399636364,-0.01242784993
194.301,0.3544,-0.01468,,,,,0.02147878788,-0.01323953824
194.801,0.31307,-0.01334,,,,,0.01897393939,-0.01203102453
195.301,0.27079,-0.01355,,,,,0.01641151515,-0.01222041847
195.801,0.22948,-0.01592,,,,,0.01390787879,-0.01435786436
196.301,0.18791,-0.01714,,,,,0.01138848485,-0.01545815296
196.801,0.14597,-0.01675,,,,,0.008846666667,-0.01510642136
197.301,0.10444,-0.01689,,,,,0.00632969697,-0.01523268398
197.801,0.06273,-0.01705,,,,,0.003801818182,-0.01537698413
198.301,0.02103,-0.01767,,,,,0.001274545455,-0.01593614719
198.557,-0.00021,-0.01861,,,,,-0.00001272727273,-0.01678391053
199.057,0.0368,-0.017,,,,,0.00223030303,-0.01533189033
199.557,0.07835,-0.01615,,,,,0.004748484848,-0.01456529582
200.057,0.12023,-0.01446,,,,,0.007286666667,-0.01304112554
200.557,0.16162,-0.01463,,,,,0.009795151515,-0.01319444444
201.057,0.2035,-0.01612,,,,,0.01233333333,-0.01453823954
201.557,0.24521,-0.01502,,,,,0.01486121212,-0.01354617605
202.057,0.28649,-0.0103,,,,,0.0173630303,-0.009289321789
202.557,0.32856,-0.01035,,,,,0.01991272727,-0.009334415584
203.057,0.37018,-0.01017,,,,,0.02243515152,-0.009172077922
203.557,0.41153,-0.00927,,,,,0.02494121212,-0.00836038961
204.057,0.45359,-0.00904,,,,,0.02749030303,-0.008152958153
204.557,0.49489,-0.00609,,,,,0.02999333333,-0.005492424242
205.057,0.53687,-0.00679,,,,,0.03253757576,-0.006123737374
205.557,0.57848,-0.00469,,,,,0.03505939394,-0.00422979798
206.057,0.61985,-0.007,,,,,0.03756666667,-0.006313131313
206.557,0.66195,-0.00702,,,,,0.04011818182,-0.006331168831
207.057,0.70356,-0.00238,,,,,0.04264,-0.002146464646
207.557,0.74478,-0.00261,,,,,0.04513818182,-0.002353896104
208.057,0.78706,-0.0044,,,,,0.04770060606,-0.003968253968
208.557,0.82838,-0.00246,,,,,0.05020484848,-0.002218614719
209.057,0.86998,-0.00303,,,,,0.05272606061,-0.002732683983
209.557,0.91195,-0.00182,,,,,0.05526969697,-0.001641414141
210.057,0.95316,-0.00433,,,,,0.05776727273,-0.003905122655
210.557,0.99516,0.0019,,,,,0.06031272727,0.001713564214
211.057,1.03683,0.0013,,,,,0.06283818182,0.001172438672
211.557,1.07819,0.00495,,,,,0.06534484848,0.004464285714
212.057,1.12018,0.0029,,,,,0.06788969697,0.002615440115
212.557,1.16181,0.00425,,,,,0.07041272727,0.003832972583
213.057,1.20329,0.00442,,,,,0.07292666667,0.003986291486
213.557,1.24529,0.00592,,,,,0.07547212121,0.005339105339
214.057,1.28653,0.00555,,,,,0.07797151515,0.005005411255
214.557,1.32857,0.00493,,,,,0.08051939394,0.004446248196
215.057,1.37022,0.00836,,,,,0.08304363636,0.00753968254
215.557,1.4114,0.01088,,,,,0.08553939394,0.009812409812
216.057,1.45363,0.00942,,,,,0.08809878788,0.008495670996
216.557,1.49517,0.00823,,,,,0.09061636364,0.007422438672
217.057,1.53651,0.00914,,,,,0.09312181818,0.008243145743
217.557,1.57849,0.01046,,,,,0.09566606061,0.009433621934
218.057,1.62001,0.01314,,,,,0.09818242424,0.01185064935
218.417,1.65014,0.01278,,,,,0.1000084848,0.01152597403
218.818,1.62144,0.01064,,,,,0.09826909091,0.009595959596
219.318,1.57937,0.00903,,,,,0.09571939394,0.008143939394
219.818,1.53784,0.01041,,,,,0.09320242424,0.009388528139
220.318,1.49639,0.00978,,,,,0.09069030303,0.00882034632
220.818,1.45429,0.00837,,,,,0.08813878788,0.007548701299
221.318,1.41298,0.00619,,,,,0.08563515152,0.005582611833
221.818,1.37119,0.0042,,,,,0.08310242424,0.003787878788
222.318,1.32952,0.00513,,,,,0.0805769697,0.004626623377
222.818,1.28807,0.00366,,,,,0.07806484848,0.003300865801
223.318,1.24598,0.00188,,,,,0.07551393939,0.001695526696
223.818,1.20461,0.00048,,,,,0.07300666667,0.0004329004329
224.318,1.16309,-0.00081,,,,,0.07049030303,-0.0007305194805
224.818,1.12094,-0.00015,,,,,0.06793575758,-0.0001352813853
225.318,1.0796,-0.00089,,,,,0.06543030303,-0.0008026695527
225.818,1.03809,-0.0023,,,,,0.06291454545,-0.002074314574
226.318,0.99607,-0.00357,,,,,0.06036787879,-0.00321969697
226.818,0.95467,-0.00351,,,,,0.05785878788,-0.003165584416
227.318,0.91273,-0.00386,,,,,0.0553169697,-0.003481240981
227.818,0.87131,-0.00487,,,,,0.05280666667,-0.004392135642
228.318,0.82965,-0.00582,,,,,0.05028181818,-0.005248917749
228.818,0.78758,-0.00692,,,,,0.04773212121,-0.006240981241
229.318,0.74628,-0.00898,,,,,0.04522909091,-0.008098845599
229.818,0.70461,-0.00919,,,,,0.04270363636,-0.008288239538
230.318,0.66269,-0.00859,,,,,0.0401630303,-0.007747113997
230.818,0.62133,-0.0097,,,,,0.03765636364,-0.008748196248
231.318,0.57944,-0.01024,,,,,0.03511757576,-0.009235209235
231.818,0.53782,-0.01209,,,,,0.03259515152,-0.01090367965
232.318,0.49649,-0.01241,,,,,0.03009030303,-0.01119227994
232.818,0.45425,-0.01246,,,,,0.02753030303,-0.01123737374
233.318,0.41293,-0.01299,,,,,0.02502606061,-0.01171536797
233.818,0.37141,-0.01611,,,,,0.02250969697,-0.01452922078
234.318,0.32929,-0.01512,,,,,0.0199569697,-0.01363636364
234.818,0.28783,-0.01501,,,,,0.01744424242,-0.01353715729
235.318,0.24624,-0.01558,,,,,0.01492363636,-0.01405122655
235.818,0.2045,-0.01715,,,,,0.01239393939,-0.01546717172
236.318,0.16303,-0.01887,,,,,0.009880606061,-0.01701839827
236.818,0.12101,-0.01879,,,,,0.007333939394,-0.0169462482
237.318,0.0796,-0.02016,,,,,0.004824242424,-0.01818181818
237.818,0.03801,-0.02027,,,,,0.002303636364,-0.01828102453
238.274,-0.00007,-0.02047,,,,,-0.000004242424242,-0.01846139971
238.576,0.01992,-0.02059,,,,,0.001207272727,-0.01856962482
239.076,0.06188,-0.0196,,,,,0.00375030303,-0.01767676768
239.576,0.10304,-0.01771,,,,,0.006244848485,-0.01597222222
240.076,0.14512,-0.01739,,,,,0.008795151515,-0.01568362193
240.576,0.18683,-0.01583,,,,,0.0113230303,-0.01427669553
241.076,0.22817,-0.01568,,,,,0.01382848485,-0.01414141414
241.576,0.2702,-0.01552,,,,,0.01637575758,-0.013997114
242.076,0.31163,-0.01279,,,,,0.01888666667,-0.01153499278
242.576,0.35341,-0.01136,,,,,0.02141878788,-0.01024531025
243.076,0.3951,-0.01272,,,,,0.02394545455,-0.01147186147
243.576,0.43642,-0.01069,,,,,0.02644969697,-0.009641053391
244.076,0.47852,-0.01114,,,,,0.02900121212,-0.01004689755
244.576,0.52016,-0.00884,,,,,0.03152484848,-0.007972582973
245.076,0.5614,-0.00621,,,,,0.03402424242,-0.005600649351
245.576,0.60354,-0.00256,,,,,0.03657818182,-0.002308802309
246.076,0.64504,-0.00897,,,,,0.03909333333,-0.00808982684
246.576,0.68658,-0.00743,,,,,0.04161090909,-0.006700937951
247.076,0.72852,-0.00662,,,,,0.04415272727,-0.00597041847
247.576,0.76986,-0.00539,,,,,0.04665818182,-0.004861111111
248.076,0.81183,-0.00352,,,,,0.04920181818,-0.003174603175
248.576,0.85348,-0.00237,,,,,0.05172606061,-0.002137445887
249.076,0.89477,-0.00057,,,,,0.05422848485,-0.0005140692641
249.576,0.9369,-0.00295,,,,,0.05678181818,-0.002660533911
250.076,0.97838,0.00072,,,,,0.05929575758,0.0006493506494
250.576,1.01994,0.00082,,,,,0.06181454545,0.0007395382395
251.076,1.06184,0.00142,,,,,0.06435393939,0.001280663781
251.576,1.10325,0.00086,,,,,0.06686363636,0.0007756132756
252.076,1.14515,0.00224,,,,,0.0694030303,0.00202020202
252.576,1.18685,0.00254,,,,,0.07193030303,0.002290764791
253.076,1.22798,0.00385,,,,,0.0744230303,0.003472222222
253.576,1.27026,0.00401,,,,,0.07698545455,0.003616522367
254.076,1.31186,0.00629,,,,,0.07950666667,0.005672799423
254.576,1.35307,0.00687,,,,,0.08200424242,0.006195887446
255.076,1.39525,0.00689,,,,,0.08456060606,0.006213924964
255.576,1.43666,0.00692,,,,,0.08707030303,0.006240981241
256.076,1.47832,0.00849,,,,,0.08959515152,0.007656926407
256.576,1.52012,0.01058,,,,,0.09212848485,0.009541847042
257.076,1.56152,0.01163,,,,,0.09463757576,0.01048881674
257.576,1.60346,0.01056,,,,,0.09717939394,0.009523809524
258.076,1.64515,0.00945,,,,,0.09970606061,0.008522727273
258.337,1.63797,0.01251,,,,,0.09927090909,0.01128246753
258.837,1.59626,0.00945,,,,,0.0967430303,0.008522727273
259.337,1.55456,0.00733,,,,,0.09421575758,0.006610750361
259.837,1.51276,0.00659,,,,,0.09168242424,0.005943362193
260.337,1.47138,0.01031,,,,,0.08917454545,0.009298340548
260.837,1.42932,0.00777,,,,,0.08662545455,0.007007575758
261.337,1.38794,0.003,,,,,0.08411757576,0.002705627706
261.837,1.34645,0.00189,,,,,0.0816030303,0.001704545455
262.337,1.30422,0.00177,,,,,0.07904363636,0.001596320346
262.837,1.26295,0.00188,,,,,0.07654242424,0.001695526696
263.337,1.22133,0.002,,,,,0.07402,0.001803751804
263.837,1.17934,0.00285,,,,,0.07147515152,0.00257034632
264.337,1.13792,0.00111,,,,,0.06896484848,0.001001082251
264.837,1.09618,-0.00254,,,,,0.06643515152,-0.002290764791
265.337,1.05446,-0.00472,,,,,0.06390666667,-0.004256854257
265.837,1.01303,-0.00325,,,,,0.06139575758,-0.002931096681
266.337,0.97095,-0.0042,,,,,0.05884545455,-0.003787878788
266.837,0.92959,-0.00476,,,,,0.05633878788,-0.004292929293
267.337,0.88802,-0.00653,,,,,0.05381939394,-0.005889249639
267.837,0.84605,-0.00571,,,,,0.05127575758,-0.0051497114
268.337,0.80466,-0.00688,,,,,0.04876727273,-0.006204906205
268.837,0.76283,-0.00531,,,,,0.04623212121,-0.004788961039
269.337,0.7212,-0.00886,,,,,0.04370909091,-0.007990620491
269.837,0.67976,-0.0099,,,,,0.04119757576,-0.008928571429
270.337,0.63767,-0.0119,,,,,0.03864666667,-0.01073232323
270.837,0.59626,-0.01247,,,,,0.0361369697,-0.0112463925
271.337,0.55484,-0.01211,,,,,0.03362666667,-0.01092171717
271.837,0.51254,-0.01235,,,,,0.0310630303,-0.01113816739
272.337,0.47129,-0.01331,,,,,0.0285630303,-0.01200396825
272.837,0.42958,-0.01455,,,,,0.02603515152,-0.01312229437
273.337,0.38787,-0.01744,,,,,0.02350727273,-0.01572871573
273.837,0.34626,-0.01532,,,,,0.02098545455,-0.01381673882
274.337,0.30439,-0.01523,,,,,0.01844787879,-0.01373556999
274.837,0.26292,-0.01647,,,,,0.01593454545,-0.0148538961
275.337,0.22142,-0.01977,,,,,0.01341939394,-0.01783008658
275.837,0.17928,-0.02124,,,,,0.01086545455,-0.01915584416
276.337,0.138,-0.0194,,,,,0.008363636364,-0.0174963925
276.837,0.09633,-0.0195,,,,,0.005838181818,-0.01758658009
277.337,0.05435,-0.02036,,,,,0.003293939394,-0.01836219336
277.837,0.01308,-0.02166,,,,,0.0007927272727,-0.01953463203
278.095,0.0023,-0.02165,,,,,0.0001393939394,-0.01952561328
278.595,0.04477,-0.01819,,,,,0.002713333333,-0.01640512266
279.095,0.08684,-0.01846,,,,,0.005263030303,-0.01664862915
279.595,0.12836,-0.01717,,,,,0.007779393939,-0.01548520924
280.095,0.16994,-0.01884,,,,,0.01029939394,-0.01699134199
280.595,0.21182,-0.01788,,,,,0.01283757576,-0.01612554113
281.095,0.25304,-0.01295,,,,,0.01533575758,-0.01167929293
281.595,0.29524,-0.01457,,,,,0.01789333333,-0.01314033189
282.095,0.33675,-0.01281,,,,,0.02040909091,-0.0115530303
282.595,0.37809,-0.01279,,,,,0.02291454545,-0.01153499278
283.095,0.42017,-0.01273,,,,,0.02546484848,-0.01148088023
283.595,0.46172,-0.01263,,,,,0.0279830303,-0.01139069264
284.095,0.50314,-0.01075,,,,,0.03049333333,-0.009695165945
284.595,0.54528,-0.00751,,,,,0.03304727273,-0.006773088023
285.095,0.58651,-0.00792,,,,,0.03554606061,-0.007142857143
285.595,0.62837,-0.00892,,,,,0.0380830303,-0.008044733045
286.095,0.67019,-0.00753,,,,,0.04061757576,-0.006791125541
286.595,0.71141,-0.00605,,,,,0.04311575758,-0.005456349206
287.095,0.75346,-0.00562,,,,,0.04566424242,-0.005068542569
287.595,0.79509,-0.00419,,,,,0.04818727273,-0.003778860029
288.095,0.83652,-0.00113,,,,,0.05069818182,-0.001019119769
288.595,0.87844,-0.00215,,,,,0.05323878788,-0.001939033189
289.095,0.91993,-0.00425,,,,,0.05575333333,-0.003832972583
289.595,0.9617,-0.00211,,,,,0.05828484848,-0.001902958153
290.095,1.00349,-0.0004,,,,,0.06081757576,-0.0003607503608
290.595,1.04468,0.00033,,,,,0.06331393939,0.0002976190476
291.095,1.08686,0.00291,,,,,0.06587030303,0.002624458874
291.595,1.12845,0.00089,,,,,0.06839090909,0.0008026695527
292.095,1.16969,0.00218,,,,,0.07089030303,0.001966089466
292.595,1.21193,0.00243,,,,,0.07345030303,0.002191558442
293.095,1.25336,0.00521,,,,,0.07596121212,0.004698773449
293.595,1.29493,0.00573,,,,,0.07848060606,0.005167748918
294.095,1.33677,0.00549,,,,,0.08101636364,0.004951298701
294.595,1.37812,0.0066,,,,,0.08352242424,0.005952380952
295.095,1.42011,0.00618,,,,,0.08606727273,0.005573593074
295.595,1.46182,0.00833,,,,,0.08859515152,0.007512626263
296.095,1.5031,0.0085,,,,,0.0910969697,0.007665945166
296.595,1.5452,0.00982,,,,,0.09364848485,0.008856421356
297.095,1.5867,0.01069,,,,,0.09616363636,0.009641053391
297.595,1.62825,0.01091,,,,,0.09868181818,0.009839466089
297.857,1.65021,0.0095,,,,,0.1000127273,0.008567821068
298.357,1.61285,0.00994,,,,,0.09774848485,0.008964646465
298.857,1.57138,0.00939,,,,,0.09523515152,0.008468614719
299.357,1.52992,0.00542,,,,,0.09272242424,0.004888167388
299.857,1.48771,0.00751,,,,,0.09016424242,0.006773088023
300.357,1.44636,0.0045,,,,,0.08765818182,0.004058441558
300.857,1.40481,0.00267,,,,,0.08514,0.002408008658
301.357,1.36274,0.00429,,,,,0.08259030303,0.003869047619
301.857,1.32132,0.00245,,,,,0.08008,0.00220959596
302.357,1.27968,0.00211,,,,,0.07755636364,0.001902958153
302.857,1.23784,-0.00365,,,,,0.07502060606,-0.003291847042
303.357,1.19645,-0.00151,,,,,0.07251212121,-0.001361832612
303.857,1.15443,-0.00052,,,,,0.06996545455,-0.000468975469
304.357,1.11307,-0.00184,,,,,0.06745878788,-0.001659451659
304.857,1.07142,-0.003,,,,,0.06493454545,-0.002705627706
305.357,1.02939,-0.00393,,,,,0.06238727273,-0.003544372294
305.857,0.98804,-0.00566,,,,,0.05988121212,-0.005104617605
306.357,0.9463,-0.00616,,,,,0.05735151515,-0.005555555556
306.857,0.90459,-0.00729,,,,,0.05482363636,-0.006574675325
307.357,0.86317,-0.00727,,,,,0.05231333333,-0.006556637807
307.857,0.82107,-0.00702,,,,,0.04976181818,-0.006331168831
308.357,0.77961,-0.00846,,,,,0.04724909091,-0.00762987013
308.857,0.73819,-0.01178,,,,,0.04473878788,-0.01062409812
309.357,0.69596,-0.01167,,,,,0.04217939394,-0.01052489177
309.857,0.65464,-0.01056,,,,,0.03967515152,-0.009523809524
310.357,0.61311,-0.01138,,,,,0.03715818182,-0.01026334776
310.857,0.57114,-0.01263,,,,,0.03461454545,-0.01139069264
311.357,0.52966,-0.01453,,,,,0.03210060606,-0.01310425685
311.857,0.48785,-0.01559,,,,,0.02956666667,-0.01406024531
312.357,0.44634,-0.01475,,,,,0.02705090909,-0.01330266955
312.857,0.40484,-0.01639,,,,,0.02453575758,-0.01478174603
313.357,0.36272,-0.0158,,,,,0.0219830303,-0.01424963925
313.857,0.32139,-0.01768,,,,,0.01947818182,-0.01594516595
314.357,0.27976,-0.0192,,,,,0.01695515152,-0.01731601732
314.857,0.23782,-0.02295,,,,,0.01441333333,-0.02069805195
315.357,0.19641,-0.01845,,,,,0.01190363636,-0.01663961039
315.857,0.15455,-0.01708,,,,,0.009366666667,-0.0154040404
316.357,0.11295,-0.02087,,,,,0.006845454545,-0.01882215007
316.857,0.07156,-0.02089,,,,,0.004336969697,-0.01884018759
317.357,0.02936,-0.02206,,,,,0.001779393939,-0.0198953824
317.715,-0.00015,-0.02102,,,,,-0.000009090909091,-0.01895743146
318.116,0.02852,-0.02025,,,,,0.001728484848,-0.01826298701
318.616,0.06983,-0.01902,,,,,0.004232121212,-0.01715367965
319.116,0.11181,-0.02188,,,,,0.006776363636,-0.01973304473
319.616,0.15345,-0.01882,,,,,0.0093,-0.01697330447
320.116,0.19465,-0.02078,,,,,0.0117969697,-0.01874098124
320.616,0.23691,-0.0133,,,,,0.01435818182,-0.01199494949
321.116,0.27846,-0.01523,,,,,0.01687636364,-0.01373556999
321.616,0.31983,-0.01095,,,,,0.01938363636,-0.009875541126
322.116,0.36188,-0.01573,,,,,0.02193212121,-0.01418650794
322.616,0.40335,-0.01516,,,,,0.02444545455,-0.01367243867
323.116,0.44507,-0.01459,,,,,0.02697393939,-0.01315836941
323.616,0.48688,-0.01246,,,,,0.02950787879,-0.01123737374
324.116,0.52817,-0.01071,,,,,0.03201030303,-0.009659090909
324.616,0.57024,-0.00897,,,,,0.03456,-0.00808982684
325.116,0.61184,-0.00937,,,,,0.03708121212,-0.008450577201
325.616,0.65313,-0.00982,,,,,0.03958363636,-0.008856421356
326.116,0.69518,-0.00784,,,,,0.04213212121,-0.007070707071
326.616,0.73664,-0.00804,,,,,0.04464484848,-0.007251082251
327.116,0.77842,-0.00575,,,,,0.0471769697,-0.005185786436
327.616,0.82013,-0.00397,,,,,0.04970484848,-0.00358044733
328.116,0.86152,-0.00212,,,,,0.05221333333,-0.001911976912
328.616,0.90356,-0.00464,,,,,0.05476121212,-0.004184704185
329.116,0.94517,-0.003,,,,,0.0572830303,-0.002705627706
329.616,0.98636,-0.00235,,,,,0.05977939394,-0.002119408369
330.116,1.02867,-0.00071,,,,,0.06234363636,-0.0006403318903
330.616,1.07015,-0.0019,,,,,0.06485757576,-0.001713564214
331.116,1.11153,0.00188,,,,,0.06736545455,0.001695526696
331.616,1.15364,0.00139,,,,,0.06991757576,0.001253607504
332.116,1.19485,0.00361,,,,,0.07241515152,0.003255772006
332.616,1.23677,0.00393,,,,,0.07495575758,0.003544372294
333.116,1.27852,0.00389,,,,,0.07748606061,0.003508297258
333.616,1.31984,0.00223,,,,,0.07999030303,0.002011183261
334.116,1.3618,0.00305,,,,,0.08253333333,0.002750721501
334.616,1.4035,0.00268,,,,,0.08506060606,0.002417027417
335.116,1.44481,0.00607,,,,,0.08756424242,0.005474386724
335.616,1.48691,0.00641,,,,,0.09011575758,0.005781024531
336.116,1.52823,0.00908,,,,,0.09262,0.008189033189
336.616,1.57015,0.01099,,,,,0.09516060606,0.009911616162
337.116,1.61187,0.00902,,,,,0.09768909091,0.008134920635
337.575,1.65003,0.00804,,,,,0.1000018182,0.007251082251
337.877,1.62988,0.00973,,,,,0.09878060606,0.008775252525
338.377,1.58817,0.00721,,,,,0.09625272727,0.006502525253
338.877,1.54609,0.00654,,,,,0.09370242424,0.005898268398
339.377,1.50476,0.00397,,,,,0.09119757576,0.00358044733
339.877,1.46303,0.00306,,,,,0.08866848485,0.00275974026
340.377,1.42125,0.00304,,,,,0.08613636364,0.002741702742
340.877,1.37979,0.00163,,,,,0.08362363636,0.00147005772
341.377,1.33794,0.00293,,,,,0.08108727273,0.002642496392
341.877,1.2963,0.00164,,,,,0.07856363636,0.001479076479
342.377,1.25488,-0.00125,,,,,0.07605333333,-0.001127344877
342.877,1.21276,-0.00158,,,,,0.07350060606,-0.001424963925
343.377,1.17143,-0.00154,,,,,0.07099575758,-0.001388888889
343.877,1.12973,-0.00288,,,,,0.06846848485,-0.002597402597
344.377,1.08794,-0.00482,,,,,0.06593575758,-0.004347041847
344.877,1.04646,-0.00525,,,,,0.06342181818,-0.004734848485
345.377,1.00451,-0.00557,,,,,0.06087939394,-0.005023448773
345.877,0.96301,-0.0077,,,,,0.05836424242,-0.006944444444
346.377,0.92155,-0.0081,,,,,0.05585151515,-0.007305194805
346.877,0.87941,-0.00881,,,,,0.05329757576,-0.007945526696
347.377,0.83802,-0.00848,,,,,0.05078909091,-0.007647907648
347.877,0.79656,-0.01118,,,,,0.04827636364,-0.01008297258
348.377,0.75445,-0.01177,,,,,0.04572424242,-0.01061507937
348.877,0.71312,-0.01081,,,,,0.04321939394,-0.009749278499
349.377,0.6713,-0.01178,,,,,0.04068484848,-0.01062409812
349.877,0.62975,-0.01176,,,,,0.03816666667,-0.01060606061
350.377,0.58813,-0.01261,,,,,0.03564424242,-0.01137265512
350.877,0.54614,-0.0155,,,,,0.03309939394,-0.01397907648
351.377,0.50478,-0.01347,,,,,0.03059272727,-0.0121482684
351.877,0.46317,-0.01696,,,,,0.02807090909,-0.0152958153
352.377,0.42107,-0.0173,,,,,0.02551939394,-0.0156024531
352.877,0.37975,-0.01709,,,,,0.02301515152,-0.01541305916
353.377,0.338,-0.01768,,,,,0.02048484848,-0.01594516595
353.877,0.29618,-0.01943,,,,,0.01795030303,-0.01752344877
354.377,0.2549,-0.01879,,,,,0.01544848485,-0.0169462482
354.877,0.21276,-0.02055,,,,,0.01289454545,-0.01853354978
355.377,0.17133,-0.02059,,,,,0.01038363636,-0.01856962482
355.877,0.12989,-0.02118,,,,,0.007872121212,-0.0191017316
356.377,0.08777,-0.02157,,,,,0.005319393939,-0.0194534632
356.877,0.04634,-0.02307,,,,,0.002808484848,-0.02080627706
357.377,0.00478,-0.02512,,,,,0.0002896969697,-0.02265512266
357.636,0.01119,-0.02278,,,,,0.0006781818182,-0.02054473304
358.136,0.05365,-0.02175,,,,,0.003251515152,-0.01961580087
358.636,0.0951,-0.01961,,,,,0.005763636364,-0.01768578644
359.136,0.13653,-0.02074,,,,,0.008274545455,-0.0187049062
359.636,0.1786,-0.0188,,,,,0.01082424242,-0.01695526696
360.136,0.22007,-0.01849,,,,,0.01333757576,-0.01667568543
360.636,0.26163,-0.01785,,,,,0.01585636364,-0.01609848485
361.136,0.30366,-0.01447,,,,,0.01840363636,-0.0130501443
361.636,0.34485,-0.01471,,,,,0.0209,-0.01326659452
362.136,0.38685,-0.01586,,,,,0.02344545455,-0.0143037518
362.636,0.42857,-0.01526,,,,,0.02597393939,-0.01376262626
363.136,0.46981,-0.01341,,,,,0.02847333333,-0.01209415584
363.636,0.51184,-0.01143,,,,,0.03102060606,-0.01030844156
364.136,0.55344,-0.01186,,,,,0.03354181818,-0.0106962482
364.636,0.59499,-0.01218,,,,,0.03606,-0.01098484848
365.136,0.63685,-0.0104,,,,,0.0385969697,-0.00937950938
365.636,0.67822,-0.00903,,,,,0.04110424242,-0.008143939394
366.136,0.72016,-0.0086,,,,,0.04364606061,-0.007756132756
366.636,0.76188,-0.0081,,,,,0.04617454545,-0.007305194805
367.136,0.80313,-0.00598,,,,,0.04867454545,-0.005393217893
367.636,0.84528,-0.00697,,,,,0.05122909091,-0.006286075036
368.136,0.88685,-0.0042,,,,,0.05374848485,-0.003787878788
368.636,0.9282,-0.00295,,,,,0.05625454545,-0.002660533911
369.136,0.97022,-0.00146,,,,,0.05880121212,-0.001316738817
369.636,1.01164,-0.00156,,,,,0.06131151515,-0.001406926407
370.136,1.05345,-0.00229,,,,,0.06384545455,-0.002065295815
370.636,1.09516,0.00127,,,,,0.06637333333,0.001145382395
371.136,1.13648,0.00132,,,,,0.06887757576,0.00119047619
371.636,1.17853,0.00026,,,,,0.07142606061,0.0002344877345
372.136,1.22015,0.00165,,,,,0.07394848485,0.001488095238
372.636,1.2615,0.00219,,,,,0.07645454545,0.001975108225
373.136,1.30359,0.00371,,,,,0.07900545455,0.003345959596
373.636,1.34512,0.0054,,,,,0.08152242424,0.00487012987
374.136,1.38675,0.0053,,,,,0.08404545455,0.00477994228
374.636,1.42862,0.00816,,,,,0.0865830303,0.007359307359
375.136,1.4698,0.00763,,,,,0.08907878788,0.006881313131
375.636,1.51192,0.0076,,,,,0.09163151515,0.006854256854
376.136,1.55363,0.01025,,,,,0.09415939394,0.009244227994
376.636,1.59479,0.0084,,,,,0.09665393939,0.007575757576
377.136,1.63697,0.00954,,,,,0.09921030303,0.008603896104
377.396,1.64717,0.01271,,,,,0.09982848485,0.01146284271
377.896,1.6046,0.00676,,,,,0.09724848485,0.006096681097
378.396,1.56313,0.00592,,,,,0.09473515152,0.005339105339
378.896,1.52128,0.00541,,,,,0.09219878788,0.004879148629
379.396,1.47972,0.00435,,,,,0.08968,0.003923160173
379.896,1.43821,0.00342,,,,,0.08716424242,0.003084415584
380.396,1.39618,0.00309,,,,,0.0846169697,0.002786796537
380.896,1.35475,0.0019,,,,,0.08210606061,0.001713564214
381.396,1.31309,-0.00022,,,,,0.07958121212,-0.0001984126984
381.896,1.27116,-0.0003,,,,,0.07704,-0.0002705627706
382.396,1.22978,-0.00007,,,,,0.07453212121,-0.00006313131313
382.896,1.18791,0.00001,,,,,0.07199454545,0.000009018759019
383.396,1.14636,-0.0025,,,,,0.06947636364,-0.002254689755
383.896,1.10488,-0.00329,,,,,0.06696242424,-0.002967171717
384.396,1.06272,-0.00459,,,,,0.06440727273,-0.00413961039
384.896,1.0214,-0.00578,,,,,0.0619030303,-0.005212842713
385.396,0.97988,-0.00761,,,,,0.05938666667,-0.006863275613
385.896,0.93779,-0.0062,,,,,0.05683575758,-0.005591630592
386.396,0.8964,-0.0078,,,,,0.05432727273,-0.007034632035
386.896,0.85479,-0.00827,,,,,0.05180545455,-0.007458513709
387.396,0.81295,-0.01064,,,,,0.04926969697,-0.009595959596
387.896,0.77148,-0.01133,,,,,0.04675636364,-0.01021825397
388.396,0.72951,-0.01228,,,,,0.04421272727,-0.01107503608
388.896,0.68806,-0.01264,,,,,0.04170060606,-0.0113997114
389.396,0.64654,-0.01453,,,,,0.03918424242,-0.01310425685
389.896,0.60449,-0.01445,,,,,0.03663575758,-0.01303210678
390.396,0.5631,-0.01574,,,,,0.03412727273,-0.0141955267
390.896,0.52136,-0.01624,,,,,0.03159757576,-0.01464646465
391.396,0.47959,-0.01847,,,,,0.02906606061,-0.01665764791
391.896,0.43815,-0.0172,,,,,0.02655454545,-0.01551226551
392.396,0.39618,-0.01816,,,,,0.02401090909,-0.01637806638
392.896,0.35471,-0.0185,,,,,0.02149757576,-0.01668470418
393.396,0.31336,-0.01912,,,,,0.01899151515,-0.01724386724
393.896,0.27108,-0.01977,,,,,0.01642909091,-0.01783008658
394.396,0.22977,-0.02099,,,,,0.01392545455,-0.01893037518
394.896,0.18814,-0.02175,,,,,0.01140242424,-0.01961580087
395.396,0.1463,-0.02188,,,,,0.008866666667,-0.01973304473
395.896,0.10475,-0.02248,,,,,0.006348484848,-0.02027417027
396.396,0.06297,-0.02215,,,,,0.003816363636,-0.01997655123
396.896,0.02136,-0.02379,,,,,0.001294545455,-0.02145562771
397.153,0,-0.02546,,,,,0,-0.02296176046