File: mechanical/hysteresis/data/g60_nonconductive_2.csv
Time,Extension,Load,Length,Width,Thickness,CS Area,Strain,Stress
(s),(mm),(N),(mm),(mm),(mm),(mm^2),(mm/mm),(MPa)
0,0,0.00038,16.5,2.8,0.34,0.952,0,0.0003991596639
0.5,0.03895,0.00225,,,,,0.002360606061,0.002363445378
1,0.08078,0.00121,,,,,0.004895757576,0.001271008403
1.5,0.12201,0.00311,,,,,0.007394545455,0.003266806723
2,0.16417,0.00051,,,,,0.00994969697,0.0005357142857
2.5,0.20571,0.00276,,,,,0.01246727273,0.002899159664
3,0.2471,0.00263,,,,,0.01497575758,0.002762605042
3.5,0.28914,0.0032,,,,,0.01752363636,0.003361344538
4,0.33052,0.0062,,,,,0.02003151515,0.006512605042
4.5,0.3723,-0.00001,,,,,0.02256363636,-0.00001050420168
5,0.41413,0.00443,,,,,0.02509878788,0.004653361345
5.5,0.45528,0.00304,,,,,0.02759272727,0.003193277311
6,0.49736,0.00722,,,,,0.0301430303,0.007584033613
6.5,0.5391,0.006,,,,,0.03267272727,0.006302521008
7,0.5803,0.0062,,,,,0.03516969697,0.006512605042
7.5,0.62245,0.0072,,,,,0.03772424242,0.00756302521
8,0.66401,0.00842,,,,,0.0402430303,0.008844537815
8.5,0.70554,0.00607,,,,,0.04276,0.00637605042
9,0.74747,0.00819,,,,,0.04530121212,0.008602941176
9.5,0.78885,0.01072,,,,,0.04780909091,0.0112605042
10,0.83075,0.00854,,,,,0.05034848485,0.008970588235
10.5,0.87237,0.00812,,,,,0.05287090909,0.008529411765
11,0.91369,0.00891,,,,,0.05537515152,0.009359243697
11.5,0.95581,0.01277,,,,,0.05792787879,0.01341386555
12,0.99725,0.0121,,,,,0.06043939394,0.01271008403
12.5,1.03877,0.01204,,,,,0.06295575758,0.01264705882
13,1.08083,0.00882,,,,,0.06550484848,0.009264705882
13.5,1.12207,0.01359,,,,,0.06800424242,0.01427521008
14,1.16396,0.01195,,,,,0.0705430303,0.01255252101
14.5,1.20579,0.01219,,,,,0.07307818182,0.01280462185
15,1.24694,0.0176,,,,,0.07557212121,0.01848739496
15.5,1.28913,0.0167,,,,,0.07812909091,0.01754201681
16,1.33075,0.01059,,,,,0.08065151515,0.01112394958
16.5,1.37204,0.01346,,,,,0.08315393939,0.01413865546
17,1.41409,0.01693,,,,,0.08570242424,0.01778361345
17.5,1.45559,0.01241,,,,,0.08821757576,0.01303571429
18,1.49732,0.01434,,,,,0.09074666667,0.01506302521
18.5,1.53907,0.01928,,,,,0.0932769697,0.02025210084
19,1.58037,0.02007,,,,,0.09578,0.02108193277
19.5,1.62247,0.0172,,,,,0.09833151515,0.01806722689
19.836,1.65015,0.02107,,,,,0.1000090909,0.02213235294
20.237,1.62136,0.01655,,,,,0.09826424242,0.01738445378
20.737,1.57999,0.01669,,,,,0.0957569697,0.01753151261
21.237,1.53838,0.01652,,,,,0.09323515152,0.01735294118
21.737,1.49633,0.01027,,,,,0.09068666667,0.01078781513
22.237,1.45508,0.01484,,,,,0.08818666667,0.01558823529
22.737,1.41321,0.01526,,,,,0.08564909091,0.01602941176
23.237,1.37153,0.01158,,,,,0.0831230303,0.01216386555
23.737,1.33017,0.0101,,,,,0.08061636364,0.0106092437
24.237,1.28803,0.01031,,,,,0.07806242424,0.01082983193
24.737,1.24661,0.00787,,,,,0.07555212121,0.008266806723
25.237,1.20511,0.00873,,,,,0.0730369697,0.009170168067
25.737,1.16307,0.00723,,,,,0.07048909091,0.007594537815
26.237,1.12159,0.00806,,,,,0.06797515152,0.008466386555
26.737,1.07993,0.00551,,,,,0.06545030303,0.005787815126
27.237,1.03815,0.00554,,,,,0.06291818182,0.005819327731
27.737,0.99676,0.00437,,,,,0.06040969697,0.004590336134
28.237,0.9547,0.00494,,,,,0.05786060606,0.00518907563
28.737,0.91329,0.00324,,,,,0.05535090909,0.003403361345
29.237,0.87184,0.00121,,,,,0.05283878788,0.001271008403
29.737,0.82962,0.00124,,,,,0.05028,0.001302521008
30.237,0.7883,0.00418,,,,,0.04777575758,0.004390756303
30.737,0.74671,0.00188,,,,,0.04525515152,0.001974789916
31.237,0.70479,0.00111,,,,,0.04271454545,0.001165966387
31.737,0.66335,0.00255,,,,,0.0402030303,0.002678571429
32.237,0.62158,-0.00219,,,,,0.03767151515,-0.002300420168
32.737,0.5799,-0.00424,,,,,0.03514545455,-0.004453781513
33.237,0.53842,-0.0008,,,,,0.03263151515,-0.0008403361345
33.737,0.49635,-0.00401,,,,,0.03008181818,-0.004212184874
34.237,0.45501,-0.00498,,,,,0.02757636364,-0.005231092437
34.737,0.41335,-0.00517,,,,,0.02505151515,-0.005430672269
35.237,0.37136,-0.00525,,,,,0.02250666667,-0.005514705882
35.737,0.33001,-0.00341,,,,,0.02000060606,-0.003581932773
36.237,0.28816,-0.00483,,,,,0.01746424242,-0.005073529412
36.737,0.24654,-0.00701,,,,,0.01494181818,-0.007363445378
37.237,0.20513,-0.00876,,,,,0.01243212121,-0.009201680672
37.737,0.163,-0.00825,,,,,0.009878787879,-0.008665966387
38.237,0.12164,-0.01036,,,,,0.007372121212,-0.01088235294
38.737,0.08015,-0.01184,,,,,0.004857575758,-0.01243697479
39.237,0.03798,-0.01105,,,,,0.002301818182,-0.01160714286
39.699,-0.00007,-0.01053,,,,,-0.000004242424242,-0.01106092437
40.001,0.0197,-0.00942,,,,,0.001193939394,-0.009894957983
40.501,0.06179,-0.00626,,,,,0.003744848485,-0.006575630252
41.001,0.10349,-0.00612,,,,,0.006272121212,-0.006428571429
41.501,0.14472,-0.00616,,,,,0.008770909091,-0.006470588235
42.001,0.18689,-0.00647,,,,,0.01132666667,-0.006796218487
42.501,0.22842,-0.00467,,,,,0.01384363636,-0.004905462185
43.001,0.26974,-0.00369,,,,,0.01634787879,-0.00387605042
43.501,0.31185,-0.00252,,,,,0.0189,-0.002647058824
44.001,0.35326,-0.00391,,,,,0.02140969697,-0.004107142857
44.501,0.39502,-0.00405,,,,,0.02394060606,-0.004254201681
45.001,0.43678,-0.00444,,,,,0.02647151515,-0.004663865546
45.501,0.4781,-0.00103,,,,,0.02897575758,-0.001081932773
46.001,0.52013,-0.00144,,,,,0.0315230303,-0.001512605042
46.501,0.56175,-0.00199,,,,,0.03404545455,-0.002090336134
47.001,0.60314,-0.00096,,,,,0.03655393939,-0.001008403361
47.501,0.6452,-0.00081,,,,,0.0391030303,-0.0008508403361
48.001,0.68668,-0.00133,,,,,0.0416169697,-0.001397058824
48.501,0.72832,-0.00041,,,,,0.04414060606,-0.0004306722689
49.001,0.77018,0.00101,,,,,0.04667757576,0.00106092437
49.501,0.81137,0.00065,,,,,0.04917393939,0.0006827731092
50.001,0.85356,-0.00027,,,,,0.05173090909,-0.0002836134454
50.501,0.8952,0.00178,,,,,0.05425454545,0.001869747899
51.001,0.93632,0.00347,,,,,0.05674666667,0.003644957983
51.501,0.97852,0.00304,,,,,0.05930424242,0.003193277311
52.001,1.02007,0.00405,,,,,0.06182242424,0.004254201681
52.501,1.06154,0.00575,,,,,0.06433575758,0.006039915966
53.001,1.10355,0.00652,,,,,0.06688181818,0.006848739496
53.501,1.14492,0.0062,,,,,0.06938909091,0.006512605042
54.001,1.18677,0.00861,,,,,0.07192545455,0.009044117647
54.501,1.2285,0.00858,,,,,0.07445454545,0.009012605042
55.001,1.26979,0.00817,,,,,0.0769569697,0.008581932773
55.501,1.31189,0.00976,,,,,0.07950848485,0.01025210084
56.001,1.35339,0.01093,,,,,0.08202363636,0.01148109244
56.501,1.39485,0.0118,,,,,0.08453636364,0.01239495798
57.001,1.43689,0.01159,,,,,0.08708424242,0.01217436975
57.501,1.47813,0.01285,,,,,0.08958363636,0.01349789916
58.001,1.52003,0.01115,,,,,0.0921230303,0.01171218487
58.501,1.5618,0.01196,,,,,0.09465454545,0.01256302521
59.001,1.60299,0.01348,,,,,0.09715090909,0.01415966387
59.501,1.64508,0.01181,,,,,0.09970181818,0.01240546218
59.765,1.63882,0.01141,,,,,0.09932242424,0.01198529412
60.265,1.5968,0.01082,,,,,0.09677575758,0.01136554622
60.765,1.55499,0.01043,,,,,0.09424181818,0.01095588235
61.265,1.51361,0.00985,,,,,0.09173393939,0.01034663866
61.765,1.47159,0.00996,,,,,0.08918727273,0.01046218487
62.265,1.43007,0.00757,,,,,0.08667090909,0.007951680672
62.765,1.38858,0.00666,,,,,0.08415636364,0.006995798319
63.265,1.34651,0.00679,,,,,0.08160666667,0.007132352941
63.765,1.30509,0.00621,,,,,0.07909636364,0.006523109244
64.265,1.26339,0.00499,,,,,0.07656909091,0.005241596639
64.765,1.2217,0.00342,,,,,0.07404242424,0.003592436975
65.265,1.18013,0.00422,,,,,0.0715230303,0.004432773109
65.765,1.13823,0.00471,,,,,0.06898363636,0.004947478992
66.265,1.09673,0.00373,,,,,0.06646848485,0.003918067227
66.765,1.05527,0.00221,,,,,0.06395575758,0.002321428571
67.265,1.01307,-0.00056,,,,,0.06139818182,-0.0005882352941
67.765,0.97184,-0.00155,,,,,0.05889939394,-0.001628151261
68.265,0.93018,-0.00105,,,,,0.05637454545,-0.001102941176
68.765,0.88826,-0.00074,,,,,0.05383393939,-0.0007773109244
69.265,0.84688,-0.00262,,,,,0.05132606061,-0.00275210084
69.765,0.80499,-0.00138,,,,,0.04878727273,-0.001449579832
70.265,0.76332,-0.0044,,,,,0.04626181818,-0.004621848739
70.765,0.72192,-0.00324,,,,,0.04375272727,-0.003403361345
71.265,0.67989,-0.0027,,,,,0.04120545455,-0.002836134454
71.765,0.63836,-0.00501,,,,,0.03868848485,-0.005262605042
72.265,0.5969,-0.00742,,,,,0.03617575758,-0.007794117647
72.765,0.55483,-0.00733,,,,,0.03362606061,-0.007699579832
73.265,0.5135,-0.00751,,,,,0.03112121212,-0.007888655462
73.765,0.47169,-0.00742,,,,,0.02858727273,-0.007794117647
74.265,0.43007,-0.00724,,,,,0.02606484848,-0.007605042017
74.765,0.38861,-0.00856,,,,,0.02355212121,-0.008991596639
75.265,0.34653,-0.01019,,,,,0.02100181818,-0.01070378151
75.765,0.30512,-0.01043,,,,,0.01849212121,-0.01095588235
76.265,0.26363,-0.01133,,,,,0.01597757576,-0.0119012605
76.765,0.22148,-0.00946,,,,,0.0134230303,-0.00993697479
77.265,0.18008,-0.01194,,,,,0.01091393939,-0.01254201681
77.765,0.13856,-0.01376,,,,,0.008397575758,-0.01445378151
78.265,0.09654,-0.01474,,,,,0.005850909091,-0.01548319328
78.765,0.05517,-0.01412,,,,,0.003343636364,-0.01483193277
79.265,0.01324,-0.01383,,,,,0.0008024242424,-0.01452731092
79.531,0.00226,-0.0135,,,,,0.000136969697,-0.01418067227
80.031,0.04506,-0.0137,,,,,0.002730909091,-0.0143907563
80.531,0.08631,-0.01343,,,,,0.005230909091,-0.01410714286
81.031,0.12854,-0.01103,,,,,0.00779030303,-0.01158613445
81.531,0.16994,-0.01083,,,,,0.01029939394,-0.01137605042
82.031,0.21158,-0.00929,,,,,0.0128230303,-0.009758403361
82.531,0.25354,-0.00974,,,,,0.01536606061,-0.01023109244
83.031,0.29473,-0.00823,,,,,0.01786242424,-0.008644957983
83.531,0.33671,-0.00774,,,,,0.02040666667,-0.008130252101
84.031,0.37844,-0.00637,,,,,0.02293575758,-0.006691176471
84.531,0.41979,-0.00433,,,,,0.02544181818,-0.004548319328
85.031,0.46173,-0.00758,,,,,0.02798363636,-0.007962184874
85.531,0.5033,-0.00574,,,,,0.0305030303,-0.006029411765
86.031,0.54483,-0.00566,,,,,0.03302,-0.005945378151
86.531,0.58682,-0.00334,,,,,0.03556484848,-0.003508403361
87.031,0.62802,-0.00365,,,,,0.03806181818,-0.003834033613
87.531,0.67012,-0.00398,,,,,0.04061333333,-0.004180672269
88.031,0.71183,-0.00317,,,,,0.04314121212,-0.003329831933
88.531,0.75296,-0.00135,,,,,0.04563393939,-0.001418067227
89.031,0.79521,-0.00088,,,,,0.04819454545,-0.0009243697479
89.531,0.83672,-0.00076,,,,,0.05071030303,-0.0007983193277
90.031,0.87813,-0.00005,,,,,0.05322,-0.0000525210084
90.531,0.91999,0.0005,,,,,0.0557569697,0.000525210084
91.031,0.96155,0.00085,,,,,0.05827575758,0.0008928571429
91.531,1.00329,0.00048,,,,,0.06080545455,0.0005042016807
92.031,1.04515,0.00083,,,,,0.06334242424,0.0008718487395
92.531,1.08632,0.00267,,,,,0.06583757576,0.002804621849
93.031,1.12851,0.00295,,,,,0.06839454545,0.003098739496
93.531,1.1701,0.0036,,,,,0.07091515152,0.003781512605
94.031,1.21143,0.00479,,,,,0.07342,0.005031512605
94.531,1.25351,0.0033,,,,,0.07597030303,0.003466386555
95.031,1.29486,0.00576,,,,,0.07847636364,0.006050420168
95.531,1.33659,0.00447,,,,,0.08100545455,0.004695378151
96.031,1.37852,0.0071,,,,,0.08354666667,0.007457983193
96.531,1.41966,0.0076,,,,,0.08604,0.007983193277
97.031,1.46175,0.00669,,,,,0.08859090909,0.007027310924
97.531,1.50347,0.00612,,,,,0.09111939394,0.006428571429
98.031,1.5447,0.00883,,,,,0.09361818182,0.009275210084
98.531,1.58681,0.00748,,,,,0.09617030303,0.007857142857
99.031,1.62835,0.01084,,,,,0.09868787879,0.01138655462
99.295,1.6502,0.0113,,,,,0.1000121212,0.0118697479
99.795,1.61344,0.01038,,,,,0.09778424242,0.01090336134
100.295,1.57198,0.00876,,,,,0.09527151515,0.009201680672
100.795,1.52982,0.00912,,,,,0.09271636364,0.009579831933
101.295,1.48843,0.00552,,,,,0.09020787879,0.005798319328
101.795,1.4468,0.00475,,,,,0.08768484848,0.004989495798
102.295,1.40496,0.00366,,,,,0.08514909091,0.003844537815
102.795,1.36344,0.00444,,,,,0.08263272727,0.004663865546
103.295,1.32162,0.00385,,,,,0.08009818182,0.004044117647
103.795,1.28008,0.00331,,,,,0.07758060606,0.003476890756
104.295,1.23854,0.00123,,,,,0.0750630303,0.001292016807
104.795,1.19646,0.00129,,,,,0.07251272727,0.001355042017
105.295,1.1551,0.0005,,,,,0.07000606061,0.000525210084
105.795,1.11361,0.00042,,,,,0.06749151515,0.0004411764706
106.295,1.07147,0.00037,,,,,0.06493757576,0.0003886554622
106.795,1.03011,-0.00085,,,,,0.06243090909,-0.0008928571429
107.295,0.98843,-0.00211,,,,,0.05990484848,-0.002216386555
107.795,0.94668,-0.00332,,,,,0.05737454545,-0.003487394958
108.295,0.90518,-0.00495,,,,,0.05485939394,-0.005199579832
108.795,0.86323,-0.00294,,,,,0.0523169697,-0.003088235294
109.295,0.82173,-0.00448,,,,,0.04980181818,-0.004705882353
109.795,0.78019,-0.0064,,,,,0.04728424242,-0.006722689076
110.295,0.73818,-0.00618,,,,,0.04473818182,-0.006491596639
110.795,0.69676,-0.00646,,,,,0.04222787879,-0.006785714286
111.295,0.65508,-0.00869,,,,,0.03970181818,-0.009128151261
111.795,0.61328,-0.00815,,,,,0.03716848485,-0.00856092437
112.295,0.57188,-0.00893,,,,,0.03465939394,-0.009380252101
112.795,0.52985,-0.00926,,,,,0.03211212121,-0.009726890756
113.295,0.48846,-0.01048,,,,,0.02960363636,-0.01100840336
113.795,0.44696,-0.01045,,,,,0.02708848485,-0.01097689076
114.295,0.40474,-0.01098,,,,,0.02452969697,-0.01153361345
114.795,0.36345,-0.01382,,,,,0.02202727273,-0.01451680672
115.295,0.32182,-0.01219,,,,,0.01950424242,-0.01280462185
115.795,0.27986,-0.01395,,,,,0.01696121212,-0.01465336134
116.295,0.23843,-0.01094,,,,,0.01445030303,-0.01149159664
116.795,0.19671,-0.01309,,,,,0.01192181818,-0.01375
117.295,0.15496,-0.01611,,,,,0.009391515152,-0.01692226891
117.795,0.11357,-0.01588,,,,,0.006883030303,-0.01668067227
118.295,0.07146,-0.01626,,,,,0.004330909091,-0.01707983193
118.795,0.03012,-0.01698,,,,,0.001825454545,-0.01783613445
119.159,-0.00009,-0.0175,,,,,-0.000005454545455,-0.01838235294
119.56,0.02825,-0.01657,,,,,0.001712121212,-0.01740546218
120.06,0.07021,-0.01374,,,,,0.004255151515,-0.01443277311
120.56,0.11156,-0.01199,,,,,0.006761212121,-0.01259453782
121.06,0.15346,-0.0114,,,,,0.009300606061,-0.01197478992
121.56,0.19517,-0.01374,,,,,0.01182848485,-0.01443277311
122.06,0.23641,-0.01127,,,,,0.01432787879,-0.01183823529
122.56,0.27854,-0.01093,,,,,0.01688121212,-0.01148109244
123.06,0.32003,-0.00994,,,,,0.01939575758,-0.01044117647
123.56,0.36146,-0.01073,,,,,0.02190666667,-0.0112710084
124.06,0.40345,-0.00997,,,,,0.02445151515,-0.01047268908
124.56,0.44497,-0.00904,,,,,0.02696787879,-0.009495798319
125.06,0.48676,-0.0081,,,,,0.02950060606,-0.008508403361
125.56,0.52855,-0.00645,,,,,0.03203333333,-0.006775210084
126.06,0.5697,-0.00725,,,,,0.03452727273,-0.007615546218
126.56,0.61191,-0.00812,,,,,0.03708545455,-0.008529411765
127.06,0.6535,-0.00638,,,,,0.03960606061,-0.006701680672
127.56,0.69479,-0.00454,,,,,0.04210848485,-0.004768907563
128.06,0.73695,-0.00551,,,,,0.04466363636,-0.005787815126
128.56,0.77837,-0.00527,,,,,0.04717393939,-0.005535714286
129.06,0.82,-0.0035,,,,,0.0496969697,-0.003676470588
129.56,0.86179,-0.00309,,,,,0.05222969697,-0.003245798319
130.06,0.9032,-0.00206,,,,,0.05473939394,-0.002163865546
130.56,0.9451,-0.00072,,,,,0.05727878788,-0.000756302521
131.06,0.98686,-0.00033,,,,,0.05980969697,-0.0003466386555
131.56,1.02812,-0.0008,,,,,0.06231030303,-0.0008403361345
132.06,1.07025,-0.00047,,,,,0.06486363636,-0.000493697479
132.56,1.11165,0.00054,,,,,0.06737272727,0.0005672268908
133.06,1.1533,0.00136,,,,,0.0698969697,0.001428571429
133.56,1.19509,0.00338,,,,,0.07242969697,0.003550420168
134.06,1.23641,0.00215,,,,,0.07493393939,0.002258403361
134.56,1.27854,0.00427,,,,,0.07748727273,0.004485294118
135.06,1.32018,0.00463,,,,,0.08001090909,0.004863445378
135.56,1.36139,0.00598,,,,,0.08250848485,0.006281512605
136.06,1.4034,0.00478,,,,,0.08505454545,0.005021008403
136.56,1.44513,0.00399,,,,,0.08758363636,0.004191176471
137.06,1.48647,0.005,,,,,0.09008909091,0.00525210084
137.56,1.52879,0.0078,,,,,0.09265393939,0.008193277311
138.06,1.5699,0.00924,,,,,0.09514545455,0.009705882353
138.56,1.61177,0.00729,,,,,0.0976830303,0.007657563025
139.022,1.65006,0.01162,,,,,0.1000036364,0.01220588235
139.324,1.63024,0.00415,,,,,0.09880242424,0.004359243697
139.824,1.58814,0.00548,,,,,0.09625090909,0.005756302521
140.324,1.54669,0.0049,,,,,0.09373878788,0.005147058824
140.824,1.5049,0.00549,,,,,0.09120606061,0.005766806723
141.324,1.46339,0.00518,,,,,0.08869030303,0.005441176471
141.824,1.42174,0.00505,,,,,0.08616606061,0.005304621849
142.324,1.37978,0.00298,,,,,0.0836230303,0.003130252101
142.824,1.33843,0.00042,,,,,0.0811169697,0.0004411764706
143.324,1.29683,-0.00118,,,,,0.07859575758,-0.001239495798
143.824,1.25467,0.00231,,,,,0.07604060606,0.002426470588
144.324,1.21343,0.00128,,,,,0.07354121212,0.001344537815
144.824,1.17173,-0.00003,,,,,0.07101393939,-0.00003151260504
145.324,1.12987,-0.00238,,,,,0.0684769697,-0.0025
145.824,1.08846,-0.00169,,,,,0.06596727273,-0.001775210084
146.324,1.04651,-0.00399,,,,,0.06342484848,-0.004191176471
146.824,1.00496,-0.00398,,,,,0.06090666667,-0.004180672269
147.324,0.96351,-0.0046,,,,,0.05839454545,-0.004831932773
147.824,0.92144,-0.00846,,,,,0.05584484848,-0.008886554622
148.324,0.87996,-0.00377,,,,,0.05333090909,-0.003960084034
148.824,0.83843,-0.00325,,,,,0.05081393939,-0.003413865546
149.324,0.7965,-0.00535,,,,,0.04827272727,-0.005619747899
149.824,0.75513,-0.00978,,,,,0.04576545455,-0.01027310924
150.324,0.7132,-0.01074,,,,,0.04322424242,-0.01128151261
150.824,0.67167,-0.00685,,,,,0.04070727273,-0.007195378151
151.324,0.63022,-0.00758,,,,,0.03819515152,-0.007962184874
151.824,0.58802,-0.00909,,,,,0.03563757576,-0.009548319328
152.324,0.5467,-0.00988,,,,,0.03313333333,-0.01037815126
152.824,0.50514,-0.01176,,,,,0.03061454545,-0.01235294118
153.324,0.46308,-0.01088,,,,,0.02806545455,-0.01142857143
153.824,0.42166,-0.01214,,,,,0.02555515152,-0.01275210084
154.324,0.38007,-0.01365,,,,,0.02303454545,-0.01433823529
154.824,0.33823,-0.01549,,,,,0.02049878788,-0.0162710084
155.324,0.29684,-0.018,,,,,0.01799030303,-0.01890756303
155.824,0.25482,-0.0161,,,,,0.01544363636,-0.01691176471
156.324,0.21344,-0.01738,,,,,0.01293575758,-0.01825630252
156.824,0.17178,-0.01884,,,,,0.01041090909,-0.01978991597
157.324,0.12973,-0.01726,,,,,0.007862424242,-0.0181302521
157.824,0.08843,-0.01692,,,,,0.005359393939,-0.01777310924
158.324,0.04666,-0.01755,,,,,0.002827878788,-0.01843487395
158.824,0.00487,-0.01809,,,,,0.0002951515152,-0.01900210084
159.089,0.0114,-0.01942,,,,,0.0006909090909,-0.02039915966
159.589,0.05301,-0.0188,,,,,0.003212727273,-0.01974789916
160.089,0.09504,-0.01986,,,,,0.00576,-0.02086134454
160.589,0.13666,-0.0153,,,,,0.008282424242,-0.01607142857
161.089,0.17808,-0.01414,,,,,0.01079272727,-0.01485294118
161.589,0.2201,-0.01327,,,,,0.01333939394,-0.01393907563
162.089,0.26155,-0.01498,,,,,0.01585151515,-0.01573529412
162.589,0.30325,-0.01268,,,,,0.01837878788,-0.01331932773
163.089,0.34513,-0.01079,,,,,0.0209169697,-0.01133403361
163.589,0.38631,-0.00811,,,,,0.02341272727,-0.008518907563
164.089,0.42843,-0.01423,,,,,0.02596545455,-0.01494747899
164.589,0.4701,-0.01286,,,,,0.02849090909,-0.01350840336
165.089,0.51135,-0.00766,,,,,0.03099090909,-0.008046218487
165.589,0.55351,-0.00694,,,,,0.03354606061,-0.007289915966
166.089,0.59503,-0.00792,,,,,0.03606242424,-0.008319327731
166.589,0.63654,-0.00919,,,,,0.03857818182,-0.009653361345
167.089,0.67834,-0.00568,,,,,0.04111151515,-0.005966386555
167.589,0.71963,-0.00443,,,,,0.04361393939,-0.004653361345
168.089,0.76177,-0.00522,,,,,0.04616787879,-0.005483193277
168.589,0.80342,-0.00671,,,,,0.04869212121,-0.007048319328
169.089,0.84471,-0.00473,,,,,0.05119454545,-0.004968487395
169.589,0.88684,-0.00436,,,,,0.05374787879,-0.004579831933
170.089,0.92828,-0.00587,,,,,0.05625939394,-0.006165966387
170.589,0.96985,-0.00205,,,,,0.05877878788,-0.002153361345
171.089,1.01192,-0.00188,,,,,0.06132848485,-0.001974789916
171.589,1.0531,-0.00148,,,,,0.06382424242,-0.001554621849
172.089,1.09506,-0.00351,,,,,0.06636727273,-0.00368697479
172.589,1.13683,-0.00127,,,,,0.06889878788,-0.001334033613
173.089,1.1779,-0.00101,,,,,0.07138787879,-0.00106092437
173.589,1.22004,0.0002,,,,,0.07394181818,0.0002100840336
174.089,1.26176,0.00205,,,,,0.07647030303,0.002153361345
174.589,1.30305,0.00363,,,,,0.07897272727,0.00381302521
175.089,1.34511,0.00402,,,,,0.08152181818,0.004222689076
175.589,1.38661,0.00447,,,,,0.0840369697,0.004695378151
176.089,1.42831,0.00334,,,,,0.08656424242,0.003508403361
176.589,1.47007,0.00261,,,,,0.08909515152,0.002741596639
177.089,1.51132,0.00586,,,,,0.09159515152,0.006155462185
177.589,1.55353,0.00393,,,,,0.09415333333,0.004128151261
178.089,1.59507,0.00702,,,,,0.09667090909,0.00737394958
178.589,1.6364,0.00647,,,,,0.09917575758,0.006796218487
178.854,1.64764,0.00696,,,,,0.0998569697,0.00731092437
179.354,1.60529,0.0048,,,,,0.09729030303,0.005042016807
179.854,1.5632,0.00197,,,,,0.09473939394,0.002069327731
180.354,1.52185,0.00196,,,,,0.09223333333,0.002058823529
180.854,1.48032,0.00273,,,,,0.08971636364,0.002867647059
181.354,1.43813,0.00311,,,,,0.08715939394,0.003266806723
181.854,1.39682,0.00457,,,,,0.08465575758,0.004800420168
182.354,1.35529,-0.0001,,,,,0.08213878788,-0.0001050420168
182.854,1.31324,-0.00134,,,,,0.07959030303,-0.001407563025
183.354,1.27189,-0.00265,,,,,0.07708424242,-0.002783613445
183.854,1.23003,-0.00348,,,,,0.07454727273,-0.003655462185
184.354,1.18845,-0.00171,,,,,0.07202727273,-0.001796218487
184.854,1.14698,-0.00151,,,,,0.06951393939,-0.001586134454
185.354,1.10488,-0.00267,,,,,0.06696242424,-0.002804621849
185.854,1.06351,-0.00358,,,,,0.06445515152,-0.003760504202
186.354,1.02189,-0.00635,,,,,0.06193272727,-0.006670168067
186.854,0.98004,-0.00756,,,,,0.05939636364,-0.007941176471
187.354,0.93849,-0.00622,,,,,0.05687818182,-0.006533613445
187.854,0.8967,-0.00609,,,,,0.05434545455,-0.006397058824
188.354,0.85505,-0.00509,,,,,0.05182121212,-0.005346638655
188.854,0.81363,-0.00811,,,,,0.04931090909,-0.008518907563
189.354,0.77146,-0.00925,,,,,0.04675515152,-0.009716386555
189.854,0.73021,-0.01135,,,,,0.04425515152,-0.01192226891
190.354,0.68862,-0.01164,,,,,0.04173454545,-0.01222689076
190.854,0.6465,-0.00928,,,,,0.03918181818,-0.00974789916
191.354,0.60519,-0.01077,,,,,0.03667818182,-0.01131302521
191.854,0.56347,-0.01206,,,,,0.03414969697,-0.01266806723
192.354,0.52166,-0.01206,,,,,0.03161575758,-0.01266806723
192.854,0.48026,-0.01621,,,,,0.02910666667,-0.01702731092
193.354,0.43834,-0.01445,,,,,0.02656606061,-0.01517857143
193.854,0.39679,-0.01633,,,,,0.02404787879,-0.01715336134
194.354,0.35534,-0.01577,,,,,0.02153575758,-0.01656512605
194.854,0.31317,-0.01472,,,,,0.01898,-0.01546218487
195.354,0.27186,-0.01469,,,,,0.01647636364,-0.01543067227
195.854,0.23017,-0.01697,,,,,0.01394969697,-0.01782563025
196.354,0.18839,-0.01826,,,,,0.01141757576,-0.01918067227
196.854,0.14693,-0.01901,,,,,0.008904848485,-0.01996848739
197.354,0.10495,-0.0178,,,,,0.006360606061,-0.01869747899
197.854,0.06348,-0.01891,,,,,0.003847272727,-0.01986344538
198.354,0.02198,-0.01911,,,,,0.001332121212,-0.02007352941
198.62,-0.00021,-0.02176,,,,,-0.00001272727273,-0.02285714286
199.12,0.03684,-0.01997,,,,,0.002232727273,-0.02097689076
199.62,0.07822,-0.01907,,,,,0.004740606061,-0.02003151261
200.12,0.11999,-0.01753,,,,,0.007272121212,-0.01841386555
200.62,0.16175,-0.01701,,,,,0.009803030303,-0.01786764706
201.12,0.20313,-0.01668,,,,,0.01231090909,-0.0175210084
201.62,0.24506,-0.01551,,,,,0.01485212121,-0.01629201681
202.12,0.28687,-0.01406,,,,,0.01738606061,-0.01476890756
202.62,0.32798,-0.01258,,,,,0.01987757576,-0.01321428571
203.12,0.37024,-0.01308,,,,,0.02243878788,-0.0137394958
203.62,0.41173,-0.01298,,,,,0.02495333333,-0.01363445378
204.12,0.45309,-0.01272,,,,,0.02746,-0.01336134454
204.62,0.49513,-0.01073,,,,,0.03000787879,-0.0112710084
205.12,0.53657,-0.00988,,,,,0.03251939394,-0.01037815126
205.62,0.57834,-0.01084,,,,,0.03505090909,-0.01138655462
206.12,0.62009,-0.00933,,,,,0.03758121212,-0.009800420168
206.62,0.66144,-0.00763,,,,,0.04008727273,-0.008014705882
207.12,0.70339,-0.00755,,,,,0.04262969697,-0.007930672269
207.62,0.74505,-0.00762,,,,,0.04515454545,-0.008004201681
208.12,0.78648,-0.00633,,,,,0.04766545455,-0.006649159664
208.62,0.8286,-0.00511,,,,,0.05021818182,-0.005367647059
209.12,0.86986,-0.0059,,,,,0.05271878788,-0.006197478992
209.62,0.91174,-0.00572,,,,,0.0552569697,-0.006008403361
210.12,0.95345,-0.00404,,,,,0.05778484848,-0.004243697479
210.62,0.99463,-0.00632,,,,,0.06028060606,-0.006638655462
211.12,1.03678,-0.00567,,,,,0.06283515152,-0.005955882353
211.62,1.07861,-0.00153,,,,,0.06537030303,-0.001607142857
212.12,1.11969,0.00088,,,,,0.06786,0.0009243697479
212.62,1.16169,-0.00103,,,,,0.07040545455,-0.001081932773
213.12,1.20335,-0.0019,,,,,0.07293030303,-0.001995798319
213.62,1.24487,-0.00103,,,,,0.07544666667,-0.001081932773
214.12,1.28676,0.00145,,,,,0.07798545455,0.001523109244
214.62,1.32811,0.00213,,,,,0.08049151515,0.002237394958
215.12,1.37014,0.00344,,,,,0.08303878788,0.003613445378
215.62,1.41175,0.00388,,,,,0.08556060606,0.004075630252
216.12,1.45307,0.00291,,,,,0.08806484848,0.003056722689
216.62,1.49521,-0.00052,,,,,0.09061878788,-0.0005462184874
217.12,1.53664,0.00189,,,,,0.09312969697,0.001985294118
217.62,1.5782,0.00574,,,,,0.09564848485,0.006029411765
218.12,1.62031,0.00939,,,,,0.09820060606,0.009863445378
218.483,1.65013,0.00428,,,,,0.1000078788,0.004495798319
218.884,1.62153,0.00436,,,,,0.09827454545,0.004579831933
219.384,1.58017,0.00087,,,,,0.09576787879,0.0009138655462
219.884,1.53855,0.00481,,,,,0.09324545455,0.005052521008
220.384,1.49653,0.00284,,,,,0.09069878788,0.002983193277
220.884,1.45527,0.00193,,,,,0.08819818182,0.002027310924
221.384,1.4134,0.00139,,,,,0.08566060606,0.001460084034
221.884,1.37163,-0.00015,,,,,0.08312909091,-0.0001575630252
222.384,1.33037,-0.0016,,,,,0.08062848485,-0.001680672269
222.884,1.28822,-0.00163,,,,,0.07807393939,-0.001712184874
223.384,1.2468,-0.00411,,,,,0.07556363636,-0.004317226891
223.884,1.20529,-0.0034,,,,,0.07304787879,-0.003571428571
224.384,1.16328,-0.00194,,,,,0.07050181818,-0.002037815126
224.884,1.12181,-0.00362,,,,,0.06798848485,-0.003802521008
225.384,1.0801,-0.00612,,,,,0.06546060606,-0.006428571429
225.884,1.03838,-0.0062,,,,,0.06293212121,-0.006512605042
226.384,0.99694,-0.00858,,,,,0.06042060606,-0.009012605042
226.884,0.95486,-0.00726,,,,,0.05787030303,-0.00762605042
227.384,0.91349,-0.0092,,,,,0.0553630303,-0.009663865546
227.884,0.87204,-0.0078,,,,,0.05285090909,-0.008193277311
228.384,0.8298,-0.00899,,,,,0.05029090909,-0.009443277311
228.884,0.78849,-0.0062,,,,,0.04778727273,-0.006512605042
229.384,0.74689,-0.00967,,,,,0.04526606061,-0.01015756303
229.884,0.70499,-0.01186,,,,,0.04272666667,-0.01245798319
230.384,0.66355,-0.01441,,,,,0.04021515152,-0.01513655462
230.884,0.62173,-0.01254,,,,,0.03768060606,-0.01317226891
231.384,0.58011,-0.01368,,,,,0.03515818182,-0.0143697479
231.884,0.5386,-0.01083,,,,,0.03264242424,-0.01137605042
232.384,0.49652,-0.01247,,,,,0.03009212121,-0.0130987395
232.884,0.45518,-0.01421,,,,,0.02758666667,-0.01492647059
233.384,0.41352,-0.01527,,,,,0.02506181818,-0.01603991597
233.884,0.37159,-0.01781,,,,,0.02252060606,-0.01870798319
234.384,0.33021,-0.01727,,,,,0.02001272727,-0.0181407563
234.884,0.28832,-0.01833,,,,,0.01747393939,-0.01925420168
235.384,0.24675,-0.01819,,,,,0.01495454545,-0.01910714286
235.884,0.20533,-0.01585,,,,,0.01244424242,-0.01664915966
236.384,0.16315,-0.01756,,,,,0.009887878788,-0.01844537815
236.884,0.12185,-0.0186,,,,,0.007384848485,-0.01953781513
237.384,0.08031,-0.02164,,,,,0.004867272727,-0.02273109244
237.884,0.03819,-0.02032,,,,,0.002314545455,-0.02134453782
238.348,-0.00004,-0.02226,,,,,-0.000002424242424,-0.02338235294
238.65,0.01967,-0.01836,,,,,0.001192121212,-0.01928571429
239.15,0.06178,-0.02036,,,,,0.003744242424,-0.02138655462
239.65,0.10348,-0.01623,,,,,0.006271515152,-0.01704831933
240.15,0.1447,-0.01841,,,,,0.00876969697,-0.01933823529
240.65,0.18685,-0.02013,,,,,0.01132424242,-0.02114495798
241.15,0.22839,-0.01893,,,,,0.01384181818,-0.01988445378
241.65,0.26973,-0.01491,,,,,0.01634727273,-0.01566176471
242.15,0.31181,-0.01364,,,,,0.01889757576,-0.01432773109
242.65,0.35335,-0.01244,,,,,0.02141515152,-0.01306722689
243.15,0.39501,-0.0132,,,,,0.02394,-0.01386554622
243.65,0.43676,-0.01485,,,,,0.02647030303,-0.0155987395
244.15,0.4781,-0.01321,,,,,0.02897575758,-0.01387605042
244.65,0.52012,-0.01123,,,,,0.03152242424,-0.01179621849
245.15,0.56172,-0.01186,,,,,0.03404363636,-0.01245798319
245.65,0.6032,-0.01003,,,,,0.03655757576,-0.01053571429
246.15,0.64525,-0.0103,,,,,0.03910606061,-0.01081932773
246.65,0.68667,-0.0092,,,,,0.04161636364,-0.009663865546
247.15,0.72832,-0.01053,,,,,0.04414060606,-0.01106092437
247.65,0.77016,-0.00906,,,,,0.04667636364,-0.009516806723
248.15,0.8113,-0.00775,,,,,0.04916969697,-0.008140756303
248.65,0.85353,-0.0065,,,,,0.05172909091,-0.006827731092
249.15,0.8952,-0.0053,,,,,0.05425454545,-0.005567226891
249.65,0.93631,-0.00433,,,,,0.05674606061,-0.004548319328
250.15,0.9785,-0.00635,,,,,0.0593030303,-0.006670168067
250.65,1.0201,-0.00471,,,,,0.06182424242,-0.004947478992
251.15,1.06148,-0.00333,,,,,0.06433212121,-0.00349789916
251.65,1.10341,-0.00263,,,,,0.06687333333,-0.002762605042
252.15,1.145,-0.00453,,,,,0.06939393939,-0.004758403361
252.65,1.18674,-0.00387,,,,,0.07192363636,-0.00406512605
253.15,1.22848,-0.00198,,,,,0.07445333333,-0.002079831933
253.65,1.26978,0.00109,,,,,0.07695636364,0.001144957983
254.15,1.31183,0.00254,,,,,0.07950484848,0.002668067227
254.65,1.35333,0.00041,,,,,0.08202,0.0004306722689
255.15,1.39497,0.00083,,,,,0.08454363636,0.0008718487395
255.65,1.43684,0.00159,,,,,0.08708121212,0.001670168067
256.15,1.47815,0.00451,,,,,0.08958484848,0.004737394958
256.65,1.52001,0.00288,,,,,0.09212181818,0.003025210084
257.15,1.56182,0.00284,,,,,0.09465575758,0.002983193277
257.65,1.60297,0.00304,,,,,0.09714969697,0.003193277311
258.15,1.64506,0.00437,,,,,0.09970060606,0.004590336134
258.414,1.63928,0.00806,,,,,0.09935030303,0.008466386555
258.914,1.59713,0.00335,,,,,0.09679575758,0.003518907563
259.414,1.55543,0.00159,,,,,0.09426848485,0.001670168067
259.914,1.51403,0.0018,,,,,0.09175939394,0.001890756303
260.414,1.47196,0.00129,,,,,0.08920969697,0.001355042017
260.914,1.43049,-0.00105,,,,,0.08669636364,-0.001102941176
261.414,1.38896,-0.0022,,,,,0.08417939394,-0.00231092437
261.914,1.34692,-0.00259,,,,,0.08163151515,-0.002720588235
262.414,1.30549,-0.00242,,,,,0.07912060606,-0.002542016807
262.914,1.26369,-0.00353,,,,,0.07658727273,-0.003707983193
263.414,1.22216,-0.00441,,,,,0.07407030303,-0.004632352941
263.914,1.18055,-0.00546,,,,,0.07154848485,-0.005735294118
264.414,1.1386,-0.00584,,,,,0.06900606061,-0.006134453782
264.914,1.09717,-0.00407,,,,,0.06649515152,-0.004275210084
265.414,1.05565,-0.00803,,,,,0.06397878788,-0.00843487395
265.914,1.01345,-0.00729,,,,,0.06142121212,-0.007657563025
266.414,0.97226,-0.00968,,,,,0.05892484848,-0.01016806723
266.914,0.93057,-0.00836,,,,,0.05639818182,-0.008781512605
267.414,0.88864,-0.00913,,,,,0.0538569697,-0.009590336134
267.914,0.84734,-0.01107,,,,,0.05135393939,-0.01162815126
268.414,0.80533,-0.01154,,,,,0.04880787879,-0.01212184874
268.914,0.76375,-0.01228,,,,,0.04628787879,-0.01289915966
269.414,0.72233,-0.01286,,,,,0.04377757576,-0.01350840336
269.914,0.68029,-0.01354,,,,,0.04122969697,-0.01422268908
270.414,0.63874,-0.01379,,,,,0.03871151515,-0.01448529412
270.914,0.59726,-0.01438,,,,,0.03619757576,-0.01510504202
271.414,0.55527,-0.0129,,,,,0.03365272727,-0.01355042017
271.914,0.51393,-0.01533,,,,,0.03114727273,-0.01610294118
272.414,0.47202,-0.01599,,,,,0.02860727273,-0.01679621849
272.914,0.43052,-0.01519,,,,,0.02609212121,-0.01595588235
273.414,0.38905,-0.01667,,,,,0.02357878788,-0.0175105042
273.914,0.34689,-0.01636,,,,,0.02102363636,-0.01718487395
274.414,0.30551,-0.0171,,,,,0.01851575758,-0.01796218487
274.914,0.26401,-0.01868,,,,,0.01600060606,-0.01962184874
275.414,0.2219,-0.01859,,,,,0.01344848485,-0.01952731092
275.914,0.18049,-0.01957,,,,,0.01093878788,-0.02055672269
276.414,0.13888,-0.02242,,,,,0.008416969697,-0.02355042017
276.914,0.09698,-0.02179,,,,,0.005877575758,-0.02288865546
277.414,0.0556,-0.02105,,,,,0.00336969697,-0.02211134454
277.914,0.0136,-0.0216,,,,,0.0008242424242,-0.02268907563
278.184,0.00229,-0.02139,,,,,0.0001387878788,-0.02246848739
278.684,0.0451,-0.02057,,,,,0.002733333333,-0.02160714286
279.184,0.08636,-0.0186,,,,,0.005233939394,-0.01953781513
279.684,0.1286,-0.01889,,,,,0.007793939394,-0.01984243697
280.184,0.17001,-0.0184,,,,,0.01030363636,-0.01932773109
280.684,0.21161,-0.01955,,,,,0.01282484848,-0.02053571429
281.184,0.25357,-0.01775,,,,,0.01536787879,-0.01864495798
281.684,0.29478,-0.01533,,,,,0.01786545455,-0.01610294118
282.184,0.33675,-0.01493,,,,,0.02040909091,-0.01568277311
282.684,0.37849,-0.0156,,,,,0.02293878788,-0.01638655462
283.184,0.41984,-0.01675,,,,,0.02544484848,-0.01759453782
283.684,0.46176,-0.01556,,,,,0.02798545455,-0.01634453782
284.184,0.50339,-0.01251,,,,,0.03050848485,-0.0131407563
284.684,0.54489,-0.01021,,,,,0.03302363636,-0.01072478992
285.184,0.58677,-0.01143,,,,,0.03556181818,-0.01200630252
285.684,0.62812,-0.01344,,,,,0.03806787879,-0.01411764706
286.184,0.67027,-0.01097,,,,,0.04062242424,-0.01152310924
286.684,0.71185,-0.00949,,,,,0.04314242424,-0.009968487395
287.184,0.75301,-0.00745,,,,,0.0456369697,-0.007825630252
287.684,0.79523,-0.00757,,,,,0.04819575758,-0.007951680672
288.184,0.83668,-0.01076,,,,,0.05070787879,-0.01130252101
288.684,0.87816,-0.00843,,,,,0.05322181818,-0.008855042017
289.184,0.92011,-0.00631,,,,,0.05576424242,-0.006628151261
289.684,0.96168,-0.00383,,,,,0.05828363636,-0.004023109244
290.184,1.00334,-0.00651,,,,,0.06080848485,-0.006838235294
290.684,1.04519,-0.0045,,,,,0.06334484848,-0.004726890756
291.184,1.08633,-0.00634,,,,,0.06583818182,-0.006659663866
291.684,1.12854,-0.00461,,,,,0.06839636364,-0.004842436975
292.184,1.17023,-0.00259,,,,,0.0709230303,-0.002720588235
292.684,1.21156,0.00046,,,,,0.07342787879,0.0004831932773
293.184,1.25356,-0.00234,,,,,0.07597333333,-0.002457983193
293.684,1.29496,-0.00276,,,,,0.07848242424,-0.002899159664
294.184,1.33666,-0.00302,,,,,0.08100969697,-0.003172268908
294.684,1.37852,-0.00333,,,,,0.08354666667,-0.00349789916
295.184,1.41975,0.005,,,,,0.08604545455,0.00525210084
295.684,1.46174,0.00423,,,,,0.08859030303,0.004443277311
296.184,1.5036,0.0013,,,,,0.09112727273,0.001365546218
296.684,1.54473,-0.00067,,,,,0.09362,-0.0007037815126
297.184,1.58687,0.00394,,,,,0.09617393939,0.004138655462
297.684,1.62834,0.00645,,,,,0.09868727273,0.006775210084
297.948,1.65022,0.00283,,,,,0.1000133333,0.002972689076
298.448,1.61384,0.00231,,,,,0.09780848485,0.002426470588
298.948,1.57235,-0.00166,,,,,0.09529393939,-0.001743697479
299.448,1.53023,0.00023,,,,,0.09274121212,0.0002415966387
299.948,1.48883,0.00073,,,,,0.09023212121,0.0007668067227
300.448,1.44716,-0.00061,,,,,0.08770666667,-0.0006407563025
300.948,1.40544,0.00167,,,,,0.08517818182,0.001754201681
301.448,1.3639,-0.00446,,,,,0.08266060606,-0.00468487395
301.948,1.32195,-0.00194,,,,,0.08011818182,-0.002037815126
302.448,1.28057,-0.00194,,,,,0.07761030303,-0.002037815126
302.948,1.23901,-0.00308,,,,,0.07509151515,-0.003235294118
303.448,1.19686,-0.00444,,,,,0.0725369697,-0.004663865546
303.948,1.15551,-0.00553,,,,,0.07003090909,-0.005808823529
304.448,1.11397,-0.00845,,,,,0.06751333333,-0.00887605042
304.948,1.07193,-0.01029,,,,,0.06496545455,-0.01080882353
305.448,1.03055,-0.00758,,,,,0.06245757576,-0.007962184874
305.948,0.98876,-0.00681,,,,,0.05992484848,-0.007153361345
306.448,0.94711,-0.0086,,,,,0.05740060606,-0.009033613445
306.948,0.90559,-0.01091,,,,,0.05488424242,-0.01146008403
307.448,0.8636,-0.01071,,,,,0.05233939394,-0.01125
307.948,0.82217,-0.00981,,,,,0.04982848485,-0.01030462185
308.448,0.78055,-0.01211,,,,,0.04730606061,-0.01272058824
308.948,0.73864,-0.0117,,,,,0.04476606061,-0.01228991597
309.448,0.69714,-0.014,,,,,0.04225090909,-0.01470588235
309.948,0.65545,-0.01514,,,,,0.03972424242,-0.01590336134
310.448,0.61374,-0.01376,,,,,0.03719636364,-0.01445378151
310.948,0.57234,-0.01412,,,,,0.03468727273,-0.01483193277
311.448,0.5302,-0.01543,,,,,0.03213333333,-0.01620798319
311.948,0.48889,-0.01596,,,,,0.02962969697,-0.01676470588
312.448,0.44736,-0.01764,,,,,0.02711272727,-0.01852941176
312.948,0.40516,-0.01683,,,,,0.02455515152,-0.01767857143
313.448,0.36384,-0.0179,,,,,0.02205090909,-0.01880252101
313.948,0.32218,-0.01863,,,,,0.01952606061,-0.01956932773
314.448,0.28032,-0.01845,,,,,0.01698909091,-0.0193802521
314.948,0.2389,-0.01834,,,,,0.01447878788,-0.01926470588
315.448,0.19704,-0.02069,,,,,0.01194181818,-0.02173319328
315.948,0.1554,-0.02266,,,,,0.009418181818,-0.02380252101
316.448,0.11398,-0.02307,,,,,0.006907878788,-0.02423319328
316.948,0.07184,-0.02046,,,,,0.004353939394,-0.02149159664
317.448,0.03055,-0.02108,,,,,0.001851515152,-0.02214285714
317.817,-0.0001,-0.02361,,,,,-0.000006060606061,-0.02480042017
318.218,0.02823,-0.02408,,,,,0.001710909091,-0.02529411765
318.718,0.07017,-0.02157,,,,,0.004252727273,-0.02265756303
319.218,0.11154,-0.02,,,,,0.00676,-0.02100840336
319.718,0.15344,-0.01889,,,,,0.009299393939,-0.01984243697
320.218,0.19514,-0.01743,,,,,0.01182666667,-0.01830882353
320.718,0.23639,-0.01659,,,,,0.01432666667,-0.01742647059
321.218,0.27851,-0.0182,,,,,0.01687939394,-0.01911764706
321.718,0.32004,-0.01852,,,,,0.01939636364,-0.01945378151
322.218,0.36151,-0.01673,,,,,0.02190969697,-0.01757352941
322.718,0.40341,-0.01733,,,,,0.02444909091,-0.01820378151
323.218,0.44487,-0.01425,,,,,0.02696181818,-0.01496848739
323.718,0.48677,-0.01329,,,,,0.02950121212,-0.01396008403
324.218,0.52854,-0.01209,,,,,0.03203272727,-0.01269957983
324.718,0.56967,-0.01338,,,,,0.03452545455,-0.01405462185
325.218,0.61193,-0.01575,,,,,0.03708666667,-0.01654411765
325.718,0.65346,-0.01553,,,,,0.03960363636,-0.01631302521
326.218,0.69471,-0.01158,,,,,0.04210363636,-0.01216386555
326.718,0.73703,-0.00911,,,,,0.04466848485,-0.009569327731
327.218,0.7783,-0.00754,,,,,0.04716969697,-0.007920168067
327.718,0.81998,-0.00841,,,,,0.04969575758,-0.008834033613
328.218,0.86178,-0.00952,,,,,0.05222909091,-0.01
328.718,0.90311,-0.00871,,,,,0.05473393939,-0.009149159664
329.218,0.94501,-0.00912,,,,,0.05727333333,-0.009579831933
329.718,0.98682,-0.0063,,,,,0.05980727273,-0.006617647059
330.218,1.02809,-0.00453,,,,,0.06230848485,-0.004758403361
330.718,1.07024,-0.00556,,,,,0.0648630303,-0.005840336134
331.218,1.11155,-0.00604,,,,,0.06736666667,-0.006344537815
331.718,1.1533,-0.0042,,,,,0.0698969697,-0.004411764706
332.218,1.19519,-0.00443,,,,,0.07243575758,-0.004653361345
332.718,1.23633,-0.00327,,,,,0.07492909091,-0.00343487395
333.218,1.27854,-0.00225,,,,,0.07748727273,-0.002363445378
333.718,1.32017,-0.00222,,,,,0.08001030303,-0.002331932773
334.218,1.36136,-0.00044,,,,,0.08250666667,-0.0004621848739
334.718,1.40335,-0.00041,,,,,0.08505151515,-0.0004306722689
335.218,1.44512,0.00032,,,,,0.0875830303,0.0003361344538
335.718,1.48644,-0.00021,,,,,0.09008727273,-0.0002205882353
336.218,1.52856,0.00213,,,,,0.09264,0.002237394958
336.718,1.56988,0.0053,,,,,0.09514424242,0.005567226891
337.218,1.61172,0.00244,,,,,0.09768,0.00256302521
337.68,1.65001,0.00331,,,,,0.1000006061,0.003476890756
337.982,1.63046,0.00234,,,,,0.09881575758,0.002457983193
338.482,1.58844,0.00066,,,,,0.09626909091,0.0006932773109
338.982,1.54699,0.00047,,,,,0.0937569697,0.000493697479
339.482,1.50514,-0.00108,,,,,0.09122060606,-0.001134453782
339.982,1.46368,-0.00134,,,,,0.08870787879,-0.001407563025
340.482,1.42203,-0.00034,,,,,0.08618363636,-0.0003571428571
340.982,1.38002,-0.00162,,,,,0.08363757576,-0.001701680672
341.482,1.33871,-0.00411,,,,,0.08113393939,-0.004317226891
341.982,1.29708,-0.00343,,,,,0.07861090909,-0.003602941176
342.482,1.25497,-0.00513,,,,,0.07605878788,-0.005388655462
342.982,1.21369,-0.00416,,,,,0.0735569697,-0.004369747899
343.482,1.17193,-0.00758,,,,,0.07102606061,-0.007962184874
343.982,1.13018,-0.00992,,,,,0.06849575758,-0.01042016807
344.482,1.08878,-0.0084,,,,,0.06598666667,-0.008823529412
344.982,1.04677,-0.00702,,,,,0.06344060606,-0.00737394958
345.482,1.00525,-0.00916,,,,,0.06092424242,-0.009621848739
345.982,0.96383,-0.01141,,,,,0.05841393939,-0.01198529412
346.482,0.92172,-0.01114,,,,,0.05586181818,-0.01170168067
346.982,0.88023,-0.01042,,,,,0.05334727273,-0.01094537815
347.482,0.83868,-0.01065,,,,,0.05082909091,-0.01118697479
347.982,0.79678,-0.01223,,,,,0.04828969697,-0.01284663866
348.482,0.75542,-0.01437,,,,,0.0457830303,-0.01509453782
348.982,0.71345,-0.01415,,,,,0.04323939394,-0.01486344538
349.482,0.67197,-0.01525,,,,,0.04072545455,-0.01601890756
349.982,0.63049,-0.01556,,,,,0.03821151515,-0.01634453782
350.482,0.58829,-0.01584,,,,,0.03565393939,-0.01663865546
350.982,0.54697,-0.01341,,,,,0.03314969697,-0.01408613445
351.482,0.50538,-0.01623,,,,,0.03062909091,-0.01704831933
351.982,0.46341,-0.01683,,,,,0.02808545455,-0.01767857143
352.482,0.42194,-0.01995,,,,,0.02557212121,-0.02095588235
352.982,0.38027,-0.02044,,,,,0.02304666667,-0.02147058824
353.482,0.33854,-0.02135,,,,,0.02051757576,-0.02242647059
353.982,0.29711,-0.01968,,,,,0.01800666667,-0.02067226891
354.482,0.25508,-0.01727,,,,,0.01545939394,-0.0181407563
354.982,0.2137,-0.02064,,,,,0.01295151515,-0.02168067227
355.482,0.17206,-0.02179,,,,,0.01042787879,-0.02288865546
355.982,0.13003,-0.02374,,,,,0.007880606061,-0.02493697479
356.482,0.08869,-0.02436,,,,,0.005375151515,-0.02558823529
356.982,0.04691,-0.0229,,,,,0.002843030303,-0.02405462185
357.482,0.0052,-0.02193,,,,,0.0003151515152,-0.02303571429
357.75,0.01137,-0.02543,,,,,0.0006890909091,-0.02671218487
358.25,0.05297,-0.02296,,,,,0.00321030303,-0.02411764706
358.75,0.09503,-0.0223,,,,,0.005759393939,-0.02342436975
359.25,0.13664,-0.0214,,,,,0.008281212121,-0.0224789916
359.75,0.17807,-0.02036,,,,,0.01079212121,-0.02138655462
360.25,0.21995,-0.0192,,,,,0.01333030303,-0.02016806723
360.75,0.26154,-0.01872,,,,,0.01585090909,-0.01966386555
361.25,0.30325,-0.01783,,,,,0.01837878788,-0.0187289916
361.75,0.34509,-0.01767,,,,,0.02091454545,-0.01856092437
362.25,0.38628,-0.01965,,,,,0.02341090909,-0.0206407563
362.75,0.42853,-0.01734,,,,,0.02597151515,-0.01821428571
363.25,0.46998,-0.01406,,,,,0.02848363636,-0.01476890756
363.75,0.51138,-0.01206,,,,,0.03099272727,-0.01266806723
364.25,0.5535,-0.01219,,,,,0.03354545455,-0.01280462185
364.75,0.59498,-0.01414,,,,,0.03605939394,-0.01485294118
365.25,0.63646,-0.01612,,,,,0.03857333333,-0.01693277311
365.75,0.67834,-0.01496,,,,,0.04111151515,-0.01571428571
366.25,0.71968,-0.01061,,,,,0.0436169697,-0.01114495798
366.75,0.76167,-0.00945,,,,,0.04616181818,-0.009926470588
367.25,0.80345,-0.01041,,,,,0.04869393939,-0.01093487395
367.75,0.84468,-0.01026,,,,,0.05119272727,-0.01077731092
368.25,0.88679,-0.01108,,,,,0.05374484848,-0.01163865546
368.75,0.92825,-0.00896,,,,,0.05625757576,-0.009411764706
369.25,0.96996,-0.00789,,,,,0.05878545455,-0.008287815126
369.75,1.01179,-0.00567,,,,,0.06132060606,-0.005955882353
370.25,1.05316,-0.00325,,,,,0.06382787879,-0.003413865546
370.75,1.09506,-0.00492,,,,,0.06636727273,-0.005168067227
371.25,1.13681,-0.00481,,,,,0.06889757576,-0.005052521008
371.75,1.17788,-0.00713,,,,,0.07138666667,-0.007489495798
372.25,1.22008,-0.00613,,,,,0.07394424242,-0.00643907563
372.75,1.26167,-0.00448,,,,,0.07646484848,-0.004705882353
373.25,1.30304,-0.00089,,,,,0.07897212121,-0.0009348739496
373.75,1.34508,0.00023,,,,,0.08152,0.0002415966387
374.25,1.38656,-0.00175,,,,,0.08403393939,-0.001838235294
374.75,1.42823,-0.00203,,,,,0.08655939394,-0.002132352941
375.25,1.47007,-0.00099,,,,,0.08909515152,-0.001039915966
375.75,1.51138,0.00077,,,,,0.09159878788,0.0008088235294
376.25,1.55344,0.00076,,,,,0.09414787879,0.0007983193277
376.75,1.59513,0.0017,,,,,0.09667454545,0.001785714286
377.25,1.63638,0.00434,,,,,0.09917454545,0.004558823529
377.515,1.64768,0.00228,,,,,0.09985939394,0.002394957983
378.015,1.6054,0.00023,,,,,0.0972969697,0.0002415966387
378.515,1.5633,-0.00037,,,,,0.09474545455,-0.0003886554622
379.015,1.52197,-0.00041,,,,,0.09224060606,-0.0004306722689
379.515,1.4804,0.00033,,,,,0.08972121212,0.0003466386555
380.015,1.43822,-0.00089,,,,,0.08716484848,-0.0009348739496
380.515,1.39695,-0.00242,,,,,0.08466363636,-0.002542016807
381.015,1.35537,-0.00515,,,,,0.08214363636,-0.005409663866
381.515,1.31337,-0.00763,,,,,0.07959818182,-0.008014705882
382.015,1.27204,-0.0067,,,,,0.07709333333,-0.007037815126
382.515,1.2301,-0.00527,,,,,0.07455151515,-0.005535714286
383.015,1.18857,-0.00495,,,,,0.07203454545,-0.005199579832
383.515,1.14709,-0.00759,,,,,0.06952060606,-0.007972689076
384.015,1.10499,-0.00598,,,,,0.06696909091,-0.006281512605
384.515,1.0636,-0.00743,,,,,0.06446060606,-0.007804621849
385.015,1.02197,-0.0102,,,,,0.06193757576,-0.01071428571
385.515,0.98013,-0.01269,,,,,0.05940181818,-0.01332983193
386.015,0.93859,-0.01263,,,,,0.05688424242,-0.01326680672
386.515,0.89679,-0.01125,,,,,0.05435090909,-0.01181722689
387.015,0.85518,-0.01128,,,,,0.05182909091,-0.0118487395
387.515,0.81371,-0.01268,,,,,0.04931575758,-0.01331932773
388.015,0.77156,-0.01364,,,,,0.04676121212,-0.01432773109
388.515,0.73033,-0.0112,,,,,0.04426242424,-0.01176470588
389.015,0.68872,-0.01432,,,,,0.04174060606,-0.01504201681
389.515,0.64662,-0.01247,,,,,0.03918909091,-0.0130987395
390.015,0.6053,-0.01814,,,,,0.03668484848,-0.01905462185
390.515,0.56358,-0.01643,,,,,0.03415636364,-0.01725840336
391.015,0.52178,-0.01628,,,,,0.0316230303,-0.01710084034
391.515,0.48037,-0.01885,,,,,0.02911333333,-0.01980042017
392.015,0.43843,-0.01717,,,,,0.02657151515,-0.01803571429
392.515,0.3969,-0.01903,,,,,0.02405454545,-0.0199894958
393.015,0.35543,-0.01714,,,,,0.02154121212,-0.01800420168
393.515,0.31326,-0.02164,,,,,0.01898545455,-0.02273109244
394.015,0.27198,-0.02206,,,,,0.01648363636,-0.02317226891
394.515,0.23024,-0.02354,,,,,0.01395393939,-0.02472689076
395.015,0.18848,-0.02106,,,,,0.0114230303,-0.02212184874
395.515,0.14707,-0.02105,,,,,0.008913333333,-0.02211134454
396.015,0.10504,-0.02286,,,,,0.006366060606,-0.02401260504
396.515,0.06358,-0.02312,,,,,0.003853333333,-0.02428571429
397.015,0.02208,-0.02398,,,,,0.001338181818,-0.02518907563
397.28,-0.00001,-0.02548,,,,,-0.0000006060606061,-0.02676470588