File: mechanical/hysteresis/data/g60_conductive_1.csv
Time,Extension,Load,Length,Width,Thickness,CS Area,Strain,Stress
(s),(mm),(N),(mm),(mm),(mm),(mm^2),(mm/mm),(MPa)
0,0,-0.00148,16.5,2.82,0.44,1.2408,0,-0.001192778852
0.5,0.03913,0.00221,,,,,0.002371515152,0.001781108962
1,0.08026,0.00517,,,,,0.004864242424,0.004166666667
1.5,0.1224,0.00447,,,,,0.007418181818,0.003602514507
2,0.16404,0.00618,,,,,0.009941818182,0.00498065764
2.5,0.20537,0.0083,,,,,0.01244666667,0.006689232753
3,0.24744,0.01084,,,,,0.01499636364,0.008736299162
3.5,0.28892,0.00953,,,,,0.01751030303,0.007680528691
4,0.3306,0.01034,,,,,0.02003636364,0.008333333333
4.5,0.37244,0.01122,,,,,0.02257212121,0.009042553191
5,0.41375,0.01323,,,,,0.02507575758,0.01066247582
5.5,0.45582,0.01197,,,,,0.02762545455,0.009647001934
6,0.49735,0.01351,,,,,0.03014242424,0.01088813669
6.5,0.53873,0.01606,,,,,0.03265030303,0.01294326241
7,0.5808,0.01692,,,,,0.0352,0.01363636364
7.5,0.62219,0.01922,,,,,0.03770848485,0.01549000645
8,0.66386,0.01853,,,,,0.04023393939,0.0149339136
8.5,0.70579,0.02179,,,,,0.04277515152,0.01756125081
9,0.74698,0.0238,,,,,0.04527151515,0.01918117344
9.5,0.789,0.02344,,,,,0.04781818182,0.01889103804
10,0.83074,0.02561,,,,,0.05034787879,0.02063990974
10.5,0.87193,0.02445,,,,,0.05284424242,0.01970502901
11,0.91418,0.02587,,,,,0.05540484848,0.02084945197
11.5,0.95569,0.02625,,,,,0.05792060606,0.021155706
12,0.99714,0.0287,,,,,0.06043272727,0.02313023856
12.5,1.03908,0.03008,,,,,0.06297454545,0.02424242424
13,1.08048,0.02936,,,,,0.06548363636,0.02366215345
13.5,1.1224,0.02922,,,,,0.06802424242,0.02354932302
14,1.16407,0.03081,,,,,0.07054969697,0.02483075435
14.5,1.20535,0.03634,,,,,0.07305151515,0.02928755642
15,1.24746,0.03317,,,,,0.07560363636,0.02673275306
15.5,1.289,0.03552,,,,,0.07812121212,0.02862669246
16,1.33034,0.03551,,,,,0.08062666667,0.02861863314
16.5,1.37249,0.03687,,,,,0.08318121212,0.02971470019
17,1.41381,0.03814,,,,,0.08568545455,0.0307382334
17.5,1.45562,0.04003,,,,,0.08821939394,0.03226144423
18,1.49741,0.04133,,,,,0.09075212121,0.03330915538
18.5,1.53874,0.04075,,,,,0.0932569697,0.03284171502
19,1.58077,0.04027,,,,,0.09580424242,0.03245486783
19.5,1.62242,0.04203,,,,,0.09832848485,0.03387330754
19.833,1.65011,0.04254,,,,,0.1000066667,0.03428433269
20.234,1.62132,0.03726,,,,,0.09826181818,0.03002901354
20.734,1.57925,0.03391,,,,,0.09571212121,0.02732914249
21.234,1.53777,0.03147,,,,,0.09319818182,0.02536266925
21.734,1.49628,0.02857,,,,,0.09068363636,0.02302546744
22.234,1.45418,0.02479,,,,,0.08813212121,0.01997904578
22.734,1.41281,0.02225,,,,,0.08562484848,0.01793197937
23.234,1.37104,0.01901,,,,,0.08309333333,0.0153207608
23.734,1.32938,0.01818,,,,,0.08056848485,0.01465183752
24.234,1.28776,0.01704,,,,,0.07804606061,0.01373307544
24.734,1.24592,0.01232,,,,,0.07551030303,0.009929078014
25.234,1.2044,0.01043,,,,,0.07299393939,0.008405867182
25.734,1.16292,0.00843,,,,,0.07048,0.006794003868
26.234,1.12073,0.00743,,,,,0.0679230303,0.005988072211
26.734,1.07952,0.00438,,,,,0.06542545455,0.003529980658
27.234,1.03786,0.00028,,,,,0.06290060606,0.000225660864
27.734,0.99592,-0.00116,,,,,0.06035878788,-0.0009348807221
28.234,0.95454,-0.00002,,,,,0.05785090909,-0.00001611863314
28.734,0.91269,-0.00181,,,,,0.05531454545,-0.001458736299
29.234,0.87103,-0.00471,,,,,0.05278969697,-0.003795938104
29.734,0.82958,-0.00551,,,,,0.05027757576,-0.00444068343
30.234,0.78756,-0.00619,,,,,0.04773090909,-0.004988716957
30.734,0.74604,-0.00679,,,,,0.04521454545,-0.005472275951
31.234,0.70451,-0.00777,,,,,0.04269757576,-0.006262088975
31.734,0.66249,-0.01317,,,,,0.04015090909,-0.01061411992
32.234,0.62114,-0.01343,,,,,0.03764484848,-0.01082366215
32.734,0.57938,-0.01466,,,,,0.03511393939,-0.01181495809
33.234,0.5377,-0.01666,,,,,0.03258787879,-0.01342682141
33.734,0.49625,-0.01738,,,,,0.03007575758,-0.0140070922
34.234,0.45416,-0.02071,,,,,0.02752484848,-0.01669084462
34.734,0.41278,-0.02228,,,,,0.0250169697,-0.01795615732
35.234,0.37128,-0.02217,,,,,0.02250181818,-0.01786750484
35.734,0.32911,-0.02283,,,,,0.01994606061,-0.01839941973
36.234,0.28776,-0.02582,,,,,0.01744,-0.02080915538
36.734,0.24624,-0.02751,,,,,0.01492363636,-0.02217117988
37.234,0.20427,-0.02826,,,,,0.01238,-0.02277562863
37.734,0.16286,-0.02858,,,,,0.00987030303,-0.02303352676
38.234,0.1209,-0.02915,,,,,0.007327272727,-0.0234929078
38.734,0.07949,-0.03286,,,,,0.004817575758,-0.02648291425
39.234,0.03788,-0.03254,,,,,0.002295757576,-0.02622501612
39.688,-0.00004,-0.03315,,,,,-0.000002424242424,-0.02671663443
39.99,0.01997,-0.031,,,,,0.00121030303,-0.02498388137
40.49,0.06176,-0.0282,,,,,0.003743030303,-0.02272727273
40.99,0.10306,-0.02493,,,,,0.006246060606,-0.02009187621
41.49,0.14518,-0.02354,,,,,0.008798787879,-0.01897163121
41.99,0.1867,-0.02268,,,,,0.01131515152,-0.01827852998
42.49,0.22819,-0.01824,,,,,0.01382969697,-0.01470019342
42.99,0.27016,-0.01777,,,,,0.01637333333,-0.01432140554
43.49,0.31156,-0.01561,,,,,0.01888242424,-0.01258059317
43.99,0.35341,-0.01435,,,,,0.02141878788,-0.01156511928
44.49,0.39516,-0.01448,,,,,0.02394909091,-0.01166989039
44.99,0.43632,-0.01066,,,,,0.02644363636,-0.008591231464
45.49,0.47852,-0.00783,,,,,0.02900121212,-0.006310444874
45.99,0.52014,-0.00836,,,,,0.03152363636,-0.006737588652
46.49,0.56134,-0.00566,,,,,0.03402060606,-0.004561573179
46.99,0.60352,-0.0039,,,,,0.0365769697,-0.003143133462
47.49,0.64498,-0.00133,,,,,0.03908969697,-0.001071889104
47.99,0.68661,-0.00118,,,,,0.04161272727,-0.0009509993553
48.49,0.72843,0.0021,,,,,0.04414727273,0.00169245648
48.99,0.76983,0.00199,,,,,0.04665636364,0.001603803997
49.49,0.81175,0.00367,,,,,0.0491969697,0.002957769181
49.99,0.85347,0.00691,,,,,0.05172545455,0.00556898775
50.49,0.89478,0.00842,,,,,0.05422909091,0.006785944552
50.99,0.93691,0.01063,,,,,0.05678242424,0.008567053514
51.49,0.97831,0.00952,,,,,0.05929151515,0.007672469375
51.99,1.01995,0.01172,,,,,0.06181515152,0.00944551902
52.49,1.06179,0.01264,,,,,0.06435090909,0.01018697614
52.99,1.10305,0.01481,,,,,0.06685151515,0.01193584784
53.49,1.1451,0.01604,,,,,0.0694,0.01292714378
53.99,1.18679,0.01756,,,,,0.07192666667,0.0141521599
54.49,1.22795,0.01815,,,,,0.07442121212,0.01462765957
54.99,1.27009,0.02057,,,,,0.07697515152,0.01657801418
55.49,1.31176,0.02262,,,,,0.07950060606,0.01823017408
55.99,1.35309,0.02479,,,,,0.08200545455,0.01997904578
56.49,1.39523,0.02529,,,,,0.08455939394,0.02038201161
56.99,1.43652,0.02729,,,,,0.08706181818,0.02199387492
57.49,1.47839,0.02849,,,,,0.08959939394,0.02296099291
57.99,1.5201,0.03022,,,,,0.09212727273,0.02435525467
58.49,1.56139,0.03222,,,,,0.09462969697,0.02596711799
58.99,1.60358,0.0311,,,,,0.09718666667,0.02506447453
59.49,1.64509,0.03293,,,,,0.09970242424,0.02653932946
59.751,1.63771,0.03217,,,,,0.09925515152,0.02592682141
60.251,1.59606,0.02871,,,,,0.09673090909,0.02313829787
60.751,1.55445,0.02267,,,,,0.09420909091,0.01827047066
61.251,1.51261,0.02055,,,,,0.09167333333,0.01656189555
61.751,1.47108,0.01658,,,,,0.08915636364,0.01336234687
62.251,1.42924,0.01491,,,,,0.08662060606,0.01201644101
62.751,1.38771,0.01243,,,,,0.08410363636,0.0100177305
63.251,1.34623,0.01027,,,,,0.08158969697,0.008276918117
63.751,1.30408,0.00838,,,,,0.07903515152,0.006753707286
64.251,1.26276,0.00404,,,,,0.07653090909,0.003255963894
64.751,1.22126,0.00432,,,,,0.07401575758,0.003481624758
65.251,1.17913,0.00288,,,,,0.07146242424,0.002321083172
65.751,1.13778,0.00141,,,,,0.06895636364,0.001136363636
66.251,1.09605,-0.00138,,,,,0.06642727273,-0.001112185687
66.751,1.0543,-0.0057,,,,,0.0638969697,-0.004593810445
67.251,1.01281,-0.00458,,,,,0.06138242424,-0.003691166989
67.751,0.97086,-0.00546,,,,,0.05884,-0.004400386847
68.251,0.92937,-0.00978,,,,,0.05632545455,-0.007882011605
68.751,0.88784,-0.0104,,,,,0.05380848485,-0.008381689233
69.251,0.84586,-0.01344,,,,,0.05126424242,-0.01083172147
69.751,0.80439,-0.01475,,,,,0.04875090909,-0.01188749194
70.251,0.76271,-0.01379,,,,,0.04622484848,-0.01111379755
70.751,0.7209,-0.01735,,,,,0.04369090909,-0.01398291425
71.251,0.6795,-0.0165,,,,,0.04118181818,-0.01329787234
71.751,0.63748,-0.01874,,,,,0.03863515152,-0.01510315925
72.251,0.59609,-0.02095,,,,,0.03612666667,-0.01688426821
72.751,0.55461,-0.02183,,,,,0.03361272727,-0.01759348807
73.251,0.5124,-0.0238,,,,,0.03105454545,-0.01918117344
73.751,0.47112,-0.02596,,,,,0.02855272727,-0.02092198582
74.251,0.42951,-0.02781,,,,,0.02603090909,-0.02241295938
74.751,0.38749,-0.02988,,,,,0.02348424242,-0.02408123791
75.251,0.34608,-0.03055,,,,,0.02097454545,-0.02462121212
75.751,0.30434,-0.03134,,,,,0.01844484848,-0.02525789813
76.251,0.26265,-0.03397,,,,,0.01591818182,-0.02737749839
76.751,0.22118,-0.03416,,,,,0.01340484848,-0.0275306254
77.251,0.17909,-0.03439,,,,,0.01085393939,-0.02771598968
77.751,0.13774,-0.03511,,,,,0.008347878788,-0.02829626048
78.251,0.09617,-0.03601,,,,,0.005828484848,-0.02902159897
78.751,0.05423,-0.03835,,,,,0.003286666667,-0.03090747905
79.251,0.01279,-0.03887,,,,,0.0007751515152,-0.03132656351
79.507,0.00229,-0.04193,,,,,0.0001387878788,-0.03379271438
80.007,0.04474,-0.03481,,,,,0.002711515152,-0.02805448098
80.507,0.08669,-0.03362,,,,,0.005253939394,-0.02709542231
81.007,0.12822,-0.03074,,,,,0.007770909091,-0.02477433914
81.507,0.16994,-0.0279,,,,,0.01029939394,-0.02248549323
82.007,0.21174,-0.02653,,,,,0.01283272727,-0.02138136686
82.507,0.25296,-0.0241,,,,,0.01533090909,-0.01942295293
83.007,0.29513,-0.02262,,,,,0.01788666667,-0.01823017408
83.507,0.3367,-0.02153,,,,,0.02040606061,-0.01735170858
84.007,0.37798,-0.01997,,,,,0.02290787879,-0.01609445519
84.507,0.42015,-0.01749,,,,,0.02546363636,-0.01409574468
85.007,0.46164,-0.01818,,,,,0.02797818182,-0.01465183752
85.507,0.50319,-0.01583,,,,,0.03049636364,-0.01275789813
86.007,0.54502,-0.01277,,,,,0.03303151515,-0.01029174726
86.507,0.58644,-0.0109,,,,,0.03554181818,-0.008784655061
87.007,0.62836,-0.01075,,,,,0.03808242424,-0.008663765313
87.507,0.67012,-0.0063,,,,,0.04061333333,-0.005077369439
88.007,0.71135,-0.00588,,,,,0.04311212121,-0.004738878143
88.507,0.7535,-0.00398,,,,,0.04566666667,-0.003207607995
89.007,0.795,-0.00299,,,,,0.04818181818,-0.002409735654
89.507,0.83646,-0.00046,,,,,0.05069454545,-0.0003707285622
90.007,0.87845,0.00001,,,,,0.05323939394,0.00000805931657
90.507,0.91975,0.00283,,,,,0.05574242424,0.002280786589
91.007,0.96168,0.0031,,,,,0.05828363636,0.002498388137
91.507,1.00346,0.00447,,,,,0.06081575758,0.003602514507
92.007,1.04463,0.00591,,,,,0.06331090909,0.004763056093
92.507,1.08679,0.00815,,,,,0.06586606061,0.006568343005
93.007,1.12844,0.00958,,,,,0.06839030303,0.007720825274
93.507,1.16971,0.01256,,,,,0.07089151515,0.01012250161
94.007,1.21177,0.0131,,,,,0.07344060606,0.01055770471
94.507,1.25328,0.01518,,,,,0.07595636364,0.01223404255
95.007,1.29494,0.01626,,,,,0.07848121212,0.01310444874
95.507,1.33676,0.01871,,,,,0.08101575758,0.0150789813
96.007,1.3781,0.019,,,,,0.08352121212,0.01531270148
96.507,1.4201,0.01896,,,,,0.08606666667,0.01528046422
97.007,1.46168,0.02179,,,,,0.08858666667,0.01756125081
97.507,1.50304,0.02287,,,,,0.09109333333,0.018431657
98.007,1.54511,0.02439,,,,,0.0936430303,0.01965667311
98.507,1.58648,0.02541,,,,,0.09615030303,0.0204787234
99.007,1.6282,0.02719,,,,,0.09867878788,0.02191328175
99.269,1.65019,0.02748,,,,,0.1000115152,0.02214700193
99.769,1.61265,0.02394,,,,,0.09773636364,0.01929400387
100.269,1.57114,0.01895,,,,,0.09522060606,0.0152724049
100.769,1.52948,0.01601,,,,,0.09269575758,0.01290296583
101.269,1.48752,0.01493,,,,,0.09015272727,0.01203255964
101.769,1.44614,0.01215,,,,,0.08764484848,0.009792069632
102.269,1.40459,0.00853,,,,,0.08512666667,0.006874597034
102.769,1.36245,0.00798,,,,,0.08257272727,0.006431334623
103.269,1.32121,0.00494,,,,,0.08007333333,0.003981302386
103.769,1.27945,0.0037,,,,,0.07754242424,0.002981947131
104.269,1.23763,0.00292,,,,,0.07500787879,0.002353320438
104.769,1.19621,0.00017,,,,,0.07249757576,0.0001370083817
105.269,1.15423,-0.00256,,,,,0.06995333333,-0.002063185042
105.769,1.11272,-0.00577,,,,,0.06743757576,-0.004650225661
106.269,1.07123,-0.00784,,,,,0.0649230303,-0.006318504191
106.769,1.02919,-0.00924,,,,,0.06237515152,-0.007446808511
107.269,0.98772,-0.01041,,,,,0.05986181818,-0.008389748549
107.769,0.94615,-0.01327,,,,,0.05734242424,-0.01069471309
108.269,0.90425,-0.01508,,,,,0.0548030303,-0.01215344939
108.769,0.86284,-0.01701,,,,,0.05229333333,-0.01370889749
109.269,0.82093,-0.01747,,,,,0.04975333333,-0.01407962605
109.769,0.77947,-0.01641,,,,,0.04724060606,-0.01322533849
110.269,0.73799,-0.0187,,,,,0.04472666667,-0.01507092199
110.769,0.69581,-0.02088,,,,,0.04217030303,-0.016827853
111.269,0.65444,-0.02389,,,,,0.0396630303,-0.01925370729
111.769,0.6129,-0.02661,,,,,0.03714545455,-0.02144584139
112.269,0.57085,-0.02656,,,,,0.0345969697,-0.02140554481
112.769,0.5294,-0.0272,,,,,0.03208484848,-0.02192134107
113.269,0.48777,-0.02837,,,,,0.02956181818,-0.02286428111
113.769,0.44597,-0.03187,,,,,0.02702848485,-0.02568504191
114.269,0.40454,-0.03208,,,,,0.02451757576,-0.02585428756
114.769,0.36253,-0.033,,,,,0.02197151515,-0.02659574468
115.269,0.32117,-0.03367,,,,,0.01946484848,-0.02713571889
115.769,0.27953,-0.035,,,,,0.01694121212,-0.02820760799
116.269,0.2375,-0.03767,,,,,0.01439393939,-0.03035944552
116.769,0.19615,-0.03983,,,,,0.01188787879,-0.0321002579
117.269,0.15441,-0.03969,,,,,0.009358181818,-0.03198742747
117.769,0.11267,-0.04034,,,,,0.006828484848,-0.03251128304
118.269,0.07125,-0.04153,,,,,0.004318181818,-0.03347034172
118.769,0.02917,-0.04336,,,,,0.001767878788,-0.03494519665
119.124,-0.00013,-0.04374,,,,,-0.000007878787879,-0.03525145068
119.525,0.02844,-0.04042,,,,,0.001723636364,-0.03257575758
120.025,0.06982,-0.03636,,,,,0.004231515152,-0.02930367505
120.525,0.11184,-0.03512,,,,,0.006778181818,-0.02830431979
121.025,0.1535,-0.0324,,,,,0.009303030303,-0.02611218569
121.525,0.19463,-0.03134,,,,,0.01179575758,-0.02525789813
122.025,0.23691,-0.03064,,,,,0.01435818182,-0.02469374597
122.525,0.27846,-0.02984,,,,,0.01687636364,-0.02404900064
123.025,0.31979,-0.02631,,,,,0.01938121212,-0.0212040619
123.525,0.36191,-0.02544,,,,,0.02193393939,-0.02050290135
124.025,0.40322,-0.02404,,,,,0.02443757576,-0.01937459703
124.525,0.44506,-0.02164,,,,,0.02697333333,-0.01744036106
125.025,0.48676,-0.01728,,,,,0.02950060606,-0.01392649903
125.525,0.52809,-0.0174,,,,,0.03200545455,-0.01402321083
126.025,0.5701,-0.0161,,,,,0.03455151515,-0.01297549968
126.525,0.61176,-0.01295,,,,,0.03707636364,-0.01043681496
127.025,0.65313,-0.01292,,,,,0.03958363636,-0.01041263701
127.525,0.69522,-0.01004,,,,,0.04213454545,-0.008091553836
128.025,0.73656,-0.00902,,,,,0.04464,-0.007269503546
128.525,0.7784,-0.00786,,,,,0.04717575758,-0.006334622824
129.025,0.82015,-0.00732,,,,,0.04970606061,-0.005899419729
129.525,0.86135,-0.00581,,,,,0.0522030303,-0.004682462927
130.025,0.90353,-0.00442,,,,,0.05475939394,-0.003562217924
130.525,0.94514,-0.00324,,,,,0.05728121212,-0.002611218569
131.025,0.98638,-0.00004,,,,,0.05978060606,-0.00003223726628
131.525,1.02842,0.00114,,,,,0.06232848485,0.000918762089
132.025,1.07006,0.00446,,,,,0.06485212121,0.00359445519
132.525,1.11155,0.00561,,,,,0.06736666667,0.004521276596
133.025,1.15356,0.0072,,,,,0.06991272727,0.00580270793
133.525,1.19477,0.01103,,,,,0.07241030303,0.008889426177
134.025,1.23681,0.01079,,,,,0.07495818182,0.008696002579
134.525,1.27843,0.01363,,,,,0.07748060606,0.01098484848
135.025,1.3197,0.01398,,,,,0.07998181818,0.01126692456
135.525,1.36189,0.0149,,,,,0.08253878788,0.01200838169
136.025,1.40339,0.01528,,,,,0.08505393939,0.01231463572
136.525,1.44487,0.01674,,,,,0.08756787879,0.01349129594
137.025,1.48689,0.02197,,,,,0.09011454545,0.0177063185
137.525,1.52817,0.02115,,,,,0.09261636364,0.01704545455
138.025,1.56997,0.0255,,,,,0.09514969697,0.02055125725
138.525,1.61192,0.02662,,,,,0.09769212121,0.02145390071
138.984,1.65,0.02554,,,,,0.1,0.02058349452
139.286,1.62977,0.02331,,,,,0.09877393939,0.01878626692
139.786,1.58812,0.0182,,,,,0.09624969697,0.01466795616
140.286,1.54592,0.014,,,,,0.09369212121,0.0112830432
140.786,1.50461,0.0126,,,,,0.09118848485,0.01015473888
141.286,1.46302,0.00917,,,,,0.08866787879,0.007390393295
141.786,1.42107,0.00654,,,,,0.08612545455,0.005270793037
142.286,1.37966,0.00653,,,,,0.08361575758,0.00526273372
142.786,1.33779,0.00457,,,,,0.08107818182,0.003683107672
143.286,1.29619,0.00227,,,,,0.0785569697,0.001829464861
143.786,1.25473,0.00024,,,,,0.07604424242,0.0001934235977
144.286,1.21264,-0.00306,,,,,0.07349333333,-0.00246615087
144.786,1.17127,-0.0042,,,,,0.07098606061,-0.003384912959
145.286,1.12964,-0.00738,,,,,0.0684630303,-0.005947775629
145.786,1.08783,-0.00971,,,,,0.06592909091,-0.007825596389
146.286,1.04627,-0.00973,,,,,0.06341030303,-0.007841715023
146.786,1.00448,-0.01214,,,,,0.06087757576,-0.009784010316
147.286,0.96288,-0.01627,,,,,0.05835636364,-0.01311250806
147.786,0.92141,-0.01533,,,,,0.0558430303,-0.0123549323
148.286,0.87922,-0.01738,,,,,0.05328606061,-0.0140070922
148.786,0.838,-0.01847,,,,,0.05078787879,-0.0148855577
149.286,0.79639,-0.02045,,,,,0.04826606061,-0.01648130239
149.786,0.75432,-0.019,,,,,0.04571636364,-0.01531270148
150.286,0.71297,-0.02723,,,,,0.04321030303,-0.02194551902
150.786,0.67124,-0.02381,,,,,0.04068121212,-0.01918923275
151.286,0.62945,-0.02599,,,,,0.03814848485,-0.02094616377
151.786,0.58803,-0.02641,,,,,0.03563818182,-0.02128465506
152.286,0.54611,-0.02909,,,,,0.03309757576,-0.0234445519
152.786,0.50455,-0.03205,,,,,0.03057878788,-0.02583010961
153.286,0.46309,-0.03273,,,,,0.02806606061,-0.02637814313
153.786,0.42098,-0.03387,,,,,0.02551393939,-0.02729690522
154.286,0.37965,-0.03552,,,,,0.02300909091,-0.02862669246
154.786,0.33795,-0.03747,,,,,0.02048181818,-0.03019825919
155.286,0.29617,-0.0393,,,,,0.01794969697,-0.03167311412
155.786,0.25468,-0.04175,,,,,0.01543515152,-0.03364764668
156.286,0.21271,-0.04108,,,,,0.01289151515,-0.03310767247
156.786,0.17125,-0.04278,,,,,0.01037878788,-0.03447775629
157.286,0.12975,-0.0443,,,,,0.007863636364,-0.0357027724
157.786,0.08761,-0.04531,,,,,0.00530969697,-0.03651676338
158.286,0.04625,-0.04501,,,,,0.002803030303,-0.03627498388
158.786,0.00475,-0.0474,,,,,0.0002878787879,-0.03820116054
159.044,0.01112,-0.0458,,,,,0.0006739393939,-0.03691166989
159.544,0.05351,-0.04273,,,,,0.003243030303,-0.0344374597
160.044,0.09507,-0.04057,,,,,0.005761818182,-0.03269664732
160.544,0.13643,-0.03618,,,,,0.008268484848,-0.02915860735
161.044,0.17849,-0.03669,,,,,0.01081757576,-0.0295696325
161.544,0.21994,-0.03295,,,,,0.01332969697,-0.0265554481
162.044,0.26166,-0.03073,,,,,0.01585818182,-0.02476627982
162.544,0.30336,-0.02996,,,,,0.01838545455,-0.02414571244
163.044,0.34473,-0.02784,,,,,0.02089272727,-0.02243713733
163.544,0.38679,-0.02674,,,,,0.02344181818,-0.02155061251
164.044,0.42841,-0.02533,,,,,0.02596424242,-0.02041424887
164.544,0.4697,-0.02159,,,,,0.02846666667,-0.01740006447
165.044,0.51182,-0.02013,,,,,0.03101939394,-0.01622340426
165.544,0.55331,-0.01935,,,,,0.03353393939,-0.01559477756
166.044,0.59495,-0.01806,,,,,0.03605757576,-0.01455512573
166.544,0.63683,-0.01569,,,,,0.03859575758,-0.0126450677
167.044,0.67805,-0.01541,,,,,0.04109393939,-0.01241940683
167.544,0.72016,-0.01297,,,,,0.04364606061,-0.01045293359
168.044,0.76184,-0.0105,,,,,0.04617212121,-0.008462282398
168.544,0.80299,-0.00912,,,,,0.04866606061,-0.007350096712
169.044,0.84514,-0.00832,,,,,0.05122060606,-0.006705351386
169.544,0.88672,-0.00634,,,,,0.05374060606,-0.005109606705
170.044,0.92817,-0.00489,,,,,0.05625272727,-0.003941005803
170.544,0.9701,-0.0018,,,,,0.05879393939,-0.001450676983
171.044,1.0115,-0.00045,,,,,0.0613030303,-0.0003626692456
171.544,1.05333,-0.00071,,,,,0.06383818182,-0.0005722114765
172.044,1.09514,0.00008,,,,,0.06637212121,0.00006447453256
172.544,1.13638,0.00354,,,,,0.06887151515,0.002852998066
173.044,1.1785,0.00428,,,,,0.07142424242,0.003449387492
173.544,1.22001,0.00662,,,,,0.07394,0.005335267569
174.044,1.26151,0.00781,,,,,0.07645515152,0.006294326241
174.544,1.30349,0.00872,,,,,0.07899939394,0.007027724049
175.044,1.34476,0.01175,,,,,0.08150060606,0.00946969697
175.544,1.38671,0.01226,,,,,0.0840430303,0.009880722115
176.044,1.42847,0.01404,,,,,0.08657393939,0.01131528046
176.544,1.46965,0.01622,,,,,0.08906969697,0.01307221148
177.044,1.51171,0.01868,,,,,0.09161878788,0.01505480335
177.544,1.55343,0.02052,,,,,0.09414727273,0.0165377176
178.044,1.5946,0.02356,,,,,0.09664242424,0.01898774984
178.544,1.63688,0.02332,,,,,0.09920484848,0.01879432624
178.806,1.64713,0.02526,,,,,0.09982606061,0.02035783366
179.306,1.60451,0.01851,,,,,0.0972430303,0.01491779497
179.806,1.56315,0.01553,,,,,0.09473636364,0.01251611863
180.306,1.52121,0.01311,,,,,0.09219454545,0.01056576402
180.806,1.47961,0.00975,,,,,0.08967333333,0.007857833656
181.306,1.43821,0.00695,,,,,0.08716424242,0.005601225016
181.806,1.39609,0.00575,,,,,0.08461151515,0.004634107028
182.306,1.35467,0.00116,,,,,0.08210121212,0.0009348807221
182.806,1.31312,-0.0005,,,,,0.0795830303,-0.0004029658285
183.306,1.27119,-0.0037,,,,,0.07704181818,-0.002981947131
183.806,1.22967,-0.00483,,,,,0.07452545455,-0.003892649903
184.306,1.18792,-0.00543,,,,,0.07199515152,-0.004376208897
184.806,1.14625,-0.00968,,,,,0.06946969697,-0.00780141844
185.306,1.10485,-0.0121,,,,,0.06696060606,-0.00975177305
185.806,1.06272,-0.0121,,,,,0.06440727273,-0.00975177305
186.306,1.02137,-0.0142,,,,,0.06190121212,-0.01144422953
186.806,0.97989,-0.01576,,,,,0.05938727273,-0.01270148291
187.306,0.93772,-0.0172,,,,,0.05683151515,-0.0138620245
187.806,0.89638,-0.01895,,,,,0.05432606061,-0.0152724049
188.306,0.85469,-0.01914,,,,,0.05179939394,-0.01542553191
188.806,0.81287,-0.02171,,,,,0.04926484848,-0.01749677627
189.306,0.77142,-0.0231,,,,,0.04675272727,-0.01861702128
189.806,0.72954,-0.02368,,,,,0.04421454545,-0.01908446164
190.306,0.68802,-0.02669,,,,,0.04169818182,-0.02151031593
190.806,0.64648,-0.02798,,,,,0.03918060606,-0.02254996776
191.306,0.60447,-0.03029,,,,,0.03663454545,-0.02441166989
191.806,0.56305,-0.03069,,,,,0.03412424242,-0.02473404255
192.306,0.52135,-0.03403,,,,,0.0315969697,-0.02742585429
192.806,0.47945,-0.03345,,,,,0.02905757576,-0.02695841393
193.306,0.43808,-0.03466,,,,,0.02655030303,-0.02793359123
193.806,0.39614,-0.03808,,,,,0.02400848485,-0.0306898775
194.306,0.35466,-0.03858,,,,,0.02149454545,-0.03109284333
194.806,0.31319,-0.03926,,,,,0.01898121212,-0.03164087685
195.306,0.271,-0.0392,,,,,0.01642424242,-0.03159252095
195.806,0.2297,-0.04112,,,,,0.01392121212,-0.03313990974
196.306,0.18815,-0.04315,,,,,0.0114030303,-0.034775951
196.806,0.14609,-0.04503,,,,,0.008853939394,-0.03629110251
197.306,0.10469,-0.0463,,,,,0.006344848485,-0.03731463572
197.806,0.06302,-0.04725,,,,,0.003819393939,-0.03808027079
198.306,0.02122,-0.04831,,,,,0.001286060606,-0.03893455835
198.565,-0.00022,-0.04917,,,,,-0.00001333333333,-0.03962765957
199.065,0.03661,-0.04492,,,,,0.002218787879,-0.03620245003
199.565,0.07818,-0.04223,,,,,0.004738181818,-0.03403449387
200.065,0.12014,-0.04159,,,,,0.007281212121,-0.03351869761
200.565,0.1614,-0.03906,,,,,0.009781818182,-0.03147969052
201.065,0.20337,-0.03621,,,,,0.01232545455,-0.0291827853
201.565,0.24503,-0.03475,,,,,0.01485030303,-0.02800612508
202.065,0.28643,-0.03416,,,,,0.01735939394,-0.0275306254
202.565,0.32839,-0.03195,,,,,0.01990242424,-0.02574951644
203.065,0.37004,-0.02938,,,,,0.02242666667,-0.02367827208
203.565,0.41152,-0.02621,,,,,0.02494060606,-0.02112346873
204.065,0.45352,-0.02475,,,,,0.02748606061,-0.01994680851
204.565,0.49475,-0.02282,,,,,0.02998484848,-0.01839136041
205.065,0.53678,-0.02201,,,,,0.03253212121,-0.01773855577
205.565,0.57844,-0.02058,,,,,0.0350569697,-0.0165860735
206.065,0.61964,-0.01817,,,,,0.03755393939,-0.01464377821
206.565,0.66186,-0.01556,,,,,0.04011272727,-0.01254029658
207.065,0.7034,-0.01383,,,,,0.04263030303,-0.01114603482
207.565,0.74473,-0.01273,,,,,0.04513515152,-0.01025950999
208.065,0.78672,-0.01185,,,,,0.04768,-0.009550290135
208.565,0.82823,-0.00945,,,,,0.05019575758,-0.007616054159
209.065,0.86997,-0.00936,,,,,0.05272545455,-0.007543520309
209.565,0.91184,-0.00654,,,,,0.0552630303,-0.005270793037
210.065,0.95301,-0.00715,,,,,0.05775818182,-0.005762411348
210.565,0.9952,-0.00594,,,,,0.06031515152,-0.004787234043
211.065,1.03675,-0.00342,,,,,0.06283333333,-0.002756286267
211.565,1.07811,-0.00132,,,,,0.06534,-0.001063829787
212.065,1.12016,0.00075,,,,,0.06788848485,0.0006044487427
212.565,1.16159,0.00174,,,,,0.07039939394,0.001402321083
213.065,1.2033,0.00349,,,,,0.07292727273,0.002812701483
213.565,1.24516,0.00597,,,,,0.07546424242,0.004811411992
214.065,1.28635,0.00744,,,,,0.07796060606,0.005996131528
214.565,1.32835,0.0102,,,,,0.08050606061,0.008220502901
215.065,1.37013,0.01194,,,,,0.08303818182,0.009622823985
215.565,1.41133,0.01262,,,,,0.08553515152,0.01017085751
216.065,1.45348,0.01541,,,,,0.08808969697,0.01241940683
216.565,1.49506,0.01566,,,,,0.09060969697,0.01262088975
217.065,1.53652,0.01749,,,,,0.09312242424,0.01409574468
217.565,1.57844,0.01861,,,,,0.0956630303,0.01499838814
218.065,1.61993,0.01901,,,,,0.09817757576,0.0153207608
218.426,1.65012,0.0214,,,,,0.1000072727,0.01724693746
218.827,1.62156,0.01634,,,,,0.09827636364,0.01316892328
219.327,1.57949,0.01417,,,,,0.09572666667,0.01142005158
219.827,1.53803,0.01073,,,,,0.09321393939,0.00864764668
220.327,1.4965,0.00801,,,,,0.0906969697,0.006455512573
220.827,1.45444,0.00507,,,,,0.08814787879,0.004086073501
221.327,1.41305,0.00357,,,,,0.08563939394,0.002877176015
221.827,1.37128,0.00164,,,,,0.08310787879,0.001321727917
222.327,1.32969,-0.0027,,,,,0.08058727273,-0.002176015474
222.827,1.28804,-0.0025,,,,,0.0780630303,-0.002014829142
223.327,1.24616,-0.00515,,,,,0.07552484848,-0.004150548034
223.827,1.20468,-0.00773,,,,,0.07301090909,-0.006229851709
224.327,1.16318,-0.00862,,,,,0.07049575758,-0.006947130883
224.827,1.12101,-0.0099,,,,,0.06794,-0.007978723404
225.327,1.07976,-0.01342,,,,,0.06544,-0.01081560284
225.827,1.03808,-0.01505,,,,,0.06291393939,-0.01212927144
226.327,0.99618,-0.0165,,,,,0.06037454545,-0.01329787234
226.827,0.95481,-0.01928,,,,,0.05786727273,-0.01553836235
227.327,0.91291,-0.01934,,,,,0.05532787879,-0.01558671825
227.827,0.8713,-0.023,,,,,0.05280606061,-0.01853642811
228.327,0.82986,-0.02273,,,,,0.05029454545,-0.01831882656
228.827,0.7878,-0.02399,,,,,0.04774545455,-0.01933430045
229.327,0.7463,-0.02585,,,,,0.04523030303,-0.02083333333
229.827,0.70476,-0.02956,,,,,0.04271272727,-0.02382333978
230.327,0.66278,-0.02971,,,,,0.04016848485,-0.02394422953
230.827,0.62142,-0.02986,,,,,0.03766181818,-0.02406511928
231.327,0.57959,-0.03191,,,,,0.03512666667,-0.02571727917
231.827,0.53797,-0.0338,,,,,0.03260424242,-0.02724049001
232.327,0.49653,-0.03363,,,,,0.03009272727,-0.02710348162
232.827,0.4544,-0.03609,,,,,0.02753939394,-0.0290860735
233.327,0.41303,-0.03671,,,,,0.02503212121,-0.02958575113
233.827,0.37153,-0.0384,,,,,0.0225169697,-0.03094777563
234.327,0.32939,-0.04029,,,,,0.0199630303,-0.03247098646
234.827,0.28803,-0.04146,,,,,0.01745636364,-0.0334139265
235.327,0.24646,-0.04397,,,,,0.0149369697,-0.03543681496
235.827,0.20457,-0.04598,,,,,0.01239818182,-0.03705673759
236.327,0.16311,-0.04538,,,,,0.009885454545,-0.03657317859
236.827,0.12113,-0.047,,,,,0.007341212121,-0.03787878788
237.327,0.07976,-0.0497,,,,,0.004833939394,-0.04005480335
237.827,0.03812,-0.05034,,,,,0.00231030303,-0.04057059961
238.284,-0.00003,-0.05105,,,,,-0.000001818181818,-0.04114281109
238.586,0.01994,-0.05092,,,,,0.001208484848,-0.04103803997
239.086,0.06172,-0.04815,,,,,0.003740606061,-0.03880560928
239.586,0.10304,-0.04359,,,,,0.006244848485,-0.03513056093
240.086,0.14513,-0.04145,,,,,0.008795757576,-0.03340586718
240.586,0.18668,-0.03926,,,,,0.01131393939,-0.03164087685
241.086,0.22816,-0.03678,,,,,0.01382787879,-0.02964216634
241.586,0.27012,-0.0365,,,,,0.01637090909,-0.02941650548
242.086,0.31152,-0.03425,,,,,0.01888,-0.02760315925
242.586,0.35337,-0.03031,,,,,0.02141636364,-0.02442778852
243.086,0.39514,-0.02994,,,,,0.02394787879,-0.02412959381
243.586,0.43626,-0.03102,,,,,0.02644,-0.025
244.086,0.47849,-0.02444,,,,,0.02899939394,-0.0196969697
244.586,0.52011,-0.02585,,,,,0.03152181818,-0.02083333333
245.086,0.56133,-0.02099,,,,,0.03402,-0.01691650548
245.586,0.60351,-0.02152,,,,,0.03657636364,-0.01734364926
246.086,0.64495,-0.01986,,,,,0.03908787879,-0.01600580271
246.586,0.68659,-0.01947,,,,,0.04161151515,-0.01569148936
247.086,0.72838,-0.01649,,,,,0.04414424242,-0.01328981302
247.586,0.76978,-0.01381,,,,,0.04665333333,-0.01112991618
248.086,0.81172,-0.01224,,,,,0.04919515152,-0.009864603482
248.586,0.85344,-0.01053,,,,,0.05172363636,-0.008486460348
249.086,0.89474,-0.01012,,,,,0.05422666667,-0.008156028369
249.586,0.93688,-0.00737,,,,,0.05678060606,-0.005939716312
250.086,0.97827,-0.00482,,,,,0.05928909091,-0.003884590587
250.586,1.01992,-0.00409,,,,,0.06181333333,-0.003296260477
251.086,1.06176,-0.00327,,,,,0.06434909091,-0.002635396518
251.586,1.10301,-0.00202,,,,,0.06684909091,-0.001627981947
252.086,1.14508,-0.00143,,,,,0.06939878788,-0.00115248227
252.586,1.18675,0.00059,,,,,0.07192424242,0.0004754996776
253.086,1.22794,0.00418,,,,,0.07442060606,0.003368794326
253.586,1.27004,0.00368,,,,,0.07697212121,0.002965828498
254.086,1.31176,0.00575,,,,,0.07950060606,0.004634107028
254.586,1.35308,0.00817,,,,,0.08200484848,0.006584461638
255.086,1.3952,0.00812,,,,,0.08455757576,0.006544165055
255.586,1.43648,0.01138,,,,,0.08705939394,0.009171502257
256.086,1.47837,0.01244,,,,,0.08959818182,0.01002578981
256.586,1.52006,0.01401,,,,,0.09212484848,0.01129110251
257.086,1.56137,0.01633,,,,,0.09462848485,0.01316086396
257.586,1.6035,0.01819,,,,,0.09718181818,0.01465989684
258.086,1.64508,0.02072,,,,,0.09970181818,0.01669890393
258.348,1.63801,0.01811,,,,,0.09927333333,0.01459542231
258.848,1.59636,0.01381,,,,,0.09674909091,0.01112991618
259.348,1.5547,0.00979,,,,,0.09422424242,0.007890070922
259.848,1.51293,0.00828,,,,,0.09169272727,0.00667311412
260.348,1.47139,0.00527,,,,,0.08917515152,0.004247259832
260.848,1.42948,0.00517,,,,,0.08663515152,0.004166666667
261.348,1.38802,0.00157,,,,,0.08412242424,0.001265312701
261.848,1.34651,-0.00111,,,,,0.08160666667,-0.0008945841393
262.348,1.30438,-0.00497,,,,,0.07905333333,-0.004005480335
262.848,1.26304,-0.00628,,,,,0.07654787879,-0.005061250806
263.348,1.22152,-0.00787,,,,,0.07403151515,-0.006342682141
263.848,1.17942,-0.00993,,,,,0.07148,-0.008002901354
264.348,1.13808,-0.0138,,,,,0.06897454545,-0.01112185687
264.848,1.09629,-0.01404,,,,,0.06644181818,-0.01131528046
265.348,1.05462,-0.01695,,,,,0.06391636364,-0.01366054159
265.848,1.01313,-0.01851,,,,,0.06140181818,-0.01491779497
266.348,0.9711,-0.01859,,,,,0.05885454545,-0.0149822695
266.848,0.92966,-0.02002,,,,,0.0563430303,-0.01613475177
267.348,0.8881,-0.02243,,,,,0.05382424242,-0.01807704707
267.848,0.84616,-0.02481,,,,,0.05128242424,-0.01999516441
268.348,0.80466,-0.02457,,,,,0.04876727273,-0.01980174081
268.848,0.76298,-0.02756,,,,,0.04624121212,-0.02221147647
269.348,0.72123,-0.02814,,,,,0.04371090909,-0.02267891683
269.848,0.67981,-0.02994,,,,,0.04120060606,-0.02412959381
270.348,0.63772,-0.03212,,,,,0.03864969697,-0.02588652482
270.848,0.5964,-0.03457,,,,,0.03614545455,-0.02786105738
271.348,0.55488,-0.03452,,,,,0.03362909091,-0.0278207608
271.848,0.51268,-0.03601,,,,,0.03107151515,-0.02902159897
272.348,0.4714,-0.03639,,,,,0.02856969697,-0.029327853
272.848,0.42975,-0.03991,,,,,0.02604545455,-0.03216473243
273.348,0.3878,-0.04109,,,,,0.0235030303,-0.03311573179
273.848,0.34642,-0.0416,,,,,0.02099515152,-0.03352675693
274.348,0.30458,-0.0435,,,,,0.01845939394,-0.03505802708
274.848,0.26294,-0.04391,,,,,0.01593575758,-0.03538845906
275.348,0.22147,-0.04362,,,,,0.01342242424,-0.03515473888
275.848,0.17937,-0.04665,,,,,0.01087090909,-0.0375967118
276.348,0.13805,-0.04612,,,,,0.008366666667,-0.03716956802
276.848,0.09642,-0.05098,,,,,0.005843636364,-0.04108639587
277.348,0.05452,-0.05008,,,,,0.003304242424,-0.04036105738
277.848,0.01309,-0.05222,,,,,0.0007933333333,-0.04208575113
278.107,0.00228,-0.05016,,,,,0.0001381818182,-0.04042553191
278.607,0.04475,-0.04624,,,,,0.002712121212,-0.03726627982
279.107,0.0867,-0.0442,,,,,0.005254545455,-0.03562217924
279.607,0.12823,-0.04131,,,,,0.007771515152,-0.03329303675
280.107,0.16995,-0.04165,,,,,0.0103,-0.03356705351
280.607,0.21177,-0.03907,,,,,0.01283454545,-0.03148774984
281.107,0.25294,-0.03604,,,,,0.01532969697,-0.02904577692
281.607,0.29514,-0.03706,,,,,0.01788727273,-0.02986782721
282.107,0.33672,-0.03498,,,,,0.02040727273,-0.02819148936
282.607,0.37798,-0.03401,,,,,0.02290787879,-0.02740973565
283.107,0.42016,-0.03178,,,,,0.02546424242,-0.02561250806
283.607,0.46167,-0.02875,,,,,0.02798,-0.02317053514
284.107,0.50321,-0.0261,,,,,0.03049757576,-0.02103481625
284.607,0.54503,-0.02431,,,,,0.03303212121,-0.01959219858
285.107,0.58645,-0.02441,,,,,0.03554242424,-0.01967279175
285.607,0.62837,-0.02196,,,,,0.0380830303,-0.01769825919
286.107,0.67013,-0.0191,,,,,0.04061393939,-0.01539329465
286.607,0.71135,-0.01707,,,,,0.04311212121,-0.01375725338
287.107,0.75352,-0.01654,,,,,0.04566787879,-0.01333010961
287.607,0.79501,-0.01688,,,,,0.04818242424,-0.01360412637
288.107,0.83647,-0.01296,,,,,0.05069515152,-0.01044487427
288.607,0.87847,-0.01081,,,,,0.05324060606,-0.008712121212
289.107,0.91976,-0.00942,,,,,0.0557430303,-0.007591876209
289.607,0.96168,-0.00946,,,,,0.05828363636,-0.007624113475
290.107,1.00347,-0.00801,,,,,0.06081636364,-0.006455512573
290.607,1.04464,-0.00668,,,,,0.06331151515,-0.005383623469
291.107,1.08679,-0.00483,,,,,0.06586606061,-0.003892649903
291.607,1.12843,-0.00208,,,,,0.06838969697,-0.001676337847
292.107,1.16975,-0.00102,,,,,0.07089393939,-0.0008220502901
292.607,1.21177,0.00106,,,,,0.07344060606,0.0008542875564
293.107,1.25328,0.00196,,,,,0.07595636364,0.001579626048
293.607,1.29494,0.00221,,,,,0.07848121212,0.001781108962
294.107,1.33681,0.00611,,,,,0.08101878788,0.004924242424
294.607,1.37809,0.00919,,,,,0.08352060606,0.007406511928
295.107,1.42012,0.00649,,,,,0.08606787879,0.005230496454
295.607,1.46167,0.0109,,,,,0.08858606061,0.008784655061
296.107,1.50306,0.01252,,,,,0.09109454545,0.01009026435
296.607,1.5451,0.01555,,,,,0.09364242424,0.01253223727
297.107,1.58651,0.01662,,,,,0.09615212121,0.01339458414
297.607,1.62822,0.01727,,,,,0.09868,0.01391843972
297.869,1.65019,0.01906,,,,,0.1000115152,0.01536105738
298.369,1.61289,0.01494,,,,,0.09775090909,0.01204061896
298.869,1.57142,0.00971,,,,,0.09523757576,0.007825596389
299.369,1.52976,0.00712,,,,,0.09271272727,0.005738233398
299.869,1.48778,0.00613,,,,,0.09016848485,0.004940361057
300.369,1.44643,0.0029,,,,,0.08766242424,0.002337201805
300.869,1.40483,-0.00101,,,,,0.08514121212,-0.0008139909736
301.369,1.36276,-0.00255,,,,,0.08259151515,-0.002055125725
301.869,1.32149,-0.00394,,,,,0.08009030303,-0.003175370729
302.369,1.27967,-0.0058,,,,,0.07755575758,-0.004674403611
302.869,1.23793,-0.00808,,,,,0.07502606061,-0.006511927789
303.369,1.19651,-0.01065,,,,,0.07251575758,-0.008583172147
303.869,1.15448,-0.01129,,,,,0.06996848485,-0.009098968407
304.369,1.113,-0.01391,,,,,0.06745454545,-0.01121050935
304.869,1.07151,-0.0149,,,,,0.06494,-0.01200838169
305.369,1.02947,-0.01664,,,,,0.06239212121,-0.01341070277
305.869,0.98798,-0.01859,,,,,0.05987757576,-0.0149822695
306.369,0.94637,-0.02223,,,,,0.05735575758,-0.01791586074
306.869,0.90457,-0.02176,,,,,0.05482242424,-0.01753707286
307.369,0.86313,-0.02513,,,,,0.05231090909,-0.02025306254
307.869,0.82118,-0.02565,,,,,0.04976848485,-0.020672147
308.369,0.77975,-0.02842,,,,,0.04725757576,-0.02290457769
308.869,0.73827,-0.03131,,,,,0.04474363636,-0.02523372018
309.369,0.69607,-0.03244,,,,,0.04218606061,-0.02614442295
309.869,0.65474,-0.03289,,,,,0.03968121212,-0.0265070922
310.369,0.61314,-0.03276,,,,,0.03716,-0.02640232108
310.869,0.57116,-0.03527,,,,,0.03461575758,-0.02842520954
311.369,0.52968,-0.03643,,,,,0.03210181818,-0.02936009026
311.869,0.48797,-0.03705,,,,,0.02957393939,-0.02985976789
312.369,0.44629,-0.03923,,,,,0.02704787879,-0.0316166989
312.869,0.40483,-0.0387,,,,,0.02453515152,-0.03118955513
313.369,0.36278,-0.04123,,,,,0.02198666667,-0.03322856222
313.869,0.32143,-0.04268,,,,,0.01948060606,-0.03439716312
314.369,0.2798,-0.04492,,,,,0.01695757576,-0.03620245003
314.869,0.23779,-0.04624,,,,,0.01441151515,-0.03726627982
315.369,0.19642,-0.04673,,,,,0.01190424242,-0.03766118633
315.869,0.15465,-0.04811,,,,,0.009372727273,-0.03877337202
316.369,0.11297,-0.05036,,,,,0.006846666667,-0.04058671825
316.869,0.07155,-0.05217,,,,,0.004336363636,-0.04204545455
317.369,0.0294,-0.05286,,,,,0.001781818182,-0.04260154739
317.727,-0.00009,-0.05431,,,,,-0.000005454545455,-0.04377014829
318.128,0.02838,-0.05017,,,,,0.00172,-0.04043359123
318.628,0.06972,-0.0474,,,,,0.004225454545,-0.03820116054
319.128,0.11176,-0.04655,,,,,0.006773333333,-0.03751611863
319.628,0.15344,-0.0438,,,,,0.009299393939,-0.03529980658
320.128,0.19457,-0.04077,,,,,0.01179212121,-0.03285783366
320.628,0.23686,-0.04082,,,,,0.01435515152,-0.03289813024
321.128,0.27839,-0.03915,,,,,0.01687212121,-0.03155222437
321.628,0.31973,-0.03526,,,,,0.01937757576,-0.02841715023
322.128,0.36183,-0.03261,,,,,0.02192909091,-0.02628143133
322.628,0.40314,-0.03177,,,,,0.02443272727,-0.02560444874
323.128,0.445,-0.03183,,,,,0.02696969697,-0.02565280464
323.628,0.48668,-0.02875,,,,,0.02949575758,-0.02317053514
324.128,0.52802,-0.02709,,,,,0.03200121212,-0.02183268859
324.628,0.57002,-0.02507,,,,,0.03454666667,-0.02020470664
325.128,0.6117,-0.02501,,,,,0.03707272727,-0.02015635074
325.628,0.65306,-0.02253,,,,,0.03957939394,-0.01815764023
326.128,0.69515,-0.01921,,,,,0.04213030303,-0.01548194713
326.628,0.73648,-0.01988,,,,,0.04463515152,-0.01602192134
327.128,0.77833,-0.01751,,,,,0.04717151515,-0.01411186331
327.628,0.82007,-0.016,,,,,0.04970121212,-0.01289490651
328.128,0.86128,-0.01258,,,,,0.05219878788,-0.01013862025
328.628,0.90347,-0.0125,,,,,0.05475575758,-0.01007414571
329.128,0.94508,-0.01013,,,,,0.05727757576,-0.008164087685
329.628,0.98632,-0.00778,,,,,0.0597769697,-0.006270148291
330.128,1.02835,-0.00671,,,,,0.06232424242,-0.005407801418
330.628,1.06996,-0.00447,,,,,0.06484606061,-0.003602514507
331.128,1.11152,-0.00283,,,,,0.06736484848,-0.002280786589
331.628,1.15348,-0.00271,,,,,0.06990787879,-0.00218407479
332.128,1.19468,-0.00097,,,,,0.07240484848,-0.0007817537073
332.628,1.23674,-0.00031,,,,,0.07495393939,-0.0002498388137
333.128,1.27838,0.00317,,,,,0.07747757576,0.002554803353
333.628,1.31966,0.00399,,,,,0.07997939394,0.003215667311
334.128,1.36183,0.00438,,,,,0.08253515152,0.003529980658
334.628,1.40332,0.00612,,,,,0.08504969697,0.004932301741
335.128,1.44483,0.00757,,,,,0.08756545455,0.006100902643
335.628,1.48681,0.01082,,,,,0.09010969697,0.008720180529
336.128,1.52812,0.01219,,,,,0.09261333333,0.009824306899
336.628,1.56995,0.01244,,,,,0.09514848485,0.01002578981
337.128,1.61182,0.01487,,,,,0.09768606061,0.01198420374
337.588,1.65,0.0174,,,,,0.1,0.01402321083
337.89,1.62987,0.01168,,,,,0.09878,0.009413281754
338.39,1.5882,0.00812,,,,,0.09625454545,0.006544165055
338.89,1.54602,0.00615,,,,,0.09369818182,0.004956479691
339.39,1.50469,0.00494,,,,,0.09119333333,0.003981302386
339.89,1.46308,0.00017,,,,,0.08867151515,0.0001370083817
340.39,1.42117,-0.00171,,,,,0.08613151515,-0.001378143133
340.89,1.37973,-0.00251,,,,,0.08362,-0.002022888459
341.39,1.33786,-0.00469,,,,,0.08108242424,-0.003779819471
341.89,1.29628,-0.0065,,,,,0.07856242424,-0.00523855577
342.39,1.25478,-0.00865,,,,,0.07604727273,-0.006971308833
342.89,1.2127,-0.00855,,,,,0.0734969697,-0.006890715667
343.39,1.17135,-0.01119,,,,,0.07099090909,-0.009018375242
343.89,1.12969,-0.01288,,,,,0.06846606061,-0.01038039974
344.39,1.08793,-0.01676,,,,,0.06593515152,-0.01350741457
344.89,1.04633,-0.01708,,,,,0.06341393939,-0.0137653127
345.39,1.00455,-0.01906,,,,,0.06088181818,-0.01536105738
345.89,0.96297,-0.02309,,,,,0.05836181818,-0.01860896196
346.39,0.92151,-0.02324,,,,,0.05584909091,-0.01872985171
346.89,0.87931,-0.02496,,,,,0.05329151515,-0.02011605416
347.39,0.83807,-0.0269,,,,,0.05079212121,-0.02167956157
347.89,0.79645,-0.02865,,,,,0.04826969697,-0.02308994197
348.39,0.75437,-0.02976,,,,,0.04571939394,-0.02398452611
348.89,0.71306,-0.0311,,,,,0.04321575758,-0.02506447453
349.39,0.6713,-0.03048,,,,,0.04068484848,-0.02456479691
349.89,0.62954,-0.0339,,,,,0.03815393939,-0.02732108317
350.39,0.5881,-0.03594,,,,,0.03564242424,-0.02896518375
350.89,0.54619,-0.03796,,,,,0.03310242424,-0.0305931657
351.39,0.50464,-0.03776,,,,,0.03058424242,-0.03043197937
351.89,0.46317,-0.04114,,,,,0.02807090909,-0.03315602837
352.39,0.42106,-0.04358,,,,,0.02551878788,-0.03512250161
352.89,0.37971,-0.04571,,,,,0.02301272727,-0.03683913604
353.39,0.338,-0.04634,,,,,0.02048484848,-0.03734687299
353.89,0.29625,-0.04496,,,,,0.01795454545,-0.0362346873
354.39,0.25478,-0.04757,,,,,0.01544121212,-0.03833816892
354.89,0.21278,-0.04761,,,,,0.01289575758,-0.03837040619
355.39,0.17132,-0.04868,,,,,0.0103830303,-0.03923275306
355.89,0.12982,-0.04925,,,,,0.007867878788,-0.03969213411
356.39,0.08768,-0.05308,,,,,0.005313939394,-0.04277885235
356.89,0.04633,-0.05335,,,,,0.002807878788,-0.0429964539
357.39,0.00484,-0.05367,,,,,0.0002933333333,-0.04325435203
357.649,0.01106,-0.0495,,,,,0.0006703030303,-0.03989361702
358.149,0.05343,-0.0481,,,,,0.003238181818,-0.0387653127
358.649,0.09499,-0.04766,,,,,0.005756969697,-0.03841070277
359.149,0.13635,-0.04473,,,,,0.008263636364,-0.03604932302
359.649,0.1784,-0.04306,,,,,0.01081212121,-0.03470341715
360.149,0.21984,-0.03607,,,,,0.01332363636,-0.02906995487
360.649,0.26161,-0.03975,,,,,0.01585515152,-0.03203578337
361.149,0.3033,-0.03501,,,,,0.01838181818,-0.02821566731
361.649,0.34465,-0.03779,,,,,0.02088787879,-0.03045615732
362.149,0.38671,-0.03405,,,,,0.0234369697,-0.02744197292
362.649,0.42834,-0.03208,,,,,0.02596,-0.02585428756
363.149,0.46966,-0.03103,,,,,0.02846424242,-0.02500805932
363.649,0.51176,-0.029,,,,,0.03101575758,-0.02337201805
364.149,0.55323,-0.0287,,,,,0.03352909091,-0.02313023856
364.649,0.59488,-0.02627,,,,,0.03605333333,-0.02117182463
365.149,0.63676,-0.02512,,,,,0.03859151515,-0.02024500322
365.649,0.67796,-0.02234,,,,,0.04108848485,-0.01800451322
366.149,0.72009,-0.02028,,,,,0.04364181818,-0.016344294
366.649,0.76177,-0.01902,,,,,0.04616787879,-0.01532882012
367.149,0.8029,-0.01562,,,,,0.04866060606,-0.01258865248
367.649,0.84508,-0.01497,,,,,0.0512169697,-0.01206479691
368.149,0.88664,-0.01401,,,,,0.05373575758,-0.01129110251
368.649,0.9281,-0.01136,,,,,0.05624848485,-0.009155383623
369.149,0.97003,-0.0095,,,,,0.05878969697,-0.007656350741
369.649,1.01142,-0.00923,,,,,0.06129818182,-0.007438749194
370.149,1.05328,-0.00799,,,,,0.06383515152,-0.006439393939
370.649,1.09507,-0.00718,,,,,0.06636787879,-0.005786589297
371.149,1.13632,-0.00494,,,,,0.06886787879,-0.003981302386
371.649,1.17843,-0.00156,,,,,0.07142,-0.001257253385
372.149,1.21995,-0.00038,,,,,0.07393636364,-0.0003062540297
372.649,1.26143,0.0009,,,,,0.07645030303,0.0007253384913
373.149,1.30341,0.00128,,,,,0.07899454545,0.001031592521
373.649,1.3447,0.00286,,,,,0.0814969697,0.002304964539
374.149,1.38665,0.00564,,,,,0.08403939394,0.004545454545
374.649,1.4284,0.00756,,,,,0.08656969697,0.006092843327
375.149,1.46957,0.00929,,,,,0.08906484848,0.007487105093
375.649,1.51164,0.00991,,,,,0.09161454545,0.007986782721
376.149,1.55338,0.01142,,,,,0.09414424242,0.009203739523
376.649,1.59456,0.01429,,,,,0.09664,0.01151676338
377.149,1.6368,0.01582,,,,,0.0992,0.01274983881
377.412,1.64716,0.01633,,,,,0.09982787879,0.01316086396
377.912,1.60455,0.01048,,,,,0.09724545455,0.008446163765
378.412,1.56319,0.0074,,,,,0.09473878788,0.005963894262
378.912,1.52127,0.00527,,,,,0.09219818182,0.004247259832
379.412,1.47967,0.00223,,,,,0.0896769697,0.001797227595
379.912,1.43827,0.0008,,,,,0.08716787879,0.0006447453256
380.412,1.39615,-0.00156,,,,,0.08461515152,-0.001257253385
380.912,1.35472,-0.00518,,,,,0.08210424242,-0.004174725983
381.412,1.31317,-0.00855,,,,,0.07958606061,-0.006890715667
381.912,1.27127,-0.00956,,,,,0.07704666667,-0.007704706641
382.412,1.22973,-0.01087,,,,,0.07452909091,-0.008760477112
382.912,1.18796,-0.01413,,,,,0.07199757576,-0.01138781431
383.412,1.14633,-0.01413,,,,,0.06947454545,-0.01138781431
383.912,1.1049,-0.01853,,,,,0.06696363636,-0.0149339136
384.412,1.06277,-0.01848,,,,,0.06441030303,-0.01489361702
384.912,1.02144,-0.01979,,,,,0.06190545455,-0.01594938749
385.412,0.97995,-0.02146,,,,,0.05939090909,-0.01729529336
385.912,0.93777,-0.02225,,,,,0.05683454545,-0.01793197937
386.412,0.89642,-0.02404,,,,,0.05432848485,-0.01937459703
386.912,0.85474,-0.02663,,,,,0.05180242424,-0.02146196003
387.412,0.81293,-0.02847,,,,,0.04926848485,-0.02294487427
387.912,0.77146,-0.0278,,,,,0.04675515152,-0.02240490006
388.412,0.72958,-0.02834,,,,,0.0442169697,-0.02284010316
388.912,0.68807,-0.03175,,,,,0.04170121212,-0.02558833011
389.412,0.64654,-0.03356,,,,,0.03918424242,-0.02704706641
389.912,0.60453,-0.03502,,,,,0.03663818182,-0.02822372663
390.412,0.5631,-0.03577,,,,,0.03412727273,-0.02882817537
390.912,0.52143,-0.03793,,,,,0.03160181818,-0.03056898775
391.412,0.47953,-0.04154,,,,,0.02906242424,-0.03347840103
391.912,0.43812,-0.04282,,,,,0.02655272727,-0.03450999355
392.412,0.3962,-0.04336,,,,,0.02401212121,-0.03494519665
392.912,0.35473,-0.04474,,,,,0.02149878788,-0.03605738233
393.412,0.31322,-0.04678,,,,,0.0189830303,-0.03770148291
393.912,0.27104,-0.04725,,,,,0.01642666667,-0.03808027079
394.412,0.22976,-0.05049,,,,,0.01392484848,-0.04069148936
394.912,0.18819,-0.05117,,,,,0.01140545455,-0.04123952289
395.412,0.14617,-0.05114,,,,,0.008858787879,-0.04121534494
395.912,0.10476,-0.05194,,,,,0.006349090909,-0.04186009026
396.412,0.06307,-0.05329,,,,,0.003822424242,-0.042948098
396.912,0.02131,-0.05527,,,,,0.001291515152,-0.04454384268
397.169,0,-0.05682,,,,,0,-0.04579303675