File: mechanical/hysteresis/data/hmwg_conductive_2.csv
Time,Extension,Load,Length,Width,Thickness,CS Area,Strain,Stress
(s),(mm),(N),(mm),(mm),(mm),(mm^2),(mm/mm),(MPa)
0,0,-0.02775,16.5,2.82,0.32,0.9024,0,-0.03075132979
0.5,0.03824,0.09693,,,,,0.002317575758,0.1074135638
1,0.08021,0.15419,,,,,0.004861212121,0.170866578
1.5,0.12187,0.19086,,,,,0.007386060606,0.2115026596
2,0.16312,0.2151,,,,,0.009886060606,0.2383643617
2.5,0.20534,0.23799,,,,,0.01244484848,0.2637300532
3,0.24684,0.25308,,,,,0.01496,0.2804521277
3.5,0.28826,0.26454,,,,,0.01747030303,0.2931515957
4,0.3303,0.28013,,,,,0.02001818182,0.3104277482
4.5,0.37169,0.28979,,,,,0.02252666667,0.3211325355
5,0.4135,0.29771,,,,,0.02506060606,0.3299091312
5.5,0.45517,0.30637,,,,,0.02758606061,0.3395057624
6,0.49646,0.31296,,,,,0.03008848485,0.3468085106
6.5,0.53858,0.32293,,,,,0.03264121212,0.3578568262
7,0.58016,0.3305,,,,,0.03516121212,0.3662455674
7.5,0.62157,0.33504,,,,,0.03767090909,0.3712765957
8,0.66362,0.34513,,,,,0.04021939394,0.3824578901
8.5,0.70504,0.349,,,,,0.04272969697,0.3867464539
9,0.7468,0.35304,,,,,0.04526060606,0.3912234043
9.5,0.78864,0.36087,,,,,0.04779636364,0.399900266
10,0.82982,0.36288,,,,,0.05029212121,0.4021276596
10.5,0.87195,0.37069,,,,,0.05284545455,0.4107823582
11,0.91362,0.37736,,,,,0.05537090909,0.4181737589
11.5,0.95479,0.37755,,,,,0.05786606061,0.4183843085
12,0.99699,0.38532,,,,,0.06042363636,0.4269946809
12.5,1.03848,0.39032,,,,,0.06293818182,0.432535461
13,1.07998,0.39207,,,,,0.06545333333,0.434474734
13.5,1.12183,0.39816,,,,,0.06798969697,0.4412234043
14,1.16328,0.39974,,,,,0.07050181818,0.4429742908
14.5,1.20519,0.40304,,,,,0.07304181818,0.4466312057
15,1.24687,0.40577,,,,,0.07556787879,0.4496564716
15.5,1.2882,0.40595,,,,,0.07807272727,0.4498559397
16,1.33033,0.41179,,,,,0.08062606061,0.4563275709
16.5,1.37178,0.41524,,,,,0.08313818182,0.4601507092
17,1.41331,0.41573,,,,,0.08565515152,0.4606937057
17.5,1.45525,0.42208,,,,,0.0881969697,0.4677304965
18,1.49657,0.42387,,,,,0.09070121212,0.4697140957
18.5,1.53853,0.42728,,,,,0.09324424242,0.4734929078
19,1.58023,0.43198,,,,,0.09577151515,0.4787012411
19.5,1.62145,0.43247,,,,,0.09826969697,0.4792442376
19.839,1.65017,0.43704,,,,,0.100010303,0.4843085106
20.24,1.62152,0.24529,,,,,0.09827393939,0.2718195922
20.74,1.57997,0.11643,,,,,0.09575575758,0.1290226064
21.24,1.53793,0.02316,,,,,0.09320787879,0.02566489362
21.74,1.4966,-0.04884,,,,,0.0907030303,-0.05412234043
22.24,1.45478,-0.10707,,,,,0.08816848485,-0.118650266
22.74,1.41322,-0.15912,,,,,0.08564969697,-0.1763297872
23.24,1.37172,-0.20226,,,,,0.08313454545,-0.2241356383
23.74,1.3296,-0.24331,,,,,0.08058181818,-0.2696254433
24.24,1.28824,-0.27779,,,,,0.07807515152,-0.3078346631
24.74,1.24671,-0.30922,,,,,0.07555818182,-0.3426640071
25.24,1.2046,-0.34057,,,,,0.07300606061,-0.3774046986
25.74,1.16321,-0.36568,,,,,0.07049757576,-0.4052304965
26.24,1.12162,-0.38892,,,,,0.0679769697,-0.4309840426
26.74,1.07968,-0.41359,,,,,0.06543515152,-0.4583222518
27.24,1.0383,-0.434,,,,,0.06292727273,-0.4809397163
27.74,0.99632,-0.45435,,,,,0.0603830303,-0.5034906915
28.24,0.95494,-0.47386,,,,,0.05787515152,-0.5251108156
28.74,0.91328,-0.49047,,,,,0.05535030303,-0.5435172872
29.24,0.87122,-0.50946,,,,,0.05280121212,-0.5645611702
29.74,0.82992,-0.5255,,,,,0.05029818182,-0.5823359929
30.24,0.78822,-0.5397,,,,,0.04777090909,-0.5980718085
30.74,0.74635,-0.55543,,,,,0.04523333333,-0.6155031028
31.24,0.70497,-0.56878,,,,,0.04272545455,-0.6302969858
31.74,0.66304,-0.58134,,,,,0.04018424242,-0.6442154255
32.24,0.62149,-0.59726,,,,,0.03766606061,-0.6618572695
32.74,0.5801,-0.60673,,,,,0.03515757576,-0.6723515071
33.24,0.53788,-0.62042,,,,,0.03259878788,-0.6875221631
33.74,0.49648,-0.63222,,,,,0.03008969697,-0.7005984043
34.24,0.45502,-0.64125,,,,,0.0275769697,-0.7106050532
34.74,0.41295,-0.65455,,,,,0.02502727273,-0.7253435284
35.24,0.37149,-0.66377,,,,,0.02251454545,-0.735560727
35.74,0.32983,-0.67454,,,,,0.01998969697,-0.7474955674
36.24,0.28812,-0.68588,,,,,0.01746181818,-0.7600620567
36.74,0.24667,-0.69289,,,,,0.01494969697,-0.7678302305
37.24,0.20466,-0.69862,,,,,0.01240363636,-0.7741799645
37.74,0.16322,-0.70254,,,,,0.009892121212,-0.7785239362
38.24,0.12165,-0.70367,,,,,0.007372727273,-0.7797761525
38.74,0.07964,-0.70481,,,,,0.004826666667,-0.7810394504
39.24,0.0383,-0.70446,,,,,0.002321212121,-0.7806515957
39.697,-0.00009,-0.70505,,,,,-0.000005454545455,-0.7813054078
39.999,0.02043,-0.69523,,,,,0.001238181818,-0.7704233156
40.499,0.06186,-0.66582,,,,,0.003749090909,-0.7378324468
40.999,0.10364,-0.59564,,,,,0.006281212121,-0.6600620567
41.499,0.14557,-0.53573,,,,,0.008822424242,-0.5936724291
41.999,0.18672,-0.49601,,,,,0.01131636364,-0.5496564716
42.499,0.22874,-0.45936,,,,,0.0138630303,-0.5090425532
42.999,0.27048,-0.4281,,,,,0.01639272727,-0.4744015957
43.499,0.31177,-0.39977,,,,,0.01889515152,-0.4430075355
43.999,0.35378,-0.36964,,,,,0.02144121212,-0.4096187943
44.499,0.39528,-0.34384,,,,,0.02395636364,-0.3810283688
44.999,0.43701,-0.31993,,,,,0.02648545455,-0.3545323582
45.499,0.47876,-0.29499,,,,,0.02901575758,-0.3268949468
45.999,0.52009,-0.27384,,,,,0.03152060606,-0.3034574468
46.499,0.56216,-0.25109,,,,,0.03407030303,-0.2782468972
46.999,0.60379,-0.22984,,,,,0.03659333333,-0.2546985816
47.499,0.64507,-0.20935,,,,,0.03909515152,-0.2319924645
47.999,0.68722,-0.18512,,,,,0.04164969697,-0.205141844
48.499,0.72871,-0.163,,,,,0.04416424242,-0.1806294326
48.999,0.77019,-0.14232,,,,,0.04667818182,-0.157712766
49.499,0.81216,-0.11869,,,,,0.04922181818,-0.131527039
49.999,0.85351,-0.09694,,,,,0.05172787879,-0.1074246454
50.499,0.89542,-0.07641,,,,,0.05426787879,-0.08467420213
50.999,0.93708,-0.05512,,,,,0.05679272727,-0.06108156028
51.499,0.9784,-0.03521,,,,,0.0592969697,-0.03901817376
51.999,1.0205,-0.01122,,,,,0.06184848485,-0.01243351064
52.499,1.06205,0.00916,,,,,0.06436666667,0.01015070922
52.999,1.10353,0.02914,,,,,0.06688060606,0.03229166667
53.499,1.1455,0.05306,,,,,0.06942424242,0.05879875887
53.999,1.18693,0.07333,,,,,0.07193515152,0.08126108156
54.499,1.22875,0.09369,,,,,0.07446969697,0.1038231383
54.999,1.27053,0.11756,,,,,0.07700181818,0.1302748227
55.499,1.31168,0.13541,,,,,0.07949575758,0.1500554078
55.999,1.35388,0.15598,,,,,0.08205333333,0.1728501773
56.499,1.39549,0.17629,,,,,0.08457515152,0.1953568262
56.999,1.4367,0.1931,,,,,0.08707272727,0.2139849291
57.499,1.47884,0.21397,,,,,0.08962666667,0.2371121454
57.999,1.52028,0.23274,,,,,0.09213818182,0.257912234
58.499,1.56191,0.24962,,,,,0.09466121212,0.2766179078
58.999,1.60376,0.26853,,,,,0.09719757576,0.2975731383
59.499,1.64519,0.28297,,,,,0.09970848485,0.3135749113
59.756,1.6384,0.18682,,,,,0.0992969697,0.2070257092
60.256,1.59648,0.04236,,,,,0.09675636364,0.04694148936
60.756,1.55507,-0.04789,,,,,0.09424666667,-0.0530695922
61.256,1.51301,-0.11865,,,,,0.09169757576,-0.1314827128
61.756,1.47164,-0.17482,,,,,0.08919030303,-0.1937278369
62.256,1.43008,-0.22157,,,,,0.08667151515,-0.2455341312
62.756,1.3879,-0.2652,,,,,0.08411515152,-0.2938829787
63.256,1.34662,-0.2993,,,,,0.08161333333,-0.3316710993
63.756,1.30496,-0.33116,,,,,0.07908848485,-0.3669769504
64.256,1.26304,-0.36263,,,,,0.07654787879,-0.4018506206
64.756,1.22159,-0.38872,,,,,0.07403575758,-0.4307624113
65.256,1.1798,-0.4131,,,,,0.0715030303,-0.4577792553
65.756,1.13817,-0.43768,,,,,0.06898,-0.4850177305
66.256,1.09673,-0.4588,,,,,0.06646848485,-0.5084219858
66.756,1.05461,-0.48008,,,,,0.06391575758,-0.5320035461
67.256,1.0133,-0.49924,,,,,0.06141212121,-0.5532358156
67.756,0.97167,-0.51432,,,,,0.05888909091,-0.5699468085
68.256,0.92978,-0.53235,,,,,0.05635030303,-0.5899268617
68.756,0.88833,-0.54631,,,,,0.05383818182,-0.6053967199
69.256,0.84646,-0.55975,,,,,0.05130060606,-0.6202903369
69.756,0.80487,-0.57487,,,,,0.04878,-0.637045656
70.256,0.76342,-0.58874,,,,,0.04626787879,-0.6524157801
70.756,0.7213,-0.60417,,,,,0.04371515152,-0.6695146277
71.256,0.6799,-0.61301,,,,,0.04120606061,-0.679310727
71.756,0.63849,-0.62615,,,,,0.03869636364,-0.6938718972
72.256,0.59626,-0.63991,,,,,0.0361369697,-0.7091201241
72.756,0.55493,-0.65062,,,,,0.03363212121,-0.7209884752
73.256,0.5132,-0.66241,,,,,0.0311030303,-0.7340536348
73.756,0.47157,-0.67283,,,,,0.02858,-0.7456006206
74.256,0.42996,-0.68224,,,,,0.02605818182,-0.7560283688
74.756,0.38804,-0.69095,,,,,0.02351757576,-0.7656804078
75.256,0.34663,-0.69838,,,,,0.02100787879,-0.7739140071
75.756,0.30506,-0.70307,,,,,0.01848848485,-0.7791112589
76.256,0.26295,-0.70548,,,,,0.01593636364,-0.7817819149
76.756,0.22166,-0.70551,,,,,0.01343393939,-0.7818151596
77.256,0.17993,-0.70682,,,,,0.01090484848,-0.783266844
77.756,0.13803,-0.70735,,,,,0.008365454545,-0.7838541667
78.256,0.09673,-0.70602,,,,,0.005862424242,-0.7823803191
78.756,0.0547,-0.70602,,,,,0.003315151515,-0.7823803191
79.256,0.01316,-0.7062,,,,,0.0007975757576,-0.7825797872
79.515,0.00241,-0.70552,,,,,0.0001460606061,-0.7818262411
80.015,0.04547,-0.70067,,,,,0.002755757576,-0.7764516844
80.515,0.08717,-0.69427,,,,,0.005283030303,-0.7693594858
81.015,0.12847,-0.66981,,,,,0.007786060606,-0.7422539894
81.515,0.17054,-0.60674,,,,,0.01033575758,-0.6723625887
82.015,0.21211,-0.55409,,,,,0.01285515152,-0.6140181738
82.515,0.25362,-0.5167,,,,,0.01537090909,-0.5725842199
83.015,0.29554,-0.4841,,,,,0.01791151515,-0.5364583333
83.515,0.33682,-0.45799,,,,,0.02041333333,-0.5075243794
84.015,0.37891,-0.43262,,,,,0.02296424242,-0.479410461
84.515,0.42044,-0.40717,,,,,0.02548121212,-0.4512078901
85.015,0.4618,-0.38606,,,,,0.02798787879,-0.4278147163
85.515,0.50394,-0.36205,,,,,0.03054181818,-0.4012078901
86.015,0.54547,-0.33826,,,,,0.03305878788,-0.3748448582
86.515,0.58676,-0.3189,,,,,0.03556121212,-0.3533909574
87.015,0.62897,-0.29518,,,,,0.03811939394,-0.3271054965
87.515,0.67026,-0.27405,,,,,0.04062181818,-0.3036901596
88.015,0.71202,-0.25433,,,,,0.04315272727,-0.2818373227
88.515,0.75388,-0.2321,,,,,0.04568969697,-0.2572030142
89.015,0.79513,-0.21436,,,,,0.04818969697,-0.2375443262
89.515,0.83717,-0.19249,,,,,0.05073757576,-0.2133089539
90.015,0.87879,-0.17058,,,,,0.05326,-0.1890292553
90.515,0.92022,-0.15235,,,,,0.05577090909,-0.1688275709
91.015,0.96215,-0.13103,,,,,0.05831212121,-0.1452016844
91.515,1.00369,-0.10922,,,,,0.06082969697,-0.1210328014
92.015,1.04538,-0.09102,,,,,0.06335636364,-0.1008643617
92.515,1.08723,-0.06819,,,,,0.06589272727,-0.07556515957
93.015,1.12841,-0.04843,,,,,0.06838848485,-0.05366799645
93.515,1.17057,-0.0266,,,,,0.07094363636,-0.02947695035
94.015,1.21215,-0.00422,,,,,0.07346363636,-0.00467641844
94.515,1.25338,0.01516,,,,,0.07596242424,0.01679964539
95.015,1.29557,0.03862,,,,,0.07851939394,0.04279698582
95.515,1.33711,0.06113,,,,,0.0810369697,0.06774157801
96.015,1.37859,0.08179,,,,,0.08355090909,0.09063608156
96.515,1.42046,0.10662,,,,,0.08608848485,0.1181515957
97.015,1.46188,0.12783,,,,,0.08859878788,0.1416555851
97.515,1.50379,0.14877,,,,,0.09113878788,0.1648603723
98.015,1.54552,0.17167,,,,,0.09366787879,0.1902371454
98.515,1.58676,0.19069,,,,,0.09616727273,0.211314273
99.015,1.62892,0.21055,,,,,0.09872242424,0.2333222518
99.271,1.65018,0.21961,,,,,0.1000109091,0.2433621454
99.771,1.61345,0.03706,,,,,0.09778484848,0.04106826241
100.271,1.57126,-0.06547,,,,,0.09522787879,-0.07255097518
100.771,1.52995,-0.13678,,,,,0.09272424242,-0.1515735816
101.271,1.4883,-0.1926,,,,,0.0902,-0.2134308511
101.771,1.44634,-0.24203,,,,,0.0876569697,-0.2682070035
102.271,1.4049,-0.28098,,,,,0.08514545455,-0.3113696809
102.771,1.3632,-0.31615,,,,,0.08261818182,-0.3503435284
103.271,1.32147,-0.35012,,,,,0.08008909091,-0.3879875887
103.771,1.28002,-0.37751,,,,,0.0775769697,-0.4183399823
104.271,1.238,-0.40716,,,,,0.07503030303,-0.4511968085
104.771,1.19663,-0.43051,,,,,0.0725230303,-0.4770722518
105.271,1.155,-0.45275,,,,,0.07,-0.5017176418
105.771,1.11301,-0.47329,,,,,0.06745515152,-0.5244791667
106.271,1.07161,-0.4918,,,,,0.06494606061,-0.5449911348
106.771,1.02983,-0.50866,,,,,0.06241393939,-0.5636746454
107.271,0.98813,-0.52779,,,,,0.05988666667,-0.5848736702
107.771,0.94669,-0.54214,,,,,0.05737515152,-0.6007757092
108.271,0.90461,-0.558,,,,,0.05482484848,-0.6183510638
108.771,0.8632,-0.57433,,,,,0.05231515152,-0.6364472518
109.271,0.82174,-0.58826,,,,,0.04980242424,-0.6518838652
109.771,0.77956,-0.60285,,,,,0.04724606061,-0.6680518617
110.271,0.73817,-0.61637,,,,,0.04473757576,-0.6830341312
110.771,0.69664,-0.6279,,,,,0.04222060606,-0.6958111702
111.271,0.65473,-0.64039,,,,,0.03968060606,-0.709652039
111.771,0.61326,-0.65098,,,,,0.03716727273,-0.7213874113
112.271,0.5714,-0.66126,,,,,0.03463030303,-0.7327792553
112.771,0.52989,-0.67266,,,,,0.03211454545,-0.745412234
113.271,0.48842,-0.68111,,,,,0.02960121212,-0.7547761525
113.771,0.44634,-0.69173,,,,,0.02705090909,-0.7665447695
114.271,0.40493,-0.69839,,,,,0.02454121212,-0.7739250887
114.771,0.36324,-0.70402,,,,,0.02201454545,-0.7801640071
115.271,0.32137,-0.70661,,,,,0.0194769697,-0.7830341312
115.771,0.27996,-0.70674,,,,,0.01696727273,-0.7831781915
116.271,0.23808,-0.70683,,,,,0.01442909091,-0.7832779255
116.771,0.19652,-0.70682,,,,,0.01191030303,-0.783266844
117.271,0.15514,-0.70631,,,,,0.009402424242,-0.7827016844
117.771,0.1129,-0.70508,,,,,0.006842424242,-0.7813386525
118.271,0.07161,-0.70631,,,,,0.00434,-0.7827016844
118.771,0.03004,-0.70656,,,,,0.001820606061,-0.7829787234
119.129,-0.00015,-0.70537,,,,,-0.000009090909091,-0.7816600177
119.53,0.02875,-0.70301,,,,,0.001742424242,-0.7790447695
120.03,0.07021,-0.6997,,,,,0.004255151515,-0.775376773
120.53,0.11213,-0.69467,,,,,0.006795757576,-0.7698027482
121.03,0.15355,-0.68132,,,,,0.009306060606,-0.7550088652
121.53,0.19543,-0.63484,,,,,0.01184424242,-0.703501773
122.03,0.23708,-0.58001,,,,,0.01436848485,-0.642741578
122.53,0.27835,-0.54042,,,,,0.01686969697,-0.5988696809
123.03,0.3205,-0.50802,,,,,0.01942424242,-0.5629654255
123.53,0.36207,-0.48056,,,,,0.02194363636,-0.532535461
124.03,0.40344,-0.45484,,,,,0.02445090909,-0.5040336879
124.53,0.44551,-0.43063,,,,,0.02700060606,-0.4772052305
125.03,0.48695,-0.40821,,,,,0.02951212121,-0.4523603723
125.53,0.52865,-0.38722,,,,,0.03203939394,-0.4291001773
126.03,0.57049,-0.36525,,,,,0.03457515152,-0.4047539894
126.53,0.61182,-0.34473,,,,,0.03708,-0.3820146277
127.03,0.65382,-0.32372,,,,,0.03962545455,-0.3587322695
127.53,0.69545,-0.30328,,,,,0.04214848485,-0.3360815603
128.03,0.73674,-0.28597,,,,,0.04465090909,-0.3168993794
128.53,0.77887,-0.26336,,,,,0.04720424242,-0.2918439716
129.03,0.82031,-0.24428,,,,,0.04971575758,-0.2707003546
129.53,0.86197,-0.22509,,,,,0.05224060606,-0.2494348404
130.03,0.90379,-0.20266,,,,,0.05477515152,-0.2245789007
130.53,0.94514,-0.18369,,,,,0.05728121212,-0.2035571809
131.03,0.98715,-0.16365,,,,,0.05982727273,-0.181349734
131.53,1.02882,-0.14368,,,,,0.06235272727,-0.1592198582
132.03,1.06997,-0.12478,,,,,0.06484666667,-0.1382757092
132.53,1.11224,-0.10103,,,,,0.06740848485,-0.1119570035
133.03,1.15379,-0.0804,,,,,0.06992666667,-0.08909574468
133.53,1.19512,-0.06149,,,,,0.07243151515,-0.06814051418
134.03,1.23723,-0.0388,,,,,0.07498363636,-0.0429964539
134.53,1.27858,-0.01687,,,,,0.07748969697,-0.0186945922
135.03,1.32038,0.00425,,,,,0.0800230303,0.004709663121
135.53,1.36208,0.02786,,,,,0.08255030303,0.03087322695
136.03,1.40346,0.04717,,,,,0.08505818182,0.05227171986
136.53,1.44544,0.06932,,,,,0.08760242424,0.07681737589
137.03,1.48713,0.09261,,,,,0.09012909091,0.1026263298
137.53,1.52847,0.11089,,,,,0.09263454545,0.122883422
138.03,1.57053,0.1366,,,,,0.09518363636,0.1513741135
138.53,1.61185,0.15676,,,,,0.09768787879,0.173714539
138.985,1.65005,0.17775,,,,,0.1000030303,0.196974734
139.287,1.62978,0.05291,,,,,0.09877454545,0.05863253546
139.787,1.58833,-0.06081,,,,,0.09626242424,-0.06738696809
140.287,1.54655,-0.13561,,,,,0.09373030303,-0.150277039
140.787,1.50485,-0.19714,,,,,0.0912030303,-0.2184618794
141.287,1.46337,-0.24617,,,,,0.08868909091,-0.2727947695
141.787,1.42144,-0.28793,,,,,0.08614787879,-0.3190713652
142.287,1.37989,-0.32489,,,,,0.08362969697,-0.3600288121
142.787,1.33844,-0.35654,,,,,0.08111757576,-0.3951019504
143.287,1.29629,-0.38718,,,,,0.0785630303,-0.4290558511
143.787,1.25499,-0.4115,,,,,0.07606,-0.4560062057
144.287,1.21326,-0.43462,,,,,0.07353090909,-0.481626773
144.787,1.17152,-0.4583,,,,,0.07100121212,-0.5078679078
145.287,1.13003,-0.47696,,,,,0.06848666667,-0.5285460993
145.787,1.08804,-0.49669,,,,,0.06594181818,-0.5504100177
146.287,1.04658,-0.51513,,,,,0.06342909091,-0.5708444149
146.787,1.00508,-0.53176,,,,,0.06091393939,-0.5892730496
147.287,0.96295,-0.55014,,,,,0.05836060606,-0.6096409574
147.787,0.92161,-0.56469,,,,,0.05585515152,-0.6257646277
148.287,0.88017,-0.57944,,,,,0.05334363636,-0.6421099291
148.787,0.83805,-0.59611,,,,,0.05079090909,-0.6605828901
149.287,0.79668,-0.60737,,,,,0.04828363636,-0.673060727
149.787,0.75483,-0.61923,,,,,0.04574727273,-0.6862034574
150.287,0.71336,-0.63163,,,,,0.04323393939,-0.6999445922
150.787,0.6717,-0.64267,,,,,0.04070909091,-0.7121786348
151.287,0.62964,-0.65541,,,,,0.03816,-0.7262965426
151.787,0.58829,-0.66616,,,,,0.03565393939,-0.7382092199
152.287,0.54667,-0.6769,,,,,0.03313151515,-0.7501108156
152.787,0.50465,-0.68769,,,,,0.03058484848,-0.7620678191
153.287,0.46334,-0.69495,,,,,0.02808121212,-0.7701130319
153.787,0.42153,-0.70147,,,,,0.02554727273,-0.7773382092
154.287,0.37976,-0.70591,,,,,0.02301575758,-0.782258422
154.787,0.33845,-0.70594,,,,,0.02051212121,-0.7822916667
155.287,0.29631,-0.70754,,,,,0.01795818182,-0.7840647163
155.787,0.25488,-0.70765,,,,,0.01544727273,-0.7841866135
156.287,0.21344,-0.70778,,,,,0.01293575758,-0.7843306738
156.787,0.17129,-0.7074,,,,,0.01038121212,-0.7839095745
157.287,0.12989,-0.70888,,,,,0.007872121212,-0.7855496454
157.787,0.08832,-0.70764,,,,,0.005352727273,-0.7841755319
158.287,0.04649,-0.70686,,,,,0.002817575758,-0.7833111702
158.787,0.00504,-0.70614,,,,,0.0003054545455,-0.7825132979
159.046,0.01177,-0.70542,,,,,0.0007133333333,-0.7817154255
159.546,0.05378,-0.70247,,,,,0.003259393939,-0.7784463652
160.046,0.09503,-0.70045,,,,,0.005759393939,-0.7762078901
160.546,0.13727,-0.69432,,,,,0.008319393939,-0.7694148936
161.046,0.17875,-0.67961,,,,,0.01083333333,-0.7531139184
161.546,0.22012,-0.63637,,,,,0.01334060606,-0.7051972518
162.046,0.26227,-0.58269,,,,,0.01589515152,-0.6457114362
162.546,0.30372,-0.54529,,,,,0.01840727273,-0.6042664007
163.046,0.34523,-0.51696,,,,,0.0209230303,-0.5728723404
163.546,0.38729,-0.48939,,,,,0.02347212121,-0.5423204787
164.046,0.42849,-0.46474,,,,,0.02596909091,-0.5150044326
164.546,0.47043,-0.44239,,,,,0.02851090909,-0.4902371454
165.046,0.51223,-0.41975,,,,,0.03104424242,-0.4651484929
165.546,0.55348,-0.40133,,,,,0.03354424242,-0.4447362589
166.046,0.59552,-0.37845,,,,,0.03609212121,-0.4193816489
166.546,0.63709,-0.35911,,,,,0.03861151515,-0.3979499113
167.046,0.67862,-0.33903,,,,,0.04112848485,-0.3756981383
167.546,0.72043,-0.31854,,,,,0.04366242424,-0.3529920213
168.046,0.76189,-0.29944,,,,,0.04617515152,-0.3318262411
168.546,0.80377,-0.28107,,,,,0.04871333333,-0.3114694149
169.046,0.84552,-0.25945,,,,,0.05124363636,-0.2875110816
169.546,0.88672,-0.24094,,,,,0.05374060606,-0.2669991135
170.046,0.92891,-0.22147,,,,,0.05629757576,-0.2454233156
170.546,0.97049,-0.20075,,,,,0.05881757576,-0.2224623227
171.046,1.0118,-0.18245,,,,,0.06132121212,-0.2021830674
171.546,1.05392,-0.15998,,,,,0.06387393939,-0.1772828014
172.046,1.09536,-0.13954,,,,,0.06638545455,-0.1546320922
172.546,1.13703,-0.12125,,,,,0.06891090909,-0.1343639184
173.046,1.1788,-0.09913,,,,,0.07144242424,-0.1098515071
173.546,1.22015,-0.08048,,,,,0.07394848485,-0.08918439716
174.046,1.26218,-0.05934,,,,,0.07649575758,-0.06575797872
174.546,1.30383,-0.03716,,,,,0.07902,-0.04117907801
175.046,1.34511,-0.0183,,,,,0.08152181818,-0.02027925532
175.546,1.3872,0.00746,,,,,0.08407272727,0.008266843972
176.046,1.42871,0.02841,,,,,0.08658848485,0.03148271277
176.546,1.47033,0.04956,,,,,0.08911090909,0.05492021277
177.046,1.51224,0.07377,,,,,0.09165090909,0.08174867021
177.546,1.55349,0.09472,,,,,0.09415090909,0.104964539
178.046,1.59554,0.11925,,,,,0.09669939394,0.1321476064
178.546,1.63726,0.14202,,,,,0.09922787879,0.1573803191
178.802,1.64749,0.10669,,,,,0.09984787879,0.1182291667
179.302,1.60479,-0.04627,,,,,0.09726,-0.05127437943
179.802,1.56323,-0.1306,,,,,0.09474121212,-0.1447251773
180.302,1.52167,-0.19402,,,,,0.09222242424,-0.2150044326
180.802,1.47962,-0.24629,,,,,0.08967393939,-0.2729277482
181.302,1.43825,-0.28796,,,,,0.08716666667,-0.3191046099
181.802,1.39658,-0.32379,,,,,0.08464121212,-0.3588098404
182.302,1.35471,-0.35766,,,,,0.08210363636,-0.3963430851
182.802,1.3133,-0.38672,,,,,0.07959393939,-0.4285460993
183.302,1.27138,-0.41303,,,,,0.07705333333,-0.4577016844
183.802,1.22986,-0.43731,,,,,0.0745369697,-0.4846077128
184.302,1.18838,-0.45955,,,,,0.0720230303,-0.5092531028
184.802,1.14622,-0.48175,,,,,0.06946787879,-0.5338541667
185.302,1.10492,-0.50058,,,,,0.06696484848,-0.5547207447
185.802,1.06336,-0.51897,,,,,0.06444606061,-0.575099734
186.302,1.02129,-0.53775,,,,,0.06189636364,-0.5959109043
186.802,0.9799,-0.55279,,,,,0.05938787879,-0.6125775709
187.302,0.93823,-0.56708,,,,,0.05686242424,-0.6284131206
187.802,0.89642,-0.58144,,,,,0.05432848485,-0.6443262411
188.302,0.85497,-0.59415,,,,,0.05181636364,-0.6584109043
188.802,0.81294,-0.60821,,,,,0.04926909091,-0.673991578
189.302,0.77154,-0.62053,,,,,0.04676,-0.6876440603
189.802,0.73003,-0.63421,,,,,0.04424424242,-0.7028036348
190.302,0.68801,-0.64603,,,,,0.04169757576,-0.715902039
190.802,0.64658,-0.65684,,,,,0.03918666667,-0.7278812057
191.302,0.60483,-0.66856,,,,,0.03665636364,-0.7408687943
191.802,0.56314,-0.67847,,,,,0.03412969697,-0.7518506206
192.302,0.52167,-0.68748,,,,,0.03161636364,-0.7618351064
192.802,0.4797,-0.69668,,,,,0.02907272727,-0.7720301418
193.302,0.43823,-0.7037,,,,,0.02655939394,-0.7798093972
193.802,0.39684,-0.70561,,,,,0.02405090909,-0.7819259752
194.302,0.35454,-0.70817,,,,,0.02148727273,-0.7847628546
194.802,0.3133,-0.70989,,,,,0.01898787879,-0.786668883
195.302,0.27161,-0.70871,,,,,0.01646121212,-0.7853612589
195.802,0.22979,-0.70863,,,,,0.01392666667,-0.7852726064
196.302,0.18822,-0.70766,,,,,0.01140727273,-0.784197695
196.802,0.14641,-0.70582,,,,,0.008873333333,-0.7821586879
197.302,0.10486,-0.70608,,,,,0.006355151515,-0.7824468085
197.802,0.06331,-0.70461,,,,,0.003836969697,-0.7808178191
198.302,0.02119,-0.7043,,,,,0.001284242424,-0.7804742908
198.561,-0.00025,-0.70522,,,,,-0.00001515151515,-0.7814937943
199.061,0.03665,-0.70234,,,,,0.002221212121,-0.778302305
199.561,0.07887,-0.70021,,,,,0.00478,-0.7759419326
200.061,0.12035,-0.69804,,,,,0.007293939394,-0.773537234
200.561,0.16191,-0.69332,,,,,0.009812727273,-0.7683067376
201.061,0.20382,-0.67462,,,,,0.01235272727,-0.7475842199
201.561,0.2452,-0.62678,,,,,0.01486060606,-0.6945700355
202.061,0.28707,-0.58021,,,,,0.01739818182,-0.6429632092
202.561,0.32883,-0.5439,,,,,0.01992909091,-0.6027260638
203.061,0.37011,-0.5177,,,,,0.02243090909,-0.5736923759
203.561,0.41217,-0.49088,,,,,0.02498,-0.5439716312
204.061,0.45375,-0.46911,,,,,0.0275,-0.5198470745
204.561,0.49511,-0.4476,,,,,0.03000666667,-0.4960106383
205.061,0.53714,-0.42591,,,,,0.03255393939,-0.471974734
205.561,0.57848,-0.40693,,,,,0.03505939394,-0.4509419326
206.061,0.6204,-0.38721,,,,,0.0376,-0.4290890957
206.561,0.66208,-0.36586,,,,,0.04012606061,-0.4054299645
207.061,0.70341,-0.3465,,,,,0.04263090909,-0.3839760638
207.561,0.74554,-0.32618,,,,,0.04518424242,-0.3614583333
208.061,0.78714,-0.30653,,,,,0.04770545455,-0.3396830674
208.561,0.82836,-0.28952,,,,,0.05020363636,-0.3208333333
209.061,0.8706,-0.2672,,,,,0.05276363636,-0.2960992908
209.561,0.912,-0.24921,,,,,0.05527272727,-0.2761635638
210.061,0.95355,-0.23135,,,,,0.05779090909,-0.2563718972
210.561,0.99553,-0.21185,,,,,0.06033515152,-0.2347628546
211.061,1.03679,-0.19268,,,,,0.06283575758,-0.2135195035
211.561,1.07872,-0.17355,,,,,0.0653769697,-0.1923204787
212.061,1.12034,-0.15321,,,,,0.06789939394,-0.1697805851
212.561,1.16176,-0.13372,,,,,0.07040969697,-0.1481826241
213.061,1.20374,-0.11293,,,,,0.07295393939,-0.1251440603
213.561,1.24537,-0.09195,,,,,0.0754769697,-0.1018949468
214.061,1.28689,-0.071,,,,,0.07799333333,-0.07867907801
214.561,1.32886,-0.04932,,,,,0.0805369697,-0.05465425532
215.061,1.37011,-0.02824,,,,,0.0830369697,-0.03129432624
215.561,1.41214,-0.00653,,,,,0.08558424242,-0.007236258865
216.061,1.45378,0.01739,,,,,0.08810787879,0.01927083333
216.561,1.49499,0.0367,,,,,0.09060545455,0.04066932624
217.061,1.53719,0.06097,,,,,0.0931630303,0.06756427305
217.561,1.57877,0.0836,,,,,0.0956830303,0.09264184397
218.061,1.62012,0.10494,,,,,0.09818909091,0.1162898936
218.417,1.65013,0.12187,,,,,0.1000078788,0.1350509752
218.818,1.62166,-0.0214,,,,,0.09828242424,-0.02371453901
219.318,1.58011,-0.11686,,,,,0.09576424242,-0.1294991135
219.818,1.53809,-0.18698,,,,,0.09321757576,-0.2072030142
220.318,1.49676,-0.239,,,,,0.09071272727,-0.2648492908
220.818,1.45488,-0.28392,,,,,0.08817454545,-0.3146276596
221.318,1.41337,-0.32274,,,,,0.08565878788,-0.3576462766
221.818,1.37189,-0.35567,,,,,0.08314484848,-0.3941378546
222.318,1.32971,-0.38641,,,,,0.08058848485,-0.4282025709
222.818,1.28838,-0.41448,,,,,0.07808363636,-0.4593085106
223.318,1.24684,-0.43732,,,,,0.07556606061,-0.4846187943
223.818,1.20476,-0.46046,,,,,0.07301575758,-0.5102615248
224.318,1.16336,-0.48167,,,,,0.07050666667,-0.5337655142
224.818,1.12175,-0.49947,,,,,0.06798484848,-0.5534906915
225.318,1.07986,-0.51932,,,,,0.06544606061,-0.5754875887
225.818,1.03846,-0.53401,,,,,0.0629369697,-0.5917664007
226.318,0.99647,-0.54938,,,,,0.06039212121,-0.6087987589
226.818,0.9551,-0.5655,,,,,0.05788484848,-0.626662234
227.318,0.91342,-0.57977,,,,,0.05535878788,-0.6424756206
227.818,0.87138,-0.59462,,,,,0.05281090909,-0.6589317376
228.318,0.83007,-0.60753,,,,,0.05030727273,-0.6732380319
228.818,0.78835,-0.62097,,,,,0.04777878788,-0.6881316489
229.318,0.74652,-0.6344,,,,,0.04524363636,-0.7030141844
229.818,0.70513,-0.64625,,,,,0.04273515152,-0.7161458333
230.318,0.66318,-0.65562,,,,,0.04019272727,-0.7265292553
230.818,0.62165,-0.66925,,,,,0.03767575758,-0.741633422
231.318,0.58025,-0.67868,,,,,0.03516666667,-0.7520833333
231.818,0.53802,-0.68976,,,,,0.03260727273,-0.7643617021
232.318,0.49664,-0.69798,,,,,0.03009939394,-0.7734707447
232.818,0.45515,-0.70274,,,,,0.02758484848,-0.7787455674
233.318,0.41312,-0.70773,,,,,0.02503757576,-0.784275266
233.818,0.37165,-0.70833,,,,,0.02252424242,-0.7849401596
234.318,0.32994,-0.7089,,,,,0.01999636364,-0.7855718085
234.818,0.28827,-0.70701,,,,,0.01747090909,-0.7834773936
235.318,0.2468,-0.70661,,,,,0.01495757576,-0.7830341312
235.818,0.2048,-0.70574,,,,,0.01241212121,-0.7820700355
236.318,0.16339,-0.70668,,,,,0.009902424242,-0.7831117021
236.818,0.12181,-0.70672,,,,,0.007382424242,-0.7831560284
237.318,0.07982,-0.70737,,,,,0.004837575758,-0.7838763298
237.818,0.03846,-0.70747,,,,,0.002330909091,-0.7839871454
238.276,0,-0.70637,,,,,0,-0.7827681738
238.578,0.02043,-0.70384,,,,,0.001238181818,-0.779964539
239.078,0.0619,-0.70251,,,,,0.003751515152,-0.7784906915
239.578,0.10366,-0.69957,,,,,0.006282424242,-0.7752327128
240.078,0.14559,-0.69757,,,,,0.008823636364,-0.7730164007
240.578,0.18675,-0.68889,,,,,0.01131818182,-0.7633976064
241.078,0.22876,-0.66537,,,,,0.01386424242,-0.7373337766
241.578,0.2705,-0.61584,,,,,0.01639393939,-0.6824468085
242.078,0.31182,-0.57413,,,,,0.01889818182,-0.6362256206
242.578,0.35381,-0.54225,,,,,0.0214430303,-0.6008976064
243.078,0.39534,-0.51618,,,,,0.02396,-0.5720079787
243.578,0.43702,-0.49375,,,,,0.02648606061,-0.547152039
244.078,0.4788,-0.46999,,,,,0.02901818182,-0.5208222518
244.578,0.52011,-0.44878,,,,,0.03152181818,-0.4973182624
245.078,0.56219,-0.42554,,,,,0.03407212121,-0.4715647163
245.578,0.60383,-0.40466,,,,,0.03659575758,-0.4484264184
246.078,0.6451,-0.38768,,,,,0.0390969697,-0.4296099291
246.578,0.68724,-0.36652,,,,,0.04165090909,-0.4061613475
247.078,0.72874,-0.34786,,,,,0.04416606061,-0.385483156
247.578,0.77023,-0.33138,,,,,0.04668060606,-0.3672207447
248.078,0.81219,-0.31144,,,,,0.04922363636,-0.3451241135
248.578,0.85355,-0.29369,,,,,0.05173030303,-0.325454344
249.078,0.89544,-0.27598,,,,,0.05426909091,-0.3058289007
249.578,0.93708,-0.25596,,,,,0.05679272727,-0.283643617
250.078,0.97842,-0.23787,,,,,0.05929818182,-0.2635970745
250.578,1.02054,-0.21642,,,,,0.06185090909,-0.2398271277
251.078,1.06208,-0.19629,,,,,0.06436848485,-0.2175199468
251.578,1.10355,-0.17776,,,,,0.06688181818,-0.1969858156
252.078,1.14553,-0.15818,,,,,0.06942606061,-0.1752881206
252.578,1.18697,-0.13735,,,,,0.07193757576,-0.1522052305
253.078,1.22878,-0.11768,,,,,0.07447151515,-0.1304078014
253.578,1.27054,-0.09493,,,,,0.07700242424,-0.1051972518
254.078,1.31172,-0.07615,,,,,0.07949818182,-0.08438608156
254.578,1.35391,-0.05447,,,,,0.08205515152,-0.06036125887
255.078,1.39554,-0.0309,,,,,0.08457818182,-0.03424202128
255.578,1.4367,-0.01286,,,,,0.08707272727,-0.01425088652
256.078,1.47883,0.01206,,,,,0.08962606061,0.0133643617
256.578,1.52035,0.03424,,,,,0.09214242424,0.03794326241
257.078,1.56193,0.05566,,,,,0.09466242424,0.06167996454
257.578,1.60378,0.08088,,,,,0.09719878788,0.08962765957
258.078,1.64521,0.10207,,,,,0.09970969697,0.1131094858
258.335,1.63857,0.02157,,,,,0.09930727273,0.02390292553
258.835,1.59668,-0.09838,,,,,0.09676848485,-0.1090203901
259.335,1.55526,-0.17134,,,,,0.09425818182,-0.1898714539
259.835,1.51314,-0.23144,,,,,0.09170545455,-0.2564716312
260.335,1.47182,-0.27866,,,,,0.08920121212,-0.3087987589
260.835,1.43027,-0.31448,,,,,0.0866830303,-0.3484929078
261.335,1.38808,-0.35288,,,,,0.08412606061,-0.3910460993
261.835,1.34681,-0.3834,,,,,0.08162484848,-0.4248670213
262.335,1.3051,-0.40913,,,,,0.0790969697,-0.4533798759
262.835,1.26326,-0.43634,,,,,0.07656121212,-0.4835328014
263.335,1.22182,-0.45638,,,,,0.07404969697,-0.5057402482
263.835,1.17997,-0.47867,,,,,0.07151333333,-0.5304410461
264.335,1.13838,-0.4979,,,,,0.06899272727,-0.5517508865
264.835,1.09693,-0.51446,,,,,0.06648060606,-0.5701019504
265.335,1.0548,-0.53394,,,,,0.06392727273,-0.5916888298
265.835,1.01348,-0.54914,,,,,0.0614230303,-0.6085328014
266.335,0.97184,-0.56526,,,,,0.05889939394,-0.6263962766
266.835,0.92997,-0.58113,,,,,0.05636181818,-0.6439827128
267.335,0.8885,-0.59473,,,,,0.05384848485,-0.6590536348
267.835,0.8466,-0.60813,,,,,0.05130909091,-0.6739029255
268.335,0.80506,-0.62184,,,,,0.04879151515,-0.6890957447
268.835,0.76357,-0.63197,,,,,0.0462769697,-0.7003213652
269.335,0.72146,-0.64496,,,,,0.04372484848,-0.7147163121
269.835,0.68008,-0.65638,,,,,0.0412169697,-0.7273714539
270.335,0.63865,-0.66698,,,,,0.03870606061,-0.7391179078
270.835,0.59644,-0.67771,,,,,0.03614787879,-0.751008422
271.335,0.55511,-0.68698,,,,,0.0336430303,-0.7612810284
271.835,0.51335,-0.69542,,,,,0.03111212121,-0.7706338652
272.335,0.47175,-0.7018,,,,,0.02859090909,-0.7777039007
272.835,0.43014,-0.70522,,,,,0.02606909091,-0.7814937943
273.335,0.38821,-0.70747,,,,,0.02352787879,-0.7839871454
273.835,0.34681,-0.70801,,,,,0.02101878788,-0.7845855496
274.335,0.30522,-0.7091,,,,,0.01849818182,-0.7857934397
274.835,0.26314,-0.70807,,,,,0.01594787879,-0.784652039
275.335,0.22184,-0.70933,,,,,0.01344484848,-0.7860483156
275.835,0.18009,-0.70861,,,,,0.01091454545,-0.7852504433
276.335,0.13823,-0.70908,,,,,0.008377575758,-0.7857712766
276.835,0.09691,-0.70754,,,,,0.005873333333,-0.7840647163
277.335,0.05486,-0.70852,,,,,0.003324848485,-0.7851507092
277.835,0.01335,-0.70768,,,,,0.0008090909091,-0.7842198582
278.096,0.00238,-0.70706,,,,,0.0001442424242,-0.7835328014
278.596,0.04545,-0.70573,,,,,0.002754545455,-0.7820589539
279.096,0.08714,-0.70221,,,,,0.005281212121,-0.7781582447
279.596,0.12843,-0.69856,,,,,0.007783636364,-0.7741134752
280.096,0.17053,-0.69449,,,,,0.01033515152,-0.7696032801
280.596,0.21209,-0.68442,,,,,0.01285393939,-0.7584441489
281.096,0.25359,-0.65104,,,,,0.01536909091,-0.7214539007
281.596,0.29552,-0.60108,,,,,0.01791030303,-0.6660904255
282.096,0.33678,-0.5661,,,,,0.02041090909,-0.6273271277
282.596,0.37888,-0.53533,,,,,0.02296242424,-0.5932291667
283.096,0.42043,-0.51042,,,,,0.02548060606,-0.565625
283.596,0.46177,-0.48898,,,,,0.02798606061,-0.5418661348
284.096,0.50392,-0.46495,,,,,0.03054060606,-0.5152371454
284.596,0.54544,-0.4453,,,,,0.0330569697,-0.4934618794
285.096,0.58674,-0.42814,,,,,0.03556,-0.474445922
285.596,0.62894,-0.40683,,,,,0.03811757576,-0.450831117
286.096,0.67025,-0.38873,,,,,0.04062121212,-0.4307734929
286.596,0.712,-0.37129,,,,,0.04315151515,-0.4114472518
287.096,0.75389,-0.35086,,,,,0.04569030303,-0.3888076241
287.596,0.79511,-0.33343,,,,,0.04818848485,-0.3694924645
288.096,0.83713,-0.31303,,,,,0.05073515152,-0.3468860816
288.596,0.87879,-0.29435,,,,,0.05326,-0.326185727
289.096,0.9202,-0.27688,,,,,0.05576969697,-0.3068262411
289.596,0.96212,-0.25726,,,,,0.05831030303,-0.2850842199
290.096,1.00365,-0.23905,,,,,0.06082727273,-0.2649046986
290.596,1.04535,-0.22154,,,,,0.06335454545,-0.2455008865
291.096,1.0872,-0.20087,,,,,0.06589090909,-0.2225953014
291.596,1.12838,-0.18148,,,,,0.06838666667,-0.201108156
292.096,1.17057,-0.16287,,,,,0.07094363636,-0.1804853723
292.596,1.21211,-0.14264,,,,,0.07346121212,-0.1580673759
293.096,1.25337,-0.12337,,,,,0.07596181818,-0.1367132092
293.596,1.29555,-0.10055,,,,,0.07851818182,-0.1114250887
294.096,1.33707,-0.0795,,,,,0.08103454545,-0.08809840426
294.596,1.37857,-0.06055,,,,,0.08354969697,-0.06709884752
295.096,1.42041,-0.03957,,,,,0.08608545455,-0.04384973404
295.596,1.46187,-0.01625,,,,,0.08859818182,-0.01800753546
296.096,1.50378,0.00675,,,,,0.09113818182,0.007480053191
296.596,1.5455,0.03142,,,,,0.09366666667,0.03481826241
297.096,1.58675,0.05284,,,,,0.09616666667,0.05855496454
297.596,1.62889,0.07606,,,,,0.09872060606,0.08428634752
297.853,1.65025,0.08564,,,,,0.1000151515,0.09490248227
298.353,1.61363,-0.07242,,,,,0.09779575758,-0.08025265957
298.853,1.57146,-0.16073,,,,,0.09524,-0.1781139184
299.353,1.53014,-0.21939,,,,,0.09273575758,-0.2431183511
299.853,1.48849,-0.26818,,,,,0.09021151515,-0.2971852837
300.353,1.44657,-0.31113,,,,,0.08767090909,-0.3447805851
300.853,1.40512,-0.34477,,,,,0.08515878788,-0.3820589539
301.353,1.36338,-0.37684,,,,,0.08262909091,-0.4175975177
301.853,1.3217,-0.40509,,,,,0.0801030303,-0.4489029255
302.353,1.28023,-0.42872,,,,,0.07758969697,-0.4750886525
302.853,1.2382,-0.45326,,,,,0.07504242424,-0.5022828014
303.353,1.19683,-0.47517,,,,,0.07253515152,-0.5265625
303.853,1.15519,-0.49489,,,,,0.07001151515,-0.5484153369
304.353,1.11323,-0.51333,,,,,0.06746848485,-0.568849734
304.853,1.07182,-0.53166,,,,,0.06495878788,-0.589162234
305.353,1.02999,-0.54731,,,,,0.06242363636,-0.6065048759
305.853,0.98837,-0.56521,,,,,0.05990121212,-0.6263408688
306.353,0.9469,-0.57798,,,,,0.05738787879,-0.6404920213
306.853,0.90478,-0.59241,,,,,0.05483515152,-0.6564827128
307.353,0.86342,-0.60632,,,,,0.05232848485,-0.6718971631
307.853,0.82194,-0.61764,,,,,0.04981454545,-0.6844414894
308.353,0.77978,-0.63082,,,,,0.04725939394,-0.6990469858
308.853,0.73839,-0.64352,,,,,0.04475090909,-0.7131205674
309.353,0.69683,-0.65302,,,,,0.04223212121,-0.7236480496
309.853,0.65495,-0.66516,,,,,0.03969393939,-0.7371010638
310.353,0.61351,-0.67545,,,,,0.03718242424,-0.7485039894
310.853,0.57158,-0.68549,,,,,0.03464121212,-0.7596298759
311.353,0.53011,-0.69326,,,,,0.03212787879,-0.7682402482
311.853,0.48861,-0.69954,,,,,0.02961272727,-0.7751994681
312.353,0.44655,-0.70451,,,,,0.02706363636,-0.7807070035
312.853,0.40512,-0.70726,,,,,0.02455272727,-0.7837544326
313.353,0.36341,-0.70776,,,,,0.02202484848,-0.7843085106
313.853,0.32161,-0.70968,,,,,0.01949151515,-0.7864361702
314.353,0.28019,-0.7081,,,,,0.01698121212,-0.7846852837
314.853,0.23827,-0.70889,,,,,0.01444060606,-0.785560727
315.353,0.19671,-0.70854,,,,,0.01192181818,-0.7851728723
315.853,0.15537,-0.70931,,,,,0.009416363636,-0.7860261525
316.353,0.1131,-0.70846,,,,,0.006854545455,-0.7850842199
316.853,0.07182,-0.70881,,,,,0.004352727273,-0.7854720745
317.353,0.03021,-0.70679,,,,,0.001830909091,-0.7832335993
317.713,-0.00012,-0.70897,,,,,-0.000007272727273,-0.7856493794
318.114,0.02878,-0.7054,,,,,0.001744242424,-0.7816932624
318.614,0.07021,-0.70286,,,,,0.004255151515,-0.7788785461
319.114,0.11217,-0.70047,,,,,0.006798181818,-0.7762300532
319.614,0.1536,-0.6976,,,,,0.009309090909,-0.7730496454
320.114,0.19544,-0.68905,,,,,0.01184484848,-0.7635749113
320.614,0.2371,-0.67092,,,,,0.01436969697,-0.7434840426
321.114,0.27839,-0.62858,,,,,0.01687212121,-0.6965647163
321.614,0.32052,-0.58712,,,,,0.01942545455,-0.6506205674
322.114,0.36209,-0.55498,,,,,0.02194484848,-0.6150044326
322.614,0.40346,-0.53063,,,,,0.02445212121,-0.5880208333
323.114,0.44556,-0.50513,,,,,0.02700363636,-0.5597628546
323.614,0.487,-0.48256,,,,,0.02951515152,-0.534751773
324.114,0.52868,-0.46267,,,,,0.03204121212,-0.5127105496
324.614,0.57053,-0.44221,,,,,0.03457757576,-0.4900376773
325.114,0.61186,-0.4236,,,,,0.03708242424,-0.4694148936
325.614,0.65385,-0.40603,,,,,0.03962727273,-0.4499445922
326.114,0.69548,-0.38662,,,,,0.04215030303,-0.4284352837
326.614,0.73677,-0.37103,,,,,0.04465272727,-0.4111591312
327.114,0.7789,-0.34988,,,,,0.04720606061,-0.3877216312
327.614,0.82033,-0.33257,,,,,0.0497169697,-0.3685394504
328.114,0.862,-0.31414,,,,,0.05224242424,-0.3481161348
328.614,0.90381,-0.29644,,,,,0.05477636364,-0.328501773
329.114,0.94518,-0.27728,,,,,0.05728363636,-0.3072695035
329.614,0.98718,-0.25748,,,,,0.05982909091,-0.2853280142
330.114,1.02886,-0.23856,,,,,0.06235515152,-0.2643617021
330.614,1.07001,-0.22086,,,,,0.06484909091,-0.2447473404
331.114,1.11228,-0.19948,,,,,0.06741090909,-0.2210549645
331.614,1.15384,-0.17996,,,,,0.06992969697,-0.1994237589
332.114,1.19515,-0.16504,,,,,0.07243333333,-0.1828900709
332.614,1.23724,-0.14228,,,,,0.07498424242,-0.1576684397
333.114,1.27863,-0.12276,,,,,0.07749272727,-0.136037234
333.614,1.32038,-0.10388,,,,,0.0800230303,-0.1151152482
334.114,1.3621,-0.0817,,,,,0.08255151515,-0.09053634752
334.614,1.40351,-0.06194,,,,,0.08506121212,-0.0686391844
335.114,1.44548,-0.03956,,,,,0.08760484848,-0.04383865248
335.614,1.48715,-0.01832,,,,,0.09013030303,-0.02030141844
336.114,1.5285,0.00323,,,,,0.09263636364,0.003579343972
336.614,1.57056,0.02875,,,,,0.09518545455,0.03185948582
337.114,1.61189,0.05012,,,,,0.09769030303,0.05554078014
337.569,1.65009,0.07116,,,,,0.1000054545,0.07885638298
337.871,1.63,-0.04035,,,,,0.09878787879,-0.04471409574
338.371,1.58853,-0.13979,,,,,0.09627454545,-0.1549091312
338.871,1.54674,-0.20695,,,,,0.09374181818,-0.2293328901
339.371,1.50507,-0.26114,,,,,0.09121636364,-0.2893838652
339.871,1.4636,-0.30244,,,,,0.0887030303,-0.3351507092
340.371,1.42163,-0.33933,,,,,0.08615939394,-0.3760305851
340.871,1.38012,-0.37066,,,,,0.08364363636,-0.4107491135
341.371,1.33862,-0.39967,,,,,0.08112848485,-0.4428967199
341.871,1.29651,-0.42737,,,,,0.07857636364,-0.4735926418
342.371,1.25518,-0.45012,,,,,0.07607151515,-0.4988031915
342.871,1.21342,-0.47144,,,,,0.07354060606,-0.522429078
343.371,1.17175,-0.49179,,,,,0.07101515152,-0.5449800532
343.871,1.13029,-0.51255,,,,,0.06850242424,-0.5679853723
344.371,1.08822,-0.52878,,,,,0.06595272727,-0.5859707447
344.871,1.04681,-0.54581,,,,,0.0634430303,-0.6048426418
345.371,1.00528,-0.56008,,,,,0.06092606061,-0.6206560284
345.871,0.96316,-0.57669,,,,,0.05837333333,-0.6390625
346.371,0.92181,-0.58818,,,,,0.05586727273,-0.6517952128
346.871,0.88031,-0.6019,,,,,0.05335212121,-0.6669991135
347.371,0.83829,-0.6159,,,,,0.05080545455,-0.6825132979
347.871,0.79689,-0.62675,,,,,0.04829636364,-0.6945367908
348.371,0.75501,-0.63927,,,,,0.04575818182,-0.7084109043
348.871,0.71358,-0.65135,,,,,0.04324727273,-0.7217974291
349.371,0.6719,-0.66084,,,,,0.04072121212,-0.7323138298
349.871,0.62984,-0.67326,,,,,0.03817212121,-0.7460771277
350.371,0.5885,-0.6824,,,,,0.03566666667,-0.7562056738
350.871,0.54686,-0.69285,,,,,0.0331430303,-0.7677859043
351.371,0.50489,-0.70002,,,,,0.03059939394,-0.775731383
351.871,0.46356,-0.70488,,,,,0.02809454545,-0.7811170213
352.371,0.42171,-0.70765,,,,,0.02555818182,-0.7841866135
352.871,0.38002,-0.70863,,,,,0.02303151515,-0.7852726064
353.371,0.33866,-0.70813,,,,,0.02052484848,-0.7847185284
353.871,0.29651,-0.70995,,,,,0.01797030303,-0.7867353723
354.371,0.2551,-0.70919,,,,,0.01546060606,-0.7858931738
354.871,0.21364,-0.70918,,,,,0.01294787879,-0.7858820922
355.371,0.17156,-0.70622,,,,,0.01039757576,-0.7826019504
355.871,0.13011,-0.70747,,,,,0.007885454545,-0.7839871454
356.371,0.08849,-0.70561,,,,,0.005363030303,-0.7819259752
356.871,0.04672,-0.70638,,,,,0.002831515152,-0.7827792553
357.371,0.00526,-0.70757,,,,,0.0003187878788,-0.784097961
357.633,0.01172,-0.70703,,,,,0.0007103030303,-0.7834995567
358.133,0.05374,-0.70435,,,,,0.003256969697,-0.7805296986
358.633,0.09498,-0.70136,,,,,0.005756363636,-0.7772163121
359.133,0.13723,-0.69864,,,,,0.008316969697,-0.7742021277
359.633,0.17872,-0.69538,,,,,0.01083151515,-0.770589539
360.133,0.22008,-0.68173,,,,,0.01333818182,-0.7554632092
360.633,0.26222,-0.65289,,,,,0.01589212121,-0.7235039894
361.133,0.30366,-0.6103,,,,,0.01840363636,-0.6763076241
361.633,0.3452,-0.57643,,,,,0.02092121212,-0.6387743794
362.133,0.38726,-0.54691,,,,,0.02347030303,-0.6060616135
362.633,0.42844,-0.52338,,,,,0.02596606061,-0.5799867021
363.133,0.47038,-0.50051,,,,,0.02850787879,-0.5546431738
363.633,0.51218,-0.47933,,,,,0.03104121212,-0.5311724291
364.133,0.55343,-0.46061,,,,,0.03354121212,-0.5104277482
364.633,0.59545,-0.4387,,,,,0.03608787879,-0.4861480496
365.133,0.63703,-0.42172,,,,,0.03860787879,-0.4673315603
365.633,0.67856,-0.40185,,,,,0.04112484848,-0.4453125
366.133,0.7204,-0.38337,,,,,0.04366060606,-0.4248337766
366.633,0.76183,-0.36741,,,,,0.04617151515,-0.4071476064
367.133,0.80374,-0.34901,,,,,0.04871151515,-0.3867575355
367.633,0.84544,-0.32891,,,,,0.05123878788,-0.3644835993
368.133,0.88666,-0.31527,,,,,0.0537369697,-0.3493683511
368.633,0.92886,-0.29468,,,,,0.05629454545,-0.3265514184
369.133,0.97044,-0.27568,,,,,0.05881454545,-0.3054964539
369.633,1.01178,-0.25736,,,,,0.06132,-0.2851950355
370.133,1.05386,-0.23861,,,,,0.06387030303,-0.2644171099
370.633,1.09531,-0.21991,,,,,0.06638242424,-0.2436945922
371.133,1.13701,-0.20214,,,,,0.06890969697,-0.2240026596
371.633,1.17876,-0.18318,,,,,0.07144,-0.2029920213
372.133,1.22007,-0.16203,,,,,0.07394363636,-0.1795545213
372.633,1.26215,-0.14342,,,,,0.07649393939,-0.1589317376
373.133,1.30375,-0.12082,,,,,0.07901515152,-0.1338874113
373.633,1.34506,-0.1035,,,,,0.08151878788,-0.1146941489
374.133,1.38716,-0.07964,,,,,0.08407030303,-0.0882535461
374.633,1.42866,-0.06252,,,,,0.08658545455,-0.06928191489
375.133,1.4703,-0.0408,,,,,0.08910909091,-0.04521276596
375.633,1.51218,-0.01496,,,,,0.09164727273,-0.01657801418
376.133,1.55343,0.0061,,,,,0.09414727273,0.006759751773
376.633,1.59552,0.0281,,,,,0.09669818182,0.0311391844
377.133,1.63719,0.05178,,,,,0.09922363636,0.05738031915
377.39,1.64773,0.02619,,,,,0.09986242424,0.02902260638
377.89,1.60502,-0.11497,,,,,0.09727393939,-0.1274046986
378.39,1.56353,-0.19138,,,,,0.09475939394,-0.2120789007
378.89,1.52196,-0.24734,,,,,0.09224,-0.2740913121
379.39,1.47995,-0.29446,,,,,0.08969393939,-0.3263076241
379.89,1.43852,-0.3352,,,,,0.0871830303,-0.3714539007
380.39,1.39685,-0.36701,,,,,0.08465757576,-0.406704344
380.89,1.35504,-0.39583,,,,,0.08212363636,-0.4386414007
381.39,1.31362,-0.41979,,,,,0.07961333333,-0.4651928191
381.89,1.27162,-0.44551,,,,,0.07706787879,-0.4936945922
382.39,1.23021,-0.4666,,,,,0.07455818182,-0.5170656028
382.89,1.18868,-0.48578,,,,,0.07204121212,-0.5383200355
383.39,1.14651,-0.50614,,,,,0.06948545455,-0.5608820922
383.89,1.10526,-0.52413,,,,,0.06698545455,-0.5808178191
384.39,1.06361,-0.53889,,,,,0.06446121212,-0.5971742021
384.89,1.02162,-0.55748,,,,,0.06191636364,-0.6177748227
385.39,0.98021,-0.57122,,,,,0.05940666667,-0.6330008865
385.89,0.9385,-0.5842,,,,,0.05687878788,-0.6473847518
386.39,0.89677,-0.59907,,,,,0.05434969697,-0.6638630319
386.89,0.8553,-0.61261,,,,,0.05183636364,-0.6788674645
387.39,0.81322,-0.62492,,,,,0.04928606061,-0.6925088652
387.89,0.77187,-0.63716,,,,,0.04678,-0.706072695
388.39,0.73032,-0.64897,,,,,0.04426181818,-0.7191600177
388.89,0.68833,-0.66081,,,,,0.0417169697,-0.7322805851
389.39,0.64688,-0.66965,,,,,0.03920484848,-0.7420766844
389.89,0.60508,-0.68051,,,,,0.03667151515,-0.7541112589
390.39,0.56347,-0.6884,,,,,0.03414969697,-0.7628546099
390.89,0.52199,-0.69586,,,,,0.03163575758,-0.7711214539
391.39,0.47994,-0.70341,,,,,0.02908727273,-0.7794880319
391.89,0.43853,-0.70555,,,,,0.02657757576,-0.7818594858
392.39,0.39713,-0.70792,,,,,0.02406848485,-0.7844858156
392.89,0.35486,-0.70874,,,,,0.02150666667,-0.7853945035
393.39,0.31359,-0.70772,,,,,0.01900545455,-0.7842641844
393.89,0.27186,-0.70781,,,,,0.01647636364,-0.7843639184
394.39,0.23013,-0.70868,,,,,0.01394727273,-0.7853280142
394.89,0.18855,-0.7059,,,,,0.01142727273,-0.7822473404
395.39,0.14667,-0.70632,,,,,0.008889090909,-0.782712766
395.89,0.1052,-0.70633,,,,,0.006375757576,-0.7827238475
396.39,0.06363,-0.70587,,,,,0.003856363636,-0.7822140957
396.89,0.02149,-0.70493,,,,,0.001302424242,-0.7811724291
397.15,-0.00001,-0.70659,,,,,-0.0000006060606061,-0.7830119681