File: mechanical/hysteresis/data/pristine_conductive_3.csv
Time,Extension,Load,Length,Width,Thickness,CS Area,Strain,Stress
(s),(mm),(N),(mm),(mm),(mm),(mm^2),(mm/mm),(MPa)
0,0,-0.03847,16.5,2.82,0.35,0.987,0,-0.03897669706
0.5,0.03861,0.02817,,,,,0.00234,0.02854103343
1,0.08067,0.05639,,,,,0.004889090909,0.05713272543
1.5,0.12217,0.0768,,,,,0.007404242424,0.07781155015
2,0.16384,0.08869,,,,,0.00992969697,0.08985815603
2.5,0.20562,0.10133,,,,,0.01246181818,0.1026646403
3,0.24692,0.10879,,,,,0.01496484848,0.1102228977
3.5,0.28898,0.11787,,,,,0.01751393939,0.1194224924
4,0.33061,0.12312,,,,,0.0200369697,0.1247416413
4.5,0.37189,0.1295,,,,,0.02253878788,0.1312056738
5,0.41407,0.13484,,,,,0.02509515152,0.1366160081
5.5,0.45555,0.13922,,,,,0.02760909091,0.1410536981
6,0.49709,0.14359,,,,,0.03012666667,0.1454812563
6.5,0.53904,0.14924,,,,,0.03266909091,0.1512056738
7,0.58042,0.1511,,,,,0.0351769697,0.1530901722
7.5,0.62229,0.15592,,,,,0.03771454545,0.1579736575
8,0.66401,0.16023,,,,,0.0402430303,0.1623404255
8.5,0.70531,0.16262,,,,,0.04274606061,0.1647619048
9,0.74737,0.16605,,,,,0.04529515152,0.1682370821
9.5,0.78894,0.16969,,,,,0.04781454545,0.1719250253
10,0.83031,0.17082,,,,,0.05032181818,0.1730699088
10.5,0.87232,0.17503,,,,,0.05286787879,0.1773353597
11,0.9137,0.17824,,,,,0.05537575758,0.1805876393
11.5,0.95563,0.1804,,,,,0.0579169697,0.1827760892
12,0.99729,0.18262,,,,,0.06044181818,0.1850253293
12.5,1.03864,0.18506,,,,,0.06294787879,0.1874974671
13,1.08072,0.18868,,,,,0.06549818182,0.1911651469
13.5,1.12238,0.19042,,,,,0.0680230303,0.1929280648
14,1.16355,0.19093,,,,,0.07051818182,0.1934447822
14.5,1.20581,0.19693,,,,,0.07307939394,0.1995238095
15,1.24721,0.19766,,,,,0.07558848485,0.2002634245
15.5,1.28876,0.19979,,,,,0.07810666667,0.2024214792
16,1.33077,0.20288,,,,,0.08065272727,0.2055521783
16.5,1.372,0.2039,,,,,0.08315151515,0.206585613
17,1.41393,0.20612,,,,,0.08569272727,0.2088348531
17.5,1.45557,0.2096,,,,,0.08821636364,0.212360689
18,1.49695,0.21181,,,,,0.09072424242,0.2145997974
18.5,1.53895,0.21579,,,,,0.09326969697,0.2186322188
19,1.58059,0.21714,,,,,0.09579333333,0.22
19.5,1.62207,0.21794,,,,,0.09830727273,0.220810537
19.834,1.65014,0.22105,,,,,0.1000084848,0.2239614995
20.235,1.6214,0.10106,,,,,0.09826666667,0.1023910841
20.735,1.57993,0.01946,,,,,0.09575333333,0.01971631206
21.235,1.53795,-0.03913,,,,,0.09320909091,-0.03964539007
21.735,1.49645,-0.08642,,,,,0.09069393939,-0.08755825735
22.235,1.45506,-0.12513,,,,,0.08818545455,-0.1267781155
22.735,1.41276,-0.16163,,,,,0.08562181818,-0.1637588652
23.235,1.37148,-0.19012,,,,,0.08312,-0.1926241135
23.735,1.32984,-0.21881,,,,,0.08059636364,-0.2216919959
24.235,1.28802,-0.24347,,,,,0.07806181818,-0.2466767984
24.735,1.24645,-0.26512,,,,,0.07554242424,-0.2686119554
25.235,1.20467,-0.28543,,,,,0.07301030303,-0.289189463
25.735,1.1631,-0.30557,,,,,0.07049090909,-0.3095947315
26.235,1.12156,-0.32098,,,,,0.06797333333,-0.3252077001
26.735,1.07948,-0.33853,,,,,0.0654230303,-0.3429888551
27.235,1.03821,-0.35429,,,,,0.06292181818,-0.3589564336
27.735,0.9966,-0.36916,,,,,0.0604,-0.3740222898
28.235,0.95447,-0.38453,,,,,0.05784666667,-0.3895947315
28.735,0.91324,-0.39737,,,,,0.05534787879,-0.4026038501
29.235,0.8714,-0.40716,,,,,0.05281212121,-0.4125227964
29.735,0.82965,-0.41993,,,,,0.05028181818,-0.4254609929
30.235,0.78821,-0.4297,,,,,0.04777030303,-0.4353596758
30.735,0.74628,-0.44195,,,,,0.04522909091,-0.4477710233
31.235,0.7047,-0.44947,,,,,0.04270909091,-0.4553900709
31.735,0.66327,-0.46434,,,,,0.04019818182,-0.4704559271
32.235,0.6212,-0.47189,,,,,0.03764848485,-0.4781053698
32.735,0.57977,-0.48119,,,,,0.03513757576,-0.4875278622
33.235,0.53815,-0.48962,,,,,0.03261515152,-0.4960688956
33.735,0.4963,-0.50039,,,,,0.03007878788,-0.5069807497
34.235,0.45487,-0.50623,,,,,0.02756787879,-0.5128976697
34.735,0.41294,-0.51363,,,,,0.02502666667,-0.5203951368
35.235,0.37152,-0.52199,,,,,0.02251636364,-0.5288652482
35.735,0.32987,-0.53033,,,,,0.01999212121,-0.5373150963
36.235,0.28786,-0.5383,,,,,0.01744606061,-0.5453900709
36.735,0.24649,-0.54638,,,,,0.01493878788,-0.5535764944
37.235,0.20485,-0.55294,,,,,0.01241515152,-0.5602228977
37.735,0.16284,-0.56118,,,,,0.009869090909,-0.5685714286
38.235,0.12155,-0.56558,,,,,0.007366666667,-0.573029382
38.735,0.07966,-0.57302,,,,,0.004827878788,-0.5805673759
39.235,0.03804,-0.5781,,,,,0.002305454545,-0.5857142857
39.69,-0.00002,-0.58355,,,,,-0.000001212121212,-0.5912360689
39.992,0.02056,-0.52081,,,,,0.001246060606,-0.5276697062
40.492,0.062,-0.47683,,,,,0.003757575758,-0.4831104357
40.992,0.10409,-0.44351,,,,,0.006308484848,-0.4493515704
41.492,0.14555,-0.41865,,,,,0.008821212121,-0.4241641337
41.992,0.18712,-0.39652,,,,,0.01134060606,-0.4017426545
42.492,0.22914,-0.37409,,,,,0.01388727273,-0.3790172239
42.992,0.2704,-0.3557,,,,,0.01638787879,-0.3603850051
43.492,0.3123,-0.33795,,,,,0.01892727273,-0.3424012158
43.992,0.35408,-0.31995,,,,,0.02145939394,-0.3241641337
44.492,0.39529,-0.30419,,,,,0.0239569697,-0.3081965552
44.992,0.43748,-0.28758,,,,,0.02651393939,-0.2913677812
45.492,0.47906,-0.27183,,,,,0.02903393939,-0.2754103343
45.992,0.52038,-0.25782,,,,,0.03153818182,-0.2612158055
46.492,0.56238,-0.24116,,,,,0.03408363636,-0.2443363728
46.992,0.60383,-0.22686,,,,,0.03659575758,-0.2298480243
47.492,0.64564,-0.21335,,,,,0.03912969697,-0.2161600811
47.992,0.68739,-0.19803,,,,,0.04166,-0.2006382979
48.492,0.72866,-0.18533,,,,,0.04416121212,-0.1877710233
48.992,0.77077,-0.17107,,,,,0.04671333333,-0.1733232016
49.492,0.81236,-0.1564,,,,,0.04923393939,-0.1584599797
49.992,0.85363,-0.14453,,,,,0.05173515152,-0.1464336373
50.492,0.89583,-0.12979,,,,,0.05429272727,-0.1314994934
50.992,0.93727,-0.1166,,,,,0.05680424242,-0.1181357649
51.492,0.9789,-0.10359,,,,,0.05932727273,-0.1049544073
51.992,1.02076,-0.08692,,,,,0.06186424242,-0.08806484296
52.492,1.06211,-0.0756,,,,,0.06437030303,-0.07659574468
52.992,1.10407,-0.06315,,,,,0.06691333333,-0.06398176292
53.492,1.14572,-0.05061,,,,,0.06943757576,-0.05127659574
53.992,1.18699,-0.03844,,,,,0.07193878788,-0.03894630193
54.492,1.2291,-0.02575,,,,,0.07449090909,-0.02608915907
54.992,1.27065,-0.01345,,,,,0.07700909091,-0.01362715299
55.492,1.31214,-0.00139,,,,,0.07952363636,-0.001408308004
55.992,1.35408,0.01102,,,,,0.08206545455,0.01116514691
56.492,1.39538,0.02159,,,,,0.08456848485,0.02187436677
56.992,1.43742,0.03271,,,,,0.08711636364,0.0331408308
57.492,1.47902,0.04512,,,,,0.08963757576,0.04571428571
57.992,1.52038,0.05461,,,,,0.09214424242,0.05532928065
58.492,1.56248,0.06533,,,,,0.09469575758,0.06619047619
58.992,1.60406,0.07567,,,,,0.09721575758,0.07666666667
59.492,1.64534,0.08337,,,,,0.09971757576,0.08446808511
59.746,1.63858,0.02575,,,,,0.09930787879,0.02608915907
60.246,1.59616,-0.06422,,,,,0.0967369697,-0.06506585613
60.746,1.5548,-0.12249,,,,,0.09423030303,-0.1241033435
61.246,1.51333,-0.16807,,,,,0.0917169697,-0.1702836879
61.746,1.47128,-0.20586,,,,,0.08916848485,-0.2085714286
62.246,1.42978,-0.23789,,,,,0.08665333333,-0.2410233029
62.746,1.38813,-0.26507,,,,,0.08412909091,-0.2685612969
63.246,1.34647,-0.28983,,,,,0.08160424242,-0.2936474164
63.746,1.30499,-0.31372,,,,,0.07909030303,-0.317852077
64.246,1.26297,-0.33293,,,,,0.07654363636,-0.3373150963
64.746,1.22153,-0.35259,,,,,0.07403212121,-0.3572340426
65.246,1.17998,-0.36813,,,,,0.07151393939,-0.3729787234
65.746,1.13795,-0.38625,,,,,0.06896666667,-0.391337386
66.246,1.09659,-0.40149,,,,,0.06646,-0.4067781155
66.746,1.05479,-0.41513,,,,,0.06392666667,-0.420597771
67.246,1.01305,-0.42969,,,,,0.0613969697,-0.4353495441
67.746,0.97167,-0.44071,,,,,0.05888909091,-0.446514691
68.246,0.92959,-0.45161,,,,,0.05633878788,-0.4575582573
68.746,0.88816,-0.4657,,,,,0.05382787879,-0.4718338399
69.246,0.84668,-0.47322,,,,,0.05131393939,-0.4794528875
69.746,0.8046,-0.48577,,,,,0.04876363636,-0.4921681864
70.246,0.76318,-0.49598,,,,,0.04625333333,-0.5025126646
70.746,0.72161,-0.50403,,,,,0.04373393939,-0.510668693
71.246,0.6797,-0.51573,,,,,0.04119393939,-0.5225227964
71.746,0.63821,-0.5231,,,,,0.03867939394,-0.5299898683
72.246,0.59639,-0.5332,,,,,0.03614484848,-0.5402228977
72.746,0.55488,-0.54192,,,,,0.03362909091,-0.5490577508
73.246,0.51331,-0.54908,,,,,0.03110969697,-0.5563120567
73.746,0.47116,-0.55688,,,,,0.02855515152,-0.5642147923
74.246,0.4299,-0.56379,,,,,0.02605454545,-0.5712158055
74.746,0.38828,-0.57264,,,,,0.02353212121,-0.5801823708
75.246,0.34623,-0.57645,,,,,0.02098363636,-0.5840425532
75.746,0.30485,-0.58461,,,,,0.01847575758,-0.5923100304
76.246,0.26318,-0.59228,,,,,0.01595030303,-0.6000810537
76.746,0.22139,-0.59657,,,,,0.01341757576,-0.6044275583
77.246,0.18,-0.60278,,,,,0.01090909091,-0.6107193516
77.746,0.13798,-0.61036,,,,,0.008362424242,-0.6183991895
78.246,0.09651,-0.61779,,,,,0.005849090909,-0.6259270517
78.746,0.05502,-0.62187,,,,,0.003334545455,-0.6300607903
79.246,0.01292,-0.63084,,,,,0.000783030303,-0.6391489362
79.504,0.00273,-0.61153,,,,,0.0001654545455,-0.6195845998
80.004,0.04576,-0.54636,,,,,0.002773333333,-0.553556231
80.504,0.08713,-0.51101,,,,,0.005280606061,-0.5177406282
81.004,0.12887,-0.48646,,,,,0.00781030303,-0.4928672746
81.504,0.1708,-0.46167,,,,,0.01035151515,-0.4677507599
82.004,0.21197,-0.44004,,,,,0.01284666667,-0.4458358663
82.504,0.25407,-0.42472,,,,,0.01539818182,-0.4303140831
83.004,0.29572,-0.40742,,,,,0.01792242424,-0.4127862209
83.504,0.33699,-0.38972,,,,,0.02042363636,-0.3948530902
84.004,0.37906,-0.37422,,,,,0.02297333333,-0.3791489362
84.504,0.42061,-0.35884,,,,,0.02549151515,-0.3635663627
85.004,0.46223,-0.34427,,,,,0.02801393939,-0.348804458
85.504,0.50404,-0.32706,,,,,0.03054787879,-0.3313677812
86.004,0.54536,-0.31482,,,,,0.03305212121,-0.3189665653
86.504,0.58742,-0.30126,,,,,0.03560121212,-0.3052279635
87.004,0.62897,-0.2859,,,,,0.03811939394,-0.2896656535
87.504,0.67028,-0.27262,,,,,0.0406230303,-0.2762107396
88.004,0.71251,-0.25886,,,,,0.04318242424,-0.2622695035
88.504,0.7539,-0.24551,,,,,0.04569090909,-0.2487436677
89.004,0.79547,-0.23271,,,,,0.04821030303,-0.235775076
89.504,0.83741,-0.21875,,,,,0.05075212121,-0.2216312057
90.004,0.87869,-0.20712,,,,,0.05325393939,-0.2098480243
90.504,0.92062,-0.19165,,,,,0.05579515152,-0.1941742655
91.004,0.96242,-0.1793,,,,,0.05832848485,-0.1816616008
91.504,1.00359,-0.16396,,,,,0.06082363636,-0.1661195542
92.004,1.0457,-0.15452,,,,,0.06337575758,-0.1565552178
92.504,1.08736,-0.13873,,,,,0.06590060606,-0.1405572442
93.004,1.12872,-0.12793,,,,,0.06840727273,-0.1296149949
93.504,1.17073,-0.11491,,,,,0.07095333333,-0.1164235056
94.004,1.21214,-0.10221,,,,,0.0734630303,-0.103556231
94.504,1.25398,-0.08952,,,,,0.07599878788,-0.09069908815
95.004,1.2957,-0.07623,,,,,0.07852727273,-0.07723404255
95.504,1.33697,-0.06404,,,,,0.08102848485,-0.06488348531
96.004,1.37909,-0.04939,,,,,0.08358121212,-0.05004052685
96.504,1.42067,-0.03604,,,,,0.08610121212,-0.03651469098
97.004,1.46199,-0.02558,,,,,0.08860545455,-0.02591691996
97.504,1.50409,-0.0115,,,,,0.0911569697,-0.0116514691
98.004,1.54554,-0.0009,,,,,0.09366909091,-0.0009118541033
98.504,1.58718,0.00963,,,,,0.09619272727,0.009756838906
99.004,1.62907,0.023,,,,,0.09873151515,0.0233029382
99.258,1.6502,0.02935,,,,,0.1000121212,0.02973657548
99.758,1.61322,-0.08799,,,,,0.09777090909,-0.08914893617
100.258,1.57146,-0.14857,,,,,0.09524,-0.150526849
100.758,1.52979,-0.19474,,,,,0.09271454545,-0.1973049645
101.258,1.48822,-0.23176,,,,,0.09019515152,-0.2348125633
101.758,1.44632,-0.2643,,,,,0.08765575758,-0.267781155
102.258,1.40484,-0.29129,,,,,0.08514181818,-0.2951266464
102.758,1.36328,-0.31638,,,,,0.0826230303,-0.3205471125
103.258,1.32114,-0.33937,,,,,0.08006909091,-0.3438399189
103.758,1.27986,-0.35708,,,,,0.07756727273,-0.3617831814
104.258,1.23817,-0.37775,,,,,0.07504060606,-0.3827254306
104.758,1.19622,-0.39481,,,,,0.07249818182,-0.4000101317
105.258,1.15494,-0.41006,,,,,0.06999636364,-0.4154609929
105.758,1.11295,-0.42464,,,,,0.06745151515,-0.4302330294
106.258,1.07136,-0.43778,,,,,0.06493090909,-0.4435460993
106.758,1.02994,-0.45302,,,,,0.06242060606,-0.4589868288
107.258,0.98787,-0.46267,,,,,0.05987090909,-0.4687639311
107.758,0.94639,-0.47814,,,,,0.0573569697,-0.48443769
108.258,0.90494,-0.48648,,,,,0.05484484848,-0.492887538
108.758,0.86294,-0.49997,,,,,0.05229939394,-0.5065552178
109.258,0.8215,-0.50581,,,,,0.04978787879,-0.5124721378
109.758,0.77976,-0.51698,,,,,0.04725818182,-0.5237892604
110.258,0.7381,-0.52629,,,,,0.04473333333,-0.5332218845
110.758,0.69657,-0.53459,,,,,0.04221636364,-0.5416312057
111.258,0.65453,-0.54578,,,,,0.03966848485,-0.5529685917
111.758,0.61321,-0.55095,,,,,0.03716424242,-0.5582066869
112.258,0.57152,-0.56171,,,,,0.03463757576,-0.5691084093
112.758,0.52951,-0.56945,,,,,0.03209151515,-0.5769503546
113.258,0.48815,-0.57847,,,,,0.02958484848,-0.5860891591
113.758,0.44644,-0.58391,,,,,0.0270569697,-0.5916008105
114.258,0.40466,-0.59233,,,,,0.02452484848,-0.6001317123
114.758,0.36328,-0.59811,,,,,0.0220169697,-0.6059878419
115.258,0.32131,-0.60465,,,,,0.01947333333,-0.6126139818
115.758,0.27981,-0.61237,,,,,0.01695818182,-0.6204356636
116.258,0.23836,-0.61961,,,,,0.01444606061,-0.6277710233
116.758,0.19619,-0.62722,,,,,0.01189030303,-0.6354812563
117.258,0.15481,-0.63245,,,,,0.009382424242,-0.6407801418
117.758,0.11321,-0.63855,,,,,0.006861212121,-0.6469604863
118.258,0.07134,-0.64528,,,,,0.004323636364,-0.6537791287
118.758,0.02978,-0.64921,,,,,0.001804848485,-0.6577608916
119.114,-0.00009,-0.65022,,,,,-0.000005454545455,-0.6587841945
119.515,0.02862,-0.58775,,,,,0.001734545455,-0.595491388
120.015,0.07067,-0.5481,,,,,0.004283030303,-0.5553191489
120.515,0.11242,-0.52259,,,,,0.006813333333,-0.529473151
121.015,0.1536,-0.49931,,,,,0.009309090909,-0.5058865248
121.515,0.19584,-0.47797,,,,,0.01186909091,-0.4842654509
122.015,0.23736,-0.46295,,,,,0.01438545455,-0.469047619
122.515,0.27884,-0.44587,,,,,0.01689939394,-0.4517426545
123.015,0.32075,-0.42921,,,,,0.01943939394,-0.4348632219
123.515,0.3621,-0.41259,,,,,0.02194545455,-0.4180243161
124.015,0.4041,-0.39809,,,,,0.02449090909,-0.4033333333
124.515,0.44575,-0.38195,,,,,0.02701515152,-0.3869807497
125.015,0.48701,-0.36707,,,,,0.02951575758,-0.3719047619
125.515,0.52913,-0.35457,,,,,0.03206848485,-0.3592401216
126.015,0.57068,-0.34244,,,,,0.03458666667,-0.3469503546
126.515,0.61205,-0.32799,,,,,0.03709393939,-0.3323100304
127.015,0.65415,-0.31272,,,,,0.03964545455,-0.3168389058
127.515,0.69544,-0.30105,,,,,0.04214787879,-0.3050151976
128.015,0.73733,-0.288,,,,,0.04468666667,-0.2917933131
128.515,0.77909,-0.27516,,,,,0.04721757576,-0.2787841945
129.015,0.82037,-0.26046,,,,,0.04971939394,-0.2638905775
129.515,0.86243,-0.24898,,,,,0.05226848485,-0.2522593718
130.015,0.90409,-0.23483,,,,,0.05479333333,-0.237922999
130.515,0.94543,-0.22336,,,,,0.05729878788,-0.226301925
131.015,0.98745,-0.20979,,,,,0.05984545455,-0.2125531915
131.515,1.02896,-0.19711,,,,,0.06236121212,-0.1997061803
132.015,1.07059,-0.18646,,,,,0.06488424242,-0.1889159068
132.515,1.11239,-0.17226,,,,,0.06741757576,-0.1745288754
133.015,1.15365,-0.15975,,,,,0.06991818182,-0.1618541033
133.515,1.19584,-0.14586,,,,,0.07247515152,-0.147781155
134.015,1.23733,-0.13288,,,,,0.07498969697,-0.1346301925
134.515,1.27872,-0.12133,,,,,0.07749818182,-0.1229280648
135.015,1.3208,-0.1075,,,,,0.08004848485,-0.1089159068
135.515,1.36233,-0.09474,,,,,0.08256545455,-0.09598784195
136.015,1.40375,-0.08348,,,,,0.08507575758,-0.08457953394
136.515,1.44586,-0.06908,,,,,0.08762787879,-0.06998986829
137.015,1.48711,-0.05673,,,,,0.09012787879,-0.05747720365
137.515,1.529,-0.04559,,,,,0.09266666667,-0.04619047619
138.015,1.57078,-0.03041,,,,,0.09519878788,-0.03081053698
138.515,1.61205,-0.01898,,,,,0.0977,-0.01922998987
138.967,1.65007,-0.0072,,,,,0.1000042424,-0.007294832827
139.269,1.62979,-0.08287,,,,,0.09877515152,-0.08396149949
139.769,1.58824,-0.15469,,,,,0.0962569697,-0.1567274569
140.269,1.54672,-0.20306,,,,,0.09374060606,-0.2057345491
140.769,1.50462,-0.24457,,,,,0.09118909091,-0.2477912867
141.269,1.46325,-0.27658,,,,,0.08868181818,-0.2802228977
141.769,1.42158,-0.30629,,,,,0.08615636364,-0.3103242148
142.269,1.37967,-0.33093,,,,,0.08361636364,-0.3352887538
142.769,1.33827,-0.35188,,,,,0.08110727273,-0.356514691
143.269,1.29643,-0.37247,,,,,0.07857151515,-0.3773758865
143.769,1.25485,-0.39102,,,,,0.07605151515,-0.3961702128
144.269,1.21348,-0.40642,,,,,0.07354424242,-0.4117730496
144.769,1.17124,-0.4224,,,,,0.07098424242,-0.4279635258
145.269,1.1299,-0.43711,,,,,0.06847878788,-0.4428672746
145.769,1.08834,-0.45134,,,,,0.06596,-0.4572847011
146.269,1.04637,-0.46529,,,,,0.06341636364,-0.4714184397
146.769,1.0049,-0.4777,,,,,0.0609030303,-0.4839918946
147.269,0.9632,-0.48919,,,,,0.05837575758,-0.495633232
147.769,0.92144,-0.50076,,,,,0.05584484848,-0.5073556231
148.269,0.87994,-0.51082,,,,,0.05332969697,-0.5175481256
148.769,0.83797,-0.51955,,,,,0.05078606061,-0.5263931104
149.269,0.79661,-0.52932,,,,,0.04827939394,-0.5362917933
149.769,0.75503,-0.53712,,,,,0.04575939394,-0.5441945289
150.269,0.71285,-0.54811,,,,,0.0432030303,-0.5553292806
150.769,0.67162,-0.55542,,,,,0.04070424242,-0.5627355623
151.269,0.62989,-0.56466,,,,,0.03817515152,-0.5720972644
151.769,0.58802,-0.57407,,,,,0.03563757576,-0.5816312057
152.269,0.54661,-0.58076,,,,,0.03312787879,-0.5884093212
152.769,0.50477,-0.58881,,,,,0.03059212121,-0.5965653495
153.269,0.46313,-0.59735,,,,,0.02806848485,-0.6052178318
153.769,0.42175,-0.60224,,,,,0.02556060606,-0.6101722391
154.269,0.37963,-0.61047,,,,,0.02300787879,-0.6185106383
154.769,0.33821,-0.61705,,,,,0.02049757576,-0.625177305
155.269,0.29664,-0.62344,,,,,0.01797818182,-0.6316514691
155.769,0.25467,-0.63098,,,,,0.01543454545,-0.6392907801
156.269,0.21325,-0.6373,,,,,0.01292424242,-0.6456940223
156.769,0.17139,-0.64307,,,,,0.01038727273,-0.6515400203
157.269,0.12991,-0.64993,,,,,0.007873333333,-0.6584903749
157.769,0.08825,-0.65489,,,,,0.005348484848,-0.6635157042
158.269,0.04628,-0.66139,,,,,0.002804848485,-0.6701013171
158.769,0.00491,-0.66629,,,,,0.0002975757576,-0.6750658561
159.027,0.01222,-0.62649,,,,,0.0007406060606,-0.6347416413
159.527,0.05408,-0.57916,,,,,0.003277575758,-0.5867882472
160.027,0.09546,-0.5498,,,,,0.005785454545,-0.55704154
160.527,0.13745,-0.52741,,,,,0.00833030303,-0.5343566363
161.027,0.17891,-0.50688,,,,,0.0108430303,-0.513556231
161.527,0.22071,-0.49061,,,,,0.01337636364,-0.4970719352
162.027,0.26239,-0.47025,,,,,0.01590242424,-0.476443769
162.527,0.30369,-0.45546,,,,,0.01840545455,-0.4614589666
163.027,0.34578,-0.44031,,,,,0.02095636364,-0.4461094225
163.527,0.38728,-0.42492,,,,,0.02347151515,-0.4305167173
164.027,0.42869,-0.40927,,,,,0.02598121212,-0.4146605876
164.527,0.47085,-0.39536,,,,,0.02853636364,-0.4005673759
165.027,0.51215,-0.38331,,,,,0.03103939394,-0.3883586626
165.527,0.55391,-0.36927,,,,,0.03357030303,-0.3741337386
166.027,0.59579,-0.35638,,,,,0.03610848485,-0.3610739615
166.527,0.63703,-0.34256,,,,,0.03860787879,-0.3470719352
167.027,0.67909,-0.33217,,,,,0.0411569697,-0.3365450861
167.527,0.72078,-0.31735,,,,,0.04368363636,-0.3215298886
168.027,0.762,-0.30529,,,,,0.04618181818,-0.3093110436
168.527,0.80408,-0.29,,,,,0.04873212121,-0.2938196555
169.027,0.84566,-0.27783,,,,,0.05125212121,-0.2814893617
169.527,0.88722,-0.26619,,,,,0.05377090909,-0.2696960486
170.027,0.9291,-0.25262,,,,,0.05630909091,-0.2559473151
170.527,0.97039,-0.23901,,,,,0.05881151515,-0.2421580547
171.027,1.0124,-0.22856,,,,,0.06135757576,-0.2315704154
171.527,1.05403,-0.2142,,,,,0.06388060606,-0.2170212766
172.027,1.09529,-0.2029,,,,,0.06638121212,-0.2055724417
172.527,1.13747,-0.1912,,,,,0.06893757576,-0.1937183384
173.027,1.17899,-0.17746,,,,,0.07145393939,-0.1797973658
173.527,1.22046,-0.1655,,,,,0.07396727273,-0.1676798379
174.027,1.26244,-0.15145,,,,,0.07651151515,-0.1534447822
174.527,1.30388,-0.13965,,,,,0.0790230303,-0.1414893617
175.027,1.34568,-0.126,,,,,0.08155636364,-0.1276595745
175.527,1.38746,-0.1122,,,,,0.08408848485,-0.1136778116
176.027,1.42873,-0.09983,,,,,0.08658969697,-0.1011448835
176.527,1.47082,-0.08795,,,,,0.08914060606,-0.08910840932
177.027,1.51242,-0.0737,,,,,0.09166181818,-0.07467071935
177.527,1.55373,-0.06215,,,,,0.09416545455,-0.06296859169
178.027,1.59577,-0.04848,,,,,0.09671333333,-0.04911854103
178.527,1.63716,-0.0342,,,,,0.09922181818,-0.03465045593
178.781,1.64742,-0.05873,,,,,0.09984363636,-0.0595035461
179.281,1.60497,-0.15301,,,,,0.09727090909,-0.1550253293
179.781,1.56289,-0.20792,,,,,0.09472060606,-0.2106585613
180.281,1.52157,-0.24881,,,,,0.09221636364,-0.2520871327
180.781,1.47977,-0.28171,,,,,0.0896830303,-0.2854204661
181.281,1.43803,-0.31191,,,,,0.08715333333,-0.3160182371
181.781,1.3967,-0.33395,,,,,0.08464848485,-0.3383485309
182.281,1.35458,-0.35889,,,,,0.08209575758,-0.3636170213
182.781,1.31315,-0.37958,,,,,0.07958484848,-0.3845795339
183.281,1.2717,-0.39733,,,,,0.07707272727,-0.4025633232
183.781,1.22957,-0.41435,,,,,0.07451939394,-0.4198074975
184.281,1.1881,-0.43162,,,,,0.07200606061,-0.4373049645
184.781,1.14654,-0.4456,,,,,0.06948727273,-0.4514690983
185.281,1.10469,-0.46039,,,,,0.06695090909,-0.4664539007
185.781,1.06324,-0.47148,,,,,0.06443878788,-0.4776899696
186.281,1.02136,-0.48541,,,,,0.06190060606,-0.4918034448
186.781,0.97985,-0.49335,,,,,0.05938484848,-0.4998480243
187.281,0.93826,-0.50524,,,,,0.05686424242,-0.5118946302
187.781,0.89622,-0.51685,,,,,0.05431636364,-0.5236575481
188.281,0.85493,-0.52605,,,,,0.05181393939,-0.5329787234
188.781,0.8132,-0.53566,,,,,0.04928484848,-0.5427152989
189.281,0.77131,-0.5466,,,,,0.04674606061,-0.5537993921
189.781,0.72995,-0.55471,,,,,0.04423939394,-0.5620162107
190.281,0.68806,-0.56269,,,,,0.04170060606,-0.5701013171
190.781,0.64649,-0.57311,,,,,0.03918121212,-0.5806585613
191.281,0.60503,-0.581,,,,,0.03666848485,-0.5886524823
191.781,0.56292,-0.58732,,,,,0.03411636364,-0.5950557244
192.281,0.52152,-0.59463,,,,,0.03160727273,-0.6024620061
192.781,0.47998,-0.60222,,,,,0.02908969697,-0.6101519757
193.281,0.43792,-0.6107,,,,,0.02654060606,-0.6187436677
193.781,0.39648,-0.61753,,,,,0.02402909091,-0.6256636272
194.281,0.35478,-0.62335,,,,,0.02150181818,-0.6315602837
194.781,0.31313,-0.63085,,,,,0.01897757576,-0.6391590679
195.281,0.27161,-0.63757,,,,,0.01646121212,-0.6459675785
195.781,0.22956,-0.64379,,,,,0.01391272727,-0.6522695035
196.281,0.18822,-0.64928,,,,,0.01140727273,-0.6578318136
196.781,0.14669,-0.65472,,,,,0.00889030303,-0.663343465
197.281,0.10454,-0.66221,,,,,0.006335757576,-0.6709321175
197.781,0.06321,-0.66701,,,,,0.003830909091,-0.6757953394
198.281,0.02161,-0.6723,,,,,0.00130969697,-0.6811550152
198.539,-0.00018,-0.67574,,,,,-0.00001090909091,-0.6846403242
199.039,0.03726,-0.60647,,,,,0.002258181818,-0.6144579534
199.539,0.079,-0.5735,,,,,0.004787878788,-0.5810536981
200.039,0.12029,-0.5479,,,,,0.00729030303,-0.5551165147
200.539,0.16241,-0.52619,,,,,0.009843030303,-0.5331205674
201.039,0.20398,-0.50823,,,,,0.01236242424,-0.5149240122
201.539,0.24525,-0.49231,,,,,0.01486363636,-0.4987943262
202.039,0.28741,-0.47461,,,,,0.01741878788,-0.4808611955
202.539,0.32886,-0.45945,,,,,0.01993090909,-0.4655015198
203.039,0.37044,-0.44513,,,,,0.02245090909,-0.4509929078
203.539,0.41247,-0.43035,,,,,0.02499818182,-0.4360182371
204.039,0.45368,-0.41672,,,,,0.02749575758,-0.4222087133
204.539,0.49572,-0.40334,,,,,0.03004363636,-0.4086524823
205.039,0.53738,-0.38935,,,,,0.03256848485,-0.3944782168
205.539,0.57868,-0.37688,,,,,0.03507151515,-0.3818439716
206.039,0.62074,-0.36218,,,,,0.03762060606,-0.3669503546
206.539,0.66235,-0.35128,,,,,0.04014242424,-0.3559067882
207.039,0.70379,-0.33778,,,,,0.04265393939,-0.3422289767
207.539,0.74569,-0.32566,,,,,0.04519333333,-0.3299493414
208.039,0.78708,-0.31289,,,,,0.04770181818,-0.3170111449
208.539,0.82897,-0.30273,,,,,0.05024060606,-0.3067173252
209.039,0.87062,-0.28798,,,,,0.05276484848,-0.2917730496
209.539,0.91188,-0.27749,,,,,0.05526545455,-0.2811448835
210.039,0.95417,-0.26447,,,,,0.05782848485,-0.2679533941
210.539,0.99558,-0.25128,,,,,0.06033818182,-0.2545896657
211.039,1.03704,-0.24136,,,,,0.06285090909,-0.2445390071
211.539,1.07911,-0.22749,,,,,0.06540060606,-0.2304863222
212.039,1.1205,-0.21477,,,,,0.06790909091,-0.2175987842
212.539,1.1622,-0.20311,,,,,0.07043636364,-0.2057852077
213.039,1.20412,-0.19004,,,,,0.0729769697,-0.1925430598
213.539,1.24528,-0.17828,,,,,0.07547151515,-0.1806281662
214.039,1.28736,-0.16421,,,,,0.07802181818,-0.166372847
214.539,1.32905,-0.15135,,,,,0.08054848485,-0.153343465
215.039,1.37033,-0.13849,,,,,0.08305030303,-0.1403140831
215.539,1.41233,-0.125,,,,,0.08559575758,-0.1266464032
216.039,1.45385,-0.11243,,,,,0.08811212121,-0.1139108409
216.539,1.49553,-0.09951,,,,,0.09063818182,-0.1008206687
217.039,1.53731,-0.08711,,,,,0.09317030303,-0.08825734549
217.539,1.5787,-0.07461,,,,,0.09567878788,-0.07559270517
218.039,1.62071,-0.0614,,,,,0.09822484848,-0.06220871327
218.392,1.6501,-0.05158,,,,,0.1000060606,-0.05225937183
218.793,1.62142,-0.14287,,,,,0.09826787879,-0.144751773
219.293,1.57996,-0.20228,,,,,0.09575515152,-0.2049442756
219.793,1.53797,-0.24612,,,,,0.09321030303,-0.2493617021
220.293,1.4965,-0.28325,,,,,0.0906969697,-0.2869807497
220.793,1.45508,-0.3125,,,,,0.08818666667,-0.3166160081
221.293,1.41278,-0.33795,,,,,0.0856230303,-0.3424012158
221.793,1.37149,-0.36208,,,,,0.08312060606,-0.3668490375
222.293,1.32988,-0.38186,,,,,0.08059878788,-0.3868895643
222.793,1.28806,-0.4019,,,,,0.07806424242,-0.4071935157
223.293,1.24649,-0.41711,,,,,0.07554484848,-0.4226038501
223.793,1.2047,-0.4329,,,,,0.07301212121,-0.4386018237
224.293,1.16312,-0.4493,,,,,0.07049212121,-0.4552178318
224.793,1.1216,-0.46147,,,,,0.06797575758,-0.4675481256
225.293,1.07952,-0.47618,,,,,0.06542545455,-0.4824518744
225.793,1.03822,-0.48732,,,,,0.06292242424,-0.4937386018
226.293,0.99661,-0.49945,,,,,0.06040060606,-0.5060283688
226.793,0.95451,-0.51058,,,,,0.05784909091,-0.5173049645
227.293,0.91327,-0.52036,,,,,0.05534969697,-0.5272137791
227.793,0.87143,-0.53027,,,,,0.05281393939,-0.537254306
228.293,0.82967,-0.54209,,,,,0.0502830303,-0.5492299899
228.793,0.78825,-0.54942,,,,,0.04777272727,-0.556656535
229.293,0.74629,-0.55913,,,,,0.04522969697,-0.5664944276
229.793,0.70473,-0.56777,,,,,0.04271090909,-0.575248227
230.293,0.66332,-0.5756,,,,,0.04020121212,-0.5831813576
230.793,0.62119,-0.58489,,,,,0.03764787879,-0.5925937183
231.293,0.5798,-0.59269,,,,,0.03513939394,-0.6004964539
231.793,0.53818,-0.60042,,,,,0.0326169697,-0.6083282675
232.293,0.49636,-0.60788,,,,,0.03008242424,-0.6158865248
232.793,0.4549,-0.61538,,,,,0.02756969697,-0.623485309
233.293,0.41295,-0.62192,,,,,0.02502727273,-0.6301114488
233.793,0.37156,-0.62819,,,,,0.02251878788,-0.6364640324
234.293,0.32987,-0.63442,,,,,0.01999212121,-0.6427760892
234.793,0.28788,-0.6425,,,,,0.01744727273,-0.6509625127
235.293,0.24651,-0.64819,,,,,0.01494,-0.6567274569
235.793,0.20487,-0.65424,,,,,0.01241636364,-0.6628571429
236.293,0.16285,-0.66185,,,,,0.00986969697,-0.6705673759
236.793,0.1216,-0.66588,,,,,0.00736969697,-0.6746504559
237.293,0.07971,-0.67155,,,,,0.004830909091,-0.6803951368
237.793,0.03809,-0.67691,,,,,0.002308484848,-0.6858257345
238.248,0,-0.68109,,,,,0,-0.6900607903
238.55,0.02059,-0.63152,,,,,0.001247878788,-0.6398378926
239.05,0.06203,-0.59296,,,,,0.003759393939,-0.6007700101
239.55,0.10415,-0.56604,,,,,0.006312121212,-0.5734954407
240.05,0.14559,-0.54402,,,,,0.008823636364,-0.5511854103
240.55,0.18713,-0.52528,,,,,0.01134121212,-0.5321985816
241.05,0.22919,-0.50617,,,,,0.01389030303,-0.5128368794
241.55,0.27041,-0.49243,,,,,0.01638848485,-0.4989159068
242.05,0.31232,-0.47629,,,,,0.01892848485,-0.4825633232
242.55,0.35414,-0.46136,,,,,0.0214630303,-0.4674366768
243.05,0.39533,-0.44739,,,,,0.02395939394,-0.4532826748
243.55,0.43749,-0.43467,,,,,0.02651454545,-0.4403951368
244.05,0.47909,-0.41964,,,,,0.02903575758,-0.4251671733
244.55,0.52043,-0.40906,,,,,0.03154121212,-0.4144478217
245.05,0.56241,-0.39391,,,,,0.03408545455,-0.3990982776
245.55,0.60388,-0.38057,,,,,0.03659878788,-0.3855825735
246.05,0.64567,-0.37143,,,,,0.03913151515,-0.3763221884
246.55,0.68741,-0.35649,,,,,0.04166121212,-0.3611854103
247.05,0.72869,-0.34715,,,,,0.0441630303,-0.3517223911
247.55,0.77079,-0.3337,,,,,0.04671454545,-0.3380952381
248.05,0.8124,-0.32038,,,,,0.04923636364,-0.3245997974
248.55,0.85367,-0.30978,,,,,0.05173757576,-0.3138601824
249.05,0.89586,-0.29296,,,,,0.05429454545,-0.2968186424
249.55,0.93729,-0.28535,,,,,0.05680545455,-0.2891084093
250.05,0.97894,-0.27209,,,,,0.05932969697,-0.2756737589
250.55,1.02078,-0.25832,,,,,0.06186545455,-0.2617223911
251.05,1.06213,-0.24801,,,,,0.06437151515,-0.2512765957
251.55,1.10408,-0.2339,,,,,0.06691393939,-0.2369807497
252.05,1.14574,-0.22237,,,,,0.06943878788,-0.2252988855
252.55,1.18701,-0.21211,,,,,0.07194,-0.2149037487
253.05,1.22914,-0.19646,,,,,0.07449333333,-0.199047619
253.55,1.27068,-0.18614,,,,,0.07701090909,-0.188591692
254.05,1.31217,-0.17224,,,,,0.07952545455,-0.174508612
254.55,1.35412,-0.15883,,,,,0.08206787879,-0.1609219858
255.05,1.39542,-0.14615,,,,,0.08457090909,-0.1480749747
255.55,1.43744,-0.1335,,,,,0.08711757576,-0.1352583587
256.05,1.47905,-0.11815,,,,,0.08963939394,-0.1197061803
256.55,1.52042,-0.10649,,,,,0.09214666667,-0.1078926039
257.05,1.5625,-0.09215,,,,,0.0946969697,-0.09336372847
257.55,1.60409,-0.0794,,,,,0.09721757576,-0.08044579534
258.05,1.64536,-0.0698,,,,,0.09971878788,-0.07071935157
258.304,1.63859,-0.11833,,,,,0.09930848485,-0.1198885512
258.804,1.59619,-0.19564,,,,,0.09673878788,-0.1982168186
259.304,1.55484,-0.24276,,,,,0.09423272727,-0.2459574468
259.804,1.51332,-0.27995,,,,,0.09171636364,-0.2836372847
260.304,1.47131,-0.31457,,,,,0.08917030303,-0.3187132725
260.804,1.42982,-0.33817,,,,,0.08665575758,-0.3426241135
261.304,1.38816,-0.35955,,,,,0.08413090909,-0.3642857143
261.804,1.34648,-0.38551,,,,,0.08160484848,-0.3905876393
262.304,1.30501,-0.40587,,,,,0.07909151515,-0.4112158055
262.804,1.26298,-0.42115,,,,,0.07654424242,-0.4266970618
263.304,1.22157,-0.43601,,,,,0.07403454545,-0.4417527862
263.804,1.18001,-0.45158,,,,,0.07151575758,-0.4575278622
264.304,1.13797,-0.46797,,,,,0.06896787879,-0.4741337386
264.804,1.09658,-0.47904,,,,,0.06645939394,-0.4853495441
265.304,1.05482,-0.49278,,,,,0.06392848485,-0.4992705167
265.804,1.01309,-0.506,,,,,0.06139939394,-0.5126646403
266.304,0.97169,-0.5159,,,,,0.05889030303,-0.5226950355
266.804,0.92961,-0.52003,,,,,0.05634,-0.5268794326
267.304,0.88818,-0.53195,,,,,0.05382909091,-0.5389564336
267.804,0.84669,-0.54176,,,,,0.05131454545,-0.5488956434
268.304,0.80461,-0.55439,,,,,0.04876424242,-0.5616919959
268.804,0.7632,-0.56277,,,,,0.04625454545,-0.5701823708
269.304,0.72162,-0.5726,,,,,0.04373454545,-0.580141844
269.804,0.67971,-0.58179,,,,,0.04119454545,-0.5894528875
270.304,0.63823,-0.58791,,,,,0.03868060606,-0.5956534954
270.804,0.59639,-0.59505,,,,,0.03614484848,-0.602887538
271.304,0.5549,-0.60418,,,,,0.03363030303,-0.6121377913
271.804,0.51334,-0.61072,,,,,0.03111151515,-0.6187639311
272.304,0.47118,-0.61927,,,,,0.02855636364,-0.6274265451
272.804,0.42992,-0.62705,,,,,0.02605575758,-0.6353090172
273.304,0.38831,-0.63199,,,,,0.02353393939,-0.6403140831
273.804,0.34626,-0.63946,,,,,0.02098545455,-0.6478824721
274.304,0.30486,-0.64521,,,,,0.01847636364,-0.6537082067
274.804,0.26319,-0.65123,,,,,0.01595090909,-0.6598074975
275.304,0.22139,-0.6578,,,,,0.01341757576,-0.6664640324
275.804,0.18002,-0.66364,,,,,0.01091030303,-0.6723809524
276.304,0.13799,-0.67041,,,,,0.008363030303,-0.6792401216
276.804,0.09653,-0.67388,,,,,0.00585030303,-0.6827558257
277.304,0.05502,-0.68164,,,,,0.003334545455,-0.6906180344
277.804,0.01295,-0.68548,,,,,0.0007848484848,-0.694508612
278.062,0.00272,-0.67467,,,,,0.0001648484848,-0.683556231
278.562,0.04577,-0.61445,,,,,0.002773939394,-0.6225430598
279.062,0.08714,-0.58433,,,,,0.005281212121,-0.5920263425
279.562,0.12891,-0.5598,,,,,0.007812727273,-0.5671732523
280.062,0.17081,-0.54009,,,,,0.01035212121,-0.5472036474
280.562,0.212,-0.52191,,,,,0.01284848485,-0.5287841945
281.062,0.25411,-0.50643,,,,,0.01540060606,-0.513100304
281.562,0.2957,-0.48891,,,,,0.01792121212,-0.4953495441
282.062,0.33703,-0.47724,,,,,0.02042606061,-0.4835258359
282.562,0.37907,-0.46238,,,,,0.02297393939,-0.4684701114
283.062,0.42063,-0.44798,,,,,0.02549272727,-0.4538804458
283.562,0.46225,-0.43689,,,,,0.02801515152,-0.4426443769
284.062,0.50406,-0.42076,,,,,0.03054909091,-0.426301925
284.562,0.54538,-0.41096,,,,,0.03305333333,-0.416372847
285.062,0.58743,-0.39665,,,,,0.03560181818,-0.4018743668
285.562,0.62898,-0.3849,,,,,0.03812,-0.3899696049
286.062,0.67029,-0.37405,,,,,0.04062363636,-0.3789766971
286.562,0.71253,-0.36213,,,,,0.04318363636,-0.366899696
287.062,0.7539,-0.34736,,,,,0.04569090909,-0.351935157
287.562,0.7955,-0.33442,,,,,0.04821212121,-0.3388247214
288.062,0.83746,-0.32399,,,,,0.05075515152,-0.3282573455
288.562,0.87872,-0.31191,,,,,0.05325575758,-0.3160182371
289.062,0.92065,-0.29919,,,,,0.0557969697,-0.3031306991
289.562,0.96245,-0.28884,,,,,0.05833030303,-0.2926443769
290.062,1.00361,-0.27748,,,,,0.06082484848,-0.2811347518
290.562,1.04572,-0.26332,,,,,0.0633769697,-0.2667882472
291.062,1.08735,-0.25257,,,,,0.0659,-0.2558966565
291.562,1.12875,-0.24105,,,,,0.06840909091,-0.244224924
292.062,1.17073,-0.22513,,,,,0.07095333333,-0.2280952381
292.562,1.21216,-0.213,,,,,0.07346424242,-0.2158054711
293.062,1.25399,-0.20073,,,,,0.07599939394,-0.2033738602
293.562,1.2957,-0.18821,,,,,0.07852727273,-0.1906889564
294.062,1.33701,-0.17541,,,,,0.08103090909,-0.1777203647
294.562,1.37913,-0.16327,,,,,0.08358363636,-0.1654204661
295.062,1.42068,-0.14977,,,,,0.08610181818,-0.1517426545
295.562,1.46201,-0.13694,,,,,0.08860666667,-0.1387436677
296.062,1.50412,-0.12289,,,,,0.09115878788,-0.124508612
296.562,1.54556,-0.11033,,,,,0.09367030303,-0.1117831814
297.062,1.58719,-0.09964,,,,,0.09619333333,-0.100952381
297.562,1.6291,-0.08581,,,,,0.09873333333,-0.0869402229
297.816,1.65019,-0.07737,,,,,0.1000115152,-0.07838905775
298.316,1.61325,-0.18144,,,,,0.09777272727,-0.1838297872
298.816,1.5715,-0.23405,,,,,0.09524242424,-0.2371327254
299.316,1.52981,-0.27476,,,,,0.09271575758,-0.278378926
299.816,1.48824,-0.30669,,,,,0.09019636364,-0.3107294833
300.316,1.44636,-0.33684,,,,,0.08765818182,-0.3412765957
300.816,1.40487,-0.35975,,,,,0.08514363636,-0.3644883485
301.316,1.3633,-0.38423,,,,,0.08262424242,-0.3892907801
301.816,1.32118,-0.40538,,,,,0.08007151515,-0.4107193516
302.316,1.2799,-0.42063,,,,,0.07756969697,-0.4261702128
302.816,1.2382,-0.43805,,,,,0.07504242424,-0.4438196555
303.316,1.19626,-0.45392,,,,,0.07250060606,-0.4598986829
303.816,1.15497,-0.46616,,,,,0.06999818182,-0.4722998987
304.316,1.11298,-0.47994,,,,,0.06745333333,-0.4862613982
304.816,1.07138,-0.49407,,,,,0.06493212121,-0.5005775076
305.316,1.02998,-0.50619,,,,,0.0624230303,-0.5128571429
305.816,0.9879,-0.51676,,,,,0.05987272727,-0.5235663627
306.316,0.94643,-0.52644,,,,,0.05735939394,-0.5333738602
306.816,0.90497,-0.53652,,,,,0.05484666667,-0.5435866261
307.316,0.86297,-0.54761,,,,,0.05230121212,-0.554822695
307.816,0.82155,-0.55562,,,,,0.04979090909,-0.5629381966
308.316,0.77981,-0.56504,,,,,0.04726121212,-0.5724822695
308.816,0.73812,-0.57382,,,,,0.04473454545,-0.5813779129
309.316,0.69659,-0.58154,,,,,0.04221757576,-0.5891995947
309.816,0.65456,-0.58838,,,,,0.03967030303,-0.5961296859
310.316,0.61325,-0.5977,,,,,0.03716666667,-0.6055724417
310.816,0.57154,-0.60487,,,,,0.03463878788,-0.6128368794
311.316,0.52956,-0.61197,,,,,0.03209454545,-0.6200303951
311.816,0.4882,-0.62051,,,,,0.02958787879,-0.6286828774
312.316,0.44647,-0.62573,,,,,0.02705878788,-0.6339716312
312.816,0.4047,-0.63454,,,,,0.02452727273,-0.6428976697
313.316,0.36332,-0.63695,,,,,0.02201939394,-0.6453394124
313.816,0.32133,-0.64547,,,,,0.01947454545,-0.6539716312
314.316,0.27985,-0.65166,,,,,0.01696060606,-0.6602431611
314.816,0.2384,-0.66027,,,,,0.01444848485,-0.6689665653
315.316,0.19623,-0.6659,,,,,0.01189272727,-0.6746707194
315.816,0.15484,-0.67298,,,,,0.009384242424,-0.6818439716
316.316,0.11324,-0.67858,,,,,0.006863030303,-0.6875177305
316.816,0.07137,-0.68383,,,,,0.004325454545,-0.6928368794
317.316,0.02982,-0.68845,,,,,0.001807272727,-0.6975177305
317.673,-0.00013,-0.69255,,,,,-0.000007878787879,-0.7016717325
318.074,0.02855,-0.63515,,,,,0.00173030303,-0.6435157042
318.574,0.0706,-0.60131,,,,,0.004278787879,-0.6092299899
319.074,0.11237,-0.57698,,,,,0.00681030303,-0.5845795339
319.574,0.15356,-0.55449,,,,,0.009306666667,-0.5617933131
320.074,0.19577,-0.53626,,,,,0.01186484848,-0.5433232016
320.574,0.2373,-0.51963,,,,,0.01438181818,-0.5264741641
321.074,0.2788,-0.50411,,,,,0.0168969697,-0.5107497467
321.574,0.3207,-0.48818,,,,,0.01943636364,-0.4946099291
322.074,0.36203,-0.47628,,,,,0.02194121212,-0.4825531915
322.574,0.40404,-0.46251,,,,,0.02448727273,-0.4686018237
323.074,0.44568,-0.44829,,,,,0.02701090909,-0.4541945289
323.574,0.48696,-0.43689,,,,,0.02951272727,-0.4426443769
324.074,0.52906,-0.42316,,,,,0.03206424242,-0.428733536
324.574,0.57062,-0.41029,,,,,0.0345830303,-0.4156940223
325.074,0.61201,-0.39875,,,,,0.03709151515,-0.4040020263
325.574,0.65407,-0.38581,,,,,0.03964060606,-0.3908915907
326.074,0.69539,-0.37405,,,,,0.04214484848,-0.3789766971
326.574,0.73728,-0.36303,,,,,0.04468363636,-0.3678115502
327.074,0.77904,-0.35187,,,,,0.04721454545,-0.3565045593
327.574,0.82034,-0.33979,,,,,0.04971757576,-0.3442654509
328.074,0.8624,-0.32595,,,,,0.05226666667,-0.3302431611
328.574,0.90403,-0.31569,,,,,0.05478969697,-0.3198480243
329.074,0.94538,-0.30474,,,,,0.05729575758,-0.3087537994
329.574,0.98738,-0.29214,,,,,0.05984121212,-0.2959878419
330.074,1.02889,-0.2776,,,,,0.0623569697,-0.2812563323
330.574,1.07055,-0.26678,,,,,0.06488181818,-0.2702938197
331.074,1.11234,-0.25517,,,,,0.06741454545,-0.2585309017
331.574,1.1536,-0.24246,,,,,0.06991515152,-0.2456534954
332.074,1.1958,-0.22806,,,,,0.07247272727,-0.2310638298
332.574,1.23726,-0.21807,,,,,0.07498545455,-0.2209422492
333.074,1.27866,-0.20362,,,,,0.07749454545,-0.206301925
333.574,1.32076,-0.19126,,,,,0.08004606061,-0.1937791287
334.074,1.36224,-0.17858,,,,,0.08256,-0.1809321175
334.574,1.40371,-0.16771,,,,,0.08507333333,-0.1699189463
335.074,1.44581,-0.15411,,,,,0.08762484848,-0.1561398176
335.574,1.48703,-0.13933,,,,,0.0901230303,-0.1411651469
336.074,1.52894,-0.12667,,,,,0.0926630303,-0.1283383992
336.574,1.57073,-0.11125,,,,,0.09519575758,-0.1127152989
337.074,1.61197,-0.10073,,,,,0.09769515152,-0.1020567376
337.527,1.65008,-0.08839,,,,,0.1000048485,-0.08955420466
337.829,1.62979,-0.15767,,,,,0.09877515152,-0.1597467072
338.329,1.58822,-0.22405,,,,,0.09625575758,-0.2270010132
338.829,1.54668,-0.26875,,,,,0.09373818182,-0.272289767
339.329,1.5046,-0.30382,,,,,0.09118787879,-0.3078216819
339.829,1.46325,-0.33219,,,,,0.08868181818,-0.3365653495
340.329,1.42157,-0.35651,,,,,0.08615575758,-0.3612056738
340.829,1.37965,-0.38,,,,,0.08361515152,-0.3850050659
341.329,1.33826,-0.3999,,,,,0.08110666667,-0.4051671733
341.829,1.2964,-0.41909,,,,,0.07856969697,-0.4246099291
342.329,1.25485,-0.43695,,,,,0.07605151515,-0.4427051672
342.829,1.21347,-0.44987,,,,,0.07354363636,-0.4557953394
343.329,1.17124,-0.46492,,,,,0.07098424242,-0.4710435664
343.829,1.12989,-0.47907,,,,,0.06847818182,-0.4853799392
344.329,1.08835,-0.49225,,,,,0.06596060606,-0.498733536
344.829,1.04637,-0.50398,,,,,0.06341636364,-0.5106180344
345.329,1.00487,-0.51762,,,,,0.06090121212,-0.52443769
345.829,0.96319,-0.52747,,,,,0.05837515152,-0.5344174265
346.329,0.92144,-0.53816,,,,,0.05584484848,-0.545248227
346.829,0.87994,-0.54731,,,,,0.05332969697,-0.5545187437
347.329,0.83796,-0.55571,,,,,0.05078545455,-0.563029382
347.829,0.7966,-0.56548,,,,,0.04827878788,-0.5729280648
348.329,0.755,-0.575,,,,,0.04575757576,-0.5825734549
348.829,0.71283,-0.58408,,,,,0.04320181818,-0.5917730496
349.329,0.67161,-0.59136,,,,,0.04070363636,-0.5991489362
349.829,0.62989,-0.59904,,,,,0.03817515152,-0.6069300912
350.329,0.58801,-0.6087,,,,,0.0356369697,-0.6167173252
350.829,0.54659,-0.61273,,,,,0.03312666667,-0.6208004053
351.329,0.50476,-0.61938,,,,,0.03059151515,-0.6275379939
351.829,0.46311,-0.62708,,,,,0.02806727273,-0.6353394124
352.329,0.42174,-0.63437,,,,,0.02556,-0.6427254306
352.829,0.37962,-0.64142,,,,,0.02300727273,-0.6498682877
353.329,0.3382,-0.64799,,,,,0.0204969697,-0.6565248227
353.829,0.29662,-0.65358,,,,,0.0179769697,-0.6621884498
354.329,0.25465,-0.65964,,,,,0.01543333333,-0.6683282675
354.829,0.21324,-0.66419,,,,,0.01292363636,-0.6729381966
355.329,0.1714,-0.67237,,,,,0.01038787879,-0.6812259372
355.829,0.12989,-0.67855,,,,,0.007872121212,-0.6874873354
356.329,0.08823,-0.68341,,,,,0.005347272727,-0.6924113475
356.829,0.04626,-0.68972,,,,,0.002803636364,-0.698804458
357.329,0.00489,-0.69529,,,,,0.0002963636364,-0.7044478217
357.587,0.0122,-0.65799,,,,,0.0007393939394,-0.666656535
358.087,0.05405,-0.61578,,,,,0.003275757576,-0.6238905775
358.587,0.09544,-0.58812,,,,,0.005784242424,-0.5958662614
359.087,0.13741,-0.56574,,,,,0.008327878788,-0.5731914894
359.587,0.1789,-0.54797,,,,,0.01084242424,-0.5551874367
360.087,0.22069,-0.53136,,,,,0.01337515152,-0.5383586626
360.587,0.26238,-0.51625,,,,,0.01590181818,-0.5230496454
361.087,0.30368,-0.49972,,,,,0.01840484848,-0.506301925
361.587,0.34578,-0.48613,,,,,0.02095636364,-0.4925329281
362.087,0.38727,-0.47303,,,,,0.02347090909,-0.479260385
362.587,0.42867,-0.46204,,,,,0.02598,-0.4681256332
363.087,0.47081,-0.44814,,,,,0.02853393939,-0.4540425532
363.587,0.51215,-0.43607,,,,,0.03103939394,-0.4418135765
364.087,0.55388,-0.42276,,,,,0.03356848485,-0.4283282675
364.587,0.59577,-0.41046,,,,,0.03610727273,-0.4158662614
365.087,0.63702,-0.39835,,,,,0.03860727273,-0.4035967579
365.587,0.67908,-0.38808,,,,,0.04115636364,-0.3931914894
366.087,0.72075,-0.37482,,,,,0.04368181818,-0.3797568389
366.587,0.76197,-0.36476,,,,,0.04618,-0.3695643364
367.087,0.80407,-0.35214,,,,,0.04873151515,-0.3567781155
367.587,0.84561,-0.33939,,,,,0.05124909091,-0.3438601824
368.087,0.8872,-0.32963,,,,,0.05376969697,-0.3339716312
368.587,0.92908,-0.31567,,,,,0.05630787879,-0.3198277609
369.087,0.9704,-0.30442,,,,,0.05881212121,-0.3084295846
369.587,1.01238,-0.2917,,,,,0.06135636364,-0.2955420466
370.087,1.054,-0.27969,,,,,0.06387878788,-0.2833738602
370.587,1.09528,-0.26801,,,,,0.06638060606,-0.2715400203
371.087,1.13746,-0.25668,,,,,0.0689369697,-0.2600607903
371.587,1.17895,-0.2436,,,,,0.07145151515,-0.2468085106
372.087,1.22044,-0.23118,,,,,0.07396606061,-0.234224924
372.587,1.26241,-0.21784,,,,,0.07650969697,-0.2207092199
373.087,1.30385,-0.20451,,,,,0.07902121212,-0.2072036474
373.587,1.34565,-0.19319,,,,,0.08155454545,-0.1957345491
374.087,1.38744,-0.17999,,,,,0.08408727273,-0.182360689
374.587,1.42869,-0.16828,,,,,0.08658727273,-0.1704964539
375.087,1.47077,-0.1546,,,,,0.08913757576,-0.1566362715
375.587,1.51238,-0.14111,,,,,0.09165939394,-0.1429685917
376.087,1.55371,-0.13002,,,,,0.09416424242,-0.1317325228
376.587,1.59575,-0.11655,,,,,0.09671212121,-0.1180851064
377.087,1.63715,-0.10287,,,,,0.09922121212,-0.104224924
377.341,1.64744,-0.1227,,,,,0.09984484848,-0.1243161094
377.841,1.60497,-0.20823,,,,,0.09727090909,-0.2109726444
378.341,1.5629,-0.25893,,,,,0.09472121212,-0.2623404255
378.841,1.52157,-0.29597,,,,,0.09221636364,-0.2998682877
379.341,1.47978,-0.32716,,,,,0.08968363636,-0.3314690983
379.841,1.43804,-0.35476,,,,,0.08715393939,-0.3594326241
380.341,1.3967,-0.37662,,,,,0.08464848485,-0.3815805471
380.841,1.35459,-0.39773,,,,,0.08209636364,-0.4029685917
381.341,1.31315,-0.41649,,,,,0.07958484848,-0.4219756839
381.841,1.27172,-0.43444,,,,,0.07707393939,-0.4401621074
382.341,1.22959,-0.45147,,,,,0.07452060606,-0.4574164134
382.841,1.18811,-0.46539,,,,,0.07200666667,-0.4715197568
383.341,1.14657,-0.47909,,,,,0.06948909091,-0.4854002026
383.841,1.10469,-0.49291,,,,,0.06695090909,-0.499402229
384.341,1.06323,-0.50406,,,,,0.06443818182,-0.5106990881
384.841,1.02136,-0.51509,,,,,0.06190060606,-0.5218743668
385.341,0.97986,-0.52876,,,,,0.05938545455,-0.5357244174
385.841,0.93828,-0.53792,,,,,0.05686545455,-0.5450050659
386.341,0.89621,-0.54869,,,,,0.05431575758,-0.55591692
386.841,0.85492,-0.55814,,,,,0.05181333333,-0.565491388
387.341,0.81319,-0.56726,,,,,0.04928424242,-0.5747315096
387.841,0.77132,-0.57618,,,,,0.04674666667,-0.583768997
388.341,0.72997,-0.58304,,,,,0.04424060606,-0.5907193516
388.841,0.68808,-0.59197,,,,,0.04170181818,-0.5997669706
389.341,0.64647,-0.60069,,,,,0.03918,-0.6086018237
389.841,0.60504,-0.60782,,,,,0.03666909091,-0.6158257345
390.341,0.56294,-0.6157,,,,,0.03411757576,-0.6238095238
390.841,0.52155,-0.62191,,,,,0.03160909091,-0.6301013171
391.341,0.47995,-0.62702,,,,,0.02908787879,-0.6352786221
391.841,0.43792,-0.63465,,,,,0.02654060606,-0.6430091185
392.341,0.39649,-0.64095,,,,,0.02402969697,-0.6493920973
392.841,0.3548,-0.64807,,,,,0.0215030303,-0.6566058764
393.341,0.31311,-0.65505,,,,,0.01897636364,-0.6636778116
393.841,0.27159,-0.66218,,,,,0.01646,-0.6709017224
394.341,0.22956,-0.66671,,,,,0.01391272727,-0.675491388
394.841,0.18823,-0.67378,,,,,0.01140787879,-0.6826545086
395.341,0.1467,-0.67761,,,,,0.008890909091,-0.6865349544
395.841,0.10454,-0.68595,,,,,0.006335757576,-0.6949848024
396.341,0.06322,-0.69167,,,,,0.003831515152,-0.7007801418
396.841,0.02161,-0.6966,,,,,0.00130969697,-0.705775076
397.097,-0.00003,-0.69955,,,,,-0.000001818181818,-0.7087639311