File: mechanical/hysteresis/data/pristine_nonconductive_1.csv
Time,Extension,Load,Length,Width,Thickness,CS Area,Strain,Stress
(s),(mm),(N),(mm),(mm),(mm),(mm^2),(mm/mm),(MPa)
0,0,-0.00526,16.5,2.82,0.3,0.846,0,-0.00621749409
0.5,0.0389,0.01097,,,,,0.002357575758,0.01296690307
1,0.08024,0.01898,,,,,0.004863030303,0.02243498818
1.5,0.12195,0.02473,,,,,0.007390909091,0.02923167849
2,0.16392,0.03063,,,,,0.009934545455,0.03620567376
2.5,0.20513,0.03623,,,,,0.01243212121,0.0428250591
3,0.24715,0.04243,,,,,0.01497878788,0.0501536643
3.5,0.28889,0.04727,,,,,0.01750848485,0.05587470449
4,0.33006,0.05241,,,,,0.02000363636,0.06195035461
4.5,0.37227,0.05723,,,,,0.02256181818,0.06764775414
5,0.41386,0.06207,,,,,0.02508242424,0.07336879433
5.5,0.45523,0.06661,,,,,0.02758969697,0.07873522459
6,0.49719,0.07133,,,,,0.03013272727,0.0843144208
6.5,0.53867,0.0747,,,,,0.03264666667,0.08829787234
7,0.58049,0.07798,,,,,0.03518121212,0.0921749409
7.5,0.62219,0.08367,,,,,0.03770848485,0.09890070922
8,0.66345,0.08636,,,,,0.04020909091,0.1020803783
8.5,0.70556,0.0879,,,,,0.04276121212,0.1039007092
9,0.74715,0.09126,,,,,0.04528181818,0.1078723404
9.5,0.7884,0.09691,,,,,0.04778181818,0.1145508274
10,0.83063,0.1009,,,,,0.05034121212,0.1192671395
10.5,0.87203,0.10445,,,,,0.05285030303,0.123463357
11,0.9137,0.10624,,,,,0.05537575758,0.1255791962
11.5,0.95553,0.10991,,,,,0.05791090909,0.1299172577
12,0.99685,0.11331,,,,,0.06041515152,0.1339361702
12.5,1.0389,0.11601,,,,,0.06296363636,0.1371276596
13,1.08058,0.12004,,,,,0.06548969697,0.141891253
13.5,1.12186,0.1231,,,,,0.06799151515,0.1455082742
14,1.16392,0.1247,,,,,0.07054060606,0.1473995272
14.5,1.20548,0.12811,,,,,0.07305939394,0.15143026
15,1.24698,0.13103,,,,,0.07557454545,0.1548817967
15.5,1.28883,0.13581,,,,,0.07811090909,0.1605319149
16,1.3301,0.13864,,,,,0.08061212121,0.1638770686
16.5,1.37223,0.14021,,,,,0.08316545455,0.1657328605
17,1.41377,0.14203,,,,,0.0856830303,0.1678841608
17.5,1.45514,0.14499,,,,,0.08819030303,0.1713829787
18,1.49728,0.14802,,,,,0.09074424242,0.174964539
18.5,1.53884,0.15111,,,,,0.0932630303,0.1786170213
19,1.58017,0.15368,,,,,0.09576787879,0.1816548463
19.5,1.62236,0.15699,,,,,0.09832484848,0.1855673759
19.84,1.6501,0.15646,,,,,0.1000060606,0.1849408983
20.241,1.62178,0.12949,,,,,0.09828969697,0.1530614657
20.741,1.58014,0.11117,,,,,0.09576606061,0.1314066194
21.241,1.53862,0.09602,,,,,0.09324969697,0.113498818
21.741,1.49655,0.08279,,,,,0.0907,0.09786052009
22.241,1.45523,0.07169,,,,,0.08819575758,0.08473995272
22.741,1.41365,0.06228,,,,,0.08567575758,0.07361702128
23.241,1.37147,0.0546,,,,,0.08311939394,0.06453900709
23.741,1.33025,0.0458,,,,,0.08062121212,0.05413711584
24.241,1.28842,0.03839,,,,,0.07808606061,0.04537825059
24.741,1.24668,0.02937,,,,,0.07555636364,0.03471631206
25.241,1.20524,0.0228,,,,,0.07304484848,0.02695035461
25.741,1.16333,0.0192,,,,,0.07050484848,0.02269503546
26.241,1.12172,0.01094,,,,,0.0679830303,0.01293144208
26.741,1.08035,0.00441,,,,,0.06547575758,0.005212765957
27.241,1.03821,-0.00202,,,,,0.06292181818,-0.002387706856
27.741,0.99679,-0.00844,,,,,0.06041151515,-0.009976359338
28.241,0.95519,-0.01365,,,,,0.05789030303,-0.01613475177
28.741,0.91334,-0.01928,,,,,0.05535393939,-0.02278959811
29.241,0.87188,-0.02294,,,,,0.05284121212,-0.02711583924
29.741,0.82998,-0.02728,,,,,0.05030181818,-0.03224586288
30.241,0.78855,-0.03308,,,,,0.04779090909,-0.03910165485
30.741,0.74686,-0.03795,,,,,0.04526424242,-0.04485815603
31.241,0.70485,-0.04184,,,,,0.04271818182,-0.04945626478
31.741,0.6635,-0.04643,,,,,0.04021212121,-0.05488179669
32.241,0.62189,-0.05061,,,,,0.03769030303,-0.05982269504
32.741,0.57987,-0.05522,,,,,0.03514363636,-0.06527186761
33.241,0.53857,-0.05987,,,,,0.03264060606,-0.07076832151
33.741,0.49672,-0.06434,,,,,0.03010424242,-0.07605200946
34.241,0.45506,-0.06835,,,,,0.02757939394,-0.08079196217
34.741,0.41368,-0.0709,,,,,0.02507151515,-0.08380614657
35.241,0.37157,-0.07606,,,,,0.02251939394,-0.08990543735
35.741,0.33013,-0.08011,,,,,0.02000787879,-0.09469267139
36.241,0.2886,-0.08381,,,,,0.01749090909,-0.09906619385
36.741,0.24661,-0.08576,,,,,0.01494606061,-0.1013711584
37.241,0.20514,-0.09028,,,,,0.01243272727,-0.106713948
37.741,0.16348,-0.09223,,,,,0.009907878788,-0.1090189125
38.241,0.12172,-0.09509,,,,,0.007376969697,-0.1123995272
38.741,0.08029,-0.10117,,,,,0.004866060606,-0.1195862884
39.241,0.03819,-0.10059,,,,,0.002314545455,-0.1189007092
39.704,-0.00003,-0.10395,,,,,-0.000001818181818,-0.1228723404
40.006,0.0197,-0.09102,,,,,0.001193939394,-0.1075886525
40.506,0.06201,-0.07962,,,,,0.003758181818,-0.09411347518
41.006,0.10357,-0.06658,,,,,0.006276969697,-0.07869976359
41.506,0.14499,-0.05702,,,,,0.008787272727,-0.06739952719
42.006,0.18697,-0.04687,,,,,0.01133151515,-0.05540189125
42.506,0.22838,-0.04039,,,,,0.01384121212,-0.04774231678
43.006,0.27019,-0.0314,,,,,0.01637515152,-0.03711583924
43.506,0.31195,-0.02422,,,,,0.01890606061,-0.02862884161
44.006,0.35326,-0.01814,,,,,0.02140969697,-0.02144208038
44.506,0.39537,-0.01152,,,,,0.02396181818,-0.01361702128
45.006,0.43683,-0.00462,,,,,0.02647454545,-0.005460992908
45.506,0.47834,0.00095,,,,,0.02899030303,0.001122931442
46.006,0.52034,0.00891,,,,,0.03153575758,0.01053191489
46.506,0.56161,0.01379,,,,,0.0340369697,0.01630023641
47.006,0.60354,0.01927,,,,,0.03657818182,0.02277777778
47.506,0.64531,0.02441,,,,,0.03910969697,0.0288534279
48.006,0.68647,0.03185,,,,,0.04160424242,0.03764775414
48.506,0.72858,0.03648,,,,,0.04415636364,0.04312056738
49.006,0.77031,0.04141,,,,,0.04668545455,0.04894799054
49.506,0.81151,0.04599,,,,,0.04918242424,0.05436170213
50.006,0.85372,0.0494,,,,,0.05174060606,0.05839243499
50.506,0.89513,0.0567,,,,,0.05425030303,0.0670212766
51.006,0.93679,0.0605,,,,,0.05677515152,0.07151300236
51.506,0.97861,0.06726,,,,,0.05930969697,0.0795035461
52.006,1.01997,0.07119,,,,,0.06181636364,0.08414893617
52.506,1.06199,0.07427,,,,,0.0643630303,0.08778959811
53.006,1.10359,0.07868,,,,,0.06688424242,0.09300236407
53.506,1.14486,0.08465,,,,,0.06938545455,0.1000591017
54.006,1.18704,0.08896,,,,,0.07194181818,0.1051536643
54.506,1.22854,0.09231,,,,,0.0744569697,0.1091134752
55.006,1.26997,0.09641,,,,,0.07696787879,0.1139598109
55.506,1.31207,0.10134,,,,,0.07951939394,0.119787234
56.006,1.35331,0.10417,,,,,0.08201878788,0.1231323877
56.506,1.39526,0.10887,,,,,0.08456121212,0.1286879433
57.006,1.43696,0.11312,,,,,0.08708848485,0.1337115839
57.506,1.47827,0.1166,,,,,0.08959212121,0.1378250591
58.006,1.52035,0.11957,,,,,0.09214242424,0.1413356974
58.506,1.56196,0.12485,,,,,0.09466424242,0.1475768322
59.006,1.60333,0.12781,,,,,0.09717151515,0.1510756501
59.506,1.64532,0.13276,,,,,0.09971636364,0.1569267139
59.77,1.63884,0.1175,,,,,0.09932363636,0.1388888889
60.27,1.59697,0.09254,,,,,0.09678606061,0.1093853428
60.77,1.5549,0.0783,,,,,0.09423636364,0.09255319149
61.27,1.51356,0.0653,,,,,0.09173090909,0.07718676123
61.77,1.47181,0.05697,,,,,0.08920060606,0.06734042553
62.27,1.43004,0.04562,,,,,0.08666909091,0.05392434988
62.77,1.38863,0.03934,,,,,0.08415939394,0.04650118203
63.27,1.34662,0.02921,,,,,0.08161333333,0.03452718676
63.77,1.30515,0.02094,,,,,0.0791,0.02475177305
64.27,1.26369,0.0139,,,,,0.07658727273,0.01643026005
64.77,1.22158,0.00802,,,,,0.07403515152,0.009479905437
65.27,1.18018,0.00066,,,,,0.07152606061,0.000780141844
65.77,1.13865,-0.00515,,,,,0.06900909091,-0.006087470449
66.27,1.09667,-0.01287,,,,,0.06646484848,-0.01521276596
66.77,1.05521,-0.01732,,,,,0.06395212121,-0.02047281324
67.27,1.01338,-0.02239,,,,,0.0614169697,-0.02646572104
67.77,0.97186,-0.02876,,,,,0.05890060606,-0.03399527187
68.27,0.93031,-0.03295,,,,,0.05638242424,-0.03894799054
68.77,0.88818,-0.04049,,,,,0.05382909091,-0.04786052009
69.27,0.84692,-0.04407,,,,,0.05132848485,-0.05209219858
69.77,0.80529,-0.04949,,,,,0.04880545455,-0.05849881797
70.27,0.76321,-0.05352,,,,,0.04625515152,-0.06326241135
70.77,0.72186,-0.05736,,,,,0.04374909091,-0.06780141844
71.27,0.68022,-0.06396,,,,,0.04122545455,-0.07560283688
71.77,0.63835,-0.06858,,,,,0.03868787879,-0.08106382979
72.27,0.597,-0.07206,,,,,0.03618181818,-0.08517730496
72.77,0.55498,-0.075,,,,,0.03363515152,-0.08865248227
73.27,0.51346,-0.07933,,,,,0.03111878788,-0.09377068558
73.77,0.47198,-0.08249,,,,,0.02860484848,-0.09750591017
74.27,0.42992,-0.08633,,,,,0.02605575758,-0.1020449173
74.77,0.3885,-0.09157,,,,,0.02354545455,-0.1082387707
75.27,0.34677,-0.09277,,,,,0.02101636364,-0.1096572104
75.77,0.30513,-0.09634,,,,,0.01849272727,-0.1138770686
76.27,0.26349,-0.09808,,,,,0.01596909091,-0.1159338061
76.77,0.22166,-0.10318,,,,,0.01343393939,-0.1219621749
77.27,0.18015,-0.10454,,,,,0.01091818182,-0.12356974
77.77,0.13868,-0.10787,,,,,0.008404848485,-0.1275059102
78.27,0.09648,-0.10899,,,,,0.005847272727,-0.1288297872
78.77,0.05526,-0.11061,,,,,0.003349090909,-0.1307446809
79.27,0.01358,-0.11288,,,,,0.000823030303,-0.133427896
79.536,0.00247,-0.10972,,,,,0.0001496969697,-0.1296926714
80.036,0.04497,-0.09662,,,,,0.002725454545,-0.1142080378
80.536,0.08672,-0.08742,,,,,0.005255757576,-0.1033333333
81.036,0.12858,-0.07611,,,,,0.007792727273,-0.08996453901
81.536,0.16979,-0.06758,,,,,0.01029030303,-0.07988179669
82.036,0.21193,-0.05831,,,,,0.01284424242,-0.06892434988
82.536,0.2535,-0.04947,,,,,0.01536363636,-0.0584751773
83.036,0.29488,-0.04181,,,,,0.01787151515,-0.04942080378
83.536,0.33695,-0.036,,,,,0.02042121212,-0.04255319149
84.036,0.37834,-0.028,,,,,0.02292969697,-0.03309692671
84.536,0.42008,-0.02092,,,,,0.02545939394,-0.02472813239
85.036,0.46197,-0.01288,,,,,0.02799818182,-0.01522458629
85.536,0.50314,-0.00867,,,,,0.03049333333,-0.01024822695
86.036,0.54518,-0.00361,,,,,0.03304121212,-0.00426713948
86.536,0.5869,0.00498,,,,,0.03556969697,0.005886524823
87.036,0.62812,0.00788,,,,,0.03806787879,0.009314420804
87.536,0.67026,0.01626,,,,,0.04062181818,0.01921985816
88.036,0.71182,0.02383,,,,,0.04314060606,0.0281678487
88.536,0.75331,0.02595,,,,,0.04565515152,0.03067375887
89.036,0.79523,0.03157,,,,,0.04819575758,0.03731678487
89.536,0.8366,0.03473,,,,,0.0507030303,0.04105200946
90.036,0.87853,0.04087,,,,,0.05324424242,0.04830969267
90.536,0.92014,0.04758,,,,,0.05576606061,0.05624113475
91.036,0.96152,0.05201,,,,,0.05827393939,0.06147754137
91.536,1.00362,0.05656,,,,,0.06082545455,0.06685579196
92.036,1.04505,0.05954,,,,,0.06333636364,0.07037825059
92.536,1.08655,0.06651,,,,,0.06585151515,0.07861702128
93.036,1.12865,0.0723,,,,,0.0684030303,0.08546099291
93.536,1.16989,0.07788,,,,,0.07090242424,0.09205673759
94.036,1.21178,0.07904,,,,,0.07344121212,0.09342789598
94.536,1.25358,0.08511,,,,,0.07597454545,0.1006028369
95.036,1.29474,0.08882,,,,,0.07846909091,0.1049881797
95.536,1.33693,0.09427,,,,,0.08102606061,0.11143026
96.036,1.37855,0.09939,,,,,0.08354848485,0.1174822695
96.536,1.41983,0.10374,,,,,0.08605030303,0.1226241135
97.036,1.46184,0.1074,,,,,0.08859636364,0.1269503546
97.536,1.50334,0.10932,,,,,0.09111151515,0.1292198582
98.036,1.54507,0.11374,,,,,0.09364060606,0.1344444444
98.536,1.58687,0.12189,,,,,0.09617393939,0.1440780142
99.036,1.62815,0.12316,,,,,0.09867575758,0.1455791962
99.301,1.65019,0.12302,,,,,0.1000115152,0.1454137116
99.801,1.61326,0.08973,,,,,0.09777333333,0.1060638298
100.301,1.57198,0.07344,,,,,0.09527151515,0.08680851064
100.801,1.53,0.06118,,,,,0.09272727273,0.07231678487
101.301,1.48844,0.05041,,,,,0.09020848485,0.05958628842
101.801,1.44702,0.0395,,,,,0.08769818182,0.04669030733
102.301,1.40494,0.03222,,,,,0.08514787879,0.03808510638
102.801,1.36346,0.02181,,,,,0.08263393939,0.02578014184
103.301,1.32203,0.01392,,,,,0.0801230303,0.01645390071
103.801,1.27995,0.00665,,,,,0.07757272727,0.007860520095
104.301,1.23851,0.00193,,,,,0.07506121212,0.002281323877
104.801,1.19679,-0.00528,,,,,0.07253272727,-0.006241134752
105.301,1.15506,-0.01277,,,,,0.07000363636,-0.01509456265
105.801,1.11358,-0.01889,,,,,0.06748969697,-0.0223286052
106.301,1.07158,-0.02464,,,,,0.06494424242,-0.02912529551
106.801,1.03024,-0.02993,,,,,0.06243878788,-0.03537825059
107.301,0.98858,-0.0347,,,,,0.05991393939,-0.04101654846
107.801,0.94655,-0.03965,,,,,0.05736666667,-0.04686761229
108.301,0.90526,-0.04635,,,,,0.05486424242,-0.05478723404
108.801,0.8635,-0.0482,,,,,0.05233333333,-0.05697399527
109.301,0.82164,-0.05453,,,,,0.04979636364,-0.06445626478
109.801,0.78032,-0.06023,,,,,0.04729212121,-0.07119385343
110.301,0.73836,-0.0648,,,,,0.04474909091,-0.07659574468
110.801,0.69684,-0.07042,,,,,0.04223272727,-0.08323877069
111.301,0.65539,-0.07277,,,,,0.03972060606,-0.08601654846
111.801,0.61323,-0.077,,,,,0.03716545455,-0.09101654846
112.301,0.57182,-0.08041,,,,,0.03465575758,-0.09504728132
112.801,0.53026,-0.08556,,,,,0.0321369697,-0.1011347518
113.301,0.48836,-0.09007,,,,,0.02959757576,-0.106465721
113.801,0.44684,-0.09288,,,,,0.02708121212,-0.109787234
114.301,0.40504,-0.09463,,,,,0.02454787879,-0.111855792
114.801,0.36352,-0.09879,,,,,0.02203151515,-0.1167730496
115.301,0.32204,-0.10222,,,,,0.01951757576,-0.1208274232
115.801,0.27986,-0.10469,,,,,0.01696121212,-0.1237470449
116.301,0.23856,-0.10747,,,,,0.01445818182,-0.1270330969
116.801,0.19707,-0.11073,,,,,0.01194363636,-0.1308865248
117.301,0.15487,-0.11101,,,,,0.009386060606,-0.1312174941
117.801,0.11356,-0.11311,,,,,0.006882424242,-0.1336997636
118.301,0.07185,-0.11517,,,,,0.004354545455,-0.1361347518
118.801,0.03005,-0.11706,,,,,0.001821212121,-0.1383687943
119.166,-0.00016,-0.11783,,,,,-0.000009696969697,-0.1392789598
119.567,0.02848,-0.10951,,,,,0.001726060606,-0.1294444444
120.067,0.07019,-0.09671,,,,,0.004253939394,-0.1143144208
120.567,0.11148,-0.08975,,,,,0.006756363636,-0.1060874704
121.067,0.1536,-0.08024,,,,,0.009309090909,-0.0948463357
121.567,0.19502,-0.07283,,,,,0.01181939394,-0.08608747045
122.067,0.23671,-0.06353,,,,,0.01434606061,-0.07509456265
122.567,0.27856,-0.05608,,,,,0.01688242424,-0.06628841608
123.067,0.31976,-0.04797,,,,,0.01937939394,-0.05670212766
123.567,0.36188,-0.04142,,,,,0.02193212121,-0.04895981087
124.067,0.40355,-0.03528,,,,,0.02445757576,-0.04170212766
124.567,0.4447,-0.02904,,,,,0.02695151515,-0.03432624113
125.067,0.48682,-0.02022,,,,,0.02950424242,-0.02390070922
125.567,0.52852,-0.01332,,,,,0.03203151515,-0.01574468085
126.067,0.56984,-0.00712,,,,,0.03453575758,-0.00841607565
126.567,0.6119,-0.00165,,,,,0.03708484848,-0.00195035461
127.067,0.65323,0.00416,,,,,0.03958969697,0.004917257683
127.567,0.69514,0.00792,,,,,0.04212969697,0.009361702128
128.067,0.73682,0.01502,,,,,0.04465575758,0.01775413712
128.567,0.77813,0.02083,,,,,0.04715939394,0.02462174941
129.067,0.82031,0.02439,,,,,0.04971575758,0.02882978723
129.567,0.86183,0.03068,,,,,0.05223212121,0.03626477541
130.067,0.90315,0.03714,,,,,0.05473636364,0.04390070922
130.567,0.94527,0.04207,,,,,0.05728909091,0.04972813239
131.067,0.9867,0.04643,,,,,0.0598,0.05488179669
131.567,1.02832,0.05173,,,,,0.06232242424,0.0611465721
132.067,1.07029,0.05518,,,,,0.06486606061,0.06522458629
132.567,1.11147,0.06151,,,,,0.06736181818,0.07270685579
133.067,1.15354,0.06616,,,,,0.06991151515,0.07820330969
133.567,1.19518,0.07064,,,,,0.07243515152,0.08349881797
134.067,1.23648,0.07368,,,,,0.07493818182,0.08709219858
134.567,1.27857,0.08089,,,,,0.07748909091,0.09561465721
135.067,1.32015,0.08396,,,,,0.08000909091,0.09924349882
135.567,1.36167,0.08685,,,,,0.08252545455,0.1026595745
136.067,1.4035,0.0931,,,,,0.08506060606,0.1100472813
136.567,1.44489,0.0979,,,,,0.08756909091,0.1157210402
137.067,1.48688,0.10093,,,,,0.09011393939,0.1193026005
137.567,1.52845,0.10684,,,,,0.09263333333,0.1262884161
138.067,1.56973,0.11017,,,,,0.09513515152,0.1302245863
138.567,1.61199,0.11243,,,,,0.09769636364,0.1328959811
139.03,1.65002,0.11716,,,,,0.1000012121,0.1384869976
139.332,1.63063,0.0951,,,,,0.09882606061,0.1124113475
139.832,1.5883,0.07633,,,,,0.09626060606,0.09022458629
140.332,1.54696,0.06024,,,,,0.09375515152,0.07120567376
140.832,1.5054,0.05034,,,,,0.09123636364,0.0595035461
141.332,1.46336,0.03998,,,,,0.08868848485,0.04725768322
141.832,1.4219,0.03027,,,,,0.08617575758,0.03578014184
142.332,1.38027,0.02052,,,,,0.08365272727,0.02425531915
142.832,1.33849,0.01236,,,,,0.08112060606,0.01460992908
143.332,1.29699,0.00432,,,,,0.07860545455,0.005106382979
143.832,1.25505,-0.00106,,,,,0.07606363636,-0.001252955083
144.332,1.21362,-0.01005,,,,,0.07355272727,-0.01187943262
144.832,1.17209,-0.01239,,,,,0.07103575758,-0.01464539007
145.332,1.12989,-0.02086,,,,,0.06847818182,-0.0246572104
145.832,1.08868,-0.02684,,,,,0.06598060606,-0.03172576832
146.332,1.04694,-0.03168,,,,,0.06345090909,-0.03744680851
146.832,1.00506,-0.03953,,,,,0.06091272727,-0.04672576832
147.332,0.96365,-0.04423,,,,,0.0584030303,-0.05228132388
147.832,0.92183,-0.04813,,,,,0.05586848485,-0.05689125296
148.332,0.88013,-0.05446,,,,,0.05334121212,-0.06437352246
148.832,0.83877,-0.05966,,,,,0.05083454545,-0.07052009456
149.332,0.79666,-0.06474,,,,,0.04828242424,-0.0765248227
149.832,0.7552,-0.06695,,,,,0.04576969697,-0.07913711584
150.332,0.71367,-0.07168,,,,,0.04325272727,-0.08472813239
150.832,0.67171,-0.07558,,,,,0.04070969697,-0.08933806147
151.332,0.63026,-0.08065,,,,,0.03819757576,-0.09533096927
151.832,0.58845,-0.08572,,,,,0.03566363636,-0.1013238771
152.332,0.54694,-0.0894,,,,,0.03314787879,-0.1056737589
152.832,0.50529,-0.0928,,,,,0.03062363636,-0.1096926714
153.332,0.46333,-0.0948,,,,,0.02808060606,-0.1120567376
153.832,0.42193,-0.09936,,,,,0.02557151515,-0.1174468085
154.332,0.38042,-0.10327,,,,,0.02305575758,-0.1220685579
154.832,0.33828,-0.10506,,,,,0.02050181818,-0.1241843972
155.332,0.297,-0.10691,,,,,0.018,-0.1263711584
155.832,0.25524,-0.10945,,,,,0.01546909091,-0.1293735225
156.332,0.21342,-0.11234,,,,,0.01293454545,-0.1327895981
156.832,0.17209,-0.11406,,,,,0.01042969697,-0.134822695
157.332,0.13007,-0.11559,,,,,0.007883030303,-0.1366312057
157.832,0.08853,-0.11699,,,,,0.005365454545,-0.138286052
158.332,0.0471,-0.1179,,,,,0.002854545455,-0.1393617021
158.832,0.00504,-0.11858,,,,,0.0003054545455,-0.1401654846
159.099,0.01133,-0.11437,,,,,0.0006866666667,-0.1351891253
159.599,0.05328,-0.1063,,,,,0.003229090909,-0.1256501182
160.099,0.09525,-0.09719,,,,,0.005772727273,-0.1148817967
160.599,0.13653,-0.08947,,,,,0.008274545455,-0.1057565012
161.099,0.17851,-0.0797,,,,,0.01081878788,-0.09420803783
161.599,0.22028,-0.0713,,,,,0.01335030303,-0.08427895981
162.099,0.26141,-0.06306,,,,,0.0158430303,-0.07453900709
162.599,0.30353,-0.05639,,,,,0.01839575758,-0.06665484634
163.099,0.34513,-0.05043,,,,,0.0209169697,-0.05960992908
163.599,0.38648,-0.04288,,,,,0.0234230303,-0.0506855792
164.099,0.42856,-0.03334,,,,,0.02597333333,-0.03940898345
164.599,0.47004,-0.02843,,,,,0.02848727273,-0.03360520095
165.099,0.5117,-0.0236,,,,,0.03101212121,-0.02789598109
165.599,0.55356,-0.01634,,,,,0.03354909091,-0.0193144208
166.099,0.5949,-0.00943,,,,,0.03605454545,-0.0111465721
166.599,0.63695,-0.00606,,,,,0.0386030303,-0.007163120567
167.099,0.67846,0.00028,,,,,0.04111878788,0.0003309692671
167.599,0.71986,0.00739,,,,,0.04362787879,0.008735224586
168.099,0.76194,0.01297,,,,,0.04617818182,0.01533096927
168.599,0.8033,0.0167,,,,,0.04868484848,0.01973995272
169.099,0.84501,0.02395,,,,,0.05121272727,0.02830969267
169.599,0.88692,0.02895,,,,,0.05375272727,0.03421985816
170.099,0.92809,0.03362,,,,,0.05624787879,0.03973995272
170.599,0.97008,0.0377,,,,,0.05879272727,0.04456264775
171.099,1.01189,0.04303,,,,,0.06132666667,0.05086288416
171.599,1.05306,0.04725,,,,,0.06382181818,0.05585106383
172.099,1.09529,0.05284,,,,,0.06638121212,0.06245862884
172.599,1.13682,0.0588,,,,,0.06889818182,0.0695035461
173.099,1.17826,0.06219,,,,,0.07140969697,0.0735106383
173.599,1.22015,0.06614,,,,,0.07394848485,0.07817966903
174.099,1.26157,0.07036,,,,,0.07645878788,0.0831678487
174.599,1.30352,0.07337,,,,,0.07900121212,0.08672576832
175.099,1.34518,0.0793,,,,,0.08152606061,0.09373522459
175.599,1.38644,0.08443,,,,,0.08402666667,0.09979905437
176.099,1.42861,0.08869,,,,,0.08658242424,0.1048345154
176.599,1.47017,0.09308,,,,,0.08910121212,0.1100236407
177.099,1.51144,0.09807,,,,,0.09160242424,0.1159219858
177.599,1.55361,0.10168,,,,,0.09415818182,0.1201891253
178.099,1.59494,0.10647,,,,,0.0966630303,0.1258510638
178.599,1.63675,0.10982,,,,,0.0991969697,0.1298108747
178.864,1.64746,0.10425,,,,,0.09984606061,0.1232269504
179.364,1.60523,0.07735,,,,,0.09728666667,0.09143026005
179.864,1.56366,0.06216,,,,,0.09476727273,0.0734751773
180.364,1.52177,0.04976,,,,,0.09222848485,0.0588179669
180.864,1.48029,0.03878,,,,,0.08971454545,0.0458392435
181.364,1.43846,0.02791,,,,,0.08717939394,0.03299054374
181.864,1.39692,0.01951,,,,,0.08466181818,0.02306146572
182.364,1.3554,0.01232,,,,,0.08214545455,0.01456264775
182.864,1.31333,0.00446,,,,,0.07959575758,0.005271867612
183.364,1.27202,-0.0027,,,,,0.07709212121,-0.003191489362
183.864,1.2303,-0.01009,,,,,0.07456363636,-0.01192671395
184.364,1.1884,-0.01728,,,,,0.07202424242,-0.02042553191
184.864,1.14702,-0.02177,,,,,0.06951636364,-0.02573286052
185.364,1.10513,-0.02817,,,,,0.06697757576,-0.03329787234
185.864,1.06347,-0.03425,,,,,0.06445272727,-0.04048463357
186.364,1.02209,-0.04104,,,,,0.06194484848,-0.0485106383
186.864,0.98004,-0.04573,,,,,0.05939636364,-0.05405437352
187.364,0.9386,-0.05043,,,,,0.05688484848,-0.05960992908
187.864,0.89711,-0.05535,,,,,0.05437030303,-0.06542553191
188.364,0.85499,-0.05956,,,,,0.05181757576,-0.07040189125
188.864,0.81357,-0.06251,,,,,0.04930727273,-0.07388888889
189.364,0.77192,-0.07015,,,,,0.0467830303,-0.08291962175
189.864,0.73024,-0.07516,,,,,0.0442569697,-0.08884160757
190.364,0.68869,-0.07971,,,,,0.04173878788,-0.09421985816
190.864,0.64668,-0.08168,,,,,0.03919272727,-0.09654846336
191.364,0.60533,-0.08716,,,,,0.03668666667,-0.1030260047
191.864,0.56377,-0.09181,,,,,0.03416787879,-0.1085224586
192.364,0.52156,-0.09292,,,,,0.03160969697,-0.1098345154
192.864,0.48027,-0.09833,,,,,0.02910727273,-0.1162293144
193.364,0.43869,-0.10082,,,,,0.02658727273,-0.1191725768
193.864,0.39672,-0.10296,,,,,0.02404363636,-0.1217021277
194.364,0.35534,-0.10576,,,,,0.02153575758,-0.1250118203
194.864,0.31348,-0.10921,,,,,0.01899878788,-0.1290898345
195.364,0.27185,-0.11079,,,,,0.01647575758,-0.1309574468
195.864,0.23043,-0.11322,,,,,0.01396545455,-0.1338297872
196.364,0.18835,-0.11288,,,,,0.01141515152,-0.133427896
196.864,0.14693,-0.1168,,,,,0.008904848485,-0.1380614657
197.364,0.1053,-0.11747,,,,,0.006381818182,-0.1388534279
197.864,0.06347,-0.1203,,,,,0.003846666667,-0.1421985816
198.364,0.02189,-0.12269,,,,,0.001326666667,-0.1450236407
198.631,-0.00024,-0.12023,,,,,-0.00001454545455,-0.1421158392
199.131,0.03687,-0.11153,,,,,0.002234545455,-0.1318321513
199.631,0.07803,-0.10698,,,,,0.004729090909,-0.1264539007
200.131,0.12025,-0.09725,,,,,0.007287878788,-0.1149527187
200.631,0.16185,-0.08866,,,,,0.009809090909,-0.1047990544
201.131,0.20313,-0.0798,,,,,0.01231090909,-0.09432624113
201.631,0.24515,-0.07305,,,,,0.01485757576,-0.08634751773
202.131,0.28678,-0.06301,,,,,0.01738060606,-0.07447990544
202.631,0.32831,-0.05615,,,,,0.01989757576,-0.06637115839
203.131,0.37029,-0.04964,,,,,0.02244181818,-0.05867612293
203.631,0.4115,-0.04262,,,,,0.02493939394,-0.05037825059
204.131,0.4536,-0.03825,,,,,0.02749090909,-0.04521276596
204.631,0.49518,-0.03136,,,,,0.03001090909,-0.03706855792
205.131,0.53651,-0.02432,,,,,0.03251575758,-0.02874704492
205.631,0.57862,-0.018,,,,,0.03506787879,-0.02127659574
206.131,0.62012,-0.01233,,,,,0.0375830303,-0.01457446809
206.631,0.66162,-0.00637,,,,,0.04009818182,-0.007529550827
207.131,0.70361,-0.00076,,,,,0.0426430303,-0.0008983451537
207.631,0.74486,0.00458,,,,,0.0451430303,0.005413711584
208.131,0.78673,0.01,,,,,0.04768060606,0.01182033097
208.631,0.8286,0.01623,,,,,0.05021818182,0.01918439716
209.131,0.86978,0.02208,,,,,0.05271393939,0.02609929078
209.631,0.91195,0.02686,,,,,0.05526969697,0.03174940898
210.131,0.95353,0.03134,,,,,0.05778969697,0.03704491726
210.631,0.99489,0.03649,,,,,0.06029636364,0.04313238771
211.131,1.03688,0.04157,,,,,0.06284121212,0.04913711584
211.631,1.07842,0.04691,,,,,0.06535878788,0.05544917258
212.131,1.12017,0.05098,,,,,0.06788909091,0.06026004728
212.631,1.16185,0.05602,,,,,0.07041515152,0.06621749409
213.131,1.20319,0.06107,,,,,0.07292060606,0.07218676123
213.631,1.24527,0.06616,,,,,0.07547090909,0.07820330969
214.131,1.28675,0.07125,,,,,0.07798484848,0.08421985816
214.631,1.3281,0.07529,,,,,0.08049090909,0.08899527187
215.131,1.37031,0.07925,,,,,0.08304909091,0.09367612293
215.631,1.41165,0.08374,,,,,0.08555454545,0.09898345154
216.131,1.45338,0.08775,,,,,0.08808363636,0.1037234043
216.631,1.49526,0.09194,,,,,0.09062181818,0.1086761229
217.131,1.53651,0.09798,,,,,0.09312181818,0.1158156028
217.631,1.57855,0.10146,,,,,0.09566969697,0.119929078
218.131,1.62028,0.10404,,,,,0.09819878788,0.1229787234
218.495,1.65013,0.10906,,,,,0.1000078788,0.1289125296
218.896,1.62189,0.08329,,,,,0.09829636364,0.09845153664
219.396,1.5803,0.06545,,,,,0.09577575758,0.07736406619
219.896,1.53879,0.05195,,,,,0.09326,0.06140661939
220.396,1.49669,0.03925,,,,,0.09070848485,0.04639479905
220.896,1.45538,0.02941,,,,,0.08820484848,0.03476359338
221.396,1.4138,0.02027,,,,,0.08568484848,0.02395981087
221.896,1.37163,0.00983,,,,,0.08312909091,0.01161938534
222.396,1.33041,0.00316,,,,,0.08063090909,0.003735224586
222.896,1.28856,-0.00313,,,,,0.07809454545,-0.003699763593
223.396,1.24683,-0.01154,,,,,0.07556545455,-0.01364066194
223.896,1.2054,-0.01658,,,,,0.07305454545,-0.01959810875
224.396,1.16346,-0.02288,,,,,0.07051272727,-0.02704491726
224.896,1.12187,-0.0299,,,,,0.06799212121,-0.0353427896
225.396,1.08048,-0.03563,,,,,0.06548363636,-0.04211583924
225.896,1.03836,-0.04114,,,,,0.06293090909,-0.04862884161
226.396,0.99695,-0.04693,,,,,0.06042121212,-0.05547281324
226.896,0.95534,-0.05193,,,,,0.05789939394,-0.06138297872
227.396,0.91354,-0.0575,,,,,0.05536606061,-0.06796690307
227.896,0.87204,-0.06244,,,,,0.05285090909,-0.07380614657
228.396,0.8301,-0.06671,,,,,0.05030909091,-0.0788534279
228.896,0.78872,-0.07159,,,,,0.04780121212,-0.08462174941
229.396,0.74703,-0.07607,,,,,0.04527454545,-0.08991725768
229.896,0.70499,-0.08116,,,,,0.04272666667,-0.09593380615
230.396,0.66364,-0.0842,,,,,0.04022060606,-0.09952718676
230.896,0.62202,-0.08971,,,,,0.03769818182,-0.1060401891
231.396,0.58001,-0.09306,,,,,0.03515212121,-0.11
231.896,0.53874,-0.09612,,,,,0.03265090909,-0.1136170213
232.396,0.49685,-0.09963,,,,,0.03011212121,-0.1177659574
232.896,0.45525,-0.10342,,,,,0.02759090909,-0.1222458629
233.396,0.41384,-0.10606,,,,,0.02508121212,-0.1253664303
233.896,0.37173,-0.10818,,,,,0.02252909091,-0.1278723404
234.396,0.33031,-0.10999,,,,,0.02001878788,-0.1300118203
234.896,0.28877,-0.11266,,,,,0.01750121212,-0.1331678487
235.396,0.24677,-0.11493,,,,,0.01495575758,-0.1358510638
235.896,0.20529,-0.11407,,,,,0.01244181818,-0.1348345154
236.396,0.16361,-0.1197,,,,,0.009915757576,-0.1414893617
236.896,0.12186,-0.11859,,,,,0.007385454545,-0.140177305
237.396,0.08046,-0.11949,,,,,0.004876363636,-0.1412411348
237.896,0.03837,-0.11964,,,,,0.002325454545,-0.1414184397
238.362,-0.00008,-0.1205,,,,,-0.000004848484848,-0.1424349882
238.664,0.01955,-0.11673,,,,,0.001184848485,-0.1379787234
239.164,0.06189,-0.11209,,,,,0.003750909091,-0.1324940898
239.664,0.10339,-0.10491,,,,,0.006266060606,-0.1240070922
240.164,0.14488,-0.09701,,,,,0.008780606061,-0.1146690307
240.664,0.18685,-0.08723,,,,,0.01132424242,-0.103108747
241.164,0.22827,-0.07953,,,,,0.01383454545,-0.0940070922
241.664,0.27008,-0.07104,,,,,0.01636848485,-0.08397163121
242.164,0.3118,-0.06648,,,,,0.0188969697,-0.07858156028
242.664,0.35312,-0.05684,,,,,0.02140121212,-0.06718676123
243.164,0.39523,-0.05025,,,,,0.02395333333,-0.05939716312
243.664,0.43668,-0.04365,,,,,0.02646545455,-0.05159574468
244.164,0.47821,-0.03785,,,,,0.02898242424,-0.04473995272
244.664,0.52016,-0.02931,,,,,0.03152484848,-0.03464539007
245.164,0.56145,-0.0254,,,,,0.03402727273,-0.03002364066
245.664,0.6034,-0.01751,,,,,0.03656969697,-0.02069739953
246.164,0.64518,-0.01103,,,,,0.03910181818,-0.01303782506
246.664,0.68633,-0.00464,,,,,0.04159575758,-0.00548463357
247.164,0.72844,-0.00111,,,,,0.04414787879,-0.001312056738
247.664,0.77016,0.00359,,,,,0.04667636364,0.004243498818
248.164,0.81138,0.01059,,,,,0.04917454545,0.0125177305
248.664,0.85356,0.01699,,,,,0.05173090909,0.02008274232
249.164,0.89497,0.02011,,,,,0.05424060606,0.02377068558
249.664,0.9367,0.02576,,,,,0.05676969697,0.03044917258
250.164,0.97846,0.03204,,,,,0.05930060606,0.03787234043
250.664,1.01981,0.03719,,,,,0.06180666667,0.04395981087
251.164,1.06185,0.04132,,,,,0.06435454545,0.04884160757
251.664,1.10343,0.04574,,,,,0.06687454545,0.05406619385
252.164,1.14473,0.05067,,,,,0.06937757576,0.05989361702
252.664,1.18689,0.05663,,,,,0.07193272727,0.06693853428
253.164,1.22836,0.06115,,,,,0.07444606061,0.07228132388
253.664,1.26982,0.06412,,,,,0.07695878788,0.07579196217
254.164,1.31191,0.06924,,,,,0.07950969697,0.08184397163
254.664,1.35316,0.07473,,,,,0.08200969697,0.08833333333
255.164,1.39513,0.07874,,,,,0.08455333333,0.09307328605
255.664,1.43682,0.08253,,,,,0.08708,0.09755319149
256.164,1.47811,0.08643,,,,,0.08958242424,0.1021631206
256.664,1.52022,0.0912,,,,,0.09213454545,0.1078014184
257.164,1.56182,0.09715,,,,,0.09465575758,0.1148345154
257.664,1.60322,0.10045,,,,,0.09716484848,0.1187352246
258.164,1.6451,0.10561,,,,,0.0997030303,0.1248345154
258.43,1.639,0.08649,,,,,0.09933333333,0.1022340426
258.93,1.59707,0.06469,,,,,0.09679212121,0.07646572104
259.43,1.55505,0.05107,,,,,0.09424545455,0.06036643026
259.93,1.51373,0.04202,,,,,0.09174121212,0.04966903073
260.43,1.47188,0.03053,,,,,0.08920484848,0.03608747045
260.93,1.43019,0.0196,,,,,0.08667818182,0.0231678487
261.43,1.3888,0.01048,,,,,0.08416969697,0.01238770686
261.93,1.34674,0.00368,,,,,0.08162060606,0.004349881797
262.43,1.30527,-0.00294,,,,,0.07910727273,-0.003475177305
262.93,1.26383,-0.01154,,,,,0.07659575758,-0.01364066194
263.43,1.22175,-0.01793,,,,,0.07404545455,-0.02119385343
263.93,1.18032,-0.02422,,,,,0.07153454545,-0.02862884161
264.43,1.13877,-0.02957,,,,,0.06901636364,-0.03495271868
264.93,1.09683,-0.03632,,,,,0.06647454545,-0.04293144208
265.43,1.05535,-0.04092,,,,,0.06396060606,-0.04836879433
265.93,1.01349,-0.04636,,,,,0.06142363636,-0.05479905437
266.43,0.97199,-0.05197,,,,,0.05890848485,-0.06143026005
266.93,0.93045,-0.05785,,,,,0.05639090909,-0.06838061466
267.43,0.88829,-0.0624,,,,,0.05383575758,-0.07375886525
267.93,0.84705,-0.068,,,,,0.05133636364,-0.08037825059
268.43,0.80541,-0.07158,,,,,0.04881272727,-0.08460992908
268.93,0.76335,-0.07557,,,,,0.04626363636,-0.08932624113
269.43,0.72198,-0.08001,,,,,0.04375636364,-0.09457446809
269.93,0.68033,-0.08508,,,,,0.04123212121,-0.1005673759
270.43,0.63853,-0.08809,,,,,0.03869878788,-0.1041252955
270.93,0.59717,-0.09285,,,,,0.03619212121,-0.109751773
271.43,0.55509,-0.0962,,,,,0.03364181818,-0.1137115839
271.93,0.51362,-0.09858,,,,,0.03112848485,-0.1165248227
272.43,0.47216,-0.10144,,,,,0.02861575758,-0.1199054374
272.93,0.43007,-0.10608,,,,,0.02606484848,-0.1253900709
273.43,0.38863,-0.10622,,,,,0.02355333333,-0.1255555556
273.93,0.34692,-0.11057,,,,,0.02102545455,-0.1306973995
274.43,0.30527,-0.11269,,,,,0.01850121212,-0.1332033097
274.93,0.26362,-0.11376,,,,,0.0159769697,-0.1344680851
275.43,0.22178,-0.11617,,,,,0.01344121212,-0.1373167849
275.93,0.18027,-0.11611,,,,,0.01092545455,-0.1372458629
276.43,0.13882,-0.11788,,,,,0.008413333333,-0.1393380615
276.93,0.09659,-0.11927,,,,,0.005853939394,-0.1409810875
277.43,0.05539,-0.12072,,,,,0.003356969697,-0.1426950355
277.93,0.01369,-0.12018,,,,,0.0008296969697,-0.1420567376
278.198,0.0024,-0.12115,,,,,0.0001454545455,-0.1432033097
278.698,0.04486,-0.11414,,,,,0.002718787879,-0.1349172577
279.198,0.08667,-0.10899,,,,,0.005252727273,-0.1288297872
279.698,0.12848,-0.10075,,,,,0.007786666667,-0.1190898345
280.198,0.1697,-0.0928,,,,,0.01028484848,-0.1096926714
280.698,0.21183,-0.08569,,,,,0.01283818182,-0.1012884161
281.198,0.2534,-0.07789,,,,,0.01535757576,-0.09206855792
281.698,0.29481,-0.07017,,,,,0.01786727273,-0.08294326241
282.198,0.33685,-0.06247,,,,,0.02041515152,-0.07384160757
282.698,0.37824,-0.05466,,,,,0.02292363636,-0.06460992908
283.198,0.41999,-0.04887,,,,,0.02545393939,-0.05776595745
283.698,0.4619,-0.04206,,,,,0.02799393939,-0.04971631206
284.198,0.50303,-0.03645,,,,,0.03048666667,-0.04308510638
284.698,0.5451,-0.03091,,,,,0.03303636364,-0.03653664303
285.198,0.58681,-0.02278,,,,,0.03556424242,-0.02692671395
285.698,0.62801,-0.0165,,,,,0.03806121212,-0.0195035461
286.198,0.67018,-0.01093,,,,,0.0406169697,-0.01291962175
286.698,0.71178,-0.0072,,,,,0.04313818182,-0.008510638298
287.198,0.75324,-0.00101,,,,,0.04565090909,-0.001193853428
287.698,0.79512,0.00562,,,,,0.04818909091,0.006643026005
288.198,0.83651,0.01092,,,,,0.05069757576,0.01290780142
288.698,0.87846,0.01525,,,,,0.05324,0.01802600473
289.198,0.92004,0.02096,,,,,0.05576,0.02477541371
289.698,0.9614,0.02561,,,,,0.05826666667,0.03027186761
290.198,1.00355,0.02976,,,,,0.06082121212,0.03517730496
290.698,1.04495,0.03488,,,,,0.06333030303,0.04122931442
291.198,1.0865,0.04026,,,,,0.06584848485,0.04758865248
291.698,1.12857,0.04668,,,,,0.06839818182,0.05517730496
292.198,1.16978,0.05389,,,,,0.07089575758,0.06369976359
292.698,1.21171,0.05479,,,,,0.0734369697,0.06476359338
293.198,1.25352,0.0597,,,,,0.07597090909,0.07056737589
293.698,1.29469,0.0637,,,,,0.07846606061,0.07529550827
294.198,1.33686,0.06915,,,,,0.08102181818,0.08173758865
294.698,1.37845,0.07227,,,,,0.08354242424,0.08542553191
295.198,1.41975,0.07787,,,,,0.08604545455,0.09204491726
295.698,1.46175,0.08324,,,,,0.08859090909,0.09839243499
296.198,1.50325,0.08557,,,,,0.09110606061,0.1011465721
296.698,1.54501,0.08939,,,,,0.0936369697,0.1056619385
297.198,1.58677,0.09315,,,,,0.09616787879,0.110106383
297.698,1.62806,0.09835,,,,,0.09867030303,0.1162529551
297.964,1.65019,0.10095,,,,,0.1000115152,0.1193262411
298.464,1.61331,0.07069,,,,,0.09777636364,0.08355791962
298.964,1.57209,0.05461,,,,,0.09527818182,0.06455082742
299.464,1.53009,0.04294,,,,,0.09273272727,0.05075650118
299.964,1.48853,0.0318,,,,,0.09021393939,0.03758865248
300.464,1.4471,0.02217,,,,,0.0877030303,0.02620567376
300.964,1.40501,0.01449,,,,,0.08515212121,0.01712765957
301.464,1.36355,0.00578,,,,,0.08263939394,0.0068321513
301.964,1.32212,-0.00353,,,,,0.08012848485,-0.004172576832
302.464,1.28001,-0.00962,,,,,0.07757636364,-0.01137115839
302.964,1.23859,-0.01523,,,,,0.07506606061,-0.01800236407
303.464,1.19687,-0.0224,,,,,0.07253757576,-0.02647754137
303.964,1.15519,-0.03023,,,,,0.07001151515,-0.03573286052
304.464,1.11369,-0.03488,,,,,0.06749636364,-0.04122931442
304.964,1.07166,-0.04059,,,,,0.06494909091,-0.0479787234
305.464,1.03034,-0.045,,,,,0.06244484848,-0.05319148936
305.964,0.98866,-0.05088,,,,,0.05991878788,-0.06014184397
306.464,0.94668,-0.05776,,,,,0.05737454545,-0.06827423168
306.964,0.90534,-0.06087,,,,,0.05486909091,-0.07195035461
307.464,0.86356,-0.06535,,,,,0.0523369697,-0.07724586288
307.964,0.82176,-0.07082,,,,,0.04980363636,-0.08371158392
308.464,0.78044,-0.07569,,,,,0.04729939394,-0.08946808511
308.964,0.73842,-0.0786,,,,,0.04475272727,-0.09290780142
309.464,0.69692,-0.08238,,,,,0.04223757576,-0.09737588652
309.964,0.65547,-0.0865,,,,,0.03972545455,-0.1022458629
310.464,0.61331,-0.09087,,,,,0.03717030303,-0.1074113475
310.964,0.57191,-0.09569,,,,,0.03466121212,-0.113108747
311.464,0.53032,-0.09882,,,,,0.03214060606,-0.1168085106
311.964,0.48846,-0.10151,,,,,0.02960363636,-0.1199881797
312.464,0.44692,-0.10482,,,,,0.02708606061,-0.1239007092
312.964,0.40508,-0.10703,,,,,0.02455030303,-0.1265130024
313.464,0.36357,-0.1098,,,,,0.02203454545,-0.129787234
313.964,0.32211,-0.11138,,,,,0.01952181818,-0.1316548463
314.464,0.27994,-0.11307,,,,,0.01696606061,-0.1336524823
314.964,0.23863,-0.11661,,,,,0.01446242424,-0.1378368794
315.464,0.19714,-0.117,,,,,0.01194787879,-0.1382978723
315.964,0.15498,-0.1167,,,,,0.009392727273,-0.1379432624
316.464,0.11365,-0.11889,,,,,0.006887878788,-0.1405319149
316.964,0.07193,-0.11952,,,,,0.004359393939,-0.1412765957
317.464,0.03014,-0.12156,,,,,0.001826666667,-0.1436879433
317.83,-0.00014,-0.12295,,,,,-0.000008484848485,-0.1453309693
318.231,0.02845,-0.11863,,,,,0.001724242424,-0.1402245863
318.731,0.07016,-0.11233,,,,,0.004252121212,-0.1327777778
319.231,0.11147,-0.10643,,,,,0.006755757576,-0.1258037825
319.731,0.15357,-0.0975,,,,,0.009307272727,-0.115248227
320.231,0.195,-0.09128,,,,,0.01181818182,-0.1078959811
320.731,0.23668,-0.08382,,,,,0.01434424242,-0.09907801418
321.231,0.27851,-0.07595,,,,,0.01687939394,-0.08977541371
321.731,0.31973,-0.06724,,,,,0.01937757576,-0.07947990544
322.231,0.36187,-0.06144,,,,,0.02193151515,-0.07262411348
322.731,0.40351,-0.054,,,,,0.02445515152,-0.06382978723
323.231,0.44468,-0.04768,,,,,0.02695030303,-0.05635933806
323.731,0.48678,-0.04164,,,,,0.02950181818,-0.04921985816
324.231,0.52851,-0.03514,,,,,0.03203090909,-0.04153664303
324.731,0.56981,-0.02869,,,,,0.03453393939,-0.03391252955
325.231,0.61189,-0.02222,,,,,0.03708424242,-0.02626477541
325.731,0.65318,-0.01638,,,,,0.03958666667,-0.01936170213
326.231,0.69512,-0.01211,,,,,0.04212848485,-0.0143144208
326.731,0.73677,-0.00537,,,,,0.04465272727,-0.00634751773
327.231,0.77815,-0.0005,,,,,0.04716060606,-0.0005910165485
327.731,0.82028,0.00522,,,,,0.04971393939,0.006170212766
328.231,0.86177,0.01099,,,,,0.05222848485,0.01299054374
328.731,0.90316,0.01591,,,,,0.0547369697,0.01880614657
329.231,0.94524,0.02179,,,,,0.05728727273,0.02575650118
329.731,0.9866,0.02772,,,,,0.05979393939,0.03276595745
330.231,1.02829,0.03153,,,,,0.06232060606,0.03726950355
330.731,1.07024,0.03603,,,,,0.0648630303,0.04258865248
331.231,1.11144,0.04034,,,,,0.06736,0.04768321513
331.731,1.15352,0.04552,,,,,0.06991030303,0.05380614657
332.231,1.19515,0.05024,,,,,0.07243333333,0.05938534279
332.731,1.23643,0.05548,,,,,0.07493515152,0.06557919622
333.231,1.27853,0.06094,,,,,0.07748666667,0.07203309693
333.731,1.32013,0.06486,,,,,0.08000787879,0.07666666667
334.231,1.36167,0.06956,,,,,0.08252545455,0.08222222222
334.731,1.40345,0.07466,,,,,0.08505757576,0.08825059102
335.231,1.44485,0.07846,,,,,0.08756666667,0.09274231678
335.731,1.48684,0.08105,,,,,0.09011151515,0.09580378251
336.231,1.5284,0.08638,,,,,0.09263030303,0.1021040189
336.731,1.56971,0.09031,,,,,0.09513393939,0.106749409
337.231,1.61195,0.09554,,,,,0.09769393939,0.1129314421
337.695,1.65006,0.09726,,,,,0.1000036364,0.114964539
337.997,1.63073,0.07656,,,,,0.09883212121,0.0904964539
338.497,1.58835,0.05882,,,,,0.09626363636,0.06952718676
338.997,1.54704,0.04489,,,,,0.09376,0.05306146572
339.497,1.50547,0.03304,,,,,0.09124060606,0.03905437352
339.997,1.46345,0.02344,,,,,0.08869393939,0.02770685579
340.497,1.42199,0.01362,,,,,0.08618121212,0.01609929078
340.997,1.38035,0.00427,,,,,0.08365757576,0.005047281324
341.497,1.33855,-0.00344,,,,,0.08112424242,-0.004066193853
341.997,1.29706,-0.00927,,,,,0.07860969697,-0.01095744681
342.497,1.25512,-0.01566,,,,,0.07606787879,-0.0185106383
342.997,1.21369,-0.02314,,,,,0.0735569697,-0.02735224586
343.497,1.17213,-0.02888,,,,,0.07103818182,-0.03413711584
343.997,1.12996,-0.03494,,,,,0.06848242424,-0.04130023641
344.497,1.08879,-0.0398,,,,,0.06598727273,-0.04704491726
344.997,1.04701,-0.04554,,,,,0.06345515152,-0.05382978723
345.497,1.00512,-0.05123,,,,,0.06091636364,-0.06055555556
345.997,0.96371,-0.05583,,,,,0.05840666667,-0.0659929078
346.497,0.9219,-0.06105,,,,,0.05587272727,-0.07216312057
346.997,0.88021,-0.06699,,,,,0.05334606061,-0.07918439716
347.497,0.83883,-0.07244,,,,,0.05083818182,-0.08562647754
347.997,0.79672,-0.07569,,,,,0.04828606061,-0.08946808511
348.497,0.75529,-0.07929,,,,,0.04577515152,-0.09372340426
348.997,0.71373,-0.08451,,,,,0.04325636364,-0.09989361702
349.497,0.67179,-0.08858,,,,,0.04071454545,-0.1047044917
349.997,0.63033,-0.09131,,,,,0.03820181818,-0.1079314421
350.497,0.58852,-0.09457,,,,,0.03566787879,-0.11178487
350.997,0.54702,-0.09918,,,,,0.03315272727,-0.1172340426
351.497,0.50537,-0.10178,,,,,0.03062848485,-0.1203073286
351.997,0.46341,-0.10429,,,,,0.02808545455,-0.1232742317
352.497,0.422,-0.10746,,,,,0.02557575758,-0.1270212766
352.997,0.38049,-0.10971,,,,,0.02306,-0.1296808511
353.497,0.33836,-0.11176,,,,,0.02050666667,-0.1321040189
353.997,0.29707,-0.11316,,,,,0.01800424242,-0.1337588652
354.497,0.2553,-0.11693,,,,,0.01547272727,-0.13821513
354.997,0.21352,-0.11824,,,,,0.01294060606,-0.1397635934
355.497,0.17215,-0.11874,,,,,0.01043333333,-0.1403546099
355.997,0.13011,-0.11827,,,,,0.007885454545,-0.1397990544
356.497,0.0886,-0.11909,,,,,0.00536969697,-0.1407683215
356.997,0.04717,-0.12061,,,,,0.002858787879,-0.1425650118
357.497,0.0051,-0.12098,,,,,0.0003090909091,-0.1430023641
357.765,0.01128,-0.12096,,,,,0.0006836363636,-0.1429787234
358.265,0.05324,-0.11531,,,,,0.003226666667,-0.1363002364
358.765,0.09521,-0.10956,,,,,0.00577030303,-0.1295035461
359.265,0.13648,-0.10131,,,,,0.008271515152,-0.119751773
359.765,0.17848,-0.09513,,,,,0.0108169697,-0.1124468085
360.265,0.22022,-0.08733,,,,,0.01334666667,-0.1032269504
360.765,0.26136,-0.0795,,,,,0.01584,-0.09397163121
361.265,0.30348,-0.07349,,,,,0.01839272727,-0.08686761229
361.765,0.34515,-0.06498,,,,,0.02091818182,-0.07680851064
362.265,0.38646,-0.0587,,,,,0.02342181818,-0.06938534279
362.765,0.42852,-0.04978,,,,,0.02597090909,-0.05884160757
363.265,0.46999,-0.04532,,,,,0.02848424242,-0.05356973995
363.765,0.51171,-0.03963,,,,,0.03101272727,-0.04684397163
364.265,0.55355,-0.03418,,,,,0.03354848485,-0.04040189125
364.765,0.59488,-0.02774,,,,,0.03605333333,-0.03278959811
365.265,0.6369,-0.0201,,,,,0.0386,-0.02375886525
365.765,0.67844,-0.0153,,,,,0.04111757576,-0.01808510638
366.265,0.71985,-0.0089,,,,,0.04362727273,-0.01052009456
366.765,0.76189,-0.00426,,,,,0.04617515152,-0.005035460993
367.265,0.80322,0.00002,,,,,0.04868,0.00002364066194
367.765,0.84503,0.00544,,,,,0.05121393939,0.006430260047
368.265,0.88685,0.0094,,,,,0.05374848485,0.01111111111
368.765,0.92808,0.01572,,,,,0.05624727273,0.01858156028
369.265,0.97007,0.0214,,,,,0.05879212121,0.02529550827
369.765,1.01184,0.02659,,,,,0.06132363636,0.03143026005
370.265,1.05298,0.03418,,,,,0.0638169697,0.04040189125
370.765,1.09525,0.0353,,,,,0.06637878788,0.04172576832
371.265,1.13681,0.03882,,,,,0.06889757576,0.04588652482
371.765,1.17825,0.04626,,,,,0.07140909091,0.05468085106
372.265,1.22013,0.05137,,,,,0.07394727273,0.06072104019
372.765,1.26152,0.05584,,,,,0.07645575758,0.06600472813
373.265,1.30345,0.05866,,,,,0.0789969697,0.06933806147
373.765,1.34516,0.06295,,,,,0.08152484848,0.07440898345
374.265,1.38644,0.06715,,,,,0.08402666667,0.07937352246
374.765,1.42859,0.07201,,,,,0.08658121212,0.08511820331
375.265,1.4701,0.07548,,,,,0.0890969697,0.08921985816
375.765,1.5114,0.08119,,,,,0.0916,0.09596926714
376.265,1.55358,0.08489,,,,,0.09415636364,0.1003427896
376.765,1.5949,0.08997,,,,,0.09666060606,0.1063475177
377.265,1.63672,0.09127,,,,,0.09919515152,0.1078841608
377.531,1.64763,0.0843,,,,,0.09985636364,0.09964539007
378.031,1.6054,0.06088,,,,,0.0972969697,0.07196217494
378.531,1.56378,0.04636,,,,,0.09477454545,0.05479905437
379.031,1.52194,0.03501,,,,,0.09223878788,0.04138297872
379.531,1.48049,0.02423,,,,,0.08972666667,0.02864066194
380.031,1.4386,0.01594,,,,,0.08718787879,0.01884160757
380.531,1.39708,0.00742,,,,,0.08467151515,0.008770685579
381.031,1.35556,-0.0003,,,,,0.08215515152,-0.0003546099291
381.531,1.31348,-0.0079,,,,,0.07960484848,-0.009338061466
382.031,1.27217,-0.01459,,,,,0.07710121212,-0.01724586288
382.531,1.23045,-0.01998,,,,,0.07457272727,-0.02361702128
383.031,1.18858,-0.02662,,,,,0.07203515152,-0.03146572104
383.531,1.1472,-0.03336,,,,,0.06952727273,-0.03943262411
384.031,1.10525,-0.03904,,,,,0.06698484848,-0.0461465721
384.531,1.06366,-0.04552,,,,,0.06446424242,-0.05380614657
385.031,1.02225,-0.04875,,,,,0.06195454545,-0.05762411348
385.531,0.98019,-0.05511,,,,,0.05940545455,-0.06514184397
386.031,0.93873,-0.05947,,,,,0.05689272727,-0.07029550827
386.531,0.89724,-0.0658,,,,,0.05437818182,-0.07777777778
387.031,0.85517,-0.06826,,,,,0.05182848485,-0.0806855792
387.531,0.81372,-0.07393,,,,,0.04931636364,-0.08738770686
388.031,0.77204,-0.07784,,,,,0.04679030303,-0.09200945626
388.531,0.73041,-0.08303,,,,,0.04426727273,-0.09814420804
389.031,0.68884,-0.08565,,,,,0.04174787879,-0.1012411348
389.531,0.64679,-0.0893,,,,,0.03919939394,-0.1055555556
390.031,0.6055,-0.09492,,,,,0.0366969697,-0.1121985816
390.531,0.56393,-0.09856,,,,,0.03417757576,-0.116501182
391.031,0.52173,-0.09886,,,,,0.03162,-0.116855792
391.531,0.48041,-0.10182,,,,,0.02911575758,-0.1203546099
392.031,0.43884,-0.10684,,,,,0.02659636364,-0.1262884161
392.531,0.3969,-0.10981,,,,,0.02405454545,-0.1297990544
393.031,0.35553,-0.11104,,,,,0.02154727273,-0.1312529551
393.531,0.31362,-0.11367,,,,,0.01900727273,-0.1343617021
394.031,0.27204,-0.11303,,,,,0.01648727273,-0.1336052009
394.531,0.2306,-0.11452,,,,,0.01397575758,-0.1353664303
395.031,0.1885,-0.11709,,,,,0.01142424242,-0.1384042553
395.531,0.14709,-0.11984,,,,,0.008914545455,-0.1416548463
396.031,0.10544,-0.11998,,,,,0.00639030303,-0.141820331
396.531,0.06367,-0.1209,,,,,0.003858787879,-0.1429078014
397.031,0.02205,-0.11936,,,,,0.001336363636,-0.1410874704
397.298,-0.00005,-0.12179,,,,,-0.00000303030303,-0.1439598109