File: mechanical/hysteresis/data/pristine_nonconductive_2.csv
Time,Extension,Load,Length,Width,Thickness,CS Area,Strain,Stress
(s),(mm),(N),(mm),(mm),(mm),(mm^2),(mm/mm),(MPa)
0,0,-0.00549,16.5,2.82,0.29,0.8178,0,-0.006713132795
0.5,0.03853,0.01148,,,,,0.002335151515,0.01403766202
1,0.07987,0.02134,,,,,0.004840606061,0.02609439961
1.5,0.12192,0.03095,,,,,0.007389090909,0.03784543898
2,0.16354,0.03808,,,,,0.009911515152,0.04656395207
2.5,0.2048,0.04479,,,,,0.01241212121,0.05476889215
3,0.24703,0.05331,,,,,0.01497151515,0.06518708731
3.5,0.28853,0.05978,,,,,0.01748666667,0.0730985571
4,0.32993,0.06654,,,,,0.01999575758,0.08136463683
4.5,0.37193,0.07329,,,,,0.02254121212,0.08961848863
5,0.41337,0.07707,,,,,0.02505272727,0.09424064563
5.5,0.45517,0.0832,,,,,0.02758606061,0.1017363659
6,0.49694,0.08732,,,,,0.03011757576,0.1067742724
6.5,0.53822,0.09188,,,,,0.03261939394,0.1123502079
7,0.58024,0.09961,,,,,0.03516606061,0.1218023967
7.5,0.62184,0.10391,,,,,0.03768727273,0.127060406
8,0.66324,0.10645,,,,,0.04019636364,0.1301662998
8.5,0.70527,0.11488,,,,,0.04274363636,0.1404744436
9,0.74666,0.11831,,,,,0.04525212121,0.1446686231
9.5,0.78849,0.11868,,,,,0.04778727273,0.1451210565
10,0.83021,0.12288,,,,,0.05031575758,0.1502567865
10.5,0.87155,0.12998,,,,,0.05282121212,0.1589386158
11,0.91359,0.13582,,,,,0.05536909091,0.1660797261
11.5,0.95533,0.1382,,,,,0.05789878788,0.1689899731
12,0.99646,0.14273,,,,,0.06039151515,0.1745292247
12.5,1.03874,0.14535,,,,,0.06295393939,0.177732942
13,1.08021,0.15048,,,,,0.06546727273,0.1840058694
13.5,1.12167,0.15246,,,,,0.06798,0.1864269993
14,1.16363,0.15805,,,,,0.0705230303,0.1932624113
14.5,1.20494,0.16057,,,,,0.07302666667,0.1963438494
15,1.24683,0.1643,,,,,0.07556545455,0.2009048667
15.5,1.2885,0.16918,,,,,0.07809090909,0.2068720959
16,1.32984,0.17172,,,,,0.08059636364,0.2099779897
16.5,1.37184,0.17439,,,,,0.08314181818,0.2132428467
17,1.41353,0.1789,,,,,0.08566848485,0.2187576425
17.5,1.45493,0.18042,,,,,0.08817757576,0.2206162876
18,1.497,0.18386,,,,,0.09072727273,0.224822695
18.5,1.53825,0.18711,,,,,0.09322727273,0.2287967718
19,1.58023,0.19242,,,,,0.09577151515,0.2352898019
19.5,1.62191,0.19532,,,,,0.09829757576,0.2388359012
19.842,1.65008,0.19558,,,,,0.1000048485,0.2391538273
20.243,1.62178,0.16006,,,,,0.09828969697,0.195720225
20.743,1.5799,0.13683,,,,,0.09575151515,0.1673147469
21.243,1.53844,0.12021,,,,,0.09323878788,0.1469919296
21.743,1.49659,0.10787,,,,,0.09070242424,0.1319026657
22.243,1.45505,0.09301,,,,,0.08818484848,0.1137319638
22.743,1.41355,0.08145,,,,,0.08566969697,0.09959647836
23.243,1.37143,0.07141,,,,,0.0831169697,0.08731963805
23.743,1.33006,0.06008,,,,,0.08060969697,0.07346539496
24.243,1.28862,0.05195,,,,,0.07809818182,0.06352408902
24.743,1.24636,0.04162,,,,,0.0755369697,0.05089263879
25.243,1.20509,0.03295,,,,,0.07303575758,0.0402910247
25.743,1.16332,0.0258,,,,,0.07050424242,0.03154805576
26.243,1.12172,0.01917,,,,,0.0679830303,0.0234409391
26.743,1.08008,0.01131,,,,,0.06545939394,0.01382978723
27.243,1.03814,0.00585,,,,,0.06291757576,0.007153338225
27.743,0.99673,-0.00221,,,,,0.06040787879,-0.002702372218
28.243,0.95516,-0.00995,,,,,0.05788848485,-0.01216678895
28.743,0.91304,-0.01688,,,,,0.05533575758,-0.02064074346
29.243,0.87182,-0.02363,,,,,0.05283757576,-0.02889459526
29.743,0.83006,-0.02912,,,,,0.05030666667,-0.03560772805
30.243,0.78818,-0.03547,,,,,0.04776848485,-0.0433724627
30.743,0.74693,-0.04007,,,,,0.04526848485,-0.04899730986
31.243,0.70482,-0.04545,,,,,0.04271636364,-0.05557593544
31.743,0.66333,-0.05239,,,,,0.04020181818,-0.06406211788
32.243,0.62186,-0.0582,,,,,0.03768848485,-0.07116654439
32.743,0.57974,-0.06305,,,,,0.03513575758,-0.07709708975
33.243,0.53829,-0.0688,,,,,0.03262363636,-0.08412814869
33.743,0.49681,-0.0738,,,,,0.03010969697,-0.09024211299
34.243,0.45482,-0.07923,,,,,0.02756484848,-0.09688187821
34.743,0.4134,-0.08066,,,,,0.02505454545,-0.098630472
35.243,0.37161,-0.08896,,,,,0.02252181818,-0.1087796527
35.743,0.32999,-0.09355,,,,,0.01999939394,-0.1143922719
36.243,0.28849,-0.09836,,,,,0.01748424242,-0.1202739056
36.743,0.24646,-0.10181,,,,,0.0149369697,-0.124492541
37.243,0.20513,-0.10667,,,,,0.01243212121,-0.1304353143
37.743,0.16344,-0.11118,,,,,0.009905454545,-0.1359501101
38.243,0.12146,-0.11351,,,,,0.007361212121,-0.1387992174
38.743,0.08011,-0.11475,,,,,0.004855151515,-0.1403154806
39.243,0.03831,-0.11557,,,,,0.002321818182,-0.1413181707
39.705,-0.00008,-0.11867,,,,,-0.000004848484848,-0.1451088286
40.007,0.01977,-0.1082,,,,,0.001198181818,-0.1323061873
40.507,0.06197,-0.09113,,,,,0.003755757576,-0.1114331132
41.007,0.10313,-0.07498,,,,,0.00625030303,-0.09168500856
41.507,0.14507,-0.06245,,,,,0.008792121212,-0.07636341404
42.007,0.18684,-0.05059,,,,,0.01132363636,-0.06186109073
42.507,0.22808,-0.03977,,,,,0.0138230303,-0.048630472
43.007,0.27022,-0.02979,,,,,0.0163769697,-0.03642699927
43.507,0.31183,-0.01941,,,,,0.01889878788,-0.02373440939
44.007,0.35315,-0.0115,,,,,0.0214030303,-0.01406211788
44.507,0.39511,-0.00102,,,,,0.02394606061,-0.001247248716
45.007,0.4366,0.00557,,,,,0.02646060606,0.006810956224
45.507,0.47846,0.01238,,,,,0.02899757576,0.01513817559
46.007,0.52015,0.02051,,,,,0.03152424242,0.02507948154
46.507,0.56145,0.02798,,,,,0.03402727273,0.03421374419
47.007,0.60357,0.03339,,,,,0.03658,0.04082905356
47.507,0.64513,0.04062,,,,,0.03909878788,0.04966984593
48.007,0.68629,0.04767,,,,,0.04159333333,0.05829053558
48.507,0.72865,0.0556,,,,,0.04416060606,0.06798728295
49.007,0.77008,0.06211,,,,,0.04667151515,0.07594766447
49.507,0.81168,0.06706,,,,,0.04919272727,0.08200048912
50.007,0.85348,0.07161,,,,,0.05172606061,0.08756419663
50.507,0.89485,0.07866,,,,,0.05423333333,0.09618488628
51.007,0.93681,0.08394,,,,,0.05677636364,0.1026412326
51.507,0.97852,0.09076,,,,,0.05930424242,0.1109806799
52.007,1.01982,0.09618,,,,,0.06180727273,0.1176082172
52.507,1.06188,0.10189,,,,,0.06435636364,0.1245903644
53.007,1.10341,0.10624,,,,,0.06687333333,0.1299095133
53.507,1.1449,0.11087,,,,,0.06938787879,0.1355710443
54.007,1.18682,0.11801,,,,,0.07192848485,0.1443017853
54.507,1.22815,0.1227,,,,,0.07443333333,0.1500366838
55.007,1.2702,0.12559,,,,,0.07698181818,0.1535705551
55.507,1.31181,0.13467,,,,,0.07950363636,0.1646735143
56.007,1.35315,0.13822,,,,,0.08200909091,0.169014429
56.507,1.3953,0.14233,,,,,0.08456363636,0.1740401076
57.007,1.4368,0.14643,,,,,0.08707878788,0.1790535583
57.507,1.47811,0.1498,,,,,0.08958242424,0.1831743703
58.007,1.52033,0.15587,,,,,0.09214121212,0.1905967229
58.507,1.56172,0.15908,,,,,0.09464969697,0.194521888
59.007,1.60334,0.16298,,,,,0.09717212121,0.1992907801
59.507,1.64523,0.16852,,,,,0.09971090909,0.2060650526
59.772,1.63887,0.1482,,,,,0.09932545455,0.1812179017
60.272,1.59711,0.12077,,,,,0.09679454545,0.1476766936
60.772,1.55494,0.10349,,,,,0.09423878788,0.126546833
61.272,1.51359,0.08914,,,,,0.09173272727,0.1089997554
61.772,1.47208,0.07506,,,,,0.0892169697,0.09178283199
62.272,1.42993,0.062,,,,,0.08666242424,0.07581315725
62.772,1.38856,0.05237,,,,,0.08415515152,0.06403766202
63.272,1.34696,0.04231,,,,,0.08163393939,0.05173636586
63.772,1.30505,0.03205,,,,,0.07909393939,0.03919051113
64.272,1.26364,0.02452,,,,,0.07658424242,0.0299828809
64.772,1.2217,0.01687,,,,,0.07404242424,0.02062851553
65.272,1.18028,0.00743,,,,,0.07153212121,0.009085350942
65.772,1.13873,-0.00006,,,,,0.06901393939,-0.00007336757153
66.272,1.09668,-0.0071,,,,,0.06646545455,-0.008681829298
66.772,1.0553,-0.01514,,,,,0.06395757576,-0.01851308388
67.272,1.01356,-0.02187,,,,,0.06142787879,-0.02674247982
67.772,0.97179,-0.02801,,,,,0.05889636364,-0.03425042798
68.272,0.93033,-0.03315,,,,,0.05638363636,-0.04053558327
68.772,0.8884,-0.03883,,,,,0.05384242424,-0.04748104671
69.272,0.84688,-0.04744,,,,,0.05132606061,-0.05800929323
69.772,0.8055,-0.05202,,,,,0.04881818182,-0.06360968452
70.272,0.76321,-0.05762,,,,,0.04625515152,-0.07045732453
70.772,0.72195,-0.0645,,,,,0.04375454545,-0.0788701394
71.272,0.68034,-0.06867,,,,,0.04123272727,-0.08396918562
71.772,0.63845,-0.07284,,,,,0.03869393939,-0.08906823184
72.272,0.59692,-0.07869,,,,,0.0361769697,-0.09622157007
72.772,0.5552,-0.08343,,,,,0.03364848485,-0.1020176082
73.272,0.51357,-0.08916,,,,,0.03112545455,-0.1090242113
73.772,0.47204,-0.09382,,,,,0.02860848485,-0.114722426
74.272,0.42999,-0.09812,,,,,0.02606,-0.1199804353
74.772,0.38867,-0.10177,,,,,0.02355575758,-0.1244436292
75.272,0.34706,-0.10656,,,,,0.02103393939,-0.130300807
75.772,0.3049,-0.11059,,,,,0.01847878788,-0.1352286623
76.272,0.26368,-0.11201,,,,,0.01598060606,-0.1369650281
76.772,0.22184,-0.11599,,,,,0.01344484848,-0.1418317437
77.272,0.18008,-0.11593,,,,,0.01091393939,-0.1417583761
77.772,0.13866,-0.11615,,,,,0.008403636364,-0.1420273906
78.272,0.09676,-0.1169,,,,,0.005864242424,-0.1429444852
78.772,0.05513,-0.11824,,,,,0.003341212121,-0.1445830276
79.272,0.01377,-0.11943,,,,,0.0008345454545,-0.1460381511
79.538,0.00215,-0.1186,,,,,0.0001303030303,-0.1450232331
80.038,0.04475,-0.11339,,,,,0.002712121212,-0.1386524823
80.538,0.08686,-0.105,,,,,0.005264242424,-0.1283932502
81.038,0.12849,-0.08958,,,,,0.007787272727,-0.1095377843
81.538,0.1698,-0.07574,,,,,0.01029090909,-0.09261433113
82.038,0.21188,-0.06614,,,,,0.01284121212,-0.08087551969
82.538,0.25339,-0.05438,,,,,0.0153569697,-0.06649547567
83.038,0.29504,-0.04343,,,,,0.01788121212,-0.05310589386
83.538,0.33683,-0.0346,,,,,0.02041393939,-0.04230863292
84.038,0.37818,-0.02824,,,,,0.02292,-0.03453167034
84.538,0.42021,-0.01404,,,,,0.02546727273,-0.01716801174
85.038,0.46173,-0.00917,,,,,0.02798363636,-0.01121301052
85.538,0.50305,-0.00415,,,,,0.03048787879,-0.005074590364
86.038,0.54541,0.00595,,,,,0.03305515152,0.00727561751
86.538,0.58672,0.01348,,,,,0.03555878788,0.01648324774
87.038,0.62827,0.02092,,,,,0.0380769697,0.02558082661
87.538,0.67024,0.02847,,,,,0.04062060606,0.03481291269
88.038,0.71148,0.0338,,,,,0.04312,0.04133039863
88.538,0.75335,0.04025,,,,,0.04565757576,0.04921741257
89.038,0.79533,0.04696,,,,,0.04820181818,0.05742235265
89.538,0.83642,0.05339,,,,,0.05069212121,0.06528491074
90.038,0.87851,0.05849,,,,,0.0532430303,0.07152115432
90.538,0.92013,0.06376,,,,,0.05576545455,0.07796527268
91.038,0.96152,0.07051,,,,,0.05827393939,0.08621912448
91.538,1.00348,0.07867,,,,,0.0608169697,0.09619711421
92.038,1.04491,0.08233,,,,,0.06332787879,0.1006725361
92.538,1.08679,0.08869,,,,,0.06586606061,0.1084494987
93.038,1.12848,0.09549,,,,,0.06839272727,0.1167644901
93.538,1.16977,0.09789,,,,,0.07089515152,0.119699193
94.038,1.21191,0.10238,,,,,0.07344909091,0.1251895329
94.538,1.25346,0.1101,,,,,0.07596727273,0.1346294938
95.038,1.2948,0.11649,,,,,0.07847272727,0.1424431401
95.538,1.33691,0.12074,,,,,0.08102484848,0.1476400098
96.038,1.37836,0.12689,,,,,0.0835369697,0.1551601859
96.538,1.41997,0.12839,,,,,0.08605878788,0.1569943752
97.038,1.46183,0.1335,,,,,0.08859575758,0.1632428467
97.538,1.50321,0.13764,,,,,0.09110363636,0.1683052091
98.038,1.54518,0.14189,,,,,0.09364727273,0.1735020787
98.538,1.58684,0.14692,,,,,0.09617212121,0.1796527268
99.038,1.62811,0.15072,,,,,0.09867333333,0.1842993397
99.303,1.65018,0.15448,,,,,0.1000109091,0.1888970408
99.803,1.61334,0.12038,,,,,0.09777818182,0.1471998044
100.303,1.57194,0.09953,,,,,0.09526909091,0.1217045732
100.803,1.53045,0.08224,,,,,0.09275454545,0.1005624847
101.303,1.48847,0.06897,,,,,0.09021030303,0.08433602348
101.803,1.44713,0.05835,,,,,0.08770484848,0.07134996332
102.303,1.40518,0.04666,,,,,0.08516242424,0.0570555148
102.803,1.3637,0.0374,,,,,0.08264848485,0.04573245292
103.303,1.32211,0.02777,,,,,0.08012787879,0.03395695769
103.803,1.28004,0.01985,,,,,0.07757818182,0.02427243825
104.303,1.23871,0.01055,,,,,0.07507333333,0.01290046466
104.803,1.19705,0.00359,,,,,0.07254848485,0.004389826363
105.303,1.15509,-0.0052,,,,,0.07000545455,-0.006358522866
105.803,1.11375,-0.01271,,,,,0.0675,-0.01554169724
106.303,1.07184,-0.01966,,,,,0.06496,-0.02404010761
106.803,1.03019,-0.02556,,,,,0.06243575758,-0.03125458547
107.303,0.98886,-0.03166,,,,,0.05993090909,-0.03871362191
107.803,0.94665,-0.03842,,,,,0.05737272727,-0.04697970164
108.303,0.90529,-0.0448,,,,,0.05486606061,-0.05478112008
108.803,0.8638,-0.05243,,,,,0.05235151515,-0.06411102959
109.303,0.82171,-0.05722,,,,,0.04980060606,-0.06996820739
109.803,0.78028,-0.06333,,,,,0.04728969697,-0.07743947175
110.303,0.73863,-0.06738,,,,,0.04476545455,-0.08239178283
110.803,0.69688,-0.07382,,,,,0.04223515152,-0.09026656884
111.303,0.65544,-0.07785,,,,,0.03972363636,-0.09519442406
111.803,0.61349,-0.08474,,,,,0.03718121212,-0.1036194669
112.303,0.57198,-0.08903,,,,,0.03466545455,-0.1088652482
112.803,0.53041,-0.09484,,,,,0.03214606061,-0.1159696747
113.303,0.48837,-0.09959,,,,,0.02959818182,-0.1217779408
113.803,0.44702,-0.10353,,,,,0.02709212121,-0.1265957447
114.303,0.40528,-0.1091,,,,,0.02456242424,-0.1334067009
114.803,0.36352,-0.11072,,,,,0.02203151515,-0.1353876253
115.303,0.32211,-0.11255,,,,,0.01952181818,-0.1376253363
115.803,0.28008,-0.11624,,,,,0.01697454545,-0.1421374419
116.303,0.2386,-0.11744,,,,,0.01446060606,-0.1436047933
116.803,0.19717,-0.11809,,,,,0.01194969697,-0.1443996087
117.303,0.15509,-0.11799,,,,,0.009399393939,-0.1442773294
117.803,0.11366,-0.11808,,,,,0.006888484848,-0.1443873808
118.303,0.07215,-0.11886,,,,,0.004372727273,-0.1453411592
118.803,0.03016,-0.11907,,,,,0.001827878788,-0.1455979457
119.169,-0.00013,-0.11751,,,,,-0.000007878787879,-0.1436903888
119.57,0.0286,-0.11705,,,,,0.001733333333,-0.1431279041
120.07,0.07013,-0.11443,,,,,0.00425030303,-0.1399241868
120.57,0.1116,-0.10703,,,,,0.006763636364,-0.1308755197
121.07,0.15347,-0.09259,,,,,0.009301212121,-0.1132183908
121.57,0.19486,-0.07935,,,,,0.01180969697,-0.09702861335
122.07,0.23684,-0.06879,,,,,0.01435393939,-0.08411592076
122.57,0.27847,-0.0585,,,,,0.0168769697,-0.07153338225
123.07,0.31975,-0.0491,,,,,0.01937878788,-0.06003912937
123.57,0.36195,-0.03938,,,,,0.02193636364,-0.04815358278
124.07,0.40348,-0.03013,,,,,0.02445333333,-0.03684274884
124.57,0.44478,-0.02299,,,,,0.02695636364,-0.02811200783
125.07,0.48692,-0.01465,,,,,0.02951030303,-0.01791391538
125.57,0.52815,-0.00735,,,,,0.03200909091,-0.008987527513
126.07,0.57006,0.00127,,,,,0.03454909091,0.001552946931
126.57,0.61187,0.00786,,,,,0.0370830303,0.009611151871
127.07,0.65315,0.0129,,,,,0.03958484848,0.01577402788
127.57,0.69521,0.01997,,,,,0.04213393939,0.02441917339
128.07,0.73687,0.02719,,,,,0.04465878788,0.03324773783
128.57,0.77811,0.03228,,,,,0.04715818182,0.03947175348
129.07,0.82024,0.03979,,,,,0.04971151515,0.04865492786
129.57,0.86172,0.04619,,,,,0.05222545455,0.05648080215
130.07,0.90336,0.05187,,,,,0.05474909091,0.06342626559
130.57,0.9452,0.05813,,,,,0.05728484848,0.07108094889
131.07,0.98642,0.06216,,,,,0.0597830303,0.07600880411
131.57,1.02858,0.06794,,,,,0.06233818182,0.08307654683
132.07,1.07002,0.0747,,,,,0.06484969697,0.09134262656
132.57,1.11144,0.08035,,,,,0.06736,0.09825140621
133.07,1.15359,0.08519,,,,,0.06991454545,0.1041697236
133.57,1.19506,0.09136,,,,,0.07242787879,0.1117143556
134.07,1.23653,0.09549,,,,,0.07494121212,0.1167644901
134.57,1.27864,0.10108,,,,,0.07749333333,0.1235999022
135.07,1.31982,0.10626,,,,,0.07998909091,0.1299339692
135.57,1.36177,0.11023,,,,,0.08253151515,0.1347884568
136.07,1.40365,0.11601,,,,,0.08506969697,0.1418561996
136.57,1.4448,0.12063,,,,,0.08756363636,0.1475055026
137.07,1.48685,0.12561,,,,,0.09011212121,0.153595011
137.57,1.52844,0.12939,,,,,0.09263272727,0.158217168
138.07,1.5699,0.13582,,,,,0.09514545455,0.1660797261
138.57,1.61177,0.1406,,,,,0.0976830303,0.171924676
139.033,1.65007,0.14357,,,,,0.1000042424,0.1755563708
139.335,1.63087,0.1197,,,,,0.09884060606,0.1463683052
139.835,1.58891,0.09772,,,,,0.09629757576,0.1194913182
140.335,1.54734,0.0796,,,,,0.09377818182,0.09733431157
140.835,1.5059,0.06466,,,,,0.09126666667,0.07906578626
141.335,1.46376,0.05155,,,,,0.08871272727,0.06303497188
141.835,1.42239,0.04194,,,,,0.08620545455,0.0512839325
142.335,1.38074,0.03259,,,,,0.08368121212,0.03985081927
142.835,1.3389,0.02373,,,,,0.08114545455,0.02901687454
143.335,1.29745,0.01441,,,,,0.07863333333,0.0176204451
143.835,1.25555,0.00707,,,,,0.07609393939,0.008645145512
144.335,1.21402,-0.00222,,,,,0.0735769697,-0.002714600147
144.835,1.17253,-0.00928,,,,,0.07106242424,-0.01134751773
145.335,1.1304,-0.01572,,,,,0.06850909091,-0.01922230374
145.835,1.08905,-0.02215,,,,,0.0660030303,-0.02708486182
146.335,1.04763,-0.03041,,,,,0.06349272727,-0.03718513084
146.835,1.00543,-0.0377,,,,,0.06093515152,-0.04609929078
147.335,0.96411,-0.0424,,,,,0.05843090909,-0.05184641722
147.835,0.92232,-0.04864,,,,,0.05589818182,-0.05947664466
148.335,0.88078,-0.05454,,,,,0.05338060606,-0.06669112252
148.835,0.8391,-0.0593,,,,,0.05085454545,-0.07251161653
149.335,0.79714,-0.06573,,,,,0.04831151515,-0.08037417461
149.835,0.75572,-0.0718,,,,,0.04580121212,-0.08779652727
150.335,0.71414,-0.07595,,,,,0.04328121212,-0.09287111763
150.835,0.67204,-0.08173,,,,,0.04072969697,-0.09993886036
151.335,0.63076,-0.08697,,,,,0.03822787879,-0.1063462949
151.835,0.58902,-0.09255,,,,,0.03569818182,-0.1131694791
152.335,0.54715,-0.09827,,,,,0.03316060606,-0.1201638542
152.835,0.50589,-0.10106,,,,,0.03066,-0.1235754463
153.335,0.46381,-0.10509,,,,,0.02810969697,-0.1285033015
153.835,0.42231,-0.10826,,,,,0.02559454545,-0.1323795549
154.335,0.38088,-0.11275,,,,,0.02308363636,-0.1378698948
154.835,0.33877,-0.11498,,,,,0.02053151515,-0.1405967229
155.335,0.29731,-0.11754,,,,,0.01801878788,-0.1437270726
155.835,0.25584,-0.11744,,,,,0.01550545455,-0.1436047933
156.335,0.21384,-0.118,,,,,0.01296,-0.1442895573
156.835,0.17239,-0.11727,,,,,0.01044787879,-0.1433969186
157.335,0.13059,-0.11782,,,,,0.007914545455,-0.1440694546
157.835,0.08897,-0.11821,,,,,0.005392121212,-0.1445463438
158.335,0.04748,-0.11784,,,,,0.002877575758,-0.1440939105
158.835,0.00545,-0.11738,,,,,0.0003303030303,-0.1435314258
159.106,0.01134,-0.11735,,,,,0.0006872727273,-0.143494742
159.606,0.05347,-0.1152,,,,,0.003240606061,-0.1408657373
160.106,0.09518,-0.11362,,,,,0.005768484848,-0.1389337246
160.606,0.13653,-0.10548,,,,,0.008274545455,-0.1289801908
161.106,0.1786,-0.09444,,,,,0.01082424242,-0.1154805576
161.606,0.22008,-0.08012,,,,,0.01333818182,-0.09797016385
162.106,0.26145,-0.07258,,,,,0.01584545455,-0.0887503057
162.606,0.30361,-0.05844,,,,,0.01840060606,-0.07146001467
163.106,0.34484,-0.04962,,,,,0.02089939394,-0.06067498166
163.606,0.38683,-0.0412,,,,,0.02344424242,-0.05037906579
164.106,0.42861,-0.0313,,,,,0.02597636364,-0.03827341648
164.606,0.46981,-0.02536,,,,,0.02847333333,-0.0310100269
165.106,0.51192,-0.0171,,,,,0.03102545455,-0.02090975789
165.606,0.55359,-0.00917,,,,,0.03355090909,-0.01121301052
166.106,0.59476,-0.00298,,,,,0.03604606061,-0.003643922719
166.606,0.6369,0.00379,,,,,0.0386,0.004634384935
167.106,0.67851,0.01078,,,,,0.04112181818,0.01318170702
167.606,0.72004,0.015,,,,,0.04363878788,0.01834189288
168.106,0.76193,0.02342,,,,,0.04617757576,0.02863780876
168.606,0.80321,0.02977,,,,,0.04867939394,0.03640254341
169.106,0.84513,0.03603,,,,,0.05122,0.04405722671
169.606,0.88684,0.04196,,,,,0.05374787879,0.05130838836
170.106,0.92818,0.04804,,,,,0.05625333333,0.05874296894
170.606,0.97031,0.0528,,,,,0.05880666667,0.06456346295
171.106,1.0118,0.05832,,,,,0.06132121212,0.07131327953
171.606,1.05326,0.06491,,,,,0.06383393939,0.07937148447
172.106,1.09523,0.07089,,,,,0.06637757576,0.08668378577
172.606,1.13655,0.07567,,,,,0.06888181818,0.09252873563
173.106,1.17851,0.08213,,,,,0.07142484848,0.1004279775
173.606,1.22025,0.08681,,,,,0.07395454545,0.1061506481
174.106,1.26155,0.0908,,,,,0.07645757576,0.1110295916
174.606,1.3036,0.09505,,,,,0.07900606061,0.1162264612
175.106,1.34521,0.1,,,,,0.08152787879,0.1222792859
175.606,1.38646,0.10461,,,,,0.08402787879,0.127916361
176.106,1.4286,0.11085,,,,,0.08658181818,0.1355465884
176.606,1.47002,0.11621,,,,,0.08909212121,0.1421007581
177.106,1.51175,0.11999,,,,,0.09162121212,0.1467229151
177.606,1.55355,0.12568,,,,,0.09415454545,0.1536806065
178.106,1.59487,0.12952,,,,,0.09665878788,0.1583761311
178.606,1.63687,0.13362,,,,,0.09920424242,0.1633895818
178.871,1.64785,0.12663,,,,,0.09986969697,0.1548422597
179.371,1.60571,0.09726,,,,,0.09731575758,0.1189288335
179.871,1.56403,0.07863,,,,,0.09478969697,0.09614820249
180.371,1.5221,0.06579,,,,,0.09224848485,0.08044754219
180.871,1.48065,0.05367,,,,,0.08973636364,0.06562729274
181.371,1.43887,0.0405,,,,,0.08720424242,0.04952311079
181.871,1.39722,0.03045,,,,,0.08468,0.03723404255
182.371,1.3558,0.02358,,,,,0.08216969697,0.02883345561
182.871,1.3137,0.01531,,,,,0.07961818182,0.01872095867
183.371,1.27235,0.00452,,,,,0.07711212121,0.005527023722
183.871,1.23087,-0.00334,,,,,0.07459818182,-0.004084128149
184.371,1.18864,-0.01053,,,,,0.07203878788,-0.0128760088
184.871,1.1473,-0.01753,,,,,0.06953333333,-0.02143555882
185.371,1.10574,-0.02618,,,,,0.06701454545,-0.03201271705
185.871,1.06381,-0.03064,,,,,0.06447333333,-0.0374663732
186.371,1.02231,-0.03732,,,,,0.06195818182,-0.04563462949
186.871,0.98044,-0.0435,,,,,0.05942060606,-0.05319148936
187.371,0.93897,-0.05098,,,,,0.05690727273,-0.06233797995
187.871,0.89748,-0.05633,,,,,0.05439272727,-0.06887992174
188.371,0.85537,-0.06128,,,,,0.05184060606,-0.07493274639
188.871,0.81399,-0.06716,,,,,0.04933272727,-0.0821227684
189.371,0.77231,-0.07347,,,,,0.04680666667,-0.08983859134
189.871,0.7305,-0.07897,,,,,0.04427272727,-0.09656395207
190.371,0.68903,-0.08455,,,,,0.04175939394,-0.1033871362
190.871,0.64715,-0.08693,,,,,0.03922121212,-0.1062973832
191.371,0.60562,-0.09392,,,,,0.03670424242,-0.1148447053
191.871,0.56424,-0.09651,,,,,0.03419636364,-0.1180117388
192.371,0.52198,-0.10175,,,,,0.03163515152,-0.1244191734
192.871,0.48068,-0.10751,,,,,0.02913212121,-0.1314624603
193.371,0.43907,-0.1103,,,,,0.02661030303,-0.1348740523
193.871,0.39714,-0.11299,,,,,0.02406909091,-0.1381633651
194.371,0.35562,-0.11476,,,,,0.02155272727,-0.1403277085
194.871,0.31394,-0.11674,,,,,0.01902666667,-0.1427488383
195.371,0.27224,-0.11783,,,,,0.01649939394,-0.1440816826
195.871,0.2307,-0.11794,,,,,0.01398181818,-0.1442161898
196.371,0.18872,-0.11873,,,,,0.01143757576,-0.1451821961
196.871,0.14736,-0.11878,,,,,0.008930909091,-0.1452433358
197.371,0.1058,-0.11839,,,,,0.006412121212,-0.1447664466
197.871,0.0636,-0.11602,,,,,0.003854545455,-0.1418684275
198.371,0.02241,-0.11799,,,,,0.001358181818,-0.1442773294
198.642,-0.00022,-0.11777,,,,,-0.00001333333333,-0.144008315
199.142,0.03678,-0.11852,,,,,0.002229090909,-0.1449254096
199.642,0.07805,-0.11519,,,,,0.00473030303,-0.1408535094
200.142,0.12019,-0.11355,,,,,0.007284242424,-0.1388481291
200.642,0.16168,-0.10447,,,,,0.009798787879,-0.12774517
201.142,0.20317,-0.09027,,,,,0.01231333333,-0.1103815114
201.642,0.24527,-0.07912,,,,,0.01486484848,-0.096747371
202.142,0.28646,-0.06848,,,,,0.01736121212,-0.08373685498
202.642,0.32847,-0.05953,,,,,0.01990727273,-0.07279285889
203.142,0.37014,-0.05199,,,,,0.02243272727,-0.06357300073
203.642,0.4114,-0.04212,,,,,0.02493333333,-0.05150403522
204.142,0.4536,-0.0326,,,,,0.02749090909,-0.0398630472
204.642,0.49514,-0.02791,,,,,0.03000848485,-0.03412814869
205.142,0.53657,-0.01847,,,,,0.03251939394,-0.0225849841
205.642,0.57848,-0.01114,,,,,0.03505939394,-0.01362191245
206.142,0.61978,-0.00406,,,,,0.03756242424,-0.004964539007
206.642,0.66176,0.00204,,,,,0.04010666667,0.002494497432
207.142,0.70346,0.00923,,,,,0.04263393939,0.01128637809
207.642,0.74467,0.01489,,,,,0.04513151515,0.01820738567
208.142,0.78694,0.02247,,,,,0.04769333333,0.02747615554
208.642,0.82838,0.02817,,,,,0.05020484848,0.03444607483
209.142,0.86979,0.03371,,,,,0.05271454545,0.04122034727
209.642,0.91187,0.0393,,,,,0.05526484848,0.04805575935
210.142,0.95329,0.04744,,,,,0.05777515152,0.05800929323
210.642,0.99503,0.05228,,,,,0.06030484848,0.06392761066
211.142,1.03694,0.05565,,,,,0.06284484848,0.0680484226
211.642,1.07812,0.06217,,,,,0.06534060606,0.07602103204
212.142,1.12011,0.06702,,,,,0.06788545455,0.0819515774
212.642,1.1618,0.07163,,,,,0.07041212121,0.08758865248
213.142,1.2031,0.07736,,,,,0.07291515152,0.09459525556
213.642,1.24525,0.08548,,,,,0.07546969697,0.1045243336
214.142,1.28666,0.08956,,,,,0.07797939394,0.1095133284
214.642,1.32827,0.09402,,,,,0.08050121212,0.1149669846
215.142,1.37005,0.09875,,,,,0.08303333333,0.1207507948
215.642,1.41143,0.10278,,,,,0.08554121212,0.12567865
216.142,1.45343,0.10734,,,,,0.08808666667,0.1312545855
216.642,1.49515,0.11214,,,,,0.09061515152,0.1371239912
217.142,1.53641,0.11897,,,,,0.09311575758,0.1454756664
217.642,1.57857,0.12168,,,,,0.09567090909,0.1487894351
218.142,1.62008,0.12472,,,,,0.09818666667,0.1525067254
218.507,1.65012,0.12994,,,,,0.1000072727,0.1588897041
218.908,1.62211,0.10051,,,,,0.09830969697,0.1229029102
219.408,1.58033,0.08015,,,,,0.09577757576,0.09800684764
219.908,1.53888,0.06599,,,,,0.09326545455,0.08069210076
220.408,1.49692,0.05318,,,,,0.09072242424,0.06502812424
220.908,1.45543,0.04206,,,,,0.08820787879,0.05143066764
221.408,1.41395,0.03248,,,,,0.08569393939,0.03971631206
221.908,1.37179,0.02349,,,,,0.08313878788,0.02872340426
222.408,1.33045,0.01297,,,,,0.08063333333,0.01585962338
222.908,1.28892,0.00551,,,,,0.07811636364,0.006737588652
223.408,1.2468,-0.0027,,,,,0.07556363636,-0.003301540719
223.908,1.20547,-0.0093,,,,,0.07305878788,-0.01137197359
224.408,1.16366,-0.01632,,,,,0.07052484848,-0.01995597946
224.908,1.12214,-0.02487,,,,,0.06800848485,-0.0304108584
225.408,1.08049,-0.03299,,,,,0.06548424242,-0.04033993641
225.908,1.03853,-0.03891,,,,,0.06294121212,-0.04757887014
226.408,0.99713,-0.04504,,,,,0.06043212121,-0.05507459036
226.908,0.95553,-0.05151,,,,,0.05791090909,-0.06298606016
227.408,0.91349,-0.0573,,,,,0.0553630303,-0.07006603081
227.908,0.8722,-0.06308,,,,,0.05286060606,-0.07713377354
228.408,0.83038,-0.07014,,,,,0.05032606061,-0.08576669112
228.908,0.78863,-0.07396,,,,,0.04779575758,-0.09043775984
229.408,0.7473,-0.07861,,,,,0.04529090909,-0.09612374664
229.908,0.70515,-0.08333,,,,,0.04273636364,-0.1018953289
230.408,0.6637,-0.08982,,,,,0.04022424242,-0.1098312546
230.908,0.62226,-0.09391,,,,,0.03771272727,-0.1148324774
231.408,0.58013,-0.09836,,,,,0.03515939394,-0.1202739056
231.908,0.53869,-0.10388,,,,,0.03264787879,-0.1270237222
232.408,0.49715,-0.10675,,,,,0.03013030303,-0.1305331377
232.908,0.45526,-0.11224,,,,,0.02759151515,-0.1372462705
233.408,0.41381,-0.11409,,,,,0.02507939394,-0.1395084373
233.908,0.37195,-0.1165,,,,,0.02254242424,-0.1424553681
234.408,0.33042,-0.11819,,,,,0.02002545455,-0.144521888
234.908,0.28889,-0.11743,,,,,0.01750848485,-0.1435925654
235.408,0.24682,-0.11719,,,,,0.01495878788,-0.1432990951
235.908,0.20552,-0.11756,,,,,0.01245575758,-0.1437515285
236.408,0.16379,-0.118,,,,,0.009926666667,-0.1442895573
236.908,0.1219,-0.12,,,,,0.007387878788,-0.1467351431
237.408,0.08055,-0.11928,,,,,0.004881818182,-0.1458547322
237.908,0.03862,-0.11856,,,,,0.002340606061,-0.1449743213
238.374,-0.00003,-0.12016,,,,,-0.000001818181818,-0.1469307899
238.676,0.01977,-0.11776,,,,,0.001198181818,-0.1439960871
239.176,0.06196,-0.1174,,,,,0.003755151515,-0.1435558816
239.676,0.10314,-0.11652,,,,,0.006250909091,-0.1424798239
240.176,0.14507,-0.11181,,,,,0.008792121212,-0.1367204696
240.676,0.18686,-0.1006,,,,,0.01132484848,-0.1230129616
241.176,0.22805,-0.08681,,,,,0.01382121212,-0.1061506481
241.676,0.27026,-0.07782,,,,,0.01637939394,-0.09515774028
242.176,0.31185,-0.06783,,,,,0.0189,-0.08294203962
242.676,0.35313,-0.05899,,,,,0.02140181818,-0.07213255075
243.176,0.39514,-0.05003,,,,,0.02394787879,-0.06117632673
243.676,0.43656,-0.0403,,,,,0.02645818182,-0.04927855221
244.176,0.47841,-0.03288,,,,,0.02899454545,-0.0402054292
244.676,0.52019,-0.02333,,,,,0.03152666667,-0.0285277574
245.176,0.56143,-0.0195,,,,,0.03402606061,-0.02384446075
245.676,0.60357,-0.01034,,,,,0.03658,-0.01264367816
246.176,0.64516,-0.00474,,,,,0.03910060606,-0.005796038151
246.676,0.68634,0.00087,,,,,0.04159636364,0.001063829787
247.176,0.72861,0.00824,,,,,0.04415818182,0.01007581316
247.676,0.77011,0.01464,,,,,0.04667333333,0.01790168745
248.176,0.81168,0.02024,,,,,0.04919272727,0.02474932746
248.676,0.85351,0.0286,,,,,0.05172787879,0.03497187576
249.176,0.89488,0.03404,,,,,0.05423515152,0.04162386892
249.676,0.93683,0.03913,,,,,0.05677757576,0.04784788457
250.176,0.9785,0.04692,,,,,0.0593030303,0.05737344094
250.676,1.01979,0.04722,,,,,0.06180545455,0.0577402788
251.176,1.06191,0.05575,,,,,0.06435818182,0.06817070188
251.676,1.10344,0.05877,,,,,0.06687515152,0.07186353632
252.176,1.14489,0.06751,,,,,0.06938727273,0.0825507459
252.676,1.18686,0.07245,,,,,0.07193090909,0.08859134263
253.176,1.22806,0.07716,,,,,0.07442787879,0.09435069699
253.676,1.27019,0.08157,,,,,0.07698121212,0.0997432135
254.176,1.3118,0.08823,,,,,0.0795030303,0.1078870139
254.676,1.35321,0.09019,,,,,0.08201272727,0.1102836879
255.176,1.39521,0.09738,,,,,0.08455818182,0.1190755686
255.676,1.43681,0.09987,,,,,0.08707939394,0.1221203228
256.176,1.47812,0.10604,,,,,0.0895830303,0.1296649548
256.676,1.5203,0.11101,,,,,0.09213939394,0.1357422353
257.176,1.56176,0.11441,,,,,0.09465212121,0.139899731
257.676,1.60333,0.1196,,,,,0.09717151515,0.1462460259
258.176,1.64516,0.12318,,,,,0.09970666667,0.1506236244
258.441,1.639,0.10804,,,,,0.09933333333,0.1321105405
258.941,1.59723,0.08302,,,,,0.09680181818,0.1015162631
259.441,1.55502,0.06834,,,,,0.09424363636,0.08356566398
259.941,1.51369,0.05426,,,,,0.09173878788,0.06634874052
260.441,1.47217,0.04329,,,,,0.08922242424,0.05293470286
260.941,1.43004,0.03128,,,,,0.08666909091,0.03824896063
261.441,1.38866,0.02033,,,,,0.08416121212,0.02485937882
261.941,1.34705,0.01255,,,,,0.08163939394,0.01534605038
262.441,1.30519,0.0059,,,,,0.07910242424,0.007214477867
262.941,1.26374,-0.0045,,,,,0.07659030303,-0.005502567865
263.441,1.22178,-0.01082,,,,,0.07404727273,-0.01323061873
263.941,1.1804,-0.0178,,,,,0.07153939394,-0.02176571289
264.441,1.13884,-0.02424,,,,,0.06902060606,-0.0296404989
264.941,1.09678,-0.03134,,,,,0.06647151515,-0.0383223282
265.441,1.0554,-0.03844,,,,,0.06396363636,-0.0470041575
265.941,1.01367,-0.04607,,,,,0.06143454545,-0.05633406701
266.441,0.9719,-0.05115,,,,,0.0589030303,-0.06254585473
266.941,0.93045,-0.05629,,,,,0.05639090909,-0.06883101003
267.441,0.88848,-0.06126,,,,,0.05384727273,-0.07490829054
267.941,0.84698,-0.06821,,,,,0.05133212121,-0.0834067009
268.441,0.8056,-0.07289,,,,,0.04882424242,-0.08912937148
268.941,0.76331,-0.07961,,,,,0.04626121212,-0.0973465395
269.441,0.72205,-0.08273,,,,,0.04376060606,-0.1011616532
269.941,0.68042,-0.08802,,,,,0.04123757576,-0.1076302274
270.441,0.63858,-0.09086,,,,,0.03870181818,-0.1111029592
270.941,0.59704,-0.09629,,,,,0.03618424242,-0.1177427244
271.441,0.55526,-0.10109,,,,,0.03365212121,-0.1236121301
271.941,0.51366,-0.10551,,,,,0.03113090909,-0.1290168745
272.441,0.47215,-0.10953,,,,,0.02861515152,-0.1339325018
272.941,0.43008,-0.11371,,,,,0.02606545455,-0.139043776
273.441,0.38878,-0.11594,,,,,0.02356242424,-0.1417706041
273.941,0.34717,-0.1172,,,,,0.02104060606,-0.1433113231
274.441,0.30499,-0.11692,,,,,0.01848424242,-0.1429689411
274.941,0.26381,-0.11666,,,,,0.01598848485,-0.1426510149
275.441,0.22194,-0.11674,,,,,0.01345090909,-0.1427488383
275.941,0.18021,-0.11704,,,,,0.01092181818,-0.1431156762
276.441,0.13878,-0.11695,,,,,0.008410909091,-0.1430056248
276.941,0.09684,-0.11764,,,,,0.005869090909,-0.1438493519
277.441,0.05524,-0.11766,,,,,0.003347878788,-0.1438738078
277.941,0.01386,-0.11805,,,,,0.00084,-0.144350697
278.208,0.00207,-0.11827,,,,,0.0001254545455,-0.1446197114
278.708,0.04472,-0.11807,,,,,0.00271030303,-0.1443751528
279.208,0.0868,-0.11607,,,,,0.005260606061,-0.1419295671
279.708,0.12846,-0.11398,,,,,0.007785454545,-0.1393739301
280.208,0.16977,-0.10624,,,,,0.01028909091,-0.1299095133
280.708,0.21183,-0.09379,,,,,0.01283818182,-0.1146857422
281.208,0.25333,-0.08273,,,,,0.01535333333,-0.1011616532
281.708,0.29505,-0.0735,,,,,0.01788181818,-0.08987527513
282.208,0.33678,-0.06375,,,,,0.02041090909,-0.07795304475
282.708,0.37817,-0.05602,,,,,0.02291939394,-0.06850085596
283.208,0.42018,-0.04757,,,,,0.02546545455,-0.0581682563
283.708,0.4617,-0.03998,,,,,0.02798181818,-0.0488872585
284.208,0.50294,-0.03177,,,,,0.03048121212,-0.03884812913
284.708,0.54527,-0.02486,,,,,0.03304666667,-0.03039863047
285.208,0.5867,-0.01789,,,,,0.03555757576,-0.02187576425
285.708,0.62825,-0.01261,,,,,0.03807575758,-0.01541941795
286.208,0.67023,-0.00551,,,,,0.04062,-0.006737588652
286.708,0.71146,0.0007,,,,,0.04311878788,0.0008559550012
287.208,0.75339,0.00627,,,,,0.04566,0.007666911225
287.708,0.79522,0.01338,,,,,0.04819515152,0.01636096845
288.208,0.83638,0.02003,,,,,0.05068969697,0.02449254096
288.708,0.87849,0.02736,,,,,0.05324181818,0.03345561262
289.208,0.92013,0.03042,,,,,0.05576545455,0.03719735877
289.708,0.96155,0.03609,,,,,0.05827575758,0.04413059428
290.208,1.00342,0.04104,,,,,0.06081333333,0.05018341893
290.708,1.04487,0.04647,,,,,0.06332545455,0.05682318415
291.208,1.0868,0.05253,,,,,0.06586666667,0.06423330888
291.708,1.12848,0.05926,,,,,0.06839272727,0.07246270482
292.208,1.16978,0.06629,,,,,0.07089575758,0.08105893862
292.708,1.2119,0.0711,,,,,0.07344848485,0.08694057227
293.208,1.2534,0.07435,,,,,0.07596363636,0.09091464906
293.708,1.29474,0.08006,,,,,0.07846909091,0.09789679628
294.208,1.33686,0.0856,,,,,0.08102181818,0.1046710687
294.708,1.37837,0.08951,,,,,0.08353757576,0.1094521888
295.208,1.41993,0.094,,,,,0.08605636364,0.1149425287
295.708,1.46178,0.09842,,,,,0.08859272727,0.1203472732
296.208,1.50311,0.10425,,,,,0.09109757576,0.1274761555
296.708,1.54514,0.10876,,,,,0.09364484848,0.1329909513
297.208,1.58674,0.11282,,,,,0.09616606061,0.1379554903
297.708,1.62816,0.11892,,,,,0.09867636364,0.1454145268
297.974,1.6502,0.11856,,,,,0.1000121212,0.1449743213
298.474,1.61357,0.08949,,,,,0.09779212121,0.1094277329
298.974,1.57221,0.06926,,,,,0.09528545455,0.08469063341
299.474,1.53065,0.05524,,,,,0.09276666667,0.06754707753
299.974,1.48877,0.04412,,,,,0.09022848485,0.05394962093
300.474,1.44738,0.03395,,,,,0.08772,0.04151381756
300.974,1.4054,0.02575,,,,,0.08517575758,0.03148691612
301.474,1.36396,0.01279,,,,,0.08266424242,0.01563952067
301.974,1.32237,0.00603,,,,,0.08014363636,0.007373440939
302.474,1.28029,-0.00101,,,,,0.07759333333,-0.001235020787
302.974,1.23896,-0.00986,,,,,0.07508848485,-0.01205673759
303.474,1.19726,-0.01606,,,,,0.07256121212,-0.01963805331
303.974,1.15541,-0.02318,,,,,0.07002484848,-0.02834433847
304.474,1.11392,-0.03028,,,,,0.06751030303,-0.03702616777
304.974,1.07204,-0.03585,,,,,0.06497212121,-0.04383712399
305.474,1.03051,-0.04225,,,,,0.06245515152,-0.05166299829
305.974,0.9891,-0.04903,,,,,0.05994545455,-0.05995353387
306.474,0.94689,-0.05388,,,,,0.05738727273,-0.06588407924
306.974,0.90557,-0.06095,,,,,0.0548830303,-0.07452922475
307.474,0.86407,-0.07042,,,,,0.05236787879,-0.08610907312
307.974,0.82201,-0.0724,,,,,0.04981878788,-0.08853020298
308.474,0.78057,-0.07739,,,,,0.04730727273,-0.09463193935
308.974,0.73886,-0.08342,,,,,0.04477939394,-0.1020053803
309.474,0.69718,-0.0849,,,,,0.04225333333,-0.1038151137
309.974,0.65573,-0.09419,,,,,0.03974121212,-0.1151748594
310.474,0.6137,-0.09617,,,,,0.03719393939,-0.1175959892
310.974,0.57225,-0.10279,,,,,0.03468181818,-0.125690878
311.474,0.53065,-0.10643,,,,,0.03216060606,-0.130141844
311.974,0.48865,-0.11072,,,,,0.02961515152,-0.1353876253
312.474,0.44728,-0.11305,,,,,0.02710787879,-0.1382367327
312.974,0.40549,-0.11577,,,,,0.02457515152,-0.1415627293
313.474,0.36381,-0.11879,,,,,0.02204909091,-0.1452555637
313.974,0.32241,-0.1176,,,,,0.01954,-0.1438004402
314.474,0.28032,-0.11822,,,,,0.01698909091,-0.1445585718
314.974,0.2389,-0.11808,,,,,0.01447878788,-0.1443873808
315.474,0.19742,-0.1176,,,,,0.01196484848,-0.1438004402
315.974,0.15536,-0.11739,,,,,0.009415757576,-0.1435436537
316.474,0.11394,-0.11861,,,,,0.006905454545,-0.145035461
316.974,0.07235,-0.11998,,,,,0.004384848485,-0.1467106872
317.474,0.03045,-0.11768,,,,,0.001845454545,-0.1438982636
317.843,-0.0001,-0.11992,,,,,-0.000006060606061,-0.1466373196
318.244,0.02848,-0.11765,,,,,0.001726060606,-0.1438615798
318.744,0.06995,-0.11921,,,,,0.004239393939,-0.1457691367
319.244,0.11149,-0.12014,,,,,0.006756969697,-0.1469063341
319.744,0.15339,-0.11268,,,,,0.009296363636,-0.1377842993
320.244,0.19473,-0.10513,,,,,0.01180181818,-0.1285522133
320.744,0.23674,-0.09118,,,,,0.01434787879,-0.1114942529
321.244,0.27837,-0.0819,,,,,0.01687090909,-0.1001467351
321.744,0.31959,-0.07123,,,,,0.01936909091,-0.08709953534
322.244,0.36187,-0.06084,,,,,0.02193151515,-0.07439471753
322.744,0.40335,-0.05154,,,,,0.02444545455,-0.06302274395
323.244,0.44468,-0.04396,,,,,0.02695030303,-0.05375397408
323.744,0.48684,-0.03734,,,,,0.02950545455,-0.04565908535
324.244,0.52803,-0.02926,,,,,0.03200181818,-0.03577891905
324.744,0.57001,-0.02533,,,,,0.03454606061,-0.03097334312
325.244,0.61176,-0.01687,,,,,0.03707636364,-0.02062851553
325.744,0.65303,-0.01164,,,,,0.03957757576,-0.01423330888
326.244,0.6951,-0.00419,,,,,0.04212727273,-0.005123502079
326.744,0.73674,0.00234,,,,,0.04465090909,0.00286133529
327.244,0.77796,0.00848,,,,,0.04714909091,0.01036928344
327.744,0.82012,0.01517,,,,,0.04970424242,0.01854976767
328.244,0.86155,0.02046,,,,,0.05221515152,0.02501834189
328.744,0.9033,0.0276,,,,,0.05474545455,0.03374908291
329.244,0.94508,0.03223,,,,,0.05727757576,0.03941061384
329.744,0.98628,0.03528,,,,,0.05977454545,0.04314013206
330.244,1.02849,0.04221,,,,,0.06233272727,0.05161408657
330.744,1.06992,0.04699,,,,,0.06484363636,0.05745903644
331.244,1.11137,0.0515,,,,,0.06735575758,0.06297383223
331.744,1.15351,0.05804,,,,,0.06990969697,0.07097089753
332.244,1.19495,0.06364,,,,,0.07242121212,0.07781853754
332.744,1.23645,0.06777,,,,,0.07493636364,0.08286867205
333.244,1.27851,0.07465,,,,,0.07748545455,0.09128148692
333.744,1.31969,0.0774,,,,,0.07998121212,0.09464416728
334.244,1.3617,0.07923,,,,,0.08252727273,0.09688187821
334.744,1.40341,0.08685,,,,,0.08505515152,0.1061995598
335.244,1.44472,0.09278,,,,,0.08755878788,0.1134507214
335.744,1.48673,0.09736,,,,,0.09010484848,0.1190511127
336.244,1.52832,0.10243,,,,,0.09262545455,0.1252506725
336.744,1.56978,0.10753,,,,,0.09513818182,0.1314869161
337.244,1.61166,0.1121,,,,,0.09767636364,0.1370750795
337.709,1.65005,0.11608,,,,,0.1000030303,0.1419417951
338.011,1.63102,0.09277,,,,,0.09884969697,0.1134384935
338.511,1.58906,0.07121,,,,,0.09630666667,0.08707507948
339.011,1.54751,0.0579,,,,,0.09378848485,0.07079970653
339.511,1.50607,0.04253,,,,,0.0912769697,0.05200538029
340.011,1.46392,0.03374,,,,,0.08872242424,0.04125703106
340.511,1.42261,0.02409,,,,,0.08621878788,0.02945707997
341.011,1.38089,0.01558,,,,,0.08369030303,0.01905111274
341.511,1.33911,0.00602,,,,,0.08115818182,0.007361213011
342.011,1.29764,-0.00051,,,,,0.07864484848,-0.000623624358
342.511,1.25569,-0.01022,,,,,0.07610242424,-0.01249694302
343.011,1.21423,-0.01687,,,,,0.07358969697,-0.02062851553
343.511,1.17262,-0.02326,,,,,0.07106787879,-0.0284421619
344.011,1.13054,-0.02889,,,,,0.06851757576,-0.03532648569
344.511,1.0892,-0.03578,,,,,0.06601212121,-0.04375152849
345.011,1.04776,-0.04215,,,,,0.06350060606,-0.051540719
345.511,1.00562,-0.04846,,,,,0.06094666667,-0.05925654194
346.011,0.96428,-0.05402,,,,,0.05844121212,-0.06605527024
346.511,0.92247,-0.05903,,,,,0.05590727273,-0.07218146246
347.011,0.88096,-0.06547,,,,,0.05339151515,-0.08005624847
347.511,0.83929,-0.06909,,,,,0.05086606061,-0.08448275862
348.011,0.79728,-0.07605,,,,,0.04832,-0.09299339692
348.511,0.75591,-0.08036,,,,,0.04581272727,-0.09826363414
349.011,0.71433,-0.08584,,,,,0.04329272727,-0.104964539
349.511,0.67226,-0.08976,,,,,0.0407430303,-0.109757887
350.011,0.63094,-0.09515,,,,,0.03823878788,-0.1163487405
350.511,0.58917,-0.10009,,,,,0.03570727273,-0.1223893372
351.011,0.54737,-0.1044,,,,,0.03317393939,-0.1276595745
351.511,0.50608,-0.10956,,,,,0.03067151515,-0.1339691856
352.011,0.46394,-0.11208,,,,,0.02811757576,-0.1370506236
352.511,0.4225,-0.11572,,,,,0.02560606061,-0.1415015896
353.011,0.38106,-0.11628,,,,,0.02309454545,-0.1421863536
353.511,0.33896,-0.11723,,,,,0.0205430303,-0.1433480068
354.011,0.29749,-0.11612,,,,,0.01802969697,-0.1419907068
354.511,0.25598,-0.11992,,,,,0.01551393939,-0.1466373196
355.011,0.21406,-0.11838,,,,,0.01297333333,-0.1447542186
355.511,0.17257,-0.11863,,,,,0.01045878788,-0.1450599169
356.011,0.13074,-0.11918,,,,,0.007923636364,-0.1457324529
356.511,0.08917,-0.12003,,,,,0.005404242424,-0.1467718269
357.011,0.04764,-0.11921,,,,,0.002887272727,-0.1457691367
357.511,0.00562,-0.11858,,,,,0.0003406060606,-0.1449987772
357.785,0.01107,-0.11961,,,,,0.0006709090909,-0.1462582539
358.285,0.0533,-0.11634,,,,,0.00323030303,-0.1422597212
358.785,0.09497,-0.11645,,,,,0.005755757576,-0.1423942284
359.285,0.13629,-0.11405,,,,,0.00826,-0.1394595256
359.785,0.17838,-0.10981,,,,,0.01081090909,-0.1342748838
360.285,0.21984,-0.09809,,,,,0.01332363636,-0.1199437515
360.785,0.26129,-0.08688,,,,,0.01583575758,-0.1062362436
361.285,0.30339,-0.07658,,,,,0.01838727273,-0.09364147713
361.785,0.34459,-0.06709,,,,,0.02088424242,-0.0820371729
362.285,0.38657,-0.05924,,,,,0.02342848485,-0.07243824896
362.785,0.42845,-0.05003,,,,,0.02596666667,-0.06117632673
363.285,0.46961,-0.04359,,,,,0.02846121212,-0.05330154072
363.785,0.51175,-0.03613,,,,,0.03101515152,-0.04417950599
364.285,0.55342,-0.02779,,,,,0.03354060606,-0.03398141355
364.785,0.59457,-0.02201,,,,,0.03603454545,-0.02691367082
365.285,0.63669,-0.01522,,,,,0.03858727273,-0.01861090731
365.785,0.6783,-0.00868,,,,,0.04110909091,-0.01061384202
366.285,0.71986,-0.0036,,,,,0.04362787879,-0.004402054292
366.785,0.76167,0.00586,,,,,0.04616181818,0.007165566153
367.285,0.80299,0.00981,,,,,0.04866606061,0.01199559795
367.785,0.84496,0.01422,,,,,0.05120969697,0.01738811445
368.285,0.88656,0.02166,,,,,0.05373090909,0.02648569332
368.785,0.92788,0.02607,,,,,0.05623515152,0.03187820983
369.285,0.97013,0.03086,,,,,0.05879575758,0.03773538763
369.785,1.0116,0.03662,,,,,0.06130909091,0.04477867449
370.285,1.05307,0.04212,,,,,0.06382242424,0.05150403522
370.785,1.09504,0.04883,,,,,0.06636606061,0.0597089753
371.285,1.13645,0.05407,,,,,0.06887575758,0.06611640988
371.785,1.17833,0.05689,,,,,0.07141393939,0.06956468574
372.285,1.2201,0.06231,,,,,0.07394545455,0.07619222304
372.785,1.26132,0.06727,,,,,0.07644363636,0.08225727562
373.285,1.3034,0.07118,,,,,0.07899393939,0.0870383957
373.785,1.34498,0.07678,,,,,0.08151393939,0.09388603571
374.285,1.38632,0.08205,,,,,0.08401939394,0.1003301541
374.785,1.42835,0.0862,,,,,0.08656666667,0.1054047444
375.285,1.4698,0.09214,,,,,0.08907878788,0.112668134
375.785,1.51158,0.09624,,,,,0.09161090909,0.1176815847
376.285,1.55333,0.10155,,,,,0.09414121212,0.1241746148
376.785,1.59465,0.1054,,,,,0.09664545455,0.1288823673
377.285,1.63671,0.10976,,,,,0.09919454545,0.1342137442
377.553,1.64798,0.10213,,,,,0.09987757576,0.1248838347
378.053,1.60588,0.07707,,,,,0.09732606061,0.09424064563
378.553,1.56421,0.05897,,,,,0.09480060606,0.07210809489
379.053,1.52222,0.04727,,,,,0.09225575758,0.05780141844
379.553,1.48086,0.03301,,,,,0.08974909091,0.04036439227
380.053,1.43897,0.02613,,,,,0.08721030303,0.0319515774
380.553,1.39745,0.01854,,,,,0.08469393939,0.0226705796
381.053,1.35602,0.01012,,,,,0.0821830303,0.01237466373
381.553,1.31386,0.00223,,,,,0.07962787879,0.002726828075
382.053,1.27252,-0.00584,,,,,0.07712242424,-0.007141110296
382.553,1.23095,-0.01541,,,,,0.0746030303,-0.01884323796
383.053,1.18889,-0.02044,,,,,0.07205393939,-0.02499388604
383.553,1.14749,-0.02844,,,,,0.06954484848,-0.03477622891
384.053,1.10589,-0.03338,,,,,0.06702363636,-0.04081682563
384.553,1.06399,-0.04047,,,,,0.06448424242,-0.049486427
385.053,1.02253,-0.04635,,,,,0.06197151515,-0.05667644901
385.553,0.98058,-0.05313,,,,,0.05942909091,-0.06496698459
386.053,0.93917,-0.05864,,,,,0.05691939394,-0.07170457325
386.553,0.89764,-0.06411,,,,,0.05440242424,-0.07839325018
387.053,0.85555,-0.06928,,,,,0.05185151515,-0.08471508926
387.553,0.81417,-0.07569,,,,,0.04934363636,-0.09255319149
388.053,0.77245,-0.08054,,,,,0.04681515152,-0.09848373685
388.553,0.73071,-0.08564,,,,,0.04428545455,-0.1047199804
389.053,0.68923,-0.09079,,,,,0.04177151515,-0.1110173637
389.553,0.64731,-0.09555,,,,,0.03923090909,-0.1168378577
390.053,0.60579,-0.10077,,,,,0.03671454545,-0.1232208364
390.553,0.56444,-0.10482,,,,,0.03420848485,-0.1281731475
391.053,0.52217,-0.10849,,,,,0.03164666667,-0.1326607973
391.553,0.48088,-0.11296,,,,,0.02914424242,-0.1381266813
392.053,0.43922,-0.11551,,,,,0.02661939394,-0.1412448031
392.553,0.39734,-0.11643,,,,,0.02408121212,-0.1423697726
393.053,0.35579,-0.11807,,,,,0.0215630303,-0.1443751528
393.553,0.31411,-0.11875,,,,,0.0190369697,-0.145206652
394.053,0.27244,-0.11828,,,,,0.01651151515,-0.1446319393
394.553,0.23089,-0.11929,,,,,0.01399333333,-0.1458669601
395.053,0.18888,-0.11741,,,,,0.01144727273,-0.1435681096
395.553,0.14754,-0.11789,,,,,0.008941818182,-0.1441550501
396.053,0.10597,-0.11902,,,,,0.006422424242,-0.1455368061
396.553,0.0638,-0.1195,,,,,0.003866666667,-0.1461237466
397.053,0.02258,-0.11961,,,,,0.001368484848,-0.1462582539
397.324,-0.00003,-0.1169,,,,,-0.000001818181818,-0.1429444852