File: mechanical/hysteresis/data/pristine_conductive_2.csv
Time,Extension,Load,Length,Width,Thickness,CS Area,Strain,Stress
(s),(mm),(N),(mm),(mm),(mm),(mm^2),(mm/mm),(MPa)
0,0,-0.02478,16.5,2.82,0.32,0.9024,0,-0.02746010638
0.5,0.0394,0.03388,,,,,0.002387878788,0.03754432624
1,0.08105,0.06513,,,,,0.004912121212,0.07217420213
1.5,0.12232,0.08222,,,,,0.007413333333,0.09111258865
2,0.16443,0.09905,,,,,0.009965454545,0.1097628546
2.5,0.20587,0.11103,,,,,0.0124769697,0.1230385638
3,0.24756,0.12101,,,,,0.01500363636,0.134097961
3.5,0.28934,0.12889,,,,,0.01753575758,0.1428302305
4,0.33072,0.13565,,,,,0.02004363636,0.1503213652
4.5,0.37272,0.14295,,,,,0.02258909091,0.1584109043
5,0.41438,0.1495,,,,,0.02511393939,0.1656693262
5.5,0.45555,0.1518,,,,,0.02760909091,0.1682180851
6,0.49785,0.15759,,,,,0.03017272727,0.1746343085
6.5,0.53935,0.16344,,,,,0.03268787879,0.1811170213
7,0.58071,0.16383,,,,,0.03519454545,0.1815492021
7.5,0.62279,0.16891,,,,,0.03774484848,0.1871786348
8,0.66412,0.17225,,,,,0.04024969697,0.1908798759
8.5,0.70592,0.1752,,,,,0.0427830303,0.1941489362
9,0.74767,0.17821,,,,,0.04531333333,0.1974844858
9.5,0.78905,0.18074,,,,,0.04782121212,0.2002881206
10,0.83102,0.18479,,,,,0.05036484848,0.2047761525
10.5,0.87271,0.18807,,,,,0.05289151515,0.2084109043
11,0.91407,0.18828,,,,,0.05539818182,0.208643617
11.5,0.95611,0.19232,,,,,0.05794606061,0.2131205674
12,0.99738,0.19362,,,,,0.06044727273,0.2145611702
12.5,1.03927,0.19507,,,,,0.06298606061,0.2161679965
13,1.08102,0.19559,,,,,0.06551636364,0.2167442376
13.5,1.12227,0.19789,,,,,0.06801636364,0.2192929965
14,1.16441,0.20162,,,,,0.07057030303,0.2234264184
14.5,1.20605,0.20305,,,,,0.07309393939,0.2250110816
15,1.24729,0.20294,,,,,0.07559333333,0.2248891844
15.5,1.28932,0.20672,,,,,0.07814060606,0.2290780142
16,1.33094,0.21007,,,,,0.0806630303,0.2327903369
16.5,1.37244,0.21068,,,,,0.08317818182,0.2334663121
17,1.41446,0.21229,,,,,0.08572484848,0.2352504433
17.5,1.45573,0.21439,,,,,0.08822606061,0.2375775709
18,1.49774,0.2166,,,,,0.09077212121,0.2400265957
18.5,1.53934,0.21998,,,,,0.09329333333,0.2437721631
19,1.58061,0.21904,,,,,0.09579454545,0.2427304965
19.5,1.62278,0.2231,,,,,0.09835030303,0.2472296099
19.835,1.65016,0.22222,,,,,0.100009697,0.2462544326
20.236,1.62173,0.12456,,,,,0.09828666667,0.1380319149
20.736,1.58034,0.05231,,,,,0.09577818182,0.05796764184
21.236,1.53881,0.00136,,,,,0.09326121212,0.001507092199
21.736,1.49659,-0.04159,,,,,0.09070242424,-0.04608820922
22.236,1.45531,-0.07653,,,,,0.08820060606,-0.08480718085
22.736,1.41369,-0.1064,,,,,0.08567818182,-0.1179078014
23.236,1.37172,-0.13433,,,,,0.08313454545,-0.1488585993
23.736,1.33032,-0.15834,,,,,0.08062545455,-0.1754654255
24.236,1.28856,-0.17921,,,,,0.07809454545,-0.1985926418
24.736,1.24688,-0.20085,,,,,0.07556848485,-0.2225731383
25.236,1.20546,-0.21776,,,,,0.07305818182,-0.2413120567
25.736,1.16335,-0.23743,,,,,0.07050606061,-0.2631094858
26.236,1.12199,-0.25338,,,,,0.06799939394,-0.2807845745
26.736,1.08038,-0.2686,,,,,0.06547757576,-0.2976507092
27.236,1.03847,-0.28346,,,,,0.06293757576,-0.3141179078
27.736,0.997,-0.298,,,,,0.06042424242,-0.3302304965
28.236,0.95517,-0.30973,,,,,0.05788909091,-0.3432291667
28.736,0.91358,-0.32434,,,,,0.05536848485,-0.3594193262
29.236,0.87209,-0.33529,,,,,0.05285393939,-0.3715536348
29.736,0.83,-0.34705,,,,,0.0503030303,-0.3845855496
30.236,0.78863,-0.35766,,,,,0.04779575758,-0.3963430851
30.736,0.74719,-0.36746,,,,,0.04528424242,-0.4072030142
31.236,0.70495,-0.37956,,,,,0.04272424242,-0.4206117021
31.736,0.66368,-0.38749,,,,,0.0402230303,-0.4293993794
32.236,0.62195,-0.39525,,,,,0.03769393939,-0.4379986702
32.736,0.58026,-0.40638,,,,,0.03516727273,-0.4503324468
33.236,0.53866,-0.41413,,,,,0.03264606061,-0.458920656
33.736,0.49678,-0.41995,,,,,0.03010787879,-0.4653701241
34.236,0.45533,-0.42835,,,,,0.02759575758,-0.4746786348
34.736,0.41376,-0.43658,,,,,0.02507636364,-0.4837987589
35.236,0.37164,-0.44414,,,,,0.02252363636,-0.4921764184
35.736,0.33035,-0.4519,,,,,0.02002121212,-0.5007757092
36.236,0.28866,-0.45719,,,,,0.01749454545,-0.5066378546
36.736,0.24672,-0.46457,,,,,0.01495272727,-0.5148160461
37.236,0.20545,-0.469,,,,,0.01245151515,-0.5197251773
37.736,0.16343,-0.47776,,,,,0.009904848485,-0.5294326241
38.236,0.12187,-0.48497,,,,,0.007386060606,-0.5374224291
38.736,0.08043,-0.48913,,,,,0.004874545455,-0.5420323582
39.236,0.03835,-0.49507,,,,,0.002324242424,-0.548614805
39.702,-0.00005,-0.5008,,,,,-0.00000303030303,-0.554964539
40.004,0.01952,-0.4524,,,,,0.001183030303,-0.5013297872
40.504,0.06181,-0.41128,,,,,0.003746060606,-0.4557624113
41.004,0.10334,-0.3822,,,,,0.006263030303,-0.423537234
41.504,0.14467,-0.36075,,,,,0.008767878788,-0.3997672872
42.004,0.18686,-0.33899,,,,,0.01132484848,-0.3756538121
42.504,0.22816,-0.31993,,,,,0.01382787879,-0.3545323582
43.004,0.27,-0.30309,,,,,0.01636363636,-0.3358710106
43.504,0.31175,-0.28542,,,,,0.01889393939,-0.3162898936
44.004,0.35305,-0.27006,,,,,0.0213969697,-0.299268617
44.504,0.39515,-0.25447,,,,,0.02394848485,-0.2819924645
45.004,0.43679,-0.241,,,,,0.02647212121,-0.2670656028
45.504,0.4781,-0.22305,,,,,0.02897575758,-0.2471742021
46.004,0.52013,-0.21156,,,,,0.0315230303,-0.2344414894
46.504,0.56167,-0.20053,,,,,0.03404060606,-0.2222185284
47.004,0.60326,-0.18487,,,,,0.03656121212,-0.204864805
47.504,0.64507,-0.17235,,,,,0.03909515152,-0.1909906915
48.004,0.68632,-0.16054,,,,,0.04159515152,-0.1779033688
48.504,0.7285,-0.15013,,,,,0.04415151515,-0.1663674645
49.004,0.76999,-0.13429,,,,,0.04666606061,-0.148814273
49.504,0.81138,-0.12526,,,,,0.04917454545,-0.1388076241
50.004,0.85354,-0.11111,,,,,0.05172969697,-0.1231272163
50.504,0.895,-0.09962,,,,,0.05424242424,-0.1103945035
51.004,0.93642,-0.08703,,,,,0.05675272727,-0.09644281915
51.504,0.97856,-0.07274,,,,,0.05930666667,-0.0806072695
52.004,1.0198,-0.06224,,,,,0.06180606061,-0.06897163121
52.504,1.06163,-0.05121,,,,,0.06434121212,-0.05674867021
53.004,1.10347,-0.03845,,,,,0.0668769697,-0.04260859929
53.504,1.14472,-0.02771,,,,,0.0693769697,-0.03070700355
54.004,1.18676,-0.01494,,,,,0.07192484848,-0.01655585106
54.504,1.22833,-0.00442,,,,,0.07444424242,-0.004898049645
55.004,1.26982,0.00644,,,,,0.07695878788,0.007136524823
55.504,1.31168,0.01955,,,,,0.07949575758,0.02166445035
56.004,1.35316,0.02929,,,,,0.08200969697,0.03245789007
56.504,1.39498,0.03833,,,,,0.08454424242,0.04247562057
57.004,1.43679,0.04856,,,,,0.08707818182,0.05381205674
57.504,1.47797,0.05812,,,,,0.08957393939,0.06440602837
58.004,1.52017,0.06563,,,,,0.09213151515,0.07272828014
58.504,1.56174,0.07459,,,,,0.09465090909,0.08265735816
59.004,1.60305,0.08347,,,,,0.09715454545,0.09249778369
59.504,1.64516,0.09357,,,,,0.09970666667,0.1036901596
59.771,1.63897,0.04251,,,,,0.09933151515,0.04710771277
60.271,1.59704,-0.03218,,,,,0.09679030303,-0.03566046099
60.771,1.55499,-0.0847,,,,,0.09424181818,-0.0938608156
61.271,1.51363,-0.12452,,,,,0.09173515152,-0.1379875887
61.771,1.47193,-0.15675,,,,,0.08920787879,-0.1737034574
62.271,1.43015,-0.1847,,,,,0.08667575758,-0.2046764184
62.771,1.38876,-0.20914,,,,,0.08416727273,-0.2317597518
63.271,1.34669,-0.23382,,,,,0.08161757576,-0.2591090426
63.771,1.30535,-0.2548,,,,,0.07911212121,-0.282358156
64.271,1.26367,-0.27156,,,,,0.07658606061,-0.3009308511
64.771,1.22164,-0.29073,,,,,0.07403878788,-0.3221742021
65.271,1.1803,-0.30601,,,,,0.07153333333,-0.3391068262
65.771,1.13854,-0.32143,,,,,0.06900242424,-0.3561945922
66.271,1.09682,-0.33562,,,,,0.06647393939,-0.3719193262
66.771,1.0554,-0.34769,,,,,0.06396363636,-0.3852947695
67.271,1.01335,-0.36027,,,,,0.06141515152,-0.3992353723
67.771,0.97191,-0.37398,,,,,0.05890363636,-0.4144281915
68.271,0.93046,-0.38476,,,,,0.05639151515,-0.4263741135
68.771,0.88824,-0.39575,,,,,0.05383272727,-0.4385527482
69.271,0.8469,-0.40676,,,,,0.05132727273,-0.4507535461
69.771,0.80539,-0.41571,,,,,0.04881151515,-0.4606715426
70.271,0.7634,-0.42621,,,,,0.04626666667,-0.4723071809
70.771,0.72195,-0.43428,,,,,0.04375454545,-0.48125
71.271,0.68015,-0.44335,,,,,0.04122121212,-0.4913009752
71.771,0.63858,-0.45121,,,,,0.03870181818,-0.5000110816
72.271,0.59704,-0.45797,,,,,0.03618424242,-0.5075022163
72.771,0.55501,-0.46796,,,,,0.0336369697,-0.518572695
73.271,0.51362,-0.47453,,,,,0.03112848485,-0.5258532801
73.771,0.47194,-0.48232,,,,,0.02860242424,-0.5344858156
74.271,0.43006,-0.48839,,,,,0.02606424242,-0.5412123227
74.771,0.38865,-0.49548,,,,,0.02355454545,-0.5490691489
75.271,0.34682,-0.50173,,,,,0.02101939394,-0.5559951241
75.771,0.30522,-0.51028,,,,,0.01849818182,-0.5654698582
76.271,0.26386,-0.51534,,,,,0.01599151515,-0.5710771277
76.771,0.22161,-0.52177,,,,,0.01343090909,-0.5782025709
77.271,0.18028,-0.52849,,,,,0.01092606061,-0.5856493794
77.771,0.13874,-0.53143,,,,,0.008408484848,-0.5889073582
78.271,0.09676,-0.53956,,,,,0.005864242424,-0.5979166667
78.771,0.05527,-0.54661,,,,,0.00334969697,-0.6057291667
79.271,0.0136,-0.55133,,,,,0.0008242424242,-0.6109596631
79.539,0.00232,-0.53568,,,,,0.0001406060606,-0.5936170213
80.039,0.0448,-0.47955,,,,,0.002715151515,-0.5314162234
80.539,0.08659,-0.45096,,,,,0.005247878788,-0.4997340426
81.039,0.12846,-0.42528,,,,,0.007785454545,-0.4712765957
81.539,0.16964,-0.40522,,,,,0.01028121212,-0.4490469858
82.039,0.21173,-0.38796,,,,,0.01283212121,-0.4299202128
82.539,0.25341,-0.37113,,,,,0.01535818182,-0.4112699468
83.039,0.29464,-0.35494,,,,,0.0178569697,-0.3933289007
83.539,0.3367,-0.34008,,,,,0.02040606061,-0.3768617021
84.039,0.37831,-0.32462,,,,,0.02292787879,-0.3597296099
84.539,0.41985,-0.31101,,,,,0.02544545455,-0.3446476064
85.039,0.46168,-0.29624,,,,,0.02798060606,-0.3282801418
85.539,0.50303,-0.28485,,,,,0.03048666667,-0.3156582447
86.039,0.54502,-0.27074,,,,,0.03303151515,-0.3000221631
86.539,0.58668,-0.25665,,,,,0.03555636364,-0.2844082447
87.039,0.62792,-0.24445,,,,,0.03805575758,-0.2708887411
87.539,0.67015,-0.23426,,,,,0.04061515152,-0.2595966312
88.039,0.71164,-0.22236,,,,,0.04312969697,-0.2464095745
88.539,0.75309,-0.20874,,,,,0.04564181818,-0.2313164894
89.039,0.79507,-0.19705,,,,,0.04818606061,-0.2183621454
89.539,0.83651,-0.18384,,,,,0.05069757576,-0.2037234043
90.039,0.87833,-0.17337,,,,,0.05323212121,-0.1921210106
90.539,0.92008,-0.16291,,,,,0.05576242424,-0.1805296986
91.039,0.96138,-0.14897,,,,,0.05826545455,-0.1650820035
91.539,1.00342,-0.13839,,,,,0.06081333333,-0.1533577128
92.039,1.045,-0.12484,,,,,0.06333333333,-0.1383421986
92.539,1.08633,-0.11599,,,,,0.06583818182,-0.1285350177
93.039,1.12841,-0.10213,,,,,0.06838848485,-0.1131759752
93.539,1.1698,-0.08959,,,,,0.0708969697,-0.09927969858
94.039,1.21162,-0.07765,,,,,0.07343151515,-0.0860483156
94.539,1.25335,-0.0668,,,,,0.07596060606,-0.0740248227
95.039,1.29471,-0.05449,,,,,0.07846727273,-0.06038342199
95.539,1.33675,-0.04586,,,,,0.08101515152,-0.05082003546
96.039,1.37843,-0.03265,,,,,0.08354121212,-0.03618129433
96.539,1.4196,-0.02089,,,,,0.08603636364,-0.02314937943
97.039,1.46185,-0.00643,,,,,0.0885969697,-0.007125443262
97.539,1.50334,0.00284,,,,,0.09111151515,0.003147163121
98.039,1.54477,0.01096,,,,,0.09362242424,0.01214539007
98.539,1.58678,0.02217,,,,,0.09616848485,0.02456781915
99.039,1.62809,0.03314,,,,,0.09867212121,0.03672429078
99.307,1.65026,0.03869,,,,,0.1000157576,0.04287455674
99.807,1.61357,-0.0574,,,,,0.09779212121,-0.06360815603
100.307,1.57214,-0.11057,,,,,0.09528121212,-0.1225288121
100.807,1.53018,-0.15144,,,,,0.09273818182,-0.1678191489
101.307,1.48861,-0.18617,,,,,0.09021878788,-0.2063054078
101.807,1.44711,-0.21527,,,,,0.08770363636,-0.2385527482
102.307,1.40501,-0.24078,,,,,0.08515212121,-0.2668218085
102.807,1.36371,-0.26259,,,,,0.08264909091,-0.2909906915
103.307,1.32201,-0.28196,,,,,0.08012181818,-0.3124556738
103.807,1.28025,-0.30143,,,,,0.07759090909,-0.3340314716
104.307,1.23875,-0.31869,,,,,0.07507575758,-0.3531582447
104.807,1.19677,-0.33353,,,,,0.07253151515,-0.3696032801
105.307,1.15536,-0.3486,,,,,0.07002181818,-0.3863031915
105.807,1.11382,-0.36161,,,,,0.06750424242,-0.4007203014
106.307,1.07165,-0.37442,,,,,0.06494848485,-0.4149157801
106.807,1.03034,-0.3878,,,,,0.06244484848,-0.4297429078
107.307,0.98887,-0.39931,,,,,0.05993151515,-0.4424977837
107.807,0.94674,-0.41113,,,,,0.05737818182,-0.4555961879
108.307,0.90537,-0.42092,,,,,0.05487090909,-0.4664450355
108.807,0.86351,-0.43189,,,,,0.05233393939,-0.4786015071
109.307,0.82202,-0.44026,,,,,0.04981939394,-0.487876773
109.807,0.78039,-0.45032,,,,,0.04729636364,-0.4990248227
110.307,0.73838,-0.45935,,,,,0.04475030303,-0.5090314716
110.807,0.69703,-0.46881,,,,,0.04224424242,-0.5195146277
111.307,0.6554,-0.47739,,,,,0.03972121212,-0.5290226064
111.807,0.61335,-0.48655,,,,,0.03717272727,-0.5391733156
112.307,0.57207,-0.49373,,,,,0.03467090909,-0.5471298759
112.807,0.53028,-0.50148,,,,,0.03213818182,-0.5557180851
113.307,0.48851,-0.50886,,,,,0.02960666667,-0.5638962766
113.807,0.44718,-0.51455,,,,,0.02710181818,-0.5702016844
114.307,0.40504,-0.52483,,,,,0.02454787879,-0.5815935284
114.807,0.36363,-0.52843,,,,,0.02203818182,-0.5855828901
115.307,0.32215,-0.53627,,,,,0.01952424242,-0.5942708333
115.807,0.28003,-0.5415,,,,,0.01697151515,-0.6000664894
116.307,0.23859,-0.5481,,,,,0.01446,-0.6073803191
116.807,0.19705,-0.55118,,,,,0.01194242424,-0.6107934397
117.307,0.1552,-0.5588,,,,,0.009406060606,-0.6192375887
117.807,0.11372,-0.56369,,,,,0.006892121212,-0.6246564716
118.307,0.07183,-0.56905,,,,,0.004353333333,-0.6305961879
118.807,0.03032,-0.57463,,,,,0.001837575758,-0.6367796986
119.174,-0.00013,-0.57716,,,,,-0.000007878787879,-0.6395833333
119.575,0.02849,-0.52358,,,,,0.001726666667,-0.5802083333
120.075,0.07011,-0.48868,,,,,0.004249090909,-0.5415336879
120.575,0.11142,-0.46545,,,,,0.006752727273,-0.5157912234
121.075,0.1535,-0.44323,,,,,0.009303030303,-0.4911679965
121.575,0.1951,-0.42382,,,,,0.01182424242,-0.4696586879
122.075,0.23649,-0.40747,,,,,0.01433272727,-0.4515403369
122.575,0.27844,-0.39165,,,,,0.01687515152,-0.4340093085
123.075,0.3199,-0.37687,,,,,0.01938787879,-0.4176307624
123.575,0.36173,-0.36651,,,,,0.0219230303,-0.406150266
124.075,0.40341,-0.3503,,,,,0.02444909091,-0.3881870567
124.575,0.44468,-0.33708,,,,,0.02695030303,-0.373537234
125.075,0.48695,-0.3218,,,,,0.02951212121,-0.3566046099
125.575,0.52837,-0.30884,,,,,0.03202242424,-0.3422429078
126.075,0.56981,-0.29577,,,,,0.03453393939,-0.3277593085
126.575,0.61187,-0.2826,,,,,0.0370830303,-0.3131648936
127.075,0.65328,-0.27064,,,,,0.03959272727,-0.2999113475
127.575,0.69491,-0.2603,,,,,0.04211575758,-0.2884530142
128.075,0.73692,-0.24893,,,,,0.04466181818,-0.2758532801
128.575,0.77808,-0.234,,,,,0.04715636364,-0.2593085106
129.075,0.82003,-0.22275,,,,,0.04969878788,-0.2468417553
129.575,0.8618,-0.20905,,,,,0.05223030303,-0.2316600177
130.075,0.90305,-0.19721,,,,,0.05473030303,-0.2185394504
130.575,0.94512,-0.18491,,,,,0.05728,-0.2049091312
131.075,0.98667,-0.17623,,,,,0.05979818182,-0.1952903369
131.575,1.02827,-0.16402,,,,,0.06231939394,-0.1817597518
132.075,1.07008,-0.15186,,,,,0.06485333333,-0.1682845745
132.575,1.11148,-0.14034,,,,,0.06736242424,-0.155518617
133.075,1.15346,-0.12917,,,,,0.06990666667,-0.1431405142
133.575,1.19513,-0.11638,,,,,0.07243212121,-0.1289671986
134.075,1.23636,-0.10575,,,,,0.07493090909,-0.1171875
134.575,1.27855,-0.09338,,,,,0.07748787879,-0.1034796099
135.075,1.32009,-0.0827,,,,,0.08000545455,-0.09164450355
135.575,1.36149,-0.07023,,,,,0.08251454545,-0.07782579787
136.075,1.40351,-0.05835,,,,,0.08506121212,-0.06466090426
136.575,1.44492,-0.04573,,,,,0.08757090909,-0.05067597518
137.075,1.48669,-0.03621,,,,,0.09010242424,-0.04012632979
137.575,1.52842,-0.02099,,,,,0.09263151515,-0.02326019504
138.075,1.56974,-0.01243,,,,,0.09513575758,-0.01377437943
138.575,1.61182,-0.00008,,,,,0.09768606061,-0.00008865248227
139.039,1.65,0.00779,,,,,0.1,0.008632535461
139.341,1.63044,-0.05472,,,,,0.09881454545,-0.06063829787
139.841,1.58831,-0.11784,,,,,0.09626121212,-0.1305851064
140.341,1.54694,-0.16105,,,,,0.09375393939,-0.1784685284
140.841,1.50527,-0.19761,,,,,0.09122848485,-0.2189827128
141.341,1.46333,-0.22652,,,,,0.08868666667,-0.2510195035
141.841,1.42195,-0.25123,,,,,0.08617878788,-0.278402039
142.341,1.38006,-0.27294,,,,,0.08364,-0.3024601064
142.841,1.33854,-0.29339,,,,,0.08112363636,-0.3251218972
143.341,1.29711,-0.31331,,,,,0.07861272727,-0.3471963652
143.841,1.2549,-0.32542,,,,,0.07605454545,-0.3606161348
144.341,1.21358,-0.3494,,,,,0.07355030303,-0.3871897163
144.841,1.17208,-0.3661,,,,,0.07103515152,-0.405695922
145.341,1.12993,-0.37622,,,,,0.06848060606,-0.416910461
145.841,1.08856,-0.38897,,,,,0.06597333333,-0.4310394504
146.341,1.04693,-0.40387,,,,,0.06345030303,-0.4475509752
146.841,1.0051,-0.41459,,,,,0.06091515152,-0.4594304078
147.341,0.96365,-0.4267,,,,,0.0584030303,-0.4728501773
147.841,0.92166,-0.43671,,,,,0.05585818182,-0.4839428191
148.341,0.88025,-0.44656,,,,,0.05334848485,-0.494858156
148.841,0.83871,-0.45655,,,,,0.05083090909,-0.5059286348
149.341,0.79667,-0.46478,,,,,0.0482830303,-0.5150487589
149.841,0.75527,-0.47482,,,,,0.04577393939,-0.5261746454
150.341,0.71354,-0.48274,,,,,0.04324484848,-0.5349512411
150.841,0.67179,-0.49223,,,,,0.04071454545,-0.5454676418
151.341,0.63036,-0.50043,,,,,0.03820363636,-0.5545545213
151.841,0.58836,-0.5076,,,,,0.03565818182,-0.5625
152.341,0.5469,-0.51589,,,,,0.03314545455,-0.5716866135
152.841,0.5055,-0.52205,,,,,0.03063636364,-0.5785128546
153.341,0.4632,-0.53017,,,,,0.02807272727,-0.5875110816
153.841,0.42192,-0.53632,,,,,0.02557090909,-0.5943262411
154.341,0.38031,-0.54389,,,,,0.02304909091,-0.6027149823
154.841,0.33843,-0.55062,,,,,0.02051090909,-0.6101728723
155.341,0.29688,-0.55699,,,,,0.01799272727,-0.6172318262
155.841,0.25514,-0.56159,,,,,0.0154630303,-0.622329344
156.341,0.21352,-0.56818,,,,,0.01294060606,-0.6296320922
156.841,0.172,-0.57276,,,,,0.01042424242,-0.6347074468
157.341,0.12993,-0.57939,,,,,0.007874545455,-0.6420545213
157.841,0.08864,-0.58379,,,,,0.005372121212,-0.6469304078
158.341,0.04703,-0.58999,,,,,0.00285030303,-0.6538009752
158.841,0.00493,-0.59565,,,,,0.0002987878788,-0.6600731383
159.108,0.01125,-0.56199,,,,,0.0006818181818,-0.6227726064
159.608,0.05306,-0.52051,,,,,0.003215757576,-0.5768062943
160.108,0.09508,-0.49121,,,,,0.005762424242,-0.5443373227
160.608,0.13659,-0.46952,,,,,0.008278181818,-0.5203014184
161.108,0.17837,-0.45169,,,,,0.01081030303,-0.5005429965
161.608,0.22011,-0.43366,,,,,0.01334,-0.4805629433
162.108,0.2614,-0.41956,,,,,0.01584242424,-0.4649379433
162.608,0.3035,-0.4043,,,,,0.01839393939,-0.4480274823
163.108,0.34506,-0.38815,,,,,0.02091272727,-0.4301307624
163.608,0.38634,-0.3747,,,,,0.02341454545,-0.4152260638
164.108,0.42854,-0.36124,,,,,0.02597212121,-0.4003102837
164.608,0.46994,-0.34829,,,,,0.02848121212,-0.3859596631
165.108,0.51158,-0.33592,,,,,0.03100484848,-0.372251773
165.608,0.55344,-0.32366,,,,,0.03354181818,-0.3586657801
166.108,0.5948,-0.31308,,,,,0.03604848485,-0.3469414894
166.608,0.63675,-0.29985,,,,,0.03859090909,-0.3322805851
167.108,0.67846,-0.28835,,,,,0.04111878788,-0.3195367908
167.608,0.71974,-0.27637,,,,,0.04362060606,-0.3062610816
168.108,0.76183,-0.26197,,,,,0.04617151515,-0.2903036348
168.608,0.80341,-0.25092,,,,,0.04869151515,-0.2780585106
169.108,0.84482,-0.23902,,,,,0.05120121212,-0.2648714539
169.608,0.88679,-0.22865,,,,,0.05374484848,-0.2533798759
170.108,0.92811,-0.21525,,,,,0.05624909091,-0.2385305851
170.608,0.97012,-0.20222,,,,,0.05879515152,-0.2240913121
171.108,1.01173,-0.19218,,,,,0.0613169697,-0.2129654255
171.608,1.05307,-0.17994,,,,,0.06382242424,-0.1994015957
172.108,1.09519,-0.16748,,,,,0.06637515152,-0.1855939716
172.608,1.13675,-0.15476,,,,,0.06889393939,-0.171498227
173.108,1.17799,-0.14264,,,,,0.07139333333,-0.1580673759
173.608,1.22023,-0.13078,,,,,0.07395333333,-0.1449246454
174.108,1.2616,-0.11923,,,,,0.07646060606,-0.1321254433
174.608,1.30324,-0.10852,,,,,0.07898424242,-0.1202570922
175.108,1.34517,-0.09302,,,,,0.08152545455,-0.1030806738
175.608,1.38644,-0.08504,,,,,0.08402666667,-0.09423758865
176.108,1.42844,-0.07173,,,,,0.08657212121,-0.07948803191
176.608,1.47003,-0.06086,,,,,0.08909272727,-0.06744237589
177.108,1.51146,-0.04946,,,,,0.09160363636,-0.05480939716
177.608,1.55338,-0.03728,,,,,0.09414424242,-0.04131205674
178.108,1.595,-0.02551,,,,,0.09666666667,-0.02826906028
178.608,1.63658,-0.01383,,,,,0.09918666667,-0.01532579787
178.875,1.6475,-0.03289,,,,,0.09984848485,-0.03644725177
179.375,1.60542,-0.11513,,,,,0.09729818182,-0.1275820035
179.875,1.56354,-0.1625,,,,,0.09476,-0.1800753546
180.375,1.52194,-0.19991,,,,,0.09223878788,-0.2215314716
180.875,1.48049,-0.23069,,,,,0.08972666667,-0.2556405142
181.375,1.43834,-0.25676,,,,,0.08717212121,-0.2845301418
181.875,1.39697,-0.28117,,,,,0.08466484848,-0.3115802305
182.375,1.35544,-0.30058,,,,,0.08214787879,-0.333089539
182.875,1.3133,-0.32099,,,,,0.07959393939,-0.3557070035
183.375,1.27191,-0.33833,,,,,0.07708545455,-0.3749224291
183.875,1.23038,-0.35536,,,,,0.07456848485,-0.3937943262
184.375,1.18844,-0.36936,,,,,0.07202666667,-0.4093085106
184.875,1.14706,-0.38297,,,,,0.06951878788,-0.4243905142
185.375,1.10508,-0.39769,,,,,0.06697454545,-0.4407025709
185.875,1.06367,-0.40942,,,,,0.06446484848,-0.4537012411
186.375,1.02205,-0.4215,,,,,0.06194242424,-0.467087766
186.875,0.97997,-0.43384,,,,,0.05939212121,-0.4807624113
187.375,0.93866,-0.44399,,,,,0.05688848485,-0.492010195
187.875,0.89702,-0.45583,,,,,0.05436484848,-0.5051307624
188.375,0.85512,-0.46611,,,,,0.05182545455,-0.5165226064
188.875,0.81375,-0.47456,,,,,0.04931818182,-0.5258865248
189.375,0.77179,-0.48374,,,,,0.04677515152,-0.5360593972
189.875,0.73023,-0.49368,,,,,0.04425636364,-0.5470744681
190.375,0.68885,-0.50039,,,,,0.04174848485,-0.554510195
190.875,0.64662,-0.5097,,,,,0.03918909091,-0.5648271277
191.375,0.60525,-0.5179,,,,,0.03668181818,-0.5739140071
191.875,0.5638,-0.52572,,,,,0.03416969697,-0.5825797872
192.375,0.5217,-0.53419,,,,,0.03161818182,-0.5919658688
192.875,0.48022,-0.5411,,,,,0.02910424242,-0.599623227
193.375,0.43858,-0.54695,,,,,0.02658060606,-0.6061059397
193.875,0.39689,-0.55314,,,,,0.02405393939,-0.6129654255
194.375,0.3554,-0.55935,,,,,0.02153939394,-0.6198470745
194.875,0.3134,-0.56487,,,,,0.01899393939,-0.6259640957
195.375,0.272,-0.57223,,,,,0.01648484848,-0.6341201241
195.875,0.23041,-0.57788,,,,,0.01396424242,-0.6403812057
196.375,0.18837,-0.58465,,,,,0.01141636364,-0.647883422
196.875,0.14703,-0.58882,,,,,0.008910909091,-0.6525044326
197.375,0.10523,-0.59447,,,,,0.006377575758,-0.6587655142
197.875,0.06348,-0.59965,,,,,0.003847272727,-0.6645057624
198.375,0.02211,-0.60486,,,,,0.00134,-0.6702792553
198.643,-0.00024,-0.60781,,,,,-0.00001454545455,-0.6735483156
199.143,0.03676,-0.54534,,,,,0.002227878788,-0.6043218085
199.643,0.0781,-0.51472,,,,,0.004733333333,-0.5703900709
200.143,0.12009,-0.49162,,,,,0.007278181818,-0.5447916667
200.643,0.16168,-0.4733,,,,,0.009798787879,-0.5244902482
201.143,0.20297,-0.45666,,,,,0.01230121212,-0.5060505319
201.643,0.24522,-0.44182,,,,,0.01486181818,-0.4896054965
202.143,0.2866,-0.42356,,,,,0.01736969697,-0.4693705674
202.643,0.32816,-0.40953,,,,,0.01988848485,-0.4538231383
203.143,0.37016,-0.39619,,,,,0.02243393939,-0.4390403369
203.643,0.41144,-0.38277,,,,,0.02493575758,-0.424168883
204.143,0.45333,-0.37046,,,,,0.02747454545,-0.4105274823
204.643,0.49518,-0.35649,,,,,0.03001090909,-0.3950465426
205.143,0.53633,-0.34457,,,,,0.03250484848,-0.3818373227
205.643,0.57839,-0.33176,,,,,0.03505393939,-0.367641844
206.143,0.62007,-0.31987,,,,,0.03758,-0.3544658688
206.643,0.66145,-0.30772,,,,,0.04008787879,-0.341001773
207.143,0.7034,-0.2946,,,,,0.04263030303,-0.326462766
207.643,0.74486,-0.28519,,,,,0.0451430303,-0.3160350177
208.143,0.78669,-0.27284,,,,,0.04767818182,-0.3023492908
208.643,0.82838,-0.25997,,,,,0.05020484848,-0.2880873227
209.143,0.86969,-0.24722,,,,,0.05270848485,-0.2739583333
209.643,0.91181,-0.23535,,,,,0.05526121212,-0.2608045213
210.143,0.95336,-0.22287,,,,,0.05777939394,-0.246974734
210.643,0.99467,-0.21328,,,,,0.0602830303,-0.2363475177
211.143,1.03679,-0.20034,,,,,0.06283575758,-0.2220079787
211.643,1.07831,-0.18726,,,,,0.06535212121,-0.2075132979
212.143,1.11988,-0.18028,,,,,0.06787151515,-0.1997783688
212.643,1.1618,-0.16569,,,,,0.07041212121,-0.1836103723
213.143,1.20312,-0.15335,,,,,0.07291636364,-0.169935727
213.643,1.24511,-0.14306,,,,,0.07546121212,-0.1585328014
214.143,1.28672,-0.13066,,,,,0.0779830303,-0.1447916667
214.643,1.32802,-0.11819,,,,,0.08048606061,-0.130972961
215.143,1.37015,-0.10738,,,,,0.08303939394,-0.1189937943
215.643,1.41165,-0.09575,,,,,0.08555454545,-0.1061059397
216.143,1.4532,-0.08489,,,,,0.08807272727,-0.09407136525
216.643,1.49511,-0.0721,,,,,0.09061272727,-0.07989804965
217.143,1.53646,-0.05987,,,,,0.09311878788,-0.06634530142
217.643,1.57838,-0.04912,,,,,0.09565939394,-0.05443262411
218.143,1.62008,-0.03687,,,,,0.09818666667,-0.04085771277
218.509,1.65014,-0.02852,,,,,0.1000084848,-0.03160460993
218.91,1.62174,-0.10338,,,,,0.09828727273,-0.1145611702
219.41,1.58039,-0.15851,,,,,0.09578121212,-0.1756538121
219.91,1.53884,-0.19848,,,,,0.0932630303,-0.2199468085
220.41,1.49663,-0.23334,,,,,0.09070484848,-0.2585771277
220.91,1.45535,-0.26004,,,,,0.0882030303,-0.2881648936
221.41,1.41372,-0.28311,,,,,0.08568,-0.3137300532
221.91,1.37177,-0.30822,,,,,0.08313757576,-0.3415558511
222.41,1.33038,-0.32648,,,,,0.08062909091,-0.3617907801
222.91,1.2886,-0.34033,,,,,0.0780969697,-0.3771387411
223.41,1.24694,-0.35751,,,,,0.07557212121,-0.3961768617
223.91,1.20548,-0.37499,,,,,0.07305939394,-0.4155474291
224.41,1.16338,-0.39039,,,,,0.07050787879,-0.4326130319
224.91,1.12205,-0.40339,,,,,0.0680030303,-0.4470190603
225.41,1.08044,-0.41632,,,,,0.06548121212,-0.4613475177
225.91,1.03852,-0.42817,,,,,0.06294060606,-0.4744791667
226.41,0.99703,-0.44175,,,,,0.06042606061,-0.4895279255
226.91,0.9552,-0.44927,,,,,0.05789090909,-0.4978612589
227.41,0.91362,-0.45993,,,,,0.05537090909,-0.5096742021
227.91,0.87214,-0.47149,,,,,0.0528569697,-0.5224844858
228.41,0.83005,-0.48098,,,,,0.05030606061,-0.5330008865
228.91,0.78868,-0.49205,,,,,0.04779878788,-0.5452681738
229.41,0.74722,-0.49883,,,,,0.04528606061,-0.5527814716
229.91,0.705,-0.50917,,,,,0.04272727273,-0.564239805
230.41,0.66372,-0.51575,,,,,0.04022545455,-0.5715314716
230.91,0.62199,-0.52435,,,,,0.03769636364,-0.5810616135
231.41,0.58033,-0.53084,,,,,0.03517151515,-0.5882535461
231.91,0.53872,-0.53811,,,,,0.03264969697,-0.5963098404
232.41,0.49681,-0.54639,,,,,0.03010969697,-0.6054853723
232.91,0.45537,-0.55262,,,,,0.02759818182,-0.6123891844
233.41,0.41379,-0.56021,,,,,0.02507818182,-0.6208000887
233.91,0.37167,-0.56475,,,,,0.02252545455,-0.625831117
234.41,0.3304,-0.57207,,,,,0.02002424242,-0.6339428191
234.91,0.2887,-0.57734,,,,,0.0174969697,-0.6397828014
235.41,0.24676,-0.5844,,,,,0.01495515152,-0.647606383
235.91,0.20551,-0.59113,,,,,0.01245515152,-0.655064273
236.41,0.16347,-0.59586,,,,,0.009907272727,-0.6603058511
236.91,0.12192,-0.6034,,,,,0.007389090909,-0.6686613475
237.41,0.08048,-0.60613,,,,,0.004877575758,-0.6716866135
237.91,0.0384,-0.61267,,,,,0.002327272727,-0.6789339539
238.376,-0.00002,-0.61813,,,,,-0.000001212121212,-0.6849844858
238.678,0.01952,-0.57158,,,,,0.001183030303,-0.6333998227
239.178,0.0618,-0.53742,,,,,0.003745454545,-0.5955452128
239.678,0.10336,-0.51219,,,,,0.006264242424,-0.5675864362
240.178,0.14469,-0.49374,,,,,0.008769090909,-0.5471409574
240.678,0.18687,-0.47449,,,,,0.01132545455,-0.5258089539
241.178,0.2282,-0.45999,,,,,0.01383030303,-0.5097406915
241.678,0.27002,-0.4406,,,,,0.01636484848,-0.4882535461
242.178,0.31174,-0.42882,,,,,0.01889333333,-0.4751994681
242.678,0.35306,-0.41423,,,,,0.02139757576,-0.4590314716
243.178,0.39517,-0.39852,,,,,0.02394969697,-0.4416223404
243.678,0.4368,-0.38825,,,,,0.02647272727,-0.430241578
244.178,0.47811,-0.37326,,,,,0.02897636364,-0.4136303191
244.678,0.52015,-0.36261,,,,,0.03152424242,-0.4018284574
245.178,0.5617,-0.35032,,,,,0.03404242424,-0.3882092199
245.678,0.60327,-0.33907,,,,,0.03656181818,-0.3757424645
246.178,0.64507,-0.32501,,,,,0.03909515152,-0.3601617908
246.678,0.68634,-0.3123,,,,,0.04159636364,-0.3460771277
247.178,0.72852,-0.30015,,,,,0.04415272727,-0.3326130319
247.678,0.77,-0.28851,,,,,0.04666666667,-0.3197140957
248.178,0.81141,-0.27615,,,,,0.04917636364,-0.3060172872
248.678,0.85354,-0.2648,,,,,0.05172969697,-0.2934397163
249.178,0.89504,-0.25273,,,,,0.05424484848,-0.280064273
249.678,0.93645,-0.24335,,,,,0.05675454545,-0.2696697695
250.178,0.97857,-0.22899,,,,,0.05930727273,-0.2537566489
250.678,1.01985,-0.22069,,,,,0.06180909091,-0.2445589539
251.178,1.06165,-0.20845,,,,,0.06434242424,-0.2309951241
251.678,1.1035,-0.19542,,,,,0.06687878788,-0.2165558511
252.178,1.14475,-0.18477,,,,,0.06937878788,-0.2047539894
252.678,1.18678,-0.17196,,,,,0.07192606061,-0.1905585106
253.178,1.22836,-0.16176,,,,,0.07444606061,-0.1792553191
253.678,1.26981,-0.15358,,,,,0.07695818182,-0.1701906028
254.178,1.3117,-0.13662,,,,,0.0794969697,-0.1513962766
254.678,1.35319,-0.1278,,,,,0.08201151515,-0.1416223404
255.178,1.39499,-0.11368,,,,,0.08454484848,-0.1259751773
255.678,1.43679,-0.10024,,,,,0.08707818182,-0.1110815603
256.178,1.47799,-0.08985,,,,,0.08957515152,-0.09956781915
256.678,1.52021,-0.07684,,,,,0.09213393939,-0.08515070922
257.178,1.56176,-0.06552,,,,,0.09465212121,-0.07260638298
257.678,1.60304,-0.05424,,,,,0.09715393939,-0.06010638298
258.178,1.64519,-0.04174,,,,,0.09970848485,-0.04625443262
258.445,1.63909,-0.08497,,,,,0.09933878788,-0.09416001773
258.945,1.5971,-0.15273,,,,,0.09679393939,-0.1692486702
259.445,1.55511,-0.1952,,,,,0.09424909091,-0.2163120567
259.945,1.51372,-0.22893,,,,,0.09174060606,-0.2536901596
260.445,1.47201,-0.25712,,,,,0.08921272727,-0.284929078
260.945,1.43029,-0.28393,,,,,0.08668424242,-0.3146387411
261.445,1.38885,-0.30499,,,,,0.08417272727,-0.3379765071
261.945,1.3468,-0.32601,,,,,0.08162424242,-0.3612699468
262.445,1.30544,-0.34425,,,,,0.07911757576,-0.3814827128
262.945,1.26376,-0.36339,,,,,0.07659151515,-0.4026928191
263.445,1.22175,-0.37819,,,,,0.07404545455,-0.4190935284
263.945,1.18039,-0.39145,,,,,0.07153878788,-0.4337876773
264.445,1.13861,-0.40794,,,,,0.06900666667,-0.4520611702
264.945,1.09693,-0.41996,,,,,0.06648060606,-0.4653812057
265.445,1.05552,-0.4325,,,,,0.06397090909,-0.4792774823
265.945,1.01341,-0.44389,,,,,0.06141878788,-0.4918993794
266.445,0.97203,-0.45649,,,,,0.05891090909,-0.5058621454
266.945,0.93056,-0.46671,,,,,0.05639757576,-0.5171875
267.445,0.88835,-0.47587,,,,,0.05383939394,-0.5273382092
267.945,0.847,-0.48609,,,,,0.05133333333,-0.5386635638
268.445,0.80549,-0.4956,,,,,0.04881757576,-0.5492021277
268.945,0.76351,-0.50417,,,,,0.04627333333,-0.5586990248
269.445,0.72207,-0.51223,,,,,0.04376181818,-0.5676307624
269.945,0.68023,-0.51857,,,,,0.04122606061,-0.5746564716
270.445,0.63868,-0.52695,,,,,0.03870787879,-0.5839428191
270.945,0.59716,-0.53478,,,,,0.03619151515,-0.5926196809
271.445,0.55511,-0.5418,,,,,0.0336430303,-0.6003989362
271.945,0.51372,-0.54799,,,,,0.03113454545,-0.607258422
272.445,0.47204,-0.5551,,,,,0.02860848485,-0.6151374113
272.945,0.43019,-0.56216,,,,,0.02607212121,-0.6229609929
273.445,0.38877,-0.56898,,,,,0.02356181818,-0.630518617
273.945,0.34689,-0.57443,,,,,0.02102363636,-0.6365580674
274.445,0.30532,-0.58123,,,,,0.01850424242,-0.6440935284
274.945,0.26397,-0.58654,,,,,0.01599818182,-0.6499778369
275.445,0.22172,-0.59321,,,,,0.01343757576,-0.6573692376
275.945,0.1804,-0.59889,,,,,0.01093333333,-0.6636635638
276.445,0.13883,-0.60425,,,,,0.008413939394,-0.6696032801
276.945,0.09686,-0.61266,,,,,0.00587030303,-0.6789228723
277.445,0.05538,-0.61536,,,,,0.003356363636,-0.6819148936
277.945,0.01368,-0.62175,,,,,0.0008290909091,-0.6889960106
278.214,0.0023,-0.60737,,,,,0.0001393939394,-0.673060727
278.714,0.04481,-0.55688,,,,,0.002715757576,-0.6171099291
279.214,0.08658,-0.52975,,,,,0.005247272727,-0.587045656
279.714,0.12844,-0.50695,,,,,0.007784242424,-0.5617796986
280.214,0.16962,-0.48852,,,,,0.01028,-0.541356383
280.714,0.21173,-0.47278,,,,,0.01283212121,-0.5239140071
281.214,0.2534,-0.45561,,,,,0.01535757576,-0.5048869681
281.714,0.29463,-0.44331,,,,,0.01785636364,-0.4912566489
282.214,0.3367,-0.42791,,,,,0.02040606061,-0.4741910461
282.714,0.37829,-0.41543,,,,,0.02292666667,-0.4603612589
283.214,0.41986,-0.40148,,,,,0.02544606061,-0.4449024823
283.714,0.46169,-0.38814,,,,,0.02798121212,-0.4301196809
284.214,0.50302,-0.37563,,,,,0.03048606061,-0.4162566489
284.714,0.54504,-0.36391,,,,,0.03303272727,-0.4032690603
285.214,0.58667,-0.3512,,,,,0.03555575758,-0.3891843972
285.714,0.62792,-0.34025,,,,,0.03805575758,-0.3770500887
286.214,0.67014,-0.3286,,,,,0.04061454545,-0.3641400709
286.714,0.71162,-0.31659,,,,,0.04312848485,-0.350831117
287.214,0.75309,-0.30404,,,,,0.04564181818,-0.3369237589
287.714,0.79506,-0.29265,,,,,0.04818545455,-0.3243018617
288.214,0.8365,-0.28097,,,,,0.0506969697,-0.3113585993
288.714,0.87833,-0.27078,,,,,0.05323212121,-0.3000664894
289.214,0.92008,-0.25965,,,,,0.05576242424,-0.2877327128
289.714,0.96137,-0.25118,,,,,0.05826484848,-0.2783466312
290.214,1.00342,-0.23783,,,,,0.06081333333,-0.2635527482
290.714,1.04501,-0.22701,,,,,0.06333393939,-0.2515625
291.214,1.08635,-0.21386,,,,,0.06583939394,-0.2369902482
291.714,1.12839,-0.20231,,,,,0.06838727273,-0.2241910461
292.214,1.16983,-0.18877,,,,,0.07089878788,-0.2091866135
292.714,1.21161,-0.1772,,,,,0.07343090909,-0.1963652482
293.214,1.25333,-0.16706,,,,,0.07595939394,-0.1851285461
293.714,1.29471,-0.15553,,,,,0.07846727273,-0.1723515071
294.214,1.33673,-0.14319,,,,,0.08101393939,-0.1586768617
294.714,1.37842,-0.13147,,,,,0.08354060606,-0.145689273
295.214,1.41959,-0.12103,,,,,0.08603575758,-0.1341201241
295.714,1.46187,-0.10678,,,,,0.08859818182,-0.1183289007
296.214,1.50335,-0.09432,,,,,0.09111212121,-0.1045212766
296.714,1.54475,-0.08354,,,,,0.09362121212,-0.09257535461
297.214,1.58682,-0.07081,,,,,0.09617090909,-0.07846852837
297.714,1.62811,-0.05925,,,,,0.09867333333,-0.06565824468
297.982,1.65026,-0.054,,,,,0.1000157576,-0.05984042553
298.482,1.61367,-0.14091,,,,,0.09779818182,-0.156150266
298.982,1.57225,-0.19008,,,,,0.09528787879,-0.2106382979
299.482,1.53028,-0.22499,,,,,0.09274424242,-0.2493240248
299.982,1.4887,-0.2558,,,,,0.09022424242,-0.2834663121
300.482,1.44719,-0.2818,,,,,0.08770848485,-0.3122783688
300.982,1.40511,-0.30611,,,,,0.08515818182,-0.3392176418
301.482,1.36381,-0.32577,,,,,0.08265515152,-0.3610039894
301.982,1.3221,-0.34548,,,,,0.08012727273,-0.3828457447
302.482,1.28033,-0.36351,,,,,0.07759575758,-0.4028257979
302.982,1.23886,-0.37837,,,,,0.07508242424,-0.4192929965
303.482,1.19686,-0.39391,,,,,0.0725369697,-0.4365137411
303.982,1.15544,-0.40849,,,,,0.07002666667,-0.452670656
304.482,1.11391,-0.42005,,,,,0.06750969697,-0.4654809397
304.982,1.07176,-0.43317,,,,,0.06495515152,-0.4800199468
305.482,1.03045,-0.44525,,,,,0.06245151515,-0.4934064716
305.982,0.98896,-0.45617,,,,,0.0599369697,-0.5055075355
306.482,0.94686,-0.46844,,,,,0.05738545455,-0.5191046099
306.982,0.90548,-0.47678,,,,,0.05487757576,-0.5283466312
307.482,0.8636,-0.48669,,,,,0.05233939394,-0.5393284574
307.982,0.8221,-0.49531,,,,,0.04982424242,-0.5488807624
308.482,0.7805,-0.50379,,,,,0.0473030303,-0.5582779255
308.982,0.73847,-0.51226,,,,,0.04475575758,-0.5676640071
309.482,0.69713,-0.5223,,,,,0.04225030303,-0.5787898936
309.982,0.65548,-0.52811,,,,,0.03972606061,-0.5852282801
310.482,0.61347,-0.53771,,,,,0.03718,-0.595866578
310.982,0.57216,-0.54357,,,,,0.03467636364,-0.6023603723
311.482,0.53034,-0.55141,,,,,0.03214181818,-0.6110483156
311.982,0.48862,-0.55878,,,,,0.02961333333,-0.6192154255
312.482,0.4473,-0.56391,,,,,0.02710909091,-0.624900266
312.982,0.40513,-0.57082,,,,,0.02455333333,-0.6325576241
313.482,0.36373,-0.57836,,,,,0.02204424242,-0.6409131206
313.982,0.32226,-0.58429,,,,,0.01953090909,-0.6474844858
314.482,0.28012,-0.59119,,,,,0.0169769697,-0.6551307624
314.982,0.23869,-0.59644,,,,,0.01446606061,-0.6609485816
315.482,0.19711,-0.60157,,,,,0.01194606061,-0.666633422
315.982,0.15531,-0.60808,,,,,0.009412727273,-0.6738475177
316.482,0.11383,-0.61422,,,,,0.006898787879,-0.6806515957
316.982,0.07192,-0.61793,,,,,0.004358787879,-0.6847628546
317.482,0.03044,-0.62329,,,,,0.001844848485,-0.6907025709
317.85,-0.00011,-0.62729,,,,,-0.000006666666667,-0.695135195
318.251,0.02845,-0.5765,,,,,0.001724242424,-0.6388519504
318.751,0.07009,-0.54574,,,,,0.004247878788,-0.6047650709
319.251,0.1114,-0.52221,,,,,0.006751515152,-0.5786901596
319.751,0.15349,-0.50212,,,,,0.009302424242,-0.556427305
320.251,0.19509,-0.4853,,,,,0.01182363636,-0.5377881206
320.751,0.23648,-0.47035,,,,,0.01433212121,-0.5212211879
321.251,0.27844,-0.45253,,,,,0.01687515152,-0.5014738475
321.751,0.31992,-0.43871,,,,,0.01938909091,-0.4861591312
322.251,0.36171,-0.42765,,,,,0.02192181818,-0.4739029255
322.751,0.4034,-0.41163,,,,,0.02444848485,-0.456150266
323.251,0.44467,-0.40031,,,,,0.02694969697,-0.4436059397
323.751,0.48692,-0.38724,,,,,0.02951030303,-0.4291223404
324.251,0.52836,-0.37589,,,,,0.03202181818,-0.4165447695
324.751,0.56979,-0.36536,,,,,0.03453272727,-0.4048758865
325.251,0.61185,-0.35123,,,,,0.03708181818,-0.3892176418
325.751,0.65323,-0.34253,,,,,0.03958969697,-0.3795766844
326.251,0.6949,-0.33039,,,,,0.04211515152,-0.3661236702
326.751,0.7369,-0.32023,,,,,0.04466060606,-0.354864805
327.251,0.77804,-0.30814,,,,,0.04715393939,-0.3414671986
327.751,0.82003,-0.29701,,,,,0.04969878788,-0.329133422
328.251,0.86179,-0.2837,,,,,0.05222969697,-0.3143838652
328.751,0.90306,-0.27383,,,,,0.05473090909,-0.3034463652
329.251,0.94509,-0.26234,,,,,0.05727818182,-0.2907136525
329.751,0.98665,-0.25113,,,,,0.0597969697,-0.2782912234
330.251,1.02826,-0.2413,,,,,0.06231878788,-0.2673980496
330.751,1.07007,-0.2282,,,,,0.06485272727,-0.2528812057
331.251,1.11149,-0.21631,,,,,0.0673630303,-0.2397052305
331.751,1.15345,-0.20537,,,,,0.06990606061,-0.2275820035
332.251,1.19513,-0.19244,,,,,0.07243212121,-0.2132535461
332.751,1.23635,-0.18099,,,,,0.07493030303,-0.2005651596
333.251,1.27853,-0.16981,,,,,0.07748666667,-0.1881759752
333.751,1.32004,-0.1576,,,,,0.08000242424,-0.1746453901
334.251,1.36147,-0.14851,,,,,0.08251333333,-0.1645722518
334.751,1.40348,-0.13583,,,,,0.08505939394,-0.1505208333
335.251,1.44488,-0.12447,,,,,0.08756848485,-0.1379321809
335.751,1.48666,-0.1127,,,,,0.09010060606,-0.1248891844
336.251,1.5284,-0.09897,,,,,0.09263030303,-0.1096742021
336.751,1.5697,-0.08721,,,,,0.09513333333,-0.09664228723
337.251,1.61181,-0.07552,,,,,0.09768545455,-0.08368794326
337.716,1.65007,-0.06663,,,,,0.1000042424,-0.07383643617
338.018,1.63062,-0.12668,,,,,0.09882545455,-0.1403812057
338.518,1.58849,-0.18104,,,,,0.09627212121,-0.2006205674
339.018,1.54711,-0.22342,,,,,0.09376424242,-0.2475842199
339.518,1.50544,-0.25134,,,,,0.09123878788,-0.2785239362
340.018,1.46354,-0.28104,,,,,0.08869939394,-0.3114361702
340.518,1.42215,-0.30549,,,,,0.08619090909,-0.3385305851
341.018,1.38025,-0.326,,,,,0.08365151515,-0.3612588652
341.518,1.33876,-0.3461,,,,,0.0811369697,-0.3835328014
342.018,1.2973,-0.36473,,,,,0.07862424242,-0.4041777482
342.518,1.25507,-0.38083,,,,,0.07606484848,-0.4220190603
343.018,1.21379,-0.39438,,,,,0.0735630303,-0.4370345745
343.518,1.17225,-0.4101,,,,,0.07104545455,-0.4544547872
344.018,1.13012,-0.42379,,,,,0.06849212121,-0.4696254433
344.518,1.08876,-0.43624,,,,,0.06598545455,-0.4834219858
345.018,1.04708,-0.44573,,,,,0.06345939394,-0.4939383865
345.518,1.00532,-0.4567,,,,,0.06092848485,-0.5060948582
346.018,0.96383,-0.46603,,,,,0.05841393939,-0.5164339539
346.518,0.92182,-0.47803,,,,,0.05586787879,-0.5297318262
347.018,0.88046,-0.48767,,,,,0.05336121212,-0.5404144504
347.518,0.83889,-0.49583,,,,,0.05084181818,-0.5494570035
348.018,0.79686,-0.5057,,,,,0.04829454545,-0.5603945035
348.518,0.75546,-0.51661,,,,,0.04578545455,-0.5724844858
349.018,0.7137,-0.52178,,,,,0.04325454545,-0.5782136525
349.518,0.672,-0.53003,,,,,0.04072727273,-0.5873559397
350.018,0.63055,-0.53775,,,,,0.03821515152,-0.5959109043
350.518,0.58852,-0.5463,,,,,0.03566787879,-0.6053856383
351.018,0.54707,-0.55445,,,,,0.03315575758,-0.6144171099
351.518,0.50569,-0.55911,,,,,0.03064787879,-0.619581117
352.018,0.46339,-0.56992,,,,,0.02808424242,-0.6315602837
352.518,0.42211,-0.57382,,,,,0.02558242424,-0.6358820922
353.018,0.38046,-0.58222,,,,,0.02305818182,-0.6451906028
353.518,0.33867,-0.58866,,,,,0.02052545455,-0.6523271277
354.018,0.29708,-0.59465,,,,,0.01800484848,-0.6589649823
354.518,0.25528,-0.59638,,,,,0.01547151515,-0.6608820922
355.018,0.21373,-0.60376,,,,,0.01295333333,-0.6690602837
355.518,0.17219,-0.6123,,,,,0.01043575758,-0.6785239362
356.018,0.1301,-0.61891,,,,,0.007884848485,-0.6858488475
356.518,0.08884,-0.62357,,,,,0.005384242424,-0.6910128546
357.018,0.0472,-0.62509,,,,,0.002860606061,-0.6926972518
357.518,0.00514,-0.63358,,,,,0.0003115151515,-0.7021054965
357.787,0.01124,-0.60394,,,,,0.0006812121212,-0.6692597518
358.287,0.05307,-0.56304,,,,,0.003216363636,-0.6239361702
358.787,0.09507,-0.53503,,,,,0.005761818182,-0.5928967199
359.287,0.13658,-0.51648,,,,,0.008277575758,-0.5723404255
359.787,0.17836,-0.49926,,,,,0.01080969697,-0.5532579787
360.287,0.22013,-0.48069,,,,,0.01334121212,-0.5326795213
360.787,0.26136,-0.46695,,,,,0.01584,-0.5174534574
361.287,0.30345,-0.45231,,,,,0.01839090909,-0.5012300532
361.787,0.34507,-0.43995,,,,,0.02091333333,-0.4875332447
362.287,0.38635,-0.4281,,,,,0.02341515152,-0.4744015957
362.787,0.42854,-0.41494,,,,,0.02597212121,-0.4598182624
363.287,0.46995,-0.40324,,,,,0.02848181818,-0.4468528369
363.787,0.51156,-0.39102,,,,,0.03100363636,-0.4333111702
364.287,0.55341,-0.37721,,,,,0.03354,-0.4180075355
364.787,0.59478,-0.36382,,,,,0.03604727273,-0.4031693262
365.287,0.63676,-0.35425,,,,,0.03859151515,-0.392564273
365.787,0.67844,-0.34613,,,,,0.04111757576,-0.3835660461
366.287,0.71974,-0.33157,,,,,0.04362060606,-0.3674312943
366.787,0.76182,-0.31991,,,,,0.04617090909,-0.354510195
367.287,0.8034,-0.31055,,,,,0.04869090909,-0.3441378546
367.787,0.84484,-0.30044,,,,,0.05120242424,-0.3329343972
368.287,0.88679,-0.28472,,,,,0.05374484848,-0.3155141844
368.787,0.9281,-0.27327,,,,,0.05624848485,-0.3028257979
369.287,0.97012,-0.26457,,,,,0.05879515152,-0.2931848404
369.787,1.01171,-0.25053,,,,,0.06131575758,-0.2776263298
370.287,1.05306,-0.2397,,,,,0.06382181818,-0.265625
370.787,1.09518,-0.22817,,,,,0.06637454545,-0.252847961
371.287,1.13676,-0.21847,,,,,0.06889454545,-0.2420988475
371.787,1.17799,-0.2065,,,,,0.07139333333,-0.2288342199
372.287,1.22024,-0.19446,,,,,0.07395393939,-0.2154920213
372.787,1.26161,-0.18099,,,,,0.07646121212,-0.2005651596
373.287,1.30323,-0.17104,,,,,0.07898363636,-0.1895390071
373.787,1.34514,-0.15846,,,,,0.08152363636,-0.1755984043
374.287,1.38648,-0.14918,,,,,0.08402909091,-0.1653147163
374.787,1.42842,-0.13744,,,,,0.08657090909,-0.1523049645
375.287,1.47002,-0.12578,,,,,0.08909212121,-0.1393838652
375.787,1.51145,-0.11607,,,,,0.0916030303,-0.1286236702
376.287,1.55339,-0.10204,,,,,0.09414484848,-0.1130762411
376.787,1.59496,-0.09014,,,,,0.09666424242,-0.0998891844
377.287,1.63658,-0.08,,,,,0.09918666667,-0.08865248227
377.554,1.64777,-0.09343,,,,,0.09986484848,-0.1035350177
378.054,1.60569,-0.17029,,,,,0.09731454545,-0.1887078901
378.554,1.56375,-0.2133,,,,,0.09477272727,-0.2363696809
379.054,1.52224,-0.24891,,,,,0.0922569697,-0.275831117
379.554,1.48077,-0.27801,,,,,0.08974363636,-0.3080784574
380.054,1.43863,-0.30342,,,,,0.08718969697,-0.3362367021
380.554,1.39724,-0.32468,,,,,0.08468121212,-0.3597960993
381.054,1.35567,-0.34327,,,,,0.08216181818,-0.3803967199
381.554,1.31357,-0.36247,,,,,0.07961030303,-0.4016733156
382.054,1.27218,-0.378,,,,,0.07710181818,-0.4188829787
382.554,1.2306,-0.39381,,,,,0.07458181818,-0.4364029255
383.054,1.18873,-0.4088,,,,,0.07204424242,-0.4530141844
383.554,1.14731,-0.42146,,,,,0.06953393939,-0.4670434397
384.054,1.10532,-0.43326,,,,,0.06698909091,-0.4801196809
384.554,1.06392,-0.44551,,,,,0.06448,-0.4936945922
385.054,1.02232,-0.45661,,,,,0.06195878788,-0.5059951241
385.554,0.98023,-0.46843,,,,,0.05940787879,-0.5190935284
386.054,0.93891,-0.47699,,,,,0.05690363636,-0.528579344
386.554,0.89724,-0.48659,,,,,0.05437818182,-0.5392176418
387.054,0.85539,-0.49869,,,,,0.05184181818,-0.5526263298
387.554,0.81403,-0.50569,,,,,0.04933515152,-0.560383422
388.054,0.77199,-0.51547,,,,,0.04678727273,-0.5712211879
388.554,0.73051,-0.523,,,,,0.04427333333,-0.5795656028
389.054,0.6891,-0.53057,,,,,0.04176363636,-0.587954344
389.554,0.64686,-0.53919,,,,,0.03920363636,-0.5975066489
390.054,0.60551,-0.54686,,,,,0.03669757576,-0.6060062057
390.554,0.56402,-0.55418,,,,,0.0341830303,-0.6141179078
391.054,0.52198,-0.56404,,,,,0.03163515152,-0.6250443262
391.554,0.48052,-0.56858,,,,,0.02912242424,-0.6300753546
392.054,0.4388,-0.57565,,,,,0.02659393939,-0.6379100177
392.554,0.39721,-0.5816,,,,,0.02407333333,-0.6445035461
393.054,0.3557,-0.58749,,,,,0.02155757576,-0.6510305851
393.554,0.31364,-0.59371,,,,,0.01900848485,-0.6579233156
394.054,0.27227,-0.59735,,,,,0.01650121212,-0.6619570035
394.554,0.23064,-0.60538,,,,,0.01397818182,-0.6708554965
395.054,0.18866,-0.61079,,,,,0.01143393939,-0.6768506206
395.554,0.14729,-0.6156,,,,,0.008926666667,-0.6821808511
396.054,0.10546,-0.62165,,,,,0.006391515152,-0.688885195
396.554,0.06378,-0.62854,,,,,0.003865454545,-0.6965203901
397.054,0.02236,-0.63123,,,,,0.001355151515,-0.6995013298
397.323,-0.00005,-0.63378,,,,,-0.00000303030303,-0.7023271277